Workbook

Sheet NOV
K1: MCPHEE RESERVOIR INFLOW/OUTFLOW TABULATION
A2: AF/cfs CONVERT FACTOR | D2: 1.9835 | L2: NOVEMBER "2014"
D4: RESERVOIR | I4: INFLOW | X4: OUTFLOW | AP4: ADJUSTMENTS | AW4: WEATHER
A5: DATE | B5: RESERV | C5: RESERV | D5: AC FT | E5: ACTIVE | F5: CONV TO | G5: DOLORES | H5: LOST | I5: RECORD | J5: CALC | K5: TOTAL | L5: CALC | M5: DOLORES TUNNEL | V5: LONE | W5: U | X5: TOTAL | Y5: TOTAL | Z5: MVI | AA5: MVI | AB5: MVI | AC5: TO EX & | AD5: MVI | AE5: DV CR | AF5: D/S SENIOR | AH5: BELOW | AI5: FISH | AJ5: SPILL | AK5: RECORD | AL5: CALC | AM5: TOTAL | AN5: NAR | AO5: MVI | AP5: MVI | AQ5: MVI | AR5: DIST. | AS5: U/S | AT5: TOTTEN | AU5: UF&R | AV5: RAIN | AW5: MAX | AX5: MIN | AZ5: TOTAL | BA5: GRNDHOG | BB5: GRNDHOG
A6: NOV | B6: ELEV | D6: CHANGE | E6: CAP | F6: CFS | G6: RIVER | H6: CAN | I6: INFLOW | J6: INFLOW | K6: INFLOW | L6: INF/OTF | M6: TOT DIV | N6: WET | O6: UTE | P6: QUEST | Q6: MWC | R6: CORTEZ | T6: UTE | U6: F-BAY | V6: PINE | W6: LAT | X6: MVI | Y6: MVI | Z6: CALL | AA6: CALL | AB6: APR- | AC6: U/S EX | AD6: PROJ | AE6: CANAL | AF6: MVIC | AG6: PROJ | AH6: MCP | AI6: LEFT | AK6: OTF | AL6: OTF | AM6: OTF | AN6: FILL | AO6: STOCK | AP6: STORED | AQ6: STORED | AR6: CLASS | AS6: USERS | AT6: (FRESH | AU6: LEASE | AW6: TMP | AX6: TMP | AZ6: TUNNEL | BA6: DISCHARGE | BB6: CAPACITY
N7: LAND | O7: F&R | Q7: NON - | R7: NON - | S7: PROJ | T7: PROJ | U7: BAL | X7: WATER | Y7: IRRIG. | Z7: STOR | AA7: SPILLED | AB7: JUNE | AF7: 1.7 | AG7: 1.3 | AI7: 29007 | AP7: Apr - Jun | AQ7: EVAP | AR7: "B" | AS7: EXCH | AT7: WATER) | AU7: WATER | AZ7: Misc.
Q8: PROJ | R8: PROJ | X8: USED | Y8: WATER | AA8: OR | AB8: (DIV+
R9: 4.2 | Y9: USED | AA9: USED | AB9: CALL) | BB9: FP = 5394
C10: AC. Ft. | E10: AC FT | G10: CFS | H10: CFS | I10: CFS | J10: CFS | K10: CFS | L10: CFS | M10: CFS | N10: CFS | O10: CFS | P10: CFS | Q10: CFS | R10: CFS | S10: CFS | T10: CFS | U10: CFS | V10: CFS | W10: CFS | X10: 153400 | Y10: 150400 | AB10: 72000 | AC10: CFS | AD10: CFS | AE10: CFS | AF10: CFS | AG10: CFS | AH10: CFS | AI10: CFS | AJ10: CFS | AK10: CFS | AL10: CFS | AM10: CFS | AN10: CFS | AO10: CFS | AP10: CFS | AQ10: AC.FT. | AR10: CFS | AS10: CFS | AT10: CFS | AU10: CFS | AZ10: Outflow | BA10: CFS | BB10: AC FT
N11: 1.03 | O11: 1.05 | P11: 1.02 | Q11: 1.02 | R11: 1.04 | T11: 1.04 | X11: CFS | Y11: CFS | Z11: CFS | AA11: CFS | AB11: Ac. Ft. | AZ11: CFS
A12: SEASON BAL
A13: YTD | B13: 6869.22 | C13: 185740 | AI13: 4134.5492
A15: 1 | B15: 6869.17 | C15: 185608 | D15: =C15-C13 -> -132 | E15: =C15-152000 -> 33608 | F15: =D15/$D$2 -> -66.549029 | G15: 102 | H15: 0 | I15: =G15+H15 -> 102 | J15: =IF(L15>0,L15,0) -> 0 | K15: =I15+J15 -> 102 | L15: =F15-(I15-AK15) -> -24.799029 | M15: 4.25 | N15: 0 | O15: =0*1.05 -> 0 | P15: 0 | Q15: =1073500/325851/1.9835*1.02 -> 1.6941465 | R15: =(3.2*1.04)-T15 -> 2.7652248 | S15: 0 | T15: =(0.5105*1.06)*1.04 -> 0.5627752 | U15: =M15-(Q15+R15+S15+T15) -> -0.77214648 | V15: 100 | W15: 0 | X15: =M15-N15-O15-P15-Q15-R15-S15-T15-U15+V15+W15-AU15+AR15 -> 100 | Y15: =X15-AO15 -> 100 | AE15: 0 | AH15: 39.5 | AI15: =AI13-AH15 -> 4095.0492 | AK15: =N15+O15+P15+Q15+R15+S15+T15+U15+X15+AE15+AH15 -> 143.75 | AL15: =IF(L15<0,L15*-1,0) -> 24.799029 | AM15: =AK15+AL15 -> 168.54903 | AN15: =V15 -> 100 | AV15: 0 | AW15: 68 | AX15: 48 | AZ15: =SUM(N15,P15:U15) -> 4.25 | BA15: 0.2 | BB15: 15448
A16: =A15+1 -> 2 | B16: 6869.18 | C16: 185634 | D16: =C16-C15 -> 26 | E16: =C16-152000 -> 33634 | F16: =D16/$D$2 -> 13.108142 | G16: 110 | H16: 0 | I16: =G16+H16 -> 110 | J16: =IF(L16>0,L16,0) -> 46.948142 | K16: =I16+J16 -> 156.94814 | L16: =F16-(I16-AK16) -> 46.948142 | M16: 3.24 | N16: 0 | O16: =0*1.05 -> 0 | P16: 0 | Q16: =1014800/325851/1.9835*1.02 -> 1.6015089 | R16: =(2*1.04)-T16 -> 1.5172248 | S16: 0 | T16: =(0.5105*1.06)*1.04 -> 0.5627752 | U16: =M16-(Q16+R16+S16+T16) -> -0.44150894 | V16: 101 | W16: 0 | X16: =M16-N16-O16-P16-Q16-R16-S16-T16-U16+V16+W16-AU16+AR16 -> 101 | Y16: =X16-AO16 -> 101 | AE16: 0 | AH16: 39.6 | AI16: =AI15-AH16 -> 4055.4492 | AK16: =N16+O16+P16+Q16+R16+S16+T16+U16+X16+AE16+AH16 -> 143.84 | AL16: =IF(L16<0,L16*-1,0) -> 0 | AM16: =AK16+AL16 -> 143.84 | AN16: =V16 -> 101 | AV16: 0.26 | AW16: 58 | AX16: 36 | AZ16: =SUM(N16,P16:U16) -> 3.24 | BA16: 0.2 | BB16: 15456
A17: =A16+1 -> 3 | B17: 6869.1 | C17: 185423 | D17: =C17-C16 -> -211 | E17: =C17-152000 -> 33423 | F17: =D17/$D$2 -> -106.37762 | G17: 123 | H17: 0 | I17: =G17+H17 -> 123 | J17: =IF(L17>0,L17,0) -> 0 | K17: =I17+J17 -> 123 | L17: =F17-(I17-AK17) -> -47.657615 | M17: 3.22 | N17: 0 | O17: =2.08*1.05 -> 2.184 | P17: 0 | Q17: =1117000/325851/1.9835*1.02 -> 1.7627961 | R17: =(2.1*1.04)-T17 -> 1.6212248 | S17: 0 | T17: =(0.5105*1.06)*1.04 -> 0.5627752 | U17: =M17-(Q17+R17+S17+T17) -> -0.7267961 | V17: 139 | W17: 0 | X17: =M17-N17-O17-P17-Q17-R17-S17-T17-U17+V17+W17-AU17+AR17 -> 136.816 | Y17: =X17-AO17 -> 136.816 | AE17: 0 | AH17: 39.5 | AI17: =AI16-AH17 -> 4015.9492 | AK17: =N17+O17+P17+Q17+R17+S17+T17+U17+X17+AE17+AH17 -> 181.72 | AL17: =IF(L17<0,L17*-1,0) -> 47.657615 | AM17: =AK17+AL17 -> 229.37762 | AN17: =V17 -> 139 | AV17: 0.02 | AW17: 51 | AX17: 32 | AZ17: =SUM(N17,P17:U17) -> 3.22 | BA17: 0.2 | BB17: 15413
A18: =A17+1 -> 4 | B18: 6869 | C18: 185158 | D18: =C18-C17 -> -265 | E18: =C18-152000 -> 33158 | F18: =D18/$D$2 -> -133.60222 | G18: 105 | H18: 0 | I18: =G18+H18 -> 105 | J18: =IF(L18>0,L18,0) -> 0 | K18: =I18+J18 -> 105 | L18: =F18-(I18-AK18) -> -1.7822183 | M18: 3.12 | N18: 0 | O18: =5.44*1.05 -> 5.712 | P18: 0 | Q18: =852400/325851/1.9835*1.02 -> 1.345217 | R18: =(1.9*1.04)-T18 -> 1.4132248 | S18: 0 | T18: =(0.5105*1.06)*1.04 -> 0.5627752 | U18: =M18-(Q18+R18+S18+T18) -> -0.20121701 | V18: 203 | W18: 0 | X18: =M18-N18-O18-P18-Q18-R18-S18-T18-U18+V18+W18-AU18+AR18 -> 197.288 | Y18: =X18-AO18 -> 197.288 | AE18: 0 | AH18: 30.7 | AI18: =AI17-AH18 -> 3985.2492 | AK18: =N18+O18+P18+Q18+R18+S18+T18+U18+X18+AE18+AH18 -> 236.82 | AL18: =IF(L18<0,L18*-1,0) -> 1.7822183 | AM18: =AK18+AL18 -> 238.60222 | AN18: =V18 -> 203 | AV18: 0 | AW18: 58 | AX18: 29 | AZ18: =SUM(N18,P18:U18) -> 3.12 | BA18: 0.2 | BB18: 15389
A19: =A18+1 -> 5 | B19: 6868.86 | C19: 184793 | D19: =C19-C18 -> -365 | E19: =C19-152000 -> 32793 | F19: =D19/$D$2 -> -184.01815 | G19: 91 | H19: 0 | I19: =G19+H19 -> 91 | J19: =IF(L19>0,L19,0) -> 0 | K19: =I19+J19 -> 91 | L19: =F19-(I19-AK19) -> -46.29815 | M19: 3.22 | N19: 0 | O19: =7.52*1.05 -> 7.896 | P19: 0 | Q19: =917100/325851/1.9835*1.02 -> 1.4473235 | R19: =(2*1.04)-T19 -> 1.5172248 | S19: 0 | T19: =(0.5105*1.06)*1.04 -> 0.5627752 | U19: =M19-(Q19+R19+S19+T19) -> -0.30732346 | V19: 200 | W19: 0 | X19: =M19-N19-O19-P19-Q19-R19-S19-T19-U19+V19+W19-AU19+AR19 -> 192.104 | Y19: =X19-AO19 -> 192.104 | AE19: 0 | AH19: 25.5 | AI19: =AI18-AH19 -> 3959.7492 | AK19: =N19+O19+P19+Q19+R19+S19+T19+U19+X19+AE19+AH19 -> 228.72 | AL19: =IF(L19<0,L19*-1,0) -> 46.29815 | AM19: =AK19+AL19 -> 275.01815 | AN19: =V19 -> 200 | AV19: 0 | AW19: 65 | AX19: 27 | AZ19: =SUM(N19,P19:U19) -> 3.22 | BA19: 0.2 | BB19: 15444
A20: =A19+1 -> 6 | B20: 6868.74 | C20: 184480 | D20: =C20-C19 -> -313 | E20: =C20-152000 -> 32480 | F20: =D20/$D$2 -> -157.80187 | G20: 97 | H20: 0 | I20: =G20+H20 -> 97 | J20: =IF(L20>0,L20,0) -> 0 | K20: =I20+J20 -> 97 | L20: =F20-(I20-AK20) -> -26.261865 | M20: 3.04 | N20: 0 | O20: =8.07*1.05 -> 8.4735 | P20: 0 | Q20: =844800/325851/1.9835*1.02 -> 1.3332231 | R20: =(2*1.04)-T20 -> 1.5172248 | S20: 0 | T20: =(0.5105*1.06)*1.04 -> 0.5627752 | U20: =M20-(Q20+R20+S20+T20) -> -0.37322305 | V20: 200 | W20: 0 | X20: =M20-N20-O20-P20-Q20-R20-S20-T20-U20+V20+W20-AU20+AR20 -> 191.5265 | Y20: =X20-AO20 -> 191.5265 | AE20: 0 | AH20: 25.5 | AI20: =AI19-AH20 -> 3934.2492 | AK20: =N20+O20+P20+Q20+R20+S20+T20+U20+X20+AE20+AH20 -> 228.54 | AL20: =IF(L20<0,L20*-1,0) -> 26.261865 | AM20: =AK20+AL20 -> 254.80187 | AN20: =V20 -> 200 | AV20: 0 | AW20: 66 | AX20: 31 | AZ20: =SUM(N20,P20:U20) -> 3.04 | BA20: 0.2 | BB20: 15447
A21: =A20+1 -> 7 | B21: 6868.63 | C21: 184193 | D21: =C21-C20 -> -287 | E21: =C21-152000 -> 32193 | F21: =D21/$D$2 -> -144.69372 | G21: 98 | H21: 0 | I21: =G21+H21 -> 98 | J21: =IF(L21>0,L21,0) -> 0 | K21: =I21+J21 -> 98 | L21: =F21-(I21-AK21) -> -16.293723 | M21: 2.9 | N21: 0 | O21: =3.15*1.05 -> 3.3075 | P21: 0 | Q21: =962100/325851/1.9835*1.02 -> 1.5183403 | R21: =(2*1.04)-T21 -> 1.5231778 | S21: 0 | T21: =(0.5051*1.06)*1.04 -> 0.55682224 | U21: =M21-(Q21+R21+S21+T21) -> -0.69834031 | V21: 198 | W21: 0 | X21: =M21-N21-O21-P21-Q21-R21-S21-T21-U21+V21+W21-AU21+AR21 -> 194.6925 | Y21: =X21-AO21 -> 194.6925 | AE21: 0 | AH21: 25.5 | AI21: =AI20-AH21 -> 3908.7492 | AK21: =N21+O21+P21+Q21+R21+S21+T21+U21+X21+AE21+AH21 -> 226.4 | AL21: =IF(L21<0,L21*-1,0) -> 16.293723 | AM21: =AK21+AL21 -> 242.69372 | AN21: =V21 -> 198 | AV21: 0 | AW21: 68 | AX21: 32 | AZ21: =SUM(N21,P21:U21) -> 2.9 | BA21: 0.2 | BB21: 15421
A22: =A21+1 -> 8 | B22: 6868.51 | C22: 183880 | D22: =C22-C21 -> -313 | E22: =C22-152000 -> 31880 | F22: =D22/$D$2 -> -157.80187 | G22: 95 | H22: 0 | I22: =G22+H22 -> 95 | J22: =IF(L22>0,L22,0) -> 0 | K22: =I22+J22 -> 95 | L22: =F22-(I22-AK22) -> -25.401865 | M22: 2.9 | N22: 0 | O22: =0.058*1.05 -> 0.0609 | P22: 0 | Q22: =1158800/325851/1.9835*1.02 -> 1.8287629 | R22: =(2*1.04)-T22 -> 1.5231778 | S22: 0 | T22: =(0.5051*1.06)*1.04 -> 0.55682224 | U22: =M22-(Q22+R22+S22+T22) -> -1.0087629 | V22: 199 | W22: 0 | X22: =M22-N22-O22-P22-Q22-R22-S22-T22-U22+V22+W22-AU22+AR22 -> 198.9391 | Y22: =X22-AO22 -> 198.9391 | AE22: 0 | AH22: 25.5 | AI22: =AI21-AH22 -> 3883.2492 | AK22: =N22+O22+P22+Q22+R22+S22+T22+U22+X22+AE22+AH22 -> 227.4 | AL22: =IF(L22<0,L22*-1,0) -> 25.401865 | AM22: =AK22+AL22 -> 252.80187 | AN22: =V22 -> 199 | AV22: 0 | AW22: 69 | AX22: 35 | AZ22: =SUM(N22,P22:U22) -> 2.9 | BA22: 0.2 | BB22: 15458
A23: =A22+1 -> 9 | B23: 6868.4 | C23: 183593 | D23: =C23-C22 -> -287 | E23: =C23-152000 -> 31593 | F23: =D23/$D$2 -> -144.69372 | G23: 89 | H23: 0 | I23: =G23+H23 -> 89 | J23: =IF(L23>0,L23,0) -> 0 | K23: =I23+J23 -> 89 | L23: =F23-(I23-AK23) -> -6.1737232 | M23: 3.02 | N23: 0 | O23: =0.453*1.05 -> 0.47565 | P23: 0 | Q23: =999000/325851/1.9835*1.02 -> 1.5765741 | R23: =(2*1.04)-T23 -> 1.5231778 | S23: 0 | T23: =(0.5051*1.06)*1.04 -> 0.55682224 | U23: =M23-(Q23+R23+S23+T23) -> -0.63657413 | V23: 199 | W23: 0 | X23: =M23-N23-O23-P23-Q23-R23-S23-T23-U23+V23+W23-AU23+AR23 -> 198.52435 | Y23: =X23-AO23 -> 198.52435 | AE23: 0 | AH23: 25.5 | AI23: =AI22-AH23 -> 3857.7492 | AK23: =N23+O23+P23+Q23+R23+S23+T23+U23+X23+AE23+AH23 -> 227.52 | AL23: =IF(L23<0,L23*-1,0) -> 6.1737232 | AM23: =AK23+AL23 -> 233.69372 | AN23: =V23 -> 199 | AV23: 0 | AW23: 65 | AX23: 32 | AZ23: =SUM(N23,P23:U23) -> 3.02 | BA23: 0.2 | BB23: 15473
A24: =A23+1 -> 10 | B24: 6868.25 | C24: 183202 | D24: =C24-C23 -> -391 | E24: =C24-152000 -> 31202 | F24: =D24/$D$2 -> -197.12629 | G24: 88 | H24: 0 | I24: =G24+H24 -> 88 | J24: =IF(L24>0,L24,0) -> 0 | K24: =I24+J24 -> 88 | L24: =F24-(I24-AK24) -> -87.406292 | M24: 3.22 | N24: 0 | O24: =1.47*1.05 -> 1.5435 | P24: 0 | Q24: =913500/325851/1.9835*1.02 -> 1.4416421 | R24: =(2*1.04)-T24 -> 1.5231778 | S24: 0 | T24: =(0.5051*1.06)*1.04 -> 0.55682224 | U24: =M24-(Q24+R24+S24+T24) -> -0.30164211 | V24: 169 | W24: 0 | X24: =M24-N24-O24-P24-Q24-R24-S24-T24-U24+V24+W24-AU24+AR24 -> 167.4565 | Y24: =X24-AO24 -> 167.4565 | AE24: 0 | AH24: 25.5 | AI24: =AI23-AH24 -> 3832.2492 | AK24: =N24+O24+P24+Q24+R24+S24+T24+U24+X24+AE24+AH24 -> 197.72 | AL24: =IF(L24<0,L24*-1,0) -> 87.406292 | AM24: =AK24+AL24 -> 285.12629 | AN24: =V24 -> 169 | AV24: 0 | AW24: 65 | AX24: 29 | AZ24: =SUM(N24,P24:U24) -> 3.22 | BA24: 0.2 | BB24: 15465
A25: =A24+1 -> 11 | B25: 6868.24 | C25: 183176 | D25: =C25-C24 -> -26 | E25: =C25-152000 -> 31176 | F25: =D25/$D$2 -> -13.108142 | G25: 85 | H25: 0 | I25: =G25+H25 -> 85 | J25: =IF(L25>0,L25,0) -> 16.211858 | K25: =I25+J25 -> 101.21186 | L25: =F25-(I25-AK25) -> 16.211858 | M25: 3.22 | N25: 0 | O25: =2.27*1.05 -> 2.3835 | P25: 0 | Q25: =1121700/325851/1.9835*1.02 -> 1.7702134 | R25: =(2*1.04)-T25 -> 1.5231778 | S25: 0 | T25: =(0.5051*1.06)*1.04 -> 0.55682224 | U25: =M25-(Q25+R25+S25+T25) -> -0.63021342 | V25: 85.6 | W25: 0 | X25: =M25-N25-O25-P25-Q25-R25-S25-T25-U25+V25+W25-AU25+AR25 -> 83.2165 | Y25: =X25-AO25 -> 83.2165 | AE25: 0 | AH25: 25.5 | AI25: =AI24-AH25 -> 3806.7492 | AK25: =N25+O25+P25+Q25+R25+S25+T25+U25+X25+AE25+AH25 -> 114.32 | AL25: =IF(L25<0,L25*-1,0) -> 0 | AM25: =AK25+AL25 -> 114.32 | AN25: =V25 -> 85.6 | AV25: 0 | AW25: 60 | AX25: 24 | AZ25: =SUM(N25,P25:U25) -> 3.22 | BA25: 0.2 | BB25: 15464
A26: =A25+1 -> 12 | B26: 6868.21 | C26: 183098 | D26: =C26-C25 -> -78 | E26: =C26-152000 -> 31098 | F26: =D26/$D$2 -> -39.324427 | G26: 84 | H26: 0 | I26: =G26+H26 -> 84 | J26: =IF(L26>0,L26,0) -> 0 | K26: =I26+J26 -> 84 | L26: =F26-(I26-AK26) -> -9.0044265 | M26: 3.22 | N26: 0 | O26: =0*1.05 -> 0 | P26: 0 | Q26: =849400/325851/1.9835*1.02 -> 1.3404826 | R26: =(2*1.04)-T26 -> 1.5231778 | S26: 0 | T26: =(0.5051*1.06)*1.04 -> 0.55682224 | U26: =M26-(Q26+R26+S26+T26) -> -0.20048255 | V26: 85.6 | W26: 0 | X26: =M26-N26-O26-P26-Q26-R26-S26-T26-U26+V26+W26-AU26+AR26 -> 85.6 | Y26: =X26-AO26 -> 85.6 | AE26: 0 | AH26: 25.5 | AI26: =AI25-AH26 -> 3781.2492 | AK26: =N26+O26+P26+Q26+R26+S26+T26+U26+X26+AE26+AH26 -> 114.32 | AL26: =IF(L26<0,L26*-1,0) -> 9.0044265 | AM26: =AK26+AL26 -> 123.32443 | AN26: =V26 -> 85.6 | AV26: 0 | AW26: 56 | AX26: 35 | AZ26: =SUM(N26,P26:U26) -> 3.22 | BA26: 0.2 | BB26: 15463
A27: =A26+1 -> 13 | B27: 6868.16 | C27: 182967 | D27: =C27-C26 -> -131 | E27: =C27-152000 -> 30967 | F27: =D27/$D$2 -> -66.04487 | G27: 85 | H27: 0 | I27: =G27+H27 -> 85 | J27: =IF(L27>0,L27,0) -> 0 | K27: =I27+J27 -> 85 | L27: =F27-(I27-AK27) -> -43.92487 | M27: 3.22 | N27: 0 | O27: =0*1.05 -> 0 | P27: 0 | Q27: =874600/325851/1.9835*1.02 -> 1.380252 | R27: =(2*1.04)-T27 -> 1.5231778 | S27: 0 | T27: =(0.5051*1.06)*1.04 -> 0.55682224 | U27: =M27-(Q27+R27+S27+T27) -> -0.24025199 | V27: 78.4 | W27: 0 | X27: =M27-N27-O27-P27-Q27-R27-S27-T27-U27+V27+W27-AU27+AR27 -> 78.4 | Y27: =X27-AO27 -> 78.4 | AE27: 0 | AH27: 25.5 | AI27: =AI26-AH27 -> 3755.7492 | AK27: =N27+O27+P27+Q27+R27+S27+T27+U27+X27+AE27+AH27 -> 107.12 | AL27: =IF(L27<0,L27*-1,0) -> 43.92487 | AM27: =AK27+AL27 -> 151.04487 | AN27: =V27 -> 78.4 | AV27: 0 | AW27: 51 | AX27: 34 | AZ27: =SUM(N27,P27:U27) -> 3.22 | BA27: 0.2 | BB27: 15466
A28: =A27+1 -> 14 | B28: 6868.2 | C28: 183072 | D28: =C28-C27 -> 105 | E28: =C28-152000 -> 31072 | F28: =D28/$D$2 -> 52.936728 | G28: 93 | H28: 0 | I28: =G28+H28 -> 93 | J28: =IF(L28>0,L28,0) -> 63.966728 | K28: =I28+J28 -> 156.96673 | L28: =F28-(I28-AK28) -> 63.966728 | M28: 3.13 | N28: 0 | O28: =0*1.05 -> 0 | P28: 0 | Q28: =766400/325851/1.9835*1.02 -> 1.2094959 | R28: =(2*1.04)-T28 -> 1.5763134 | S28: 0 | T28: =(0.4569*1.06)*1.04 -> 0.50368656 | U28: =M28-(Q28+R28+S28+T28) -> -0.15949591 | V28: 75.1 | W28: 0 | X28: =M28-N28-O28-P28-Q28-R28-S28-T28-U28+V28+W28-AU28+AR28 -> 75.1 | Y28: =X28-AO28 -> 75.1 | AE28: 0 | AH28: 25.8 | AI28: =AI27-AH28 -> 3729.9492 | AK28: =N28+O28+P28+Q28+R28+S28+T28+U28+X28+AE28+AH28 -> 104.03 | AL28: =IF(L28<0,L28*-1,0) -> 0 | AM28: =AK28+AL28 -> 104.03 | AN28: =V28 -> 75.1 | AV28: 0.35 | AW28: 47 | AX28: 32 | AZ28: =SUM(N28,P28:U28) -> 3.13 | BA28: 0.2 | BB28: 15493
A29: =A28+1 -> 15 | B29: 6868.18 | C29: 183019 | D29: =C29-C28 -> -53 | E29: =C29-152000 -> 31019 | F29: =D29/$D$2 -> -26.720444 | G29: 101 | H29: 0 | I29: =G29+H29 -> 101 | J29: =IF(L29>0,L29,0) -> 0 | K29: =I29+J29 -> 101 | L29: =F29-(I29-AK29) -> -24.220444 | M29: 2.9 | N29: 0 | O29: =0*1.05 -> 0 | P29: 0 | Q29: =926500/325851/1.9835*1.02 -> 1.4621581 | R29: =(2*1.04)-T29 -> 1.5763134 | S29: 0 | T29: =(0.4569*1.06)*1.04 -> 0.50368656 | U29: =M29-(Q29+R29+S29+T29) -> -0.64215809 | V29: 75.1 | W29: 0 | X29: =M29-N29-O29-P29-Q29-R29-S29-T29-U29+V29+W29-AU29+AR29 -> 75.1 | Y29: =X29-AO29 -> 75.1 | AE29: 0 | AH29: 25.5 | AI29: =AI28-AH29 -> 3704.4492 | AK29: =N29+O29+P29+Q29+R29+S29+T29+U29+X29+AE29+AH29 -> 103.5 | AL29: =IF(L29<0,L29*-1,0) -> 24.220444 | AM29: =AK29+AL29 -> 127.72044 | AN29: =V29 -> 75.1 | AV29: 0.15 | AW29: 50 | AX29: 30 | AZ29: =SUM(N29,P29:U29) -> 2.9 | BA29: 0.2 | BB29: 15517
A30: =A29+1 -> 16 | B30: 6868.17 | C30: 182993 | D30: =C30-C29 -> -26 | E30: =C30-152000 -> 30993 | F30: =D30/$D$2 -> -13.108142 | G30: 96 | H30: 0 | I30: =G30+H30 -> 96 | J30: =IF(L30>0,L30,0) -> 0 | K30: =I30+J30 -> 96 | L30: =F30-(I30-AK30) -> -5.5081422 | M30: 2.9 | N30: 0 | O30: =0*1.05 -> 0 | P30: 0 | Q30: =920100/325851/1.9835*1.02 -> 1.4520579 | R30: =(1.9*1.04)-T30 -> 1.4723134 | S30: 0 | T30: =(0.4569*1.06)*1.04 -> 0.50368656 | U30: =M30-(Q30+R30+S30+T30) -> -0.52805792 | V30: 75.1 | W30: 0 | X30: =M30-N30-O30-P30-Q30-R30-S30-T30-U30+V30+W30-AU30+AR30 -> 75.1 | Y30: =X30-AO30 -> 75.1 | AE30: 0 | AH30: 25.6 | AI30: =AI29-AH30 -> 3678.8492 | AK30: =N30+O30+P30+Q30+R30+S30+T30+U30+X30+AE30+AH30 -> 103.6 | AL30: =IF(L30<0,L30*-1,0) -> 5.5081422 | AM30: =AK30+AL30 -> 109.10814 | AN30: =V30 -> 75.1 | AV30: 0 | AW30: 34 | AX30: 17 | AZ30: =SUM(N30,P30:U30) -> 2.9 | BA30: 0.2 | BB30: 15564
A31: =A30+1 -> 17 | B31: 6868.11 | C31: 182837 | D31: =C31-C30 -> -156 | E31: =C31-152000 -> 30837 | F31: =D31/$D$2 -> -78.648853 | G31: 74 | H31: 0 | I31: =G31+H31 -> 74 | J31: =IF(L31>0,L31,0) -> 0 | K31: =I31+J31 -> 74 | L31: =F31-(I31-AK31) -> -49.048853 | M31: 2.9 | N31: 0 | O31: =0*1.05 -> 0 | P31: 0 | Q31: =936700/325851/1.9835*1.02 -> 1.4782552 | R31: =(2*1.04)-T31 -> 1.5763134 | S31: 0 | T31: =(0.4569*1.06)*1.04 -> 0.50368656 | U31: =M31-(Q31+R31+S31+T31) -> -0.65825525 | V31: 75.1 | W31: 0 | X31: =M31-N31-O31-P31-Q31-R31-S31-T31-U31+V31+W31-AU31+AR31 -> 75.1 | Y31: =X31-AO31 -> 75.1 | AE31: 0 | AH31: 25.6 | AI31: =AI30-AH31 -> 3653.2492 | AK31: =N31+O31+P31+Q31+R31+S31+T31+U31+X31+AE31+AH31 -> 103.6 | AL31: =IF(L31<0,L31*-1,0) -> 49.048853 | AM31: =AK31+AL31 -> 152.64885 | AN31: =V31 -> 75.1 | AV31: 0 | AW31: 43 | AX31: 14 | AZ31: =SUM(N31,P31:U31) -> 2.9 | BA31: 0.2 | BB31: 15564
A32: =A31+1 -> 18 | B32: 6868.04 | C32: 182654 | D32: =C32-C31 -> -183 | E32: =C32-152000 -> 30654 | F32: =D32/$D$2 -> -92.261155 | G32: 79 | H32: 0 | I32: =G32+H32 -> 79 | J32: =IF(L32>0,L32,0) -> 0 | K32: =I32+J32 -> 79 | L32: =F32-(I32-AK32) -> -68.111155 | M32: 3.05 | N32: 0 | O32: =0*1.05 -> 0 | P32: 0 | Q32: =855000/325851/1.9835*1.02 -> 1.3493202 | R32: =(1.9*1.04)-T32 -> 1.4723134 | S32: 0 | T32: =(0.4569*1.06)*1.04 -> 0.50368656 | U32: =M32-(Q32+R32+S32+T32) -> -0.2753202 | V32: 74.6 | W32: 0 | X32: =M32-N32-O32-P32-Q32-R32-S32-T32-U32+V32+W32-AU32+AR32 -> 74.6 | Y32: =X32-AO32 -> 74.6 | AE32: 0 | AH32: 25.5 | AI32: =AI31-AH32 -> 3627.7492 | AK32: =N32+O32+P32+Q32+R32+S32+T32+U32+X32+AE32+AH32 -> 103.15 | AL32: =IF(L32<0,L32*-1,0) -> 68.111155 | AM32: =AK32+AL32 -> 171.26115 | AN32: =V32 -> 74.6 | AV32: 0 | AW32: 47 | AX32: 15 | AZ32: =SUM(N32,P32:U32) -> 3.05 | BA32: 0.2 | BB32: 15527
A33: =A32+1 -> 19 | B33: 6867.99 | C33: 182524 | D33: =C33-C32 -> -130 | E33: =C33-152000 -> 30524 | F33: =D33/$D$2 -> -65.540711 | G33: 95 | H33: 0 | I33: =G33+H33 -> 95 | J33: =IF(L33>0,L33,0) -> 0 | K33: =I33+J33 -> 95 | L33: =F33-(I33-AK33) -> -57.620711 | M33: 3.22 | N33: 0 | O33: =0*1.05 -> 0 | P33: 0 | Q33: =820800/325851/1.9835*1.02 -> 1.2953474 | R33: =(2*1.04)-T33 -> 1.5763134 | S33: 0 | T33: =(0.4569*1.06)*1.04 -> 0.50368656 | U33: =M33-(Q33+R33+S33+T33) -> -0.1553474 | V33: 74.2 | W33: 0 | X33: =M33-N33-O33-P33-Q33-R33-S33-T33-U33+V33+W33-AU33+AR33 -> 74.2 | Y33: =X33-AO33 -> 74.2 | AE33: 0 | AH33: 25.5 | AI33: =AI32-AH33 -> 3602.2492 | AK33: =N33+O33+P33+Q33+R33+S33+T33+U33+X33+AE33+AH33 -> 102.92 | AL33: =IF(L33<0,L33*-1,0) -> 57.620711 | AM33: =AK33+AL33 -> 160.54071 | AN33: =V33 -> 74.2 | AV33: 0 | AW33: 50 | AX33: 19 | AZ33: =SUM(N33,P33:U33) -> 3.22 | BA33: 0.2 | BB33: 15515
A34: =A33+1 -> 20 | B34: 6867.93 | C34: 182370 | D34: =C34-C33 -> -154 | E34: =C34-152000 -> 30370 | F34: =D34/$D$2 -> -77.640534 | G34: 97 | H34: 0 | I34: =G34+H34 -> 97 | J34: =IF(L34>0,L34,0) -> 0 | K34: =I34+J34 -> 97 | L34: =F34-(I34-AK34) -> -64.320534 | M34: 3.22 | N34: 0 | O34: =0*1.05 -> 0 | P34: 0 | Q34: =813900/325851/1.9835*1.02 -> 1.2844581 | R34: =(2*1.04)-T34 -> 1.5763134 | S34: 0 | T34: =(0.4569*1.06)*1.04 -> 0.50368656 | U34: =M34-(Q34+R34+S34+T34) -> -0.14445815 | V34: 81.6 | W34: 0 | X34: =M34-N34-O34-P34-Q34-R34-S34-T34-U34+V34+W34-AU34+AR34 -> 81.6 | Y34: =X34-AO34 -> 81.6 | AE34: 0 | AH34: 25.5 | AI34: =AI33-AH34 -> 3576.7492 | AK34: =N34+O34+P34+Q34+R34+S34+T34+U34+X34+AE34+AH34 -> 110.32 | AL34: =IF(L34<0,L34*-1,0) -> 64.320534 | AM34: =AK34+AL34 -> 174.64053 | AN34: =V34 -> 81.6 | AV34: 0 | AW34: 51 | AX34: 24 | AZ34: =SUM(N34,P34:U34) -> 3.22 | BA34: 0.2 | BB34: 15537
A35: =A34+1 -> 21 | B35: 6867.94 | C35: 182396 | D35: =C35-C34 -> 26 | E35: =C35-152000 -> 30396 | F35: =D35/$D$2 -> 13.108142 | G35: 104 | H35: 0 | I35: =G35+H35 -> 104 | J35: =IF(L35>0,L35,0) -> 7.4281422 | K35: =I35+J35 -> 111.42814 | L35: =F35-(I35-AK35) -> 7.4281422 | M35: 3.22 | N35: 0 | O35: =0*1.05 -> 0 | P35: 0 | Q35: =868800/325851/1.9835*1.02 -> 1.3710987 | R35: =(2*1.04)-T35 -> 1.6207402 | S35: 0 | T35: =(0.4166*1.06)*1.04 -> 0.45925984 | U35: =M35-(Q35+R35+S35+T35) -> -0.23109871 | V35: 69.6 | W35: 0 | X35: =M35-N35-O35-P35-Q35-R35-S35-T35-U35+V35+W35-AU35+AR35 -> 69.6 | Y35: =X35-AO35 -> 69.6 | AE35: 0 | AH35: 25.5 | AI35: =AI34-AH35 -> 3551.2492 | AK35: =N35+O35+P35+Q35+R35+S35+T35+U35+X35+AE35+AH35 -> 98.32 | AL35: =IF(L35<0,L35*-1,0) -> 0 | AM35: =AK35+AL35 -> 98.32 | AN35: =V35 -> 69.6 | AV35: 0 | AW35: 56 | AX35: 26 | AZ35: =SUM(N35,P35:U35) -> 3.22 | BA35: 0.2 | BB35: 15547
A36: =A35+1 -> 22 | B36: 6867.88 | C36: 182241 | D36: =C36-C35 -> -155 | E36: =C36-152000 -> 30241 | F36: =D36/$D$2 -> -78.144694 | G36: 98 | H36: 0 | I36: =G36+H36 -> 98 | J36: =IF(L36>0,L36,0) -> 0 | K36: =I36+J36 -> 98 | L36: =F36-(I36-AK36) -> -78.024694 | M36: 3.02 | N36: 0 | O36: =0*1.05 -> 0 | P36: 0 | Q36: =917000/325851/1.9835*1.02 -> 1.4471656 | R36: =(2*1.04)-T36 -> 1.6207402 | S36: 0 | T36: =(0.4166*1.06)*1.04 -> 0.45925984 | U36: =M36-(Q36+R36+S36+T36) -> -0.50716565 | V36: 69.6 | W36: 0 | X36: =M36-N36-O36-P36-Q36-R36-S36-T36-U36+V36+W36-AU36+AR36 -> 69.6 | Y36: =X36-AO36 -> 69.6 | AC36: 22.332094 | AE36: 0 | AH36: 25.5 | AI36: =AI35-AH36 -> 3525.7492 | AK36: =N36+O36+P36+Q36+R36+S36+T36+U36+X36+AE36+AH36 -> 98.12 | AL36: =IF(L36<0,L36*-1,0) -> 78.024694 | AM36: =AK36+AL36 -> 176.14469 | AN36: =V36 -> 69.6 | AV36: 0 | AW36: 53 | AX36: 26 | AZ36: =SUM(N36,P36:U36) -> 3.02 | BA36: 0.2 | BB36: 15533
A37: =A36+1 -> 23 | B37: 6867.9 | C37: 182293 | D37: =C37-C36 -> 52 | E37: =C37-152000 -> 30293 | F37: =D37/$D$2 -> 26.216284 | G37: 91 | H37: 0 | I37: =G37+H37 -> 91 | J37: =IF(L37>0,L37,0) -> 33.436284 | K37: =I37+J37 -> 124.43628 | L37: =F37-(I37-AK37) -> 33.436284 | M37: 3.12 | N37: 0 | O37: =0*1.05 -> 0 | P37: 0 | Q37: =898100/325851/1.9835*1.02 -> 1.4173386 | R37: =(2*1.04)-T37 -> 1.6207402 | S37: 0 | T37: =(0.4166*1.06)*1.04 -> 0.45925984 | U37: =M37-(Q37+R37+S37+T37) -> -0.37733857 | V37: 69.6 | W37: 0 | X37: =M37-N37-O37-P37-Q37-R37-S37-T37-U37+V37+W37-AU37+AR37 -> 69.6 | Y37: =X37-AO37 -> 69.6 | AC37: 21.361921 | AE37: 0 | AH37: 25.5 | AI37: =AI36-AH37 -> 3500.2492 | AK37: =N37+O37+P37+Q37+R37+S37+T37+U37+X37+AE37+AH37 -> 98.22 | AL37: =IF(L37<0,L37*-1,0) -> 0 | AM37: =AK37+AL37 -> 98.22 | AN37: =V37 -> 69.6 | AV37: 0.01 | AW37: 42 | AX37: 14 | AZ37: =SUM(N37,P37:U37) -> 3.12 | BA37: 0.2 | BB37: 15521
A38: =A37+1 -> 24 | B38: 6867.84 | C38: 182139 | D38: =C38-C37 -> -154 | E38: =C38-152000 -> 30139 | F38: =D38/$D$2 -> -77.640534 | G38: 73 | H38: 0 | I38: =G38+H38 -> 73 | J38: =IF(L38>0,L38,0) -> 0 | K38: =I38+J38 -> 73 | L38: =F38-(I38-AK38) -> -52.220534 | M38: 3.22 | N38: 0 | O38: =0*1.05 -> 0 | P38: 0 | Q38: =961100/325851/1.9835*1.02 -> 1.5167622 | R38: =(2*1.04)-T38 -> 1.6207402 | S38: 0 | T38: =(0.4166*1.06)*1.04 -> 0.45925984 | U38: =M38-(Q38+R38+S38+T38) -> -0.37676216 | V38: 69.6 | W38: 0 | X38: =M38-N38-O38-P38-Q38-R38-S38-T38-U38+V38+W38-AU38+AR38 -> 69.6 | Y38: =X38-AO38 -> 69.6 | AC38: 0 | AE38: 0 | AH38: 25.6 | AI38: =AI37-AH38 -> 3474.6492 | AK38: =N38+O38+P38+Q38+R38+S38+T38+U38+X38+AE38+AH38 -> 98.42 | AL38: =IF(L38<0,L38*-1,0) -> 52.220534 | AM38: =AK38+AL38 -> 150.64053 | AN38: =V38 -> 69.6 | AV38: 0 | AW38: 42 | AX38: 14 | AZ38: =SUM(N38,P38:U38) -> 3.22 | BA38: 0.2 | BB38: 15556
A39: =A38+1 -> 25 | B39: 6867.8 | C39: 182036 | D39: =C39-C38 -> -103 | E39: =C39-152000 -> 30036 | F39: =D39/$D$2 -> -51.928409 | G39: 88 | H39: 0 | I39: =G39+H39 -> 88 | J39: =IF(L39>0,L39,0) -> 0 | K39: =I39+J39 -> 88 | L39: =F39-(I39-AK39) -> -41.508409 | M39: 3.22 | N39: 0 | O39: =0*1.05 -> 0 | P39: 0 | Q39: =814000/325851/1.9835*1.02 -> 1.284616 | R39: =(2*1.04)-T39 -> 1.6207402 | S39: 0 | T39: =(0.4166*1.06)*1.04 -> 0.45925984 | U39: =M39-(Q39+R39+S39+T39) -> -0.14461596 | V39: 69.6 | W39: 0 | X39: =M39-N39-O39-P39-Q39-R39-S39-T39-U39+V39+W39-AU39+AR39 -> 69.6 | Y39: =X39-AO39 -> 69.6 | AC39: 12.494644 | AE39: 0 | AH39: 25.6 | AI39: =AI38-AH39 -> 3449.0492 | AK39: =N39+O39+P39+Q39+R39+S39+T39+U39+X39+AE39+AH39 -> 98.42 | AL39: =IF(L39<0,L39*-1,0) -> 41.508409 | AM39: =AK39+AL39 -> 139.92841 | AN39: =V39 -> 69.6 | AV39: 0 | AW39: 46 | AX39: 15 | AZ39: =SUM(N39,P39:U39) -> 3.22 | BA39: 0.2 | BB39: 15572
A40: =A39+1 -> 26 | B40: 6867.77 | C40: 181959 | D40: =C40-C39 -> -77 | E40: =C40-152000 -> 29959 | F40: =D40/$D$2 -> -38.820267 | G40: 102 | H40: 0 | I40: =G40+H40 -> 102 | J40: =IF(L40>0,L40,0) -> 0 | K40: =I40+J40 -> 102 | L40: =F40-(I40-AK40) -> -42.300267 | M40: 3.22 | N40: 0 | O40: =0*1.05 -> 0 | P40: 0 | Q40: =865900/325851/1.9835*1.04 -> 1.3933166 | R40: =(2*1.04)-T40 -> 1.6207402 | S40: 0 | T40: =(0.4166*1.06)*1.04 -> 0.45925984 | U40: =M40-(Q40+R40+S40+T40) -> -0.25331661 | V40: 69.6 | W40: 0 | X40: =M40-N40-O40-P40-Q40-R40-S40-T40-U40+V40+W40-AU40+AR40 -> 69.6 | Y40: =X40-AO40 -> 69.6 | AC40: 40.385943 | AE40: 0 | AH40: 25.7 | AI40: =AI39-AH40 -> 3423.3492 | AK40: =N40+O40+P40+Q40+R40+S40+T40+U40+X40+AE40+AH40 -> 98.52 | AL40: =IF(L40<0,L40*-1,0) -> 42.300267 | AM40: =AK40+AL40 -> 140.82027 | AN40: =V40 -> 69.6 | AV40: 0 | AW40: 58 | AX40: 28 | AZ40: =SUM(N40,P40:U40) -> 3.22 | BA40: 0.2 | BB40: 15579
A41: =A40+1 -> 27 | B41: 6867.75 | C41: 181907 | D41: =C41-C40 -> -52 | E41: =C41-152000 -> 29907 | F41: =D41/$D$2 -> -26.216284 | G41: 97 | H41: 0 | I41: =G41+H41 -> 97 | J41: =IF(L41>0,L41,0) -> 0 | K41: =I41+J41 -> 97 | L41: =F41-(I41-AK41) -> -24.756284 | M41: 2.96 | N41: 0 | O41: =0*1.05 -> 0 | P41: 0 | Q41: =945000/325851/1.9835*1.02 -> 1.4913539 | R41: =(2*1.04)-T41 -> 1.6207402 | S41: 0 | T41: =(0.4166*1.06)*1.04 -> 0.45925984 | U41: =M41-(Q41+R41+S41+T41) -> -0.61135391 | V41: 69.6 | W41: 0 | X41: =M41-N41-O41-P41-Q41-R41-S41-T41-U41+V41+W41-AU41+AR41 -> 69.6 | Y41: =X41-AO41 -> 69.6 | AC41: 31.287906 | AE41: 0 | AH41: 25.9 | AI41: =AI40-AH41 -> 3397.4492 | AK41: =N41+O41+P41+Q41+R41+S41+T41+U41+X41+AE41+AH41 -> 98.46 | AL41: =IF(L41<0,L41*-1,0) -> 24.756284 | AM41: =AK41+AL41 -> 123.21628 | AN41: =V41 -> 69.6 | AV41: 0 | AW41: 62 | AX41: 28 | AZ41: =SUM(N41,P41:U41) -> 2.96 | BA41: 0.2 | BB41: 15580
A42: =A41+1 -> 28 | B42: 6867.73 | C42: 181856 | D42: =C42-C41 -> -51 | E42: =C42-152000 -> 29856 | F42: =D42/$D$2 -> -25.712125 | G42: 87 | H42: 0 | I42: =G42+H42 -> 87 | J42: =IF(L42>0,L42,0) -> 0 | K42: =I42+J42 -> 87 | L42: =F42-(I42-AK42) -> -14.662125 | M42: 2.65 | N42: 0 | O42: =0*1.05 -> 0 | P42: 0 | Q42: =997900/325851/1.9835*1.02 -> 1.5748382 | R42: =(2*1.04)-T42 -> 1.5830381 | S42: 0 | T42: =(0.4508*1.06)*1.04 -> 0.49696192 | U42: =M42-(Q42+R42+S42+T42) -> -1.0048382 | V42: 69.6 | W42: 0 | X42: =M42-N42-O42-P42-Q42-R42-S42-T42-U42+V42+W42-AU42+AR42 -> 69.6 | Y42: =X42-AO42 -> 69.6 | AC42: 10.242124 | AE42: 0 | AH42: 25.8 | AI42: =AI41-AH42 -> 3371.6492 | AK42: =N42+O42+P42+Q42+R42+S42+T42+U42+X42+AE42+AH42 -> 98.05 | AL42: =IF(L42<0,L42*-1,0) -> 14.662125 | AM42: =AK42+AL42 -> 112.71213 | AN42: =V42 -> 69.6 | AV42: 0 | AW42: 65 | AX42: 29 | AZ42: =SUM(N42,P42:U42) -> 2.65 | BA42: 0.2 | BB42: 15584
...

Sheet DEC
K1: MCPHEE RESERVOIR INFLOW/OUTFLOW TABULATION
A2: AF/cfs CONVERT FACTOR | D2: 1.9835 | K2: DECEMBER "2014"
D4: RESERVOIR | I4: INFLOW | X4: OUTFLOW | AP4: ADJUSTMENTS | AW4: WEATHER
A5: DATE | B5: RESERV | C5: RESERV | D5: AC FT | E5: ACTIVE | F5: CONV TO | G5: DOLORES | H5: LOST | I5: RECORD | J5: CALC | K5: TOTAL | L5: CALC | M5: DOLORES TUNNEL | V5: LONE | W5: U | X5: TOTAL | Y5: TOTAL | Z5: MVI | AA5: MVI | AB5: MVI | AC5: TO EX & | AD5: MVI | AE5: DV CR | AF5: D/S SENIOR | AH5: BELOW | AI5: FISH | AJ5: SPILL | AK5: RECORD | AL5: CALC | AM5: TOTAL | AN5: NAR | AO5: MVI | AP5: MVI | AQ5: MVI | AR5: DIST. | AS5: U/S | AT5: TOTTEN | AU5: UF&R | AV5: RAIN | AW5: MAX | AX5: MIN | AZ5: TOTAL | BA5: GRNDHOG | BB5: GRNDHOG
A6: DEC | B6: ELEV | D6: CHANGE | E6: CAP | F6: CFS | G6: RIVER | H6: CAN | I6: INFLOW | J6: INFLOW | K6: INFLOW | L6: INF/OTF | M6: TOT DIV | N6: WET | O6: UTE | P6: QUEST | Q6: MWC | R6: CORTEZ | T6: UTE | U6: F-BAY | V6: PINE | W6: LAT | X6: MVI | Y6: MVI | Z6: CALL | AA6: CALL | AB6: APR- | AC6: U/S EX | AD6: PROJ | AE6: CANAL | AF6: MVIC | AG6: PROJ | AH6: MCP | AI6: LEFT | AK6: OTF | AL6: OTF | AM6: OTF | AN6: FILLL | AO6: STOCK | AP6: STORED | AQ6: STORED | AR6: CLASS | AS6: USERS | AT6: (FRESH | AU6: LEASE | AW6: TMP | AX6: TMP | AZ6: TUNNEL | BA6: DISCHARGE | BB6: CAPACITY
N7: LAND | O7: F&R | Q7: NON - | R7: NON - | S7: PROJ | T7: PROJ | U7: BAL | X7: WATER | Y7: IRRIG. | Z7: STOR | AA7: SPILLED | AB7: JUNE | AF7: 1.7 | AG7: 1.3 | AI7: 29007 | AP7: Apr - Jun | AQ7: EVAP | AR7: "B" | AS7: EXCH | AT7: WATER) | AU7: WATER | AZ7: Misc.
Q8: PROJ | R8: PROJ | X8: USED | Y8: WATER | AA8: OR | AB8: (DIV+
R9: 4.2 | Y9: USED | AA9: USED | AB9: CALL) | BB9: FP = 5394
C10: AC. Ft. | E10: AC FT | G10: CFS | H10: CFS | I10: CFS | J10: CFS | K10: CFS | L10: CFS | M10: CFS | N10: CFS | O10: CFS | P10: CFS | Q10: CFS | R10: CFS | S10: CFS | T10: CFS | U10: CFS | V10: CFS | W10: CFS | X10: 153400 | Y10: 150400 | AB10: 72000 | AC10: CFS | AD10: CFS | AE10: CFS | AF10: CFS | AG10: CFS | AH10: CFS | AI10: CFS | AJ10: CFS | AK10: CFS | AL10: CFS | AM10: CFS | AN10: CFS | AO10: CFS | AP10: CFS | AQ10: AC.FT. | AR10: CFS | AS10: CFS | AT10: CFS | AU10: CFS | AZ10: Outflow | BA10: CFS | BB10: AC FT
N11: 1.03 | O11: 1.05 | P11: 1.02 | Q11: 1.02 | R11: 1.04 | T11: 1.04 | X11: CFS | Y11: CFS | Z11: CFS | AA11: CFS | AB11: Ac. Ft. | AZ11: CFS
A12: SEASON BAL
A13: YTD | B13: =NOV!B44 -> 6867.69 | C13: =NOV!C44 -> 181753 | D13: =NOV!D53 -> -3987 | E13: =NOV!E53 -> 29753 | F13: =NOV!F52 -> -2010.0832 | G13: =NOV!G52 -> 2798 | H13: =NOV!H52 -> 0.62 | I13: =NOV!I52 -> 2798 | J13: =NOV!J52 -> 167.99115 | K13: =NOV!K52 -> 2965.9912 | L13: =NOV!L52 -> -715.82319 | M13: =NOV!M52 -> 94.76 | ... Y13: =NOV!Y52 -> 3152.3634 | AC13: =NOV!AC52 -> 157.63259 | AH13: =NOV!AH52 -> 813.1 | AI13: =NOV!AI52 -> 3321.4492 | AK13: =NOV!AK52 -> 4092.26 | AL13: =NOV!AL52 -> 883.81434 | AM13: =NOV!AM52 -> 4976.0743 | AN13: =NOV!AN52 -> 3184.4 | AO13: =NOV!AO52 -> 0 | AV13: =NOV!AV52 -> 0.79 | AZ13: =NOV!AZ52 -> 94.76 | BA13: =NOV!BA52 -> 6
A15: 1 | B15: 6867.65 | C15: 181650 | D15: =C15-C13 -> -103 | E15: =C15-152000 -> 29650 | F15: =D15/$D$2 -> -51.928409 | G15: 83 | H15: 0 | I15: =G15+H15 -> 83 | J15: =IF(L15>0,L15,0) -> 0 | K15: =I15+J15 -> 83 | L15: =F15-(I15-AK15) -> -37.168409 | M15: 3.16 | N15: 0 | O15: =0*1.05 -> 0 | P15: 0 | Q15: =841300/325851/1.9835*1.02 -> 1.3276995 | R15: =(2*1.04)-T15 -> 1.5785182 | S15: 0 | T15: =(0.4549*1.06)*1.04 -> 0.50148176 | U15: =M15-(Q15+R15+S15+T15) -> -0.24769952 | V15: 69.6 | W15: 0 | X15: =M15-N15-P15-O15-Q15-R15-S15-T15-U15+V15+W15 -> 69.6 | Y15: =X15-AO15 -> 69.6 | AC15: 7.4937822 | AE15: 0 | AH15: 25 | AI15: =AI13-AH15 -> 3296.4492 | AK15: =N15+O15+P15+Q15+R15+S15+T15+U15+X15+AE15+AH15 -> 97.76 | AL15: =IF(L15<0,L15*-1,0) -> 37.168409 | AM15: =AK15+AL15 -> 134.92841 | AN15: =V15 -> 69.6 | AV15: 0 | AW15: 54 | AX15: 25 | AZ15: =SUM(N15,P15:U15) -> 3.16 | BA15: 0.2 | BB15: 15586
A16: =A15+1 -> 2 | B16: 6867.63 | C16: 181599 | D16: =C16-C15 -> -51 | E16: =C16-152000 -> 29599 | F16: =D16/$D$2 -> -25.712125 | G16: 77 | H16: 0 | I16: =G16+H16 -> 77 | J16: =IF(L16>0,L16,0) -> 0 | K16: =I16+J16 -> 77 | L16: =F16-(I16-AK16) -> -5.092125 | M16: 3.22 | N16: 0 | O16: =0*1.05 -> 0 | P16: 0 | Q16: =809100/325851/1.9835*1.02 -> 1.276883 | R16: =(1.8*1.04)-T16 -> 1.3705182 | S16: 0 | T16: =(0.4549*1.06)*1.04 -> 0.50148176 | U16: =M16-(Q16+R16+S16+T16) -> 0.071116985 | V16: 69.5 | W16: 0 | X16: =M16-N16-P16-O16-Q16-R16-S16-T16-U16+V16+W16 -> 69.5 | Y16: =X16-AO16 -> 69.5 | AC16: 0 | AE16: 0 | AH16: 24.9 | AI16: =AI15-AH16 -> 3271.5492 | AK16: =N16+O16+P16+Q16+R16+S16+T16+U16+X16+AE16+AH16 -> 97.62 | AL16: =IF(L16<0,L16*-1,0) -> 5.092125 | AM16: =AK16+AL16 -> 102.71213 | AN16: =V16 -> 69.5 | AV16: 0.01 | AW16: 50 | AX16: 29 | AZ16: =SUM(N16,P16:U16) -> 3.22 | BA16: 0.2 | BB16: 15585
A17: =A16+1 -> 3 | B17: 6867.62 | C17: 181573 | D17: =C17-C16 -> -26 | E17: =C17-152000 -> 29573 | F17: =D17/$D$2 -> -13.108142 | G17: 81 | H17: 0 | I17: =G17+H17 -> 81 | J17: =IF(L17>0,L17,0) -> 3.5518578 | K17: =I17+J17 -> 84.551858 | L17: =F17-(I17-AK17) -> 3.5518578 | M17: 3.16 | N17: 0 | O17: =0*1.05 -> 0 | P17: 0 | Q17: =904200/325851/1.9835*1.02 -> 1.4269653 | R17: =(1.9*1.04)-T17 -> 1.4745182 | S17: 0 | T17: =(0.4549*1.06)*1.04 -> 0.50148176 | U17: =M17-(Q17+R17+S17+T17) -> -0.2429653 | V17: 69.5 | W17: 0 | X17: =M17-N17-P17-O17-Q17-R17-S17-T17-U17+V17+W17 -> 69.5 | Y17: =X17-AO17 -> 69.5 | AC17: 1.5985165 | AE17: 0 | AH17: 25 | AI17: =AI16-AH17 -> 3246.5492 | AK17: =N17+O17+P17+Q17+R17+S17+T17+U17+X17+AE17+AH17 -> 97.66 | AL17: =IF(L17<0,L17*-1,0) -> 0 | AM17: =AK17+AL17 -> 97.66 | AN17: =V17 -> 69.5 | AV17: 0 | AW17: 53 | AX17: 28 | AZ17: =SUM(N17,P17:U17) -> 3.16 | BA17: 0.2 | BB17: 15591
A18: =A17+1 -> 4 | B18: 6867.6 | C18: 181521 | D18: =C18-C17 -> -52 | E18: =C18-152000 -> 29521 | F18: =D18/$D$2 -> -26.216284 | G18: 84 | H18: 0 | I18: =G18+H18 -> 84 | J18: =IF(L18>0,L18,0) -> 0 | K18: =I18+J18 -> 84 | L18: =F18-(I18-AK18) -> -12.396284 | M18: 3.22 | N18: 0 | O18: =0*1.05 -> 0 | P18: 0 | Q18: =804900/325851/1.9835*1.02 -> 1.2702548 | R18: =(2*1.04)-T18 -> 1.5785182 | S18: 0 | T18: =(0.4549*1.06)*1.04 -> 0.50148176 | U18: =M18-(Q18+R18+S18+T18) -> -0.13025478 | V18: 69.6 | W18: 0 | X18: =M18-N18-P18-O18-Q18-R18-S18-T18-U18+V18+W18 -> 69.6 | Y18: =X18-AO18 -> 69.6 | AC18: 6.551227 | AE18: 0 | AH18: 25 | AI18: =AI17-AH18 -> 3221.5492 | AK18: =N18+O18+P18+Q18+R18+S18+T18+U18+X18+AE18+AH18 -> 97.82 | AL18: =IF(L18<0,L18*-1,0) -> 12.396284 | AM18: =AK18+AL18 -> 110.21628 | AN18: =V18 -> 69.6 | AV18: 0.11 | AW18: 47 | AX18: 37 | AZ18: =SUM(N18,P18:U18) -> 3.22 | BA18: 0.2 | BB18: 15600
A19: =A18+1 -> 5 | B19: 6867.6 | C19: 181521 | D19: =C19-C18 -> 0 | E19: =C19-152000 -> 29521 | F19: =D19/$D$2 -> 0 | G19: 84 | H19: 0 | I19: =G19+H19 -> 84 | J19: =IF(L19>0,L19,0) -> 13.72 | K19: =I19+J19 -> 97.72 | L19: =F19-(I19-AK19) -> 13.72 | M19: 3.22 | N19: 0 | O19: =0*1.05 -> 0 | P19: 0 | Q19: =801500/325851/1.9835*1.02 -> 1.2648891 | R19: =(2*1.04)-T19 -> 1.6126926 | S19: 0 | T19: =(0.4239*1.06)*1.04 -> 0.46730736 | U19: =M19-(Q19+R19+S19+T19) -> -0.12488906 | V19: 69.6 | W19: 0 | X19: =M19-N19-P19-O19-Q19-R19-S19-T19-U19+V19+W19 -> 69.6 | Y19: =X19-AO19 -> 69.6 | AC19: 3.5224183 | AE19: 0 | AH19: 24.9 | AI19: =AI18-AH19 -> 3196.6492 | AK19: =N19+O19+P19+Q19+R19+S19+T19+U19+X19+AE19+AH19 -> 97.72 | AL19: =IF(L19<0,L19*-1,0) -> 0 | AM19: =AK19+AL19 -> 97.72 | AN19: =V19 -> 69.6 | AV19: 0.01 | AW19: 51 | AX19: 33 | AZ19: =SUM(N19,P19:U19) -> 3.22 | BA19: 0.2 | BB19: 15610
A20: =A19+1 -> 6 | B20: 6867.58 | C20: 181470 | D20: =C20-C19 -> -51 | E20: =C20-152000 -> 29470 | F20: =D20/$D$2 -> -25.712125 | G20: 80 | H20: 0 | I20: =G20+H20 -> 80 | J20: =IF(L20>0,L20,0) -> 0 | K20: =I20+J20 -> 80 | L20: =F20-(I20-AK20) -> -8.192125 | M20: 3.22 | N20: 0 | O20: =0*1.05 -> 0 | P20: 0 | Q20: =800200/325851/1.9835*1.02 -> 1.2628375 | R20: =(2*1.04)-T20 -> 1.6126926 | S20: 0 | T20: =(0.4239*1.06)*1.04 -> 0.46730736 | U20: =M20-(Q20+R20+S20+T20) -> -0.12283746 | V20: 69.3 | W20: 0 | X20: =M20-N20-P20-O20-Q20-R20-S20-T20-U20+V20+W20 -> 69.3 | Y20: =X20-AO20 -> 69.3 | AC20: 0 | AE20: 0 | AH20: 25 | AI20: =AI19-AH20 -> 3171.6492 | AK20: =N20+O20+P20+Q20+R20+S20+T20+U20+X20+AE20+AH20 -> 97.52 | AL20: =IF(L20<0,L20*-1,0) -> 8.192125 | AM20: =AK20+AL20 -> 105.71213 | AN20: =V20 -> 69.3 | AV20: 0 | AW20: 52 | AX20: 32 | AZ20: =SUM(N20,P20:U20) -> 3.22 | BA20: 0.2 | BB20: 15618
A21: =A20+1 -> 7 | B21: 6867.55 | C21: 181393 | D21: =C21-C20 -> -77 | E21: =C21-152000 -> 29393 | F21: =D21/$D$2 -> -38.820267 | G21: 72 | H21: 0 | I21: =G21+H21 -> 72 | J21: =IF(L21>0,L21,0) -> 0 | K21: =I21+J21 -> 72 | L21: =F21-(I21-AK21) -> -14.060267 | M21: 2.76 | N21: 0 | O21: =0*1.05 -> 0 | P21: 0 | Q21: =983800/325851/1.9835*1.02 -> 1.5525862 | R21: =(1.9*1.04)-T21 -> 1.5086926 | S21: 0 | T21: =(0.4239*1.06)*1.04 -> 0.46730736 | U21: =M21-(Q21+R21+S21+T21) -> -0.76858622 | V21: 69 | W21: 0 | X21: =M21-N21-P21-O21-Q21-R21-S21-T21-U21+V21+W21 -> 69 | Y21: =X21-AO21 -> 69 | AC21: 0 | AE21: 0 | AH21: 25 | AI21: =AI20-AH21 -> 3146.6492 | AK21: =N21+O21+P21+Q21+R21+S21+T21+U21+X21+AE21+AH21 -> 96.76 | AL21: =IF(L21<0,L21*-1,0) -> 14.060267 | AM21: =AK21+AL21 -> 110.82027 | AN21: =V21 -> 69 | AV21: 0 | AW21: 56 | AX21: 28 | AZ21: =SUM(N21,P21:U21) -> 2.76 | BA21: 0.2 | BB21: 15635
A22: =A21+1 -> 8 | B22: 6867.52 | C22: 181316 | D22: =C22-C21 -> -77 | E22: =C22-152000 -> 29316 | F22: =D22/$D$2 -> -38.820267 | G22: 65 | H22: 0 | I22: =G22+H22 -> 65 | J22: =IF(L22>0,L22,0) -> 0 | K22: =I22+J22 -> 65 | L22: =F22-(I22-AK22) -> -7.1602672 | M22: 2.76 | N22: 0 | O22: =0*1.05 -> 0 | P22: 0 | Q22: =778900/325851/1.9835*1.02 -> 1.2292228 | R22: =(2*1.04)-T22 -> 1.6126926 | S22: 0 | T22: =(0.4239*1.06)*1.04 -> 0.46730736 | U22: =M22-(Q22+R22+S22+T22) -> -0.54922282 | V22: 68.8 | W22: 0 | X22: =M22-N22-P22-O22-Q22-R22-S22-T22-U22+V22+W22 -> 68.8 | Y22: =X22-AO22 -> 68.8 | AC22: 0 | AE22: 0 | AH22: 25.1 | AI22: =AI21-AH22 -> 3121.5492 | AK22: =N22+O22+P22+Q22+R22+S22+T22+U22+X22+AE22+AH22 -> 96.66 | AL22: =IF(L22<0,L22*-1,0) -> 7.1602672 | AM22: =AK22+AL22 -> 103.82027 | AN22: =V22 -> 68.8 | AV22: 0 | AW22: 59 | AX22: 28 | AZ22: =SUM(N22,P22:U22) -> 2.76 | BA22: 0.2 | BB22: 15765
A23: =A22+1 -> 9 | B23: 6867.47 | C23: 181187 | D23: =C23-C22 -> -129 | E23: =C23-152000 -> 29187 | F23: =D23/$D$2 -> -65.036552 | G23: 64 | H23: 0 | I23: =G23+H23 -> 64 | J23: =IF(L23>0,L23,0) -> 0 | K23: =I23+J23 -> 64 | L23: =F23-(I23-AK23) -> -31.556552 | M23: 3.58 | N23: 0 | O23: =0*1.05 -> 0 | P23: 0 | Q23: =836800/325851/1.9835*1.02 -> 1.3205978 | R23: =(1.9*1.04)-T23 -> 1.5086926 | S23: 0 | T23: =(0.4239*1.06)*1.04 -> 0.46730736 | U23: =M23-(Q23+R23+S23+T23) -> 0.28340217 | V23: 68.7 | W23: 0 | X23: =M23-N23-P23-O23-Q23-R23-S23-T23-U23+V23+W23 -> 68.7 | Y23: =X23-AO23 -> 68.7 | AC23: 0 | AE23: 0 | AH23: 25.2 | AI23: =AI22-AH23 -> 3096.3492 | AK23: =N23+O23+P23+Q23+R23+S23+T23+U23+X23+AE23+AH23 -> 97.48 | AL23: =IF(L23<0,L23*-1,0) -> 31.556552 | AM23: =AK23+AL23 -> 129.03655 | AN23: =V23 -> 68.7 | AV23: 0 | AW23: 58 | AX23: 26 | AZ23: =SUM(N23,P23:U23) -> 3.58 | BA23: 0.2 | BB23: 15808
A24: =A23+1 -> 10 | B24: 6867.4 | C24: 181007 | D24: =C24-C23 -> -180 | E24: =C24-152000 -> 29007 | F24: =D24/$D$2 -> -90.748677 | G24: 65 | H24: 0 | I24: =G24+H24 -> 65 | J24: =IF(L24>0,L24,0) -> 0 | K24: =I24+J24 -> 65 | L24: =F24-(I24-AK24) -> -58.778677 | M24: 3.07 | N24: 0 | O24: =0*1.05 -> 0 | P24: 0 | Q24: =823200/325851/1.9835*1.02 -> 1.299135 | R24: =(1.8*1.04)-T24 -> 1.4046926 | S24: 0 | T24: =(0.4239*1.06)*1.04 -> 0.46730736 | U24: =M24-(Q24+R24+S24+T24) -> -0.10113496 | V24: 68.7 | W24: 0 | X24: =M24-N24-P24-O24-Q24-R24-S24-T24-U24+V24+W24 -> 68.7 | Y24: =X24-AO24 -> 68.7 | AC24: 0 | AE24: 0 | AH24: 25.2 | AI24: =AI23-AH24 -> 3071.1492 | AK24: =N24+O24+P24+Q24+R24+S24+T24+U24+X24+AE24+AH24 -> 96.97 | AL24: =IF(L24<0,L24*-1,0) -> 58.778677 | AM24: =AK24+AL24 -> 155.74868 | AN24: =V24 -> 68.7 | AV24: 0 | AW24: 55 | AX24: 26 | AZ24: =SUM(N24,P24:U24) -> 3.07 | BA24: 0.2 | BB24: 15863
A25: =A24+1 -> 11 | B25: 6867.36 | C25: 180904 | D25: =C25-C24 -> -103 | E25: =C25-152000 -> 28904 | F25: =D25/$D$2 -> -51.928409 | G25: 68 | H25: 0 | I25: =G25+H25 -> 68 | J25: =IF(L25>0,L25,0) -> 0 | K25: =I25+J25 -> 68 | L25: =F25-(I25-AK25) -> -23.028409 | M25: 2.9 | N25: 0 | O25: =0*1.05 -> 0 | P25: 0 | Q25: =823400/325851/1.9835*1.02 -> 1.2994506 | R25: =(2*1.04)-T25 -> 1.6126926 | S25: 0 | T25: =(0.4239*1.06)*1.04 -> 0.46730736 | U25: =M25-(Q25+R25+S25+T25) -> -0.47945059 | V25: 68.7 | W25: 0 | X25: =M25-N25-P25-O25-Q25-R25-S25-T25-U25+V25+W25 -> 68.7 | Y25: =X25-AO25 -> 68.7 | AC25: 0 | AE25: 0 | AH25: 25.3 | AI25: =AI24-AH25 -> 3045.8492 | AK25: =N25+O25+P25+Q25+R25+S25+T25+U25+X25+AE25+AH25 -> 96.9 | AL25: =IF(L25<0,L25*-1,0) -> 23.028409 | AM25: =AK25+AL25 -> 119.92841 | AN25: =V25 -> 68.7 | AV25: 0 | AW25: 58 | AX25: 27 | AZ25: =SUM(N25,P25:U25) -> 2.9 | BA25: 0.2 | BB25: 15860
A26: =A25+1 -> 12 | B26: 6867.35 | C26: 180879 | D26: =C26-C25 -> -25 | E26: =C26-152000 -> 28879 | F26: =D26/$D$2 -> -12.603983 | G26: 71 | H26: 0 | I26: =G26+H26 -> 71 | J26: =IF(L26>0,L26,0) -> 13.576017 | K26: =I26+J26 -> 84.576017 | L26: =F26-(I26-AK26) -> 13.576017 | M26: 3.18 | N26: 0 | O26: =0*1.05 -> 0 | P26: 0 | Q26: =801900/325851/1.9835*1.02 -> 1.2655203 | R26: =(2*1.04)-T26 -> 1.619748 | S26: 0 | T26: =(0.4175*1.06)*1.04 -> 0.460252 | U26: =M26-(Q26+R26+S26+T26) -> -0.16552032 | V26: 68.7 | W26: 0 | X26: =M26-N26-P26-O26-Q26-R26-S26-T26-U26+V26+W26 -> 68.7 | Y26: =X26-AO26 -> 68.7 | AC26: 0 | AE26: 0 | AH26: 25.3 | AI26: =AI25-AH26 -> 3020.5492 | AK26: =N26+O26+P26+Q26+R26+S26+T26+U26+X26+AE26+AH26 -> 97.18 | AL26: =IF(L26<0,L26*-1,0) -> 0 | AM26: =AK26+AL26 -> 97.18 | AN26: =V26 -> 68.7 | AV26: 0 | AW26: 61 | AX26: 30 | AZ26: =SUM(N26,P26:U26) -> 3.18 | BA26: 0.2 | BB26: 15741
A27: =A26+1 -> 13 | B27: 6867.36 | C27: 180904 | D27: =C27-C26 -> 25 | E27: =C27-152000 -> 28904 | F27: =D27/$D$2 -> 12.603983 | G27: 73 | H27: 0 | I27: =G27+H27 -> 73 | J27: =IF(L27>0,L27,0) -> 36.693983 | K27: =I27+J27 -> 109.69398 | L27: =F27-(I27-AK27) -> 36.693983 | M27: 2.99 | N27: 0 | O27: =0*1.05 -> 0 | P27: 0 | Q27: =777000/325851/1.9835*1.02 -> 1.2262243 | R27: =(2*1.04)-T27 -> 1.619748 | S27: 0 | T27: =(0.4175*1.06)*1.04 -> 0.460252 | U27: =M27-(Q27+R27+S27+T27) -> -0.31622433 | V27: 68.7 | W27: 0 | X27: =M27-N27-P27-O27-Q27-R27-S27-T27-U27+V27+W27 -> 68.7 | Y27: =X27-AO27 -> 68.7 | AC27: 0 | AE27: 0 | AH27: 25.4 | AI27: =AI26-AH27 -> 2995.1492 | AK27: =N27+O27+P27+Q27+R27+S27+T27+U27+X27+AE27+AH27 -> 97.09 | AL27: =IF(L27<0,L27*-1,0) -> 0 | AM27: =AK27+AL27 -> 97.09 | AN27: =V27 -> 68.7 | AV27: 0.26 | AW27: 52 | AX27: 25 | AZ27: =SUM(N27,P27:U27) -> 2.99 | BA27: 0.2 | BB27: 15730
A28: =A27+1 -> 14 | B28: 6867.36 | C28: 180904 | D28: =C28-C27 -> 0 | E28: =C28-152000 -> 28904 | F28: =D28/$D$2 -> 0 | G28: 69 | H28: 0 | I28: =G28+H28 -> 69 | J28: =IF(L28>0,L28,0) -> 27.56 | K28: =I28+J28 -> 96.56 | L28: =F28-(I28-AK28) -> 27.56 | M28: 2.36 | N28: 0 | O28: =0*1.05 -> 0 | P28: 0 | Q28: =944000/325851/1.9835*1.02 -> 1.4897758 | R28: =(2*1.04)-T28 -> 1.619748 | S28: 0 | T28: =(0.4175*1.06)*1.04 -> 0.460252 | U28: =M28-(Q28+R28+S28+T28) -> -1.2097758 | V28: 68.7 | W28: 0 | X28: =M28-N28-P28-O28-Q28-R28-S28-T28-U28+V28+W28 -> 68.7 | Y28: =X28-AO28 -> 68.7 | AC28: 0 | AE28: 0 | AH28: 25.5 | AI28: =AI27-AH28 -> 2969.6492 | AK28: =N28+O28+P28+Q28+R28+S28+T28+U28+X28+AE28+AH28 -> 96.56 | AL28: =IF(L28<0,L28*-1,0) -> 0 | AM28: =AK28+AL28 -> 96.56 | AN28: =V28 -> 68.7 | AV28: 0.11 | AW28: 37 | AX28: 18 | AZ28: =SUM(N28,P28:U28) -> 2.36 | BA28: 0.2 | BB28: 15763
A29: =A28+1 -> 15 | B29: 6867.33 | C29: 180827 | D29: =C29-C28 -> -77 | E29: =C29-152000 -> 28827 | F29: =D29/$D$2 -> -38.820267 | G29: 63 | H29: 0 | I29: =G29+H29 -> 63 | J29: =IF(L29>0,L29,0) -> 0 | K29: =I29+J29 -> 63 | L29: =F29-(I29-AK29) -> -41.970267 | M29: 3.55 | N29: 0 | O29: =0*1.05 -> 0 | P29: 0 | Q29: =747300/325851/1.9835*1.02 -> 1.1793532 | R29: =(2.1*1.04)-T29 -> 1.723748 | S29: 0 | T29: =(0.4175*1.06)*1.04 -> 0.460252 | U29: =M29-(Q29+R29+S29+T29) -> 0.1866468 | V29: 30.8 | W29: 0 | X29: =M29-N29-P29-O29-Q29-R29-S29-T29-U29+V29+W29 -> 30.8 | Y29: =X29-AO29 -> 30.8 | AC29: 26.296899 | AE29: 0 | AH29: 25.5 | AI29: =AI28-AH29 -> 2944.1492 | AK29: =N29+O29+P29+Q29+R29+S29+T29+U29+X29+AE29+AH29 -> 59.85 | AL29: =IF(L29<0,L29*-1,0) -> 41.970267 | AM29: =AK29+AL29 -> 101.82027 | AN29: =V29 -> 30.8 | AV29: 0.01 | AW29: 41 | AX29: 15 | AZ29: =SUM(N29,P29:U29) -> 3.55 | BA29: 0.2 | BB29: 15794
A30: =A29+1 -> 16 | B30: 6867.33 | C30: 180827 | D30: =C30-C29 -> 0 | E30: =C30-152000 -> 28827 | F30: =D30/$D$2 -> 0 | G30: 66 | H30: 0 | I30: =G30+H30 -> 66 | J30: =IF(L30>0,L30,0) -> 0 | K30: =I30+J30 -> 66 | L30: =F30-(I30-AK30) -> -35.89 | M30: 2.92 | N30: 0 | O30: =0*1.05 -> 0 | P30: 0 | Q30: =856600/325851/1.9835*1.02 -> 1.3518452 | R30: =(2.6*1.04)-T30 -> 2.243748 | S30: 0 | T30: =(0.4175*1.06)*1.04 -> 0.460252 | U30: =M30-(Q30+R30+S30+T30) -> -1.1358452 | V30: 1.69 | W30: 0 | X30: =M30-N30-P30-O30-Q30-R30-S30-T30-U30+V30+W30 -> 1.69 | Y30: =X30-AO30 -> 1.69 | AC30: 57.714407 | AE30: 0 | AH30: 25.5 | AI30: =AI29-AH30 -> 2918.6492 | AK30: =N30+O30+P30+Q30+R30+S30+T30+U30+X30+AE30+AH30 -> 30.11 | AL30: =IF(L30<0,L30*-1,0) -> 35.89 | AM30: =AK30+AL30 -> 66 | AN30: =V30 -> 1.69 | AV30: 0 | AW30: 48 | AX30: 23 | AZ30: =SUM(N30,P30:U30) -> 2.92 | BA30: 0.2 | BB30: 15851
A31: =A30+1 -> 17 | B31: 6867.39 | C31: 180982 | D31: =C31-C30 -> 155 | E31: =C31-152000 -> 28982 | F31: =D31/$D$2 -> 78.144694 | G31: 64 | H31: 0.399 | I31: =G31+H31 -> 64.399 | J31: =IF(L31>0,L31,0) -> 42.125694 | K31: =I31+J31 -> 106.52469 | L31: =F31-(I31-AK31) -> 42.125694 | M31: 2.88 | N31: 0 | O31: =0*1.05 -> 0 | P31: 0 | Q31: =822600/325851/1.9835*1.02 -> 1.2981881 | R31: =(1.2*1.04)-T31 -> 0.787748 | S31: 0 | T31: =(0.4175*1.06)*1.04 -> 0.460252 | U31: =M31-(Q31+R31+S31+T31) -> 0.33381193 | V31: 0 | W31: 0 | X31: =M31-N31-P31-O31-Q31-R31-S31-T31-U31+V31+W31 -> 0 | Y31: =X31-AO31 -> 0 | AC31: 58.914064 | AE31: 0 | AH31: 25.5 | AI31: =AI30-AH31 -> 2893.1492 | AK31: =N31+O31+P31+Q31+R31+S31+T31+U31+X31+AE31+AH31 -> 28.38 | AL31: =IF(L31<0,L31*-1,0) -> 0 | AM31: =AK31+AL31 -> 28.38 | AN31: =V31 -> 0 | AV31: 0.17 | AW31: 42 | AX31: 28 | AZ31: =SUM(N31,P31:U31) -> 2.88 | BA31: 0.2 | BB31: 15870
A32: =A31+1 -> 18 | B32: 6867.45 | C32: 181136 | D32: =C32-C31 -> 154 | E32: =C32-152000 -> 29136 | F32: =D32/$D$2 -> 77.640534 | G32: 63 | H32: 1.21 | I32: =G32+H32 -> 64.21 | J32: =IF(L32>0,L32,0) -> 42.470534 | K32: =I32+J32 -> 106.68053 | L32: =F32-(I32-AK32) -> 42.470534 | M32: 3.54 | N32: 0 | O32: =0*1.05 -> 0 | P32: 0 | Q32: =871100/325851/1.9835*1.02 -> 1.3747285 | R32: =(2*1.04)-T32 -> 1.619748 | S32: 0 | T32: =(0.4175*1.06)*1.04 -> 0.460252 | U32: =M32-(Q32+R32+S32+T32) -> 0.085271543 | V32: 0 | W32: 0 | X32: =M32-N32-P32-O32-Q32-R32-S32-T32-U32+V32+W32 -> 0 | Y32: =X32-AO32 -> 0 | AC32: 57.005524 | AE32: 0 | AH32: 25.5 | AI32: =AI31-AH32 -> 2867.6492 | AK32: =N32+O32+P32+Q32+R32+S32+T32+U32+X32+AE32+AH32 -> 29.04 | AL32: =IF(L32<0,L32*-1,0) -> 0 | AM32: =AK32+AL32 -> 29.04 | AN32: =V32 -> 0 | AV32: 0.05 | AW32: 39 | AX32: 19 | AZ32: =SUM(N32,P32:U32) -> 3.54 | BA32: 0.2 | BB32: 15891
A33: =A32+1 -> 19 | B33: 6867.42 | C33: 181059 | D33: =C33-C32 -> -77 | E33: =C33-152000 -> 29059 | F33: =D33/$D$2 -> -38.820267 | G33: 63 | H33: 0.99 | I33: =G33+H33 -> 63.99 | J33: =IF(L33>0,L33,0) -> 0 | K33: =I33+J33 -> 63.99 | L33: =F33-(I33-AK33) -> -74.090267 | M33: 3.22 | N33: 0 | O33: =0*1.05 -> 0 | P33: 0 | Q33: =809900/325851/1.9835*1.02 -> 1.2781455 | R33: =(2*1.04)-T33 -> 1.586676 | S33: 0 | T33: =(0.4475*1.06)*1.04 -> 0.493324 | U33: =M33-(Q33+R33+S33+T33) -> -0.13814554 | V33: 0 | W33: 0 | X33: =M33-N33-P33-O33-Q33-R33-S33-T33-U33+V33+W33 -> 0 | Y33: =X33-AO33 -> 0 | AC33: 57.135178 | AE33: 0 | AH33: 25.5 | AI33: =AI32-AH33 -> 2842.1492 | AK33: =N33+O33+P33+Q33+R33+S33+T33+U33+X33+AE33+AH33 -> 28.72 | AL33: =IF(L33<0,L33*-1,0) -> 74.090267 | AM33: =AK33+AL33 -> 102.81027 | AN33: =V33 -> 0 | AV33: 0.01 | AW33: 42 | AX33: 15 | AZ33: =SUM(N33,P33:U33) -> 3.22 | BA33: 0.2 | BB33: 15900
A34: =A33+1 -> 20 | B34: 6867.41 | C34: 181033 | D34: =C34-C33 -> -26 | E34: =C34-152000 -> 29033 | F34: =D34/$D$2 -> -13.108142 | G34: 63 | H34: 1.09 | I34: =G34+H34 -> 64.09 | J34: =IF(L34>0,L34,0) -> 0 | K34: =I34+J34 -> 64.09 | L34: =F34-(I34-AK34) -> -48.768142 | M34: 2.93 | N34: 0 | O34: =0*1.05 -> 0 | P34: 0 | Q34: =817700/325851/1.9835*1.02 -> 1.2904551 | R34: =(2*1.04)-T34 -> 1.586676 | S34: 0 | T34: =(0.4475*1.06)*1.04 -> 0.493324 | U34: =M34-(Q34+R34+S34+T34) -> -0.44045512 | V34: 0 | W34: 0 | X34: =M34-N34-P34-O34-Q34-R34-S34-T34-U34+V34+W34 -> 0 | Y34: =X34-AO34 -> 0 | AC34: 57.122869 | AE34: 0 | AH34: 25.5 | AI34: =AI33-AH34 -> 2816.6492 | AK34: =N34+O34+P34+Q34+R34+S34+T34+U34+X34+AE34+AH34 -> 28.43 | AL34: =IF(L34<0,L34*-1,0) -> 48.768142 | AM34: =AK34+AL34 -> 77.198142 | AN34: =V34 -> 0 | AV34: 0 | AW34: 41 | AX34: 20 | AZ34: =SUM(N34,P34:U34) -> 2.93 | BA34: 0.2 | BB34: 15914
A35: =A34+1 -> 21 | B35: 6867.43 | C35: 181084 | D35: =C35-C34 -> 51 | E35: =C35-152000 -> 29084 | F35: =D35/$D$2 -> 25.712125 | G35: 62 | H35: 1.3 | I35: =G35+H35 -> 63.3 | J35: =IF(L35>0,L35,0) -> 0 | K35: =I35+J35 -> 63.3 | L35: =F35-(I35-AK35) -> -9.357875 | M35: 2.73 | N35: 0 | O35: =0*1.05 -> 0 | P35: 0 | Q35: =1036600/325851/1.9835*1.02 -> 1.6359127 | R35: =(1.9*1.04)-T35 -> 1.482676 | S35: 0 | T35: =(0.4475*1.06)*1.04 -> 0.493324 | U35: =M35-(Q35+R35+S35+T35) -> -0.88191266 | V35: 0 | W35: 0 | X35: =M35-N35-P35-O35-Q35-R35-S35-T35-U35+V35+W35 -> 0 | Y35: =X35-AO35 -> 0 | AC35: 55.881411 | AE35: 0 | AH35: 25.5 | AI35: =AI34-AH35 -> 2791.1492 | AK35: =N35+O35+P35+Q35+R35+S35+T35+U35+X35+AE35+AH35 -> 28.23 | AL35: =IF(L35<0,L35*-1,0) -> 9.357875 | AM35: =AK35+AL35 -> 37.587875 | AN35: =V35 -> 0 | AV35: 0 | AW35: 44 | AX35: 23 | AZ35: =SUM(N35,P35:U35) -> 2.73 | BA35: 0.2 | BB35: 15917
A36: =A35+1 -> 22 | B36: 6867.52 | C36: 181316 | D36: =C36-C35 -> 232 | E36: =C36-152000 -> 29316 | F36: =D36/$D$2 -> 116.96496 | G36: 61 | H36: 1.53 | I36: =G36+H36 -> 62.53 | J36: =IF(L36>0,L36,0) -> 82.834961 | K36: =I36+J36 -> 145.36496 | L36: =F36-(I36-AK36) -> 82.834961 | M36: 2.9 | N36: 0 | O36: =0*1.05 -> 0 | P36: 0 | Q36: =717600/325851/1.9835*1.02 -> 1.1324821 | R36: =(2*1.04)-T36 -> 1.586676 | S36: 0 | T36: =(0.4475*1.06)*1.04 -> 0.493324 | U36: =M36-(Q36+R36+S36+T36) -> -0.31248208 | V36: 0 | W36: 0 | X36: =M36-N36-P36-O36-Q36-R36-S36-T36-U36+V36+W36 -> 0 | Y36: =X36-AO36 -> 0 | AC36: 55.280842 | AE36: 0 | AH36: 25.5 | AI36: =AI35-AH36 -> 2765.6492 | AK36: =N36+O36+P36+Q36+R36+S36+T36+U36+X36+AE36+AH36 -> 28.4 | AL36: =IF(L36<0,L36*-1,0) -> 0 | AM36: =AK36+AL36 -> 28.4 | AN36: =V36 -> 0 | AV36: 0.02 | AW36: 48 | AX36: 26 | AZ36: =SUM(N36,P36:U36) -> 2.9 | BA36: 0.2 | BB36: 15908
A37: =A36+1 -> 23 | B37: 6867.52 | C37: 181316 | D37: =C37-C36 -> 0 | E37: =C37-152000 -> 29316 | F37: =D37/$D$2 -> 0 | G37: 60 | H37: 1.44 | I37: =G37+H37 -> 61.44 | J37: =IF(L37>0,L37,0) -> 0 | K37: =I37+J37 -> 61.44 | L37: =F37-(I37-AK37) -> -33.04 | M37: 2.9 | N37: 0 | O37: =0*1.05 -> 0 | P37: 0 | Q37: =797500/325851/1.9835*1.02 -> 1.2585764 | R37: =(2*1.04)-T37 -> 1.586676 | S37: 0 | T37: =(0.4475*1.06)*1.04 -> 0.493324 | U37: =M37-(Q37+R37+S37+T37) -> -0.43857645 | V37: 0 | W37: 0 | X37: =M37-N37-P37-O37-Q37-R37-S37-T37-U37+V37+W37 -> 0 | Y37: =X37-AO37 -> 0 | AC37: 54.154748 | AE37: 0 | AH37: 25.5 | AI37: =AI36-AH37 -> 2740.1492 | AK37: =N37+O37+P37+Q37+R37+S37+T37+U37+X37+AE37+AH37 -> 28.4 | AL37: =IF(L37<0,L37*-1,0) -> 33.04 | AM37: =AK37+AL37 -> 61.44 | AN37: =V37 -> 0 | AV37: 0 | AW37: 35 | AX37: 19 | AZ37: =SUM(N37,P37:U37) -> 2.9 | BA37: 0.2 | BB37: 15925
A38: =A37+1 -> 24 | B38: 6867.5 | C38: 181264 | D38: =C38-C37 -> -52 | E38: =C38-152000 -> 29264 | F38: =D38/$D$2 -> -26.216284 | G38: 61 | H38: 1.09 | I38: =G38+H38 -> 62.09 | J38: =IF(L38>0,L38,0) -> 0 | K38: =I38+J38 -> 62.09 | L38: =F38-(I38-AK38) -> -59.606284 | M38: 3.2 | N38: 0 | O38: =0*1.05 -> 0 | P38: 0 | Q38: =1028300/325851/1.9835*1.02 -> 1.622814 | R38: =(2*1.04)-T38 -> 1.586676 | S38: 0 | T38: =(0.4475*1.06)*1.04 -> 0.493324 | U38: =M38-(Q38+R38+S38+T38) -> -0.502814 | V38: 0 | W38: 0 | X38: =M38-N38-P38-O38-Q38-R38-S38-T38-U38+V38+W38 -> 0 | Y38: =X38-AO38 -> 0 | AC38: 54.79051 | AE38: 0 | AH38: 25.5 | AI38: =AI37-AH38 -> 2714.6492 | AK38: =N38+O38+P38+Q38+R38+S38+T38+U38+X38+AE38+AH38 -> 28.7 | AL38: =IF(L38<0,L38*-1,0) -> 59.606284 | AM38: =AK38+AL38 -> 88.306284 | AN38: =V38 -> 0 | AV38: 0 | AW38: 42 | AX38: 12 | AZ38: =SUM(N38,P38:U38) -> 3.2 | BA38: 0.2 | BB38: 16039
A39: =A38+1 -> 25 | B39: 6867.53 | C39: 181341 | D39: =C39-C38 -> 77 | E39: =C39-152000 -> 29341 | F39: =D39/$D$2 -> 38.820267 | G39: 62 | H39: 1.38 | I39: =G39+H39 -> 63.38 | J39: =IF(L39>0,L39,0) -> 4.4902672 | K39: =I39+J39 -> 67.870267 | L39: =F39-(I39-AK39) -> 4.4902672 | M39: 3.55 | N39: 0 | O39: =0*1.05 -> 0 | P39: 0 | Q39: =850700/325851/1.9835*1.02 -> 1.3425341 | R39: =(2*1.04)-T39 -> 1.586676 | S39: 0 | T39: =(0.4475*1.06)*1.04 -> 0.493324 | U39: =M39-(Q39+R39+S39+T39) -> 0.12746585 | V39: 0 | W39: 0 | X39: =M39-N39-P39-O39-Q39-R39-S39-T39-U39+V39+W39 -> 0 | Y39: =X39-AO39 -> 0 | AC39: 56.07079 | AE39: 0 | AH39: 25.5 | AI39: =AI38-AH39 -> 2689.1492 | AK39: =N39+O39+P39+Q39+R39+S39+T39+U39+X39+AE39+AH39 -> 29.05 | AL39: =IF(L39<0,L39*-1,0) -> 0 | AM39: =AK39+AL39 -> 29.05 | AN39: =V39 -> 0 | AV39: 0 | AW39: 38 | AX39: 13 | AZ39: =SUM(N39,P39:U39) -> 3.55 | BA39: 0.2 | BB39: 16122
A40: =A39+1 -> 26 | B40: 6867.55 | C40: 181393 | D40: =C40-C39 -> 52 | E40: =C40-152000 -> 29393 | F40: =D40/$D$2 -> 26.216284 | G40: 62 | H40: 1.56 | I40: =G40+H40 -> 63.56 | J40: =IF(L40>0,L40,0) -> 0 | K40: =I40+J40 -> 63.56 | L40: =F40-(I40-AK40) -> -9.1737157 | M40: 2.67 | N40: 0 | O40: =0*1.05 -> 0 | P40: 0 | Q40: =895200/325851/1.9835*1.02 -> 1.4127619 | R40: =(2*1.04)-T40 -> 1.4279304 | S40: 0 | T40: =(0.5915*1.06)*1.04 -> 0.6520696 | U40: =M40-(Q40+R40+S40+T40) -> -0.82276193 | V40: 0 | W40: 0 | X40: =M40-N40-P40-O40-Q40-R40-S40-T40-U40+V40+W40 -> 0 | Y40: =X40-AO40 -> 0 | AC40: 56.159308 | AE40: 0 | AH40: 25.5 | AI40: =AI39-AH40 -> 2663.6492 | AK40: =N40+O40+P40+Q40+R40+S40+T40+U40+X40+AE40+AH40 -> 28.17 | AL40: =IF(L40<0,L40*-1,0) -> 9.1737157 | AM40: =AK40+AL40 -> 37.343716 | AN40: =V40 -> 0 | AV40: 0.02 | AW40: 34 | AX40: 11 | AZ40: =SUM(N40,P40:U40) -> 2.67 | BA40: 0.2 | BB40: 16089
A41: =A40+1 -> 27 | B41: 6867.54 | C41: 181367 | D41: =C41-C40 -> -26 | E41: =C41-152000 -> 29367 | F41: =D41/$D$2 -> -13.108142 | G41: 60 | H41: 1.38 | I41: =G41+H41 -> 61.38 | J41: =IF(L41>0,L41,0) -> 0 | K41: =I41+J41 -> 61.38 | L41: =F41-(I41-AK41) -> -45.398142 | M41: 3.59 | N41: 0 | O41: =0*1.05 -> 0 | P41: 0 | Q41: =879400/325851/1.9835*1.02 -> 1.3878271 | R41: =(2*1.04)-T41 -> 1.4279304 | S41: 0 | T41: =(0.5915*1.06)*1.04 -> 0.6520696 | U41: =M41-(Q41+R41+S41+T41) -> 0.12217288 | V41: 0 | W41: 0 | X41: =M41-N41-P41-O41-Q41-R41-S41-T41-U41+V41+W41 -> 0 | Y41: =X41-AO41 -> 0 | AC41: 54.184242 | AE41: 0 | AH41: 25.5 | AI41: =AI40-AH41 -> 2638.1492 | AK41: =N41+O41+P41+Q41+R41+S41+T41+U41+X41+AE41+AH41 -> 29.09 | AL41: =IF(L41<0,L41*-1,0) -> 45.398142 | AM41: =AK41+AL41 -> 74.488142 | AN41: =V41 -> 0 | AV41: 0 | AW41: 33 | AX41: 2 | AZ41: =SUM(N41,P41:U41) -> 3.59 | BA41: 0.2 | BB41: 16113
A42: =A41+1 -> 28 | B42: 6867.54 | C42: 181367 | D42: =C42-C41 -> 0 | E42: =C42-152000 -> 29367 | F42: =D42/$D$2 -> 0 | G42: 59 | H42: 1.5 | I42: =G42+H42 -> 60.5 | J42: =IF(L42>0,L42,0) -> 0 | K42: =I42+J42 -> 60.5 | L42: =F42-(I42-AK42) -> -32.13 | M42: 2.87 | N42: 0 | O42: =0*1.05 -> 0 | P42: 0 | Q42: =984400/325851/1.9835*1.02 -> 1.5535331 | R42: =(2*1.04)-T42 -> 1.4279304 | S42: 0 | T42: =(0.5915*1.06)*1.04 -> 0.6520696 | U42: =M42-(Q42+R42+S42+T42) -> -0.76353311 | V42: 0 | W42: 0 | X42: =M42-N42-P42-O42-Q42-R42-S42-T42-U42+V42+W42 -> 0 | Y42: =X42-AO42 -> 0 | AC42: 53.018536 | AE42: 0 | AH42: 25.5 | AI42: =AI41-AH42 -> 2612.6492 | AK42: =N42+O42+P42+Q42+R42+S42+T42+U42+X42+AE42+AH42 -> 28.37 | AL42: =IF(L42<0,L42*-1,0) -> 32.13 | AM42: =AK42+AL42 -> 60.5 | AN42: =V42 -> 0 | AV42: 0 | AW42: 35 | AX42: 7 | AZ42: =SUM(N42,P42:U42) -> 2.87 | BA42: 0.2 | BB42: 16015
...

Sheet JAN
K1: MCPHEE RESERVOIR INFLOW/OUTFLOW TABULATION
A2: AF/cfs CONVERT FACTOR | D2: 1.9835 | K2: JANUARY "2015"
D4: RESERVOIR | I4: INFLOW | X4: OUTFLOW | AP4: ADJUSTMENTS | AW4: WEATHER
A5: DATE | B5: RESERV | C5: RESERV | D5: AC FT | E5: ACTIVE | F5: CONV TO | G5: DOLORES | H5: LOST | I5: RECORD | J5: CALC | K5: TOTAL | L5: CALC | M5: DOLORES TUNNEL | V5: LONE | W5: U | X5: TOTAL | Y5: TOTAL | Z5: MVI | AA5: MVI | AB5: MVI | AC5: TO EX & | AD5: MVI | AE5: DV CR | AF5: D/S SENIOR | AH5: BELOW | AI5: FISH | AJ5: SPILL | AK5: RECORD | AL5: CALC | AM5: TOTAL | AN5: NAR | AO5: MVI | AP5: MVI | AQ5: MVI | AR5: DIST. | AS5: U/S | AT5: TOTTEN | AU5: UF&R | AV5: RAIN | AW5: MAX | AX5: MIN | AZ5: TOTAL | BA5: GRNDHOG | BB5: GRNDHOG
A6: JAN | B6: ELEV | D6: CHANGE | E6: CAP | F6: CFS | G6: RIVER | H6: CAN | I6: INFLOW | J6: INFLOW | K6: INFLOW | L6: INF/OTF | M6: TOT DIV | N6: WET | O6: UTE | P6: QUEST | Q6: MWC | R6: CORTEZ | T6: UTE | U6: F-BAY | V6: PINE | W6: LAT | X6: MVI | Y6: MVI | Z6: CALL | AA6: CALL | AB6: APR- | AC6: U/S EX | AD6: PROJ | AE6: CANAL | AF6: MVIC | AG6: PROJ | AH6: MCP | AI6: LEFT | AK6: OTF | AL6: OTF | AM6: OTF | AN6: FILL | AO6: STOCK | AP6: STORED | AQ6: STORED | AR6: CLASS | AS6: USERS | AT6: (FRESH | AU6: LEASE | AW6: TMP | AX6: TMP | AZ6: TUNNEL | BA6: DISCHARGE | BB6: CAPACITY
N7: LAND | O7: F&R | Q7: NON - | R7: NON - | S7: PROJ | T7: PROJ | U7: BAL | X7: WATER | Y7: IRRIG. | Z7: STOR | AA7: SPILLED | AB7: JUNE | AF7: 1.7 | AG7: 1.3 | AI7: 29007 | AP7: Apr - Jun | AQ7: EVAP | AR7: "B" | AS7: EXCH | AT7: WATER) | AU7: WATER | AZ7: Misc.
Q8: PROJ | R8: PROJ | X8: USED | Y8: WATER | AA8: OR | AB8: (DIV+
R9: 4.2 | Y9: USED | AA9: USED | AB9: CALL) | BB9: FP = 5394
C10: AC. Ft. | E10: AC FT | G10: CFS | H10: CFS | I10: CFS | J10: CFS | K10: CFS | L10: CFS | M10: CFS | N10: CFS | O10: CFS | P10: CFS | Q10: CFS | R10: CFS | S10: CFS | T10: CFS | U10: CFS | V10: CFS | W10: CFS | X10: 153400 | Y10: 150400 | AB10: 72000 | AC10: CFS | AD10: CFS | AE10: CFS | AF10: CFS | AG10: CFS | AH10: CFS | AI10: CFS | AJ10: CFS | AK10: CFS | AL10: CFS | AM10: CFS | AN10: CFS | AO10: CFS | AP10: CFS | AQ10: AC.FT. | AR10: CFS | AS10: CFS | AT10: CFS | AU10: CFS | AZ10: Outflow | BA10: CFS | BB10: AC FT
N11: 1.03 | O11: 1.05 | P11: 1.02 | Q11: 1.02 | R11: 1.04 | T11: 1.04 | X11: CFS | Y11: CFS | Z11: CFS | AA11: CFS | AB11: Ac. Ft. | AZ11: CFS
A12: SEASON BAL
A13: YTD | B13: =DEC!B45 -> 6867.57 | C13: =DEC!C45 -> 181444 | D13: =DEC!D54 -> -4296 | E13: =DEC!E54 -> 29444 | F13: =DEC!F53 -> -2165.8684 | G13: =DEC!G53 -> 4877 | H13: =DEC!H53 -> 19.949 | I13: =DEC!I53 -> 4896.329 | J13: =DEC!J53 -> 443.22474 | K13: =DEC!K53 -> 5339.5537 | L13: =DEC!L53 -> -1089.0174 | M13: =DEC!M53 -> 190.79 | ... Y13: =DEC!Y53 -> 4151.9534 | AC13: =DEC!AC53 -> 1087.2311 | AH13: =DEC!AH53 -> 1598.4 | AI13: =DEC!AI53 -> 2536.1492 | AK13: =DEC!AK53 -> 5973.18 | AL13: =DEC!AL53 -> 1532.2422 | AM13: =DEC!AM53 -> 7505.4222 | AN13: =DEC!AN53 -> 4183.99 | AO13: =DEC!AO53 -> 0 | AV13: =DEC!AV53 -> 1.57 | AZ13: =DEC!AZ53 -> 190.79 | BA13: =DEC!BA53 -> 12.2
