Workbook

Sheet NOV
K1: MCPHEE RESERVOIR INFLOW/OUTFLOW TABULATION
A2: AF/cfs CONVERT FACTOR | D2: 1.9835 | K2: NOVEMBER "2019"
D4: RESERVOIR | I4: INFLOW | X4: OUTFLOW | AQ4: ADJUSTMENTS | AX4: WEATHER
A5: DATE | B5: RESERV | C5: RESERV | D5: AC FT | E5: ACTIVE | F5: CONV TO | G5: DOLORES | H5: LOST | I5: RECORD | J5: CALC | K5: TOTAL | L5: CALC | M5: DOLORES TUNNEL | V5: LONE | W5: U | X5: TOTAL | Y5: TOTAL | Z5: MVI | AA5: MVI | AB5: MVI | AC5: TO EX & | AD5: MVI | AE5: DV CR | AF5: D/S SENIOR | AH5: BELOW | AI5: FISH | AJ5: SPILL | AK5: RECORD | AL5: CALC | AM5: TOTAL | AN5: NAR | AO5: NARR | AP5: MVI | AQ5: MVI | AR5: MVI | AS5: DIST. | AT5: U/S | AU5: TOTTEN | AV5: UF&R | AW5: RAIN | AX5: MAX | AY5: MIN | BA5: TOTAL | BB5: GRNDHOG | BC5: GRNDHOG | BF5: RESERV | BH5: BELOW | BI5: BELOW
A6: NOV | B6: ELEV | D6: CHANGE | E6: CAP | F6: CFS | G6: RIVER | H6: CAN | I6: INFLOW | J6: INFLOW | K6: INFLOW | L6: INF/OTF | M6: TOT DIV | N6: WET | O6: UTE | P6: QUEST | Q6: MWC | R6: CORTEZ | T6: UTE | U6: F-BAY | V6: PINE | W6: LAT | X6: MVI | Y6: MVI | Z6: CALL | AA6: CALL | AB6: APR- | AC6: U/S EX | AD6: PROJ | AE6: CANAL | AF6: MVIC | AG6: PROJ | AH6: MCP | AI6: LEFT | AK6: OTF | AL6: OTF | AM6: OTF | AN6: FILL | AO6: FILL | AP6: STOCK | AQ6: STORED | AR6: STORED | AS6: CLASS | AT6: USERS | AU6: (FRESH | AV6: LEASE | AX6: TMP | AY6: TMP | BA6: TUNNEL | BB6: DISCHARGE | BC6: CAPACITY | BF6: ELEV | BH6: MCP | BI6: MCP
N7: LAND | O7: F&R | Q7: NON - | R7: NON - | S7: PROJ | T7: PROJ | U7: BAL | X7: WATER | Y7: IRRIG. | Z7: STOR | AA7: SPILLED | AB7: JUNE | AF7: 1.7 | AG7: 1.3 | AO7: IN | AQ7: Apr - Jun | AR7: EVAP | AS7: "B" | AT7: EXCH | AU7: WATER) | AV7: WATER | BA7: Misc. | BF7: DTGH | BH7: MPP | BI7: OVER
Q8: PROJ | R8: PROJ | X8: USED | Y8: WATER | AA8: OR | AB8: (DIV+ | AO8: MCPHEE | BI8: MPP
R9: 4.2 | Y9: USED | AA9: USED | AB9: CALL) | BC9: FP = 3960
C10: AC. Ft. | E10: AC FT | G10: CFS | H10: CFS | I10: CFS | J10: CFS | K10: CFS | L10: CFS | M10: CFS | N10: CFS | O10: CFS | P10: CFS | Q10: CFS | R10: CFS | S10: CFS | T10: CFS | U10: CFS | V10: CFS | W10: CFS | X10: 153400 | Y10: 150400 | AB10: 72000 | AC10: CFS | AD10: CFS | AE10: CFS | AF10: CFS | AG10: CFS | AH10: CFS | AI10: CFS | AJ10: CFS | AK10: CFS | AL10: CFS | AM10: CFS | AN10: CFS | AO10: CFS | AP10: CFS | AQ10: CFS | AR10: AC.FT. | AS10: CFS | AT10: CFS | AU10: CFS | AV10: CFS | BA10: Outflow | BB10: CFS | BC10: AC FT | BH10: CFS | BI10: CFS
N11: 1.03 | O11: 1.05 | P11: 1.02 | Q11: 1.02 | R11: 1.04 | T11: 1.04 | X11: CFS | Y11: CFS | Z11: CFS | AA11: CFS | AB11: Ac. Ft. | BA11: CFS
A12: SEASON BAL
A13: YTD | B13: 6902.18 | C13: =VLOOKUP(TRUNC(B13,1),VLOOKUP!$A$3:$K$2834,RIGHT(TEXT(B13,"0000.00"),1)+2,FALSE) -> 291692 | AI13: 6456.1579 | AO13: 0
A15: 1 | B15: 6902.18 | C15: =IF(B15="",C13,VLOOKUP(TRUNC(B15,1),VLOOKUP!$A$3:$K$2834,RIGHT(TEXT(B15,"0000.00"),1)+2,FALSE)) -> 291692 | D15: =C15-C13 -> 0 | E15: =C15-152000 -> 139692 | F15: =D15/$D$2 -> 0 | G15: 26.2 | H15: 0 | I15: =G15+H15 -> 26.2 | J15: =IF(L15>0,L15,0) -> 16.2 | K15: =I15+J15 -> 42.4 | L15: =IF(G15="",0,F15-(I15-AK15)) -> 16.2 | M15: 4.4 | N15: 0 | O15: =0*1.05 -> 0 | P15: 0 | Q15: =1143800/325851/1.9835*1.02 -> 1.8050906 | R15: 0 | S15: =IF(((2*1.04)-T15)>=4.2,4.2,(2*1.04)-T15) -> 1.4923106 | T15: =(0.5331*1.06)*1.04 -> 0.58768944 | U15: =M15-(Q15+R15+S15+T15) -> 0.51490941 | V15: 0 | W15: 0 | X15: =MAX(0,M15-N15-O15-P15-Q15-R15-S15-T15-U15+V15+W15-AU15+AS15) -> 0 | Y15: =X15-AP15 -> 0 | AE15: 0 | AF15: 0 | AG15: 0 | AH15: 38 | AI15: =AI13-AH15 -> 6418.1579 | AK15: =N15+O15+P15+Q15+R15+S15+T15+U15+X15+AE15+AH15 -> 42.4 | AL15: =IF(L15<0,L15*-1,0) -> 0 | AM15: =AK15+AL15 -> 42.4 | AO15: =IF(G15="","",IF(I15>=795,795-X15,I15-Q15-R15-X15-AF15)-AJ15) -> 24.394909 | AW15: 0 | AX15: 60 | AY15: 21 | BA15: =SUM(N15,P15:U15) -> 4.4 | BB15: 1.14 | BC15: 15835 | BE15: 1 | BF15: 6902.2 | BG15: =B15-BF15 -> -0.02 | BH15: 24.952083 | BI15: =AH15-BH15 -> 13.047917
A16: =A15+1 -> 2 | B16: 6902.18 | C16: =IF(B16="",C15,VLOOKUP(TRUNC(B16,1),VLOOKUP!$A$3:$K$2834,RIGHT(TEXT(B16,"0000.00"),1)+2,FALSE)) -> 291692 | D16: =C16-C15 -> 0 | E16: =C16-152000 -> 139692 | F16: =D16/$D$2 -> 0 | G16: 31.6 | H16: 0 | I16: =G16+H16 -> 31.6 | J16: =IF(L16>0,L16,0) -> 10.9 | K16: =I16+J16 -> 42.5 | L16: =IF(G16="",0,F16-(I16-AK16)) -> 10.9 | M16: 4.5 | N16: 0 | O16: =0*1.05 -> 0 | P16: 0 | Q16: =1204900/325851/1.9835*1.02 -> 1.9015157 | R16: 0 | S16: =IF(((2.5*1.04)-T16)>=4.2,4.2,(2.5*1.04)-T16) -> 2.0123106 | T16: =(0.5331*1.06)*1.04 -> 0.58768944 | U16: =M16-(Q16+R16+S16+T16) -> -0.0015156897 | V16: 0 | W16: 0 | X16: =MAX(0,M16-N16-O16-P16-Q16-R16-S16-T16-U16+V16+W16-AU16+AS16) -> 0 | Y16: =X16-AP16 -> 0 | AE16: 0 | AF16: 0 | AG16: 0 | AH16: 38 | AI16: =AI15-AH16 -> 6380.1579 | AK16: =N16+O16+P16+Q16+R16+S16+T16+U16+X16+AE16+AH16 -> 42.5 | AL16: =IF(L16<0,L16*-1,0) -> 0 | AM16: =AK16+AL16 -> 42.5 | AO16: =IF(G16="","",IF(I16>=795,795-X16,I16-Q16-R16-X16-AF16)-AJ16) -> 29.698484 | AW16: 0 | AX16: 59 | AY16: 21 | BA16: =SUM(N16,P16:U16) -> 4.5 | BB16: 1.14 | BC16: 15830 | BE16: =BE15+1 -> 2 | BF16: 6902.18 | BG16: =B16-BF16 -> 0 | BH16: 24.89375 | BI16: =AH16-BH16 -> 13.10625
A17: =A16+1 -> 3 | B17: 6902.18 | C17: =IF(B17="",C16,VLOOKUP(TRUNC(B17,1),VLOOKUP!$A$3:$K$2834,RIGHT(TEXT(B17,"0000.00"),1)+2,FALSE)) -> 291692 | D17: =C17-C16 -> 0 | E17: =C17-152000 -> 139692 | F17: =D17/$D$2 -> 0 | G17: 33.3 | H17: 0 | I17: =G17+H17 -> 33.3 | J17: =IF(L17>0,L17,0) -> 9.3 | K17: =I17+J17 -> 42.6 | L17: =IF(G17="",0,F17-(I17-AK17)) -> 9.3 | M17: 4.6 | N17: 0 | O17: =0*1.05 -> 0 | P17: 0 | Q17: =1300200/325851/1.9835*1.02 -> 2.0519136 | R17: 0 | S17: =IF(((2.6*1.04)-T17)>=4.2,4.2,(2.6*1.04)-T17) -> 2.1163106 | T17: =(0.5331*1.06)*1.04 -> 0.58768944 | U17: =M17-(Q17+R17+S17+T17) -> -0.1559136 | V17: 0 | W17: 0 | X17: =MAX(0,M17-N17-O17-P17-Q17-R17-S17-T17-U17+V17+W17-AU17+AS17) -> 4.4408921e-16 | Y17: =X17-AP17 -> 4.4408921e-16 | AE17: 0 | AF17: 0 | AG17: 0 | AH17: 38 | AI17: =AI16-AH17 -> 6342.1579 | AK17: =N17+O17+P17+Q17+R17+S17+T17+U17+X17+AE17+AH17 -> 42.6 | AL17: =IF(L17<0,L17*-1,0) -> 0 | AM17: =AK17+AL17 -> 42.6 | AO17: =IF(G17="","",IF(I17>=795,795-X17,I17-Q17-R17-X17-AF17)-AJ17) -> 31.248086 | AW17: 0 | AX17: 63 | AY17: 26 | BA17: =SUM(N17,P17:U17) -> 4.6 | BB17: 1.14 | BC17: 15825 | BE17: =BE16+1 -> 3 | BF17: 6902.17 | BG17: =B17-BF17 -> 0.01 | BH17: 25.089 | BI17: =AH17-BH17 -> 12.911
A18: =A17+1 -> 4 | B18: 6902.09 | C18: =IF(B18="",C17,VLOOKUP(TRUNC(B18,1),VLOOKUP!$A$3:$K$2834,RIGHT(TEXT(B18,"0000.00"),1)+2,FALSE)) -> 291353 | D18: =C18-C17 -> -339 | E18: =C18-152000 -> 139353 | F18: =D18/$D$2 -> -170.91001 | G18: 42.5 | H18: 0 | I18: =G18+H18 -> 42.5 | J18: =IF(L18>0,L18,0) -> 0 | K18: =I18+J18 -> 42.5 | L18: =IF(G18="",0,F18-(I18-AK18)) -> -78.610008 | M18: 4.8 | N18: 0 | O18: =0*1.05 -> 0 | P18: 0 | Q18: =966400/325851/1.9835*1.02 -> 1.5251264 | R18: 0 | S18: =IF(((2.5*1.04)-T18)>=4.2,4.2,(2.5*1.04)-T18) -> 2.0123106 | T18: =(0.5331*1.06)*1.04 -> 0.58768944 | U18: =M18-(Q18+R18+S18+T18) -> 0.67487363 | V18: 92 | W18: 0 | X18: =MAX(0,M18-N18-O18-P18-Q18-R18-S18-T18-U18+V18+W18-AU18+AS18) -> 92 | Y18: =X18-AP18 -> 92 | AE18: 0 | AF18: 0 | AG18: 0 | AH18: 38 | AI18: =AI17-AH18 -> 6304.1579 | AK18: =N18+O18+P18+Q18+R18+S18+T18+U18+X18+AE18+AH18 -> 134.8 | AL18: =IF(L18<0,L18*-1,0) -> 78.610008 | AM18: =AK18+AL18 -> 213.41001 | AN18: =V18 -> 92 | AO18: =IF(G18="","",IF(I18>=795,795-X18,I18-Q18-R18-X18-AF18)-AJ18) -> -51.025126 | AW18: 0 | AX18: 65 | AY18: 29 | BA18: =SUM(N18,P18:U18) -> 4.8 | BB18: 1.14 | BC18: 15822 | BE18: =BE17+1 -> 4 | BF18: 6902.11 | BG18: =B18-BF18 -> -0.02 | BH18: 24.764583 | BI18: =AH18-BH18 -> 13.235417
A19: =A18+1 -> 5 | B19: 6901.99 | C19: =IF(B19="",C18,VLOOKUP(TRUNC(B19,1),VLOOKUP!$A$3:$K$2834,RIGHT(TEXT(B19,"0000.00"),1)+2,FALSE)) -> 290977 | D19: =C19-C18 -> -376 | E19: =C19-152000 -> 138977 | F19: =D19/$D$2 -> -189.5639 | G19: 48.2 | H19: 0 | I19: =G19+H19 -> 48.2 | J19: =IF(L19>0,L19,0) -> 0 | K19: =I19+J19 -> 48.2 | L19: =IF(G19="",0,F19-(I19-AK19)) -> -14.963902 | M19: 4.8 | N19: 0 | O19: =0*1.05 -> 0 | P19: 0 | Q19: =1003100/325851/1.9835*1.02 -> 1.5830446 | R19: 0 | S19: =IF(((2.6*1.04)-T19)>=4.2,4.2,(2.6*1.04)-T19) -> 2.1163106 | T19: =(0.5331*1.06)*1.04 -> 0.58768944 | U19: =M19-(Q19+R19+S19+T19) -> 0.51295544 | V19: 180 | W19: 0 | X19: =MAX(0,M19-N19-O19-P19-Q19-R19-S19-T19-U19+V19+W19-AU19+AS19) -> 180 | Y19: =X19-AP19 -> 180 | AE19: 0 | AF19: 0 | AG19: 0 | AH19: 38 | AI19: =AI18-AH19 -> 6266.1579 | AK19: =N19+O19+P19+Q19+R19+S19+T19+U19+X19+AE19+AH19 -> 222.8 | AL19: =IF(L19<0,L19*-1,0) -> 14.963902 | AM19: =AK19+AL19 -> 237.7639 | AN19: =V19 -> 180 | AO19: =IF(G19="","",IF(I19>=795,795-X19,I19-Q19-R19-X19-AF19)-AJ19) -> -133.38304 | AW19: 0 | AX19: 66 | AY19: 31 | BA19: =SUM(N19,P19:U19) -> 4.8 | BB19: 1.14 | BC19: 15819 | BE19: =BE18+1 -> 5 | BF19: 6902.01 | BG19: =B19-BF19 -> -0.02 | BH19: 24.814583 | BI19: =AH19-BH19 -> 13.185417
A20: =A19+1 -> 6 | B20: 6901.89 | C20: =IF(B20="",C19,VLOOKUP(TRUNC(B20,1),VLOOKUP!$A$3:$K$2834,RIGHT(TEXT(B20,"0000.00"),1)+2,FALSE)) -> 290604 | D20: =C20-C19 -> -373 | E20: =C20-152000 -> 138604 | F20: =D20/$D$2 -> -188.05142 | G20: 46.4 | H20: 0 | I20: =G20+H20 -> 46.4 | J20: =IF(L20>0,L20,0) -> 0 | K20: =I20+J20 -> 46.4 | L20: =IF(G20="",0,F20-(I20-AK20)) -> -11.651424 | M20: 4.8 | N20: 0 | O20: =0*1.05 -> 0 | P20: 0 | Q20: =1226900/325851/1.9835*1.02 -> 1.936235 | R20: 0 | S20: =IF(((2.7*1.04)-T20)>=4.2,4.2,(2.7*1.04)-T20) -> 2.2203106 | T20: =(0.5331*1.06)*1.04 -> 0.58768944 | U20: =M20-(Q20+R20+S20+T20) -> 0.05576496 | V20: 180 | W20: 0 | X20: =MAX(0,M20-N20-O20-P20-Q20-R20-S20-T20-U20+V20+W20-AU20+AS20) -> 180 | Y20: =X20-AP20 -> 180 | AE20: 0 | AF20: 0 | AG20: 0 | AH20: 38 | AI20: =AI19-AH20 -> 6228.1579 | AK20: =N20+O20+P20+Q20+R20+S20+T20+U20+X20+AE20+AH20 -> 222.8 | AL20: =IF(L20<0,L20*-1,0) -> 11.651424 | AM20: =AK20+AL20 -> 234.45142 | AN20: =V20 -> 180 | AO20: =IF(G20="","",IF(I20>=795,795-X20,I20-Q20-R20-X20-AF20)-AJ20) -> -135.53624 | AW20: 0 | AX20: 67 | AY20: 32 | BA20: =SUM(N20,P20:U20) -> 4.8 | BB20: 1.14 | BC20: 15816 | BE20: =BE19+1 -> 6 | BF20: 6901.9 | BG20: =B20-BF20 -> -0.01 | BH20: 24.753125 | BI20: =AH20-BH20 -> 13.246875
A21: =A20+1 -> 7 | B21: 6901.79 | C21: =IF(B21="",C20,VLOOKUP(TRUNC(B21,1),VLOOKUP!$A$3:$K$2834,RIGHT(TEXT(B21,"0000.00"),1)+2,FALSE)) -> 290231 | D21: =C21-C20 -> -373 | E21: =C21-152000 -> 138231 | F21: =D21/$D$2 -> -188.05142 | G21: 46.7 | H21: 0 | I21: =G21+H21 -> 46.7 | J21: =IF(L21>0,L21,0) -> 0 | K21: =I21+J21 -> 46.7 | L21: =IF(G21="",0,F21-(I21-AK21)) -> -12.551424 | M21: 5.2 | N21: 0 | O21: =0*1.05 -> 0 | P21: 0 | Q21: =1036500/325851/1.9835*1.02 -> 1.6357548 | R21: 0 | S21: =IF(((2.6*1.04)-T21)>=4.2,4.2,(2.6*1.04)-T21) -> 2.1163106 | T21: =(0.5331*1.06)*1.04 -> 0.58768944 | U21: =M21-(Q21+R21+S21+T21) -> 0.86024516 | V21: 179 | W21: 0 | X21: =MAX(0,M21-N21-O21-P21-Q21-R21-S21-T21-U21+V21+W21-AU21+AS21) -> 179 | Y21: =X21-AP21 -> 179 | AE21: 0 | AF21: 0 | AG21: 0 | AH21: 38 | AI21: =AI20-AH21 -> 6190.1579 | AK21: =N21+O21+P21+Q21+R21+S21+T21+U21+X21+AE21+AH21 -> 222.2 | AL21: =IF(L21<0,L21*-1,0) -> 12.551424 | AM21: =AK21+AL21 -> 234.75142 | AN21: =V21 -> 179 | AO21: =IF(G21="","",IF(I21>=795,795-X21,I21-Q21-R21-X21-AF21)-AJ21) -> -133.93575 | AW21: 0 | AX21: 64 | AY21: 31 | BA21: =SUM(N21,P21:U21) -> 5.2 | BB21: 1.14 | BC21: 15814 | BE21: =BE20+1 -> 7 | BF21: 6901.8 | BG21: =B21-BF21 -> -0.01 | BH21: 24.805208 | BI21: =AH21-BH21 -> 13.194792
A22: =A21+1 -> 8 | B22: 6901.68 | C22: =IF(B22="",C21,VLOOKUP(TRUNC(B22,1),VLOOKUP!$A$3:$K$2834,RIGHT(TEXT(B22,"0000.00"),1)+2,FALSE)) -> 289820 | D22: =C22-C21 -> -411 | E22: =C22-152000 -> 137820 | F22: =D22/$D$2 -> -207.20948 | G22: 42 | H22: 0 | I22: =G22+H22 -> 42 | J22: =IF(L22>0,L22,0) -> 0 | K22: =I22+J22 -> 42 | L22: =IF(G22="",0,F22-(I22-AK22)) -> -27.409478 | M22: 4.8 | N22: 0 | O22: =0*1.05 -> 0 | P22: 0 | Q22: =1263700/325851/1.9835*1.02 -> 1.994311 | R22: 0 | S22: =IF(((2.4*1.04)-T22)>=4.2,4.2,(2.4*1.04)-T22) -> 1.9765491 | T22: =(0.4712*1.06)*1.04 -> 0.51945088 | U22: =M22-(Q22+R22+S22+T22) -> 0.30968896 | V22: 179 | W22: 0 | X22: =MAX(0,M22-N22-O22-P22-Q22-R22-S22-T22-U22+V22+W22-AU22+AS22) -> 179 | Y22: =X22-AP22 -> 179 | AE22: 0 | AF22: 0 | AG22: 0 | AH22: 38 | AI22: =AI21-AH22 -> 6152.1579 | AK22: =N22+O22+P22+Q22+R22+S22+T22+U22+X22+AE22+AH22 -> 221.8 | AL22: =IF(L22<0,L22*-1,0) -> 27.409478 | AM22: =AK22+AL22 -> 249.20948 | AN22: =V22 -> 179 | AO22: =IF(G22="","",IF(I22>=795,795-X22,I22-Q22-R22-X22-AF22)-AJ22) -> -138.99431 | AW22: 0 | AX22: 68 | AY22: 30 | BA22: =SUM(N22,P22:U22) -> 4.8 | BB22: 1.14 | BC22: 15811 | BE22: =BE21+1 -> 8 | BF22: 6901.68 | BG22: =B22-BF22 -> 0 | BH22: 24.791667 | BI22: =AH22-BH22 -> 13.208333
A23: =A22+1 -> 9 | B23: 6901.57 | C23: =IF(B23="",C22,VLOOKUP(TRUNC(B23,1),VLOOKUP!$A$3:$K$2834,RIGHT(TEXT(B23,"0000.00"),1)+2,FALSE)) -> 289409 | D23: =C23-C22 -> -411 | E23: =C23-152000 -> 137409 | F23: =D23/$D$2 -> -207.20948 | G23: 42.2 | H23: 0 | I23: =G23+H23 -> 42.2 | J23: =IF(L23>0,L23,0) -> 0 | K23: =I23+J23 -> 42.2 | L23: =IF(G23="",0,F23-(I23-AK23)) -> -28.009478 | M23: 4.4 | N23: 0 | O23: =0*1.05 -> 0 | P23: 0 | Q23: =1135800/325851/1.9835*1.02 -> 1.7924654 | R23: 0 | S23: =IF(((2.4*1.04)-T23)>=4.2,4.2,(2.4*1.04)-T23) -> 1.9765491 | T23: =(0.4712*1.06)*1.04 -> 0.51945088 | U23: =M23-(Q23+R23+S23+T23) -> 0.11153463 | V23: 179 | W23: 0 | X23: =MAX(0,M23-N23-O23-P23-Q23-R23-S23-T23-U23+V23+W23-AU23+AS23) -> 179 | Y23: =X23-AP23 -> 179 | AE23: 0 | AF23: 0 | AG23: 0 | AH23: 38 | AI23: =AI22-AH23 -> 6114.1579 | AK23: =N23+O23+P23+Q23+R23+S23+T23+U23+X23+AE23+AH23 -> 221.4 | AL23: =IF(L23<0,L23*-1,0) -> 28.009478 | AM23: =AK23+AL23 -> 249.40948 | AN23: =V23 -> 179 | AO23: =IF(G23="","",IF(I23>=795,795-X23,I23-Q23-R23-X23-AF23)-AJ23) -> -138.59247 | AW23: 0 | AX23: 68 | AY23: 32 | BA23: =SUM(N23,P23:U23) -> 4.4 | BB23: 1.14 | BC23: 15806 | BE23: =BE22+1 -> 9 | BF23: 6901.59 | BG23: =B23-BF23 -> -0.02 | BH23: 24.691667 | BI23: =AH23-BH23 -> 13.308333
A24: =A23+1 -> 10 | B24: 6901.46 | C24: =IF(B24="",C23,VLOOKUP(TRUNC(B24,1),VLOOKUP!$A$3:$K$2834,RIGHT(TEXT(B24,"0000.00"),1)+2,FALSE)) -> 288999 | D24: =C24-C23 -> -410 | E24: =C24-152000 -> 136999 | F24: =D24/$D$2 -> -206.70532 | G24: 46 | H24: 0 | I24: =G24+H24 -> 46 | J24: =IF(L24>0,L24,0) -> 0 | K24: =I24+J24 -> 46 | L24: =IF(G24="",0,F24-(I24-AK24)) -> -30.505319 | M24: 5.2 | N24: 0 | O24: =0*1.05 -> 0 | P24: 0 | Q24: =1155400/325851/1.9835*1.02 -> 1.8233972 | R24: 0 | S24: =IF(((2.2*1.04)-T24)>=4.2,4.2,(2.2*1.04)-T24) -> 1.7685491 | T24: =(0.4712*1.06)*1.04 -> 0.51945088 | U24: =M24-(Q24+R24+S24+T24) -> 1.0886028 | V24: 179 | W24: 0 | X24: =MAX(0,M24-N24-O24-P24-Q24-R24-S24-T24-U24+V24+W24-AU24+AS24) -> 179 | Y24: =X24-AP24 -> 179 | AE24: 0 | AF24: 0 | AG24: 0 | AH24: 38 | AI24: =AI23-AH24 -> 6076.1579 | AK24: =N24+O24+P24+Q24+R24+S24+T24+U24+X24+AE24+AH24 -> 222.2 | AL24: =IF(L24<0,L24*-1,0) -> 30.505319 | AM24: =AK24+AL24 -> 252.70532 | AN24: =V24 -> 179 | AO24: =IF(G24="","",IF(I24>=795,795-X24,I24-Q24-R24-X24-AF24)-AJ24) -> -134.8234 | AW24: 0 | AX24: 65 | AY24: 33 | BA24: =SUM(N24,P24:U24) -> 5.2 | BB24: 1.14 | BC24: 15805 | BE24: =BE23+1 -> 10 | BF24: 6901.47 | BG24: =B24-BF24 -> -0.01 | BH24: 24.741667 | BI24: =AH24-BH24 -> 13.258333
A25: =A24+1 -> 11 | B25: 6901.42 | C25: =IF(B25="",C24,VLOOKUP(TRUNC(B25,1),VLOOKUP!$A$3:$K$2834,RIGHT(TEXT(B25,"0000.00"),1)+2,FALSE)) -> 288850 | D25: =C25-C24 -> -149 | E25: =C25-152000 -> 136850 | F25: =D25/$D$2 -> -75.119738 | G25: 42.2 | H25: 0 | I25: =G25+H25 -> 42.2 | J25: =IF(L25>0,L25,0) -> 0 | K25: =I25+J25 -> 42.2 | L25: =IF(G25="",0,F25-(I25-AK25)) -> -1.2197378 | M25: 4.1 | N25: 0 | O25: =0*1.05 -> 0 | P25: 0 | Q25: =1110900/325851/1.9835*1.02 -> 1.7531694 | R25: 0 | S25: =IF(((2.2*1.04)-T25)>=4.2,4.2,(2.2*1.04)-T25) -> 1.7685491 | T25: =(0.4712*1.06)*1.04 -> 0.51945088 | U25: =M25-(Q25+R25+S25+T25) -> 0.058830625 | V25: 74 | W25: 0 | X25: =MAX(0,M25-N25-O25-P25-Q25-R25-S25-T25-U25+V25+W25-AU25+AS25) -> 74 | Y25: =X25-AP25 -> 74 | AE25: 0 | AF25: 0 | AG25: 0 | AH25: 38 | AI25: =AI24-AH25 -> 6038.1579 | AK25: =N25+O25+P25+Q25+R25+S25+T25+U25+X25+AE25+AH25 -> 116.1 | AL25: =IF(L25<0,L25*-1,0) -> 1.2197378 | AM25: =AK25+AL25 -> 117.31974 | AN25: =V25 -> 74 | AO25: =IF(G25="","",IF(I25>=795,795-X25,I25-Q25-R25-X25-AF25)-AJ25) -> -33.553169 | AW25: 0 | AX25: 60 | AY25: 31 | BA25: =SUM(N25,P25:U25) -> 4.1 | BB25: 1.17 | BC25: 15802 | BE25: =BE24+1 -> 11 | BF25: 6901.42 | BG25: =B25-BF25 -> 0 | BH25: 24.729167 | BI25: =AH25-BH25 -> 13.270833
A26: =A25+1 -> 12 | B26: 6901.41 | C26: =IF(B26="",C25,VLOOKUP(TRUNC(B26,1),VLOOKUP!$A$3:$K$2834,RIGHT(TEXT(B26,"0000.00"),1)+2,FALSE)) -> 288812 | D26: =C26-C25 -> -38 | E26: =C26-152000 -> 136812 | F26: =D26/$D$2 -> -19.158054 | G26: 37.2 | H26: 0 | I26: =G26+H26 -> 37.2 | J26: =IF(L26>0,L26,0) -> 0 | K26: =I26+J26 -> 37.2 | L26: =IF(G26="",0,F26-(I26-AK26)) -> -12.758054 | M26: 4.6 | N26: 0 | O26: =0*1.05 -> 0 | P26: 0 | Q26: =1221300/325851/1.9835*1.02 -> 1.9273974 | R26: 0 | S26: =IF(((2.2*1.04)-T26)>=4.2,4.2,(2.2*1.04)-T26) -> 1.7685491 | T26: =(0.4712*1.06)*1.04 -> 0.51945088 | U26: =M26-(Q26+R26+S26+T26) -> 0.38460261 | V26: 0 | W26: 0 | X26: =MAX(0,M26-N26-O26-P26-Q26-R26-S26-T26-U26+V26+W26-AU26+AS26) -> 0 | Y26: =X26-AP26 -> 0 | AE26: 0 | AF26: 0 | AG26: 0 | AH26: 39 | AI26: =AI25-AH26 -> 5999.1579 | AK26: =N26+O26+P26+Q26+R26+S26+T26+U26+X26+AE26+AH26 -> 43.6 | AL26: =IF(L26<0,L26*-1,0) -> 12.758054 | AM26: =AK26+AL26 -> 56.358054 | AO26: =IF(G26="","",IF(I26>=795,795-X26,I26-Q26-R26-X26-AF26)-AJ26) -> 35.272603 | AW26: 0 | AX26: 56 | AY26: 23 | BA26: =SUM(N26,P26:U26) -> 4.6 | BB26: 1.16 | BC26: 15797 | BE26: =BE25+1 -> 12 | BF26: 6901.4 | BG26: =B26-BF26 -> 0.01 | BH26: 24.829167 | BI26: =AH26-BH26 -> 14.170833
A27: =A26+1 -> 13 | B27: 6901.37 | C27: =IF(B27="",C26,VLOOKUP(TRUNC(B27,1),VLOOKUP!$A$3:$K$2834,RIGHT(TEXT(B27,"0000.00"),1)+2,FALSE)) -> 288663 | D27: =C27-C26 -> -149 | E27: =C27-152000 -> 136663 | F27: =D27/$D$2 -> -75.119738 | G27: 38.9 | H27: 0 | I27: =G27+H27 -> 38.9 | J27: =IF(L27>0,L27,0) -> 0 | K27: =I27+J27 -> 38.9 | L27: =IF(G27="",0,F27-(I27-AK27)) -> -70.519738 | M27: 3.5 | N27: 0 | O27: =0*1.05 -> 0 | P27: 0 | Q27: =984600/325851/1.9835*1.02 -> 1.5538487 | R27: 0 | S27: =IF(((2.2*1.04)-T27)>=4.2,4.2,(2.2*1.04)-T27) -> 1.7685491 | T27: =(0.4712*1.06)*1.04 -> 0.51945088 | U27: =M27-(Q27+R27+S27+T27) -> -0.34184874 | V27: 0 | W27: 0 | X27: =MAX(0,M27-N27-O27-P27-Q27-R27-S27-T27-U27+V27+W27-AU27+AS27) -> 0 | Y27: =X27-AP27 -> 0 | AE27: 0 | AF27: 0 | AG27: 0 | AH27: 40 | AI27: =AI26-AH27 -> 5959.1579 | AK27: =N27+O27+P27+Q27+R27+S27+T27+U27+X27+AE27+AH27 -> 43.5 | AL27: =IF(L27<0,L27*-1,0) -> 70.519738 | AM27: =AK27+AL27 -> 114.01974 | AO27: =IF(G27="","",IF(I27>=795,795-X27,I27-Q27-R27-X27-AF27)-AJ27) -> 37.346151 | AW27: 0 | AX27: 65 | AY27: 27 | BA27: =SUM(N27,P27:U27) -> 3.5 | BB27: 1.17 | BC27: 15794 | BE27: =BE26+1 -> 13 | BF27: 6901.4 | BG27: =B27-BF27 -> -0.03 | BH27: 24.970833 | BI27: =AH27-BH27 -> 15.029167
A28: =A27+1 -> 14 | B28: 6901.36 | C28: =IF(B28="",C27,VLOOKUP(TRUNC(B28,1),VLOOKUP!$A$3:$K$2834,RIGHT(TEXT(B28,"0000.00"),1)+2,FALSE)) -> 288626 | D28: =C28-C27 -> -37 | E28: =C28-152000 -> 136626 | F28: =D28/$D$2 -> -18.653895 | G28: 40.1 | H28: 0 | I28: =G28+H28 -> 40.1 | J28: =IF(L28>0,L28,0) -> 0 | K28: =I28+J28 -> 40.1 | L28: =IF(G28="",0,F28-(I28-AK28)) -> -15.353895 | M28: 3.4 | N28: 0 | O28: =0*1.05 -> 0 | P28: 0 | Q28: =1137800/325851/1.9835*1.02 -> 1.7956217 | R28: 0 | S28: =IF(((2.2*1.04)-T28)>=4.2,4.2,(2.2*1.04)-T28) -> 1.7685491 | T28: =(0.4712*1.06)*1.04 -> 0.51945088 | U28: =M28-(Q28+R28+S28+T28) -> -0.68362167 | V28: 0 | W28: 0 | X28: =MAX(0,M28-N28-O28-P28-Q28-R28-S28-T28-U28+V28+W28-AU28+AS28) -> 3.3306691e-16 | Y28: =X28-AP28 -> 3.3306691e-16 | AE28: 0 | AF28: 0 | AG28: 0 | AH28: 40 | AI28: =AI27-AH28 -> 5919.1579 | AK28: =N28+O28+P28+Q28+R28+S28+T28+U28+X28+AE28+AH28 -> 43.4 | AL28: =IF(L28<0,L28*-1,0) -> 15.353895 | AM28: =AK28+AL28 -> 58.753895 | AO28: =IF(G28="","",IF(I28>=795,795-X28,I28-Q28-R28-X28-AF28)-AJ28) -> 38.304378 | AW28: 0 | AX28: 62 | AY28: 29 | BA28: =SUM(N28,P28:U28) -> 3.4 | BB28: 1.18 | BC28: 15790 | BE28: =BE27+1 -> 14 | BF28: 6901.38 | BG28: =B28-BF28 -> -0.02 | BH28: 24.991667 | BI28: =AH28-BH28 -> 15.008333
A29: =A28+1 -> 15 | B29: 6901.35 | C29: =IF(B29="",C28,VLOOKUP(TRUNC(B29,1),VLOOKUP!$A$3:$K$2834,RIGHT(TEXT(B29,"0000.00"),1)+2,FALSE)) -> 288588 | D29: =C29-C28 -> -38 | E29: =C29-152000 -> 136588 | F29: =D29/$D$2 -> -19.158054 | G29: 41.8 | H29: 0 | I29: =G29+H29 -> 41.8 | J29: =IF(L29>0,L29,0) -> 0 | K29: =I29+J29 -> 41.8 | L29: =IF(G29="",0,F29-(I29-AK29)) -> -17.058054 | M29: 3.9 | N29: 0 | O29: =0*1.05 -> 0 | P29: 0 | Q29: =928500/325851/1.9835*1.02 -> 1.4653144 | R29: 0 | S29: =IF(((2.2*1.04)-T29)>=4.2,4.2,(2.2*1.04)-T29) -> 1.6785933 | T29: =(0.5528*1.06)*1.04 -> 0.60940672 | U29: =M29-(Q29+R29+S29+T29) -> 0.1466856 | V29: 0 | W29: 0 | X29: =MAX(0,M29-N29-O29-P29-Q29-R29-S29-T29-U29+V29+W29-AU29+AS29) -> 4.4408921e-16 | Y29: =X29-AP29 -> 4.4408921e-16 | AE29: 0 | AF29: 0 | AG29: 0 | AH29: 40 | AI29: =AI28-AH29 -> 5879.1579 | AK29: =N29+O29+P29+Q29+R29+S29+T29+U29+X29+AE29+AH29 -> 43.9 | AL29: =IF(L29<0,L29*-1,0) -> 17.058054 | AM29: =AK29+AL29 -> 60.958054 | AO29: =IF(G29="","",IF(I29>=795,795-X29,I29-Q29-R29-X29-AF29)-AJ29) -> 40.334686 | AW29: 0 | AX29: 65 | AY29: 33 | BA29: =SUM(N29,P29:U29) -> 3.9 | BB29: 1.15 | BC29: 15787 | BE29: =BE28+1 -> 15 | BF29: 6901.38 | BG29: =B29-BF29 -> -0.03 | BH29: 25.034375 | BI29: =AH29-BH29 -> 14.965625
A30: =A29+1 -> 16 | B30: 6901.32 | C30: =IF(B30="",C29,VLOOKUP(TRUNC(B30,1),VLOOKUP!$A$3:$K$2834,RIGHT(TEXT(B30,"0000.00"),1)+2,FALSE)) -> 288476 | D30: =C30-C29 -> -112 | E30: =C30-152000 -> 136476 | F30: =D30/$D$2 -> -56.465843 | G30: 44.9 | H30: 0 | I30: =G30+H30 -> 44.9 | J30: =IF(L30>0,L30,0) -> 0 | K30: =I30+J30 -> 44.9 | L30: =IF(G30="",0,F30-(I30-AK30)) -> -58.265843 | M30: 3.1 | N30: 0 | O30: =0*1.05 -> 0 | P30: 0 | Q30: =1137200/325851/1.9835*1.02 -> 1.7946748 | R30: 0 | S30: =IF(((2.2*1.04)-T30)>=4.2,4.2,(2.2*1.04)-T30) -> 1.6785933 | T30: =(0.5528*1.06)*1.04 -> 0.60940672 | U30: =M30-(Q30+R30+S30+T30) -> -0.98267478 | V30: 0 | W30: 0 | X30: =MAX(0,M30-N30-O30-P30-Q30-R30-S30-T30-U30+V30+W30-AU30+AS30) -> 0 | Y30: =X30-AP30 -> 0 | AE30: 0 | AF30: 0 | AG30: 0 | AH30: 40 | AI30: =AI29-AH30 -> 5839.1579 | AK30: =N30+O30+P30+Q30+R30+S30+T30+U30+X30+AE30+AH30 -> 43.1 | AL30: =IF(L30<0,L30*-1,0) -> 58.265843 | AM30: =AK30+AL30 -> 101.36584 | AO30: =IF(G30="","",IF(I30>=795,795-X30,I30-Q30-R30-X30-AF30)-AJ30) -> 43.105325 | AW30: 0 | AX30: 65 | AY30: 33 | BA30: =SUM(N30,P30:U30) -> 3.1 | BB30: 1.17 | BC30: 15785 | BE30: =BE29+1 -> 16 | BF30: 6901.36 | BG30: =B30-BF30 -> -0.04 | BH30: 25 | BI30: =AH30-BH30 -> 15
A31: =A30+1 -> 17 | B31: 6901.3 | C31: =IF(B31="",C30,VLOOKUP(TRUNC(B31,1),VLOOKUP!$A$3:$K$2834,RIGHT(TEXT(B31,"0000.00"),1)+2,FALSE)) -> 288402 | D31: =C31-C30 -> -74 | E31: =C31-152000 -> 136402 | F31: =D31/$D$2 -> -37.307789 | G31: 38.8 | H31: 0 | I31: =G31+H31 -> 38.8 | J31: =IF(L31>0,L31,0) -> 0 | K31: =I31+J31 -> 38.8 | L31: =IF(G31="",0,F31-(I31-AK31)) -> -32.407789 | M31: 3.7 | N31: 0 | O31: =0*1.05 -> 0 | P31: 0 | Q31: =929300/325851/1.9835*1.02 -> 1.4665769 | R31: 0 | S31: =IF(((2.2*1.04)-T31)>=4.2,4.2,(2.2*1.04)-T31) -> 1.6785933 | T31: =(0.5528*1.06)*1.04 -> 0.60940672 | U31: =M31-(Q31+R31+S31+T31) -> -0.05457692 | V31: 0 | W31: 0 | X31: =MAX(0,M31-N31-O31-P31-Q31-R31-S31-T31-U31+V31+W31-AU31+AS31) -> 0 | Y31: =X31-AP31 -> 0 | AE31: 0 | AF31: 0 | AG31: 0 | AH31: 40 | AI31: =AI30-AH31 -> 5799.1579 | AK31: =N31+O31+P31+Q31+R31+S31+T31+U31+X31+AE31+AH31 -> 43.7 | AL31: =IF(L31<0,L31*-1,0) -> 32.407789 | AM31: =AK31+AL31 -> 76.107789 | AO31: =IF(G31="","",IF(I31>=795,795-X31,I31-Q31-R31-X31-AF31)-AJ31) -> 37.333423 | AW31: 0 | AX31: 64 | AY31: 28 | BA31: =SUM(N31,P31:U31) -> 3.7 | BB31: 1.2 | BC31: 15782 | BE31: =BE30+1 -> 17 | BF31: 6901.36 | BG31: =B31-BF31 -> -0.06 | BH31: 25.040625 | BI31: =AH31-BH31 -> 14.959375
A32: =A31+1 -> 18 | B32: 6901.3 | C32: =IF(B32="",C31,VLOOKUP(TRUNC(B32,1),VLOOKUP!$A$3:$K$2834,RIGHT(TEXT(B32,"0000.00"),1)+2,FALSE)) -> 288402 | D32: =C32-C31 -> 0 | E32: =C32-152000 -> 136402 | F32: =D32/$D$2 -> 0 | G32: 41.3 | H32: 0 | I32: =G32+H32 -> 41.3 | J32: =IF(L32>0,L32,0) -> 1.8 | K32: =I32+J32 -> 43.1 | L32: =IF(G32="",0,F32-(I32-AK32)) -> 1.8 | M32: 3.1 | N32: 0 | O32: =0*1.05 -> 0 | P32: 0 | Q32: =1427300/325851/1.9835*1.02 -> 2.2524968 | R32: 0 | S32: =IF(((2.2*1.04)-T32)>=4.2,4.2,(2.2*1.04)-T32) -> 1.6785933 | T32: =(0.5528*1.06)*1.04 -> 0.60940672 | U32: =M32-(Q32+R32+S32+T32) -> -1.4404968 | V32: 0 | W32: 0 | X32: =MAX(0,M32-N32-O32-P32-Q32-R32-S32-T32-U32+V32+W32-AU32+AS32) -> 0 | Y32: =X32-AP32 -> 0 | AE32: 0 | AF32: 0 | AG32: 0 | AH32: 40 | AI32: =AI31-AH32 -> 5759.1579 | AK32: =N32+O32+P32+Q32+R32+S32+T32+U32+X32+AE32+AH32 -> 43.1 | AL32: =IF(L32<0,L32*-1,0) -> 0 | AM32: =AK32+AL32 -> 43.1 | AO32: =IF(G32="","",IF(I32>=795,795-X32,I32-Q32-R32-X32-AF32)-AJ32) -> 39.047503 | AW32: 0 | AX32: 65 | AY32: 30 | BA32: =SUM(N32,P32:U32) -> 3.1 | BB32: 1.15 | BC32: 15779 | BE32: =BE31+1 -> 18 | BF32: 6901.34 | BG32: =B32-BF32 -> -0.04 | BH32: 24.901042 | BI32: =AH32-BH32 -> 15.098958
A33: =A32+1 -> 19 | B33: 6901.31 | C33: =IF(B33="",C32,VLOOKUP(TRUNC(B33,1),VLOOKUP!$A$3:$K$2834,RIGHT(TEXT(B33,"0000.00"),1)+2,FALSE)) -> 288439 | D33: =C33-C32 -> 37 | E33: =C33-152000 -> 136439 | F33: =D33/$D$2 -> 18.653895 | G33: 39.5 | H33: 0 | I33: =G33+H33 -> 39.5 | J33: =IF(L33>0,L33,0) -> 23.253895 | K33: =I33+J33 -> 62.753895 | L33: =IF(G33="",0,F33-(I33-AK33)) -> 23.253895 | M33: 4.1 | N33: 0 | O33: =0*1.05 -> 0 | P33: 0 | Q33: =1096300/325851/1.9835*1.02 -> 1.7301284 | R33: 0 | S33: =IF(((2.3*1.04)-T33)>=4.2,4.2,(2.3*1.04)-T33) -> 1.7825933 | T33: =(0.5528*1.06)*1.04 -> 0.60940672 | U33: =M33-(Q33+R33+S33+T33) -> -0.022128351 | V33: 0 | W33: 0 | X33: =MAX(0,M33-N33-O33-P33-Q33-R33-S33-T33-U33+V33+W33-AU33+AS33) -> 0 | Y33: =X33-AP33 -> 0 | AE33: 0 | AF33: 0 | AG33: 0 | AH33: 40 | AI33: =AI32-AH33 -> 5719.1579 | AK33: =N33+O33+P33+Q33+R33+S33+T33+U33+X33+AE33+AH33 -> 44.1 | AL33: =IF(L33<0,L33*-1,0) -> 0 | AM33: =AK33+AL33 -> 44.1 | AO33: =IF(G33="","",IF(I33>=795,795-X33,I33-Q33-R33-X33-AF33)-AJ33) -> 37.769872 | AW33: 0.14 | AX33: 65 | AY33: 32 | BA33: =SUM(N33,P33:U33) -> 4.1 | BB33: 0.935 | BC33: 15777 | BE33: =BE32+1 -> 19 | BF33: 6901.35 | BG33: =B33-BF33 -> -0.04 | BH33: 24.717708 | BI33: =AH33-BH33 -> 15.282292
A34: =A33+1 -> 20 | B34: 6901.34 | C34: =IF(B34="",C33,VLOOKUP(TRUNC(B34,1),VLOOKUP!$A$3:$K$2834,RIGHT(TEXT(B34,"0000.00"),1)+2,FALSE)) -> 288551 | D34: =C34-C33 -> 112 | E34: =C34-152000 -> 136551 | F34: =D34/$D$2 -> 56.465843 | G34: 51.9 | H34: 0 | I34: =G34+H34 -> 51.9 | J34: =IF(L34>0,L34,0) -> 48.465843 | K34: =I34+J34 -> 100.36584 | L34: =IF(G34="",0,F34-(I34-AK34)) -> 48.465843 | M34: 2.9 | N34: 0 | O34: =0*1.05 -> 0 | P34: 0 | Q34: =957300/325851/1.9835*1.02 -> 1.5107652 | R34: 0 | S34: =IF(((2.1*1.04)-T34)>=4.2,4.2,(2.1*1.04)-T34) -> 1.5745933 | T34: =(0.5528*1.06)*1.04 -> 0.60940672 | U34: =M34-(Q34+R34+S34+T34) -> -0.79476518 | V34: 0 | W34: 0 | X34: =MAX(0,M34-N34-O34-P34-Q34-R34-S34-T34-U34+V34+W34-AU34+AS34) -> 0 | Y34: =X34-AP34 -> 0 | AE34: 0 | AF34: 0 | AG34: 0 | AH34: 41 | AI34: =AI33-AH34 -> 5678.1579 | AK34: =N34+O34+P34+Q34+R34+S34+T34+U34+X34+AE34+AH34 -> 43.9 | AL34: =IF(L34<0,L34*-1,0) -> 0 | AM34: =AK34+AL34 -> 43.9 | AO34: =IF(G34="","",IF(I34>=795,795-X34,I34-Q34-R34-X34-AF34)-AJ34) -> 50.389235 | AW34: 0.31 | AX34: 52 | AY34: 41 | BA34: =SUM(N34,P34:U34) -> 2.9 | BB34: 0.65 | BC34: 15783 | BE34: =BE33+1 -> 20 | BF34: 6901.38 | BG34: =B34-BF34 -> -0.04 | BH34: 24.814583 | BI34: =AH34-BH34 -> 16.185417
A35: =A34+1 -> 21 | B35: 6901.42 | C35: =IF(B35="",C34,VLOOKUP(TRUNC(B35,1),VLOOKUP!$A$3:$K$2834,RIGHT(TEXT(B35,"0000.00"),1)+2,FALSE)) -> 288850 | D35: =C35-C34 -> 299 | E35: =C35-152000 -> 136850 | F35: =D35/$D$2 -> 150.74363 | G35: 63.4 | H35: 0 | I35: =G35+H35 -> 63.4 | J35: =IF(L35>0,L35,0) -> 132.04363 | K35: =I35+J35 -> 195.44363 | L35: =IF(G35="",0,F35-(I35-AK35)) -> 132.04363 | M35: 3.7 | N35: 0 | O35: =0*1.05 -> 0 | P35: 0 | Q35: =899300/325851/1.9835*1.02 -> 1.4192324 | R35: 0 | S35: =IF(((2.1*1.04)-T35)>=4.2,4.2,(2.1*1.04)-T35) -> 1.5745933 | T35: =(0.5528*1.06)*1.04 -> 0.60940672 | U35: =M35-(Q35+R35+S35+T35) -> 0.096767649 | V35: 0 | W35: 0 | X35: =MAX(0,M35-N35-O35-P35-Q35-R35-S35-T35-U35+V35+W35-AU35+AS35) -> 0 | Y35: =X35-AP35 -> 0 | AE35: 0 | AF35: 0 | AG35: 0 | AH35: 41 | AI35: =AI34-AH35 -> 5637.1579 | AK35: =N35+O35+P35+Q35+R35+S35+T35+U35+X35+AE35+AH35 -> 44.7 | AL35: =IF(L35<0,L35*-1,0) -> 0 | AM35: =AK35+AL35 -> 44.7 | AO35: =IF(G35="","",IF(I35>=795,795-X35,I35-Q35-R35-X35-AF35)-AJ35) -> 61.980768 | AW35: 0.65 | AX35: 48 | AY35: 32 | BA35: =SUM(N35,P35:U35) -> 3.7 | BB35: 0.65 | BC35: 15807 | BE35: =BE34+1 -> 21 | BF35: 6901.43 | BG35: =B35-BF35 -> -0.01 | BH35: 24.520833 | BI35: =AH35-BH35 -> 16.479167
A36: =A35+1 -> 22 | B36: 6901.43 | C36: =IF(B36="",C35,VLOOKUP(TRUNC(B36,1),VLOOKUP!$A$3:$K$2834,RIGHT(TEXT(B36,"0000.00"),1)+2,FALSE)) -> 288887 | D36: =C36-C35 -> 37 | E36: =C36-152000 -> 136887 | F36: =D36/$D$2 -> 18.653895 | G36: 59.4 | H36: 0 | I36: =G36+H36 -> 59.4 | J36: =IF(L36>0,L36,0) -> 2.8538946 | K36: =I36+J36 -> 62.253895 | L36: =IF(G36="",0,F36-(I36-AK36)) -> 2.8538946 | M36: 2.6 | N36: 0 | O36: =0*1.05 -> 0 | P36: 0 | Q36: =881000/325851/1.9835*1.02 -> 1.3903522 | R36: 0 | S36: =IF(((2.1*1.04)-T36)>=4.2,4.2,(2.1*1.04)-T36) -> 1.6845026 | T36: =(0.4531*1.06)*1.04 -> 0.49949744 | U36: =M36-(Q36+R36+S36+T36) -> -0.97435216 | V36: 0 | W36: 0 | X36: =MAX(0,M36-N36-O36-P36-Q36-R36-S36-T36-U36+V36+W36-AU36+AS36) -> 0 | Y36: =X36-AP36 -> 0 | AE36: 0 | AF36: 0 | AG36: 0 | AH36: 41 | AI36: =AI35-AH36 -> 5596.1579 | AK36: =N36+O36+P36+Q36+R36+S36+T36+U36+X36+AE36+AH36 -> 43.6 | AL36: =IF(L36<0,L36*-1,0) -> 0 | AM36: =AK36+AL36 -> 43.6 | AO36: =IF(G36="","",IF(I36>=795,795-X36,I36-Q36-R36-X36-AF36)-AJ36) -> 58.009648 | AW36: 0.02 | AX36: 46 | AY36: 29 | BA36: =SUM(N36,P36:U36) -> 2.6 | BB36: 0.642 | BC36: 15817 | BE36: =BE35+1 -> 22 | BF36: 6901.44 | BG36: =B36-BF36 -> -0.01 | BH36: 24.979167 | BI36: =AH36-BH36 -> 16.020833
A37: =A36+1 -> 23 | B37: 6901.41 | C37: =IF(B37="",C36,VLOOKUP(TRUNC(B37,1),VLOOKUP!$A$3:$K$2834,RIGHT(TEXT(B37,"0000.00"),1)+2,FALSE)) -> 288812 | D37: =C37-C36 -> -75 | E37: =C37-152000 -> 136812 | F37: =D37/$D$2 -> -37.811949 | G37: 44.6 | H37: 0 | I37: =G37+H37 -> 44.6 | J37: =IF(L37>0,L37,0) -> 0 | K37: =I37+J37 -> 44.6 | L37: =IF(G37="",0,F37-(I37-AK37)) -> -37.911949 | M37: 3.5 | N37: 0 | O37: =0*1.05 -> 0 | P37: 0 | Q37: =887400/325851/1.9835*1.02 -> 1.4004523 | R37: 0 | S37: =IF(((2*1.04)-T37)>=4.2,4.2,(2*1.04)-T37) -> 1.5805026 | T37: =(0.4531*1.06)*1.04 -> 0.49949744 | U37: =M37-(Q37+R37+S37+T37) -> 0.019547661 | V37: 0 | W37: 0 | X37: =MAX(0,M37-N37-O37-P37-Q37-R37-S37-T37-U37+V37+W37-AU37+AS37) -> 0 | Y37: =X37-AP37 -> 0 | AE37: 0 | AF37: 0 | AG37: 0 | AH37: 41 | AI37: =AI36-AH37 -> 5555.1579 | AK37: =N37+O37+P37+Q37+R37+S37+T37+U37+X37+AE37+AH37 -> 44.5 | AL37: =IF(L37<0,L37*-1,0) -> 37.911949 | AM37: =AK37+AL37 -> 82.411949 | AO37: =IF(G37="","",IF(I37>=795,795-X37,I37-Q37-R37-X37-AF37)-AJ37) -> 43.199548 | AW37: 0 | AX37: 50 | AY37: 24 | BA37: =SUM(N37,P37:U37) -> 3.5 | BB37: 0.648 | BC37: 15816 | BE37: =BE36+1 -> 23 | BF37: 6901.43 | BG37: =B37-BF37 -> -0.02 | BH37: 25.001042 | BI37: =AH37-BH37 -> 15.998958
A38: =A37+1 -> 24 | B38: 6901.39 | C38: =IF(B38="",C37,VLOOKUP(TRUNC(B38,1),VLOOKUP!$A$3:$K$2834,RIGHT(TEXT(B38,"0000.00"),1)+2,FALSE)) -> 288738 | D38: =C38-C37 -> -74 | E38: =C38-152000 -> 136738 | F38: =D38/$D$2 -> -37.307789 | G38: 39.4 | H38: 0 | I38: =G38+H38 -> 39.4 | J38: =IF(L38>0,L38,0) -> 0 | K38: =I38+J38 -> 39.4 | L38: =IF(G38="",0,F38-(I38-AK38)) -> -33.107789 | M38: 2.6 | N38: 0 | O38: =0*1.05 -> 0 | P38: 0 | Q38: =1121500/325851/1.9835*1.02 -> 1.7698978 | R38: 0 | S38: =IF(((2*1.04)-T38)>=4.2,4.2,(2*1.04)-T38) -> 1.5805026 | T38: =(0.4531*1.06)*1.04 -> 0.49949744 | U38: =M38-(Q38+R38+S38+T38) -> -1.2498978 | V38: 0 | W38: 0 | X38: =MAX(0,M38-N38-O38-P38-Q38-R38-S38-T38-U38+V38+W38-AU38+AS38) -> 0 | Y38: =X38-AP38 -> 0 | AE38: 0 | AF38: 0 | AG38: 0 | AH38: 41 | AI38: =AI37-AH38 -> 5514.1579 | AK38: =N38+O38+P38+Q38+R38+S38+T38+U38+X38+AE38+AH38 -> 43.6 | AL38: =IF(L38<0,L38*-1,0) -> 33.107789 | AM38: =AK38+AL38 -> 76.707789 | AO38: =IF(G38="","",IF(I38>=795,795-X38,I38-Q38-R38-X38-AF38)-AJ38) -> 37.630102 | AW38: 0 | AX38: 50 | AY38: 22 | BA38: =SUM(N38,P38:U38) -> 2.6 | BB38: 0.594 | BC38: 15815 | BE38: =BE37+1 -> 24 | BF38: 6901.42 | BG38: =B38-BF38 -> -0.03 | BH38: 24.942708 | BI38: =AH38-BH38 -> 16.057292
A39: =A38+1 -> 25 | B39: 6901.39 | C39: =IF(B39="",C38,VLOOKUP(TRUNC(B39,1),VLOOKUP!$A$3:$K$2834,RIGHT(TEXT(B39,"0000.00"),1)+2,FALSE)) -> 288738 | D39: =C39-C38 -> 0 | E39: =C39-152000 -> 136738 | F39: =D39/$D$2 -> 0 | G39: 36.2 | H39: 0 | I39: =G39+H39 -> 36.2 | J39: =IF(L39>0,L39,0) -> 8.3 | K39: =I39+J39 -> 44.5 | L39: =IF(G39="",0,F39-(I39-AK39)) -> 8.3 | M39: 3.5 | N39: 0 | O39: =0*1.05 -> 0 | P39: 0 | Q39: =1050600/325851/1.9835*1.02 -> 1.6580068 | R39: 0 | S39: =IF(((2.1*1.04)-T39)>=4.2,4.2,(2.1*1.04)-T39) -> 1.6845026 | T39: =(0.4531*1.06)*1.04 -> 0.49949744 | U39: =M39-(Q39+R39+S39+T39) -> -0.34200679 | V39: 0 | W39: 0 | X39: =MAX(0,M39-N39-O39-P39-Q39-R39-S39-T39-U39+V39+W39-AU39+AS39) -> 0 | Y39: =X39-AP39 -> 0 | AE39: 0 | AF39: 0 | AG39: 0 | AH39: 41 | AI39: =AI38-AH39 -> 5473.1579 | AK39: =N39+O39+P39+Q39+R39+S39+T39+U39+X39+AE39+AH39 -> 44.5 | AL39: =IF(L39<0,L39*-1,0) -> 0 | AM39: =AK39+AL39 -> 44.5 | AO39: =IF(G39="","",IF(I39>=795,795-X39,I39-Q39-R39-X39-AF39)-AJ39) -> 34.541993 | AW39: 0 | AX39: 49 | AY39: 25 | BA39: =SUM(N39,P39:U39) -> 3.5 | BB39: 0.636 | BC39: 15809 | BE39: =BE38+1 -> 25 | BF39: 6901.46 | BG39: =B39-BF39 -> -0.07 | BH39: 24.965625 | BI39: =AH39-BH39 -> 16.034375
A40: =A39+1 -> 26 | B40: 6901.39 | C40: =IF(B40="",C39,VLOOKUP(TRUNC(B40,1),VLOOKUP!$A$3:$K$2834,RIGHT(TEXT(B40,"0000.00"),1)+2,FALSE)) -> 288738 | D40: =C40-C39 -> 0 | E40: =C40-152000 -> 136738 | F40: =D40/$D$2 -> 0 | G40: 23.2 | H40: 0 | I40: =G40+H40 -> 23.2 | J40: =IF(L40>0,L40,0) -> 21.2 | K40: =I40+J40 -> 44.4 | L40: =IF(G40="",0,F40-(I40-AK40)) -> 21.2 | M40: 3.4 | N40: 0 | O40: =0*1.05 -> 0 | P40: 0 | Q40: =881800/325851/1.9835*1.02 -> 1.3916147 | R40: 0 | S40: =IF(((2*1.04)-T40)>=4.2,4.2,(2*1.04)-T40) -> 1.5805026 | T40: =(0.4531*1.06)*1.04 -> 0.49949744 | U40: =M40-(Q40+R40+S40+T40) -> -0.071614686 | V40: 0 | W40: 0 | X40: =MAX(0,M40-N40-O40-P40-Q40-R40-S40-T40-U40+V40+W40-AU40+AS40) -> 0 | Y40: =X40-AP40 -> 0 | AE40: 0 | AF40: 0 | AG40: 0 | AH40: 41 | AI40: =AI39-AH40 -> 5432.1579 | AK40: =N40+O40+P40+Q40+R40+S40+T40+U40+X40+AE40+AH40 -> 44.4 | AL40: =IF(L40<0,L40*-1,0) -> 0 | AM40: =AK40+AL40 -> 44.4 | AO40: =IF(G40="","",IF(I40>=795,795-X40,I40-Q40-R40-X40-AF40)-AJ40) -> 21.808385 | AW40: 0 | AX40: 30 | AY40: 9 | BA40: =SUM(N40,P40:U40) -> 3.4 | BB40: 0.619 | BC40: 15832 | BE40: =BE39+1 -> 26 | BF40: 6901.4 | BG40: =B40-BF40 -> -0.01 | BH40: 25.003125 | BI40: =AH40-BH40 -> 15.996875
A41: =A40+1 -> 27 | B41: 6901.39 | C41: =IF(B41="",C40,VLOOKUP(TRUNC(B41,1),VLOOKUP!$A$3:$K$2834,RIGHT(TEXT(B41,"0000.00"),1)+2,FALSE)) -> 288738 | D41: =C41-C40 -> 0 | E41: =C41-152000 -> 136738 | F41: =D41/$D$2 -> 0 | G41: 22.7 | H41: 0 | I41: =G41+H41 -> 22.7 | J41: =IF(L41>0,L41,0) -> 19.7 | K41: =I41+J41 -> 42.4 | L41: =IF(G41="",0,F41-(I41-AK41)) -> 19.7 | M41: 2.4 | N41: 0 | O41: =0*1.05 -> 0 | P41: 0 | Q41: =989800/325851/1.9835*1.02 -> 1.5620551 | R41: 0 | S41: =IF(((2*1.04)-T41)>=4.2,4.2,(2*1.04)-T41) -> 1.5805026 | T41: =(0.4531*1.06)*1.04 -> 0.49949744 | U41: =M41-(Q41+R41+S41+T41) -> -1.2420551 | V41: 0 | W41: 0 | X41: =MAX(0,M41-N41-O41-P41-Q41-R41-S41-T41-U41+V41+W41-AU41+AS41) -> 0 | Y41: =X41-AP41 -> 0 | AE41: 0 | AF41: 0 | AG41: 0 | AH41: 40 | AI41: =AI40-AH41 -> 5392.1579 | AK41: =N41+O41+P41+Q41+R41+S41+T41+U41+X41+AE41+AH41 -> 42.4 | AL41: =IF(L41<0,L41*-1,0) -> 0 | AM41: =AK41+AL41 -> 42.4 | AO41: =IF(G41="","",IF(I41>=795,795-X41,I41-Q41-R41-X41-AF41)-AJ41) -> 21.137945 | AW41: 0.01 | AX41: 43 | AY41: 9 | BA41: =SUM(N41,P41:U41) -> 2.4 | BB41: 0.65 | BC41: 15832 | BE41: =BE40+1 -> 27 | BF41: 6901.4 | BG41: =B41-BF41 -> -0.01 | BH41: 25.02 | BI41: =AH41-BH41 -> 14.98
A42: =A41+1 -> 28 | B42: 6901.4 | C42: =IF(B42="",C41,VLOOKUP(TRUNC(B42,1),VLOOKUP!$A$3:$K$2834,RIGHT(TEXT(B42,"0000.00"),1)+2,FALSE)) -> 288775 | D42: =C42-C41 -> 37 | E42: =C42-152000 -> 136775 | F42: =D42/$D$2 -> 18.653895 | G42: 26 | H42: 0 | I42: =G42+H42 -> 26 | J42: =IF(L42>0,L42,0) -> 35.853895 | K42: =I42+J42 -> 61.853895 | L42: =IF(G42="",0,F42-(I42-AK42)) -> 35.853895 | M42: 3.2 | N42: 0 | O42: =0*1.05 -> 0 | P42: 0 | Q42: =904000/325851/1.9835*1.02 -> 1.4266497 | R42: 0 | S42: =IF(((2.1*1.04)-T42)>=4.2,4.2,(2.1*1.04)-T42) -> 1.6845026 | T42: =(0.4531*1.06)*1.04 -> 0.49949744 | U42: =M42-(Q42+R42+S42+T42) -> -0.41064967 | V42: 0 | W42: 0 | X42: =MAX(0,M42-N42-O42-P42-Q42-R42-S42-T42-U42+V42+W42-AU42+AS42) -> 0 | Y42: =X42-AP42 -> 0 | AE42: 0 | AF42: 0 | AG42: 0 | AH42: 40 | AI42: =AI41-AH42 -> 5352.1579 | AK42: =N42+O42+P42+Q42+R42+S42+T42+U42+X42+AE42+AH42 -> 43.2 | AL42: =IF(L42<0,L42*-1,0) -> 0 | AM42: =AK42+AL42 -> 43.2 | AO42: =IF(G42="","",IF(I42>=795,795-X42,I42-Q42-R42-X42-AF42)-AJ42) -> 24.57335 | AW42: 0.11 | AX42: 46 | AY42: 35 | BA42: =SUM(N42,P42:U42) -> 3.2 | BB42: 0.558 | BC42: 15827 | BE42: =BE41+1 -> 28 | BF42: 6901.38 | BG42: =B42-BF42 -> 0.02 | BH42: 14.189583 | BI42: =AH42-BH42 -> 25.810417
...

Sheet DEC
K1: MCPHEE RESERVOIR INFLOW/OUTFLOW TABULATION
A2: AF/cfs CONVERT FACTOR | D2: 1.9835 | K2: DECEMBER "2019"
D4: RESERVOIR | I4: INFLOW | X4: OUTFLOW | AQ4: ADJUSTMENTS | AX4: WEATHER
A5: DATE | B5: RESERV | C5: RESERV | D5: AC FT | E5: ACTIVE | F5: CONV TO | G5: DOLORES | H5: LOST | I5: RECORD | J5: CALC | K5: TOTAL | L5: CALC | M5: DOLORES TUNNEL | V5: LONE | W5: U | X5: TOTAL | Y5: TOTAL | Z5: MVI | AA5: MVI | AB5: MVI | AC5: TO EX & | AD5: MVI | AE5: DV CR | AF5: D/S SENIOR | AH5: BELOW | AI5: FISH | AJ5: SPILL | AK5: RECORD | AL5: CALC | AM5: TOTAL | AN5: NAR | AO5: NARR | AP5: MVI | AQ5: MVI | AR5: MVI | AS5: DIST. | AT5: U/S | AU5: TOTTEN | AV5: UF&R | AW5: RAIN | AX5: MAX | AY5: MIN | BA5: TOTAL | BB5: GRNDHOG | BC5: GRNDHOG | BF5: RESERV | BH5: BELOW | BI5: BELOW
A6: DEC | B6: ELEV | D6: CHANGE | E6: CAP | F6: CFS | G6: RIVER | H6: CAN | I6: INFLOW | J6: INFLOW | K6: INFLOW | L6: INF/OTF | M6: TOT DIV | N6: WET | O6: UTE | P6: QUEST | Q6: MWC | R6: CORTEZ | T6: UTE | U6: F-BAY | V6: PINE | W6: LAT | X6: MVI | Y6: MVI | Z6: CALL | AA6: CALL | AB6: APR- | AC6: U/S EX | AD6: PROJ | AE6: CANAL | AF6: MVIC | AG6: PROJ | AH6: MCP | AI6: LEFT | AK6: OTF | AL6: OTF | AM6: OTF | AN6: FILL | AO6: FILL | AP6: STOCK | AQ6: STORED | AR6: STORED | AS6: CLASS | AT6: USERS | AU6: (FRESH | AV6: LEASE | AX6: TMP | AY6: TMP | BA6: TUNNEL | BB6: DISCHARGE | BC6: CAPACITY | BF6: ELEV | BH6: MCP | BI6: MCP
N7: LAND | O7: F&R | Q7: NON - | R7: NON - | S7: PROJ | T7: PROJ | U7: BAL | X7: WATER | Y7: IRRIG. | Z7: STOR | AA7: SPILLED | AB7: JUNE | AF7: 1.7 | AG7: 1.3 | AO7: IN | AQ7: Apr - Jun | AR7: EVAP | AS7: "B" | AT7: EXCH | AU7: WATER) | AV7: WATER | BA7: Misc. | BF7: DTGH | BH7: MPP | BI7: OVER
Q8: PROJ | R8: PROJ | X8: USED | Y8: WATER | AA8: OR | AB8: (DIV+ | AO8: MCPHEE | BI8: MPP
R9: 4.2 | Y9: USED | AA9: USED | AB9: CALL) | BC9: FP = 3960
C10: AC. Ft. | E10: AC FT | G10: CFS | H10: CFS | I10: CFS | J10: CFS | K10: CFS | L10: CFS | M10: CFS | N10: CFS | O10: CFS | P10: CFS | Q10: CFS | R10: CFS | S10: CFS | T10: CFS | U10: CFS | V10: CFS | W10: CFS | X10: 153400 | Y10: 150400 | AB10: 72000 | AC10: CFS | AD10: CFS | AE10: CFS | AF10: CFS | AG10: CFS | AH10: CFS | AI10: CFS | AJ10: CFS | AK10: CFS | AL10: CFS | AM10: CFS | AN10: CFS | AO10: CFS | AP10: CFS | AQ10: CFS | AR10: AC.FT. | AS10: CFS | AT10: CFS | AU10: CFS | AV10: CFS | BA10: Outflow | BB10: CFS | BC10: AC FT | BH10: CFS | BI10: CFS
N11: 1.03 | O11: 1.05 | P11: 1.02 | Q11: 1.02 | R11: 1.04 | T11: 1.04 | X11: CFS | Y11: CFS | Z11: CFS | AA11: CFS | AB11: Ac. Ft. | BA11: CFS
A12: SEASON BAL
A13: YTD | B13: =NOV!B44 -> 6901.39 | C13: =NOV!C44 -> 288738 | D13: =NOV!D53 -> -2954 | E13: =NOV!E53 -> 136738 | F13: =NOV!F52 -> -1489.2866 | G13: =NOV!G52 -> 1189.3 | H13: =NOV!H52 -> 0 | I13: =NOV!I52 -> 1189.3 | J13: =NOV!J52 -> 381.78311 | K13: =NOV!K52 -> 1571.0831 | L13: =NOV!L52 -> -137.78661 | M13: =NOV!M52 -> 114.8 | ... Y13: =NOV!Y52 -> 1242 | AC13: =NOV!AC52 -> 0 | AH13: =NOV!AH52 -> 1184 | AI13: =NOV!AI52 -> 5272.1579 | AK13: =NOV!AK52 -> 2540.8 | AL13: =NOV!AL52 -> 519.56973 | AM13: =NOV!AM52 -> 3060.3697 | AN13: =NOV!AN52 -> 1242 | AO13: =NOV!AO52 -> -103.00139 | AP13: =NOV!AP52 -> 0 | AW13: =NOV!AW52 -> 1.26 | BA13: =NOV!BA52 -> 114.8 | BB13: =NOV!BB52 -> 28.308 | BH13: =NOV!BH46 -> 735.86686 | BI13: =NOV!BI46 -> 448.13314
A15: 1 | B15: 6901.39 | C15: =IF(B15="",C13,VLOOKUP(TRUNC(B15,1),VLOOKUP!$A$3:$K$2834,RIGHT(TEXT(B15,"0000.00"),1)+2,FALSE)) -> 288738 | D15: =C15-C13 -> 0 | E15: =C15-152000 -> 136738 | F15: =D15/$D$2 -> 0 | G15: 17.7 | H15: 0 | I15: =G15+H15 -> 17.7 | J15: =IF(L15>0,L15,0) -> 25.8 | K15: =I15+J15 -> 43.5 | L15: =IF(G15="",0,F15-(I15-AK15)) -> 25.8 | M15: 3.5 | N15: 0 | O15: =0*1.05 -> 0 | P15: 0 | Q15: =1036000/325851/1.9835*1.02 -> 1.6349658 | R15: 0 | S15: =IF(((2*1.04)-T15)>=4.2,4.2,(2*1.04)-T15) -> 1.6176534 | T15: =(0.4194*1.06)*1.04 -> 0.46234656 | U15: =M15-(Q15+R15+S15+T15) -> -0.21496577 | V15: 0 | W15: 0 | X15: =MAX(0,M15-N15-P15-O15-Q15-R15-S15-T15-U15+V15+W15-AU15+AS15) -> 0 | Y15: =X15-AP15 -> 0 | AE15: 0 | AH15: 40 | AI15: =AI13-AH15 -> 5232.1579 | AK15: =N15+O15+P15+Q15+R15+S15+T15+U15+X15+AE15+AH15 -> 43.5 | AL15: =IF(L15<0,L15*-1,0) -> 0 | AM15: =AK15+AL15 -> 43.5 | AO15: =IF(G15="","",IF(I15>=795,795-X15,I15-Q15-R15-X15-AF15)-AJ15) -> 16.065034 | AW15: 0 | AX15: 40 | AY15: 11 | BA15: =SUM(N15,P15:U15) -> 3.5 | BB15: 0.487 | BC15: 15855 | BE15: 1 | BF15: 6901.39 | BG15: =B15-BF15 -> 0 | BH15: 27.895833 | BI15: =AH15-BH15 -> 12.104167
A16: =A15+1 -> 2 | B16: 6901.39 | C16: =IF(B16="",C15,VLOOKUP(TRUNC(B16,1),VLOOKUP!$A$3:$K$2834,RIGHT(TEXT(B16,"0000.00"),1)+2,FALSE)) -> 288738 | D16: =C16-C15 -> 0 | E16: =C16-152000 -> 136738 | F16: =D16/$D$2 -> 0 | G16: 20.8 | H16: 0 | I16: =G16+H16 -> 20.8 | J16: =IF(L16>0,L16,0) -> 22.2 | K16: =I16+J16 -> 43 | L16: =IF(G16="",0,F16-(I16-AK16)) -> 22.2 | M16: 3 | N16: 0 | O16: =0*1.05 -> 0 | P16: 0 | Q16: =1067500/325851/1.9835*1.02 -> 1.6846776 | R16: 0 | S16: =IF(((2*1.04)-T16)>=4.2,4.2,(2*1.04)-T16) -> 1.6176534 | T16: =(0.4194*1.06)*1.04 -> 0.46234656 | U16: =M16-(Q16+R16+S16+T16) -> -0.76467757 | V16: 0 | W16: 0 | X16: =MAX(0,M16-N16-P16-O16-Q16-R16-S16-T16-U16+V16+W16-AU16+AS16) -> 0 | Y16: =X16-AP16 -> 0 | AE16: 0 | AH16: 40 | AI16: =AI15-AH16 -> 5192.1579 | AK16: =N16+O16+P16+Q16+R16+S16+T16+U16+X16+AE16+AH16 -> 43 | AL16: =IF(L16<0,L16*-1,0) -> 0 | AM16: =AK16+AL16 -> 43 | AO16: =IF(G16="","",IF(I16>=795,795-X16,I16-Q16-R16-X16-AF16)-AJ16) -> 19.115322 | AW16: 0 | AX16: 51 | AY16: 22 | BA16: =SUM(N16,P16:U16) -> 3 | BB16: 0.487 | BC16: 15855 | BE16: =BE15+1 -> 2 | BF16: 6901.39 | BG16: =B16-BF16 -> 0 | BH16: 27.595833 | BI16: =AH16-BH16 -> 12.404167
A17: =A16+1 -> 3 | B17: 6901.4 | C17: =IF(B17="",C16,VLOOKUP(TRUNC(B17,1),VLOOKUP!$A$3:$K$2834,RIGHT(TEXT(B17,"0000.00"),1)+2,FALSE)) -> 288775 | D17: =C17-C16 -> 37 | E17: =C17-152000 -> 136775 | F17: =D17/$D$2 -> 18.653895 | G17: 30.4 | H17: 0 | I17: =G17+H17 -> 30.4 | J17: =IF(L17>0,L17,0) -> 31.753895 | K17: =I17+J17 -> 62.153895 | L17: =IF(G17="",0,F17-(I17-AK17)) -> 31.753895 | M17: 3.5 | N17: 0 | O17: =0*1.05 -> 0 | P17: 0 | Q17: =1114600/325851/1.9835*1.02 -> 1.7590085 | R17: 0 | S17: =IF(((2.1*1.04)-T17)>=4.2,4.2,(2.1*1.04)-T17) -> 1.7216534 | T17: =(0.4194*1.06)*1.04 -> 0.46234656 | U17: =M17-(Q17+R17+S17+T17) -> -0.44300854 | V17: 0 | W17: 0 | X17: =MAX(0,M17-N17-P17-O17-Q17-R17-S17-T17-U17+V17+W17-AU17+AS17) -> 5.5511151e-17 | Y17: =X17-AP17 -> 5.5511151e-17 | AE17: 0 | AH17: 40 | AI17: =AI16-AH17 -> 5152.1579 | AK17: =N17+O17+P17+Q17+R17+S17+T17+U17+X17+AE17+AH17 -> 43.5 | AL17: =IF(L17<0,L17*-1,0) -> 0 | AM17: =AK17+AL17 -> 43.5 | AO17: =IF(G17="","",IF(I17>=795,795-X17,I17-Q17-R17-X17-AF17)-AJ17) -> 28.640991 | AW17: 0 | AX17: 50 | AY17: 27 | BA17: =SUM(N17,P17:U17) -> 3.5 | BB17: 0.531 | BC17: 15853 | BE17: =BE16+1 -> 3 | BF17: 6901.39 | BG17: =B17-BF17 -> 0.01 | BH17: 27.74375 | BI17: =AH17-BH17 -> 12.25625
A18: =A17+1 -> 4 | B18: 6901.4 | C18: =IF(B18="",C17,VLOOKUP(TRUNC(B18,1),VLOOKUP!$A$3:$K$2834,RIGHT(TEXT(B18,"0000.00"),1)+2,FALSE)) -> 288775 | D18: =C18-C17 -> 0 | E18: =C18-152000 -> 136775 | F18: =D18/$D$2 -> 0 | G18: 33.5 | H18: 0 | I18: =G18+H18 -> 33.5 | J18: =IF(L18>0,L18,0) -> 10.2 | K18: =I18+J18 -> 43.7 | L18: =IF(G18="",0,F18-(I18-AK18)) -> 10.2 | M18: 3.7 | N18: 0 | O18: =0*1.05 -> 0 | P18: 0 | Q18: =1098200/325851/1.9835*1.02 -> 1.7331268 | R18: 0 | S18: =IF(((2.2*1.04)-T18)>=4.2,4.2,(2.2*1.04)-T18) -> 1.8256534 | T18: =(0.4194*1.06)*1.04 -> 0.46234656 | U18: =M18-(Q18+R18+S18+T18) -> -0.32112684 | V18: 0 | W18: 0 | X18: =MAX(0,M18-N18-P18-O18-Q18-R18-S18-T18-U18+V18+W18-AU18+AS18) -> 0 | Y18: =X18-AP18 -> 0 | AE18: 0 | AH18: 40 | AI18: =AI17-AH18 -> 5112.1579 | AK18: =N18+O18+P18+Q18+R18+S18+T18+U18+X18+AE18+AH18 -> 43.7 | AL18: =IF(L18<0,L18*-1,0) -> 0 | AM18: =AK18+AL18 -> 43.7 | AO18: =IF(G18="","",IF(I18>=795,795-X18,I18-Q18-R18-X18-AF18)-AJ18) -> 31.766873 | AW18: 0 | AX18: 53 | AY18: 30 | BA18: =SUM(N18,P18:U18) -> 3.7 | BB18: 0.716 | BC18: 15854 | BE18: =BE17+1 -> 4 | BF18: 6901.4 | BG18: =B18-BF18 -> 0 | BH18: 26.971717 | BI18: =AH18-BH18 -> 13.028283
A19: =A18+1 -> 5 | B19: 6901.41 | C19: =IF(B19="",C18,VLOOKUP(TRUNC(B19,1),VLOOKUP!$A$3:$K$2834,RIGHT(TEXT(B19,"0000.00"),1)+2,FALSE)) -> 288812 | D19: =C19-C18 -> 37 | E19: =C19-152000 -> 136812 | F19: =D19/$D$2 -> 18.653895 | G19: 33.3 | H19: 0 | I19: =G19+H19 -> 33.3 | J19: =IF(L19>0,L19,0) -> 27.953895 | K19: =I19+J19 -> 61.253895 | L19: =IF(G19="",0,F19-(I19-AK19)) -> 27.953895 | M19: 2.6 | N19: 0 | O19: =0*1.05 -> 0 | P19: 0 | Q19: =985900/325851/1.9835*1.02 -> 1.5559003 | R19: 0 | S19: =IF(((1.5*1.04)-T19)>=4.2,4.2,(1.5*1.04)-T19) -> 1.0976534 | T19: =(0.4194*1.06)*1.04 -> 0.46234656 | U19: =M19-(Q19+R19+S19+T19) -> -0.51590034 | V19: 0 | W19: 0 | X19: =MAX(0,M19-N19-P19-O19-Q19-R19-S19-T19-U19+V19+W19-AU19+AS19) -> 0 | Y19: =X19-AP19 -> 0 | AE19: 0 | AH19: 40 | AI19: =AI18-AH19 -> 5072.1579 | AK19: =N19+O19+P19+Q19+R19+S19+T19+U19+X19+AE19+AH19 -> 42.6 | AL19: =IF(L19<0,L19*-1,0) -> 0 | AM19: =AK19+AL19 -> 42.6 | AO19: =IF(G19="","",IF(I19>=795,795-X19,I19-Q19-R19-X19-AF19)-AJ19) -> 31.7441 | AW19: 0.12 | AX19: 44 | AY19: 30 | BA19: =SUM(N19,P19:U19) -> 2.6 | BB19: 0.813 | BC19: 15868 | BE19: =BE18+1 -> 5 | BF19: 6901.45 | BG19: =B19-BF19 -> -0.04 | BH19: 27.898958 | BI19: =AH19-BH19 -> 12.101042
A20: =A19+1 -> 6 | B20: 6901.43 | C20: =IF(B20="",C19,VLOOKUP(TRUNC(B20,1),VLOOKUP!$A$3:$K$2834,RIGHT(TEXT(B20,"0000.00"),1)+2,FALSE)) -> 288887 | D20: =C20-C19 -> 75 | E20: =C20-152000 -> 136887 | F20: =D20/$D$2 -> 37.811949 | G20: 28.8 | H20: 0 | I20: =G20+H20 -> 28.8 | J20: =IF(L20>0,L20,0) -> 51.911949 | K20: =I20+J20 -> 80.711949 | L20: =IF(G20="",0,F20-(I20-AK20)) -> 51.911949 | M20: 2.9 | N20: 0 | O20: =0*1.05 -> 0 | P20: 0 | Q20: =1022800/325851/1.9835*1.02 -> 1.6141342 | R20: 0 | S20: =IF(((1.8*1.04)-T20)>=4.2,4.2,(1.8*1.04)-T20) -> 1.3055869 | T20: =(0.5138*1.06)*1.04 -> 0.56641312 | U20: =M20-(Q20+R20+S20+T20) -> -0.58613416 | V20: 0 | W20: 0 | X20: =MAX(0,M20-N20-P20-O20-Q20-R20-S20-T20-U20+V20+W20-AU20+AS20) -> 0 | Y20: =X20-AP20 -> 0 | AE20: 0 | AH20: 40 | AI20: =AI19-AH20 -> 5032.1579 | AK20: =N20+O20+P20+Q20+R20+S20+T20+U20+X20+AE20+AH20 -> 42.9 | AL20: =IF(L20<0,L20*-1,0) -> 0 | AM20: =AK20+AL20 -> 42.9 | AO20: =IF(G20="","",IF(I20>=795,795-X20,I20-Q20-R20-X20-AF20)-AJ20) -> 27.185866 | AW20: 0.09 | AX20: 52 | AY20: 24 | BA20: =SUM(N20,P20:U20) -> 2.9 | BB20: 0.867 | BC20: 15874 | BE20: =BE19+1 -> 6 | BF20: 6901.45 | BG20: =B20-BF20 -> -0.02 | BH20: 27.78125 | BI20: =AH20-BH20 -> 12.21875
A21: =A20+1 -> 7 | B21: 6901.45 | C21: =IF(B21="",C20,VLOOKUP(TRUNC(B21,1),VLOOKUP!$A$3:$K$2834,RIGHT(TEXT(B21,"0000.00"),1)+2,FALSE)) -> 288962 | D21: =C21-C20 -> 75 | E21: =C21-152000 -> 136962 | F21: =D21/$D$2 -> 37.811949 | G21: 30.1 | H21: 0 | I21: =G21+H21 -> 30.1 | J21: =IF(L21>0,L21,0) -> 51.111949 | K21: =I21+J21 -> 81.211949 | L21: =IF(G21="",0,F21-(I21-AK21)) -> 51.111949 | M21: 3.4 | N21: 0 | O21: =0*1.05 -> 0 | P21: 0 | Q21: =943500/325851/1.9835*1.02 -> 1.4889867 | R21: 0 | S21: =IF(((1.7*1.04)-T21)>=4.2,4.2,(1.7*1.04)-T21) -> 1.2015869 | T21: =(0.5138*1.06)*1.04 -> 0.56641312 | U21: =M21-(Q21+R21+S21+T21) -> 0.14301332 | V21: 0 | W21: 0 | X21: =MAX(0,M21-N21-P21-O21-Q21-R21-S21-T21-U21+V21+W21-AU21+AS21) -> 0 | Y21: =X21-AP21 -> 0 | AE21: 0 | AH21: 40 | AI21: =AI20-AH21 -> 4992.1579 | AK21: =N21+O21+P21+Q21+R21+S21+T21+U21+X21+AE21+AH21 -> 43.4 | AL21: =IF(L21<0,L21*-1,0) -> 0 | AM21: =AK21+AL21 -> 43.4 | AO21: =IF(G21="","",IF(I21>=795,795-X21,I21-Q21-R21-X21-AF21)-AJ21) -> 28.611013 | AW21: 0.17 | AX21: 53 | AY21: 28 | BA21: =SUM(N21,P21:U21) -> 3.4 | BB21: 0.975 | BC21: 15873 | BE21: =BE20+1 -> 7 | BF21: 6901.47 | BG21: =B21-BF21 -> -0.02 | BH21: 27.898958 | BI21: =AH21-BH21 -> 12.101042
A22: =A21+1 -> 8 | B22: 6901.5 | C22: =IF(B22="",C21,VLOOKUP(TRUNC(B22,1),VLOOKUP!$A$3:$K$2834,RIGHT(TEXT(B22,"0000.00"),1)+2,FALSE)) -> 289148 | D22: =C22-C21 -> 186 | E22: =C22-152000 -> 137148 | F22: =D22/$D$2 -> 93.773632 | G22: 36.3 | H22: 0 | I22: =G22+H22 -> 36.3 | J22: =IF(L22>0,L22,0) -> 99.473632 | K22: =I22+J22 -> 135.77363 | L22: =IF(G22="",0,F22-(I22-AK22)) -> 99.473632 | M22: 2 | N22: 0 | O22: =0*1.05 -> 0 | P22: 0 | Q22: =1378100/325851/1.9835*1.02 -> 2.1748517 | R22: 0 | S22: =IF(((2.3*1.04)-T22)>=4.2,4.2,(2.3*1.04)-T22) -> 1.8255869 | T22: =(0.5138*1.06)*1.04 -> 0.56641312 | U22: =M22-(Q22+R22+S22+T22) -> -2.5668517 | V22: 0 | W22: 0 | X22: =MAX(0,M22-N22-P22-O22-Q22-R22-S22-T22-U22+V22+W22-AU22+AS22) -> 0 | Y22: =X22-AP22 -> 0 | AE22: 0 | AH22: 40 | AI22: =AI21-AH22 -> 4952.1579 | AK22: =N22+O22+P22+Q22+R22+S22+T22+U22+X22+AE22+AH22 -> 42 | AL22: =IF(L22<0,L22*-1,0) -> 0 | AM22: =AK22+AL22 -> 42 | AO22: =IF(G22="","",IF(I22>=795,795-X22,I22-Q22-R22-X22-AF22)-AJ22) -> 34.125148 | AW22: 0.29 | AX22: 45 | AY22: 31 | BA22: =SUM(N22,P22:U22) -> 2 | BB22: 0.975 | BC22: 15883 | BE22: =BE21+1 -> 8 | BF22: 6901.51 | BG22: =B22-BF22 -> -0.01 | BH22: 27.864583 | BI22: =AH22-BH22 -> 12.135417
A23: =A22+1 -> 9 | B23: 6901.5 | C23: =IF(B23="",C22,VLOOKUP(TRUNC(B23,1),VLOOKUP!$A$3:$K$2834,RIGHT(TEXT(B23,"0000.00"),1)+2,FALSE)) -> 289148 | D23: =C23-C22 -> 0 | E23: =C23-152000 -> 137148 | F23: =D23/$D$2 -> 0 | G23: 29.5 | H23: 0 | I23: =G23+H23 -> 29.5 | J23: =IF(L23>0,L23,0) -> 13.9 | K23: =I23+J23 -> 43.4 | L23: =IF(G23="",0,F23-(I23-AK23)) -> 13.9 | M23: 3.4 | N23: 0 | O23: =0*1.05 -> 0 | P23: 0 | Q23: =1029100/325851/1.9835*1.02 -> 1.6240765 | R23: 0 | S23: =IF(((2.7*1.04)-T23)>=4.2,4.2,(2.7*1.04)-T23) -> 2.2415869 | T23: =(0.5138*1.06)*1.04 -> 0.56641312 | U23: =M23-(Q23+R23+S23+T23) -> -1.0320765 | V23: 0 | W23: 0 | X23: =MAX(0,M23-N23-P23-O23-Q23-R23-S23-T23-U23+V23+W23-AU23+AS23) -> 0 | Y23: =X23-AP23 -> 0 | AE23: 0 | AH23: 40 | AI23: =AI22-AH23 -> 4912.1579 | AK23: =N23+O23+P23+Q23+R23+S23+T23+U23+X23+AE23+AH23 -> 43.4 | AL23: =IF(L23<0,L23*-1,0) -> 0 | AM23: =AK23+AL23 -> 43.4 | AO23: =IF(G23="","",IF(I23>=795,795-X23,I23-Q23-R23-X23-AF23)-AJ23) -> 27.875923 | AW23: 0.08 | AX23: 50 | AY23: 24 | BA23: =SUM(N23,P23:U23) -> 3.4 | BB23: 0.975 | BC23: 15905 | BE23: =BE22+1 -> 9 | BF23: 6901.51 | BG23: =B23-BF23 -> -0.01 | BH23: 27.880208 | BI23: =AH23-BH23 -> 12.119792
A24: =A23+1 -> 10 | B24: 6901.5 | C24: =IF(B24="",C23,VLOOKUP(TRUNC(B24,1),VLOOKUP!$A$3:$K$2834,RIGHT(TEXT(B24,"0000.00"),1)+2,FALSE)) -> 289148 | D24: =C24-C23 -> 0 | E24: =C24-152000 -> 137148 | F24: =D24/$D$2 -> 0 | G24: 19.1 | H24: 0 | I24: =G24+H24 -> 19.1 | J24: =IF(L24>0,L24,0) -> 23.3 | K24: =I24+J24 -> 42.4 | L24: =IF(G24="",0,F24-(I24-AK24)) -> 23.3 | M24: 2.4 | N24: 0 | O24: =0*1.05 -> 0 | P24: 0 | Q24: =797300/325851/1.9835*1.02 -> 1.2582608 | R24: 0 | S24: =IF(((2.7*1.04)-T24)>=4.2,4.2,(2.7*1.04)-T24) -> 2.2415869 | T24: =(0.5138*1.06)*1.04 -> 0.56641312 | U24: =M24-(Q24+R24+S24+T24) -> -1.6662608 | V24: 0 | W24: 0 | X24: =MAX(0,M24-N24-P24-O24-Q24-R24-S24-T24-U24+V24+W24-AU24+AS24) -> 0 | Y24: =X24-AP24 -> 0 | AE24: 0 | AH24: 40 | AI24: =AI23-AH24 -> 4872.1579 | AK24: =N24+O24+P24+Q24+R24+S24+T24+U24+X24+AE24+AH24 -> 42.4 | AL24: =IF(L24<0,L24*-1,0) -> 0 | AM24: =AK24+AL24 -> 42.4 | AO24: =IF(G24="","",IF(I24>=795,795-X24,I24-Q24-R24-X24-AF24)-AJ24) -> 17.841739 | AW24: 0 | AX24: 46 | AY24: 19 | BA24: =SUM(N24,P24:U24) -> 2.4 | BB24: 0.975 | BC24: 15906 | BE24: =BE23+1 -> 10 | BF24: 6901.51 | BG24: =B24-BF24 -> -0.01 | BH24: 27.165306 | BI24: =AH24-BH24 -> 12.834694
A25: =A24+1 -> 11 | B25: 6901.5 | C25: =IF(B25="",C24,VLOOKUP(TRUNC(B25,1),VLOOKUP!$A$3:$K$2834,RIGHT(TEXT(B25,"0000.00"),1)+2,FALSE)) -> 289148 | D25: =C25-C24 -> 0 | E25: =C25-152000 -> 137148 | F25: =D25/$D$2 -> 0 | G25: 18.2 | H25: 0 | I25: =G25+H25 -> 18.2 | J25: =IF(L25>0,L25,0) -> 22.37 | K25: =I25+J25 -> 40.57 | L25: =IF(G25="",0,F25-(I25-AK25)) -> 22.37 | M25: 0.57 | N25: 0 | O25: =0*1.05 -> 0 | P25: 0 | Q25: =980900/325851/1.9835*1.02 -> 1.5480096 | R25: 0 | S25: 0 | T25: =(0.5138*1.06)*1.04 -> 0.56641312 | U25: =M25-(Q25+R25+S25+T25) -> -1.5444227 | V25: 0 | W25: 0 | X25: =MAX(0,M25-N25-P25-O25-Q25-R25-S25-T25-U25+V25+W25-AU25+AS25) -> 0 | Y25: =X25-AP25 -> 0 | AE25: 0 | AH25: 40 | AI25: =AI24-AH25 -> 4832.1579 | AK25: =N25+O25+P25+Q25+R25+S25+T25+U25+X25+AE25+AH25 -> 40.57 | AL25: =IF(L25<0,L25*-1,0) -> 0 | AM25: =AK25+AL25 -> 40.57 | AO25: =IF(G25="","",IF(I25>=795,795-X25,I25-Q25-R25-X25-AF25)-AJ25) -> 16.65199 | AW25: 0 | AX25: 46 | AY25: 21 | BA25: =SUM(N25,P25:U25) -> 0.57 | BB25: 0.975 | BC25: 15905 | BE25: =BE24+1 -> 11 | BF25: 6901.51 | BG25: =B25-BF25 -> -0.01 | BH25: 27.469792 | BI25: =AH25-BH25 -> 12.530208
A26: =A25+1 -> 12 | B26: 6901.5 | C26: =IF(B26="",C25,VLOOKUP(TRUNC(B26,1),VLOOKUP!$A$3:$K$2834,RIGHT(TEXT(B26,"0000.00"),1)+2,FALSE)) -> 289148 | D26: =C26-C25 -> 0 | E26: =C26-152000 -> 137148 | F26: =D26/$D$2 -> 0 | G26: 29.6 | H26: 0 | I26: =G26+H26 -> 29.6 | J26: =IF(L26>0,L26,0) -> 11.8 | K26: =I26+J26 -> 41.4 | L26: =IF(G26="",0,F26-(I26-AK26)) -> 11.8 | M26: 1.4 | N26: 0 | O26: =0*1.05 -> 0 | P26: 0 | Q26: =1050200/325851/1.9835*1.02 -> 1.6573755 | R26: 0 | S26: 0 | T26: =(0.5138*1.06)*1.04 -> 0.56641312 | U26: =M26-(Q26+R26+S26+T26) -> -0.82378865 | V26: 0 | W26: 0 | X26: =MAX(0,M26-N26-P26-O26-Q26-R26-S26-T26-U26+V26+W26-AU26+AS26) -> 0 | Y26: =X26-AP26 -> 0 | AE26: 0 | AH26: 40 | AI26: =AI25-AH26 -> 4792.1579 | AK26: =N26+O26+P26+Q26+R26+S26+T26+U26+X26+AE26+AH26 -> 41.4 | AL26: =IF(L26<0,L26*-1,0) -> 0 | AM26: =AK26+AL26 -> 41.4 | AO26: =IF(G26="","",IF(I26>=795,795-X26,I26-Q26-R26-X26-AF26)-AJ26) -> 27.942624 | AW26: 0 | AX26: 48 | AY26: 21 | BA26: =SUM(N26,P26:U26) -> 1.4 | BB26: 0.975 | BC26: 15905 | BE26: =BE25+1 -> 12 | BF26: 6901.51 | BG26: =B26-BF26 -> -0.01 | BH26: 27.272917 | BI26: =AH26-BH26 -> 12.727083
A27: =A26+1 -> 13 | B27: 6901.5 | C27: =IF(B27="",C26,VLOOKUP(TRUNC(B27,1),VLOOKUP!$A$3:$K$2834,RIGHT(TEXT(B27,"0000.00"),1)+2,FALSE)) -> 289148 | D27: =C27-C26 -> 0 | E27: =C27-152000 -> 137148 | F27: =D27/$D$2 -> 0 | G27: 39.7 | H27: 0 | I27: =G27+H27 -> 39.7 | J27: =IF(L27>0,L27,0) -> 0.3 | K27: =I27+J27 -> 40 | L27: =IF(G27="",0,F27-(I27-AK27)) -> 0.3 | M27: 0 | N27: 0 | O27: =0*1.05 -> 0 | P27: 0 | Q27: =931600/325851/1.9835*1.02 -> 1.4702067 | R27: 0 | S27: 0 | T27: =(0.4883*1.06)*1.04 -> 0.53830192 | U27: =M27-(Q27+R27+S27+T27) -> -2.0085086 | V27: 0 | W27: 0 | X27: =MAX(0,M27-N27-P27-O27-Q27-R27-S27-T27-U27+V27+W27-AU27+AS27) -> 0 | Y27: =X27-AP27 -> 0 | AE27: 0 | AH27: 40 | AI27: =AI26-AH27 -> 4752.1579 | AK27: =N27+O27+P27+Q27+R27+S27+T27+U27+X27+AE27+AH27 -> 40 | AL27: =IF(L27<0,L27*-1,0) -> 0 | AM27: =AK27+AL27 -> 40 | AO27: =IF(G27="","",IF(I27>=795,795-X27,I27-Q27-R27-X27-AF27)-AJ27) -> 38.229793 | AW27: 0 | AX27: 49 | AY27: 28 | BA27: =SUM(N27,P27:U27) -> 0 | BB27: 1.2 | BC27: 15905 | BE27: =BE26+1 -> 13 | BF27: 6901.51 | BG27: =B27-BF27 -> -0.01 | BH27: 27.839583 | BI27: =AH27-BH27 -> 12.160417
A28: =A27+1 -> 14 | B28: 6901.5 | C28: =IF(B28="",C27,VLOOKUP(TRUNC(B28,1),VLOOKUP!$A$3:$K$2834,RIGHT(TEXT(B28,"0000.00"),1)+2,FALSE)) -> 289148 | D28: =C28-C27 -> 0 | E28: =C28-152000 -> 137148 | F28: =D28/$D$2 -> 0 | G28: 42.9 | H28: 0 | I28: =G28+H28 -> 42.9 | J28: =IF(L28>0,L28,0) -> 0 | K28: =I28+J28 -> 42.9 | L28: =IF(G28="",0,F28-(I28-AK28)) -> -1.98 | M28: 0.92 | N28: 0 | O28: =0*1.05 -> 0 | P28: 0 | Q28: =956000/325851/1.9835*1.02 -> 1.5087136 | R28: 0 | S28: 0 | T28: =(0.4883*1.06)*1.04 -> 0.53830192 | U28: =M28-(Q28+R28+S28+T28) -> -1.1270155 | V28: 0 | W28: 0 | X28: =MAX(0,M28-N28-P28-O28-Q28-R28-S28-T28-U28+V28+W28-AU28+AS28) -> 2.220446e-16 | Y28: =X28-AP28 -> 2.220446e-16 | AE28: 0 | AH28: 40 | AI28: =AI27-AH28 -> 4712.1579 | AK28: =N28+O28+P28+Q28+R28+S28+T28+U28+X28+AE28+AH28 -> 40.92 | AL28: =IF(L28<0,L28*-1,0) -> 1.98 | AM28: =AK28+AL28 -> 42.9 | AO28: =IF(G28="","",IF(I28>=795,795-X28,I28-Q28-R28-X28-AF28)-AJ28) -> 41.391286 | AW28: 0.04 | AX28: 46 | AY28: 31 | BA28: =SUM(N28,P28:U28) -> 0.92 | BB28: 1.3 | BC28: 15909 | BE28: =BE27+1 -> 14 | BF28: 6901.51 | BG28: =B28-BF28 -> -0.01 | BH28: 27.81875 | BI28: =AH28-BH28 -> 12.18125
A29: =A28+1 -> 15 | B29: 6901.5 | C29: =IF(B29="",C28,VLOOKUP(TRUNC(B29,1),VLOOKUP!$A$3:$K$2834,RIGHT(TEXT(B29,"0000.00"),1)+2,FALSE)) -> 289148 | D29: =C29-C28 -> 0 | E29: =C29-152000 -> 137148 | F29: =D29/$D$2 -> 0 | G29: 37.8 | H29: 0 | I29: =G29+H29 -> 37.8 | J29: =IF(L29>0,L29,0) -> 3.05 | K29: =I29+J29 -> 40.85 | L29: =IF(G29="",0,F29-(I29-AK29)) -> 3.05 | M29: 0.85 | N29: 0 | O29: =0*1.05 -> 0 | P29: 0 | Q29: =1063200/325851/1.9835*1.02 -> 1.6778915 | R29: 0 | S29: 0 | T29: =(0.4883*1.06)*1.04 -> 0.53830192 | U29: =M29-(Q29+R29+S29+T29) -> -1.3661934 | V29: 0 | W29: 0 | X29: =MAX(0,M29-N29-P29-O29-Q29-R29-S29-T29-U29+V29+W29-AU29+AS29) -> 0 | Y29: =X29-AP29 -> 0 | AE29: 0 | AH29: 40 | AI29: =AI28-AH29 -> 4672.1579 | AK29: =N29+O29+P29+Q29+R29+S29+T29+U29+X29+AE29+AH29 -> 40.85 | AL29: =IF(L29<0,L29*-1,0) -> 0 | AM29: =AK29+AL29 -> 40.85 | AO29: =IF(G29="","",IF(I29>=795,795-X29,I29-Q29-R29-X29-AF29)-AJ29) -> 36.122108 | AW29: 0.09 | AX29: 36 | AY29: 18 | BA29: =SUM(N29,P29:U29) -> 0.85 | BB29: 1.3 | BC29: 15915 | BE29: =BE28+1 -> 15 | BF29: 6901.51 | BG29: =B29-BF29 -> -0.01 | BH29: 27.794792 | BI29: =AH29-BH29 -> 12.205208
A30: =A29+1 -> 16 | B30: 6901.49 | C30: =IF(B30="",C29,VLOOKUP(TRUNC(B30,1),VLOOKUP!$A$3:$K$2834,RIGHT(TEXT(B30,"0000.00"),1)+2,FALSE)) -> 289111 | D30: =C30-C29 -> -37 | E30: =C30-152000 -> 137111 | F30: =D30/$D$2 -> -18.653895 | G30: 30.5 | H30: 0 | I30: =G30+H30 -> 30.5 | J30: =IF(L30>0,L30,0) -> 0 | K30: =I30+J30 -> 30.5 | L30: =IF(G30="",0,F30-(I30-AK30)) -> -8.0538946 | M30: 1.1 | N30: 0 | O30: =0*1.05 -> 0 | P30: 0 | Q30: =1007700/325851/1.9835*1.02 -> 1.5903041 | R30: 0 | S30: 0 | T30: =(0.4883*1.06)*1.04 -> 0.53830192 | U30: =M30-(Q30+R30+S30+T30) -> -1.028606 | V30: 0 | W30: 0 | X30: =MAX(0,M30-N30-P30-O30-Q30-R30-S30-T30-U30+V30+W30-AU30+AS30) -> 0 | Y30: =X30-AP30 -> 0 | AE30: 0 | AH30: 40 | AI30: =AI29-AH30 -> 4632.1579 | AK30: =N30+O30+P30+Q30+R30+S30+T30+U30+X30+AE30+AH30 -> 41.1 | AL30: =IF(L30<0,L30*-1,0) -> 8.0538946 | AM30: =AK30+AL30 -> 49.153895 | AO30: =IF(G30="","",IF(I30>=795,795-X30,I30-Q30-R30-X30-AF30)-AJ30) -> 28.909696 | AW30: 0 | AX30: 30 | AY30: 9 | BA30: =SUM(N30,P30:U30) -> 1.1 | BB30: 1.3 | BC30: 15924 | BE30: =BE29+1 -> 16 | BF30: 6901.5 | BG30: =B30-BF30 -> -0.01 | BH30: 27.05 | BI30: =AH30-BH30 -> 12.95
