Workbook

Sheet NOV
K1: MCPHEE RESERVOIR INFLOW/OUTFLOW TABULATION
A2: AF/cfs CONVERT FACTOR | D2: 1.9835 | L2: NOVEMBER "2002"
D4: RESERVOIR | Q4: INFLOW/OUTFLOW (CFS) | AB4: WEATHER
A5: DATE | B5: RESERV | C5: RESERV | D5: AC FT | E5: ACTIVE | F5: CONV TO | G5: DOLORES | H5: LOST | I5: RECORDED | J5: CALC | K5: TOTAL | L5: CALC | M5: DOLORES TUNNEL | Q5: LONE | R5: U | S5: TOTAL | T5: MVI | U5: DV CR | V5: BELOW | W5: REMAIN | X5: RECORDED | Y5: CALC | Z5: TOTAL | AA5: RAIN | AB5: MAX | AC5: MIN | AD5: NAR. | AE5: MVI
A6: "NOV" | B6: ELEV | C6: AC FT | D6: CHANGE | E6: CAP | F6: CFS | G6: RIVER | H6: CANYON | I6: INFLOW | J6: INFLOW | K6: INFLOW | L6: INF/OTF | M6: TOT DIV | N6: SWAMP | O6: UTE F&R | P6: MVI,CTZ | Q6: PINE | R6: LAT | S6: MVI | T6: CALL | U6: CANAL | V6: MCPHEE | W6: RELEASE | X6: OUTFLOW | Y6: OUTFLOW | Z6: OUTFLOW | AB6: TMP | AC6: TMP | AD6: CALL | AE6: CALL
E7: AC FT | T7: & PROJ. | AB7: NOV-OCT | AE7: Apr-Jun
A9: SEASON BAL
A10: YTD | B10: 6857.1 | C10: 156567 | O10: 0 | W10: 2410
A12: 1 | B12: 6857.13 | C12: 156634 | D12: =C12-C10 -> 67 | E12: =C12-152000 -> 4634 | F12: =D12/$D$2 -> 33.778674 | G12: 67 | H12: 0 | I12: =G12+H12 -> 67 | J12: =IF(L12>0,L12,0) -> 0 | K12: =I12+J12 -> 67 | L12: =F12-(I12-X12) -> -15.421326 | M12: 4.8 | N12: 0 | O12: 0 | P12: =M12-(N12+O12) -> 4.8 | Q12: 0 | R12: 0 | S12: =SUM(P12:R12) -> 4.8 | U12: 0 | V12: 13 | W12: =W10-V12 -> 2397 | X12: =N12+O12+S12+U12+V12 -> 17.8 | Y12: =IF(L12<0,L12*-1,0) -> 15.421326 | Z12: =X12+Y12 -> 33.221326 | AA12: 0 | AB12: 55 | AC12: 34
A13: =A12+1 -> 2 | B13: 6857.16 | C13: 156700 | D13: =C13-C12 -> 66 | E13: =C13-152000 -> 4700 | F13: =D13/$D$2 -> 33.274515 | G13: 64 | H13: 0 | I13: =G13+H13 -> 64 | J13: =IF(L13>0,L13,0) -> 0 | K13: =I13+J13 -> 64 | L13: =F13-(I13-X13) -> -12.925485 | M13: 4.8 | N13: 0 | O13: 0 | P13: =M13-(N13+O13) -> 4.8 | Q13: 0 | R13: 0 | S13: =SUM(P13:R13) -> 4.8 | U13: 0 | V13: 13 | W13: =W12-V13 -> 2384 | X13: =N13+O13+S13+U13+V13 -> 17.8 | Y13: =IF(L13<0,L13*-1,0) -> 12.925485 | Z13: =X13+Y13 -> 30.725485 | AA13: 0 | AB13: 51 | AC13: 30
A14: =A13+1 -> 3 | B14: 6857.19 | C14: 156767 | D14: =C14-C13 -> 67 | E14: =C14-152000 -> 4767 | F14: =D14/$D$2 -> 33.778674 | G14: 61 | H14: 0 | I14: =G14+H14 -> 61 | J14: =IF(L14>0,L14,0) -> 0 | K14: =I14+J14 -> 61 | L14: =F14-(I14-X14) -> -9.4213259 | M14: 4.8 | N14: 0 | O14: 0 | P14: =M14-(N14+O14) -> 4.8 | Q14: 0 | R14: 0 | S14: =SUM(P14:R14) -> 4.8 | U14: 0 | V14: 13 | W14: =W13-V14 -> 2371 | X14: =N14+O14+S14+U14+V14 -> 17.8 | Y14: =IF(L14<0,L14*-1,0) -> 9.4213259 | Z14: =X14+Y14 -> 27.221326 | AA14: 0 | AB14: 46 | AC14: 32
A15: =A14+1 -> 4 | B15: 6857.22 | C15: 156833 | D15: =C15-C14 -> 66 | E15: =C15-152000 -> 4833 | F15: =D15/$D$2 -> 33.274515 | G15: 55 | H15: 0 | I15: =G15+H15 -> 55 | J15: =IF(L15>0,L15,0) -> 0 | K15: =I15+J15 -> 55 | L15: =F15-(I15-X15) -> -3.9254853 | M15: 4.8 | N15: 0 | O15: 0 | P15: =M15-(N15+O15) -> 4.8 | Q15: 0 | R15: 0 | S15: =SUM(P15:R15) -> 4.8 | U15: 0 | V15: 13 | W15: =W14-V15 -> 2358 | X15: =N15+O15+S15+U15+V15 -> 17.8 | Y15: =IF(L15<0,L15*-1,0) -> 3.9254853 | Z15: =X15+Y15 -> 21.725485 | AA15: 0 | AB15: 46 | AC15: 30
A16: =A15+1 -> 5 | B16: 6857.25 | C16: 156900 | D16: =C16-C15 -> 67 | E16: =C16-152000 -> 4900 | F16: =D16/$D$2 -> 33.778674 | G16: 55 | H16: 0 | I16: =G16+H16 -> 55 | J16: =IF(L16>0,L16,0) -> 0 | K16: =I16+J16 -> 55 | L16: =F16-(I16-X16) -> -3.7213259 | M16: 4.5 | N16: 0 | O16: 0 | P16: =M16-(N16+O16) -> 4.5 | Q16: 0 | R16: 0 | S16: =SUM(P16:R16) -> 4.5 | U16: 0 | V16: 13 | W16: =W15-V16 -> 2345 | X16: =N16+O16+S16+U16+V16 -> 17.5 | Y16: =IF(L16<0,L16*-1,0) -> 3.7213259 | Z16: =X16+Y16 -> 21.221326 | AA16: 0 | AB16: 51 | AC16: 20
A17: =A16+1 -> 6 | B17: 6857.58 | C17: 156966 | D17: =C17-C16 -> 66 | E17: =C17-152000 -> 4966 | F17: =D17/$D$2 -> 33.274515 | G17: 48 | H17: 0 | I17: =G17+H17 -> 48 | J17: =IF(L17>0,L17,0) -> 2.3745147 | K17: =I17+J17 -> 50.374515 | L17: =F17-(I17-X17) -> 2.3745147 | M17: 4.1 | N17: 0 | O17: 0 | P17: =M17-(N17+O17) -> 4.1 | Q17: 0 | R17: 0 | S17: =SUM(P17:R17) -> 4.1 | U17: 0 | V17: 13 | W17: =W16-V17 -> 2332 | X17: =N17+O17+S17+U17+V17 -> 17.1 | Y17: =IF(L17<0,L17*-1,0) -> 0 | Z17: =X17+Y17 -> 17.1 | AA17: 0 | AB17: 52 | AC17: 23
A18: =A17+1 -> 7 | B18: 6857.31 | C18: 157033 | D18: =C18-C17 -> 67 | E18: =C18-152000 -> 5033 | F18: =D18/$D$2 -> 33.778674 | G18: 51 | H18: 0 | I18: =G18+H18 -> 51 | J18: =IF(L18>0,L18,0) -> 0.87867406 | K18: =I18+J18 -> 51.878674 | L18: =F18-(I18-X18) -> 0.87867406 | M18: 4.1 | N18: 0 | O18: 0 | P18: =M18-(N18+O18) -> 4.1 | Q18: 0 | R18: 0 | S18: =SUM(P18:R18) -> 4.1 | U18: 0 | V18: 14 | W18: =W17-V18 -> 2318 | X18: =N18+O18+S18+U18+V18 -> 18.1 | Y18: =IF(L18<0,L18*-1,0) -> 0 | Z18: =X18+Y18 -> 18.1 | AA18: 0 | AB18: 59 | AC18: 29
A19: =A18+1 -> 8 | B19: 6857.36 | C19: 157144 | D19: =C19-C18 -> 111 | E19: =C19-152000 -> 5144 | F19: =D19/$D$2 -> 55.961684 | G19: 61 | H19: 0 | I19: =G19+H19 -> 61 | J19: =IF(L19>0,L19,0) -> 14.061684 | K19: =I19+J19 -> 75.061684 | L19: =F19-(I19-X19) -> 14.061684 | M19: 4.1 | N19: 0 | O19: 0 | P19: =M19-(N19+O19) -> 4.1 | Q19: 0 | R19: 0 | S19: =SUM(P19:R19) -> 4.1 | U19: 0 | V19: 15 | W19: =W18-V19 -> 2303 | X19: =N19+O19+S19+U19+V19 -> 19.1 | Y19: =IF(L19<0,L19*-1,0) -> 0 | Z19: =X19+Y19 -> 19.1 | AA19: 0.4 | AB19: 47 | AC19: 34
A20: =A19+1 -> 9 | B20: 6857.46 | C20: 157365 | D20: =C20-C19 -> 221 | E20: =C20-152000 -> 5365 | F20: =D20/$D$2 -> 111.41921 | G20: 97 | H20: 0 | I20: =G20+H20 -> 97 | J20: =IF(L20>0,L20,0) -> 33.519208 | K20: =I20+J20 -> 130.51921 | L20: =F20-(I20-X20) -> 33.519208 | M20: 4.1 | N20: 0 | O20: 0 | P20: =M20-(N20+O20) -> 4.1 | Q20: 0 | R20: 0 | S20: =SUM(P20:R20) -> 4.1 | U20: 0 | V20: 15 | W20: =W19-V20 -> 2288 | X20: =N20+O20+S20+U20+V20 -> 19.1 | Y20: =IF(L20<0,L20*-1,0) -> 0 | Z20: =X20+Y20 -> 19.1 | AA20: 0.72 | AB20: 54 | AC20: 34
A21: =A20+1 -> 10 | B21: 6857.53 | C21: 157521 | D21: =C21-C20 -> 156 | E21: =C21-152000 -> 5521 | F21: =D21/$D$2 -> 78.648853 | G21: 96 | H21: 0 | I21: =G21+H21 -> 96 | J21: =IF(L21>0,L21,0) -> 0.74885304 | K21: =I21+J21 -> 96.748853 | L21: =F21-(I21-X21) -> 0.74885304 | M21: 4.1 | N21: 0 | O21: 0 | P21: =M21-(N21+O21) -> 4.1 | Q21: 0 | R21: 0 | S21: =SUM(P21:R21) -> 4.1 | U21: 0 | V21: 14 | W21: =W20-V21 -> 2274 | X21: =N21+O21+S21+U21+V21 -> 18.1 | Y21: =IF(L21<0,L21*-1,0) -> 0 | Z21: =X21+Y21 -> 18.1 | AA21: 0.03 | AB21: 43 | AC21: 27
A22: =A21+1 -> 11 | B22: 6857.53 | C22: 157521 | D22: =C22-C21 -> 0 | E22: =C22-152000 -> 5521 | F22: =D22/$D$2 -> 0 | G22: 76 | H22: 0 | I22: =G22+H22 -> 76 | J22: =IF(L22>0,L22,0) -> 0 | K22: =I22+J22 -> 76 | L22: =F22-(I22-X22) -> -21 | M22: 22 | N22: 0 | O22: 0 | P22: =M22-(N22+O22) -> 22 | Q22: 9 | R22: 10 | S22: =SUM(P22:R22) -> 41 | U22: 0 | V22: 14 | W22: =W21-V22 -> 2260 | X22: =N22+O22+S22+U22+V22 -> 55 | Y22: =IF(L22<0,L22*-1,0) -> 21 | Z22: =X22+Y22 -> 76 | AA22: 0 | AB22: 42 | AC22: 27
A23: =A22+1 -> 12 | B23: 6857.52 | C23: 157498 | D23: =C23-C22 -> -23 | E23: =C23-152000 -> 5498 | F23: =D23/$D$2 -> -11.595664 | G23: 59 | H23: 0 | I23: =G23+H23 -> 59 | J23: =IF(L23>0,L23,0) -> 3.4043358 | K23: =I23+J23 -> 62.404336 | L23: =F23-(I23-X23) -> 3.4043358 | M23: 28 | N23: 0 | O23: 0 | P23: =M23-(N23+O23) -> 28 | Q23: 17 | R23: 15 | S23: =SUM(P23:R23) -> 60 | U23: 0 | V23: 14 | W23: =W22-V23 -> 2246 | X23: =N23+O23+S23+U23+V23 -> 74 | Y23: =IF(L23<0,L23*-1,0) -> 0 | Z23: =X23+Y23 -> 74 | AA23: 0 | AB23: 46 | AC23: 22
A24: =A23+1 -> 13 | B24: 6857.51 | C24: 157476 | D24: =C24-C23 -> -22 | E24: =C24-152000 -> 5476 | F24: =D24/$D$2 -> -11.091505 | G24: 61 | H24: 0 | I24: =G24+H24 -> 61 | J24: =IF(L24>0,L24,0) -> 4.9084951 | K24: =I24+J24 -> 65.908495 | L24: =F24-(I24-X24) -> 4.9084951 | M24: 27 | N24: 0 | O24: 0 | P24: =M24-(N24+O24) -> 27 | Q24: 21 | R24: 15 | S24: =SUM(P24:R24) -> 63 | U24: 0 | V24: 14 | W24: =W23-V24 -> 2232 | X24: =N24+O24+S24+U24+V24 -> 77 | Y24: =IF(L24<0,L24*-1,0) -> 0 | Z24: =X24+Y24 -> 77 | AA24: 0 | AB24: 48 | AC24: 28
... A40: =A39+1 -> 29 | B40: 6857.87 | C40: 158274 | D40: =C40-C39 -> 66 | E40: =C40-152000 -> 6274 | F40: =D40/$D$2 -> 33.274515 | G40: 72 | H40: 0 | I40: =G40+H40 -> 72 | J40: =IF(L40>0,L40,0) -> 0 | K40: =I40+J40 -> 72 | L40: =F40-(I40-X40) -> -19.525485 | M40: 4.2 | N40: 0 | O40: 0 | P40: =M40-(N40+O40) -> 4.2 | Q40: 0 | R40: 0 | S40: =SUM(P40:R40) -> 4.2 | U40: 0 | V40: 15 | W40: =W39-V40 -> 2000 | X40: =N40+O40+S40+U40+V40 -> 19.2 | Y40: =IF(L40<0,L40*-1,0) -> 19.525485 | Z40: =X40+Y40 -> 38.725485 | AA40: 0 | AB40: 56 | AC40: 25
A41: 30 | B41: 6857.9 | C41: 158341 | D41: =C41-C40 -> 67 | E41: =C41-152000 -> 6341 | F41: =D41/$D$2 -> 33.778674 | G41: 72 | H41: 0 | I41: =G41+H41 -> 72 | J41: =IF(L41>0,L41,0) -> 0 | K41: =I41+J41 -> 72 | L41: =F41-(I41-X41) -> -19.121326 | M41: 4.1 | N41: 0 | O41: 0 | P41: =M41-(N41+O41) -> 4.1 | Q41: 0 | R41: 0 | S41: =SUM(P41:R41) -> 4.1 | U41: 0 | V41: 15 | W41: =W40-V41 -> 1985 | X41: =N41+O41+S41+U41+V41 -> 19.1 | Y41: =IF(L41<0,L41*-1,0) -> 19.121326 | Z41: =X41+Y41 -> 38.221326 | AA41: 0.08 | AB41: 50 | AC41: 25
AC42: 22
A43: MONTH / CFS | F43: =SUM(F12:F41) -> 894.37862 | G43: =SUM(G12:G41) -> 1859 | H43: =SUM(H12:H41) -> 0 | I43: =SUM(I12:I41) -> 1859 | J43: =SUM(J12:J41) -> 67.348954 | K43: =SUM(K12:K41) -> 1926.349 | L43: =SUM(L12:L41) -> -217.52138 | M43: =SUM(M12:M41) -> 209.1 | ... S43: =SUM(S12:S41) -> 322.1 | U43: =SUM(U12:U41) -> 0 | V43: =SUM(V12:V41) -> 425 | X43: =SUM(X12:X41) -> 747.1 | Y43: =SUM(Y12:Y41) -> 284.87033 | Z43: =SUM(Z12:Z41) -> 1031.9703 | AA43: =SUM(AA12:AA41) -> 1.23 | AB43: =AVERAGE(AB12:AB41) -> 50.2 | AC43: =AVERAGE(AC12:AC42) -> 26.774194 | AD43: Avg
A44: MONTH / AF | D44: =SUM(D12:D41) -> 1774 | F44: =F43*$D$2 -> 1774 | G44: =G43*$D$2 -> 3687.3265 | H44: =H43*$D$2 -> 0 | I44: =I43*$D$2 -> 3687.3265 | J44: =J43*$D$2 -> 133.58665 | K44: =K43*$D$2 -> 3820.9131 | L44: =L43*$D$2 -> -431.45365 | M44: =M43*$D$2 -> 414.74985 | ... S44: =S43*$D$2 -> 638.88535 | U44: =U43*$D$2 -> 0 | V44: =V43*$D$2 -> 842.9875 | X44: =X43*$D$2 -> 1481.8728 | Y44: =Y43*$D$2 -> 565.0403 | Z44: =Z43*$D$2 -> 2046.9132 | AB44: =MAX(AB12:AB41) -> 60 | AC44: =MAX(AC12:AC42) -> 34 | AD44: HI
A46: SEASON / CFS | AB46: =MIN(AB12:AB41) -> 41 | AC46: =MIN(AC12:AC42) -> 20 | AD46: LO
A47: SEASON / AF
A49: YTD / CFS | F49: =F10+F43 -> 894.37862 | G49: =G10+G43 -> 1859 | H49: =H10+H43 -> 0 | I49: =I10+I43 -> 1859 | J49: =J10+J43 -> 67.348954 | K49: =K10+K43 -> 1926.349 | L49: =L10+L43 -> -217.52138 | M49: =M10+M43 -> 209.1 | ... S49: =S10+S43 -> 322.1 | U49: =U10+U43 -> 0 | V49: =V10+V43 -> 425 | W49: =W41 -> 1985 | X49: =X10+X43 -> 747.1 | Y49: =Y10+Y43 -> 284.87033 | Z49: =Z10+Z43 -> 1031.9703 | AA49: =AA10+AA43 -> 1.23
A50: YTD / AF | D50: =D10+D44 -> 1774 | E50: =E41 -> 6341 | F50: =F49*$D$2 -> 1774 | G50: =G49*$D$2 -> 3687.3265 | H50: =H49*$D$2 -> 0 | I50: =I49*$D$2 -> 3687.3265 | J50: =J49*$D$2 -> 133.58665 | K50: =K49*$D$2 -> 3820.9131 | L50: =L49*$D$2 -> -431.45365 | M50: =M49*$D$2 -> 414.74985 | ... Z50: =Z49*$D$2 -> 2046.9132

Sheet DEC
K1: MCPHEE RESERVOIR INFLOW/OUTFLOW TABULATION
A2: AF/cfs CONVERT FACTOR | D2: 1.9835 | K2: DECEMBER "2002"
D4: RESERVOIR | Q4: INFLOW/OUTFLOW (CFS) | AB4: WEATHER
A5: DATE | B5: RESERV | C5: RESERV | D5: AC FT | E5: ACTIVE | F5: CONV TO | G5: DOLORES | H5: LOST | I5: RECORDED | J5: CALC | K5: TOTAL | L5: CALC | M5: DOLORES TUNNEL | Q5: LONE | R5: U | S5: TOTAL | T5: MVI | U5: DV CR | V5: BELOW | W5: REMAIN | X5: RECORDED | Y5: CALC | Z5: TOTAL | AA5: RAIN | AB5: MAX | AC5: MIN | AD5: NAR | AE5: MVI
A6: "DEC" | B6: ELEV | C6: AC FT | D6: CHANGE | E6: CAP | F6: CFS | G6: RIVER | H6: CANYON | I6: INFLOW | J6: INFLOW | K6: INFLOW | L6: INF/OTF | M6: TOT DIV | N6: SWAMP | O6: UTE F&R | P6: MVI,CTZ | Q6: PINE | R6: LAT | S6: MVI | T6: CALL | U6: CANAL | V6: MCPHEE | W6: RELEASE | X6: OUTFLOW | Y6: OUTFLOW | Z6: OUTFLOW | AB6: TMP | AC6: TMP | AD6: CALL | AE6: CALL
E7: AC FT | T7: &PROJ. | AB7: NOV-OCT | AE7: Apr-Jun
A9: SEASON BAL
A10: YTD | B10: =NOV!B41 -> 6857.9 | C10: =NOV!C41 -> 158341 | D10: =NOV!$D$50 -> 1774 | E10: =NOV!$E$41 -> 6341 | F10: =NOV!F49 -> 894.37862 | G10: =NOV!G49 -> 1859 | H10: =NOV!H49 -> 0 | I10: =NOV!I49 -> 1859 | J10: =NOV!J49 -> 67.348954 | K10: =NOV!K49 -> 1926.349 | L10: =NOV!L49 -> -217.52138 | M10: =NOV!M49 -> 209.1 | ... AA10: =NOV!AA49 -> 1.23
A12: 1 | B12: 6857.93 | C12: 158408 | D12: =C12-C10 -> 67 | E12: =C12-152000 -> 6408 | F12: =D12/$D$2 -> 33.778674 | G12: 69 | H12: 0 | I12: =G12+H12 -> 69 | J12: =IF(L12>0,L12,0) -> 0 | K12: =I12+J12 -> 69 | L12: =F12-(I12-X12) -> -16.121326 | M12: 4.1 | N12: 0 | O12: 0 | P12: =M12-(N12+O12) -> 4.1 | Q12: 0 | R12: 0 | S12: =SUM(P12:R12) -> 4.1 | U12: 0 | V12: 15 | W12: =W10-V12 -> 1970 | X12: =N12+O12+S12+U12+V12 -> 19.1 | Y12: =IF(L12<0,L12*-1,0) -> 16.121326 | Z12: =X12+Y12 -> 35.221326 | AA12: 0.13 | AB12: 43 | AC12: 22
A13: =A12+1 -> 2 | B13: 6857.95 | C13: 158452 | D13: =C13-C12 -> 44 | E13: =C13-152000 -> 6452 | F13: =D13/$D$2 -> 22.18301 | G13: 62 | H13: 0 | I13: =G13+H13 -> 62 | J13: =IF(L13>0,L13,0) -> 0 | K13: =I13+J13 -> 62 | L13: =F13-(I13-X13) -> -20.71699 | M13: 4.1 | N13: 0 | O13: 0 | P13: =M13-(N13+O13) -> 4.1 | Q13: 0 | R13: 0 | S13: =SUM(P13:R13) -> 4.1 | U13: 0 | V13: 15 | W13: =W12-V13 -> 1955 | X13: =N13+O13+S13+U13+V13 -> 19.1 | Y13: =IF(L13<0,L13*-1,0) -> 20.71699 | Z13: =X13+Y13 -> 39.81699 | AA13: 0 | AB13: 44 | AC13: 20
A14: =A13+1 -> 3 | B14: 6857.96 | C14: 158474 | D14: =C14-C13 -> 22 | E14: =C14-152000 -> 6474 | F14: =D14/$D$2 -> 11.091505 | G14: 68 | H14: 0 | I14: =G14+H14 -> 68 | J14: =IF(L14>0,L14,0) -> 0 | K14: =I14+J14 -> 68 | L14: =F14-(I14-X14) -> -37.808495 | M14: 4.1 | N14: 0 | O14: 0 | P14: =M14-(N14+O14) -> 4.1 | Q14: 0 | R14: 0 | S14: =SUM(P14:R14) -> 4.1 | U14: 0 | V14: 15 | W14: =W13-V14 -> 1940 | X14: =N14+O14+S14+U14+V14 -> 19.1 | Y14: =IF(L14<0,L14*-1,0) -> 37.808495 | Z14: =X14+Y14 -> 56.908495 | AA14: 0 | AB14: 42 | AC14: 24
A15: =A14+1 -> 4 | B15: 6857.98 | C15: 158518 | D15: =C15-C14 -> 44 | E15: =C15-152000 -> 6518 | F15: =D15/$D$2 -> 22.18301 | G15: 71 | H15: 0 | I15: =G15+H15 -> 71 | J15: =IF(L15>0,L15,0) -> 0 | K15: =I15+J15 -> 71 | L15: =F15-(I15-X15) -> -29.71699 | M15: 4.1 | N15: 0 | O15: 0 | P15: =M15-(N15+O15) -> 4.1 | Q15: 0 | R15: 0 | S15: =SUM(P15:R15) -> 4.1 | U15: 0 | V15: 15 | W15: =W14-V15 -> 1925 | X15: =N15+O15+S15+U15+V15 -> 19.1 | Y15: =IF(L15<0,L15*-1,0) -> 29.71699 | Z15: =X15+Y15 -> 48.81699 | AA15: 0 | AB15: 44 | AC15: 19
A16: =A15+1 -> 5 | B16: 9858 | C16: 158563 | D16: =C16-C15 -> 45 | E16: =C16-152000 -> 6563 | F16: =D16/$D$2 -> 22.687169 | G16: 60 | H16: 0 | I16: =G16+H16 -> 60 | J16: =IF(L16>0,L16,0) -> 0 | K16: =I16+J16 -> 60 | L16: =F16-(I16-X16) -> -18.212831 | M16: 4.1 | N16: 0 | O16: 0 | P16: =M16-(N16+O16) -> 4.1 | Q16: 0 | R16: 0 | S16: =SUM(P16:R16) -> 4.1 | U16: 0 | V16: 15 | W16: =W15-V16 -> 1910 | X16: =N16+O16+S16+U16+V16 -> 19.1 | Y16: =IF(L16<0,L16*-1,0) -> 18.212831 | Z16: =X16+Y16 -> 37.312831 | AA16: 0 | AB16: 46 | AC16: 20
A17: =A16+1 -> 6 | B17: 6858.02 | C17: 158608 | D17: =C17-C16 -> 45 | E17: =C17-152000 -> 6608 | F17: =D17/$D$2 -> 22.687169 | G17: 59 | H17: 0 | I17: =G17+H17 -> 59 | J17: =IF(L17>0,L17,0) -> 0 | K17: =I17+J17 -> 59 | L17: =F17-(I17-X17) -> -17.212831 | M17: 4.1 | N17: 0 | O17: 0 | P17: =M17-(N17+O17) -> 4.1 | Q17: 0 | R17: 0 | S17: =SUM(P17:R17) -> 4.1 | U17: 0 | V17: 15 | W17: =W16-V17 -> 1895 | X17: =N17+O17+S17+U17+V17 -> 19.1 | Y17: =IF(L17<0,L17*-1,0) -> 17.212831 | Z17: =X17+Y17 -> 36.312831 | AA17: 0 | AB17: 44 | AC17: 19
A18: =A17+1 -> 7 | B18: 6858.04 | C18: 158652 | D18: =C18-C17 -> 44 | E18: =C18-152000 -> 6652 | F18: =D18/$D$2 -> 22.18301 | G18: 55 | H18: 0 | I18: =G18+H18 -> 55 | J18: =IF(L18>0,L18,0) -> 0 | K18: =I18+J18 -> 55 | L18: =F18-(I18-X18) -> -13.71699 | M18: 4.1 | N18: 0 | O18: 0 | P18: =M18-(N18+O18) -> 4.1 | Q18: 0 | R18: 0 | S18: =SUM(P18:R18) -> 4.1 | U18: 0 | V18: 15 | W18: =W17-V18 -> 1880 | X18: =N18+O18+S18+U18+V18 -> 19.1 | Y18: =IF(L18<0,L18*-1,0) -> 13.71699 | Z18: =X18+Y18 -> 32.81699 | AA18: 0 | AB18: 45 | AC18: 18
A19: =A18+1 -> 8 | B19: 6858.05 | C19: 158675 | D19: =C19-C18 -> 23 | E19: =C19-152000 -> 6675 | F19: =D19/$D$2 -> 11.595664 | G19: 36 | H19: 0 | I19: =G19+H19 -> 36 | J19: =IF(L19>0,L19,0) -> 0 | K19: =I19+J19 -> 36 | L19: =F19-(I19-X19) -> -5.3043358 | M19: 4.1 | N19: 0 | O19: 0 | P19: =M19-(N19+O19) -> 4.1 | Q19: 0 | R19: 0 | S19: =SUM(P19:R19) -> 4.1 | U19: 0 | V19: 15 | W19: =W18-V19 -> 1865 | X19: =N19+O19+S19+U19+V19 -> 19.1 | Y19: =IF(L19<0,L19*-1,0) -> 5.3043358 | Z19: =X19+Y19 -> 24.404336 | AA19: 0 | AB19: 41 | AC19: 20
A20: =A19+1 -> 9 | B20: 6858.05 | C20: 158675 | D20: =C20-C19 -> 0 | E20: =C20-152000 -> 6675 | F20: =D20/$D$2 -> 0 | G20: 29 | H20: 0 | I20: =G20+H20 -> 29 | J20: =IF(L20>0,L20,0) -> 0 | K20: =I20+J20 -> 29 | L20: =F20-(I20-X20) -> -9.9 | M20: 4.1 | N20: 0 | O20: 0 | P20: =M20-(N20+O20) -> 4.1 | Q20: 0 | R20: 0 | S20: =SUM(P20:R20) -> 4.1 | U20: 0 | V20: 15 | W20: =W19-V20 -> 1850 | X20: =N20+O20+S20+U20+V20 -> 19.1 | Y20: =IF(L20<0,L20*-1,0) -> 9.9 | Z20: =X20+Y20 -> 29 | AA20: 0 | AB20: 43 | AC20: 18
A21: =A20+1 -> 10 | B21: 6858.06 | C21: 158697 | D21: =C21-C20 -> 22 | E21: =C21-152000 -> 6697 | F21: =D21/$D$2 -> 11.091505 | G21: 33 | H21: 0 | I21: =G21+H21 -> 33 | J21: =IF(L21>0,L21,0) -> 0 | K21: =I21+J21 -> 33 | L21: =F21-(I21-X21) -> -2.8084951 | M21: 4.1 | N21: 0 | O21: 0 | P21: =M21-(N21+O21) -> 4.1 | Q21: 0 | R21: 0 | S21: =SUM(P21:R21) -> 4.1 | U21: 0 | V21: 15 | W21: =W20-V21 -> 1835 | X21: =N21+O21+S21+U21+V21 -> 19.1 | Y21: =IF(L21<0,L21*-1,0) -> 2.8084951 | Z21: =X21+Y21 -> 21.908495 | AA21: 0 | AB21: 47 | AC21: 19
A22: =A21+1 -> 11 | B22: 6858.07 | C22: 158720 | D22: =C22-C21 -> 23 | E22: =C22-152000 -> 6720 | F22: =D22/$D$2 -> 11.595664 | G22: 28 | H22: 0 | I22: =G22+H22 -> 28 | J22: =IF(L22>0,L22,0) -> 2.6956642 | K22: =I22+J22 -> 30.695664 | L22: =F22-(I22-X22) -> 2.6956642 | M22: 4.1 | N22: 0 | O22: 0 | P22: =M22-(N22+O22) -> 4.1 | Q22: 0 | R22: 0 | S22: =SUM(P22:R22) -> 4.1 | U22: 0 | V22: 15 | W22: =W21-V22 -> 1820 | X22: =N22+O22+S22+U22+V22 -> 19.1 | Y22: =IF(L22<0,L22*-1,0) -> 0 | Z22: =X22+Y22 -> 19.1 | AA22: 0 | AB22: 46 | AC22: 18
A23: =A22+1 -> 12 | B23: 6858.08 | C23: 158742 | D23: =C23-C22 -> 22 | E23: =C23-152000 -> 6742 | F23: =D23/$D$2 -> 11.091505 | G23: 25 | H23: 0 | I23: =G23+H23 -> 25 | J23: =IF(L23>0,L23,0) -> 5.1715049 | K23: =I23+J23 -> 30.171505 | L23: =F23-(I23-X23) -> 5.1715049 | M23: 4.1 | N23: 0 | O23: 0 | P23: =M23-(N23+O23) -> 4.1 | Q23: 0 | R23: 0 | S23: =SUM(P23:R23) -> 4.1 | U23: 0 | V23: 14.98 | W23: =W22-V23 -> 1805.02 | X23: =N23+O23+S23+U23+V23 -> 19.08 | Y23: =IF(L23<0,L23*-1,0) -> 0 | Z23: =X23+Y23 -> 19.08 | AA23: 0 | AB23: 48 | AC23: 18
A24: =A23+1 -> 13 | B24: 6858.09 | C24: 158764 | D24: =C24-C23 -> 22 | E24: =C24-152000 -> 6764 | F24: =D24/$D$2 -> 11.091505 | G24: 34 | H24: 0 | I24: =G24+H24 -> 34 | J24: =IF(L24>0,L24,0) -> 0 | K24: =I24+J24 -> 34 | L24: =F24-(I24-X24) -> -3.9084951 | M24: 4 | N24: 0 | O24: 0 | P24: =M24-(N24+O24) -> 4 | Q24: 0 | R24: 0 | S24: =SUM(P24:R24) -> 4 | U24: 0 | V24: 15 | W24: =W23-V24 -> 1790.02 | X24: =N24+O24+S24+U24+V24 -> 19 | Y24: =IF(L24<0,L24*-1,0) -> 3.9084951 | Z24: =X24+Y24 -> 22.908495 | AA24: 0 | AB24: 46 | AC24: 18
... A40: =A39+1 -> 29 | B40: 6858.38 | C40: 159414 | D40: =C40-C39 -> 45 | E40: =C40-152000 -> 7414 | F40: =D40/$D$2 -> 22.687169 | G40: 20 | H40: 0 | I40: =G40+H40 -> 20 | J40: =IF(L40>0,L40,0) -> 20.087169 | K40: =I40+J40 -> 40.087169 | L40: =F40-(I40-X40) -> 20.087169 | M40: 3.4 | N40: 0 | O40: 0 | P40: =M40-(N40+O40) -> 3.4 | Q40: 0 | R40: 0 | S40: =SUM(P40:R40) -> 3.4 | U40: 0 | V40: 14 | W40: =W39-V40 -> 1557.12 | X40: =N40+O40+S40+U40+V40 -> 17.4 | Y40: =IF(L40<0,L40*-1,0) -> 0 | Z40: =X40+Y40 -> 17.4 | AA40: 0 | AB40: 35 | AC40: 20
A41: 30 | B41: 6858.39 | C41: 159436 | D41: =C41-C40 -> 22 | E41: =C41-152000 -> 7436 | F41: =D41/$D$2 -> 11.091505 | G41: 20 | H41: 0 | I41: =G41+H41 -> 20 | J41: =IF(L41>0,L41,0) -> 8.4915049 | K41: =I41+J41 -> 28.491505 | L41: =F41-(I41-X41) -> 8.4915049 | M41: 3.4 | N41: 0 | O41: 0 | P41: =M41-(N41+O41) -> 3.4 | Q41: 0 | R41: 0 | S41: =SUM(P41:R41) -> 3.4 | U41: 0 | V41: 14 | W41: =W40-V41 -> 1543.12 | X41: =N41+O41+S41+U41+V41 -> 17.4 | Y41: =IF(L41<0,L41*-1,0) -> 0 | Z41: =X41+Y41 -> 17.4 | AA41: 0.1 | AB41: 37 | AC41: 14
A42: 31 | B42: 6858.4 | C42: 159459 | D42: =C42-C41 -> 23 | E42: =C42-152000 -> 7459 | F42: =D42/$D$2 -> 11.595664 | G42: 21 | H42: 0 | I42: =G42+H42 -> 21 | J42: =IF(L42>0,L42,0) -> 8.0956642 | K42: =I42+J42 -> 29.095664 | L42: =F42-(I42-X42) -> 8.0956642 | M42: 3.5 | N42: 0 | O42: 0 | P42: =M42-(N42+O42) -> 3.5 | Q42: 0 | R42: 0 | S42: =SUM(P42:R42) -> 3.5 | U42: 0 | V42: 14 | W42: =W41-V42 -> 1529.12 | X42: =N42+O42+S42+U42+V42 -> 17.5 | Y42: =IF(L42<0,L42*-1,0) -> 0 | Z42: =X42+Y42 -> 17.5 | AA42: 0 | AB42: 36 | AC42: 13
A44: MONTH / CFS | F44: =SUM(F12:F42) -> 563.65011 | G44: =SUM(G12:G42) -> 1133 | H44: =SUM(H12:H42) -> 0 | I44: =SUM(I12:I42) -> 1133 | J44: =SUM(J12:J42) -> 206.48789 | K44: =SUM(K12:K42) -> 1339.4879 | L44: =SUM(L12:L42) -> 4.3301134 | M44: =SUM(M12:M42) -> 117.8 | ... S44: =SUM(S12:S42) -> 117.8 | U44: =SUM(U12:U42) -> 0 | V44: =SUM(V12:V42) -> 455.88 | X44: =SUM(X12:X42) -> 573.68 | Y44: =SUM(Y12:Y42) -> 202.15778 | Z44: =SUM(Z12:Z42) -> 775.83778 | AA44: =SUM(AA12:AA42) -> 0.82 | AB44: =AVERAGE(AB12:AB42) -> 37.870968 | AC44: =AVERAGE(AC12:AC42) -> 16.774194 | AD44: Avg
A45: MONTH / AF | D45: =SUM(D12:D42) -> 1118 | F45: =F44*$D$2 -> 1118 | G45: =G44*$D$2 -> 2247.3055 | H45: =H44*$D$2 -> 0 | I45: =I44*$D$2 -> 2247.3055 | J45: =J44*$D$2 -> 409.56873 | K45: =K44*$D$2 -> 2656.8742 | L45: =L44*$D$2 -> 8.58878 | M45: =M44*$D$2 -> 233.6563 | ... S45: =S44*$D$2 -> 233.6563 | U45: =U44*$D$2 -> 0 | V45: =V44*$D$2 -> 904.23798 | X45: =X44*$D$2 -> 1137.8943 | Y45: =Y44*$D$2 -> 400.97995 | Z45: =Z44*$D$2 -> 1538.8742 | AB45: =MAX(AB12:AB42) -> 51 | AC45: =MAX(AC12:AC42) -> 29 | AD45: HI
A47: SEASON / CFS | AB47: =MIN(AB12:AB42) -> 9 | AC47: =MIN(AC12:AC42) -> 4 | AD47: LO
A48: SEASON / AF
A50: YTD / CFS | F50: =F10+F44 -> 1458.0287 | G50: =G10+G44 -> 2992 | H50: =H10+H44 -> 0 | I50: =I10+I44 -> 2992 | J50: =J10+J44 -> 273.83684 | K50: =K10+K44 -> 3265.8368 | L50: =L10+L44 -> -213.19126 | M50: =M10+M44 -> 326.9 | ... S50: =S10+S44 -> 439.9 | U50: =U10+U44 -> 0 | V50: =V10+V44 -> 880.88 | W50: =W42 -> 1529.12 | X50: =X10+X44 -> 1320.78 | Y50: =Y10+Y44 -> 487.02811 | Z50: =Z10+Z44 -> 1807.8081 | AA50: =AA10+AA44 -> 2.05
A51: YTD / AF | D51: =D10+D45 -> 2892 | E51: =E42 -> 7459 | F51: =F50*$D$2 -> 2892 | G51: =G50*$D$2 -> 5934.632 | H51: =H50*$D$2 -> 0 | I51: =I50*$D$2 -> 5934.632 | J51: =J50*$D$2 -> 543.15538 | K51: =K50*$D$2 -> 6477.7874 | L51: =L50*$D$2 -> -422.86487 | M51: =M50*$D$2 -> 648.40615 | ... Z51: =Z50*$D$2 -> 3585.7874

Sheet JAN
K1: MCPHEE RESERVOIR INFLOW/OUTFLOW TABULATION
A2: AF/cfs CONVERT FACTOR | D2: 1.9835 | K2: JANUARY "2003"
D4: RESERVOIR | Q4: INFLOW/OUTFLOW (CFS) | AB4: WEATHER
A5: DATE | B5: RESERV | C5: RESERV | D5: AC FT | E5: ACTIVE | F5: CONV TO | G5: DOLORES | H5: LOST | I5: RECORDED | J5: CALC | K5: TOTAL | L5: CALC | M5: DOLORES TUNNEL | Q5: LONE | R5: U | S5: TOTAL | T5: MVI | U5: DV CR | V5: BELOW | W5: REMAIN | X5: RECORDED | Y5: CALC | Z5: TOTAL | AA5: RAIN | AB5: MAX | AC5: MIN | AD5: NAR | AE5: MVI
A6: "JAN" | B6: ELEV | C6: AC FT | D6: CHANGE | E6: CAP | F6: CFS | G6: RIVER | H6: CANYON | I6: INFLOW | J6: INFLOW | K6: INFLOW | L6: INF/OTF | M6: TOT DIV | N6: SWAMP | O6: UTE F&R | P6: MVI,CTZ | Q6: PINE | R6: LAT | S6: MVI | T6: CALL | U6: CANAL | V6: MCPHEE | W6: RELEASE | X6: OUTFLOW | Y6: OUTFLOW | Z6: OUTFLOW | AB6: TMP | AC6: TMP | AD6: CALL | AE6: CALL
E7: AC FT | T7: & PROJ. | AB7: NOV-OCT | AE7: Apr-Jun
A9: SEASON BAL
A10: YTD | B10: =DEC!B42 -> 6858.4 | C10: =DEC!C42 -> 159459 | D10: =DEC!$D$51 -> 2892 | E10: =DEC!$E$42 -> 7459 | F10: =DEC!F50 -> 1458.0287 | G10: =DEC!G50 -> 2992 | H10: =DEC!H50 -> 0 | I10: =DEC!I50 -> 2992 | J10: =DEC!J50 -> 273.83684 | K10: =DEC!K50 -> 3265.8368 | L10: =DEC!L50 -> -213.19126 | M10: =DEC!M50 -> 326.9 | ... AA10: =DEC!AA50 -> 2.05
A12: 1 | B12: 6858.41 | C12: 159481 | D12: =C12-C10 -> 22 | E12: =C12-152000 -> 7481 | F12: =D12/$D$2 -> 11.091505 | G12: 22 | H12: 0 | I12: =G12+H12 -> 22 | J12: =IF(L12>0,L12,0) -> 7.5915049 | K12: =I12+J12 -> 29.591505 | L12: =F12-(I12-X12) -> 7.5915049 | M12: 4.5 | N12: 0 | O12: 0 | P12: =M12-(N12+O12) -> 4.5 | Q12: 0 | R12: 0 | S12: =SUM(P12:R12) -> 4.5 | U12: 0 | V12: 14 | W12: =W10-V12 -> 1515.12 | X12: =N12+O12+S12+U12+V12 -> 18.5 | Y12: =IF(L12<0,L12*-1,0) -> 0 | Z12: =X12+Y12 -> 18.5 | AA12: 0 | AB12: 37 | AC12: 16
A13: =A12+1 -> 2 | B13: 6858.42 | C13: 159504 | D13: =C13-C12 -> 23 | E13: =C13-152000 -> 7504 | F13: =D13/$D$2 -> 11.595664 | G13: 24 | H13: 0 | I13: =G13+H13 -> 24 | J13: =IF(L13>0,L13,0) -> 6.7956642 | K13: =I13+J13 -> 30.795664 | L13: =F13-(I13-X13) -> 6.7956642 | M13: 5.2 | N13: 0 | O13: 0 | P13: =M13-(N13+O13) -> 5.2 | Q13: 0 | R13: 0 | S13: =SUM(P13:R13) -> 5.2 | U13: 0 | V13: 14 | W13: =W12-V13 -> 1501.12 | X13: =N13+O13+S13+U13+V13 -> 19.2 | Y13: =IF(L13<0,L13*-1,0) -> 0 | Z13: =X13+Y13 -> 19.2 | AA13: 0 | AB13: 46 | AC13: 10
A14: =A13+1 -> 3 | B14: 6858.43 | C14: 159526 | D14: =C14-C13 -> 22 | E14: =C14-152000 -> 7526 | F14: =D14/$D$2 -> 11.091505 | G14: 34 | H14: 0 | I14: =G14+H14 -> 34 | J14: =IF(L14>0,L14,0) -> 0 | K14: =I14+J14 -> 34 | L14: =F14-(I14-X14) -> -3.9084951 | M14: 5 | N14: 0 | O14: 0 | P14: =M14-(N14+O14) -> 5 | Q14: 0 | R14: 0 | S14: =SUM(P14:R14) -> 5 | U14: 0 | V14: 14 | W14: =W13-V14 -> 1487.12 | X14: =N14+O14+S14+U14+V14 -> 19 | Y14: =IF(L14<0,L14*-1,0) -> 3.9084951 | Z14: =X14+Y14 -> 22.908495 | AA14: 0 | AB14: 46 | AC14: 16
A15: =A14+1 -> 4 | B15: 6858.44 | C15: 159548 | D15: =C15-C14 -> 22 | E15: =C15-152000 -> 7548 | F15: =D15/$D$2 -> 11.091505 | G15: 38 | H15: 0 | I15: =G15+H15 -> 38 | J15: =IF(L15>0,L15,0) -> 0 | K15: =I15+J15 -> 38 | L15: =F15-(I15-X15) -> -7.4084951 | M15: 5.5 | N15: 0 | O15: 0 | P15: =M15-(N15+O15) -> 5.5 | Q15: 0 | R15: 0 | S15: =SUM(P15:R15) -> 5.5 | U15: 0 | V15: 14 | W15: =W14-V15 -> 1473.12 | X15: =N15+O15+S15+U15+V15 -> 19.5 | Y15: =IF(L15<0,L15*-1,0) -> 7.4084951 | Z15: =X15+Y15 -> 26.908495 | AA15: 0 | AB15: 47 | AC15: 21
A16: =A15+1 -> 5 | B16: 6858.45 | C16: 159571 | D16: =C16-C15 -> 23 | E16: =C16-152000 -> 7571 | F16: =D16/$D$2 -> 11.595664 | G16: 25 | H16: 0 | I16: =G16+H16 -> 25 | J16: =IF(L16>0,L16,0) -> 4.4956642 | K16: =I16+J16 -> 29.495664 | L16: =F16-(I16-X16) -> 4.4956642 | M16: 3.9 | N16: 0 | O16: 0 | P16: =M16-(N16+O16) -> 3.9 | Q16: 0 | R16: 0 | S16: =SUM(P16:R16) -> 3.9 | U16: 0 | V16: 14 | W16: =W15-V16 -> 1459.12 | X16: =N16+O16+S16+U16+V16 -> 17.9 | Y16: =IF(L16<0,L16*-1,0) -> 0 | Z16: =X16+Y16 -> 17.9 | AA16: 0 | AB16: 44 | AC16: 22
A17: =A16+1 -> 6 | B17: 6858.47 | C17: 159616 | D17: =C17-C16 -> 45 | E17: =C17-152000 -> 7616 | F17: =D17/$D$2 -> 22.687169 | G17: 27 | H17: 0 | I17: =G17+H17 -> 27 | J17: =IF(L17>0,L17,0) -> 13.387169 | K17: =I17+J17 -> 40.387169 | L17: =F17-(I17-X17) -> 13.387169 | M17: 3.7 | N17: 0 | O17: 0 | P17: =M17-(N17+O17) -> 3.7 | Q17: 0 | R17: 0 | S17: =SUM(P17:R17) -> 3.7 | U17: 0 | V17: 14 | W17: =W16-V17 -> 1445.12 | X17: =N17+O17+S17+U17+V17 -> 17.7 | Y17: =IF(L17<0,L17*-1,0) -> 0 | Z17: =X17+Y17 -> 17.7 | AA17: 0 | AB17: 46 | AC17: 29
A18: =A17+1 -> 7 | B18: 6858.49 | C18: 159660 | D18: =C18-C17 -> 44 | E18: =C18-152000 -> 7660 | F18: =D18/$D$2 -> 22.18301 | G18: 37 | H18: 0 | I18: =G18+H18 -> 37 | J18: =IF(L18>0,L18,0) -> 2.8830098 | K18: =I18+J18 -> 39.88301 | L18: =F18-(I18-X18) -> 2.8830098 | M18: 3.7 | N18: 0 | O18: 0 | P18: =M18-(N18+O18) -> 3.7 | Q18: 0 | R18: 0 | S18: =SUM(P18:R18) -> 3.7 | U18: 0 | V18: 14 | W18: =W17-V18 -> 1431.12 | X18: =N18+O18+S18+U18+V18 -> 17.7 | Y18: =IF(L18<0,L18*-1,0) -> 0 | Z18: =X18+Y18 -> 17.7 | AA18: 0 | AB18: 50 | AC18: 21
A19: =A18+1 -> 8 | B19: 6858.51 | C19: 159705 | D19: =C19-C18 -> 45 | E19: =C19-152000 -> 7705 | F19: =D19/$D$2 -> 22.687169 | G19: 35 | H19: 0 | I19: =G19+H19 -> 35 | J19: =IF(L19>0,L19,0) -> 5.3871691 | K19: =I19+J19 -> 40.387169 | L19: =F19-(I19-X19) -> 5.3871691 | M19: 3.7 | N19: 0 | O19: 0 | P19: =M19-(N19+O19) -> 3.7 | Q19: 0 | R19: 0 | S19: =SUM(P19:R19) -> 3.7 | U19: 0 | V19: 14 | W19: =W18-V19 -> 1417.12 | X19: =N19+O19+S19+U19+V19 -> 17.7 | Y19: =IF(L19<0,L19*-1,0) -> 0 | Z19: =X19+Y19 -> 17.7 | AA19: 0 | AB19: 52 | AC19: 20
A20: =A19+1 -> 9 | B20: 6858.54 | C20: 159772 | D20: =C20-C19 -> 67 | E20: =C20-152000 -> 7772 | F20: =D20/$D$2 -> 33.778674 | G20: 40 | H20: 0 | I20: =G20+H20 -> 40 | J20: =IF(L20>0,L20,0) -> 12.478674 | K20: =I20+J20 -> 52.478674 | L20: =F20-(I20-X20) -> 12.478674 | M20: 3.7 | N20: 0 | O20: 0 | P20: =M20-(N20+O20) -> 3.7 | Q20: 0 | R20: 0 | S20: =SUM(P20:R20) -> 3.7 | U20: 0 | V20: 15 | W20: =W19-V20 -> 1402.12 | X20: =N20+O20+S20+U20+V20 -> 18.7 | Y20: =IF(L20<0,L20*-1,0) -> 0 | Z20: =X20+Y20 -> 18.7 | AA20: 0.04 | AB20: 38 | AC20: 27
A21: =A20+1 -> 10 | B21: 6858.56 | C21: 159817 | D21: =C21-C20 -> 45 | E21: =C21-152000 -> 7817 | F21: =D21/$D$2 -> 22.687169 | G21: 44 | H21: 0 | I21: =G21+H21 -> 44 | J21: =IF(L21>0,L21,0) -> 0 | K21: =I21+J21 -> 44 | L21: =F21-(I21-X21) -> -3.6128309 | M21: 3.7 | N21: 0 | O21: 0 | P21: =M21-(N21+O21) -> 3.7 | Q21: 0 | R21: 0 | S21: =SUM(P21:R21) -> 3.7 | U21: 0 | V21: 14 | W21: =W20-V21 -> 1388.12 | X21: =N21+O21+S21+U21+V21 -> 17.7 | Y21: =IF(L21<0,L21*-1,0) -> 3.6128309 | Z21: =X21+Y21 -> 21.312831 | AA21: 0 | AB21: 41 | AC21: 31
A22: =A21+1 -> 11 | B22: 6858.62 | C22: 159952 | D22: =C22-C21 -> 135 | E22: =C22-152000 -> 7952 | F22: =D22/$D$2 -> 68.061507 | G22: 27 | H22: 0 | I22: =G22+H22 -> 27 | J22: =IF(L22>0,L22,0) -> 58.761507 | K22: =I22+J22 -> 85.761507 | L22: =F22-(I22-X22) -> 58.761507 | M22: 3.7 | N22: 0 | O22: 0 | P22: =M22-(N22+O22) -> 3.7 | Q22: 0 | R22: 0 | S22: =SUM(P22:R22) -> 3.7 | U22: 0 | V22: 14 | W22: =W21-V22 -> 1374.12 | X22: =N22+O22+S22+U22+V22 -> 17.7 | Y22: =IF(L22<0,L22*-1,0) -> 0 | Z22: =X22+Y22 -> 17.7 | AA22: 0.18 | AB22: 38 | AC22: 18
A23: =A22+1 -> 12 | B23: 6858.64 | C23: 159995 | D23: =C23-C22 -> 43 | E23: =C23-152000 -> 7995 | F23: =D23/$D$2 -> 21.678851 | G23: 16 | H23: 0 | I23: =G23+H23 -> 16 | J23: =IF(L23>0,L23,0) -> 23.378851 | K23: =I23+J23 -> 39.378851 | L23: =F23-(I23-X23) -> 23.378851 | M23: 3.7 | N23: 0 | O23: 0 | P23: =M23-(N23+O23) -> 3.7 | Q23: 0 | R23: 0 | S23: =SUM(P23:R23) -> 3.7 | U23: 0 | V23: 14 | W23: =W22-V23 -> 1360.12 | X23: =N23+O23+S23+U23+V23 -> 17.7 | Y23: =IF(L23<0,L23*-1,0) -> 0 | Z23: =X23+Y23 -> 17.7 | AA23: 0 | AB23: 42 | AC23: 15
A24: 13 | B24: 6858.65 | C24: 160019 | D24: =C24-C23 -> 24 | E24: =C24-152000 -> 8019 | F24: =D24/$D$2 -> 12.099824 | G24: 25 | H24: 0 | I24: =G24+H24 -> 25 | J24: =IF(L24>0,L24,0) -> 5.1998235 | K24: =I24+J24 -> 30.199824 | L24: =F24-(I24-X24) -> 5.1998235 | M24: 4.1 | N24: 0 | O24: 0 | P24: =M24-(N24+O24) -> 4.1 | Q24: 0 | R24: 0 | S24: =SUM(P24:R24) -> 4.1 | U24: 0 | V24: 14 | W24: =W23-V24 -> 1346.12 | X24: =N24+O24+S24+U24+V24 -> 18.1 | Y24: =IF(L24<0,L24*-1,0) -> 0 | Z24: =X24+Y24 -> 18.1 | AA24: 0 | AB24: 46 | AC24: 15
A25: =A24+1 -> 14 | B25: 6858.66 | C25: 160041 | D25: =C25-C24 -> 22 | E25: =C25-152000 -> 8041 | F25: =D25/$D$2 -> 11.091505 | G25: 36 | H25: 0 | I25: =G25+H25 -> 36 | J25: =IF(L25>0,L25,0) -> 0 | K25: =I25+J25 -> 36 | L25: =F25-(I25-X25) -> -6.1084951 | M25: 4.8 | N25: 0 | O25: 0 | P25: =M25-(N25+O25) -> 4.8 | Q25: 0 | R25: 0 | S25: =SUM(P25:R25) -> 4.8 | U25: 0 | V25: 14 | W25: =W24-V25 -> 1332.12 | X25: =N25+O25+S25+U25+V25 -> 18.8 | Y25: =IF(L25<0,L25*-1,0) -> 6.1084951 | Z25: =X25+Y25 -> 24.908495 | AA25: 0 | AB25: 50 | AC25: 22
A26: =A25+1 -> 15 | B26: 6858.67 | C26: 160064 | D26: =C26-C25 -> 23 | E26: =C26-152000 -> 8064 | F26: =D26/$D$2 -> 11.595664 | G26: 41 | H26: 0 | I26: =G26+H26 -> 41 | J26: =IF(L26>0,L26,0) -> 0 | K26: =I26+J26 -> 41 | L26: =F26-(I26-X26) -> -11.904336 | M26: 3.5 | N26: 0 | O26: 0 | P26: =M26-(N26+O26) -> 3.5 | Q26: 0 | R26: 0 | S26: =SUM(P26:R26) -> 3.5 | U26: 0 | V26: 14 | W26: =W25-V26 -> 1318.12 | X26: =N26+O26+S26+U26+V26 -> 17.5 | Y26: =IF(L26<0,L26*-1,0) -> 11.904336 | Z26: =X26+Y26 -> 29.404336 | AA26: 0 | AB26: 44 | AC26: 24
A27: =A26+1 -> 16 | B27: 6858.68 | C27: 160086 | D27: =C27-C26 -> 22 | E27: =C27-152000 -> 8086 | F27: =D27/$D$2 -> 11.091505 | G27: 34 | H27: 0 | I27: =G27+H27 -> 34 | J27: =IF(L27>0,L27,0) -> 0 | K27: =I27+J27 -> 34 | L27: =F27-(I27-X27) -> -5.2084951 | M27: 3.7 | N27: 0 | O27: 0 | P27: =M27-(N27+O27) -> 3.7 | Q27: 0 | R27: 0 | S27: =SUM(P27:R27) -> 3.7 | U27: 0 | V27: 14 | W27: =W26-V27 -> 1304.12 | X27: =N27+O27+S27+U27+V27 -> 17.7 | Y27: =IF(L27<0,L27*-1,0) -> 5.2084951 | Z27: =X27+Y27 -> 22.908495 | AA27: 0 | AB27: 46 | AC27: 20
A28: =A27+1 -> 17 | B28: 6858.69 | C28: 160109 | D28: =C28-C27 -> 23 | E28: =C28-152000 -> 8109 | F28: =D28/$D$2 -> 11.595664 | G28: 32 | H28: 0 | I28: =G28+H28 -> 32 | J28: =IF(L28>0,L28,0) -> 0 | K28: =I28+J28 -> 32 | L28: =F28-(I28-X28) -> -1.1043358 | M28: 5.3 | N28: 0 | O28: 0 | P28: =M28-(N28+O28) -> 5.3 | Q28: 0 | R28: 0 | S28: =SUM(P28:R28) -> 5.3 | U28: 0 | V28: 14 | W28: =W27-V28 -> 1290.12 | X28: =N28+O28+S28+U28+V28 -> 19.3 | Y28: =IF(L28<0,L28*-1,0) -> 1.1043358 | Z28: =X28+Y28 -> 20.404336 | AA28: 0 | AB28: 45 | AC28: 22
A29: =A28+1 -> 18 | B29: 6858.7 | C29: 160131 | D29: =C29-C28 -> 22 | E29: =C29-152000 -> 8131 | F29: =D29/$D$2 -> 11.091505 | G29: 20 | H29: 0 | I29: =G29+H29 -> 20 | J29: =IF(L29>0,L29,0) -> 12.591505 | K29: =I29+J29 -> 32.591505 | L29: =F29-(I29-X29) -> 12.591505 | M29: 7.5 | N29: 0 | O29: 0 | P29: =M29-(N29+O29) -> 7.5 | Q29: 0 | R29: 0 | S29: =SUM(P29:R29) -> 7.5 | U29: 0 | V29: 14 | W29: =W28-V29 -> 1276.12 | X29: =N29+O29+S29+U29+V29 -> 21.5 | Y29: =IF(L29<0,L29*-1,0) -> 0 | Z29: =X29+Y29 -> 21.5 | AA29: 0 | AB29: 47 | AC29: 18
A30: =A29+1 -> 19 | B30: 6858.72 | C30: 160176 | D30: =C30-C29 -> 45 | E30: =C30-152000 -> 8176 | F30: =D30/$D$2 -> 22.687169 | G30: 21 | H30: 0 | I30: =G30+H30 -> 21 | J30: =IF(L30>0,L30,0) -> 23.187169 | K30: =I30+J30 -> 44.187169 | L30: =F30-(I30-X30) -> 23.187169 | M30: 7.5 | N30: 0 | O30: 0 | P30: =M30-(N30+O30) -> 7.5 | Q30: 0 | R30: 0 | S30: =SUM(P30:R30) -> 7.5 | U30: 0 | V30: 14 | W30: =W29-V30 -> 1262.12 | X30: =N30+O30+S30+U30+V30 -> 21.5 | Y30: =IF(L30<0,L30*-1,0) -> 0 | Z30: =X30+Y30 -> 21.5 | AA30: 0 | AB30: 50 | AC30: 20
A31: =A30+1 -> 20 | B31: 6858.74 | C31: 160221 | D31: =C31-C30 -> 45 | E31: =C31-152000 -> 8221 | F31: =D31/$D$2 -> 22.687169 | G31: 21 | H31: 0 | I31: =G31+H31 -> 21 | J31: =IF(L31>0,L31,0) -> 24.387169 | K31: =I31+J31 -> 45.387169 | L31: =F31-(I31-X31) -> 24.387169 | M31: 8.7 | N31: 0 | O31: 0 | P31: =M31-(N31+O31) -> 8.7 | Q31: 0 | R31: 0 | S31: =SUM(P31:R31) -> 8.7 | U31: 0 | V31: 14 | W31: =W30-V31 -> 1248.12 | X31: =N31+O31+S31+U31+V31 -> 22.7 | Y31: =IF(L31<0,L31*-1,0) -> 0 | Z31: =X31+Y31 -> 22.7 | AA31: 0 | AB31: 51 | AC31: 24
A32: =A31+1 -> 21 | B32: 6858.75 | C32: 160243 | D32: =C32-C31 -> 22 | E32: =C32-152000 -> 8243 | F32: =D32/$D$2 -> 11.091505 | G32: 30 | H32: 0 | I32: =G32+H32 -> 30 | J32: =IF(L32>0,L32,0) -> 5.9915049 | K32: =I32+J32 -> 35.991505 | L32: =F32-(I32-X32) -> 5.9915049 | M32: 9.9 | N32: 0 | O32: 0 | P32: =M32-(N32+O32) -> 9.9 | Q32: 0 | R32: 0 | S32: =SUM(P32:R32) -> 9.9 | U32: 0 | V32: 15 | W32: =W31-V32 -> 1233.12 | X32: =N32+O32+S32+U32+V32 -> 24.9 | Y32: =IF(L32<0,L32*-1,0) -> 0 | Z32: =X32+Y32 -> 24.9 | AA32: 0 | AB32: 49 | AC32: 23
A33: =A32+1 -> 22 | B33: 6858.76 | C33: 160265 | D33: =C33-C32 -> 22 | E33: =C33-152000 -> 8265 | F33: =D33/$D$2 -> 11.091505 | G33: 37 | H33: 0 | I33: =G33+H33 -> 37 | J33: =IF(L33>0,L33,0) -> 0 | K33: =I33+J33 -> 37 | L33: =F33-(I33-X33) -> -3.4084951 | M33: 8.5 | N33: 0 | O33: 0 | P33: =M33-(N33+O33) -> 8.5 | Q33: 0 | R33: 0 | S33: =SUM(P33:R33) -> 8.5 | U33: 0 | V33: 14 | W33: =W32-V33 -> 1219.12 | X33: =N33+O33+S33+U33+V33 -> 22.5 | Y33: =IF(L33<0,L33*-1,0) -> 3.4084951 | Z33: =X33+Y33 -> 25.908495 | AA33: 0 | AB33: 48 | AC33: 24
A34: =A33+1 -> 23 | B34: 6858.78 | C34: 160310 | D34: =C34-C33 -> 45 | E34: =C34-152000 -> 8310 | F34: =D34/$D$2 -> 22.687169 | G34: 35 | H34: 0 | I34: =G34+H34 -> 35 | J34: =IF(L34>0,L34,0) -> 10.087169 | K34: =I34+J34 -> 45.087169 | L34: =F34-(I34-X34) -> 10.087169 | M34: 8.4 | N34: 0 | O34: 0 | P34: =M34-(N34+O34) -> 8.4 | Q34: 0 | R34: 0 | S34: =SUM(P34:R34) -> 8.4 | U34: 0 | V34: 14 | W34: =W33-V34 -> 1205.12 | X34: =N34+O34+S34+U34+V34 -> 22.4 | Y34: =IF(L34<0,L34*-1,0) -> 0 | Z34: =X34+Y34 -> 22.4 | AA34: 0 | AB34: 53 | AC34: 26
A35: =A34+1 -> 24 | B35: 6858.8 | C35: 160355 | D35: =C35-C34 -> 45 | E35: =C35-152000 -> 8355 | F35: =D35/$D$2 -> 22.687169 | G35: 35 | H35: 0 | I35: =G35+H35 -> 35 | J35: =IF(L35>0,L35,0) -> 10.987169 | K35: =I35+J35 -> 45.987169 | L35: =F35-(I35-X35) -> 10.987169 | M35: 9.3 | N35: 0 | O35: 0 | P35: =M35-(N35+O35) -> 9.3 | Q35: 0 | R35: 0 | S35: =SUM(P35:R35) -> 9.3 | U35: 0 | V35: 14 | W35: =W34-V35 -> 1191.12 | X35: =N35+O35+S35+U35+V35 -> 23.3 | Y35: =IF(L35<0,L35*-1,0) -> 0 | Z35: =X35+Y35 -> 23.3 | AA35: 0 | AB35: 52 | AC35: 27
A36: =A35+1 -> 25 | B36: 6858.81 | C36: 160377 | D36: =C36-C35 -> 22 | E36: =C36-152000 -> 8377 | F36: =D36/$D$2 -> 11.091505 | G36: 34 | H36: 0 | I36: =G36+H36 -> 34 | J36: =IF(L36>0,L36,0) -> 0 | K36: =I36+J36 -> 34 | L36: =F36-(I36-X36) -> -0.90849508 | M36: 8 | N36: 0 | O36: 0 | P36: =M36-(N36+O36) -> 8 | Q36: 0 | R36: 0 | S36: =SUM(P36:R36) -> 8 | U36: 0 | V36: 14 | W36: =W35-V36 -> 1177.12 | X36: =N36+O36+S36+U36+V36 -> 22 | Y36: =IF(L36<0,L36*-1,0) -> 0.90849508 | Z36: =X36+Y36 -> 22.908495 | AA36: 0 | AB36: 47 | AC36: 29
... A40: =A39+1 -> 29 | B40: 6858.88 | C40: 160534 | D40: =C40-C39 -> 45 | E40: =C40-152000 -> 8534 | F40: =D40/$D$2 -> 22.687169 | G40: 37 | H40: 0.3 | I40: =G40+H40 -> 37.3 | J40: =IF(L40>0,L40,0) -> 7.3871691 | K40: =I40+J40 -> 44.687169 | L40: =F40-(I40-X40) -> 7.3871691 | M40: 8 | N40: 0 | O40: 0 | P40: =M40-(N40+O40) -> 8 | Q40: 0 | R40: 0 | S40: =SUM(P40:R40) -> 8 | U40: 0 | V40: 14 | W40: =W39-V40 -> 1121.12 | X40: =N40+O40+S40+U40+V40 -> 22 | Y40: =IF(L40<0,L40*-1,0) -> 0 | Z40: =X40+Y40 -> 22 | AA40: 0 | AB40: 50 | AC40: 26
A41: 30 | B41: 6858.91 | C41: 160601 | D41: =C41-C40 -> 67 | E41: =C41-152000 -> 8601 | F41: =D41/$D$2 -> 33.778674 | G41: 34 | H41: 0.38 | I41: =G41+H41 -> 34.38 | J41: =IF(L41>0,L41,0) -> 22.408674 | K41: =I41+J41 -> 56.788674 | L41: =F41-(I41-X41) -> 22.408674 | M41: 8 | N41: 0 | O41: 0 | P41: =M41-(N41+O41) -> 8 | Q41: 0 | R41: 0 | S41: =SUM(P41:R41) -> 8 | U41: 0 | V41: 15.01 | W41: =W40-V41 -> 1106.11 | X41: =N41+O41+S41+U41+V41 -> 23.01 | Y41: =IF(L41<0,L41*-1,0) -> 0 | Z41: =X41+Y41 -> 23.01 | AA41: 0 | AB41: 52 | AC41: 27
A42: 31 | B42: 6858.93 | C42: 160646 | D42: =C42-C41 -> 45 | E42: =C42-152000 -> 8646 | F42: =D42/$D$2 -> 22.687169 | G42: 29 | H42: 0.43 | I42: =G42+H42 -> 29.43 | J42: =IF(L42>0,L42,0) -> 15.257169 | K42: =I42+J42 -> 44.687169 | L42: =F42-(I42-X42) -> 15.257169 | M42: 8 | N42: 0 | O42: 0 | P42: =M42-(N42+O42) -> 8 | Q42: 0 | R42: 0 | S42: =SUM(P42:R42) -> 8 | U42: 0 | V42: 14 | W42: =W41-V42 -> 1092.11 | X42: =N42+O42+S42+U42+V42 -> 22 | Y42: =IF(L42<0,L42*-1,0) -> 0 | Z42: =X42+Y42 -> 22 | AA42: 0 | AB42: 51 | AC42: 29
AB43: 39
A44: MONTH / CFS | F44: =SUM(F12:F42) -> 598.43711 | G44: =SUM(G12:G42) -> 958 | H44: =SUM(H12:H42) -> 1.9 | I44: =SUM(I12:I42) -> 959.9 | J44: =SUM(J12:J42) -> 306.98391 | K44: =SUM(K12:K42) -> 1266.8839 | L44: =SUM(L12:L42) -> 262.74711 | M44: =SUM(M12:M42) -> 187.2 | ... S44: =SUM(S12:S42) -> 187.2 | U44: =SUM(U12:U42) -> 0 | V44: =SUM(V12:V42) -> 437.01 | X44: =SUM(X12:X42) -> 624.21 | Y44: =SUM(Y12:Y42) -> 44.236809 | Z44: =SUM(Z12:Z42) -> 668.44681 | AA44: =SUM(AA12:AA42) -> 0.22 | AB44: =AVERAGE(AB12:AB42) -> 47.225806 | AC44: =AVERAGE(AC12:AC42) -> 22.645161 | AD44: AVE
A45: MONTH / AF | D45: =SUM(D12:D42) -> 1187 | F45: =F44*$D$2 -> 1187 | G45: =G44*$D$2 -> 1900.193 | H45: =H44*$D$2 -> 3.76865 | I45: =I44*$D$2 -> 1903.9616 | J45: =J44*$D$2 -> 608.9026 | K45: =K44*$D$2 -> 2512.8642 | L45: =L44*$D$2 -> 521.15889 | M45: =M44*$D$2 -> 371.3112 | ... S45: =S44*$D$2 -> 371.3112 | U45: =U44*$D$2 -> 0 | V45: =V44*$D$2 -> 866.80934 | X45: =X44*$D$2 -> 1238.1205 | Y45: =Y44*$D$2 -> 87.74371 | Z45: =Z44*$D$2 -> 1325.8642 | AB45: =MAX(AB12:AB42) -> 54 | AC45: =MAX(AC12:AC42) -> 31 | AD45: HI
A47: SEASON / CFS | AB47: =MIN(AB12:AB42) -> 37 | AC47: =MIN(AC12:AC42) -> 10 | AD47: LO
...

Sheet FEB
K1: MCPHEE RESERVOIR INFLOW/OUTFLOW TABULATION
A2: AF/cfs CONVERT FACTOR | D2: 1.9835 | K2: FEBRUARY "2003"
D4: RESERVOIR | Q4: INFLOW/OUTFLOW (CFS) | AB4: WEATHER
A5: DATE | B5: RESERV | C5: RESERV | D5: AC FT | E5: ACTIVE | F5: CONV TO | G5: DOLORES | H5: LOST | I5: RECORDED | J5: CALC | K5: TOTAL | L5: CALC | M5: DOLORES TUNNEL | Q5: LONE | R5: U | S5: TOTAL | T5: MVI | U5: DV CR | V5: BELOW | W5: REMAIN | X5: RECORDED | Y5: CALC | Z5: TOTAL | AA5: RAIN | AB5: MAX | AC5: MIN | AD5: NAR | AE5: MVI
A6: FEB | B6: ELEV | C6: AC FT | D6: CHANGE | E6: CAP | F6: CFS | G6: RIVER | H6: CANYON | I6: INFLOW | J6: INFLOW | K6: INFLOW | L6: INF/OTF | M6: TOT DIV | N6: SWAMP | O6: UTE F&R | P6: MVI,CTZ | Q6: PINE | R6: LAT | S6: MVI | T6: CALL | U6: CANAL | V6: MCPHEE | W6: RELEASE | X6: OUTFLOW | Y6: OUTFLOW | Z6: OUTFLOW | AB6: TMP | AC6: TMP | AD6: CALL | AE6: CALL
E7: AC FT | T7: & PROJ. | AB7: NOV-OCT | AE7: Apr-Jun
A9: SEASON BAL
A10: YTD | B10: =JAN!B42 -> 6858.93 | C10: =JAN!C42 -> 160646 | D10: =JAN!$D$51 -> 4079 | E10: =JAN!$E$42 -> 8646 | F10: =JAN!F50 -> 2056.4658 | G10: =JAN!G50 -> 3950 | H10: =JAN!H50 -> 1.9 | I10: =JAN!I50 -> 3951.9 | J10: =JAN!J50 -> 580.82076 | K10: =JAN!K50 -> 4532.7208 | L10: =JAN!L50 -> 49.555843 | M10: =JAN!M50 -> 514.1 | ... AA10: =JAN!AA50 -> 2.27
A12: 1 | B12: 6858.96 | C12: 160713 | D12: =C12-C10 -> 67 | E12: =C12-152000 -> 8713 | F12: =D12/$D$2 -> 33.778674 | G12: 28 | H12: 0.47 | I12: =G12+H12 -> 28.47 | J12: =IF(L12>0,L12,0) -> 27.308674 | K12: =I12+J12 -> 55.778674 | L12: =F12-(I12-X12) -> 27.308674 | M12: 8 | N12: 0 | O12: 0 | P12: =M12-(N12+O12) -> 8 | Q12: 0 | R12: 0 | S12: =SUM(P12:R12) -> 8 | U12: 0 | V12: 14 | W12: =W10-V12 -> 1078.11 | X12: =N12+O12+S12+U12+V12 -> 22 | Y12: =IF(L12<0,L12*-1,0) -> 0 | Z12: =X12+Y12 -> 22 | AA12: 0 | AB12: 53 | AC12: 30
A13: =A12+1 -> 2 | B13: 6858.98 | C13: 160758 | D13: =C13-C12 -> 45 | E13: =C13-152000 -> 8758 | F13: =D13/$D$2 -> 22.687169 | G13: 35 | H13: 0.6 | I13: =G13+H13 -> 35.6 | J13: =IF(L13>0,L13,0) -> 9.0871691 | K13: =I13+J13 -> 44.687169 | L13: =F13-(I13-X13) -> 9.0871691 | M13: 8 | N13: 0 | O13: 0 | P13: =M13-(N13+O13) -> 8 | Q13: 0 | R13: 0 | S13: =SUM(P13:R13) -> 8 | U13: 0 | V13: 14 | W13: =W12-V13 -> 1064.11 | X13: =N13+O13+S13+U13+V13 -> 22 | Y13: =IF(L13<0,L13*-1,0) -> 0 | Z13: =X13+Y13 -> 22 | AA13: 0.08 | AB13: 47 | AC13: 35
A14: =A13+1 -> 3 | B14: 6858.98 | C14: 160758 | D14: =C14-C13 -> 0 | E14: =C14-152000 -> 8758 | F14: =D14/$D$2 -> 0 | G14: 34 | H14: 0.64 | I14: =G14+H14 -> 34.64 | J14: =IF(L14>0,L14,0) -> 0 | K14: =I14+J14 -> 34.64 | L14: =F14-(I14-X14) -> -12.94 | M14: 7.7 | N14: 0 | O14: 0 | P14: =M14-(N14+O14) -> 7.7 | Q14: 0 | R14: 0 | S14: =SUM(P14:R14) -> 7.7 | U14: 0 | V14: 14 | W14: =W13-V14 -> 1050.11 | X14: =N14+O14+S14+U14+V14 -> 21.7 | Y14: =IF(L14<0,L14*-1,0) -> 12.94 | Z14: =X14+Y14 -> 34.64 | AA14: 0 | AB14: 35 | AC14: 14
A15: =A14+1 -> 4 | B15: 6858.98 | C15: 160758 | D15: =C15-C14 -> 0 | E15: =C15-152000 -> 8758 | F15: =D15/$D$2 -> 0 | G15: 25 | H15: 0.58 | I15: =G15+H15 -> 25.58 | J15: =IF(L15>0,L15,0) -> 0 | K15: =I15+J15 -> 25.58 | L15: =F15-(I15-X15) -> -4.08 | M15: 7.5 | N15: 0 | O15: 0 | P15: =M15-(N15+O15) -> 7.5 | Q15: 0 | R15: 0 | S15: =SUM(P15:R15) -> 7.5 | U15: 0 | V15: 14 | W15: =W14-V15 -> 1036.11 | X15: =N15+O15+S15+U15+V15 -> 21.5 | Y15: =IF(L15<0,L15*-1,0) -> 4.08 | Z15: =X15+Y15 -> 25.58 | AA15: 0 | AB15: 39 | AC15: 10.9
A16: =A15+1 -> 5 | B16: 6858.98 | C16: 160758 | D16: =C16-C15 -> 0 | E16: =C16-152000 -> 8758 | F16: =D16/$D$2 -> 0 | G16: 28 | H16: 0.56 | I16: =G16+H16 -> 28.56 | J16: =IF(L16>0,L16,0) -> 0 | K16: =I16+J16 -> 28.56 | L16: =F16-(I16-X16) -> -7.06 | M16: 7.5 | N16: 0 | O16: 0 | P16: =M16-(N16+O16) -> 7.5 | Q16: 0 | R16: 0 | S16: =SUM(P16:R16) -> 7.5 | U16: 0 | V16: 14 | W16: =W15-V16 -> 1022.11 | X16: =N16+O16+S16+U16+V16 -> 21.5 | Y16: =IF(L16<0,L16*-1,0) -> 7.06 | Z16: =X16+Y16 -> 28.56 | AA16: 0 | AB16: 34 | AC16: 10
A17: =A16+1 -> 6 | B17: 6858.98 | C17: 160758 | D17: =C17-C16 -> 0 | E17: =C17-152000 -> 8758 | F17: =D17/$D$2 -> 0 | G17: 24 | H17: 0.51 | I17: =G17+H17 -> 24.51 | J17: =IF(L17>0,L17,0) -> 0 | K17: =I17+J17 -> 24.51 | L17: =F17-(I17-X17) -> -3.01 | M17: 7.5 | N17: 0 | O17: 0 | P17: =M17-(N17+O17) -> 7.5 | Q17: 0 | R17: 0 | S17: =SUM(P17:R17) -> 7.5 | U17: 0 | V17: 14 | W17: =W16-V17 -> 1008.11 | X17: =N17+O17+S17+U17+V17 -> 21.5 | Y17: =IF(L17<0,L17*-1,0) -> 3.01 | Z17: =X17+Y17 -> 24.51 | AA17: 0 | AB17: 28 | AC17: 8.1
A18: =A17+1 -> 7 | B18: 6858.98 | C18: 160758 | D18: =C18-C17 -> 0 | E18: =C18-152000 -> 8758 | F18: =D18/$D$2 -> 0 | G18: 17 | H18: 0.44 | I18: =G18+H18 -> 17.44 | J18: =IF(L18>0,L18,0) -> 4.36 | K18: =I18+J18 -> 21.8 | L18: =F18-(I18-X18) -> 4.36 | M18: 7.8 | N18: 0 | O18: 0 | P18: =M18-(N18+O18) -> 7.8 | Q18: 0 | R18: 0 | S18: =SUM(P18:R18) -> 7.8 | U18: 0 | V18: 14 | W18: =W17-V18 -> 994.11 | X18: =N18+O18+S18+U18+V18 -> 21.8 | Y18: =IF(L18<0,L18*-1,0) -> 0 | Z18: =X18+Y18 -> 21.8 | AA18: 0 | AB18: 34 | AC18: 1
A19: =A18+1 -> 8 | B19: 6858.98 | C19: 160758 | D19: =C19-C18 -> 0 | E19: =C19-152000 -> 8758 | F19: =D19/$D$2 -> 0 | G19: 19 | H19: 0.31 | I19: =G19+H19 -> 19.31 | J19: =IF(L19>0,L19,0) -> 2.69 | K19: =I19+J19 -> 22 | L19: =F19-(I19-X19) -> 2.69 | M19: 8 | N19: 0 | O19: 0 | P19: =M19-(N19+O19) -> 8 | Q19: 0 | R19: 0 | S19: =SUM(P19:R19) -> 8 | U19: 0 | V19: 14 | W19: =W18-V19 -> 980.11 | X19: =N19+O19+S19+U19+V19 -> 22 | Y19: =IF(L19<0,L19*-1,0) -> 0 | Z19: =X19+Y19 -> 22 | AA19: 0 | AB19: 38 | AC19: 5
A20: =A19+1 -> 9 | B20: 6858.99 | C20: 160781 | D20: =C20-C19 -> 23 | E20: =C20-152000 -> 8781 | F20: =D20/$D$2 -> 11.595664 | G20: 22 | H20: 0.22 | I20: =G20+H20 -> 22.22 | J20: =IF(L20>0,L20,0) -> 11.375664 | K20: =I20+J20 -> 33.595664 | L20: =F20-(I20-X20) -> 11.375664 | M20: 8 | N20: 0 | O20: 0 | P20: =M20-(N20+O20) -> 8 | Q20: 0 | R20: 0 | S20: =SUM(P20:R20) -> 8 | U20: 0 | V20: 14 | W20: =W19-V20 -> 966.11 | X20: =N20+O20+S20+U20+V20 -> 22 | Y20: =IF(L20<0,L20*-1,0) -> 0 | Z20: =X20+Y20 -> 22 | AA20: 0 | AB20: 32 | AC20: 8.1
A21: =A20+1 -> 10 | B21: 6859 | C21: 160803 | D21: =C21-C20 -> 22 | E21: =C21-152000 -> 8803 | F21: =D21/$D$2 -> 11.091505 | G21: 28 | H21: 0.2 | I21: =G21+H21 -> 28.2 | J21: =IF(L21>0,L21,0) -> 4.8915049 | K21: =I21+J21 -> 33.091505 | L21: =F21-(I21-X21) -> 4.8915049 | M21: 8 | N21: 0 | O21: 0 | P21: =M21-(N21+O21) -> 8 | Q21: 0 | R21: 0 | S21: =SUM(P21:R21) -> 8 | U21: 0 | V21: 14 | W21: =W20-V21 -> 952.11 | X21: =N21+O21+S21+U21+V21 -> 22 | Y21: =IF(L21<0,L21*-1,0) -> 0 | Z21: =X21+Y21 -> 22 | AA21: 0 | AB21: 43 | AC21: 11
A22: =A21+1 -> 11 | B22: 6859.01 | C22: 160826 | D22: =C22-C21 -> 23 | E22: =C22-152000 -> 8826 | F22: =D22/$D$2 -> 11.595664 | G22: 28 | H22: 0.22 | I22: =G22+H22 -> 28.22 | J22: =IF(L22>0,L22,0) -> 5.3756642 | K22: =I22+J22 -> 33.595664 | L22: =F22-(I22-X22) -> 5.3756642 | M22: 8 | N22: 0 | O22: 0 | P22: =M22-(N22+O22) -> 8 | Q22: 0 | R22: 0 | S22: =SUM(P22:R22) -> 8 | U22: 0 | V22: 14 | W22: =W21-V22 -> 938.11 | X22: =N22+O22+S22+U22+V22 -> 22 | Y22: =IF(L22<0,L22*-1,0) -> 0 | Z22: =X22+Y22 -> 22 | AA22: 0 | AB22: 44 | AC22: 21
A23: =A22+1 -> 12 | B23: 6859.02 | C23: 160848 | D23: =C23-C22 -> 22 | E23: =C23-152000 -> 8848 | F23: =D23/$D$2 -> 11.091505 | G23: 57 | H23: 0.23 | I23: =G23+H23 -> 57.23 | J23: =IF(L23>0,L23,0) -> 0 | K23: =I23+J23 -> 57.23 | L23: =F23-(I23-X23) -> -24.138495 | M23: 8 | N23: 0 | O23: 0 | P23: =M23-(N23+O23) -> 8 | Q23: 0 | R23: 0 | S23: =SUM(P23:R23) -> 8 | U23: 0 | V23: 14 | W23: =W22-V23 -> 924.11 | X23: =N23+O23+S23+U23+V23 -> 22 | Y23: =IF(L23<0,L23*-1,0) -> 24.138495 | Z23: =X23+Y23 -> 46.138495 | AA23: 0 | AB23: 50 | AC23: 27
A24: =A23+1 -> 13 | B24: 6859.5 | C24: 161935 | D24: =C24-C23 -> 1087 | E24: =C24-152000 -> 9935 | F24: =D24/$D$2 -> 548.02117 | G24: 69 | H24: 0.76 | I24: =G24+H24 -> 69.76 | J24: =IF(L24>0,L24,0) -> 501.26117 | K24: =I24+J24 -> 571.02117 | L24: =F24-(I24-X24) -> 501.26117 | M24: 8 | N24: 0 | O24: 0 | P24: =M24-(N24+O24) -> 8 | Q24: 0 | R24: 0 | S24: =SUM(P24:R24) -> 8 | U24: 0 | V24: 15 | W24: =W23-V24 -> 909.11 | X24: =N24+O24+S24+U24+V24 -> 23 | Y24: =IF(L24<0,L24*-1,0) -> 0 | Z24: =X24+Y24 -> 23 | AA24: 0.75 | AB24: 41 | AC24: 35
... A31: =A30+1 -> 20 | B31: 6859.9 | C31: 162840 | D31: =C31-C30 -> 90 | E31: =C31-152000 -> 10840 | F31: =D31/$D$2 -> 45.374338 | G31: 38 | H31: 1.6 | I31: =G31+H31 -> 39.6 | J31: =IF(L31>0,L31,0) -> 28.774338 | K31: =I31+J31 -> 68.374338 | L31: =F31-(I31-X31) -> 28.774338 | M31: 8 | N31: 0 | O31: 0 | P31: =M31-(N31+O31) -> 8 | Q31: 0 | R31: 0 | S31: =SUM(P31:R31) -> 8 | U31: 0 | V31: 15 | W31: =W30-V31 -> 807.11 | X31: =N31+O31+S31+U31+V31 -> 23 | Y31: =IF(L31<0,L31*-1,0) -> 0 | Z31: =X31+Y31 -> 23 | AA31: 0 | AB31: 46 | AC31: 28
A32: =A31+1 -> 21 | B32: 6859.91 | C32: 162863 | D32: =C32-C31 -> 23 | E32: =C32-152000 -> 10863 | F32: =D32/$D$2 -> 11.595664 | G32: 39 | H32: 1.4 | I32: =G32+H32 -> 40.4 | J32: =IF(L32>0,L32,0) -> 0 | K32: =I32+J32 -> 40.4 | L32: =F32-(I32-X32) -> -6.3043358 | M32: 7.5 | N32: 0 | O32: 0 | P32: =M32-(N32+O32) -> 7.5 | Q32: 0 | R32: 0 | S32: =SUM(P32:R32) -> 7.5 | U32: 0 | V32: 15 | W32: =W31-V32 -> 792.11 | X32: =N32+O32+S32+U32+V32 -> 22.5 | Y32: =IF(L32<0,L32*-1,0) -> 6.3043358 | Z32: =X32+Y32 -> 28.804336 | AA32: 0 | AB32: 44 | AC32: 24 | AD32: =(G32+H32-P32-3.35)*0.33*1.9835 -> 19.3421
A33: =A32+1 -> 22 | B33: 6859.92 | C33: 162885 | D33: =C33-C32 -> 22 | E33: =C33-152000 -> 10885 | F33: =D33/$D$2 -> 11.091505 | G33: 23 | H33: 1.3 | I33: =G33+H33 -> 24.3 | J33: =IF(L33>0,L33,0) -> 9.3915049 | K33: =I33+J33 -> 33.691505 | L33: =F33-(I33-X33) -> 9.3915049 | M33: 7.6 | N33: 0 | O33: 0 | P33: =M33-(N33+O33) -> 7.6 | Q33: 0 | R33: 0 | S33: =SUM(P33:R33) -> 7.6 | U33: 0 | V33: 15 | W33: =W32-V33 -> 777.11 | X33: =N33+O33+S33+U33+V33 -> 22.6 | Y33: =IF(L33<0,L33*-1,0) -> 0 | Z33: =X33+Y33 -> 22.6 | AA33: 0 | AB33: 45 | AC33: 22 | AD33: =AD32+(G33+H33-P33-3.35)*1.9835 -> 45.821825
A34: =A33+1 -> 23 | B34: 6859.93 | C34: 162908 | D34: =C34-C33 -> 23 | E34: =C34-152000 -> 10908 | F34: =D34/$D$2 -> 11.595664 | G34: 19 | H34: 1.2 | I34: =G34+H34 -> 20.2 | J34: =IF(L34>0,L34,0) -> 13.895664 | K34: =I34+J34 -> 34.095664 | L34: =F34-(I34-X34) -> 13.895664 | M34: 7.5 | N34: 0 | O34: 0 | P34: =M34-(N34+O34) -> 7.5 | Q34: 0 | R34: 0 | S34: =SUM(P34:R34) -> 7.5 | U34: 0 | V34: 15 | W34: =W33-V34 -> 762.11 | X34: =N34+O34+S34+U34+V34 -> 22.5 | Y34: =IF(L34<0,L34*-1,0) -> 0 | Z34: =X34+Y34 -> 22.5 | AA34: 0 | AB34: 38 | AC34: 16 | AD34: =AD33+(G34+H34-P34-3.35)*1.9835 -> 64.36755
A35: =A34+1 -> 24 | B35: 6859.94 | C35: 162931 | D35: =C35-C34 -> 23 | E35: =C35-152000 -> 10931 | F35: =D35/$D$2 -> 11.595664 | G35: 21 | H35: 1.1 | I35: =G35+H35 -> 22.1 | J35: =IF(L35>0,L35,0) -> 11.995664 | K35: =I35+J35 -> 34.095664 | L35: =F35-(I35-X35) -> 11.995664 | M35: 7.5 | N35: 0 | O35: 0 | P35: =M35-(N35+O35) -> 7.5 | Q35: 0 | R35: 0 | S35: =SUM(P35:R35) -> 7.5 | U35: 0 | V35: 15 | W35: =W34-V35 -> 747.11 | X35: =N35+O35+S35+U35+V35 -> 22.5 | Y35: =IF(L35<0,L35*-1,0) -> 0 | Z35: =X35+Y35 -> 22.5 | AA35: 0 | AB35: 45 | AC35: 25 | AD35: =AD34+(G35+H35-P35-3.35)*1.9835 -> 86.681925
A36: =A35+1 -> 25 | B36: 6960.08 | C36: 163250 | D36: =C36-C35 -> 319 | E36: =C36-152000 -> 11250 | F36: =D36/$D$2 -> 160.82682 | G36: 44 | H36: 1.2 | I36: =G36+H36 -> 45.2 | J36: =IF(L36>0,L36,0) -> 138.12682 | K36: =I36+J36 -> 183.32682 | L36: =F36-(I36-X36) -> 138.12682 | M36: 7.5 | N36: 0 | O36: 0 | P36: =M36-(N36+O36) -> 7.5 | Q36: 0 | R36: 0 | S36: =SUM(P36:R36) -> 7.5 | U36: 0 | V36: 15 | W36: =W35-V36 -> 732.11 | X36: =N36+O36+S36+U36+V36 -> 22.5 | Y36: =IF(L36<0,L36*-1,0) -> 0 | Z36: =X36+Y36 -> 22.5 | AA36: 0.76 | AB36: 38 | AC36: 28 | AD36: =AD35+(G36+H36-P36-3.35)*1.9835 -> 154.81515
A37: =A36+1 -> 26 | B37: 6860.11 | C37: 163319 | D37: =C37-C36 -> 69 | E37: =C37-152000 -> 11319 | F37: =D37/$D$2 -> 34.786993 | G37: 49 | H37: 1.2 | I37: =G37+H37 -> 50.2 | J37: =IF(L37>0,L37,0) -> 7.9869927 | K37: =I37+J37 -> 58.186993 | L37: =F37-(I37-X37) -> 7.9869927 | M37: 7.4 | N37: 0 | O37: 0 | P37: =M37-(N37+O37) -> 7.4 | Q37: 0 | R37: 0 | S37: =SUM(P37:R37) -> 7.4 | U37: 0 | V37: 16 | W37: =W36-V37 -> 716.11 | X37: =N37+O37+S37+U37+V37 -> 23.4 | Y37: =IF(L37<0,L37*-1,0) -> 0 | Z37: =X37+Y37 -> 23.4 | AA37: 0.53 | AB37: 38 | AC37: 29 | AD37: =AD36+(G37+H37-P37-3.35)*1.9835 -> 233.06423
A38: =A37+1 -> 27 | B38: 6860.16 | C38: 163434 | D38: =C38-C37 -> 115 | E38: =C38-152000 -> 11434 | F38: =D38/$D$2 -> 57.978321 | G38: 48 | H38: 1.2 | I38: =G38+H38 -> 49.2 | J38: =IF(L38>0,L38,0) -> 31.178321 | K38: =I38+J38 -> 80.378321 | L38: =F38-(I38-X38) -> 31.178321 | M38: 7.4 | N38: 0 | O38: 0 | P38: =M38-(N38+O38) -> 7.4 | Q38: 0 | R38: 0 | S38: =SUM(P38:R38) -> 7.4 | U38: 0 | V38: 15 | W38: =W37-V38 -> 701.11 | X38: =N38+O38+S38+U38+V38 -> 22.4 | Y38: =IF(L38<0,L38*-1,0) -> 0 | Z38: =X38+Y38 -> 22.4 | AA38: 0.17 | AB38: 34 | AC38: 19 | AD38: =AD37+(G38+H38-P38-3.35)*1.9835 -> 309.3298
A39: 28 | B39: 6860.23 | C39: 163594 | D39: =C39-C38 -> 160 | E39: =C39-152000 -> 11594 | F39: =D39/$D$2 -> 80.66549 | G39: 45 | H39: 1.2 | I39: =G39+H39 -> 46.2 | J39: =IF(L39>0,L39,0) -> 55.96549 | K39: =I39+J39 -> 102.16549 | L39: =F39-(I39-X39) -> 55.96549 | M39: 7.5 | N39: 0 | O39: 0 | P39: =M39-(N39+O39) -> 7.5 | Q39: 0 | R39: 0 | S39: =SUM(P39:R39) -> 7.5 | U39: 0 | V39: 14 | W39: =W38-V39 -> 687.11 | X39: =N39+O39+S39+U39+V39 -> 21.5 | Y39: =IF(L39<0,L39*-1,0) -> 0 | Z39: =X39+Y39 -> 21.5 | AA39: 0.42 | AB39: 34 | AC39: 22 | AD39: =AD38+(G39+H39-P39-3.35)*1.9835 -> 379.44653
A41: MONTH / CFS | F41: =SUM(F12:F39) -> 1486.2617 | G41: =SUM(G12:G39) -> 1011 | H41: =SUM(H12:H39) -> 26.94 | I41: =SUM(I12:I39) -> 1037.94 | J41: =SUM(J12:J39) -> 1128.6545 | K41: =SUM(K12:K39) -> 2166.5945 | L41: =SUM(L12:L39) -> 1071.1217 | M41: =SUM(M12:M39) -> 217.8 | ... S41: =SUM(S12:S39) -> 217.8 | U41: =SUM(U12:U39) -> 0 | V41: =SUM(V12:V39) -> 405 | X41: =SUM(X12:X39) -> 622.8 | Y41: =SUM(Y12:Y39) -> 57.532831 | Z41: =SUM(Z12:Z39) -> 680.33283 | AA41: =SUM(AA12:AA39) -> 2.97 | AB41: =AVERAGE(AB12:AB39) -> 40.928571 | AC41: =AVERAGE(AC12:AC39) -> 20.860714 | AD41: AVE
A42: MONTH / AF | D42: =SUM(D12:D39) -> 2948 | F42: =F41*$D$2 -> 2948 | G42: =G41*$D$2 -> 2005.3185 | H42: =H41*$D$2 -> 53.43549 | I42: =I41*$D$2 -> 2058.754 | J42: =J41*$D$2 -> 2238.6862 | K42: =K41*$D$2 -> 4297.4402 | L42: =L41*$D$2 -> 2124.5698 | M42: =M41*$D$2 -> 432.0063 | ... S42: =S41*$D$2 -> 432.0063 | U42: =U41*$D$2 -> 0 | V42: =V41*$D$2 -> 803.3175 | X42: =X41*$D$2 -> 1235.3238 | Y42: =Y41*$D$2 -> 114.11637 | Z42: =Z41*$D$2 -> 1349.4402 | AB42: =MAX(AB12:AB39) -> 53 | AC42: =MAX(AC12:AC39) -> 35 | AD42: HI
A44: SEASON / CFS | AB44: =MIN(AB12:AB39) -> 28 | AC44: =MIN(AC12:AC39) -> 1 | AD44: LO
A45: SEASON / AF
A47: YTD / CFS | F47: =F10+F41 -> 3542.7275 | G47: =G10+G41 -> 4961 | H47: =H10+H41 -> 28.84 | I47: =I10+I41 -> 4989.84 | J47: =J10+J41 -> 1709.4752 | K47: =K10+K41 -> 6699.3152 | L47: =L10+L41 -> 1120.6775 | M47: =M10+M41 -> 731.9 | ... S47: =S10+S41 -> 844.9 | U47: =U10+U41 -> 0 | V47: =V10+V41 -> 1722.89 | W47: =W39 -> 687.11 | X47: =X10+X41 -> 2567.79 | Y47: =Y10+Y41 -> 588.79775 | Z47: =Z10+Z41 -> 3156.5877 | AA47: =AA10+AA41 -> 5.24
A48: YTD / AF | D48: =D10+D42 -> 7027 | E48: =E39 -> 11594 | F48: =F47*$D$2 -> 7027 | G48: =G47*$D$2 -> 9840.1435 | H48: =H47*$D$2 -> 57.20414 | I48: =I47*$D$2 -> 9897.3476 | J48: =J47*$D$2 -> 3390.7442 | K48: =K47*$D$2 -> 13288.092 | L48: =L47*$D$2 -> 2222.8638 | M48: =M47*$D$2 -> 1451.7236 | ... Z48: =Z47*$D$2 -> 6261.0918

Sheet MAR
K1: MCPHEE RESERVOIR INFLOW/OUTFLOW TABULATION
A2: AF/cfs CONVERT FACTOR | D2: 1.9835 | K2: MARCH "2003"
D4: RESERVOIR | Q4: INFLOW/OUTFLOW (CFS) | AB4: WEATHER
A5: DATE | B5: RESERV | C5: RESERV | D5: AC FT | E5: ACTIVE | F5: CONV TO | G5: DOLORES | H5: LOST | I5: RECORDED | J5: CALC | K5: TOTAL | L5: CALC | M5: DOLORES TUNNEL | Q5: LONE | R5: U | S5: TOTAL | T5: MVI | U5: DV CR | V5: BELOW | W5: REMAIN | X5: RECORDED | Y5: CALC | Z5: TOTAL | AA5: RAIN | AB5: MAX | AC5: MIN | AD5: NAR | AE5: MVI
A6: MAR | B6: ELEV | C6: AC FT | D6: CHANGE | E6: CAP | F6: CFS | G6: RIVER | H6: CANYON | I6: INFLOW | J6: INFLOW | K6: INFLOW | L6: INF/OTF | M6: TOT DIV | N6: SWAMP | O6: UTE F&R | P6: MVI,CTZ | Q6: PINE | R6: LAT | S6: MVI | T6: CALL | U6: CANAL | V6: MCPHEE | W6: RELEASE | X6: OUTFLOW | Y6: OUTFLOW | Z6: OUTFLOW | AB6: TMP | AC6: TMP | AD6: CALL | AE6: CALL
E7: AC FT | T7: & PROJ. | AB7: NOV-OCT | AE7: Apr-Jun
A9: SEASON BAL
A10: YTD | B10: =FEB!B39 -> 6860.23 | C10: =FEB!C39 -> 163594 | D10: =FEB!$D$48 -> 7027 | E10: =FEB!$E$39 -> 11594 | F10: =FEB!F47 -> 3542.7275 | G10: =FEB!G47 -> 4961 | H10: =FEB!H47 -> 28.84 | I10: =FEB!I47 -> 4989.84 | J10: =FEB!J47 -> 1709.4752 | K10: =FEB!K47 -> 6699.3152 | L10: =FEB!L47 -> 1120.6775 | M10: =FEB!M47 -> 731.9 | ... AA10: =FEB!AA47 -> 5.24 | AD10: =FEB!AD39 -> 379.44653
A12: 1 | B12: 6860.28 | C12: 163709 | D12: =C12-C10 -> 115 | E12: =C12-152000 -> 11709 | F12: =D12/$D$2 -> 57.978321 | G12: 29 | H12: 1.2 | I12: =G12+H12 -> 30.2 | J12: =IF(L12>0,L12,0) -> 50.078321 | K12: =I12+J12 -> 80.278321 | L12: =F12-(I12-X12) -> 50.078321 | M12: 7.3 | N12: 0 | O12: 0 | P12: =M12-(N12+O12) -> 7.3 | Q12: 0 | R12: 0 | S12: =SUM(P12:R12) -> 7.3 | U12: 0 | V12: 15 | W12: =W10-V12 -> 672.11 | X12: =N12+O12+S12+U12+V12 -> 22.3 | Y12: =IF(L12<0,L12*-1,0) -> 0 | Z12: =X12+Y12 -> 22.3 | AA12: 0.15 | AB12: 45 | AC12: 11 | AD12: =AD10+(G12+H12-P12-3.35)*1.9835 -> 418.22395
A13: =A12+1 -> 2 | B13: 6860.31 | C13: 163778 | D13: =C13-C12 -> 69 | E13: =C13-152000 -> 11778 | F13: =D13/$D$2 -> 34.786993 | G13: 19 | H13: 1.1 | I13: =G13+H13 -> 20.1 | J13: =IF(L13>0,L13,0) -> 36.786993 | K13: =I13+J13 -> 56.886993 | L13: =F13-(I13-X13) -> 36.786993 | M13: 7.1 | N13: 0 | O13: 0 | P13: =M13-(N13+O13) -> 7.1 | Q13: 0 | R13: 0 | S13: =SUM(P13:R13) -> 7.1 | U13: 0 | V13: 15 | W13: =W12-V13 -> 657.11 | X13: =N13+O13+S13+U13+V13 -> 22.1 | Y13: =IF(L13<0,L13*-1,0) -> 0 | Z13: =X13+Y13 -> 22.1 | AA13: 0 | AB13: 39 | AC13: 6 | AD13: =AD12+(G13+H13-P13-3.35)*1.9835 -> 437.36473
A14: =A13+1 -> 3 | B14: 6860.33 | C14: 163824 | D14: =C14-C13 -> 46 | E14: =C14-152000 -> 11824 | F14: =D14/$D$2 -> 23.191328 | G14: 18 | H14: 1.2 | I14: =G14+H14 -> 19.2 | J14: =IF(L14>0,L14,0) -> 26.391328 | K14: =I14+J14 -> 45.591328 | L14: =F14-(I14-X14) -> 26.391328 | M14: 7.4 | N14: 0 | O14: 0 | P14: =M14-(N14+O14) -> 7.4 | Q14: 0 | R14: 0 | S14: =SUM(P14:R14) -> 7.4 | U14: 0 | V14: 15 | W14: =W13-V14 -> 642.11 | X14: =N14+O14+S14+U14+V14 -> 22.4 | Y14: =IF(L14<0,L14*-1,0) -> 0 | Z14: =X14+Y14 -> 22.4 | AA14: 0 | AB14: 41 | AC14: 10 | AD14: =AD13+(G14+H14-P14-3.35)*1.9835 -> 454.1253
A15: =A14+1 -> 4 | B15: 6860.38 | C15: 163939 | D15: =C15-C14 -> 115 | E15: =C15-152000 -> 11939 | F15: =D15/$D$2 -> 57.978321 | G15: 38 | H15: 1.2 | I15: =G15+H15 -> 39.2 | J15: =IF(L15>0,L15,0) -> 41.478321 | K15: =I15+J15 -> 80.678321 | L15: =F15-(I15-X15) -> 41.478321 | M15: 7.7 | N15: 0 | O15: 0 | P15: =M15-(N15+O15) -> 7.7 | Q15: 0 | R15: 0 | S15: =SUM(P15:R15) -> 7.7 | U15: 0 | V15: 15 | W15: =W14-V15 -> 627.11 | X15: =N15+O15+S15+U15+V15 -> 22.7 | Y15: =IF(L15<0,L15*-1,0) -> 0 | Z15: =X15+Y15 -> 22.7 | AA15: 0.35 | AB15: 33 | AC15: 25 | AD15: =AD14+(G15+H15-P15-3.35)*1.9835 -> 509.96083
