Workbook

Sheet NOV
K1: MCPHEE RESERVOIR INFLOW/OUTFLOW TABULATION
A2: AF/cfs CONVERT FACTOR | D2: 1.9835 | K2: NOVEMBER "2024"
D4: RESERVOIR | I4: INFLOW | X4: OUTFLOW | AX4: ADJUSTMENTS | BE4: WEATHER
A5: DATE | B5: RESERV | C5: RESERV | D5: AC FT | E5: ACTIVE | F5: CONV TO | G5: DOLORES | H5: LOST | I5: RECORD | J5: CALC | K5: TOTAL | L5: CALC | M5: DOLORES TUNNEL | V5: LONE | W5: U | X5: TOTAL | Y5: TOTAL | Z5: MVI | AA5: MVI | AB5: MVI | AC5: TO EX & | AD5: MVI | AE5: DV CR | AF5: D/S SENIOR | AH5: BELOW | AI5: FISH | AJ5: SPILL | AK5: RECORD | AL5: CALC | AM5: TOTAL | AN5: NAR | AO5: NARR | AP5: DWR | AQ5: MCPHEE | AR5: LAKE | AS5: MCPHEE | AT5: NARR | AU5: CUM | AV5: CUM | AW5: MVI | AX5: MVI | AY5: MVI | AZ5: DIST. | BA5: U/S | BB5: TOTTEN | BC5: UF&R | BD5: RAIN | BE5: MAX | BF5: MIN | BH5: TOTAL | BI5: GRNDHOG | BJ5: GRNDHOG | BM5: RESERV | BO5: BELOW | BP5: BELOW
A6: NOV | B6: ELEV | C6: TOT CAP | D6: CHANGE | E6: CAP | F6: CFS | G6: RIVER | H6: CAN | I6: INFLOW | J6: INFLOW | K6: INFLOW | L6: INF/OTF | M6: DOL | N6: WET | O6: UTE | P6: SEELEY | Q6: MWC | R6: CORTEZ | T6: UTE | U6: F-BAY | V6: PINE | W6: LAT | X6: MVI | Y6: MVI | Z6: CALL | AA6: CALL | AB6: APR- | AC6: U/S EX | AD6: PROJ | AE6: CANAL | AF6: MVIC | AG6: PROJ | AH6: MCP | AI6: LEFT | AK6: OTF | AL6: OTF | AM6: OTF | AN6: FILL | AO6: FILL | AP6: EST | AQ6: DAILY | AR6: SURFACE | AS6: DAILY | AT6: IN MCP | AU6: NARR | AV6: NARR | AW6: STOCK | AX6: STORED | AY6: STORED | AZ6: CLASS | BA6: USERS | BB6: (FRESH | BC6: LEASE | BE6: TMP | BF6: TMP | BH6: TUNNEL | BI6: DISCHARGE | BJ6: CAPACITY | BM6: ELEV | BO6: MCP | BP6: MCP
M7: TUN | N7: LAND | O7: F&R | Q7: NON - | R7: NON - | S7: PROJ | T7: PROJ | U7: BAL | X7: WATER | Y7: IRRIG. | Z7: STOR | AA7: SPILLED | AB7: JUNE | AF7: 1.7 | AG7: 1.3 | AI7: =29824+1274+700 -> 31798 | AO7: IN | AP7: PAN | AQ7: EVAP | AR7: AREA | AS7: EVAP | AT7: EVAP | AU7: IN MCP | AV7: IN | AX7: Apr - Jun | AY7: EVAP | AZ7: "B" | BA7: EXCH | BB7: WATER) | BC7: WATER | BH7: Misc. | BM7: DTGH | BO7: MPP | BP7: OVER
M8: TOT | Q8: PROJ | R8: PROJ | X8: USED | Y8: WATER | AA8: OR | AB8: (DIV+ | AI8: =AI7/1.9835 -> 16031.258 | AO8: MCPHEE | AP8: EVAP | AU8: EVAP | AV8: MCPHEE | BP8: MPP
M9: DIV | R9: 4.2 | Y9: USED | AA9: USED | AB9: CALL) | AI9: 9697.843 | BJ9: FP = 3960
A10: UNIT | B10: FT | C10: AC FT | D10: AC FT | E10: AC FT | F10: CFS | G10: CFS | H10: CFS | I10: CFS | J10: CFS | K10: CFS | L10: CFS | M10: CFS | N10: CFS | O10: CFS | P10: CFS | Q10: CFS | R10: CFS | S10: CFS | T10: CFS | U10: CFS | V10: CFS | W10: CFS | X10: 153400 | Y10: 150400 | AB10: 72000 | AC10: CFS | AD10: CFS | AE10: CFS | AF10: CFS | AG10: CFS | AH10: CFS | AI10: CFS | AJ10: CFS | AK10: CFS | AL10: CFS | AM10: CFS | AN10: CFS | AO10: CFS | AP10: IN | AQ10: IN | AR10: AC. | AS10: AF | AT10: AF | AU10: AF | AV10: CFS | AW10: CFS | AX10: CFS | AY10: AC.FT. | AZ10: CFS | BA10: CFS | BB10: CFS | BC10: CFS | BD10: IN | BE10: DEG ° | BF10: DEG ° | BH10: Outflow | BI10: CFS | BJ10: AC FT | BO10: CFS | BP10: CFS
N11: 1.03 | O11: 1.05 | P11: 1.02 | Q11: 1.02 | R11: 1.04 | T11: 1.04 | X11: CFS | Y11: CFS | Z11: CFS | AA11: CFS | AB11: Ac. Ft. | AT11: 0 | BE11: F | BF11: F | BH11: CFS
A12: SEASON BAL | AT12: AF | AU12: AF
A13: YTD | B13: 6877.66 | C13: =VLOOKUP(TRUNC(B13,1),VLOOKUP!$A$3:$K$2834,RIGHT(TEXT(B13,"0000.00"),1)+2,FALSE) -> 209232 | E13: =C13-152000 -> 57232 | AI13: =AI9/1.9835 -> 4889.2579 | AO13: 0 | AT13: 0 | AU13: 0 | AV13: 0
A15: 1 | B15: 6877.68 | C15: =IF(B15="",C13,VLOOKUP(TRUNC(B15,1),VLOOKUP!$A$3:$K$2834,RIGHT(TEXT(B15,"0000.00"),1)+2,FALSE)) -> 209290 | D15: =C15-C13 -> 58 | E15: =C15-152000 -> 57290 | F15: =D15/$D$2 -> 29.24124 | G15: 85.7 | H15: 0 | I15: =G15+H15 -> 85.7 | J15: =IF(L15>0,L15,0) -> 0 | K15: =I15+J15 -> 85.7 | L15: =IF(G15="",0,F15-(I15-AK15)) -> -13.66876 | M15: 3.39 | N15: 0 | O15: =15*1.05 -> 15.75 | P15: 0 | Q15: =883200/325851/1.9835*1.02 -> 1.3938241 | R15: 0 | S15: =IF(((2.5*1.04)-T15)>=4.2,4.2,(2.5*1.04)-T15) -> 1.894464 | T15: =(0.64*1.06)*1.04 -> 0.705536 | U15: =M15-(Q15+R15+S15+T15) -> -0.6038241 | V15: 0 | W15: 0 | X15: =MAX(0,M15-N15-O15-P15-Q15-R15-S15-T15-U15+V15+W15-BB15+AZ15-AN15) -> 0 | Y15: =X15-AW15 -> 0 | AE15: 0 | AF15: 0 | AG15: 0 | AH15: 39.4 | AI15: =AI13-AH15 -> 4849.8579 | AJ15: 0 | AK15: =AE15+AH15+M15+V15+W15 -> 42.79 | AL15: =IF(L15<0,L15*-1,0) -> 13.66876 | AM15: =AK15+AL15 -> 56.45876 | AN15: =IF(V15="","",V15) -> 0 | AO15: =IF(G15="","",IF(I15>=795,795-MAX(0,M15-N15-O15-P15-Q15-R15-S15-T15-U15+V15+W15-BB15+AZ15),I15-Q15-R15-MAX(0,M15-N15-O15-P15-Q15-R15-S15-T15-U15+V15+W15-BB15+AZ15)-AF15)-AJ15) -> 84.306176 | AP15: 0.0475 | AQ15: =AP15*0.7 -> 0.03325 | AR15: =IF(AP15="",0,VLOOKUP(ROUNDDOWN(TEXT(B15,"0000"),-1),VLOOKUP!$M$3:$W$32,RIGHT(TEXT(B15,"0000"),1)+2,FALSE)) -> 2938 | AS15: =IF(B15="",0,AQ15/12*AR15) -> 8.1407083 | AT15: =AS15*(AV15/E15) -> 0.011979612 | AU15: =AT15+AU13 -> 0.011979612 | AV15: =IF(AO15="",AV13,AO15+AV13-(AT13/1.9835)) -> 84.306176 | BD15: 0 | BE15: 61 | BF15: 30 | BH15: =SUM(N15,P15:U15) -> 3.39 | BI15: 0 | BJ15: 12571.875 | BL15: 1 | BM15: 6878.08 | BN15: =B15-BM15 -> -0.4 | BO15: 0 | BP15: =AH15-BO15 -> 39.4
A16: =A15+1 -> 2 | B16: 6877.7 | C16: =IF(B16="",C15,VLOOKUP(TRUNC(B16,1),VLOOKUP!$A$3:$K$2834,RIGHT(TEXT(B16,"0000.00"),1)+2,FALSE)) -> 209348 | D16: =C16-C15 -> 58 | E16: =C16-152000 -> 57348 | F16: =D16/$D$2 -> 29.24124 | G16: 81.1 | H16: 0 | I16: =G16+H16 -> 81.1 | J16: =IF(L16>0,L16,0) -> 0 | K16: =I16+J16 -> 81.1 | L16: =IF(G16="",0,F16-(I16-AK16)) -> -8.9887598 | M16: 3.47 | N16: 0 | O16: =18.3*1.05 -> 19.215 | P16: 0 | Q16: =1070300/325851/1.9835*1.02 -> 1.6890964 | R16: 0 | S16: =IF(((1.4*1.04)-T16)>=4.2,4.2,(1.4*1.04)-T16) -> 0.750464 | T16: =(0.64*1.06)*1.04 -> 0.705536 | U16: =M16-(Q16+R16+S16+T16) -> 0.32490361 | V16: 0 | W16: 0 | X16: =MAX(0,M16-N16-O16-P16-Q16-R16-S16-T16-U16+V16+W16-BB16+AZ16-AN16) -> 0 | Y16: =X16-AW16 -> 0 | AE16: 0 | AF16: 0 | AG16: 0 | AH16: 39.4 | AI16: =AI15-AH16 -> 4810.4579 | AJ16: 0 | AK16: =AE16+AH16+M16+V16+W16 -> 42.87 | AL16: =IF(L16<0,L16*-1,0) -> 8.9887598 | AM16: =AK16+AL16 -> 51.85876 | AN16: =IF(V16="","",V16) -> 0 | AO16: =IF(G16="","",IF(I16>=795,795-MAX(0,M16-N16-O16-P16-Q16-R16-S16-T16-U16+V16+W16-BB16+AZ16),I16-Q16-R16-MAX(0,M16-N16-O16-P16-Q16-R16-S16-T16-U16+V16+W16-BB16+AZ16)-AF16)-AJ16) -> 79.410904 | AP16: 0.0475 | AQ16: =AP16*0.7 -> 0.03325 | AR16: =IF(AP16="",0,VLOOKUP(ROUNDDOWN(TEXT(B16,"0000"),-1),VLOOKUP!$M$3:$W$32,RIGHT(TEXT(B16,"0000"),1)+2,FALSE)) -> 2938 | AS16: =IF(B16="",0,AQ16/12*AR16) -> 8.1407083 | AT16: =AS16*(AV16/E16) -> 0.023239238 | AU16: =AT16+AU15 -> 0.03521885 | AV16: =IF(AO16="",AV15,AO16+AV15-(AT15/1.9835)) -> 163.71104 | BD16: 0 | BE16: 61 | BF16: 30 | BH16: =SUM(N16,P16:U16) -> 3.47 | BI16: 0 | BJ16: 12568.125 | BL16: =BL15+1 -> 2 | BM16: 6878.1 | BN16: =B16-BM16 -> -0.4 | BO16: 0 | BP16: =AH16-BO16 -> 39.4
A17: =A16+1 -> 3 | B17: 6877.72 | C17: =IF(B17="",C16,VLOOKUP(TRUNC(B17,1),VLOOKUP!$A$3:$K$2834,RIGHT(TEXT(B17,"0000.00"),1)+2,FALSE)) -> 209407 | D17: =C17-C16 -> 59 | E17: =C17-152000 -> 57407 | F17: =D17/$D$2 -> 29.7454 | G17: 78.7 | H17: 0 | I17: =G17+H17 -> 78.7 | J17: =IF(L17>0,L17,0) -> 0 | K17: =I17+J17 -> 78.7 | L17: =IF(G17="",0,F17-(I17-AK17)) -> -5.7246005 | M17: 3.83 | N17: 0 | O17: =0*1.05 -> 0 | P17: 0 | Q17: =1037600/325851/1.9835*1.02 -> 1.6374908 | R17: 0 | S17: =IF(((2.4*1.04)-T17)>=4.2,4.2,(2.4*1.04)-T17) -> 1.790464 | T17: =(0.64*1.06)*1.04 -> 0.705536 | U17: =M17-(Q17+R17+S17+T17) -> -0.30349081 | V17: 0 | W17: 0 | X17: =MAX(0,M17-N17-O17-P17-Q17-R17-S17-T17-U17+V17+W17-BB17+AZ17-AN17) -> 3.3306691e-16 | Y17: =X17-AW17 -> 3.3306691e-16 | AE17: 0 | AF17: 0 | AG17: 0 | AH17: 39.4 | AI17: =AI16-AH17 -> 4771.0579 | AJ17: 0 | AK17: =AE17+AH17+M17+V17+W17 -> 43.23 | AL17: =IF(L17<0,L17*-1,0) -> 5.7246005 | AM17: =AK17+AL17 -> 48.9546 | AN17: =IF(V17="","",V17) -> 0 | AO17: =IF(G17="","",IF(I17>=795,795-MAX(0,M17-N17-O17-P17-Q17-R17-S17-T17-U17+V17+W17-BB17+AZ17),I17-Q17-R17-MAX(0,M17-N17-O17-P17-Q17-R17-S17-T17-U17+V17+W17-BB17+AZ17)-AF17)-AJ17) -> 77.062509 | AP17: 0.0475 | AQ17: =AP17*0.7 -> 0.03325 | AR17: =IF(AP17="",0,VLOOKUP(ROUNDDOWN(TEXT(B17,"0000"),-1),VLOOKUP!$M$3:$W$32,RIGHT(TEXT(B17,"0000"),1)+2,FALSE)) -> 2938 | AS17: =IF(B17="",0,AQ17/12*AR17) -> 8.1407083 | AT17: =AS17*(AV17/E17) -> 0.034141688 | AU17: =AT17+AU16 -> 0.069360538 | AV17: =IF(AO17="",AV16,AO17+AV16-(AT16/1.9835)) -> 240.76183 | BD17: 0.02 | BE17: 46 | BF17: 29 | BH17: =SUM(N17,P17:U17) -> 3.83 | BI17: 0 | BJ17: 12565.458 | BL17: =BL16+1 -> 3 | BM17: 6878.13 | BN17: =B17-BM17 -> -0.41 | BO17: 0 | BP17: =AH17-BO17 -> 39.4
A18: =A17+1 -> 4 | B18: 6877.72 | C18: =IF(B18="",C17,VLOOKUP(TRUNC(B18,1),VLOOKUP!$A$3:$K$2834,RIGHT(TEXT(B18,"0000.00"),1)+2,FALSE)) -> 209407 | D18: =C18-C17 -> 0 | E18: =C18-152000 -> 57407 | F18: =D18/$D$2 -> 0 | G18: 75.6 | H18: 1.04 | I18: =G18+H18 -> 76.64 | J18: =IF(L18>0,L18,0) -> 0 | K18: =I18+J18 -> 76.64 | L18: =IF(G18="",0,F18-(I18-AK18)) -> -33.1 | M18: 4.14 | N18: 0 | O18: =16.3*1.05 -> 17.115 | P18: 0 | Q18: =1029200/325851/1.9835*1.02 -> 1.6242343 | R18: 0 | S18: =IF(((2.4*1.04)-T18)>=4.2,4.2,(2.4*1.04)-T18) -> 1.790464 | T18: =(0.64*1.06)*1.04 -> 0.705536 | U18: =M18-(Q18+R18+S18+T18) -> 0.019765667 | V18: 0 | W18: 0 | X18: =MAX(0,M18-N18-O18-P18-Q18-R18-S18-T18-U18+V18+W18-BB18+AZ18-AN18) -> 0 | Y18: =X18-AW18 -> 0 | AE18: 0 | AF18: 0 | AG18: 0 | AH18: 39.4 | AI18: =AI17-AH18 -> 4731.6579 | AJ18: 0 | AK18: =AE18+AH18+M18+V18+W18 -> 43.54 | AL18: =IF(L18<0,L18*-1,0) -> 33.1 | AM18: =AK18+AL18 -> 76.64 | AN18: =IF(V18="","",V18) -> 0 | AO18: =IF(G18="","",IF(I18>=795,795-MAX(0,M18-N18-O18-P18-Q18-R18-S18-T18-U18+V18+W18-BB18+AZ18),I18-Q18-R18-MAX(0,M18-N18-O18-P18-Q18-R18-S18-T18-U18+V18+W18-BB18+AZ18)-AF18)-AJ18) -> 75.015766 | AP18: 0.0475 | AQ18: =AP18*0.7 -> 0.03325 | AR18: =IF(AP18="",0,VLOOKUP(ROUNDDOWN(TEXT(B18,"0000"),-1),VLOOKUP!$M$3:$W$32,RIGHT(TEXT(B18,"0000"),1)+2,FALSE)) -> 2938 | AS18: =IF(B18="",0,AQ18/12*AR18) -> 8.1407083 | AT18: =AS18*(AV18/E18) -> 0.044776999 | AU18: =AT18+AU17 -> 0.11413754 | AV18: =IF(AO18="",AV17,AO18+AV17-(AT17/1.9835)) -> 315.76039 | BD18: 0 | BE18: 47 | BF18: 28 | BH18: =SUM(N18,P18:U18) -> 4.14 | BI18: 0 | BJ18: 12565.875 | BL18: =BL17+1 -> 4 | BM18: 6878.14 | BN18: =B18-BM18 -> -0.42 | BO18: 0 | BP18: =AH18-BO18 -> 39.4
A19: =A18+1 -> 5 | B19: 6877.7233 | C19: =IF(B19="",C18,VLOOKUP(TRUNC(B19,1),VLOOKUP!$A$3:$K$2834,RIGHT(TEXT(B19,"0000.00"),1)+2,FALSE)) -> 209407 | D19: =C19-C18 -> 0 | E19: =C19-152000 -> 57407 | F19: =D19/$D$2 -> 0 | G19: 68.3 | H19: 0.74 | I19: =G19+H19 -> 69.04 | J19: =IF(L19>0,L19,0) -> 0 | K19: =I19+J19 -> 69.04 | L19: =IF(G19="",0,F19-(I19-AK19)) -> -25.32 | M19: 4.32 | N19: 0 | O19: =2.76*1.05 -> 2.898 | P19: 0 | Q19: =1022300/325851/1.9835*1.02 -> 1.6133451 | R19: 0 | S19: =IF(((2.3*1.04)-T19)>=4.2,4.2,(2.3*1.04)-T19) -> 1.686464 | T19: =(0.64*1.06)*1.04 -> 0.705536 | U19: =M19-(Q19+R19+S19+T19) -> 0.31465492 | V19: 0 | W19: 0 | X19: =MAX(0,M19-N19-O19-P19-Q19-R19-S19-T19-U19+V19+W19-BB19+AZ19-AN19) -> 0 | Y19: =X19-AW19 -> 0 | AE19: 0 | AF19: 0 | AG19: 0 | AH19: 39.4 | AI19: =AI18-AH19 -> 4692.2579 | AJ19: 0 | AK19: =AE19+AH19+M19+V19+W19 -> 43.72 | AL19: =IF(L19<0,L19*-1,0) -> 25.32 | AM19: =AK19+AL19 -> 69.04 | AN19: =IF(V19="","",V19) -> 0 | AO19: =IF(G19="","",IF(I19>=795,795-MAX(0,M19-N19-O19-P19-Q19-R19-S19-T19-U19+V19+W19-BB19+AZ19),I19-Q19-R19-MAX(0,M19-N19-O19-P19-Q19-R19-S19-T19-U19+V19+W19-BB19+AZ19)-AF19)-AJ19) -> 67.426655 | AP19: 0.0475 | AQ19: =AP19*0.7 -> 0.03325 | AR19: =IF(AP19="",0,VLOOKUP(ROUNDDOWN(TEXT(B19,"0000"),-1),VLOOKUP!$M$3:$W$32,RIGHT(TEXT(B19,"0000"),1)+2,FALSE)) -> 2938 | AS19: =IF(B19="",0,AQ19/12*AR19) -> 8.1407083 | AT19: =AS19*(AV19/E19) -> 0.054335363 | AU19: =AT19+AU18 -> 0.1684729 | AV19: =IF(AO19="",AV18,AO19+AV18-(AT18/1.9835)) -> 383.16447 | BD19: 0 | BE19: 40.57 | BF19: 22.18 | BH19: =SUM(N19,P19:U19) -> 4.32 | BI19: 0 | BJ19: 12562.583 | BL19: =BL18+1 -> 5 | BM19: 6878.14 | BN19: =B19-BM19 -> -0.41666667 | BO19: 0 | BP19: =AH19-BO19 -> 39.4
A20: =A19+1 -> 6 | B20: 6877.7267 | C20: =IF(B20="",C19,VLOOKUP(TRUNC(B20,1),VLOOKUP!$A$3:$K$2834,RIGHT(TEXT(B20,"0000.00"),1)+2,FALSE)) -> 209436 | D20: =C20-C19 -> 29 | E20: =C20-152000 -> 57436 | F20: =D20/$D$2 -> 14.62062 | G20: 67.4 | H20: 0.19 | I20: =G20+H20 -> 67.59 | J20: =IF(L20>0,L20,0) -> 0 | K20: =I20+J20 -> 67.59 | L20: =IF(G20="",0,F20-(I20-AK20)) -> -9.1693799 | M20: 4.4 | N20: 0 | O20: =7.41*1.05 -> 7.7805 | P20: 0 | Q20: =1046200/325851/1.9835*1.02 -> 1.6510629 | R20: 0 | S20: =IF(((2.1*1.04)-T20)>=4.2,4.2,(2.1*1.04)-T20) -> 1.478464 | T20: =(0.64*1.06)*1.04 -> 0.705536 | U20: =M20-(Q20+R20+S20+T20) -> 0.56493708 | V20: 0 | W20: 0 | X20: =MAX(0,M20-N20-O20-P20-Q20-R20-S20-T20-U20+V20+W20-BB20+AZ20-AN20) -> 0 | Y20: =X20-AW20 -> 0 | AE20: 0 | AF20: 0 | AG20: 0 | AH20: 39.4 | AI20: =AI19-AH20 -> 4652.8579 | AJ20: 0 | AK20: =AE20+AH20+M20+V20+W20 -> 43.8 | AL20: =IF(L20<0,L20*-1,0) -> 9.1693799 | AM20: =AK20+AL20 -> 52.96938 | AN20: =IF(V20="","",V20) -> 0 | AO20: =IF(G20="","",IF(I20>=795,795-MAX(0,M20-N20-O20-P20-Q20-R20-S20-T20-U20+V20+W20-BB20+AZ20),I20-Q20-R20-MAX(0,M20-N20-O20-P20-Q20-R20-S20-T20-U20+V20+W20-BB20+AZ20)-AF20)-AJ20) -> 65.938937 | AP20: 0.0475 | AQ20: =AP20*0.7 -> 0.03325 | AR20: =IF(AP20="",0,VLOOKUP(ROUNDDOWN(TEXT(B20,"0000"),-1),VLOOKUP!$M$3:$W$32,RIGHT(TEXT(B20,"0000"),1)+2,FALSE)) -> 2938 | AS20: =IF(B20="",0,AQ20/12*AR20) -> 8.1407083 | AT20: =AS20*(AV20/E20) -> 0.06364992 | AU20: =AT20+AU19 -> 0.23212282 | AV20: =IF(AO20="",AV19,AO20+AV19-(AT19/1.9835)) -> 449.07601 | BD20: 0 | BE20: 30.94 | BF20: 19.24 | BH20: =SUM(N20,P20:U20) -> 4.4 | BI20: 0 | BJ20: 12573.083 | BL20: =BL19+1 -> 6 | BM20: 6878.14 | BN20: =B20-BM20 -> -0.41333333 | BO20: 0 | BP20: =AH20-BO20 -> 39.4
A21: =A20+1 -> 7 | B21: 6877.73 | C21: =IF(B21="",C20,VLOOKUP(TRUNC(B21,1),VLOOKUP!$A$3:$K$2834,RIGHT(TEXT(B21,"0000.00"),1)+2,FALSE)) -> 209436 | D21: =C21-C20 -> 0 | E21: =C21-152000 -> 57436 | F21: =D21/$D$2 -> 0 | G21: 55.8 | H21: 0.18 | I21: =G21+H21 -> 55.98 | J21: =IF(L21>0,L21,0) -> 17.6 | K21: =I21+J21 -> 73.58 | L21: =IF(G21="",0,F21-(I21-AK21)) -> 17.6 | M21: 4.48 | N21: 0 | O21: =0*1.05 -> 0 | P21: 0 | Q21: =911800/325851/1.9835*1.02 -> 1.4389593 | R21: 0 | S21: =IF(((1.9*1.04)-T21)>=4.2,4.2,(1.9*1.04)-T21) -> 1.270464 | T21: =(0.64*1.06)*1.04 -> 0.705536 | U21: =M21-(Q21+R21+S21+T21) -> 1.0650407 | V21: 29.7 | W21: 0 | X21: =MAX(0,M21-N21-O21-P21-Q21-R21-S21-T21-U21+V21+W21-BB21+AZ21-AN21) -> 0 | Y21: =X21-AW21 -> 0 | AE21: 0 | AF21: 0 | AG21: 0 | AH21: 39.4 | AI21: =AI20-AH21 -> 4613.4579 | AJ21: 0 | AK21: =AE21+AH21+M21+V21+W21 -> 73.58 | AL21: =IF(L21<0,L21*-1,0) -> 0 | AM21: =AK21+AL21 -> 73.58 | AN21: =IF(V21="","",V21) -> 29.7 | AO21: =IF(G21="","",IF(I21>=795,795-MAX(0,M21-N21-O21-P21-Q21-R21-S21-T21-U21+V21+W21-BB21+AZ21),I21-Q21-R21-MAX(0,M21-N21-O21-P21-Q21-R21-S21-T21-U21+V21+W21-BB21+AZ21)-AF21)-AJ21) -> 24.841041 | AP21: 0.0475 | AQ21: =AP21*0.7 -> 0.03325 | AR21: =IF(AP21="",0,VLOOKUP(ROUNDDOWN(TEXT(B21,"0000"),-1),VLOOKUP!$M$3:$W$32,RIGHT(TEXT(B21,"0000"),1)+2,FALSE)) -> 2938 | AS21: =IF(B21="",0,AQ21/12*AR21) -> 8.1407083 | AT21: =AS21*(AV21/E21) -> 0.067166224 | AU21: =AT21+AU20 -> 0.29928904 | AV21: =IF(AO21="",AV20,AO21+AV20-(AT20/1.9835)) -> 473.88496 | BD21: 0 | BE21: 44 | BF21: 25 | BH21: =SUM(N21,P21:U21) -> 4.48 | BI21: 0 | BJ21: 12574.708 | BL21: =BL20+1 -> 7 | BM21: 6878.14 | BN21: =B21-BM21 -> -0.41 | BO21: 0 | BP21: =AH21-BO21 -> 39.4
A22: =A21+1 -> 8 | B22: 6877.68 | C22: =IF(B22="",C21,VLOOKUP(TRUNC(B22,1),VLOOKUP!$A$3:$K$2834,RIGHT(TEXT(B22,"0000.00"),1)+2,FALSE)) -> 209290 | D22: =C22-C21 -> -146 | E22: =C22-152000 -> 57290 | F22: =D22/$D$2 -> -73.60726 | G22: 73.2 | H22: 0.22 | I22: =G22+H22 -> 73.42 | J22: =IF(L22>0,L22,0) -> 0 | K22: =I22+J22 -> 73.42 | L22: =IF(G22="",0,F22-(I22-AK22)) -> -5.6172599 | M22: 3.21 | N22: 0 | O22: =0*1.05 -> 0 | P22: 0 | Q22: =980600/325851/1.9835*1.02 -> 1.5475361 | R22: 0 | S22: =IF(((2*1.04)-T22)>=4.2,4.2,(2*1.04)-T22) -> 1.429584 | T22: =(0.59*1.06)*1.04 -> 0.650416 | U22: =M22-(Q22+R22+S22+T22) -> -0.41753613 | V22: 98.8 | W22: 0 | X22: =MAX(0,M22-N22-O22-P22-Q22-R22-S22-T22-U22+V22+W22-BB22+AZ22-AN22) -> 0 | Y22: =X22-AW22 -> 0 | AE22: 0 | AF22: 0 | AG22: 0 | AH22: 39.4 | AI22: =AI21-AH22 -> 4574.0579 | AJ22: 0 | AK22: =AE22+AH22+M22+V22+W22 -> 141.41 | AL22: =IF(L22<0,L22*-1,0) -> 5.6172599 | AM22: =AK22+AL22 -> 147.02726 | AN22: =IF(V22="","",V22) -> 98.8 | AO22: =IF(G22="","",IF(I22>=795,795-MAX(0,M22-N22-O22-P22-Q22-R22-S22-T22-U22+V22+W22-BB22+AZ22),I22-Q22-R22-MAX(0,M22-N22-O22-P22-Q22-R22-S22-T22-U22+V22+W22-BB22+AZ22)-AF22)-AJ22) -> -26.927536 | AP22: 0.0475 | AQ22: =AP22*0.7 -> 0.03325 | AR22: =IF(AP22="",0,VLOOKUP(ROUNDDOWN(TEXT(B22,"0000"),-1),VLOOKUP!$M$3:$W$32,RIGHT(TEXT(B22,"0000"),1)+2,FALSE)) -> 2938 | AS22: =IF(B22="",0,AQ22/12*AR22) -> 8.1407083 | AT22: =AS22*(AV22/E22) -> 0.063506273 | AU22: =AT22+AU21 -> 0.36279532 | AV22: =IF(AO22="",AV21,AO22+AV21-(AT21/1.9835)) -> 446.92356 | BD22: 0.04 | BE22: 43 | BF22: 27 | BH22: =SUM(N22,P22:U22) -> 3.21 | BI22: 0 | BJ22: 12576.875 | BL22: =BL21+1 -> 8 | BM22: 6878.08 | BN22: =B22-BM22 -> -0.4 | BO22: 0 | BP22: =AH22-BO22 -> 39.4
A23: =A22+1 -> 9 | B23: 6877.61 | C23: =IF(B23="",C22,VLOOKUP(TRUNC(B23,1),VLOOKUP!$A$3:$K$2834,RIGHT(TEXT(B23,"0000.00"),1)+2,FALSE)) -> 209086 | D23: =C23-C22 -> -204 | E23: =C23-152000 -> 57086 | F23: =D23/$D$2 -> -102.8485 | G23: 68.6 | H23: 0.34 | I23: =G23+H23 -> 68.94 | J23: =IF(L23>0,L23,0) -> 0 | K23: =I23+J23 -> 68.94 | L23: =IF(G23="",0,F23-(I23-AK23)) -> -29.8885 | M23: 4 | N23: 0 | O23: =0*1.05 -> 0 | P23: 0 | Q23: =1044800/325851/1.9835*1.02 -> 1.6488535 | R23: 0 | S23: =IF(((2*1.04)-T23)>=4.2,4.2,(2*1.04)-T23) -> 1.429584 | T23: =(0.59*1.06)*1.04 -> 0.650416 | U23: =M23-(Q23+R23+S23+T23) -> 0.27114649 | V23: 98.5 | W23: 0 | X23: =MAX(0,M23-N23-O23-P23-Q23-R23-S23-T23-U23+V23+W23-BB23+AZ23-AN23) -> 0 | Y23: =X23-AW23 -> 0 | AE23: 0 | AF23: 0 | AG23: 0 | AH23: 39.4 | AI23: =AI22-AH23 -> 4534.6579 | AJ23: 0 | AK23: =AE23+AH23+M23+V23+W23 -> 141.9 | AL23: =IF(L23<0,L23*-1,0) -> 29.8885 | AM23: =AK23+AL23 -> 171.7885 | AN23: =IF(V23="","",V23) -> 98.5 | AO23: =IF(G23="","",IF(I23>=795,795-MAX(0,M23-N23-O23-P23-Q23-R23-S23-T23-U23+V23+W23-BB23+AZ23),I23-Q23-R23-MAX(0,M23-N23-O23-P23-Q23-R23-S23-T23-U23+V23+W23-BB23+AZ23)-AF23)-AJ23) -> -31.208854 | AP23: 0.0475 | AQ23: =AP23*0.7 -> 0.03325 | AR23: =IF(AP23="",0,VLOOKUP(ROUNDDOWN(TEXT(B23,"0000"),-1),VLOOKUP!$M$3:$W$32,RIGHT(TEXT(B23,"0000"),1)+2,FALSE)) -> 2938 | AS23: =IF(B23="",0,AQ23/12*AR23) -> 8.1407083 | AT23: =AS23*(AV23/E23) -> 0.059278134 | AU23: =AT23+AU22 -> 0.42207345 | AV23: =IF(AO23="",AV22,AO23+AV22-(AT22/1.9835)) -> 415.68269 | BD23: 0 | BE23: 55 | BF23: 31 | BH23: =SUM(N23,P23:U23) -> 4 | BI23: 0 | BJ23: 12576.583 | BL23: =BL22+1 -> 9 | BM23: 6878.02 | BN23: =B23-BM23 -> -0.41 | BO23: 0 | BP23: =AH23-BO23 -> 39.4
A24: =A23+1 -> 10 | B24: 6877.54 | C24: =IF(B24="",C23,VLOOKUP(TRUNC(B24,1),VLOOKUP!$A$3:$K$2834,RIGHT(TEXT(B24,"0000.00"),1)+2,FALSE)) -> 208881 | D24: =C24-C23 -> -205 | E24: =C24-152000 -> 56881 | F24: =D24/$D$2 -> -103.35266 | G24: 59.1 | H24: 0.28 | I24: =G24+H24 -> 59.38 | J24: =IF(L24>0,L24,0) -> 0 | K24: =I24+J24 -> 59.38 | L24: =IF(G24="",0,F24-(I24-AK24)) -> -20.762659 | M24: 4.07 | N24: 0 | O24: =0*1.05 -> 0 | P24: 0 | Q24: =1164900/325851/1.9835*1.02 -> 1.8383896 | R24: 0 | S24: =IF(((2.4*1.04)-T24)>=4.2,4.2,(2.4*1.04)-T24) -> 1.845584 | T24: =(0.59*1.06)*1.04 -> 0.650416 | U24: =M24-(Q24+R24+S24+T24) -> -0.2643896 | V24: 98.5 | W24: 0 | X24: =MAX(0,M24-N24-O24-P24-Q24-R24-S24-T24-U24+V24+W24-BB24+AZ24-AN24) -> 0 | Y24: =X24-AW24 -> 0 | AE24: 0 | AF24: 0 | AG24: 0 | AH24: 39.4 | AI24: =AI23-AH24 -> 4495.2579 | AJ24: 0 | AK24: =AE24+AH24+M24+V24+W24 -> 141.97 | AL24: =IF(L24<0,L24*-1,0) -> 20.762659 | AM24: =AK24+AL24 -> 162.73266 | AN24: =IF(V24="","",V24) -> 98.5 | AO24: =IF(G24="","",IF(I24>=795,795-MAX(0,M24-N24-O24-P24-Q24-R24-S24-T24-U24+V24+W24-BB24+AZ24),I24-Q24-R24-MAX(0,M24-N24-O24-P24-Q24-R24-S24-T24-U24+V24+W24-BB24+AZ24)-AF24)-AJ24) -> -40.95839 | AP24: 0.0475 | AQ24: =AP24*0.7 -> 0.03325 | AR24: =IF(AP24="",0,VLOOKUP(ROUNDDOWN(TEXT(B24,"0000"),-1),VLOOKUP!$M$3:$W$32,RIGHT(TEXT(B24,"0000"),1)+2,FALSE)) -> 2938 | AS24: =IF(B24="",0,AQ24/12*AR24) -> 8.1407083 | AT24: =AS24*(AV24/E24) -> 0.053625603 | AU24: =AT24+AU23 -> 0.47569905 | AV24: =IF(AO24="",AV23,AO24+AV23-(AT23/1.9835)) -> 374.69442 | BD24: 0 | BE24: 60 | BF24: 28 | BH24: =SUM(N24,P24:U24) -> 4.07 | BI24: 0 | BJ24: 12576 | BL24: =BL23+1 -> 10 | BM24: 6877.95 | BN24: =B24-BM24 -> -0.41 | BO24: 0 | BP24: =AH24-BO24 -> 39.4
A25: =A24+1 -> 11 | B25: 6877.48 | C25: =IF(B25="",C24,VLOOKUP(TRUNC(B25,1),VLOOKUP!$A$3:$K$2834,RIGHT(TEXT(B25,"0000.00"),1)+2,FALSE)) -> 208706 | D25: =C25-C24 -> -175 | E25: =C25-152000 -> 56706 | F25: =D25/$D$2 -> -88.22788 | G25: 57.7 | H25: 0.23 | I25: =G25+H25 -> 57.93 | J25: =IF(L25>0,L25,0) -> 0 | K25: =I25+J25 -> 57.93 | L25: =IF(G25="",0,F25-(I25-AK25)) -> -5.31788 | M25: 3.14 | N25: 0 | O25: =0*1.05 -> 0 | P25: 0 | Q25: =996900/325851/1.9835*1.02 -> 1.57326 | R25: 0 | S25: =IF(((1.3*1.04)-T25)>=4.2,4.2,(1.3*1.04)-T25) -> 0.701584 | T25: =(0.59*1.06)*1.04 -> 0.650416 | U25: =M25-(Q25+R25+S25+T25) -> 0.21473999 | V25: 98.3 | W25: 0 | X25: =IF(B25="",0,MAX(0,M25-N25-O25-P25-Q25-R25-S25-T25-U25+V25+W25-BB25+AZ25-AN25)) -> 0 | Y25: =X25-AW25 -> 0 | AE25: 0 | AF25: 0 | AG25: 0 | AH25: 39.4 | AI25: =AI24-AH25 -> 4455.8579 | AJ25: 0 | AK25: =AE25+AH25+M25+V25+W25 -> 140.84 | AL25: =IF(L25<0,L25*-1,0) -> 5.31788 | AM25: =AK25+AL25 -> 146.15788 | AN25: =IF(V25="","",V25) -> 98.3 | AO25: =IF(G25="","",IF(I25>=795,795-MAX(0,M25-N25-O25-P25-Q25-R25-S25-T25-U25+V25+W25-BB25+AZ25),I25-Q25-R25-MAX(0,M25-N25-O25-P25-Q25-R25-S25-T25-U25+V25+W25-BB25+AZ25)-AF25)-AJ25) -> -41.94326 | AP25: 0.0475 | AQ25: =AP25*0.7 -> 0.03325 | AR25: =IF(B25="",0,IF(AP25="",0,VLOOKUP(ROUNDDOWN(TEXT(B25,"0000"),-1),VLOOKUP!$M$3:$W$32,RIGHT(TEXT(B25,"0000"),1)+2,FALSE))) -> 2905 | AS25: =IF(B25="",0,AQ25/12*AR25) -> 8.0492708 | AT25: =AS25*(AV25/E25) -> 0.047229333 | AU25: =AT25+AU24 -> 0.52292839 | AV25: =IF(AO25="",AV24,AO25+AV24-(AT24/1.9835)) -> 332.72412 | BD25: 0 | BE25: 63 | BF25: 29 | BH25: =SUM(N25,P25:U25) -> 3.14 | BI25: 0 | BJ25: 12575.417 | BL25: =BL24+1 -> 11 | BM25: 6877.88 | BN25: =B25-BM25 -> -0.4 | BO25: 0 | BP25: =AH25-BO25 -> 39.4
A26: =A25+1 -> 12 | B26: 6877.41 | C26: =IF(B26="",C25,VLOOKUP(TRUNC(B26,1),VLOOKUP!$A$3:$K$2834,RIGHT(TEXT(B26,"0000.00"),1)+2,FALSE)) -> 208501 | D26: =C26-C25 -> -205 | E26: =C26-152000 -> 56501 | F26: =D26/$D$2 -> -103.35266 | G26: 60.8 | H26: 0.26 | I26: =G26+H26 -> 61.06 | J26: =IF(L26>0,L26,0) -> 0 | K26: =I26+J26 -> 61.06 | L26: =IF(G26="",0,F26-(I26-AK26)) -> -23.692659 | M26: 3.22 | N26: 0 | O26: =0*1.05 -> 0 | P26: 0 | Q26: =919100/325851/1.9835*1.02 -> 1.4504798 | R26: 0 | S26: =IF(((2.5*1.04)-T26)>=4.2,4.2,(2.5*1.04)-T26) -> 1.949584 | T26: =(0.59*1.06)*1.04 -> 0.650416 | U26: =M26-(Q26+R26+S26+T26) -> -0.83047977 | V26: 98.1 | W26: 0 | X26: =IF(B26="",0,MAX(0,M26-N26-O26-P26-Q26-R26-S26-T26-U26+V26+W26-BB26+AZ26-AN26)) -> 0 | Y26: =X26-AW26 -> 0 | AE26: 0 | AF26: 0 | AG26: 0 | AH26: 39.4 | AI26: =AI25-AH26 -> 4416.4579 | AJ26: 0 | AK26: =AE26+AH26+M26+V26+W26 -> 140.72 | AL26: =IF(L26<0,L26*-1,0) -> 23.692659 | AM26: =AK26+AL26 -> 164.41266 | AN26: =IF(V26="","",V26) -> 98.1 | AO26: =IF(G26="","",IF(I26>=795,795-MAX(0,M26-N26-O26-P26-Q26-R26-S26-T26-U26+V26+W26-BB26+AZ26),I26-Q26-R26-MAX(0,M26-N26-O26-P26-Q26-R26-S26-T26-U26+V26+W26-BB26+AZ26)-AF26)-AJ26) -> -38.49048 | AP26: 0.0475 | AQ26: =AP26*0.7 -> 0.03325 | AR26: =IF(B26="",0,IF(AP26="",0,VLOOKUP(ROUNDDOWN(TEXT(B26,"0000"),-1),VLOOKUP!$M$3:$W$32,RIGHT(TEXT(B26,"0000"),1)+2,FALSE))) -> 2905 | AS26: =IF(B26="",0,AQ26/12*AR26) -> 8.0492708 | AT26: =AS26*(AV26/E26) -> 0.041913853 | AU26: =AT26+AU25 -> 0.56484224 | AV26: =IF(AO26="",AV25,AO26+AV25-(AT25/1.9835)) -> 294.20983 | BD26: 0 | BE26: 52 | BF26: 31 | BH26: =SUM(N26,P26:U26) -> 3.22 | BI26: 0 | BJ26: 12572.333 | BL26: =BL25+1 -> 12 | BM26: 6877.82 | BN26: =B26-BM26 -> -0.41 | BO26: 0 | BP26: =AH26-BO26 -> 39.4
A27: =A26+1 -> 13 | B27: 6877.35 | C27: =IF(B27="",C26,VLOOKUP(TRUNC(B27,1),VLOOKUP!$A$3:$K$2834,RIGHT(TEXT(B27,"0000.00"),1)+2,FALSE)) -> 208326 | D27: =C27-C26 -> -175 | E27: =C27-152000 -> 56326 | F27: =D27/$D$2 -> -88.22788 | G27: 56.7 | H27: 0.17 | I27: =G27+H27 -> 56.87 | J27: =IF(L27>0,L27,0) -> 0 | K27: =I27+J27 -> 56.87 | L27: =IF(G27="",0,F27-(I27-AK27)) -> -4.44788 | M27: 3.35 | N27: 0 | O27: =0*1.05 -> 0 | P27: 0 | Q27: =959800/325851/1.9835*1.02 -> 1.5147106 | R27: 0 | S27: =IF(((2.4*1.04)-T27)>=4.2,4.2,(2.4*1.04)-T27) -> 1.845584 | T27: =(0.59*1.06)*1.04 -> 0.650416 | U27: =M27-(Q27+R27+S27+T27) -> -0.66071056 | V27: 97.9 | W27: 0 | X27: =IF(B27="",0,MAX(0,M27-N27-O27-P27-Q27-R27-S27-T27-U27+V27+W27-BB27+AZ27-AN27)) -> 0 | Y27: =X27-AW27 -> 0 | AE27: 0 | AF27: 0 | AG27: 0 | AH27: 39.4 | AI27: =AI26-AH27 -> 4377.0579 | AJ27: 0 | AK27: =AE27+AH27+M27+V27+W27 -> 140.65 | AL27: =IF(L27<0,L27*-1,0) -> 4.44788 | AM27: =AK27+AL27 -> 145.09788 | AN27: =IF(V27="","",V27) -> 97.9 | AO27: =IF(G27="","",IF(I27>=795,795-MAX(0,M27-N27-O27-P27-Q27-R27-S27-T27-U27+V27+W27-BB27+AZ27),I27-Q27-R27-MAX(0,M27-N27-O27-P27-Q27-R27-S27-T27-U27+V27+W27-BB27+AZ27)-AF27)-AJ27) -> -42.544711 | AP27: 0.0475 | AQ27: =AP27*0.7 -> 0.03325 | AR27: =IF(B27="",0,IF(AP27="",0,VLOOKUP(ROUNDDOWN(TEXT(B27,"0000"),-1),VLOOKUP!$M$3:$W$32,RIGHT(TEXT(B27,"0000"),1)+2,FALSE))) -> 2905 | AS27: =IF(B27="",0,AQ27/12*AR27) -> 8.0492708 | AT27: =AS27*(AV27/E27) -> 0.035961201 | AU27: =AT27+AU26 -> 0.60080344 | AV27: =IF(AO27="",AV26,AO27+AV26-(AT26/1.9835)) -> 251.64399 | BD27: 0 | BE27: 52 | BF27: 25 | BH27: =SUM(N27,P27:U27) -> 3.35 | BI27: 0 | BJ27: 12570.333 | BL27: =BL26+1 -> 13 | BM27: 6877.74 | BN27: =B27-BM27 -> -0.39 | BO27: 0 | BP27: =AH27-BO27 -> 39.4
A28: =A27+1 -> 14 | B28: 6877.28 | C28: =IF(B28="",C27,VLOOKUP(TRUNC(B28,1),VLOOKUP!$A$3:$K$2834,RIGHT(TEXT(B28,"0000.00"),1)+2,FALSE)) -> 208121 | D28: =C28-C27 -> -205 | E28: =C28-152000 -> 56121 | F28: =D28/$D$2 -> -103.35266 | G28: 50.3 | H28: 0.15 | I28: =G28+H28 -> 50.45 | J28: =IF(L28>0,L28,0) -> 0 | K28: =I28+J28 -> 50.45 | L28: =IF(G28="",0,F28-(I28-AK28)) -> -54.982659 | M28: 3.82 | N28: 0 | O28: =0*1.05 -> 0 | P28: 0 | Q28: =943200/325851/1.9835*1.02 -> 1.4885132 | R28: 0 | S28: =IF(((2.3*1.04)-T28)>=4.2,4.2,(2.3*1.04)-T28) -> 1.741584 | T28: =(0.59*1.06)*1.04 -> 0.650416 | U28: =M28-(Q28+R28+S28+T28) -> -0.060513236 | V28: 66.1 | W28: 0 | X28: =IF(B28="",0,MAX(0,M28-N28-O28-P28-Q28-R28-S28-T28-U28+V28+W28-BB28+AZ28-AN28)) -> 0 | Y28: =X28-AW28 -> 0 | AE28: 0 | AF28: 0 | AG28: 0 | AH28: 28.9 | AI28: =AI27-AH28 -> 4348.1579 | AJ28: 0 | AK28: =AE28+AH28+M28+V28+W28 -> 98.82 | AL28: =IF(L28<0,L28*-1,0) -> 54.982659 | AM28: =AK28+AL28 -> 153.80266 | AN28: =IF(V28="","",V28) -> 66.1 | AO28: =IF(G28="","",IF(I28>=795,795-MAX(0,M28-N28-O28-P28-Q28-R28-S28-T28-U28+V28+W28-BB28+AZ28),I28-Q28-R28-MAX(0,M28-N28-O28-P28-Q28-R28-S28-T28-U28+V28+W28-BB28+AZ28)-AF28)-AJ28) -> -17.138513 | AP28: 0.0475 | AQ28: =AP28*0.7 -> 0.03325 | AR28: =IF(B28="",0,IF(AP28="",0,VLOOKUP(ROUNDDOWN(TEXT(B28,"0000"),-1),VLOOKUP!$M$3:$W$32,RIGHT(TEXT(B28,"0000"),1)+2,FALSE))) -> 2905 | AS28: =IF(B28="",0,AQ28/12*AR28) -> 8.0492708 | AT28: =AS28*(AV28/E28) -> 0.033631834 | AU28: =AT28+AU27 -> 0.63443527 | AV28: =IF(AO28="",AV27,AO28+AV27-(AT27/1.9835)) -> 234.48734 | BD28: 0 | BE28: 65 | BF28: 26 | BH28: =SUM(N28,P28:U28) -> 3.82 | BI28: 0 | BJ28: 12545.389 | BL28: =BL27+1 -> 14 | BM28: 6877.69 | BN28: =B28-BM28 -> -0.41 | BO28: 0 | BP28: =AH28-BO28 -> 28.9
A29: =A28+1 -> 15 | B29: 6877.33 | C29: =IF(B29="",C28,VLOOKUP(TRUNC(B29,1),VLOOKUP!$A$3:$K$2834,RIGHT(TEXT(B29,"0000.00"),1)+2,FALSE)) -> 208268 | D29: =C29-C28 -> 147 | E29: =C29-152000 -> 56268 | F29: =D29/$D$2 -> 74.111419 | G29: 52 | H29: 0.14 | I29: =G29+H29 -> 52.14 | J29: =IF(L29>0,L29,0) -> 51.131419 | K29: =I29+J29 -> 103.27142 | L29: =IF(G29="",0,F29-(I29-AK29)) -> 51.131419 | M29: 4.16 | N29: 0 | O29: =0*1.05 -> 0 | P29: 0 | Q29: =965700/325851/1.9835*1.02 -> 1.5240217 | R29: 0 | S29: =IF(((2.1*1.04)-T29)>=4.2,4.2,(2.1*1.04)-T29) -> 1.544608 | T29: =(0.58*1.06)*1.04 -> 0.639392 | U29: =M29-(Q29+R29+S29+T29) -> 0.45197834 | V29: 0 | W29: 0 | X29: =IF(B29="",0,MAX(0,M29-N29-O29-P29-Q29-R29-S29-T29-U29+V29+W29-BB29+AZ29-AN29)) -> 0 | Y29: =X29-AW29 -> 0 | AE29: 0 | AF29: 0 | AG29: 0 | AH29: 25 | AI29: =AI28-AH29 -> 4323.1579 | AJ29: 0 | AK29: =AE29+AH29+M29+V29+W29 -> 29.16 | AL29: =IF(L29<0,L29*-1,0) -> 0 | AM29: =AK29+AL29 -> 29.16 | AN29: =IF(V29="","",V29) -> 0 | AO29: =IF(G29="","",IF(I29>=795,795-MAX(0,M29-N29-O29-P29-Q29-R29-S29-T29-U29+V29+W29-BB29+AZ29),I29-Q29-R29-MAX(0,M29-N29-O29-P29-Q29-R29-S29-T29-U29+V29+W29-BB29+AZ29)-AF29)-AJ29) -> 50.615978 | AP29: 0.0475 | AQ29: =AP29*0.7 -> 0.03325 | AR29: =IF(B29="",0,IF(AP29="",0,VLOOKUP(ROUNDDOWN(TEXT(B29,"0000"),-1),VLOOKUP!$M$3:$W$32,RIGHT(TEXT(B29,"0000"),1)+2,FALSE))) -> 2905 | AS29: =IF(B29="",0,AQ29/12*AR29) -> 8.0492708 | AT29: =AS29*(AV29/E29) -> 0.040782281 | AU29: =AT29+AU28 -> 0.67521756 | AV29: =IF(AO29="",AV28,AO29+AV28-(AT28/1.9835)) -> 285.08637 | BD29: 0 | BE29: 64 | BF29: 35 | BH29: =SUM(N29,P29:U29) -> 4.16 | BI29: 0 | BJ29: 12541.875 | BL29: =BL28+1 -> 15 | BM29: 6877.69 | BN29: =B29-BM29 -> -0.36 | BO29: 0 | BP29: =AH29-BO29 -> 25
A30: =A29+1 -> 16 | B30: 6877.33 | C30: =IF(B30="",C29,VLOOKUP(TRUNC(B30,1),VLOOKUP!$A$3:$K$2834,RIGHT(TEXT(B30,"0000.00"),1)+2,FALSE)) -> 208268 | D30: =C30-C29 -> 0 | E30: =C30-152000 -> 56268 | F30: =D30/$D$2 -> 0 | G30: 61.1 | H30: 0.19 | I30: =G30+H30 -> 61.29 | J30: =IF(L30>0,L30,0) -> 0 | K30: =I30+J30 -> 61.29 | L30: =IF(G30="",0,F30-(I30-AK30)) -> -32.08 | M30: 4.21 | N30: 0 | O30: =0*1.05 -> 0 | P30: 0 | Q30: =984800/325851/1.9835*1.02 -> 1.5541644 | R30: 0 | S30: =IF(((2*1.04)-T30)>=4.2,4.2,(2*1.04)-T30) -> 1.440608 | T30: =(0.58*1.06)*1.04 -> 0.639392 | U30: =M30-(Q30+R30+S30+T30) -> 0.57583563 | V30: 0 | W30: 0 | X30: =IF(B30="",0,MAX(0,M30-N30-O30-P30-Q30-R30-S30-T30-U30+V30+W30-BB30+AZ30-AN30)) -> 0 | Y30: =X30-AW30 -> 0 | AE30: 0 | AF30: 0 | AG30: 0 | AH30: 25 | AI30: =AI29-AH30 -> 4298.1579 | AJ30: 0 | AK30: =AE30+AH30+M30+V30+W30 -> 29.21 | AL30: =IF(L30<0,L30*-1,0) -> 32.08 | AM30: =AK30+AL30 -> 61.29 | AN30: =IF(V30="","",V30) -> 0 | AO30: =IF(G30="","",IF(I30>=795,795-MAX(0,M30-N30-O30-P30-Q30-R30-S30-T30-U30+V30+W30-BB30+AZ30),I30-Q30-R30-MAX(0,M30-N30-O30-P30-Q30-R30-S30-T30-U30+V30+W30-BB30+AZ30)-AF30)-AJ30) -> 59.735836 | AP30: 0.0475 | AQ30: =AP30*0.7 -> 0.03325 | AR30: =IF(B30="",0,IF(AP30="",0,VLOOKUP(ROUNDDOWN(TEXT(B30,"0000"),-1),VLOOKUP!$M$3:$W$32,RIGHT(TEXT(B30,"0000"),1)+2,FALSE))) -> 2905 | AS30: =IF(B30="",0,AQ30/12*AR30) -> 8.0492708 | AT30: =AS30*(AV30/E30) -> 0.049324692 | AU30: =AT30+AU29 -> 0.72454225 | AV30: =IF(AO30="",AV29,AO30+AV29-(AT29/1.9835)) -> 344.80164 | BD30: 0 | BE30: 47 | BF30: 28 | BH30: =SUM(N30,P30:U30) -> 4.21 | BI30: 0 | BJ30: 12537.625 | BL30: =BL29+1 -> 16 | BM30: 6877.72 | BN30: =B30-BM30 -> -0.39 | BO30: 0 | BP30: =AH30-BO30 -> 25
A31: =A30+1 -> 17 | B31: 6877.31 | C31: =IF(B31="",C30,VLOOKUP(TRUNC(B31,1),VLOOKUP!$A$3:$K$2834,RIGHT(TEXT(B31,"0000.00"),1)+2,FALSE)) -> 208209 | D31: =C31-C30 -> -59 | E31: =C31-152000 -> 56209 | F31: =D31/$D$2 -> -29.7454 | G31: 49.2 | H31: 0.19 | I31: =G31+H31 -> 49.39 | J31: =IF(L31>0,L31,0) -> 0 | K31: =I31+J31 -> 49.39 | L31: =IF(G31="",0,F31-(I31-AK31)) -> -49.9654 | M31: 4.17 | N31: 0 | O31: =0*1.05 -> 0 | P31: 0 | Q31: =1212100/325851/1.9835*1.02 -> 1.9128784 | R31: 0 | S31: =IF(((1.7*1.04)-T31)>=4.2,4.2,(1.7*1.04)-T31) -> 1.128608 | T31: =(0.58*1.06)*1.04 -> 0.639392 | U31: =M31-(Q31+R31+S31+T31) -> 0.48912161 | V31: 0 | W31: 0 | X31: =IF(B31="",0,MAX(0,M31-N31-O31-P31-Q31-R31-S31-T31-U31+V31+W31-BB31+AZ31-AN31)) -> 0 | Y31: =X31-AW31 -> 0 | AE31: 0 | AF31: 0 | AG31: 0 | AH31: 25 | AI31: =AI30-AH31 -> 4273.1579 | AJ31: 0 | AK31: =AE31+AH31+M31+V31+W31 -> 29.17 | AL31: =IF(L31<0,L31*-1,0) -> 49.9654 | AM31: =AK31+AL31 -> 79.1354 | AN31: =IF(V31="","",V31) -> 0 | AO31: =IF(G31="","",IF(I31>=795,795-MAX(0,M31-N31-O31-P31-Q31-R31-S31-T31-U31+V31+W31-BB31+AZ31),I31-Q31-R31-MAX(0,M31-N31-O31-P31-Q31-R31-S31-T31-U31+V31+W31-BB31+AZ31)-AF31)-AJ31) -> 47.477122 | AP31: 0.0475 | AQ31: =AP31*0.7 -> 0.03325 | AR31: =IF(B31="",0,IF(AP31="",0,VLOOKUP(ROUNDDOWN(TEXT(B31,"0000"),-1),VLOOKUP!$M$3:$W$32,RIGHT(TEXT(B31,"0000"),1)+2,FALSE))) -> 2905 | AS31: =IF(B31="",0,AQ31/12*AR31) -> 8.0492708 | AT31: =AS31*(AV31/E31) -> 0.056171749 | AU31: =AT31+AU30 -> 0.780714 | AV31: =IF(AO31="",AV30,AO31+AV30-(AT30/1.9835)) -> 392.2539 | BD31: 0 | BE31: 53 | BF31: 23 | BH31: =SUM(N31,P31:U31) -> 4.17 | BI31: 0 | BJ31: 12536.125 | BL31: =BL30+1 -> 17 | BM31: 6877.73 | BN31: =B31-BM31 -> -0.42 | BO31: 0 | BP31: =AH31-BO31 -> 25
A32: =A31+1 -> 18 | B32: 6877.32 | C32: =IF(B32="",C31,VLOOKUP(TRUNC(B32,1),VLOOKUP!$A$3:$K$2834,RIGHT(TEXT(B32,"0000.00"),1)+2,FALSE)) -> 208238 | D32: =C32-C31 -> 29 | E32: =C32-152000 -> 56238 | F32: =D32/$D$2 -> 14.62062 | G32: 38.8 | H32: 0.17 | I32: =G32+H32 -> 38.97 | J32: =IF(L32>0,L32,0) -> 4.8206201 | K32: =I32+J32 -> 43.79062 | L32: =IF(G32="",0,F32-(I32-AK32)) -> 4.8206201 | M32: 4.17 | N32: 0 | O32: =0*1.05 -> 0 | P32: 0 | Q32: =905900/325851/1.9835*1.02 -> 1.4296482 | R32: 0 | S32: =IF(((2.3*1.04)-T32)>=4.2,4.2,(2.3*1.04)-T32) -> 1.752608 | T32: =(0.58*1.06)*1.04 -> 0.639392 | U32: =M32-(Q32+R32+S32+T32) -> 0.34835184 | V32: 0 | W32: 0 | X32: =IF(B32="",0,MAX(0,M32-N32-O32-P32-Q32-R32-S32-T32-U32+V32+W32-BB32+AZ32-AN32)) -> 0 | Y32: =X32-AW32 -> 0 | AE32: 0 | AF32: 0 | AG32: 0 | AH32: 25 | AI32: =AI31-AH32 -> 4248.1579 | AJ32: 0 | AK32: =AE32+AH32+M32+V32+W32 -> 29.17 | AL32: =IF(L32<0,L32*-1,0) -> 0 | AM32: =AK32+AL32 -> 29.17 | AN32: =IF(V32="","",V32) -> 0 | AO32: =IF(G32="","",IF(I32>=795,795-MAX(0,M32-N32-O32-P32-Q32-R32-S32-T32-U32+V32+W32-BB32+AZ32),I32-Q32-R32-MAX(0,M32-N32-O32-P32-Q32-R32-S32-T32-U32+V32+W32-BB32+AZ32)-AF32)-AJ32) -> 37.540352 | AP32: 0.0475 | AQ32: =AP32*0.7 -> 0.03325 | AR32: =IF(B32="",0,IF(AP32="",0,VLOOKUP(ROUNDDOWN(TEXT(B32,"0000"),-1),VLOOKUP!$M$3:$W$32,RIGHT(TEXT(B32,"0000"),1)+2,FALSE))) -> 2905 | AS32: =IF(B32="",0,AQ32/12*AR32) -> 8.0492708 | AT32: =AS32*(AV32/E32) -> 0.061511831 | AU32: =AT32+AU31 -> 0.84222583 | AV32: =IF(AO32="",AV31,AO32+AV31-(AT31/1.9835)) -> 429.76593 | BD32: 0 | BE32: 48 | BF32: 20 | BH32: =SUM(N32,P32:U32) -> 4.17 | BI32: 0 | BJ32: 12535.083 | BL32: =BL31+1 -> 18 | BM32: 6877.72 | BN32: =B32-BM32 -> -0.4 | BO32: 0 | BP32: =AH32-BO32 -> 25
A33: =A32+1 -> 19 | B33: 6877.31 | C33: =IF(B33="",C32,VLOOKUP(TRUNC(B33,1),VLOOKUP!$A$3:$K$2834,RIGHT(TEXT(B33,"0000.00"),1)+2,FALSE)) -> 208209 | D33: =C33-C32 -> -29 | E33: =C33-152000 -> 56209 | F33: =D33/$D$2 -> -14.62062 | G33: 34 | H33: 0.07 | I33: =G33+H33 -> 34.07 | J33: =IF(L33>0,L33,0) -> 0 | K33: =I33+J33 -> 34.07 | L33: =IF(G33="",0,F33-(I33-AK33)) -> -19.51062 | M33: 4.18 | N33: 0 | O33: =0*1.05 -> 0 | P33: 0 | Q33: =1011300/325851/1.9835*1.02 -> 1.5959854 | R33: 0 | S33: =IF(((2.2*1.04)-T33)>=4.2,4.2,(2.2*1.04)-T33) -> 1.648608 | T33: =(0.58*1.06)*1.04 -> 0.639392 | U33: =M33-(Q33+R33+S33+T33) -> 0.29601459 | V33: 0 | W33: 0 | X33: =IF(B33="",0,MAX(0,M33-N33-O33-P33-Q33-R33-S33-T33-U33+V33+W33-BB33+AZ33-AN33)) -> 0 | Y33: =X33-AW33 -> 0 | AE33: 0 | AF33: 0 | AG33: 0 | AH33: 25 | AI33: =AI32-AH33 -> 4223.1579 | AJ33: 0 | AK33: =AE33+AH33+M33+V33+W33 -> 29.18 | AL33: =IF(L33<0,L33*-1,0) -> 19.51062 | AM33: =AK33+AL33 -> 48.69062 | AN33: =IF(V33="","",V33) -> 0 | AO33: =IF(G33="","",IF(I33>=795,795-MAX(0,M33-N33-O33-P33-Q33-R33-S33-T33-U33+V33+W33-BB33+AZ33),I33-Q33-R33-MAX(0,M33-N33-O33-P33-Q33-R33-S33-T33-U33+V33+W33-BB33+AZ33)-AF33)-AJ33) -> 32.474015 | AP33: 0.0475 | AQ33: =AP33*0.7 -> 0.03325 | AR33: =IF(B33="",0,IF(AP33="",0,VLOOKUP(ROUNDDOWN(TEXT(B33,"0000"),-1),VLOOKUP!$M$3:$W$32,RIGHT(TEXT(B33,"0000"),1)+2,FALSE))) -> 2905 | AS33: =IF(B33="",0,AQ33/12*AR33) -> 8.0492708 | AT33: =AS33*(AV33/E33) -> 0.066189487 | AU33: =AT33+AU32 -> 0.90841531 | AV33: =IF(AO33="",AV32,AO33+AV32-(AT32/1.9835)) -> 462.20893 | BD33: 0 | BE33: 40 | BF33: 16 | BH33: =SUM(N33,P33:U33) -> 4.18 | BI33: 0 | BJ33: 12534.292 | BL33: =BL32+1 -> 19 | BM33: 6877.72 | BN33: =B33-BM33 -> -0.41 | BO33: 0 | BP33: =AH33-BO33 -> 25
A34: =A33+1 -> 20 | B34: 6877.3 | C34: =IF(B34="",C33,VLOOKUP(TRUNC(B34,1),VLOOKUP!$A$3:$K$2834,RIGHT(TEXT(B34,"0000.00"),1)+2,FALSE)) -> 208180 | D34: =C34-C33 -> -29 | E34: =C34-152000 -> 56180 | F34: =D34/$D$2 -> -14.62062 | G34: 30.2 | H34: 0.01 | I34: =G34+H34 -> 30.21 | J34: =IF(L34>0,L34,0) -> 0 | K34: =I34+J34 -> 30.21 | L34: =IF(G34="",0,F34-(I34-AK34)) -> -15.55062 | M34: 4.28 | N34: 0 | O34: =0*1.05 -> 0 | P34: 0 | Q34: =1020100/325851/1.9835*1.02 -> 1.6098731 | R34: 0 | S34: =IF(((2.2*1.04)-T34)>=4.2,4.2,(2.2*1.04)-T34) -> 1.648608 | T34: =(0.58*1.06)*1.04 -> 0.639392 | U34: =M34-(Q34+R34+S34+T34) -> 0.38212685 | V34: 0 | W34: 0 | X34: =IF(B34="",0,MAX(0,M34-N34-O34-P34-Q34-R34-S34-T34-U34+V34+W34-BB34+AZ34-AN34)) -> 0 | Y34: =X34-AW34 -> 0 | AE34: 0 | AF34: 0 | AG34: 0 | AH34: 25 | AI34: =AI33-AH34 -> 4198.1579 | AJ34: 0 | AK34: =AE34+AH34+M34+V34+W34 -> 29.28 | AL34: =IF(L34<0,L34*-1,0) -> 15.55062 | AM34: =AK34+AL34 -> 44.83062 | AN34: =IF(V34="","",V34) -> 0 | AO34: =IF(G34="","",IF(I34>=795,795-MAX(0,M34-N34-O34-P34-Q34-R34-S34-T34-U34+V34+W34-BB34+AZ34),I34-Q34-R34-MAX(0,M34-N34-O34-P34-Q34-R34-S34-T34-U34+V34+W34-BB34+AZ34)-AF34)-AJ34) -> 28.600127 | AP34: 0.0475 | AQ34: =AP34*0.7 -> 0.03325 | AR34: =IF(B34="",0,IF(AP34="",0,VLOOKUP(ROUNDDOWN(TEXT(B34,"0000"),-1),VLOOKUP!$M$3:$W$32,RIGHT(TEXT(B34,"0000"),1)+2,FALSE))) -> 2905 | AS34: =IF(B34="",0,AQ34/12*AR34) -> 8.0492708 | AT34: =AS34*(AV34/E34) -> 0.070316597 | AU34: =AT34+AU33 -> 0.97873191 | AV34: =IF(AO34="",AV33,AO34+AV33-(AT33/1.9835)) -> 490.77569 | BD34: 0 | BE34: 52 | BF34: 15 | BH34: =SUM(N34,P34:U34) -> 4.28 | BI34: 0 | BJ34: 12530.375 | BL34: =BL33+1 -> 20 | BM34: 6877.71 | BN34: =B34-BM34 -> -0.41 | BO34: 0 | BP34: =AH34-BO34 -> 25
A35: =A34+1 -> 21 | B35: 6877.29 | C35: =IF(B35="",C34,VLOOKUP(TRUNC(B35,1),VLOOKUP!$A$3:$K$2834,RIGHT(TEXT(B35,"0000.00"),1)+2,FALSE)) -> 208151 | D35: =C35-C34 -> -29 | E35: =C35-152000 -> 56151 | F35: =D35/$D$2 -> -14.62062 | G35: 29.3 | H35: 0 | I35: =G35+H35 -> 29.3 | J35: =IF(L35>0,L35,0) -> 0 | K35: =I35+J35 -> 29.3 | L35: =IF(G35="",0,F35-(I35-AK35)) -> -14.98062 | M35: 3.94 | N35: 0 | O35: =0*1.05 -> 0 | P35: 0 | Q35: =923900/325851/1.9835*1.02 -> 1.4580549 | R35: 0 | S35: =IF(((1.9*1.04)-T35)>=4.2,4.2,(1.9*1.04)-T35) -> 1.336608 | T35: =(0.58*1.06)*1.04 -> 0.639392 | U35: =M35-(Q35+R35+S35+T35) -> 0.5059451 | V35: 0 | W35: 0 | X35: =IF(B35="",0,MAX(0,M35-N35-O35-P35-Q35-R35-S35-T35-U35+V35+W35-BB35+AZ35-AN35)) -> 0 | Y35: =X35-AW35 -> 0 | AE35: 0 | AF35: 0 | AG35: 0 | AH35: 25 | AI35: =AI34-AH35 -> 4173.1579 | AJ35: 0 | AK35: =AE35+AH35+M35+V35+W35 -> 28.94 | AL35: =IF(L35<0,L35*-1,0) -> 14.98062 | AM35: =AK35+AL35 -> 43.92062 | AN35: =IF(V35="","",V35) -> 0 | AO35: =IF(G35="","",IF(I35>=795,795-MAX(0,M35-N35-O35-P35-Q35-R35-S35-T35-U35+V35+W35-BB35+AZ35),I35-Q35-R35-MAX(0,M35-N35-O35-P35-Q35-R35-S35-T35-U35+V35+W35-BB35+AZ35)-AF35)-AJ35) -> 27.841945 | AP35: 0.0475 | AQ35: =AP35*0.7 -> 0.03325 | AR35: =IF(B35="",0,IF(AP35="",0,VLOOKUP(ROUNDDOWN(TEXT(B35,"0000"),-1),VLOOKUP!$M$3:$W$32,RIGHT(TEXT(B35,"0000"),1)+2,FALSE))) -> 2905 | AS35: =IF(B35="",0,AQ35/12*AR35) -> 8.0492708 | AT35: =AS35*(AV35/E35) -> 0.074338986 | AU35: =AT35+AU34 -> 1.0530709 | AV35: =IF(AO35="",AV34,AO35+AV34-(AT34/1.9835)) -> 518.58218 | BD35: 0 | BE35: 61 | BF35: 24 | BH35: =SUM(N35,P35:U35) -> 3.94 | BI35: 0 | BJ35: 12531.833 | BL35: =BL34+1 -> 21 | BM35: 6877.7 | BN35: =B35-BM35 -> -0.41 | BO35: 0 | BP35: =AH35-BO35 -> 25
A36: =A35+1 -> 22 | B36: 6877.29 | C36: =IF(B36="",C35,VLOOKUP(TRUNC(B36,1),VLOOKUP!$A$3:$K$2834,RIGHT(TEXT(B36,"0000.00"),1)+2,FALSE)) -> 208151 | D36: =C36-C35 -> 0 | E36: =C36-152000 -> 56151 | F36: =D36/$D$2 -> 0 | G36: 29.2 | H36: 0 | I36: =G36+H36 -> 29.2 | J36: =IF(L36>0,L36,0) -> 0 | K36: =I36+J36 -> 29.2 | L36: =IF(G36="",0,F36-(I36-AK36)) -> -1.01 | M36: 3.19 | N36: 0 | O36: =0*1.05 -> 0 | P36: 0 | Q36: =995100/325851/1.9835*1.02 -> 1.5704193 | R36: 0 | S36: =IF(((1.8*1.04)-T36)>=4.2,4.2,(1.8*1.04)-T36) -> 1.26568 | T36: =(0.55*1.06)*1.04 -> 0.60632 | U36: =M36-(Q36+R36+S36+T36) -> -0.25241934 | V36: 0 | W36: 0 | X36: =IF(B36="",0,MAX(0,M36-N36-O36-P36-Q36-R36-S36-T36-U36+V36+W36-BB36+AZ36-AN36)) -> 3.3306691e-16 | Y36: =X36-AW36 -> 3.3306691e-16 | AE36: 0 | AF36: 0 | AG36: 0 | AH36: 25 | AI36: =AI35-AH36 -> 4148.1579 | AJ36: 0 | AK36: =AE36+AH36+M36+V36+W36 -> 28.19 | AL36: =IF(L36<0,L36*-1,0) -> 1.01 | AM36: =AK36+AL36 -> 29.2 | AN36: =IF(V36="","",V36) -> 0 | AO36: =IF(G36="","",IF(I36>=795,795-MAX(0,M36-N36-O36-P36-Q36-R36-S36-T36-U36+V36+W36-BB36+AZ36),I36-Q36-R36-MAX(0,M36-N36-O36-P36-Q36-R36-S36-T36-U36+V36+W36-BB36+AZ36)-AF36)-AJ36) -> 27.629581 | AP36: 0.0475 | AQ36: =AP36*0.7 -> 0.03325 | AR36: =IF(B36="",0,IF(AP36="",0,VLOOKUP(ROUNDDOWN(TEXT(B36,"0000"),-1),VLOOKUP!$M$3:$W$32,RIGHT(TEXT(B36,"0000"),1)+2,FALSE))) -> 2905 | AS36: =IF(B36="",0,AQ36/12*AR36) -> 8.0492708 | AT36: =AS36*(AV36/E36) -> 0.078294327 | AU36: =AT36+AU35 -> 1.1313652 | AV36: =IF(AO36="",AV35,AO36+AV35-(AT35/1.9835)) -> 546.17428 | BD36: 0 | BE36: 65 | BF36: 24 | BH36: =SUM(N36,P36:U36) -> 3.19 | BI36: 0 | BJ36: 12529.958 | BL36: =BL35+1 -> 22 | BM36: 6877.69 | BN36: =B36-BM36 -> -0.4 | BO36: 0 | BP36: =AH36-BO36 -> 25
A37: =A36+1 -> 23 | B37: 6877.29 | C37: =IF(B37="",C36,VLOOKUP(TRUNC(B37,1),VLOOKUP!$A$3:$K$2834,RIGHT(TEXT(B37,"0000.00"),1)+2,FALSE)) -> 208151 | D37: =C37-C36 -> 0 | E37: =C37-152000 -> 56151 | F37: =D37/$D$2 -> 0 | G37: 29.1 | H37: 0 | I37: =G37+H37 -> 29.1 | J37: =IF(L37>0,L37,0) -> 0 | K37: =I37+J37 -> 29.1 | L37: =IF(G37="",0,F37-(I37-AK37)) -> -0.57 | M37: 3.23 | N37: 0 | O37: =0*1.05 -> 0 | P37: 0 | Q37: =1107800/325851/1.9835*1.02 -> 1.7482771 | R37: 0 | S37: =IF(((2.2*1.04)-T37)>=4.2,4.2,(2.2*1.04)-T37) -> 1.68168 | T37: =(0.55*1.06)*1.04 -> 0.60632 | U37: =M37-(Q37+R37+S37+T37) -> -0.8062771 | V37: 0 | W37: 0 | X37: =IF(B37="",0,MAX(0,M37-N37-O37-P37-Q37-R37-S37-T37-U37+V37+W37-BB37+AZ37-AN37)) -> 3.3306691e-16 | Y37: =X37-AW37 -> 3.3306691e-16 | AE37: 0 | AF37: 0 | AG37: 0 | AH37: 25.3 | AI37: =AI36-AH37 -> 4122.8579 | AJ37: 0 | AK37: =AE37+AH37+M37+V37+W37 -> 28.53 | AL37: =IF(L37<0,L37*-1,0) -> 0.57 | AM37: =AK37+AL37 -> 29.1 | AN37: =IF(V37="","",V37) -> 0 | AO37: =IF(G37="","",IF(I37>=795,795-MAX(0,M37-N37-O37-P37-Q37-R37-S37-T37-U37+V37+W37-BB37+AZ37),I37-Q37-R37-MAX(0,M37-N37-O37-P37-Q37-R37-S37-T37-U37+V37+W37-BB37+AZ37)-AF37)-AJ37) -> 27.351723 | AP37: 0.0475 | AQ37: =AP37*0.7 -> 0.03325 | AR37: =IF(B37="",0,IF(AP37="",0,VLOOKUP(ROUNDDOWN(TEXT(B37,"0000"),-1),VLOOKUP!$M$3:$W$32,RIGHT(TEXT(B37,"0000"),1)+2,FALSE))) -> 2905 | AS37: =IF(B37="",0,AQ37/12*AR37) -> 8.0492708 | AT37: =AS37*(AV37/E37) -> 0.08220955 | AU37: =AT37+AU36 -> 1.2135748 | AV37: =IF(AO37="",AV36,AO37+AV36-(AT36/1.9835)) -> 573.48653 | BD37: 0 | BE37: 66 | BF37: 28 | BH37: =SUM(N37,P37:U37) -> 3.23 | BI37: 0 | BJ37: 12526.458 | BL37: =BL36+1 -> 23 | BM37: 6877.69 | BN37: =B37-BM37 -> -0.4 | BO37: 0 | BP37: =AH37-BO37 -> 25.3
A38: =A37+1 -> 24 | B38: 6877.3 | C38: =IF(B38="",C37,VLOOKUP(TRUNC(B38,1),VLOOKUP!$A$3:$K$2834,RIGHT(TEXT(B38,"0000.00"),1)+2,FALSE)) -> 208180 | D38: =C38-C37 -> 29 | E38: =C38-152000 -> 56180 | F38: =D38/$D$2 -> 14.62062 | G38: 29 | H38: 0 | I38: =G38+H38 -> 29 | J38: =IF(L38>0,L38,0) -> 14.78062 | K38: =I38+J38 -> 43.78062 | L38: =IF(G38="",0,F38-(I38-AK38)) -> 14.78062 | M38: 3.46 | N38: 0 | O38: =0*1.05 -> 0 | P38: 0 | Q38: =1043000/325851/1.9835*1.02 -> 1.6460128 | R38: 0 | S38: =IF(((2*1.04)-T38)>=4.2,4.2,(2*1.04)-T38) -> 1.47368 | T38: =(0.55*1.06)*1.04 -> 0.60632 | U38: =M38-(Q38+R38+S38+T38) -> -0.26601283 | V38: 0 | W38: 0 | X38: =IF(B38="",0,MAX(0,M38-N38-O38-P38-Q38-R38-S38-T38-U38+V38+W38-BB38+AZ38-AN38)) -> 1.110223e-16 | Y38: =X38-AW38 -> 1.110223e-16 | AE38: 0 | AF38: 0 | AG38: 0 | AH38: 25.7 | AI38: =AI37-AH38 -> 4097.1579 | AJ38: 0 | AK38: =AE38+AH38+M38+V38+W38 -> 29.16 | AL38: =IF(L38<0,L38*-1,0) -> 0 | AM38: =AK38+AL38 -> 29.16 | AN38: =IF(V38="","",V38) -> 0 | AO38: =IF(G38="","",IF(I38>=795,795-MAX(0,M38-N38-O38-P38-Q38-R38-S38-T38-U38+V38+W38-BB38+AZ38),I38-Q38-R38-MAX(0,M38-N38-O38-P38-Q38-R38-S38-T38-U38+V38+W38-BB38+AZ38)-AF38)-AJ38) -> 27.353987 | AP38: 0.0475 | AQ38: =AP38*0.7 -> 0.03325 | AR38: =IF(B38="",0,IF(AP38="",0,VLOOKUP(ROUNDDOWN(TEXT(B38,"0000"),-1),VLOOKUP!$M$3:$W$32,RIGHT(TEXT(B38,"0000"),1)+2,FALSE))) -> 2905 | AS38: =IF(B38="",0,AQ38/12*AR38) -> 8.0492708 | AT38: =AS38*(AV38/E38) -> 0.086080357 | AU38: =AT38+AU37 -> 1.2996551 | AV38: =IF(AO38="",AV37,AO38+AV37-(AT37/1.9835)) -> 600.79907 | BD38: 0 | BE38: 57 | BF38: 34 | BH38: =SUM(N38,P38:U38) -> 3.46 | BI38: 0 | BJ38: 12524.917 | BL38: =BL37+1 -> 24 | BM38: 6877.7 | BN38: =B38-BM38 -> -0.4 | BO38: 0 | BP38: =AH38-BO38 -> 25.7
A39: =A38+1 -> 25 | B39: 6877.32 | C39: =IF(B39="",C38,VLOOKUP(TRUNC(B39,1),VLOOKUP!$A$3:$K$2834,RIGHT(TEXT(B39,"0000.00"),1)+2,FALSE)) -> 208238 | D39: =C39-C38 -> 58 | E39: =C39-152000 -> 56238 | F39: =D39/$D$2 -> 29.24124 | G39: 28.9 | H39: 0.01 | I39: =G39+H39 -> 28.91 | J39: =IF(L39>0,L39,0) -> 29.16124 | K39: =I39+J39 -> 58.07124 | L39: =IF(G39="",0,F39-(I39-AK39)) -> 29.16124 | M39: 3.43 | N39: 0 | O39: =0*1.05 -> 0 | P39: 0 | Q39: =1127700/325851/1.9835*1.02 -> 1.7796823 | R39: 0 | S39: =IF(((2.1*1.04)-T39)>=4.2,4.2,(2.1*1.04)-T39) -> 1.57768 | T39: =(0.55*1.06)*1.04 -> 0.60632 | U39: =M39-(Q39+R39+S39+T39) -> -0.53368233 | V39: 0 | W39: 0 | X39: =IF(B39="",0,MAX(0,M39-N39-O39-P39-Q39-R39-S39-T39-U39+V39+W39-BB39+AZ39-AN39)) -> 3.3306691e-16 | Y39: =X39-AW39 -> 3.3306691e-16 | AE39: 0 | AF39: 0 | AG39: 0 | AH39: 25.4 | AI39: =AI38-AH39 -> 4071.7579 | AJ39: 0 | AK39: =AE39+AH39+M39+V39+W39 -> 28.83 | AL39: =IF(L39<0,L39*-1,0) -> 0 | AM39: =AK39+AL39 -> 28.83 | AN39: =IF(V39="","",V39) -> 0 | AO39: =IF(G39="","",IF(I39>=795,795-MAX(0,M39-N39-O39-P39-Q39-R39-S39-T39-U39+V39+W39-BB39+AZ39),I39-Q39-R39-MAX(0,M39-N39-O39-P39-Q39-R39-S39-T39-U39+V39+W39-BB39+AZ39)-AF39)-AJ39) -> 27.130318 | AP39: 0.0475 | AQ39: =AP39*0.7 -> 0.03325 | AR39: =IF(B39="",0,IF(AP39="",0,VLOOKUP(ROUNDDOWN(TEXT(B39,"0000"),-1),VLOOKUP!$M$3:$W$32,RIGHT(TEXT(B39,"0000"),1)+2,FALSE))) -> 2905 | AS39: =IF(B39="",0,AQ39/12*AR39) -> 8.0492708 | AT39: =AS39*(AV39/E39) -> 0.089868495 | AU39: =AT39+AU38 -> 1.3895236 | AV39: =IF(AO39="",AV38,AO39+AV38-(AT38/1.9835)) -> 627.88599 | BD39: 0 | BE39: 52 | BF39: 24 | BH39: =SUM(N39,P39:U39) -> 3.43 | BI39: 0 | BJ39: 12524.292 | BL39: =BL38+1 -> 25 | BM39: 6877.71 | BN39: =B39-BM39 -> -0.39 | BO39: 0 | BP39: =AH39-BO39 -> 25.4
A40: =A39+1 -> 26 | B40: 6877.38 | C40: =IF(B40="",C39,VLOOKUP(TRUNC(B40,1),VLOOKUP!$A$3:$K$2834,RIGHT(TEXT(B40,"0000.00"),1)+2,FALSE)) -> 208414 | D40: =C40-C39 -> 176 | E40: =C40-152000 -> 56414 | F40: =D40/$D$2 -> 88.732039 | G40: 34 | H40: 0 | I40: =G40+H40 -> 34 | J40: =IF(L40>0,L40,0) -> 83.172039 | K40: =I40+J40 -> 117.17204 | L40: =IF(G40="",0,F40-(I40-AK40)) -> 83.172039 | M40: 3.24 | N40: 0 | O40: =0*1.05 -> 0 | P40: 0 | Q40: =888900/325851/1.9835*1.02 -> 1.4028196 | R40: 0 | S40: =IF(((2.2*1.04)-T40)>=4.2,4.2,(2.2*1.04)-T40) -> 1.68168 | T40: =(0.55*1.06)*1.04 -> 0.60632 | U40: =M40-(Q40+R40+S40+T40) -> -0.45081957 | V40: 0 | W40: 0 | X40: =IF(B40="",0,MAX(0,M40-N40-O40-P40-Q40-R40-S40-T40-U40+V40+W40-BB40+AZ40-AN40)) -> 1.110223e-16 | Y40: =X40-AW40 -> 1.110223e-16 | AE40: 0 | AF40: 0 | AG40: 0 | AH40: 25.2 | AI40: =AI39-AH40 -> 4046.5579 | AJ40: 0 | AK40: =AE40+AH40+M40+V40+W40 -> 28.44 | AL40: =IF(L40<0,L40*-1,0) -> 0 | AM40: =AK40+AL40 -> 28.44 | AN40: =IF(V40="","",V40) -> 0 | AO40: =IF(G40="","",IF(I40>=795,795-MAX(0,M40-N40-O40-P40-Q40-R40-S40-T40-U40+V40+W40-BB40+AZ40),I40-Q40-R40-MAX(0,M40-N40-O40-P40-Q40-R40-S40-T40-U40+V40+W40-BB40+AZ40)-AF40)-AJ40) -> 32.59718 | AP40: 0.0475 | AQ40: =AP40*0.7 -> 0.03325 | AR40: =IF(B40="",0,IF(AP40="",0,VLOOKUP(ROUNDDOWN(TEXT(B40,"0000"),-1),VLOOKUP!$M$3:$W$32,RIGHT(TEXT(B40,"0000"),1)+2,FALSE))) -> 2905 | AS40: =IF(B40="",0,AQ40/12*AR40) -> 8.0492708 | AT40: =AS40*(AV40/E40) -> 0.094232695 | AU40: =AT40+AU39 -> 1.4837563 | AV40: =IF(AO40="",AV39,AO40+AV39-(AT39/1.9835)) -> 660.43787 | BD40: 0.57 | BE40: 48 | BF40: 38 | BH40: =SUM(N40,P40:U40) -> 3.24 | BI40: 0 | BJ40: 12534.042 | BL40: =BL39+1 -> 26 | BM40: 6877.78 | BN40: =B40-BM40 -> -0.4 | BO40: 0 | BP40: =AH40-BO40 -> 25.2
A41: =A40+1 -> 27 | B41: 6877.44 | C41: =IF(B41="",C40,VLOOKUP(TRUNC(B41,1),VLOOKUP!$A$3:$K$2834,RIGHT(TEXT(B41,"0000.00"),1)+2,FALSE)) -> 208589 | D41: =C41-C40 -> 175 | E41: =C41-152000 -> 56589 | F41: =D41/$D$2 -> 88.22788 | G41: 40.8 | H41: 0.13 | I41: =G41+H41 -> 40.93 | J41: =IF(L41>0,L41,0) -> 75.63788 | K41: =I41+J41 -> 116.56788 | L41: =IF(G41="",0,F41-(I41-AK41)) -> 75.63788 | M41: 3.14 | N41: 0 | O41: =0*1.05 -> 0 | P41: 0 | Q41: =900700/325851/1.9835*1.02 -> 1.4214418 | R41: 0 | S41: =IF(((1.8*1.04)-T41)>=4.2,4.2,(1.8*1.04)-T41) -> 1.26568 | T41: =(0.55*1.06)*1.04 -> 0.60632 | U41: =M41-(Q41+R41+S41+T41) -> -0.15344176 | V41: 0 | W41: 0 | X41: =IF(B41="",0,MAX(0,M41-N41-O41-P41-Q41-R41-S41-T41-U41+V41+W41-BB41+AZ41-AN41)) -> 1.110223e-16 | Y41: =X41-AW41 -> 1.110223e-16 | AE41: 0 | AF41: 0 | AG41: 0 | AH41: 25.2 | AI41: =AI40-AH41 -> 4021.3579 | AJ41: 0 | AK41: =AE41+AH41+M41+V41+W41 -> 28.34 | AL41: =IF(L41<0,L41*-1,0) -> 0 | AM41: =AK41+AL41 -> 28.34 | AN41: =IF(V41="","",V41) -> 0 | AO41: =IF(G41="","",IF(I41>=795,795-MAX(0,M41-N41-O41-P41-Q41-R41-S41-T41-U41+V41+W41-BB41+AZ41),I41-Q41-R41-MAX(0,M41-N41-O41-P41-Q41-R41-S41-T41-U41+V41+W41-BB41+AZ41)-AF41)-AJ41) -> 39.508558 | AP41: 0.0475 | AQ41: =AP41*0.7 -> 0.03325 | AR41: =IF(B41="",0,IF(AP41="",0,VLOOKUP(ROUNDDOWN(TEXT(B41,"0000"),-1),VLOOKUP!$M$3:$W$32,RIGHT(TEXT(B41,"0000"),1)+2,FALSE))) -> 2905 | AS41: =IF(B41="",0,AQ41/12*AR41) -> 8.0492708 | AT41: =AS41*(AV41/E41) -> 0.099554258 | AU41: =AT41+AU40 -> 1.5833106 | AV41: =IF(AO41="",AV40,AO41+AV40-(AT40/1.9835)) -> 699.89892 | BD41: 0 | BE41: 47 | BF41: 22 | BH41: =SUM(N41,P41:U41) -> 3.14 | BI41: 0 | BJ41: 12571.458 | BL41: =BL40+1 -> 27 | BM41: 6877.83 | BN41: =B41-BM41 -> -0.39 | BO41: 0 | BP41: =AH41-BO41 -> 25.2
A42: =A41+1 -> 28 | B42: 6877.45 | C42: =IF(B42="",C41,VLOOKUP(TRUNC(B42,1),VLOOKUP!$A$3:$K$2834,RIGHT(TEXT(B42,"0000.00"),1)+2,FALSE)) -> 208618 | D42: =C42-C41 -> 29 | E42: =C42-152000 -> 56618 | F42: =D42/$D$2 -> 14.62062 | G42: 32.2 | H42: 0 | I42: =G42+H42 -> 32.2 | J42: =IF(L42>0,L42,0) -> 10.84062 | K42: =I42+J42 -> 43.04062 | L42: =IF(G42="",0,F42-(I42-AK42)) -> 10.84062 | M42: 3.42 | N42: 0 | O42: =0*1.05 -> 0 | P42: 0 | Q42: =1094100/325851/1.9835*1.02 -> 1.7266564 | R42: 0 | S42: =IF(((2.1*1.04)-T42)>=4.2,4.2,(2.1*1.04)-T42) -> 1.57768 | T42: =(0.55*1.06)*1.04 -> 0.60632 | U42: =M42-(Q42+R42+S42+T42) -> -0.49065642 | V42: 0 | W42: 0 | X42: =IF(B42="",0,MAX(0,M42-N42-O42-P42-Q42-R42-S42-T42-U42+V42+W42-BB42+AZ42-AN42)) -> 3.3306691e-16 | Y42: =X42-AW42 -> 3.3306691e-16 | AE42: 0 | AF42: 0 | AG42: 0 | AH42: 25 | AI42: =AI41-AH42 -> 3996.3579 | AJ42: 0 | AK42: =AE42+AH42+M42+V42+W42 -> 28.42 | AL42: =IF(L42<0,L42*-1,0) -> 0 | AM42: =AK42+AL42 -> 28.42 | AN42: =IF(V42="","",V42) -> 0 | AO42: =IF(G42="","",IF(I42>=795,795-MAX(0,M42-N42-O42-P42-Q42-R42-S42-T42-U42+V42+W42-BB42+AZ42),I42-Q42-R42-MAX(0,M42-N42-O42-P42-Q42-R42-S42-T42-U42+V42+W42-BB42+AZ42)-AF42)-AJ42) -> 30.473344 | AP42: 0.0475 | AQ42: =AP42*0.7 -> 0.03325 | AR42: =IF(B42="",0,IF(AP42="",0,VLOOKUP(ROUNDDOWN(TEXT(B42,"0000"),-1),VLOOKUP!$M$3:$W$32,RIGHT(TEXT(B42,"0000"),1)+2,FALSE))) -> 2905 | AS42: =IF(B42="",0,AQ42/12*AR42) -> 8.0492708 | AT42: =AS42*(AV42/E42) -> 0.10382847 | AU42: =AT42+AU41 -> 1.687139 | AV42: =IF(AO42="",AV41,AO42+AV41-(AT41/1.9835)) -> 730.32207 | BD42: 0 | BE42: 43 | BF42: 18 | BH42: =SUM(N42,P42:U42) -> 3.42 | BI42: 0 | BJ42: 12571.542 | BL42: =BL41+1 -> 28 | BM42: 6877.84 | BN42: =B42-BM42 -> -0.39 | BO42: 0 | BP42: =AH42-BO42 -> 25
...

Sheet DEC
K1: MCPHEE RESERVOIR INFLOW/OUTFLOW TABULATION
A2: AF/cfs CONVERT FACTOR | D2: 1.9835 | K2: DECEMBER "2024"
D4: RESERVOIR | I4: INFLOW | X4: OUTFLOW | AX4: ADJUSTMENTS | BE4: WEATHER
A5: DATE | B5: RESERV | C5: RESERV | D5: AC FT | E5: ACTIVE | F5: CONV TO | G5: DOLORES | H5: LOST | I5: RECORD | J5: CALC | K5: TOTAL | L5: CALC | M5: DOLORES TUNNEL | V5: LONE | W5: U | X5: TOTAL | Y5: TOTAL | Z5: MVI | AA5: MVI | AB5: MVI | AC5: TO EX & | AD5: MVI | AE5: DV CR | AF5: D/S SENIOR | AH5: BELOW | AI5: FISH | AJ5: SPILL | AK5: RECORD | AL5: CALC | AM5: TOTAL | AN5: NAR | AO5: NARR | AP5: DWR | AQ5: MCPHEE | AR5: LAKE | AS5: MCPHEE | AT5: NARR | AU5: CUM | AV5: CUM | AW5: MVI | AX5: MVI | AY5: MVI | AZ5: DIST. | BA5: U/S | BB5: TOTTEN | BC5: UF&R | BD5: RAIN | BE5: MAX | BF5: MIN | BH5: TOTAL | BI5: GRNDHOG | BJ5: GRNDHOG | BM5: RESERV | BO5: BELOW | BP5: BELOW
A6: DEC | B6: ELEV | C6: TOT CAP | D6: CHANGE | E6: CAP | F6: CFS | G6: RIVER | H6: CAN | I6: INFLOW | J6: INFLOW | K6: INFLOW | L6: INF/OTF | M6: DOL | N6: WET | O6: UTE | P6: SEELEY | Q6: MWC | R6: CORTEZ | T6: UTE | U6: F-BAY | V6: PINE | W6: LAT | X6: MVI | Y6: MVI | Z6: CALL | AA6: CALL | AB6: APR- | AC6: U/S EX | AD6: PROJ | AE6: CANAL | AF6: MVIC | AG6: PROJ | AH6: MCP | AI6: LEFT | AK6: OTF | AL6: OTF | AM6: OTF | AN6: FILL | AO6: FILL | AP6: EST | AQ6: DAILY | AR6: SURFACE | AS6: DAILY | AT6: IN MCP | AU6: NARR | AV6: NARR | AW6: STOCK | AX6: STORED | AY6: STORED | AZ6: CLASS | BA6: USERS | BB6: (FRESH | BC6: LEASE | BE6: TMP | BF6: TMP | BH6: TUNNEL | BI6: DISCHARGE | BJ6: CAPACITY | BM6: ELEV | BO6: MCP | BP6: MCP
M7: TUN | N7: LAND | O7: F&R | Q7: NON - | R7: NON - | S7: PROJ | T7: PROJ | U7: BAL | X7: WATER | Y7: IRRIG. | Z7: STOR | AA7: SPILLED | AB7: JUNE | AF7: 1.7 | AG7: 1.3 | AO7: IN | AP7: PAN | AQ7: EVAP | AR7: AREA | AS7: EVAP | AT7: EVAP | AU7: IN MCP | AV7: IN | AX7: Apr - Jun | AY7: EVAP | AZ7: "B" | BA7: EXCH | BB7: WATER) | BC7: WATER | BH7: Misc. | BM7: DTGH | BO7: MPP | BP7: OVER
M8: TOT | Q8: PROJ | R8: PROJ | X8: USED | Y8: WATER | AA8: OR | AB8: (DIV+ | AO8: MCPHEE | AP8: EVAP | AU8: EVAP | AV8: MCPHEE | BP8: MPP
M9: DIV | R9: 4.2 | Y9: USED | AA9: USED | AB9: CALL) | BJ9: FP = 3960
A10: UNIT | B10: FT | C10: AC FT | D10: AC FT | E10: AC FT | F10: CFS | G10: CFS | H10: CFS | I10: CFS | J10: CFS | K10: CFS | L10: CFS | M10: CFS | N10: CFS | O10: CFS | P10: CFS | Q10: CFS | R10: CFS | S10: CFS | T10: CFS | U10: CFS | V10: CFS | W10: CFS | X10: 153400 | Y10: 150400 | AB10: 72000 | AC10: CFS | AD10: CFS | AE10: CFS | AF10: CFS | AG10: CFS | AH10: CFS | AI10: CFS | AJ10: CFS | AK10: CFS | AL10: CFS | AM10: CFS | AN10: CFS | AO10: CFS | AP10: IN | AQ10: IN | AR10: AC. | AS10: AF | AT10: AF | AU10: AF | AV10: CFS | AW10: CFS | AX10: CFS | AY10: AC.FT. | AZ10: CFS | BA10: CFS | BB10: CFS | BC10: CFS | BD10: IN | BE10: DEG ° | BF10: DEG ° | BH10: Outflow | BI10: CFS | BJ10: AC FT | BO10: CFS | BP10: CFS
N11: 1.03 | O11: 1.05 | P11: 1.02 | Q11: 1.02 | R11: 1.04 | T11: 1.04 | X11: CFS | Y11: CFS | Z11: CFS | AA11: CFS | AB11: Ac. Ft. | AT11: =NOV!AT53 -> 1.9065036 | BE11: F | BF11: F | BH11: CFS
A12: SEASON BAL | AT12: AF | AU12: AF
A13: YTD | B13: =NOV!B44 -> 6877.42 | C13: =NOV!C44 -> 208530 | D13: =NOV!D53 -> -702 | E13: =NOV!E53 -> 56530 | F13: =NOV!F52 -> -353.91984 | G13: =NOV!G52 -> 1513.3 | H13: =NOV!H52 -> 4.71 | I13: =NOV!I52 -> 1518.01 | J13: =NOV!J52 -> 287.14444 | K13: =NOV!K52 -> 1805.1544 | L13: =NOV!L52 -> -131.24984 | M13: =NOV!M52 -> 111.68 | ... Y13: =NOV!Y52 -> 2.220446e-15 | AC13: =NOV!AC52 -> 0 | AH13: =NOV!AH52 -> 943.1 | AI13: =NOV!AI52 -> 3946.1579 | AK13: =NOV!AK52 -> 1740.68 | AL13: =NOV!AL52 -> 418.39428 | AM13: =NOV!AM52 -> 2159.0743 | AN13: =NOV!AN52 -> 685.9 | AO13: =NOV!AO52 -> 784.53912 | AT13: =NOV!AT44 -> 0.11158118 | AU13: =NOV!AU53 -> 1.9065036 | AV13: =NOV!AV52 -> 783.6342 | AW13: =NOV!AW52 -> 0 | BD13: =NOV!BD52 -> 0.63 | BH13: =NOV!BH52 -> 111.68 | BI13: =NOV!BI52 -> 0 | BO13: =NOV!BO46 -> 0 | BP13: =NOV!BP46 -> 943.1
A15: 1 | B15: 6877.42 | C15: =IF(B15="",C13,VLOOKUP(TRUNC(B15,1),VLOOKUP!$A$3:$K$2834,RIGHT(TEXT(B15,"0000.00"),1)+2,FALSE)) -> 208530 | D15: =C15-C13 -> 0 | E15: =C15-152000 -> 56530 | F15: =D15/$D$2 -> 0 | G15: 28.3 | H15: 0 | I15: =G15+H15 -> 28.3 | J15: =IF(L15>0,L15,0) -> 0.39 | K15: =I15+J15 -> 28.69 | L15: =IF(G15="",0,F15-(I15-AK15)) -> 0.39 | M15: 3.39 | N15: 0 | O15: =0*1.05 -> 0 | P15: 0 | Q15: =1168900/325851/1.9835*1.02 -> 1.8447022 | R15: 0 | S15: =IF(((2.4*1.04)-T15)>=4.2,4.2,(2.4*1.04)-T15) -> 1.8962944 | T15: =(0.544*1.06)*1.04 -> 0.5997056 | U15: =M15-(Q15+R15+S15+T15) -> -0.95070221 | V15: 0 | W15: 0 | X15: =MAX(0,M15-N15-P15-O15-Q15-R15-S15-T15-U15+V15+W15-BB15+AZ15-AN15) -> 0 | Y15: =X15-AW15 -> 0 | AE15: 0 | AF15: 0 | AG15: 0 | AH15: 25.3 | AI15: =AI13-AH15 -> 3920.8579 | AJ15: 0 | AK15: =N15+O15+P15+Q15+R15+S15+T15+U15+X15+AE15+AH15 -> 28.69 | AL15: =IF(L15<0,L15*-1,0) -> 0 | AM15: =AK15+AL15 -> 28.69 | AN15: =IF(V15="","",V15) -> 0 | AO15: =IF(G15="","",IF(I15>=795,795-MAX(0,M15-N15-P15-O15-Q15-R15-S15-T15-U15+V15+W15-BB15+AZ15),I15-Q15-R15-MAX(0,M15-N15-P15-O15-Q15-R15-S15-T15-U15+V15+W15-BB15+AZ15)-AF15)-AJ15) -> 26.455298 | AP15: 0.0475 | AQ15: =AP15*0.7 -> 0.03325 | AR15: =IF(AP15="",0,VLOOKUP(ROUNDDOWN(TEXT(B15,"0000"),-1),VLOOKUP!$M$3:$W$32,RIGHT(TEXT(B15,"0000"),1)+2,FALSE)) -> 2905 | AS15: =IF(B15="",0,AQ15/12*AR15) -> 8.0492708 | AT15: =AS15*(AV15/E15) -> 0.11534012 | AU15: =AT15+AU13 -> 2.0218438 | AV15: =IF(AO15="",AV13,AO15+AV13-(AT13/1.9835)) -> 810.03324 | BD15: 0 | BE15: 53 | BF15: 21 | BH15: =SUM(N15,P15:U15) -> 3.39 | BI15: 0 | BJ15: 12571.458 | BL15: 1 | BM15: 6877.82 | BN15: =B15-BM15 -> -0.4 | BO15: 0 | BP15: =AH15-BO15 -> 25.3
A16: =A15+1 -> 2 | B16: 6877.44 | C16: =IF(B16="",C15,VLOOKUP(TRUNC(B16,1),VLOOKUP!$A$3:$K$2834,RIGHT(TEXT(B16,"0000.00"),1)+2,FALSE)) -> 208589 | D16: =C16-C15 -> 59 | E16: =C16-152000 -> 56589 | F16: =D16/$D$2 -> 29.7454 | G16: 30.1 | H16: 0 | I16: =G16+H16 -> 30.1 | J16: =IF(L16>0,L16,0) -> 28.4954 | K16: =I16+J16 -> 58.5954 | L16: =IF(G16="",0,F16-(I16-AK16)) -> 28.4954 | M16: 3.55 | N16: 0 | O16: =0*1.05 -> 0 | P16: 0 | Q16: =1057700/325851/1.9835*1.02 -> 1.6692117 | R16: 0 | S16: =IF(((2*1.04)-T16)>=4.2,4.2,(2*1.04)-T16) -> 1.4802944 | T16: =(0.544*1.06)*1.04 -> 0.5997056 | U16: =M16-(Q16+R16+S16+T16) -> -0.19921167 | V16: 0 | W16: 0 | X16: =MAX(0,M16-N16-P16-O16-Q16-R16-S16-T16-U16+V16+W16-BB16+AZ16-AN16) -> 0 | Y16: =X16-AW16 -> 0 | AE16: 0 | AF16: 0 | AG16: 0 | AH16: 25.3 | AI16: =AI15-AH16 -> 3895.5579 | AJ16: 0 | AK16: =N16+O16+P16+Q16+R16+S16+T16+U16+X16+AE16+AH16 -> 28.85 | AL16: =IF(L16<0,L16*-1,0) -> 0 | AM16: =AK16+AL16 -> 28.85 | AN16: =IF(V16="","",V16) -> 0 | AO16: =IF(G16="","",IF(I16>=795,795-MAX(0,M16-N16-P16-O16-Q16-R16-S16-T16-U16+V16+W16-BB16+AZ16),I16-Q16-R16-MAX(0,M16-N16-P16-O16-Q16-R16-S16-T16-U16+V16+W16-BB16+AZ16)-AF16)-AJ16) -> 28.430788 | AP16: 0.0475 | AQ16: =AP16*0.7 -> 0.03325 | AR16: =IF(AP16="",0,VLOOKUP(ROUNDDOWN(TEXT(B16,"0000"),-1),VLOOKUP!$M$3:$W$32,RIGHT(TEXT(B16,"0000"),1)+2,FALSE)) -> 2905 | AS16: =IF(B16="",0,AQ16/12*AR16) -> 8.0492708 | AT16: =AS16*(AV16/E16) -> 0.11925561 | AU16: =AT16+AU15 -> 2.1410994 | AV16: =IF(AO16="",AV15,AO16+AV15-(AT15/1.9835)) -> 838.40588 | BD16: 0 | BE16: 56 | BF16: 24 | BH16: =SUM(N16,P16:U16) -> 3.55 | BI16: 0 | BJ16: 12572 | BL16: =BL15+1 -> 2 | BM16: 6877.84 | BN16: =B16-BM16 -> -0.4 | BO16: 0 | BP16: =AH16-BO16 -> 25.3
