Workbook

Sheet NOV
K1: MC PHEE RESERVOIR IN/OUT FLOW TABULATION
A2: AF/cfs CONVERT FACTOR | D2: 1.9835 | L2: NOVEMBER "1989"
A4: DATE | B4: RESERV | C4: RESERV | D4: AC FT | E4: ACTIVE | F4: CONV TO | G4: DOLORES | H4: LOST | I4: RECORDED | J4: CALC | K4: TOTAL | L4: CALC | M4: TUNNEL | Q4: LONE | R4: U | S4: TOTAL | T4: MVI | U4: DV CR | V4: BELOW | W4: RECORDED | X4: CALC | Y4: TOTAL | Z4: RAIN | AA4: MAX | AB4: MIN | AC4: DATE
A5: "NOV" | B5: ELEV | C5: AC FT | D5: CHANGE | E5: CAP | F5: CFS | G5: RIVER | H5: CANYON | I5: INFLOW | J5: INFLOW | K5: INFLOW | L5: INF/OTF | M5: TOT DIV | N5: WETLAND | O5: UTE F&R | P5: MVI,CTZ | Q5: PINE | R5: LAT | S5: MVI | T5: CALL | U5: CANAL | V5: MC PHEE | W5: OUTFLOW | X5: OUTFLOW | Y5: OUTFLOW | AA5: TMP | AB5: TMP | AC5: "NOV"
A7: SEASON BAL
A8: YTD | B8: 6903.45 | C8: 296485
A10: 1 | B10: 6903.38 | C10: 296219 | D10: =C10-C8 -> -266 | E10: =C10-152000 -> 144219 | F10: =D10/$D$2 -> -134.10638 | G10: 52.08 | H10: 0 | I10: =G10+H10 -> 52.08 | J10: =IF(L10>0,L10,0) -> 0 | K10: =I10+J10 -> 52.08 | L10: =F10-(I10-W10) -> -82.816378 | M10: 29 | N10: 0 | O10: 0 | P10: =M10-(N10+O10) -> 29 | Q10: 0 | R10: 0 | S10: =SUM(P10:R10) -> 29 | U10: 0 | V10: 74.37 | W10: =N10+O10+S10+U10+V10 -> 103.37 | X10: =IF(L10<0,L10*-1,0) -> 82.816378 | Y10: =W10+X10 -> 186.18638 | Z10: 0 | AA10: 34 | AB10: 21 | AC10: 1
A11: =A10+1 -> 2 | B11: 6903.32 | C11: 295991 | D11: =C11-C10 -> -228 | E11: =C11-152000 -> 143991 | F11: =D11/$D$2 -> -114.94832 | G11: 57.93 | H11: 0 | I11: =G11+H11 -> 57.93 | J11: =IF(L11>0,L11,0) -> 0 | K11: =I11+J11 -> 57.93 | L11: =F11-(I11-W11) -> -69.508324 | M11: 29 | N11: 0 | O11: 0 | P11: =M11-(N11+O11) -> 29 | Q11: 0 | R11: 0 | S11: =SUM(P11:R11) -> 29 | U11: 0 | V11: 74.37 | W11: =N11+O11+S11+U11+V11 -> 103.37 | X11: =IF(L11<0,L11*-1,0) -> 69.508324 | Y11: =W11+X11 -> 172.87832 | Z11: 0 | AA11: 44 | AB11: 14 | AC11: =AC10+1 -> 2
A12: =A11+1 -> 3 | B12: 6903.27 | C12: 295802 | D12: =C12-C11 -> -189 | E12: =C12-152000 -> 143802 | F12: =D12/$D$2 -> -95.28611 | G12: 52.68 | H12: 0 | I12: =G12+H12 -> 52.68 | J12: =IF(L12>0,L12,0) -> 0 | K12: =I12+J12 -> 52.68 | L12: =F12-(I12-W12) -> -44.59611 | M12: 29 | N12: 0 | O12: 0 | P12: =M12-(N12+O12) -> 29 | Q12: 0 | R12: 0 | S12: =SUM(P12:R12) -> 29 | U12: 0 | V12: 74.37 | W12: =N12+O12+S12+U12+V12 -> 103.37 | X12: =IF(L12<0,L12*-1,0) -> 44.59611 | Y12: =W12+X12 -> 147.96611 | Z12: 0 | AA12: 54 | AB12: 18 | AC12: =AC11+1 -> 3
A13: =A12+1 -> 4 | B13: 6903.23 | C13: 295650 | D13: =C13-C12 -> -152 | E13: =C13-152000 -> 143650 | F13: =D13/$D$2 -> -76.632216 | G13: 46.86 | H13: 0 | I13: =G13+H13 -> 46.86 | J13: =IF(L13>0,L13,0) -> 0 | K13: =I13+J13 -> 46.86 | L13: =F13-(I13-W13) -> -20.122216 | M13: 29 | N13: 0 | O13: 0 | P13: =M13-(N13+O13) -> 29 | Q13: 0 | R13: 0 | S13: =SUM(P13:R13) -> 29 | U13: 0 | V13: 74.37 | W13: =N13+O13+S13+U13+V13 -> 103.37 | X13: =IF(L13<0,L13*-1,0) -> 20.122216 | Y13: =W13+X13 -> 123.49222 | Z13: 0 | AA13: 52 | AB13: 20 | AC13: =AC12+1 -> 4
A14: =A13+1 -> 5 | B14: 6903.19 | C14: 295498 | D14: =C14-C13 -> -152 | E14: =C14-152000 -> 143498 | F14: =D14/$D$2 -> -76.632216 | G14: 47.84 | H14: 0 | I14: =G14+H14 -> 47.84 | J14: =IF(L14>0,L14,0) -> 0 | K14: =I14+J14 -> 47.84 | L14: =F14-(I14-W14) -> -21.102216 | M14: 29 | N14: 0 | O14: 0 | P14: =M14-(N14+O14) -> 29 | Q14: 0 | R14: 0 | S14: =SUM(P14:R14) -> 29 | U14: 0 | V14: 74.37 | W14: =N14+O14+S14+U14+V14 -> 103.37 | X14: =IF(L14<0,L14*-1,0) -> 21.102216 | Y14: =W14+X14 -> 124.47222 | Z14: 0.02 | AA14: 48 | AB14: 20 | AC14: =AC13+1 -> 5
A15: =A14+1 -> 6 | B15: 6903.16 | C15: 295384 | D15: =C15-C14 -> -114 | E15: =C15-152000 -> 143384 | F15: =D15/$D$2 -> -57.474162 | G15: 51.95 | H15: 0 | I15: =G15+H15 -> 51.95 | J15: =IF(L15>0,L15,0) -> 0 | K15: =I15+J15 -> 51.95 | L15: =F15-(I15-W15) -> -6.0441618 | M15: 29 | N15: 0 | O15: 0 | P15: =M15-(N15+O15) -> 29 | Q15: 0 | R15: 0 | S15: =SUM(P15:R15) -> 29 | U15: 0 | V15: 74.38 | W15: =N15+O15+S15+U15+V15 -> 103.38 | X15: =IF(L15<0,L15*-1,0) -> 6.0441618 | Y15: =W15+X15 -> 109.42416 | Z15: 0.01 | AA15: 46 | AB15: 21 | AC15: =AC14+1 -> 6
A16: =A15+1 -> 7 | B16: 6903.11 | C16: 295195 | D16: =C16-C15 -> -189 | E16: =C16-152000 -> 143195 | F16: =D16/$D$2 -> -95.28611 | G16: 47.15 | H16: 0 | I16: =G16+H16 -> 47.15 | J16: =IF(L16>0,L16,0) -> 0 | K16: =I16+J16 -> 47.15 | L16: =F16-(I16-W16) -> -39.05611 | M16: 29 | N16: 0 | O16: 0 | P16: =M16-(N16+O16) -> 29 | Q16: 0 | R16: 0 | S16: =SUM(P16:R16) -> 29 | U16: 0 | V16: 74.38 | W16: =N16+O16+S16+U16+V16 -> 103.38 | X16: =IF(L16<0,L16*-1,0) -> 39.05611 | Y16: =W16+X16 -> 142.43611 | Z16: 0 | AA16: 44 | AB16: 20 | AC16: =AC15+1 -> 7
A17: =A16+1 -> 8 | B17: 6903.07 | C17: 295043 | D17: =C17-C16 -> -152 | E17: =C17-152000 -> 143043 | F17: =D17/$D$2 -> -76.632216 | G17: 42.36 | H17: 0 | I17: =G17+H17 -> 42.36 | J17: =IF(L17>0,L17,0) -> 0 | K17: =I17+J17 -> 42.36 | L17: =F17-(I17-W17) -> -11.532216 | M17: 29 | N17: 0 | O17: 0 | P17: =M17-(N17+O17) -> 29 | Q17: 0 | R17: 0 | S17: =SUM(P17:R17) -> 29 | U17: 0 | V17: 78.46 | W17: =N17+O17+S17+U17+V17 -> 107.46 | X17: =IF(L17<0,L17*-1,0) -> 11.532216 | Y17: =W17+X17 -> 118.99222 | Z17: 0.03 | AA17: 45 | AB17: 25 | AC17: =AC16+1 -> 8
A18: =A17+1 -> 9 | B18: 6903.02 | C18: 294853 | D18: =C18-C17 -> -190 | E18: =C18-152000 -> 142853 | F18: =D18/$D$2 -> -95.79027 | G18: 39.38 | H18: 0 | I18: =G18+H18 -> 39.38 | J18: =IF(L18>0,L18,0) -> 0 | K18: =I18+J18 -> 39.38 | L18: =F18-(I18-W18) -> -27.67027 | M18: 29 | N18: 0 | O18: 0 | P18: =M18-(N18+O18) -> 29 | Q18: 0 | R18: 0 | S18: =SUM(P18:R18) -> 29 | U18: 0 | V18: 78.5 | W18: =N18+O18+S18+U18+V18 -> 107.5 | X18: =IF(L18<0,L18*-1,0) -> 27.67027 | Y18: =W18+X18 -> 135.17027 | Z18: 0 | AA18: 46 | AB18: 23 | AC18: =AC17+1 -> 9
A19: =A18+1 -> 10 | B19: 6902.97 | C19: 294665 | D19: =C19-C18 -> -188 | E19: =C19-152000 -> 142665 | F19: =D19/$D$2 -> -94.781951 | G19: 45.8 | H19: 0 | I19: =G19+H19 -> 45.8 | J19: =IF(L19>0,L19,0) -> 0 | K19: =I19+J19 -> 45.8 | L19: =F19-(I19-W19) -> -33.091951 | M19: 29 | N19: 0 | O19: 0 | P19: =M19-(N19+O19) -> 29 | Q19: 0 | R19: 0 | S19: =SUM(P19:R19) -> 29 | U19: 0 | V19: 78.49 | W19: =N19+O19+S19+U19+V19 -> 107.49 | X19: =IF(L19<0,L19*-1,0) -> 33.091951 | Y19: =W19+X19 -> 140.58195 | Z19: 0 | AA19: 45 | AB19: 24 | AC19: =AC18+1 -> 10
A20: =A19+1 -> 11 | B20: 6902.92 | C20: 294476 | D20: =C20-C19 -> -189 | E20: =C20-152000 -> 142476 | F20: =D20/$D$2 -> -95.28611 | G20: 48.33 | H20: 0 | I20: =G20+H20 -> 48.33 | J20: =IF(L20>0,L20,0) -> 0 | K20: =I20+J20 -> 48.33 | L20: =F20-(I20-W20) -> -36.11611 | M20: 29 | N20: 0 | O20: 0 | P20: =M20-(N20+O20) -> 29 | Q20: 0 | R20: 0 | S20: =SUM(P20:R20) -> 29 | U20: 0 | V20: 78.5 | W20: =N20+O20+S20+U20+V20 -> 107.5 | X20: =IF(L20<0,L20*-1,0) -> 36.11611 | Y20: =W20+X20 -> 143.61611 | Z20: 0 | AA20: 45 | AB20: 23 | AC20: =AC19+1 -> 11
A21: =A20+1 -> 12 | B21: 6902.86 | C21: 294251 | D21: =C21-C20 -> -225 | E21: =C21-152000 -> 142251 | F21: =D21/$D$2 -> -113.43585 | G21: 46.22 | H21: 0 | I21: =G21+H21 -> 46.22 | J21: =IF(L21>0,L21,0) -> 0 | K21: =I21+J21 -> 46.22 | L21: =F21-(I21-W21) -> -52.165846 | M21: 29 | N21: 0 | O21: 0 | P21: =M21-(N21+O21) -> 29 | Q21: 0 | R21: 0 | S21: =SUM(P21:R21) -> 29 | U21: 0 | V21: 78.49 | W21: =N21+O21+S21+U21+V21 -> 107.49 | X21: =IF(L21<0,L21*-1,0) -> 52.165846 | Y21: =W21+X21 -> 159.65585 | Z21: 0 | AA21: 47 | AB21: 24 | AC21: =AC20+1 -> 12
A22: =A21+1 -> 13 | B22: 6902.82 | C22: 294100 | D22: =C22-C21 -> -151 | E22: =C22-152000 -> 142100 | F22: =D22/$D$2 -> -76.128056 | G22: 43.47 | H22: 0 | I22: =G22+H22 -> 43.47 | J22: =IF(L22>0,L22,0) -> 0 | K22: =I22+J22 -> 43.47 | L22: =F22-(I22-W22) -> -11.978056 | M22: 29 | N22: 0 | O22: 0 | P22: =M22-(N22+O22) -> 29 | Q22: 0 | R22: 0 | S22: =SUM(P22:R22) -> 29 | U22: 0 | V22: 78.62 | W22: =N22+O22+S22+U22+V22 -> 107.62 | X22: =IF(L22<0,L22*-1,0) -> 11.978056 | Y22: =W22+X22 -> 119.59806 | Z22: 0 | AA22: 46 | AB22: 22 | AC22: =AC21+1 -> 13
... A38: =A37+1 -> 29 | B38: 6900.65 | C38: 285986 | D38: =C38-C37 -> -270 | E38: =C38-152000 -> 133986 | F38: =D38/$D$2 -> -136.12301 | G38: 28 | H38: 0 | I38: =G38+H38 -> 28 | J38: =IF(L38>0,L38,0) -> 10.526985 | K38: =I38+J38 -> 38.526985 | L38: =F38-(I38-W38) -> 10.526985 | M38: 5.13 | N38: 0 | O38: 0 | P38: =M38-(N38+O38) -> 5.13 | Q38: 90.87 | R38: 0 | S38: =SUM(P38:R38) -> 96 | U38: 0 | V38: 78.65 | W38: =N38+O38+S38+U38+V38 -> 174.65 | X38: =IF(L38<0,L38*-1,0) -> 0 | Y38: =W38+X38 -> 174.65 | Z38: 0.04 | AA38: 40 | AB38: 27 | AC38: =AC37+1 -> 29
A39: 30 | B39: 6900.6 | C39: 285801 | D39: =C39-C38 -> -185 | E39: =C39-152000 -> 133801 | F39: =D39/$D$2 -> -93.269473 | G39: 28 | H39: 0 | I39: =G39+H39 -> 28 | J39: =IF(L39>0,L39,0) -> 0 | K39: =I39+J39 -> 28 | L39: =F39-(I39-W39) -> -37.629473 | M39: 5.13 | N39: 0 | O39: 0 | P39: =M39-(N39+O39) -> 5.13 | Q39: 0 | R39: 0 | S39: =SUM(P39:R39) -> 5.13 | U39: 0 | V39: 78.51 | W39: =N39+O39+S39+U39+V39 -> 83.64 | X39: =IF(L39<0,L39*-1,0) -> 37.629473 | Y39: =W39+X39 -> 121.26947 | Z39: 0.12 | AA39: 50 | AB39: 33 | AC39: 30
A41: MONTH / CFS | F41: =SUM(F10:F39) -> -5386.4381 | G41: =SUM(G10:G39) -> 1320.62 | H41: =SUM(H10:H39) -> 0 | I41: =SUM(I10:I39) -> 1320.62 | J41: =SUM(J10:J39) -> 184.80309 | K41: =SUM(K10:K39) -> 1505.4231 | L41: =SUM(L10:L39) -> -1096.4681 | M41: =SUM(M10:M39) -> 617.79 | ... S41: =SUM(S10:S39) -> 3282.25 | U41: =SUM(U10:U39) -> 0 | V41: =SUM(V10:V39) -> 2328.34 | W41: =SUM(W10:W39) -> 5610.59 | X41: =SUM(X10:X39) -> 1281.2712 | Y41: =SUM(Y10:Y39) -> 6891.8612 | Z41: =SUM(Z10:Z39) -> 1.92 | AA41: =AVERAGE(AA10:AA39) -> 46.066667 | AB41: =AVERAGE(AB10:AB39) -> 21.733333 | AC41: Avg
A42: MONTH / AF | D42: =SUM(D10:D39) -> -10684 | F42: =F41*$D$2 -> -10684 | G42: =G41*$D$2 -> 2619.4498 | H42: =H41*$D$2 -> 0 | I42: =I41*$D$2 -> 2619.4498 | J42: =J41*$D$2 -> 366.55692 | K42: =K41*$D$2 -> 2986.0067 | L42: =L41*$D$2 -> -2174.8445 | M42: =M41*$D$2 -> 1225.3865 | ... S42: =S41*$D$2 -> 6510.3429 | U42: =U41*$D$2 -> 0 | V42: =V41*$D$2 -> 4618.2624 | W42: =W41*$D$2 -> 11128.605 | X42: =X41*$D$2 -> 2541.4014 | Y42: =Y41*$D$2 -> 13670.007 | AA42: =MAX(AA10:AA39) -> 59 | AB42: =MAX(AB10:AB39) -> 33 | AC42: HI
A44: SEASON / CFS | AA44: =MIN(AA10:AA39) -> 34 | AB44: =MIN(AB10:AB39) -> 14 | AC44: LO
A45: SEASON / AF
A47: YTD / CFS | F47: =F8+F41 -> -5386.4381 | G47: =G8+G41 -> 1320.62 | H47: =H8+H41 -> 0 | I47: =I8+I41 -> 1320.62 | J47: =J8+J41 -> 184.80309 | K47: =K8+K41 -> 1505.4231 | L47: =L8+L41 -> -1096.4681 | M47: =M8+M41 -> 617.79 | ... S47: =S8+S41 -> 3282.25 | U47: =U8+U41 -> 0 | V47: =V8+V41 -> 2328.34 | W47: =W8+W41 -> 5610.59 | X47: =X8+X41 -> 1281.2712 | Y47: =Y8+Y41 -> 6891.8612 | Z47: =Z8+Z41 -> 1.92
A48: YTD / AF | D48: =D8+D42 -> -10684 | E48: =E39 -> 133801 | F48: =F47*$D$2 -> -10684 | G48: =G47*$D$2 -> 2619.4498 | H48: =H47*$D$2 -> 0 | I48: =I47*$D$2 -> 2619.4498 | J48: =J47*$D$2 -> 366.55692 | K48: =K47*$D$2 -> 2986.0067 | L48: =L47*$D$2 -> -2174.8445 | M48: =M47*$D$2 -> 1225.3865 | ... Y48: =Y47*$D$2 -> 13670.007

Sheet DEC
K1: MC PHEE RESERVOIR IN/OUT FLOW TABULATION
A2: AF/cfs CONVERT FACTOR | D2: 1.9835 | K2: DECEMBER "1989"
A4: DATE | B4: RESERV | C4: RESERV | D4: AC FT | E4: ACTIVE | F4: CONV TO | G4: DOLORES | H4: LOST | I4: RECORDED | J4: CALC | K4: TOTAL | L4: CALC | M4: TUNNEL | Q4: LONE | R4: U | S4: TOTAL | T4: MVI | U4: DV CR | V4: BELOW | W4: RECORDED | X4: CALC | Y4: TOTAL | Z4: RAIN | AA4: MAX | AB4: MIN | AC4: DATE
A5: "DEC" | B5: ELEV | C5: AC FT | D5: CHANGE | E5: CAP | F5: CFS | G5: RIVER | H5: CANYON | I5: INFLOW | J5: INFLOW | K5: INFLOW | L5: INF/OTF | M5: TOT DIV | N5: WETLAND | O5: UTE F&R | P5: MVI,CTZ | Q5: PINE | R5: LAT | S5: MVI | T5: CALL | U5: CANAL | V5: MC PHEE | W5: OUTFLOW | X5: OUTFLOW | Y5: OUTFLOW | AA5: TMP | AB5: TMP | AC5: "DEC"
A7: SEASON BAL
A8: YTD | B8: =NOV!B39 -> 6900.6 | C8: =NOV!C39 -> 285801 | D8: =NOV!$D$48 -> -10684 | E8: =NOV!$E$39 -> 133801 | F8: =NOV!F47 -> -5386.4381 | G8: =NOV!G47 -> 1320.62 | H8: =NOV!H47 -> 0 | I8: =NOV!I47 -> 1320.62 | J8: =NOV!J47 -> 184.80309 | K8: =NOV!K47 -> 1505.4231 | L8: =NOV!L47 -> -1096.4681 | M8: =NOV!M47 -> 617.79 | ... Z8: =NOV!Z47 -> 1.92
A10: 1 | B10: 6900.57 | C10: 285690 | D10: =C10-C8 -> -111 | E10: =C10-152000 -> 133690 | F10: =D10/$D$2 -> -55.961684 | G10: 32.8 | H10: 0 | I10: =G10+H10 -> 32.8 | J10: =IF(L10>0,L10,0) -> 0 | K10: =I10+J10 -> 32.8 | L10: =F10-(I10-W10) -> -4.9816839 | M10: 5.13 | N10: 0 | O10: 0 | P10: =M10-(N10+O10) -> 5.13 | Q10: 0 | R10: 0 | S10: =SUM(P10:R10) -> 5.13 | U10: 0 | V10: 78.65 | W10: =N10+O10+S10+U10+V10 -> 83.78 | X10: =IF(L10<0,L10*-1,0) -> 4.9816839 | Y10: =W10+X10 -> 88.761684 | Z10: 0 | AA10: 40 | AB10: 13 | AC10: 1
A11: =A10+1 -> 2 | B11: 6900.55 | C11: 285616 | D11: =C11-C10 -> -74 | E11: =C11-152000 -> 133616 | F11: =D11/$D$2 -> -37.307789 | G11: 46.4 | H11: 0 | I11: =G11+H11 -> 46.4 | J11: =IF(L11>0,L11,0) -> 0 | K11: =I11+J11 -> 46.4 | L11: =F11-(I11-W11) -> -0.0077892614 | M11: 5.13 | N11: 0 | O11: 0 | P11: =M11-(N11+O11) -> 5.13 | Q11: 0 | R11: 0 | S11: =SUM(P11:R11) -> 5.13 | U11: 0 | V11: 78.57 | W11: =N11+O11+S11+U11+V11 -> 83.7 | X11: =IF(L11<0,L11*-1,0) -> 0.0077892614 | Y11: =W11+X11 -> 83.707789 | Z11: 0 | AA11: 40 | AB11: 13 | AC11: =AC10+1 -> 2
A12: =A11+1 -> 3 | B12: 6900.52 | C12: 285505 | D12: =C12-C11 -> -111 | E12: =C12-152000 -> 133505 | F12: =D12/$D$2 -> -55.961684 | G12: 28 | H12: 0 | I12: =G12+H12 -> 28 | J12: =IF(L12>0,L12,0) -> 0.028316108 | K12: =I12+J12 -> 28.028316 | L12: =F12-(I12-W12) -> 0.028316108 | M12: 5.13 | N12: 0 | O12: 0 | P12: =M12-(N12+O12) -> 5.13 | Q12: 0 | R12: 0 | S12: =SUM(P12:R12) -> 5.13 | U12: 0 | V12: 78.86 | W12: =N12+O12+S12+U12+V12 -> 83.99 | X12: =IF(L12<0,L12*-1,0) -> 0 | Y12: =W12+X12 -> 83.99 | Z12: 0 | AA12: 43 | AB12: 14 | AC12: =AC11+1 -> 3
A13: =A12+1 -> 4 | B13: 6900.48 | C13: 285357 | D13: =C13-C12 -> -148 | E13: =C13-152000 -> 133357 | F13: =D13/$D$2 -> -74.615579 | G13: 9.6 | H13: 0 | I13: =G13+H13 -> 9.6 | J13: =IF(L13>0,L13,0) -> 0 | K13: =I13+J13 -> 9.6 | L13: =F13-(I13-W13) -> -0.045578523 | M13: 5.13 | N13: 0 | O13: 0 | P13: =M13-(N13+O13) -> 5.13 | Q13: 0 | R13: 0 | S13: =SUM(P13:R13) -> 5.13 | U13: 0 | V13: 79.04 | W13: =N13+O13+S13+U13+V13 -> 84.17 | X13: =IF(L13<0,L13*-1,0) -> 0.045578523 | Y13: =W13+X13 -> 84.215579 | Z13: 0 | AA13: 44 | AB13: 17 | AC13: =AC12+1 -> 4
A14: =A13+1 -> 5 | B14: 6900.45 | C14: 285246 | D14: =C14-C13 -> -111 | E14: =C14-152000 -> 133246 | F14: =D14/$D$2 -> -55.961684 | G14: 28.1 | H14: 0 | I14: =G14+H14 -> 28.1 | J14: =IF(L14>0,L14,0) -> 0.018316108 | K14: =I14+J14 -> 28.118316 | L14: =F14-(I14-W14) -> 0.018316108 | M14: 5.13 | N14: 0 | O14: 0 | P14: =M14-(N14+O14) -> 5.13 | Q14: 0 | R14: 0 | S14: =SUM(P14:R14) -> 5.13 | U14: 0 | V14: 78.95 | W14: =N14+O14+S14+U14+V14 -> 84.08 | X14: =IF(L14<0,L14*-1,0) -> 0 | Y14: =W14+X14 -> 84.08 | Z14: 0 | AA14: 41 | AB14: 18 | AC14: =AC13+1 -> 5
A15: =A14+1 -> 6 | B15: 6900.41 | C15: 285098 | D15: =C15-C14 -> -148 | E15: =C15-152000 -> 133098 | F15: =D15/$D$2 -> -74.615579 | G15: 9.4 | H15: 0 | I15: =G15+H15 -> 9.4 | J15: =IF(L15>0,L15,0) -> 0.034421477 | K15: =I15+J15 -> 9.4344215 | L15: =F15-(I15-W15) -> 0.034421477 | M15: 5.13 | N15: 0 | O15: 0 | P15: =M15-(N15+O15) -> 5.13 | Q15: 0 | R15: 0 | S15: =SUM(P15:R15) -> 5.13 | U15: 0 | V15: 78.92 | W15: =N15+O15+S15+U15+V15 -> 84.05 | X15: =IF(L15<0,L15*-1,0) -> 0 | Y15: =W15+X15 -> 84.05 | Z15: 0 | AA15: 36 | AB15: 21 | AC15: =AC14+1 -> 6
A16: =A15+1 -> 7 | B16: 6900.37 | C16: 284950 | D16: =C16-C15 -> -148 | E16: =C16-152000 -> 132950 | F16: =D16/$D$2 -> -74.615579 | G16: 9.4 | H16: 0 | I16: =G16+H16 -> 9.4 | J16: =IF(L16>0,L16,0) -> 0 | K16: =I16+J16 -> 9.4 | L16: =F16-(I16-W16) -> -0.0055785228 | M16: 5.13 | N16: 0 | O16: 0 | P16: =M16-(N16+O16) -> 5.13 | Q16: 0 | R16: 0 | S16: =SUM(P16:R16) -> 5.13 | U16: 0 | V16: 78.88 | W16: =N16+O16+S16+U16+V16 -> 84.01 | X16: =IF(L16<0,L16*-1,0) -> 0.0055785228 | Y16: =W16+X16 -> 84.015579 | Z16: 0 | AA16: 40 | AB16: 19 | AC16: =AC15+1 -> 7
A17: =A16+1 -> 8 | B17: 6900.33 | C17: 284801 | D17: =C17-C16 -> -149 | E17: =C17-152000 -> 132801 | F17: =D17/$D$2 -> -75.119738 | G17: 9.1 | H17: 0 | I17: =G17+H17 -> 9.1 | J17: =IF(L17>0,L17,0) -> 0 | K17: =I17+J17 -> 9.1 | L17: =F17-(I17-W17) -> -0.019737837 | M17: 5.13 | N17: 0 | O17: 0 | P17: =M17-(N17+O17) -> 5.13 | Q17: 0 | R17: 0 | S17: =SUM(P17:R17) -> 5.13 | U17: 0 | V17: 79.07 | W17: =N17+O17+S17+U17+V17 -> 84.2 | X17: =IF(L17<0,L17*-1,0) -> 0.019737837 | Y17: =W17+X17 -> 84.219738 | Z17: 0 | AA17: 38 | AB17: 17 | AC17: =AC16+1 -> 8
A18: =A17+1 -> 9 | B18: 6900.29 | C18: 284653 | D18: =C18-C17 -> -148 | E18: =C18-152000 -> 132653 | F18: =D18/$D$2 -> -74.615579 | G18: 9.3 | H18: 0 | I18: =G18+H18 -> 9.3 | J18: =IF(L18>0,L18,0) -> 0.014421477 | K18: =I18+J18 -> 9.3144215 | L18: =F18-(I18-W18) -> 0.014421477 | M18: 5.13 | N18: 0 | O18: 0 | P18: =M18-(N18+O18) -> 5.13 | Q18: 0 | R18: 0 | S18: =SUM(P18:R18) -> 5.13 | U18: 0 | V18: 78.8 | W18: =N18+O18+S18+U18+V18 -> 83.93 | X18: =IF(L18<0,L18*-1,0) -> 0 | Y18: =W18+X18 -> 83.93 | Z18: 0 | AA18: 37 | AB18: 15 | AC18: =AC17+1 -> 9
A19: =A18+1 -> 10 | B19: 6900.25 | C19: 284505 | D19: =C19-C18 -> -148 | E19: =C19-152000 -> 132505 | F19: =D19/$D$2 -> -74.615579 | G19: 9.7 | H19: 0 | I19: =G19+H19 -> 9.7 | J19: =IF(L19>0,L19,0) -> 0.014421477 | K19: =I19+J19 -> 9.7144215 | L19: =F19-(I19-W19) -> 0.014421477 | M19: 5.13 | N19: 0 | O19: 0 | P19: =M19-(N19+O19) -> 5.13 | Q19: 0 | R19: 0 | S19: =SUM(P19:R19) -> 5.13 | U19: 0 | V19: 79.2 | W19: =N19+O19+S19+U19+V19 -> 84.33 | X19: =IF(L19<0,L19*-1,0) -> 0 | Y19: =W19+X19 -> 84.33 | Z19: 0 | AA19: 21 | AB19: 12 | AC19: =AC18+1 -> 10
A20: =A19+1 -> 11 | B20: 6900.21 | C20: 284320 | D20: =C20-C19 -> -185 | E20: =C20-152000 -> 132320 | F20: =D20/$D$2 -> -93.269473 | G20: 0 | H20: 0 | I20: =G20+H20 -> 0 | J20: =IF(L20>0,L20,0) -> 0 | K20: =I20+J20 -> 0 | L20: =F20-(I20-W20) -> -9.1194732 | M20: 5.13 | N20: 0 | O20: 0 | P20: =M20-(N20+O20) -> 5.13 | Q20: 0 | R20: 0 | S20: =SUM(P20:R20) -> 5.13 | U20: 0 | V20: 79.02 | W20: =N20+O20+S20+U20+V20 -> 84.15 | X20: =IF(L20<0,L20*-1,0) -> 9.1194732 | Y20: =W20+X20 -> 93.269473 | Z20: 0 | AA20: 28 | AB20: 5 | AC20: =AC19+1 -> 11
A21: =A20+1 -> 12 | B21: 6900.17 | C21: 284209 | D21: =C21-C20 -> -111 | E21: =C21-152000 -> 132209 | F21: =D21/$D$2 -> -55.961684 | G21: 28.3 | H21: 0 | I21: =G21+H21 -> 28.3 | J21: =IF(L21>0,L21,0) -> 0 | K21: =I21+J21 -> 28.3 | L21: =F21-(I21-W21) -> -0.041683892 | M21: 4.92 | N21: 0 | O21: 0 | P21: =M21-(N21+O21) -> 4.92 | Q21: 0 | R21: 0 | S21: =SUM(P21:R21) -> 4.92 | U21: 0 | V21: 79.3 | W21: =N21+O21+S21+U21+V21 -> 84.22 | X21: =IF(L21<0,L21*-1,0) -> 0.041683892 | Y21: =W21+X21 -> 84.261684 | Z21: 0.2 | AA21: 29 | AB21: 8 | AC21: =AC20+1 -> 12
A22: =A21+1 -> 13 | B22: 6900.13 | C22: 284061 | D22: =C22-C21 -> -148 | E22: =C22-152000 -> 132061 | F22: =D22/$D$2 -> -74.615579 | G22: 9.5 | H22: 0 | I22: =G22+H22 -> 9.5 | J22: =IF(L22>0,L22,0) -> 0 | K22: =I22+J22 -> 9.5 | L22: =F22-(I22-W22) -> -0.015578523 | M22: 4.76 | N22: 0 | O22: 0 | P22: =M22-(N22+O22) -> 4.76 | Q22: 0 | R22: 0 | S22: =SUM(P22:R22) -> 4.76 | U22: 0 | V22: 79.34 | W22: =N22+O22+S22+U22+V22 -> 84.1 | X22: =IF(L22<0,L22*-1,0) -> 0.015578523 | Y22: =W22+X22 -> 84.115579 | Z22: 0 | AA22: 28 | AB22: 7 | AC22: =AC21+1 -> 13
... A38: =A37+1 -> 29 | B38: 6899.48 | C38: 281670 | D38: =C38-C37 -> -147 | E38: =C38-152000 -> 129670 | F38: =D38/$D$2 -> -74.111419 | G38: 6 | H38: 0 | I38: =G38+H38 -> 6 | J38: =IF(L38>0,L38,0) -> 0.018580792 | K38: =I38+J38 -> 6.0185808 | L38: =F38-(I38-W38) -> 0.018580792 | M38: 5.13 | N38: 0 | O38: 0 | P38: =M38-(N38+O38) -> 5.13 | Q38: 0 | R38: 0 | S38: =SUM(P38:R38) -> 5.13 | U38: 0 | V38: 75 | W38: =N38+O38+S38+U38+V38 -> 80.13 | X38: =IF(L38<0,L38*-1,0) -> 0 | Y38: =W38+X38 -> 80.13 | Z38: 0 | AA38: 46 | AB38: 19 | AC38: =AC37+1 -> 29
A39: 30 | B39: 6899.44 | C39: 281523 | D39: =C39-C38 -> -147 | E39: =C39-152000 -> 129523 | F39: =D39/$D$2 -> -74.111419 | G39: 6 | H39: 0 | I39: =G39+H39 -> 6 | J39: =IF(L39>0,L39,0) -> 0.018580792 | K39: =I39+J39 -> 6.0185808 | L39: =F39-(I39-W39) -> 0.018580792 | M39: 5.13 | N39: 0 | O39: 0 | P39: =M39-(N39+O39) -> 5.13 | Q39: 0 | R39: 0 | S39: =SUM(P39:R39) -> 5.13 | U39: 0 | V39: 75 | W39: =N39+O39+S39+U39+V39 -> 80.13 | X39: =IF(L39<0,L39*-1,0) -> 0 | Y39: =W39+X39 -> 80.13 | Z39: 0 | AA39: 47 | AB39: 8 | AC39: 30
A40: 31 | B40: 6899.4 | C40: 281376 | D40: =C40-C39 -> -147 | E40: =C40-152000 -> 129376 | F40: =D40/$D$2 -> -74.111419 | G40: 6 | H40: 0 | I40: =G40+H40 -> 6 | J40: =IF(L40>0,L40,0) -> 0.018580792 | K40: =I40+J40 -> 6.0185808 | L40: =F40-(I40-W40) -> 0.018580792 | M40: 5.13 | N40: 0 | O40: 0 | P40: =M40-(N40+O40) -> 5.13 | Q40: 0 | R40: 0 | S40: =SUM(P40:R40) -> 5.13 | U40: 0 | V40: 75 | W40: =N40+O40+S40+U40+V40 -> 80.13 | X40: =IF(L40<0,L40*-1,0) -> 0 | Y40: =W40+X40 -> 80.13 | Z40: 0 | AA40: 40 | AB40: 6 | AC40: 31
A42: MONTH / CFS | F42: =SUM(F10:F40) -> -2230.905 | G42: =SUM(G10:G40) -> 369.3 | H42: =SUM(H10:H40) -> 0 | I42: =SUM(I10:I40) -> 369.3 | J42: =SUM(J10:J40) -> 0.30022435 | K42: =SUM(K10:K40) -> 369.60022 | L42: =SUM(L10:L40) -> -54.224966 | M42: =SUM(M10:M40) -> 155.17 | ... S42: =SUM(S10:S40) -> 155.17 | U42: =SUM(U10:U40) -> 0 | V42: =SUM(V10:V40) -> 2390.81 | W42: =SUM(W10:W40) -> 2545.98 | X42: =SUM(X10:X40) -> 54.52519 | Y42: =SUM(Y10:Y40) -> 2600.5052 | Z42: =SUM(Z10:Z40) -> 0.2 | AA42: =AVERAGE(AA10:AA40) -> 39.483871 | AB42: =AVERAGE(AB10:AB40) -> 11.129032 | AC42: Avg
A43: MONTH / AF | D43: =SUM(D10:D40) -> -4425 | F43: =F42*$D$2 -> -4425 | G43: =G42*$D$2 -> 732.50655 | H43: =H42*$D$2 -> 0 | I43: =I42*$D$2 -> 732.50655 | J43: =J42*$D$2 -> 0.595495 | K43: =K42*$D$2 -> 733.10204 | L43: =L42*$D$2 -> -107.55522 | M43: =M42*$D$2 -> 307.7797 | ... S43: =S42*$D$2 -> 307.7797 | U43: =U42*$D$2 -> 0 | V43: =V42*$D$2 -> 4742.1716 | W43: =W42*$D$2 -> 5049.9513 | X43: =X42*$D$2 -> 108.15072 | Y43: =Y42*$D$2 -> 5158.102 | AA43: =MAX(AA10:AA40) -> 62 | AB43: =MAX(AB10:AB40) -> 21 | AC43: HI
A45: SEASON / CFS | AA45: =MIN(AA10:AA40) -> 21 | AB45: =MIN(AB10:AB40) -> 2 | AC45: LO
A46: SEASON / AF
A48: YTD / CFS | F48: =F8+F42 -> -7617.3431 | G48: =G8+G42 -> 1689.92 | H48: =H8+H42 -> 0 | I48: =I8+I42 -> 1689.92 | J48: =J8+J42 -> 185.10331 | K48: =K8+K42 -> 1875.0233 | L48: =L8+L42 -> -1150.6931 | M48: =M8+M42 -> 772.96 | ... S48: =S8+S42 -> 3437.42 | U48: =U8+U42 -> 0 | V48: =V8+V42 -> 4719.15 | W48: =W8+W42 -> 8156.57 | X48: =X8+X42 -> 1335.7964 | Y48: =Y8+Y42 -> 9492.3664 | Z48: =Z8+Z42 -> 2.12
A49: YTD / AF | D49: =D8+D43 -> -15109 | E49: =E40 -> 129376 | F49: =F48*$D$2 -> -15109 | G49: =G48*$D$2 -> 3351.9563 | H49: =H48*$D$2 -> 0 | I49: =I48*$D$2 -> 3351.9563 | J49: =J48*$D$2 -> 367.15242 | K49: =K48*$D$2 -> 3719.1087 | L49: =L48*$D$2 -> -2282.3997 | M49: =M48*$D$2 -> 1533.1662 | ... Y49: =Y48*$D$2 -> 18828.109

Sheet JAN
K1: MC PHEE RESERVOIR IN/OUT FLOW TABULATION
A2: AF/cfs CONVERT FACTOR | D2: 1.9835 | K2: JANUARY "1990"
A4: DATE | B4: RESERV | C4: RESERV | D4: AC FT | E4: ACTIVE | F4: CONV TO | G4: DOLORES | H4: LOST | I4: RECORDED | J4: CALC | K4: TOTAL | L4: CALC | M4: TUNNEL | Q4: LONE | R4: U | S4: TOTAL | T4: MVI | U4: DV CR | V4: BELOW | W4: RECORDED | X4: CALC | Y4: TOTAL | Z4: RAIN | AA4: MAX | AB4: MIN | AC4: DATE
A5: "JAN" | B5: ELEV | C5: AC FT | D5: CHANGE | E5: CAP | F5: CFS | G5: RIVER | H5: CANYON | I5: INFLOW | J5: INFLOW | K5: INFLOW | L5: INF/OTF | M5: TOT DIV | N5: WETLAND | O5: UTE F&R | P5: MVI,CTZ | Q5: PINE | R5: LAT | S5: MVI | T5: CALL | U5: CANAL | V5: MC PHEE | W5: OUTFLOW | X5: OUTFLOW | Y5: OUTFLOW | AA5: TMP | AB5: TMP | AC5: "JAN"
A7: SEASON BAL
A8: YTD | B8: =DEC!B40 -> 6899.4 | C8: =DEC!C40 -> 281376 | D8: =DEC!$D$49 -> -15109 | E8: =DEC!$E$40 -> 129376 | F8: =DEC!F48 -> -7617.3431 | G8: =DEC!G48 -> 1689.92 | H8: =DEC!H48 -> 0 | I8: =DEC!I48 -> 1689.92 | J8: =DEC!J48 -> 185.10331 | K8: =DEC!K48 -> 1875.0233 | L8: =DEC!L48 -> -1150.6931 | M8: =DEC!M48 -> 772.96 | ... Z8: =DEC!Z48 -> 2.12
A10: 1 | B10: 6899.36 | C10: 281229 | D10: =C10-C8 -> -147 | E10: =C10-152000 -> 129229 | F10: =D10/$D$2 -> -74.111419 | G10: 6.38 | H10: 0 | I10: =G10+H10 -> 6.38 | J10: =IF(L10>0,L10,0) -> 0.018580792 | K10: =I10+J10 -> 6.3985808 | L10: =F10-(I10-W10) -> 0.018580792 | M10: 5.13 | N10: 0 | O10: 0 | P10: =M10-(N10+O10) -> 5.13 | Q10: 0 | R10: 0 | S10: =SUM(P10:R10) -> 5.13 | U10: 0 | V10: 75.38 | W10: =N10+O10+S10+U10+V10 -> 80.51 | X10: =IF(L10<0,L10*-1,0) -> 0 | Y10: =W10+X10 -> 80.51 | Z10: 0 | AA10: 43 | AB10: 10 | AC10: 1
A11: =A10+1 -> 2 | B11: 6899.32 | C11: 281082 | D11: =C11-C10 -> -147 | E11: =C11-152000 -> 129082 | F11: =D11/$D$2 -> -74.111419 | G11: 6.38 | H11: 0 | I11: =G11+H11 -> 6.38 | J11: =IF(L11>0,L11,0) -> 0.018580792 | K11: =I11+J11 -> 6.3985808 | L11: =F11-(I11-W11) -> 0.018580792 | M11: 5.13 | N11: 0 | O11: 0 | P11: =M11-(N11+O11) -> 5.13 | Q11: 0 | R11: 0 | S11: =SUM(P11:R11) -> 5.13 | U11: 0 | V11: 75.38 | W11: =N11+O11+S11+U11+V11 -> 80.51 | X11: =IF(L11<0,L11*-1,0) -> 0 | Y11: =W11+X11 -> 80.51 | Z11: 0.16 | AA11: 40 | AB11: 9 | AC11: =AC10+1 -> 2
A12: =A11+1 -> 3 | B12: 6899.28 | C12: 280935 | D12: =C12-C11 -> -147 | E12: =C12-152000 -> 128935 | F12: =D12/$D$2 -> -74.111419 | G12: 7.79 | H12: 0 | I12: =G12+H12 -> 7.79 | J12: =IF(L12>0,L12,0) -> 0.018580792 | K12: =I12+J12 -> 7.8085808 | L12: =F12-(I12-W12) -> 0.018580792 | M12: 5.13 | N12: 0 | O12: 0 | P12: =M12-(N12+O12) -> 5.13 | Q12: 0 | R12: 0 | S12: =SUM(P12:R12) -> 5.13 | U12: 0 | V12: 76.79 | W12: =N12+O12+S12+U12+V12 -> 81.92 | X12: =IF(L12<0,L12*-1,0) -> 0 | Y12: =W12+X12 -> 81.92 | Z12: 0 | AA12: 25 | AB12: 16 | AC12: =AC11+1 -> 3
A13: =A12+1 -> 4 | B13: 6899.25 | C13: 280825 | D13: =C13-C12 -> -110 | E13: =C13-152000 -> 128825 | F13: =D13/$D$2 -> -55.457525 | G13: 28.12 | H13: 0 | I13: =G13+H13 -> 28.12 | J13: =IF(L13>0,L13,0) -> 0.012475422 | K13: =I13+J13 -> 28.132475 | L13: =F13-(I13-W13) -> 0.012475422 | M13: 5.13 | N13: 0 | O13: 0 | P13: =M13-(N13+O13) -> 5.13 | Q13: 0 | R13: 0 | S13: =SUM(P13:R13) -> 5.13 | U13: 0 | V13: 78.46 | W13: =N13+O13+S13+U13+V13 -> 83.59 | X13: =IF(L13<0,L13*-1,0) -> 0 | Y13: =W13+X13 -> 83.59 | Z13: 0 | AA13: 23 | AB13: -4 | AC13: =AC12+1 -> 4
A14: =A13+1 -> 5 | B14: 6899.22 | C14: 280715 | D14: =C14-C13 -> -110 | E14: =C14-152000 -> 128715 | F14: =D14/$D$2 -> -55.457525 | G14: 28.12 | H14: 0 | I14: =G14+H14 -> 28.12 | J14: =IF(L14>0,L14,0) -> 0.012475422 | K14: =I14+J14 -> 28.132475 | L14: =F14-(I14-W14) -> 0.012475422 | M14: 5.13 | N14: 0 | O14: 0 | P14: =M14-(N14+O14) -> 5.13 | Q14: 0 | R14: 0 | S14: =SUM(P14:R14) -> 5.13 | U14: 0 | V14: 78.46 | W14: =N14+O14+S14+U14+V14 -> 83.59 | X14: =IF(L14<0,L14*-1,0) -> 0 | Y14: =W14+X14 -> 83.59 | Z14: 0 | AA14: 28 | AB14: -2 | AC14: =AC13+1 -> 5
A15: =A14+1 -> 6 | B15: 6899.18 | C15: 280568 | D15: =C15-C14 -> -147 | E15: =C15-152000 -> 128568 | F15: =D15/$D$2 -> -74.111419 | G15: 9.456 | H15: 0 | I15: =G15+H15 -> 9.456 | J15: =IF(L15>0,L15,0) -> 0.022580792 | K15: =I15+J15 -> 9.4785808 | L15: =F15-(I15-W15) -> 0.022580792 | M15: 5.13 | N15: 0 | O15: 0 | P15: =M15-(N15+O15) -> 5.13 | Q15: 0 | R15: 0 | S15: =SUM(P15:R15) -> 5.13 | U15: 0 | V15: 78.46 | W15: =N15+O15+S15+U15+V15 -> 83.59 | X15: =IF(L15<0,L15*-1,0) -> 0 | Y15: =W15+X15 -> 83.59 | Z15: 0 | AA15: 33 | AB15: 3 | AC15: =AC14+1 -> 6
A16: =A15+1 -> 7 | B16: 6899.14 | C16: 280421 | D16: =C16-C15 -> -147 | E16: =C16-152000 -> 128421 | F16: =D16/$D$2 -> -74.111419 | G16: 9.46 | H16: 0 | I16: =G16+H16 -> 9.46 | J16: =IF(L16>0,L16,0) -> 0.018580792 | K16: =I16+J16 -> 9.4785808 | L16: =F16-(I16-W16) -> 0.018580792 | M16: 5.13 | N16: 0 | O16: 0 | P16: =M16-(N16+O16) -> 5.13 | Q16: 0 | R16: 0 | S16: =SUM(P16:R16) -> 5.13 | U16: 0 | V16: 78.46 | W16: =N16+O16+S16+U16+V16 -> 83.59 | X16: =IF(L16<0,L16*-1,0) -> 0 | Y16: =W16+X16 -> 83.59 | Z16: 0 | AA16: 38 | AB16: 8 | AC16: =AC15+1 -> 7
A17: =A16+1 -> 8 | B17: 6899.1 | C17: 280274 | D17: =C17-C16 -> -147 | E17: =C17-152000 -> 128274 | F17: =D17/$D$2 -> -74.111419 | G17: 9.46 | H17: 0 | I17: =G17+H17 -> 9.46 | J17: =IF(L17>0,L17,0) -> 0.018580792 | K17: =I17+J17 -> 9.4785808 | L17: =F17-(I17-W17) -> 0.018580792 | M17: 5.13 | N17: 0 | O17: 0 | P17: =M17-(N17+O17) -> 5.13 | Q17: 0 | R17: 0 | S17: =SUM(P17:R17) -> 5.13 | U17: 0 | V17: 78.46 | W17: =N17+O17+S17+U17+V17 -> 83.59 | X17: =IF(L17<0,L17*-1,0) -> 0 | Y17: =W17+X17 -> 83.59 | Z17: 0 | AA17: 43 | AB17: 10 | AC17: =AC16+1 -> 8
A18: =A17+1 -> 9 | B18: 6899.07 | C18: 280164 | D18: =C18-C17 -> -110 | E18: =C18-152000 -> 128164 | F18: =D18/$D$2 -> -55.457525 | G18: 28.12 | H18: 0 | I18: 27.61 | J18: =IF(L18>0,L18,0) -> 0.52247542 | K18: =I18+J18 -> 28.132475 | L18: =F18-(I18-W18) -> 0.52247542 | M18: 5.13 | N18: 0 | O18: 0 | P18: =M18-(N18+O18) -> 5.13 | Q18: 0 | R18: 0 | S18: =SUM(P18:R18) -> 5.13 | U18: 0 | V18: 78.46 | W18: =N18+O18+S18+U18+V18 -> 83.59 | X18: =IF(L18<0,L18*-1,0) -> 0 | Y18: =W18+X18 -> 83.59 | Z18: 0 | AA18: 52 | AB18: 15 | AC18: =AC17+1 -> 9
A19: =A18+1 -> 10 | B19: 6899.04 | C19: 280053 | D19: =C19-C18 -> -111 | E19: =C19-152000 -> 128053 | F19: =D19/$D$2 -> -55.961684 | G19: 0 | H19: 0 | I19: 28.15 | J19: =IF(L19>0,L19,0) -> 0 | K19: =I19+J19 -> 28.15 | L19: =F19-(I19-W19) -> -0.52168389 | M19: 5.13 | N19: 0 | O19: 0 | P19: =M19-(N19+O19) -> 5.13 | Q19: 0 | R19: 0 | S19: =SUM(P19:R19) -> 5.13 | U19: 0 | V19: 78.46 | W19: =N19+O19+S19+U19+V19 -> 83.59 | X19: =IF(L19<0,L19*-1,0) -> 0.52168389 | Y19: =W19+X19 -> 84.111684 | Z19: 0 | AA19: 54 | AB19: 20 | AC19: =AC18+1 -> 10
A20: =A19+1 -> 11 | B20: 6899.01 | C20: 279943 | D20: =C20-C19 -> -110 | E20: =C20-152000 -> 127943 | F20: =D20/$D$2 -> -55.457525 | G20: 0 | H20: 0 | I20: 9.99 | J20: =IF(L20>0,L20,0) -> 18.172475 | K20: =I20+J20 -> 28.162475 | L20: =F20-(I20-W20) -> 18.172475 | M20: 5.13 | N20: 0 | O20: 0 | P20: =M20-(N20+O20) -> 5.13 | Q20: 0 | R20: 0 | S20: =SUM(P20:R20) -> 5.13 | U20: 0 | V20: 78.49 | W20: =N20+O20+S20+U20+V20 -> 83.62 | X20: =IF(L20<0,L20*-1,0) -> 0 | Y20: =W20+X20 -> 83.62 | Z20: 0 | AA20: 54 | AB20: 20 | AC20: =AC19+1 -> 11
A21: =A20+1 -> 12 | B21: 6898.97 | C21: 279797 | D21: =C21-C20 -> -146 | E21: =C21-152000 -> 127797 | F21: =D21/$D$2 -> -73.60726 | G21: 0 | H21: 0 | I21: 10.42 | J21: =IF(L21>0,L21,0) -> 0 | K21: =I21+J21 -> 10.42 | L21: =F21-(I21-W21) -> -0.40725989 | M21: 5.13 | N21: 0 | O21: 0 | P21: =M21-(N21+O21) -> 5.13 | Q21: 0 | R21: 0 | S21: =SUM(P21:R21) -> 5.13 | U21: 0 | V21: 78.49 | W21: =N21+O21+S21+U21+V21 -> 83.62 | X21: =IF(L21<0,L21*-1,0) -> 0.40725989 | Y21: =W21+X21 -> 84.02726 | Z21: 0 | AA21: 51 | AB21: 20 | AC21: =AC20+1 -> 12
A22: 13 | B22: 6898.93 | C22: 279651 | D22: =C22-C21 -> -146 | E22: =C22-152000 -> 127651 | F22: =D22/$D$2 -> -73.60726 | G22: 0 | H22: 0 | I22: 10.66 | J22: =IF(L22>0,L22,0) -> 0 | K22: =I22+J22 -> 10.66 | L22: =F22-(I22-W22) -> -0.21725989 | M22: 5.13 | N22: 0 | O22: 0 | P22: =M22-(N22+O22) -> 5.13 | Q22: 0 | R22: 0 | S22: =SUM(P22:R22) -> 5.13 | U22: 0 | V22: 78.92 | W22: =N22+O22+S22+U22+V22 -> 84.05 | X22: =IF(L22<0,L22*-1,0) -> 0.21725989 | Y22: =W22+X22 -> 84.26726 | Z22: 0 | AA22: 47 | AB22: 19 | AC22: =AC21+1 -> 13
A23: =A22+1 -> 14 | B23: 6898.89 | C23: 279505 | D23: =C23-C22 -> -146 | E23: =C23-152000 -> 127505 | F23: =D23/$D$2 -> -73.60726 | G23: 10.7 | H23: 0 | I23: 11.46 | J23: =IF(L23>0,L23,0) -> 0 | K23: =I23+J23 -> 11.46 | L23: =F23-(I23-W23) -> -0.77725989 | M23: 5.13 | N23: 0 | O23: 0 | P23: =M23-(N23+O23) -> 5.13 | Q23: 0 | R23: 0 | S23: =SUM(P23:R23) -> 5.13 | U23: 0 | V23: 79.16 | W23: =N23+O23+S23+U23+V23 -> 84.29 | X23: =IF(L23<0,L23*-1,0) -> 0.77725989 | Y23: =W23+X23 -> 85.06726 | Z23: 0 | AA23: 41 | AB23: 17 | AC23: =AC22+1 -> 14
A24: =A23+1 -> 15 | B24: 6898.85 | C24: 279360 | D24: =C24-C23 -> -145 | E24: =C24-152000 -> 127360 | F24: =D24/$D$2 -> -73.103101 | G24: 11.5 | H24: 0 | I24: 10.52 | J24: =IF(L24>0,L24,0) -> 0.95689942 | K24: =I24+J24 -> 11.476899 | L24: =F24-(I24-W24) -> 0.95689942 | M24: 5.13 | N24: 0 | O24: 0 | P24: =M24-(N24+O24) -> 5.13 | Q24: 0 | R24: 0 | S24: =SUM(P24:R24) -> 5.13 | U24: 0 | V24: 79.45 | W24: =N24+O24+S24+U24+V24 -> 84.58 | X24: =IF(L24<0,L24*-1,0) -> 0 | Y24: =W24+X24 -> 84.58 | Z24: 0.15 | AA24: 33 | AB24: 16 | AC24: =AC23+1 -> 15
A25: =A24+1 -> 16 | B25: 6898.81 | C25: 279214 | D25: =C25-C24 -> -146 | E25: =C25-152000 -> 127214 | F25: =D25/$D$2 -> -73.60726 | G25: 0 | H25: 0 | I25: 10.02 | J25: =IF(L25>0,L25,0) -> 0.52274011 | K25: =I25+J25 -> 10.54274 | L25: =F25-(I25-W25) -> 0.52274011 | M25: 5.13 | N25: 0 | O25: 0 | P25: =M25-(N25+O25) -> 5.13 | Q25: 0 | R25: 0 | S25: =SUM(P25:R25) -> 5.13 | U25: 0 | V25: 79.02 | W25: =N25+O25+S25+U25+V25 -> 84.15 | X25: =IF(L25<0,L25*-1,0) -> 0 | Y25: =W25+X25 -> 84.15 | Z25: 0 | AA25: 35 | AB25: 11 | AC25: =AC24+1 -> 16
A26: =A25+1 -> 17 | B26: 6898.77 | C26: 279068 | D26: =C26-C25 -> -146 | E26: =C26-152000 -> 127068 | F26: =D26/$D$2 -> -73.60726 | G26: 0 | H26: 0 | I26: 28.45 | J26: =IF(L26>0,L26,0) -> 0 | K26: =I26+J26 -> 28.45 | L26: =F26-(I26-W26) -> -18.40726 | M26: 4.92 | N26: 0 | O26: 0 | P26: =M26-(N26+O26) -> 4.92 | Q26: 0 | R26: 0 | S26: =SUM(P26:R26) -> 4.92 | U26: 0 | V26: 78.73 | W26: =N26+O26+S26+U26+V26 -> 83.65 | X26: =IF(L26<0,L26*-1,0) -> 18.40726 | Y26: =W26+X26 -> 102.05726 | Z26: 0 | AA26: 32 | AB26: 11 | AC26: =AC25+1 -> 17
A27: =A26+1 -> 18 | B27: 6898.74 | C27: 278959 | D27: =C27-C26 -> -109 | E27: =C27-152000 -> 126959 | F27: =D27/$D$2 -> -54.953365 | G27: 0 | H27: 0 | I27: 46.42 | J27: =IF(L27>0,L27,0) -> 0 | K27: =I27+J27 -> 46.42 | L27: =F27-(I27-W27) -> -17.953365 | M27: 4.76 | N27: 0 | O27: 0 | P27: =M27-(N27+O27) -> 4.76 | Q27: 0 | R27: 0 | S27: =SUM(P27:R27) -> 4.76 | U27: 0 | V27: 78.66 | W27: =N27+O27+S27+U27+V27 -> 83.42 | X27: =IF(L27<0,L27*-1,0) -> 17.953365 | Y27: =W27+X27 -> 101.37337 | Z27: 0.28 | AA27: 32 | AB27: 10 | AC27: =AC26+1 -> 18
A28: =A27+1 -> 19 | B28: 6898.72 | C28: 278886 | D28: =C28-C27 -> -73 | E28: =C28-152000 -> 126886 | F28: =D28/$D$2 -> -36.80363 | G28: 0 | H28: 0 | I28: 27.75 | J28: =IF(L28>0,L28,0) -> 18.67637 | K28: =I28+J28 -> 46.42637 | L28: =F28-(I28-W28) -> 18.67637 | M28: 4.76 | N28: 0 | O28: 0 | P28: =M28-(N28+O28) -> 4.76 | Q28: 0 | R28: 0 | S28: =SUM(P28:R28) -> 4.76 | U28: 0 | V28: 78.47 | W28: =N28+O28+S28+U28+V28 -> 83.23 | X28: =IF(L28<0,L28*-1,0) -> 0 | Y28: =W28+X28 -> 83.23 | Z28: 0.17 | AA28: 31 | AB28: 19 | AC28: =AC27+1 -> 19
A29: =A28+1 -> 20 | B29: 6898.69 | C29: 278776 | D29: =C29-C28 -> -110 | E29: =C29-152000 -> 126776 | F29: =D29/$D$2 -> -55.457525 | G29: 0 | H29: 0 | I29: 46.41 | J29: =IF(L29>0,L29,0) -> 0 | K29: =I29+J29 -> 46.41 | L29: =F29-(I29-W29) -> -18.647525 | M29: 4.76 | N29: 0 | O29: 0 | P29: =M29-(N29+O29) -> 4.76 | Q29: 0 | R29: 0 | S29: =SUM(P29:R29) -> 4.76 | U29: 0 | V29: 78.46 | W29: =N29+O29+S29+U29+V29 -> 83.22 | X29: =IF(L29<0,L29*-1,0) -> 18.647525 | Y29: =W29+X29 -> 101.86752 | Z29: 0 | AA29: 28 | AB29: 21 | AC29: =AC28+1 -> 20
A30: =A29+1 -> 21 | B30: 6898.67 | C30: 278703 | D30: =C30-C29 -> -73 | E30: =C30-152000 -> 126703 | F30: =D30/$D$2 -> -36.80363 | G30: 0 | H30: 0 | I30: 28.25 | J30: =IF(L30>0,L30,0) -> 18.16637 | K30: =I30+J30 -> 46.41637 | L30: =F30-(I30-W30) -> 18.16637 | M30: 4.76 | N30: 0 | O30: 0 | P30: =M30-(N30+O30) -> 4.76 | Q30: 0 | R30: 0 | S30: =SUM(P30:R30) -> 4.76 | U30: 0 | V30: 78.46 | W30: =N30+O30+S30+U30+V30 -> 83.22 | X30: =IF(L30<0,L30*-1,0) -> 0 | Y30: =W30+X30 -> 83.22 | Z30: 0 | AA30: 34 | AB30: 11 | AC30: =AC29+1 -> 21
A31: =A30+1 -> 22 | B31: 6898.64 | C31: 278594 | D31: =C31-C30 -> -109 | E31: =C31-152000 -> 126594 | F31: =D31/$D$2 -> -54.953365 | G31: 0 | H31: 0 | I31: 9.59 | J31: =IF(L31>0,L31,0) -> 18.676635 | K31: =I31+J31 -> 28.266635 | L31: =F31-(I31-W31) -> 18.676635 | M31: 4.76 | N31: 0 | O31: 0 | P31: =M31-(N31+O31) -> 4.76 | Q31: 0 | R31: 0 | S31: =SUM(P31:R31) -> 4.76 | U31: 0 | V31: 78.46 | W31: =N31+O31+S31+U31+V31 -> 83.22 | X31: =IF(L31<0,L31*-1,0) -> 0 | Y31: =W31+X31 -> 83.22 | Z31: 0 | AA31: 34 | AB31: 16 | AC31: =AC30+1 -> 22
A32: =A31+1 -> 23 | B32: 6898.6 | C32: 278448 | D32: =C32-C31 -> -146 | E32: =C32-152000 -> 126448 | F32: =D32/$D$2 -> -73.60726 | G32: 0 | H32: 0 | I32: 9.61 | J32: =IF(L32>0,L32,0) -> 0.022740106 | K32: =I32+J32 -> 9.6327401 | L32: =F32-(I32-W32) -> 0.022740106 | M32: 4.78 | N32: 0 | O32: 0 | P32: =M32-(N32+O32) -> 4.78 | Q32: 0 | R32: 0 | S32: =SUM(P32:R32) -> 4.78 | U32: 0 | V32: 78.46 | W32: =N32+O32+S32+U32+V32 -> 83.24 | X32: =IF(L32<0,L32*-1,0) -> 0 | Y32: =W32+X32 -> 83.24 | Z32: 0 | AA32: 33 | AB32: 4 | AC32: =AC31+1 -> 23
A33: =A32+1 -> 24 | B33: 6898.56 | C33: 278302 | D33: =C33-C32 -> -146 | E33: =C33-152000 -> 126302 | F33: =D33/$D$2 -> -73.60726 | G33: 0 | H33: 0 | I33: 9.61 | J33: =IF(L33>0,L33,0) -> 0.022740106 | K33: =I33+J33 -> 9.6327401 | L33: =F33-(I33-W33) -> 0.022740106 | M33: 4.78 | N33: 0 | O33: 0 | P33: =M33-(N33+O33) -> 4.78 | Q33: 0 | R33: 0 | S33: =SUM(P33:R33) -> 4.78 | U33: 0 | V33: 78.46 | W33: =N33+O33+S33+U33+V33 -> 83.24 | X33: =IF(L33<0,L33*-1,0) -> 0 | Y33: =W33+X33 -> 83.24 | Z33: 0 | AA33: 30 | AB33: 5 | AC33: =AC32+1 -> 24
A34: =A33+1 -> 25 | B34: 6898.52 | C34: 278156 | D34: =C34-C33 -> -146 | E34: =C34-152000 -> 126156 | F34: =D34/$D$2 -> -73.60726 | G34: 0 | H34: 0 | I34: 10.11 | J34: =IF(L34>0,L34,0) -> 0 | K34: 9.61 | L34: =F34-(I34-W34) -> -0.47725989 | M34: 4.78 | N34: 0 | O34: 0 | P34: =M34-(N34+O34) -> 4.78 | Q34: 0 | R34: 0 | S34: =SUM(P34:R34) -> 4.78 | U34: 0 | V34: 78.46 | W34: =N34+O34+S34+U34+V34 -> 83.24 | X34: =IF(L34<0,L34*-1,0) -> 0.47725989 | Y34: =W34+X34 -> 83.71726 | Z34: 0 | AA34: 28 | AB34: 3 | AC34: =AC33+1 -> 25
A35: =A34+1 -> 26 | B35: 6898.48 | C35: 278011 | D35: =C35-C34 -> -145 | E35: =C35-152000 -> 126011 | F35: =D35/$D$2 -> -73.103101 | G35: 0 | H35: 0 | I35: 27.79 | J35: =IF(L35>0,L35,0) -> 0 | K35: 10.11 | L35: =F35-(I35-W35) -> -17.663101 | M35: 4.77 | N35: 0 | O35: 0 | P35: =M35-(N35+O35) -> 4.77 | Q35: 0 | R35: 0 | S35: =SUM(P35:R35) -> 4.77 | U35: 0 | V35: 78.46 | W35: =N35+O35+S35+U35+V35 -> 83.23 | X35: =IF(L35<0,L35*-1,0) -> 17.663101 | Y35: =W35+X35 -> 100.8931 | Z35: 0 | AA35: 29 | AB35: 4 | AC35: =AC34+1 -> 26
A36: =A35+1 -> 27 | B36: 6898.45 | C36: 277901 | D36: =C36-C35 -> -110 | E36: =C36-152000 -> 125901 | F36: =D36/$D$2 -> -55.457525 | G36: 0 | H36: 0 | I36: 9.68 | J36: =IF(L36>0,L36,0) -> 18.122475 | K36: 27.79 | L36: =F36-(I36-W36) -> 18.122475 | M36: 4.8 | N36: 0 | O36: 0 | P36: =M36-(N36+O36) -> 4.8 | Q36: 0 | R36: 0 | S36: =SUM(P36:R36) -> 4.8 | U36: 0 | V36: 78.46 | W36: =N36+O36+S36+U36+V36 -> 83.26 | X36: =IF(L36<0,L36*-1,0) -> 0 | Y36: =W36+X36 -> 83.26 | Z36: 0 | AA36: 31 | AB36: -1 | AC36: =AC35+1 -> 27
A37: =A36+1 -> 28 | B37: 6898.41 | C37: 277755 | D37: =C37-C36 -> -146 | E37: =C37-152000 -> 125755 | F37: =D37/$D$2 -> -73.60726 | G37: 0 | H37: 0 | I37: 28.25 | J37: =IF(L37>0,L37,0) -> 0 | K37: 9.68 | L37: =F37-(I37-W37) -> -18.54726 | M37: 4.85 | N37: 0 | O37: 0 | P37: =M37-(N37+O37) -> 4.85 | Q37: 0 | R37: 0 | S37: =SUM(P37:R37) -> 4.85 | U37: 0 | V37: 78.46 | W37: =N37+O37+S37+U37+V37 -> 83.31 | X37: =IF(L37<0,L37*-1,0) -> 18.54726 | Y37: =W37+X37 -> 101.85726 | Z37: 0 | AA37: 33 | AB37: 5 | AC37: =AC36+1 -> 28
A38: =A37+1 -> 29 | B38: 6898.38 | C38: 277646 | D38: =C38-C37 -> -109 | E38: =C38-152000 -> 125646 | F38: =D38/$D$2 -> -54.953365 | G38: 0 | H38: 0 | I38: 9.63 | J38: =IF(L38>0,L38,0) -> 18.636635 | K38: 28.25 | L38: =F38-(I38-W38) -> 18.636635 | M38: 4.76 | N38: 0 | O38: 0 | P38: =M38-(N38+O38) -> 4.76 | Q38: 0 | R38: 0 | S38: =SUM(P38:R38) -> 4.76 | U38: 0 | V38: 78.46 | W38: =N38+O38+S38+U38+V38 -> 83.22 | X38: =IF(L38<0,L38*-1,0) -> 0 | Y38: =W38+X38 -> 83.22 | Z38: 0 | AA38: 33 | AB38: 4 | AC38: =AC37+1 -> 29
A39: 30 | B39: 3898.34 | C39: 277500 | D39: =C39-C38 -> -146 | E39: =C39-152000 -> 125500 | F39: =D39/$D$2 -> -73.60726 | G39: 0 | H39: 0 | I39: 46.43 | J39: =IF(L39>0,L39,0) -> 0 | K39: 9.63 | L39: =F39-(I39-W39) -> -36.77726 | M39: 4.8 | N39: 0 | O39: 0 | P39: =M39-(N39+O39) -> 4.8 | Q39: 0 | R39: 0 | S39: =SUM(P39:R39) -> 4.8 | U39: 0 | V39: 78.46 | W39: =N39+O39+S39+U39+V39 -> 83.26 | X39: =IF(L39<0,L39*-1,0) -> 36.77726 | Y39: =W39+X39 -> 120.03726 | Z39: 0 | AA39: 40 | AB39: 7 | AC39: 30
A40: 31 | B40: 6898.32 | C40: 277427 | D40: =C40-C39 -> -73 | E40: =C40-152000 -> 125427 | F40: =D40/$D$2 -> -36.80363 | G40: 0 | H40: 0 | I40: =G40+H40 -> 0 | J40: =IF(L40>0,L40,0) -> 46.43637 | K40: 46.43 | L40: =F40-(I40-W40) -> 46.43637 | M40: 4.78 | N40: 0 | O40: 0 | P40: =M40-(N40+O40) -> 4.78 | Q40: 0 | R40: 0 | S40: =SUM(P40:R40) -> 4.78 | U40: 0 | V40: 78.46 | W40: =N40+O40+S40+U40+V40 -> 83.24 | X40: =IF(L40<0,L40*-1,0) -> 0 | Y40: =W40+X40 -> 83.24 | Z40: 0.1 | AA40: 33 | AB40: 10 | AC40: 31
AA41: 39
A42: MONTH / CFS | F42: =SUM(F10:F40) -> -1990.9251 | G42: =SUM(G10:G40) -> 155.486 | H42: =SUM(H10:H40) -> 0 | I42: =SUM(I10:I40) -> 561.976 | J42: =SUM(J10:J40) -> 159.07536 | K42: =SUM(K10:K40) -> 647.46588 | L42: =SUM(L10:L40) -> 28.678868 | M42: =SUM(M10:M40) -> 153.9 | ... S42: =SUM(S10:S40) -> 153.9 | U42: =SUM(U10:U40) -> 0 | V42: =SUM(V10:V40) -> 2427.68 | W42: =SUM(W10:W40) -> 2581.58 | X42: =SUM(X10:X40) -> 130.39649 | Y42: =SUM(Y10:Y40) -> 2711.9765 | Z42: =SUM(Z10:Z40) -> 0.86 | AA42: =AVERAGE(AA10:AA40) -> 36.16129 | AB42: =AVERAGE(AB10:AB40) -> 10.225806 | AC42: AVE
A43: MONTH / AF | D43: =SUM(D10:D40) -> -3949 | F43: =F42*$D$2 -> -3949 | G43: =G42*$D$2 -> 308.40648 | H43: =H42*$D$2 -> 0 | I43: =I42*$D$2 -> 1114.6794 | J43: =J42*$D$2 -> 315.52598 | K43: =K42*$D$2 -> 1284.2486 | L43: =L42*$D$2 -> 56.884534 | M43: =M42*$D$2 -> 305.26065 | ... S43: =S42*$D$2 -> 305.26065 | U43: =U42*$D$2 -> 0 | V43: =V42*$D$2 -> 4815.3033 | W43: =W42*$D$2 -> 5120.5639 | X43: =X42*$D$2 -> 258.64144 | Y43: =Y42*$D$2 -> 5379.2054 | AA43: =MAX(AA10:AA40) -> 54 | AB43: =MAX(AB10:AB40) -> 21 | AC43: HI
...

Sheet FEB
K1: MC PHEE RESERVOIR IN/OUT FLOW TABULATION
A2: AF/cfs CONVERT FACTOR | D2: 1.9835 | K2: FEBRUARY "1990"
A4: DATE | B4: RESERV | C4: RESERV | D4: AC FT | E4: ACTIVE | F4: CONV TO | G4: DOLORES | H4: LOST | I4: RECORDED | J4: CALC | K4: TOTAL | L4: CALC | M4: TUNNEL | Q4: LONE | R4: U | S4: TOTAL | T4: MVI | U4: DV CR | V4: BELOW | W4: RECORDED | X4: CALC | Y4: TOTAL | Z4: RAIN | AA4: MAX | AB4: MIN | AC4: DATE
A5: FEB | B5: ELEV | C5: AC FT | D5: CHANGE | E5: CAP | F5: CFS | G5: RIVER | H5: CANYON | I5: INFLOW | J5: INFLOW | K5: INFLOW | L5: INF/OTF | M5: TOT DIV | N5: WETLAND | O5: UTE F&R | P5: MVI,CTZ | Q5: PINE | R5: LAT | S5: MVI | T5: CALL | U5: CANAL | V5: MC PHEE | W5: OUTFLOW | X5: OUTFLOW | Y5: OUTFLOW | AA5: TMP | AB5: TMP | AC5: FEB
A7: SEASON BAL
A8: YTD | B8: =JAN!B40 -> 6898.32 | C8: =JAN!C40 -> 277427 | D8: =JAN!$D$49 -> -19058 | E8: =JAN!$E$40 -> 125427 | F8: =JAN!F48 -> -9608.2682 | G8: =JAN!G48 -> 1845.406 | H8: =JAN!H48 -> 0 | I8: =JAN!I48 -> 2251.896 | J8: =JAN!J48 -> 344.17867 | K8: =JAN!K48 -> 2522.4892 | L8: =JAN!L48 -> -1122.0142 | M8: =JAN!M48 -> 926.86 | ... Z8: =JAN!Z48 -> 2.98
A10: 1 | B10: 6898.31 | C10: 277391 | D10: =C10-C8 -> -36 | E10: =C10-152000 -> 125391 | F10: =D10/$D$2 -> -18.149735 | G10: 65.07 | H10: 0 | I10: =G10+H10 -> 65.07 | J10: =IF(L10>0,L10,0) -> 0.00026468364 | K10: =I10+J10 -> 65.070265 | L10: =F10-(I10-W10) -> 0.00026468364 | M10: 4.76 | N10: 0 | O10: 0 | P10: =M10-(N10+O10) -> 4.76 | Q10: 0 | R10: 0 | S10: =SUM(P10:R10) -> 4.76 | U10: 0 | V10: 78.46 | W10: =N10+O10+S10+U10+V10 -> 83.22 | X10: =IF(L10<0,L10*-1,0) -> 0 | Y10: =W10+X10 -> 83.22 | Z10: 0.43 | AA10: 33 | AB10: 15 | AC10: 1
A11: =A10+1 -> 2 | B11: 6898.28 | C11: 277281 | D11: =C11-C10 -> -110 | E11: =C11-152000 -> 125281 | F11: =D11/$D$2 -> -55.457525 | G11: 27.75 | H11: 0 | I11: =G11+H11 -> 27.75 | J11: =IF(L11>0,L11,0) -> 0.012475422 | K11: =I11+J11 -> 27.762475 | L11: =F11-(I11-W11) -> 0.012475422 | M11: 4.76 | N11: 0 | O11: 0 | P11: =M11-(N11+O11) -> 4.76 | Q11: 0 | R11: 0 | S11: =SUM(P11:R11) -> 4.76 | U11: 0 | V11: 78.46 | W11: =N11+O11+S11+U11+V11 -> 83.22 | X11: =IF(L11<0,L11*-1,0) -> 0 | Y11: =W11+X11 -> 83.22 | Z11: 0 | AA11: 35 | AB11: 16 | AC11: =AC10+1 -> 2
A12: =A11+1 -> 3 | B12: 6898.25 | C12: 277172 | D12: =C12-C11 -> -109 | E12: =C12-152000 -> 125172 | F12: =D12/$D$2 -> -54.953365 | G12: 28.25 | H12: 0 | I12: =G12+H12 -> 28.25 | J12: =IF(L12>0,L12,0) -> 0.016634737 | K12: =I12+J12 -> 28.266635 | L12: =F12-(I12-W12) -> 0.016634737 | M12: 4.76 | N12: 0 | O12: 0 | P12: =M12-(N12+O12) -> 4.76 | Q12: 0 | R12: 0 | S12: =SUM(P12:R12) -> 4.76 | U12: 0 | V12: 78.46 | W12: =N12+O12+S12+U12+V12 -> 83.22 | X12: =IF(L12<0,L12*-1,0) -> 0 | Y12: =W12+X12 -> 83.22 | Z12: 0 | AA12: 38 | AB12: 12 | AC12: =AC11+1 -> 3
A13: =A12+1 -> 4 | B13: 6898.21 | C13: 277026 | D13: =C13-C12 -> -146 | E13: =C13-152000 -> 125026 | F13: =D13/$D$2 -> -73.60726 | G13: 9.59 | H13: 0 | I13: =G13+H13 -> 9.59 | J13: =IF(L13>0,L13,0) -> 0.022740106 | K13: =I13+J13 -> 9.6127401 | L13: =F13-(I13-W13) -> 0.022740106 | M13: 4.76 | N13: 0 | O13: 0 | P13: =M13-(N13+O13) -> 4.76 | Q13: 0 | R13: 0 | S13: =SUM(P13:R13) -> 4.76 | U13: 0 | V13: 78.46 | W13: =N13+O13+S13+U13+V13 -> 83.22 | X13: =IF(L13<0,L13*-1,0) -> 0 | Y13: =W13+X13 -> 83.22 | Z13: 0 | AA13: 42 | AB13: 9 | AC13: =AC12+1 -> 4
A14: =A13+1 -> 5 | B14: 6898.17 | C14: 276880 | D14: =C14-C13 -> -146 | E14: =C14-152000 -> 124880 | F14: =D14/$D$2 -> -73.60726 | G14: 9.59 | H14: 0 | I14: =G14+H14 -> 9.59 | J14: =IF(L14>0,L14,0) -> 0.022740106 | K14: =I14+J14 -> 9.6127401 | L14: =F14-(I14-W14) -> 0.022740106 | M14: 4.76 | N14: 0 | O14: 0 | P14: =M14-(N14+O14) -> 4.76 | Q14: 0 | R14: 0 | S14: =SUM(P14:R14) -> 4.76 | U14: 0 | V14: 78.46 | W14: =N14+O14+S14+U14+V14 -> 83.22 | X14: =IF(L14<0,L14*-1,0) -> 0 | Y14: =W14+X14 -> 83.22 | Z14: 0 | AA14: 38 | AB14: 3 | AC14: =AC13+1 -> 5
A15: =A14+1 -> 6 | B15: 6898.14 | C15: 276771 | D15: =C15-C14 -> -109 | E15: =C15-152000 -> 124771 | F15: =D15/$D$2 -> -54.953365 | G15: 28.25 | H15: 0 | I15: =G15+H15 -> 28.25 | J15: =IF(L15>0,L15,0) -> 0.016634737 | K15: =I15+J15 -> 28.266635 | L15: =F15-(I15-W15) -> 0.016634737 | M15: 4.76 | N15: 0 | O15: 0 | P15: =M15-(N15+O15) -> 4.76 | Q15: 0 | R15: 0 | S15: =SUM(P15:R15) -> 4.76 | U15: 0 | V15: 78.46 | W15: =N15+O15+S15+U15+V15 -> 83.22 | X15: =IF(L15<0,L15*-1,0) -> 0 | Y15: =W15+X15 -> 83.22 | Z15: 0 | AA15: 43 | AB15: 6 | AC15: =AC14+1 -> 6
A16: =A15+1 -> 7 | B16: 6898.1 | C16: 276625 | D16: =C16-C15 -> -146 | E16: =C16-152000 -> 124625 | F16: =D16/$D$2 -> -73.60726 | G16: 9.59 | H16: 0 | I16: =G16+H16 -> 9.59 | J16: =IF(L16>0,L16,0) -> 0.022740106 | K16: =I16+J16 -> 9.6127401 | L16: =F16-(I16-W16) -> 0.022740106 | M16: 4.76 | N16: 0 | O16: 0 | P16: =M16-(N16+O16) -> 4.76 | Q16: 0 | R16: 0 | S16: =SUM(P16:R16) -> 4.76 | U16: 0 | V16: 78.46 | W16: =N16+O16+S16+U16+V16 -> 83.22 | X16: =IF(L16<0,L16*-1,0) -> 0 | Y16: =W16+X16 -> 83.22 | Z16: 0 | AA16: 44 | AB16: 7 | AC16: =AC15+1 -> 7
A17: =A16+1 -> 8 | B17: 6898.07 | C17: 276516 | D17: =C17-C16 -> -109 | E17: =C17-152000 -> 124516 | F17: =D17/$D$2 -> -54.953365 | G17: 28.25 | H17: 0 | I17: =G17+H17 -> 28.25 | J17: =IF(L17>0,L17,0) -> 0.016634737 | K17: =I17+J17 -> 28.266635 | L17: =F17-(I17-W17) -> 0.016634737 | M17: 4.76 | N17: 0 | O17: 0 | P17: =M17-(N17+O17) -> 4.76 | Q17: 0 | R17: 0 | S17: =SUM(P17:R17) -> 4.76 | U17: 0 | V17: 78.46 | W17: =N17+O17+S17+U17+V17 -> 83.22 | X17: =IF(L17<0,L17*-1,0) -> 0 | Y17: =W17+X17 -> 83.22 | Z17: 0.17 | AA17: 33 | AB17: 12 | AC17: =AC16+1 -> 8
A18: =A17+1 -> 9 | B18: 6898.03 | C18: 276370 | D18: =C18-C17 -> -146 | E18: =C18-152000 -> 124370 | F18: =D18/$D$2 -> -73.60726 | G18: 9.13 | H18: 0 | I18: =G18+H18 -> 9.13 | J18: =IF(L18>0,L18,0) -> 0.022740106 | K18: =I18+J18 -> 9.1527401 | L18: =F18-(I18-W18) -> 0.022740106 | M18: 4.76 | N18: 0 | O18: 0 | P18: =M18-(N18+O18) -> 4.76 | Q18: 0 | R18: 0 | S18: =SUM(P18:R18) -> 4.76 | U18: 0 | V18: 78 | W18: =N18+O18+S18+U18+V18 -> 82.76 | X18: =IF(L18<0,L18*-1,0) -> 0 | Y18: =W18+X18 -> 82.76 | Z18: 0 | AA18: 36 | AB18: 2 | AC18: =AC17+1 -> 9
A19: =A18+1 -> 10 | B19: 6898 | C19: 276261 | D19: =C19-C18 -> -109 | E19: =C19-152000 -> 124261 | F19: =D19/$D$2 -> -54.953365 | G19: 28.25 | H19: 0 | I19: =G19+H19 -> 28.25 | J19: =IF(L19>0,L19,0) -> 0.016634737 | K19: =I19+J19 -> 28.266635 | L19: =F19-(I19-W19) -> 0.016634737 | M19: 4.76 | N19: 0 | O19: 0 | P19: =M19-(N19+O19) -> 4.76 | Q19: 0 | R19: 0 | S19: =SUM(P19:R19) -> 4.76 | U19: 0 | V19: 78.46 | W19: =N19+O19+S19+U19+V19 -> 83.22 | X19: =IF(L19<0,L19*-1,0) -> 0 | Y19: =W19+X19 -> 83.22 | Z19: 0 | AA19: 41 | AB19: 8 | AC19: =AC18+1 -> 10
A20: =A19+1 -> 11 | B20: 6897.97 | C20: 276152 | D20: =C20-C19 -> -109 | E20: =C20-152000 -> 124152 | F20: =D20/$D$2 -> -54.953365 | G20: 27.79 | H20: 0 | I20: =G20+H20 -> 27.79 | J20: =IF(L20>0,L20,0) -> 0.016634737 | K20: =I20+J20 -> 27.806635 | L20: =F20-(I20-W20) -> 0.016634737 | M20: 4.76 | N20: 0 | O20: 0 | P20: =M20-(N20+O20) -> 4.76 | Q20: 0 | R20: 0 | S20: =SUM(P20:R20) -> 4.76 | U20: 0 | V20: 78 | W20: =N20+O20+S20+U20+V20 -> 82.76 | X20: =IF(L20<0,L20*-1,0) -> 0 | Y20: =W20+X20 -> 82.76 | Z20: 0 | AA20: 48 | AB20: 14 | AC20: =AC19+1 -> 11
A21: =A20+1 -> 12 | B21: 6897.95 | C21: 276080 | D21: =C21-C20 -> -72 | E21: =C21-152000 -> 124080 | F21: =D21/$D$2 -> -36.299471 | G21: 45.85 | H21: 0 | I21: =G21+H21 -> 45.85 | J21: =IF(L21>0,L21,0) -> 0.010529367 | K21: =I21+J21 -> 45.860529 | L21: =F21-(I21-W21) -> 0.010529367 | M21: 4.76 | N21: 0 | O21: 0 | P21: =M21-(N21+O21) -> 4.76 | Q21: 0 | R21: 0 | S21: =SUM(P21:R21) -> 4.76 | U21: 0 | V21: 77.4 | W21: =N21+O21+S21+U21+V21 -> 82.16 | X21: =IF(L21<0,L21*-1,0) -> 0 | Y21: =W21+X21 -> 82.16 | Z21: 0 | AA21: 45 | AB21: 18 | AC21: =AC20+1 -> 12
A22: =A21+1 -> 13 | B22: 6897.92 | C22: 275951 | D22: =C22-C21 -> -129 | E22: =C22-152000 -> 123951 | F22: =D22/$D$2 -> -65.036552 | G22: 17.14 | H22: 0 | I22: =G22+H22 -> 17.14 | J22: =IF(L22>0,L22,0) -> 0.01344845 | K22: =I22+J22 -> 17.153448 | L22: =F22-(I22-W22) -> 0.01344845 | M22: 4.76 | N22: 0 | O22: 0 | P22: =M22-(N22+O22) -> 4.76 | Q22: 0 | R22: 0 | S22: =SUM(P22:R22) -> 4.76 | U22: 0 | V22: 77.43 | W22: =N22+O22+S22+U22+V22 -> 82.19 | X22: =IF(L22<0,L22*-1,0) -> 0 | Y22: =W22+X22 -> 82.19 | Z22: 0 | AA22: 39 | AB22: 21 | AC22: =AC21+1 -> 13
... A36: =A35+1 -> 27 | B36: 6897.54 | C36: 274597 | D36: =C36-C35 -> 0 | E36: =C36-152000 -> 122597 | F36: =D36/$D$2 -> 0 | G36: 117.24 | H36: 0 | I36: =G36+H36 -> 117.24 | J36: =IF(L36>0,L36,0) -> 0 | K36: =I36+J36 -> 117.24 | L36: =F36-(I36-W36) -> 0 | M36: 39.79 | N36: 0 | O36: 0 | P36: =M36-(N36+O36) -> 39.79 | Q36: 0 | R36: 0 | S36: =SUM(P36:R36) -> 39.79 | U36: 0 | V36: 77.45 | W36: =N36+O36+S36+U36+V36 -> 117.24 | X36: =IF(L36<0,L36*-1,0) -> 0 | Y36: =W36+X36 -> 117.24 | Z36: 0.3 | AA36: 47 | AB36: 24 | AC36: =AC35+1 -> 27
A37: 28 | B37: 6897.51 | C37: 274488 | D37: =C37-C36 -> -109 | E37: =C37-152000 -> 122488 | F37: =D37/$D$2 -> -54.953365 | G37: 62.34 | H37: 0 | I37: =G37+H37 -> 62.34 | J37: =IF(L37>0,L37,0) -> 0.016634737 | K37: =I37+J37 -> 62.356635 | L37: =F37-(I37-W37) -> 0.016634737 | M37: 39.91 | N37: 0 | O37: 0 | P37: =M37-(N37+O37) -> 39.91 | Q37: 0 | R37: 0 | S37: =SUM(P37:R37) -> 39.91 | U37: 0 | V37: 77.4 | W37: =N37+O37+S37+U37+V37 -> 117.31 | X37: =IF(L37<0,L37*-1,0) -> 0 | Y37: =W37+X37 -> 117.31 | Z37: 0.16 | AA37: 39 | AB37: 29 | AC37: 28
A39: MONTH / CFS | F39: =SUM(F10:F37) -> -1481.7242 | G39: =SUM(G10:G37) -> 1037.46 | H39: =SUM(H10:H37) -> 0 | I39: =SUM(I10:I37) -> 1037.46 | J39: =SUM(J10:J37) -> 0.3448122 | K39: =SUM(K10:K37) -> 1037.8048 | L39: =SUM(L10:L37) -> -93.194225 | M39: =SUM(M10:M37) -> 247.9 | ... S39: =SUM(S10:S37) -> 247.9 | U39: =SUM(U10:U37) -> 0 | V39: =SUM(V10:V37) -> 2178.09 | W39: =SUM(W10:W37) -> 2425.99 | X39: =SUM(X10:X37) -> 93.539037 | Y39: =SUM(Y10:Y37) -> 2519.529 | Z39: =SUM(Z10:Z37) -> 2.19 | AA39: =AVERAGE(AA10:AA37) -> 40.071429 | AB39: =AVERAGE(AB10:AB37) -> 12.571429 | AC39: AVE
A40: MONTH / AF | D40: =SUM(D10:D37) -> -2939 | F40: =F39*$D$2 -> -2939 | G40: =G39*$D$2 -> 2057.8019 | H40: =H39*$D$2 -> 0 | I40: =I39*$D$2 -> 2057.8019 | J40: =J39*$D$2 -> 0.683935 | K40: =K39*$D$2 -> 2058.4858 | L40: =L39*$D$2 -> -184.85074 | M40: =M39*$D$2 -> 491.70965 | ... S40: =S39*$D$2 -> 491.70965 | U40: =U39*$D$2 -> 0 | V40: =V39*$D$2 -> 4320.2415 | W40: =W39*$D$2 -> 4811.9512 | X40: =X39*$D$2 -> 185.53468 | Y40: =Y39*$D$2 -> 4997.4858 | AA40: =MAX(AA10:AA37) -> 55 | AB40: =MAX(AB10:AB37) -> 29 | AC40: HI
A42: SEASON / CFS | AA42: =MIN(AA10:AA37) -> 26 | AB42: =MIN(AB10:AB37) -> -8 | AC42: LO
A43: SEASON / AF
A45: YTD / CFS | F45: =F8+F39 -> -11089.992 | G45: =G8+G39 -> 2882.866 | H45: =H8+H39 -> 0 | I45: =I8+I39 -> 3289.356 | J45: =J8+J39 -> 344.52349 | K45: =K8+K39 -> 3560.294 | L45: =L8+L39 -> -1215.2084 | M45: =M8+M39 -> 1174.76 | ... S45: =S8+S39 -> 3839.22 | U45: =U8+U39 -> 0 | V45: =V8+V39 -> 9324.92 | W45: =W8+W39 -> 13164.14 | X45: =X8+X39 -> 1559.7319 | Y45: =Y8+Y39 -> 14723.872 | Z45: =Z8+Z39 -> 5.17
A46: YTD / AF | D46: =D8+D40 -> -21997 | E46: =E37 -> 122488 | F46: =F45*$D$2 -> -21997 | G46: =G45*$D$2 -> 5718.1647 | H46: =H45*$D$2 -> 0 | I46: =I45*$D$2 -> 6524.4376 | J46: =J45*$D$2 -> 683.36233 | K46: =K45*$D$2 -> 7061.8432 | L46: =L45*$D$2 -> -2410.3659 | M46: =M45*$D$2 -> 2330.1365 | ... Y46: =Y45*$D$2 -> 29204.8

Sheet MAR
K1: MC PHEE RESERVOIR IN/OUT FLOW TABULATION
A2: AF/cfs CONVERT FACTOR | D2: 1.9835 | K2: MARCH "1990"
A4: DATE | B4: RESERV | C4: RESERV | D4: AC FT | E4: ACTIVE | F4: CONV TO | G4: DOLORES | H4: LOST | I4: RECORDED | J4: CALC | K4: TOTAL | L4: CALC | M4: TUNNEL | Q4: LONE | R4: U | S4: TOTAL | T4: MVI | U4: DV CR | V4: BELOW | W4: RECORDED | X4: CALC | Y4: TOTAL | Z4: RAIN | AA4: MAX | AB4: MIN | AC4: DATE
A5: MAR | B5: ELEV | C5: AC FT | D5: CHANGE | E5: CAP | F5: CFS | G5: RIVER | H5: CANYON | I5: INFLOW | J5: INFLOW | K5: INFLOW | L5: INF/OTF | M5: TOT DIV | N5: WETLAND | O5: UTE F&R | P5: MVI,CTZ | Q5: PINE | R5: LAT | S5: MVI | T5: CALL | U5: CANAL | V5: MC PHEE | W5: OUTFLOW | X5: OUTFLOW | Y5: OUTFLOW | AA5: TMP | AB5: TMP | AC5: MAR
A7: SEASON BAL
A8: YTD | B8: =FEB!B37 -> 6897.51 | C8: =FEB!C37 -> 274488 | D8: =FEB!$D$46 -> -21997 | E8: =FEB!$E$37 -> 122488 | F8: =FEB!F45 -> -11089.992 | G8: =FEB!G45 -> 2882.866 | H8: =FEB!H45 -> 0 | I8: =FEB!I45 -> 3289.356 | J8: =FEB!J45 -> 344.52349 | K8: =FEB!K45 -> 3560.294 | L8: =FEB!L45 -> -1215.2084 | M8: =FEB!M45 -> 1174.76 | ... Z8: =FEB!Z45 -> 5.17
A10: 1 | B10: 6897.45 | C10: 274271 | D10: =C10-C8 -> -217 | E10: =C10-152000 -> 122271 | F10: =D10/$D$2 -> -109.40257 | G10: 7.57 | H10: 0 | I10: =G10+H10 -> 7.57 | J10: =IF(L10>0,L10,0) -> 0.027428787 | K10: =I10+J10 -> 7.5974288 | L10: =F10-(I10-W10) -> 0.027428787 | M10: 39.6 | N10: 0 | O10: 0 | P10: =M10-(N10+O10) -> 39.6 | Q10: 0 | R10: 0 | S10: =SUM(P10:R10) -> 39.6 | U10: 0 | V10: 77.4 | W10: =N10+O10+S10+U10+V10 -> 117 | X10: =IF(L10<0,L10*-1,0) -> 0 | Y10: =W10+X10 -> 117 | Z10: 0.05 | AA10: 44 | AB10: 22 | AC10: 1
A11: =A10+1 -> 2 | B11: 6897.42 | C11: 274163 | D11: =C11-C10 -> -108 | E11: =C11-152000 -> 122163 | F11: =D11/$D$2 -> -54.449206 | G11: 50.39 | H11: 0 | I11: =G11+H11 -> 50.39 | J11: =IF(L11>0,L11,0) -> 0.010794051 | K11: =I11+J11 -> 50.400794 | L11: =F11-(I11-W11) -> 0.010794051 | M11: 39.64 | N11: 0 | O11: 0 | P11: =M11-(N11+O11) -> 39.64 | Q11: 0 | R11: 0 | S11: =SUM(P11:R11) -> 39.64 | U11: 0 | V11: 65.21 | W11: =N11+O11+S11+U11+V11 -> 104.85 | X11: =IF(L11<0,L11*-1,0) -> 0 | Y11: =W11+X11 -> 104.85 | Z11: 0 | AA11: 43 | AB11: 23 | AC11: =AC10+1 -> 2
A12: =A11+1 -> 3 | B12: 6897.4 | C12: 274090 | D12: =C12-C11 -> -73 | E12: =C12-152000 -> 122090 | F12: =D12/$D$2 -> -36.80363 | G12: 25.88 | H12: 0 | I12: =G12+H12 -> 25.88 | J12: =IF(L12>0,L12,0) -> 0.0063700529 | K12: =I12+J12 -> 25.88637 | L12: =F12-(I12-W12) -> 0.0063700529 | M12: 19.88 | N12: 0 | O12: 0 | P12: =M12-(N12+O12) -> 19.88 | Q12: 0 | R12: 0 | S12: =SUM(P12:R12) -> 19.88 | U12: 0 | V12: 42.81 | W12: =N12+O12+S12+U12+V12 -> 62.69 | X12: =IF(L12<0,L12*-1,0) -> 0 | Y12: =W12+X12 -> 62.69 | Z12: 0 | AA12: 44 | AB12: 22 | AC12: =AC11+1 -> 3
A13: =A12+1 -> 4 | B13: 6897.43 | C13: 274199 | D13: =C13-C12 -> 109 | E13: =C13-152000 -> 122199 | F13: =D13/$D$2 -> 54.953365 | G13: 96.2 | H13: 0 | I13: =G13+H13 -> 96.2 | J13: =IF(L13>0,L13,0) -> 0 | K13: =I13+J13 -> 96.2 | L13: =F13-(I13-W13) -> -0.016634737 | M13: 5.13 | N13: 0 | O13: 0 | P13: =M13-(N13+O13) -> 5.13 | Q13: 0 | R13: 0 | S13: =SUM(P13:R13) -> 5.13 | U13: 0 | V13: 36.1 | W13: =N13+O13+S13+U13+V13 -> 41.23 | X13: =IF(L13<0,L13*-1,0) -> 0.016634737 | Y13: =W13+X13 -> 41.246635 | Z13: 0 | AA13: 45 | AB13: 21 | AC13: =AC12+1 -> 4
A14: =A13+1 -> 5 | B14: 6897.5 | C14: 274452 | D14: =C14-C13 -> 253 | E14: =C14-152000 -> 122452 | F14: =D14/$D$2 -> 127.55231 | G14: 157.22 | H14: 0 | I14: =G14+H14 -> 157.22 | J14: =IF(L14>0,L14,0) -> 0 | K14: =I14+J14 -> 157.22 | L14: =F14-(I14-W14) -> -0.027693471 | M14: 4.88 | N14: 0 | O14: 0 | P14: =M14-(N14+O14) -> 4.88 | Q14: 0 | R14: 0 | S14: =SUM(P14:R14) -> 4.88 | U14: 0 | V14: 24.76 | W14: =N14+O14+S14+U14+V14 -> 29.64 | X14: =IF(L14<0,L14*-1,0) -> 0.027693471 | Y14: =W14+X14 -> 29.667693 | Z14: 0.22 | AA14: 43 | AB14: 23 | AC14: =AC13+1 -> 5
A15: =A14+1 -> 6 | B15: 6897.51 | C15: 274488 | D15: =C15-C14 -> 36 | E15: =C15-152000 -> 122488 | F15: =D15/$D$2 -> 18.149735 | G15: 42.07 | H15: 0 | I15: =G15+H15 -> 42.07 | J15: =IF(L15>0,L15,0) -> 0 | K15: =I15+J15 -> 42.07 | L15: =F15-(I15-W15) -> -0.00026468364 | M15: 4.76 | N15: 0 | O15: 0 | P15: =M15-(N15+O15) -> 4.76 | Q15: 0 | R15: 0 | S15: =SUM(P15:R15) -> 4.76 | U15: 0 | V15: 19.16 | W15: =N15+O15+S15+U15+V15 -> 23.92 | X15: =IF(L15<0,L15*-1,0) -> 0.00026468364 | Y15: =W15+X15 -> 23.920265 | Z15: 0.16 | AA15: 39 | AB15: 22 | AC15: =AC14+1 -> 6
A16: =A15+1 -> 7 | B16: 6897.51 | C16: 274488 | D16: =C16-C15 -> 0 | E16: =C16-152000 -> 122488 | F16: =D16/$D$2 -> 0 | G16: 25.06 | H16: 0 | I16: =G16+H16 -> 25.06 | J16: =IF(L16>0,L16,0) -> 0 | K16: =I16+J16 -> 25.06 | L16: =F16-(I16-W16) -> 0 | M16: 4.76 | N16: 0 | O16: 0 | P16: =M16-(N16+O16) -> 4.76 | Q16: 0 | R16: 0 | S16: =SUM(P16:R16) -> 4.76 | U16: 0 | V16: 20.3 | W16: =N16+O16+S16+U16+V16 -> 25.06 | X16: =IF(L16<0,L16*-1,0) -> 0 | Y16: =W16+X16 -> 25.06 | Z16: 0 | AA16: 41 | AB16: 19 | AC16: =AC15+1 -> 7
A17: =A16+1 -> 8 | B17: 6897.53 | C17: 274560 | D17: =C17-C16 -> 72 | E17: =C17-152000 -> 122560 | F17: =D17/$D$2 -> 36.299471 | G17: 61.37 | H17: 0 | I17: =G17+H17 -> 61.37 | J17: =IF(L17>0,L17,0) -> 0 | K17: =I17+J17 -> 61.37 | L17: =F17-(I17-W17) -> -0.010529367 | M17: 4.76 | N17: 0 | O17: 0 | P17: =M17-(N17+O17) -> 4.76 | Q17: 0 | R17: 0 | S17: =SUM(P17:R17) -> 4.76 | U17: 0 | V17: 20.3 | W17: =N17+O17+S17+U17+V17 -> 25.06 | X17: =IF(L17<0,L17*-1,0) -> 0.010529367 | Y17: =W17+X17 -> 25.070529 | Z17: 0 | AA17: 53 | AB17: 23 | AC17: =AC16+1 -> 8
A18: =A17+1 -> 9 | B18: 6897.55 | C18: 274633 | D18: =C18-C17 -> 73 | E18: =C18-152000 -> 122633 | F18: =D18/$D$2 -> 36.80363 | G18: 61.87 | H18: 0 | I18: =G18+H18 -> 61.87 | J18: =IF(L18>0,L18,0) -> 0 | K18: =I18+J18 -> 61.87 | L18: =F18-(I18-W18) -> -0.0063700529 | M18: 4.76 | N18: 0 | O18: 0 | P18: =M18-(N18+O18) -> 4.76 | Q18: 0 | R18: 0 | S18: =SUM(P18:R18) -> 4.76 | U18: 0 | V18: 20.3 | W18: =N18+O18+S18+U18+V18 -> 25.06 | X18: =IF(L18<0,L18*-1,0) -> 0.0063700529 | Y18: =W18+X18 -> 25.06637 | Z18: 0 | AA18: 54 | AB18: 24 | AC18: =AC17+1 -> 9
A19: =A18+1 -> 10 | B19: 6897.57 | C19: 274705 | D19: =C19-C18 -> 72 | E19: =C19-152000 -> 122705 | F19: =D19/$D$2 -> 36.299471 | G19: 61.43 | H19: 0 | I19: =G19+H19 -> 61.43 | J19: =IF(L19>0,L19,0) -> 0 | K19: =I19+J19 -> 61.43 | L19: =F19-(I19-W19) -> -0.010529367 | M19: 4.76 | N19: 0 | O19: 0 | P19: =M19-(N19+O19) -> 4.76 | Q19: 0 | R19: 0 | S19: =SUM(P19:R19) -> 4.76 | U19: 0 | V19: 20.36 | W19: =N19+O19+S19+U19+V19 -> 25.12 | X19: =IF(L19<0,L19*-1,0) -> 0.010529367 | Y19: =W19+X19 -> 25.130529 | Z19: 0.2 | AA19: 49 | AB19: 20 | AC19: =AC18+1 -> 10
