Workbook

Sheet NOV
K1: MC PHEE RESERVOIR IN/OUT FLOW TABULATION
A2: AF/cfs CONVERT FACTOR | D2: 1.9835 | L2: NOVEMBER "99"
A4: DATE | B4: RESERV | C4: RESERV | D4: AC FT | E4: ACTIVE | F4: CONV TO | G4: DOLORES | H4: LOST | I4: RECORDED | J4: CALC | K4: TOTAL | L4: CALC | M4: DOLORES TUNNEL | Q4: LONE | R4: U | S4: TOTAL | T4: MVI | U4: DV CR | V4: BELOW | W4: REMAIN | X4: RECORDED | Y4: CALC | Z4: TOTAL | AA4: RAIN | AB4: MAX | AC4: MIN | AD4: DATE
A5: "NOV" | B5: ELEV | C5: AC FT | D5: CHANGE | E5: CAP | F5: CFS | G5: RIVER | H5: CANYON | I5: INFLOW | J5: INFLOW | K5: INFLOW | L5: INF/OTF | M5: TOT DIV | N5: WETLAND | O5: UTE F&R | P5: MVI,CTZ | Q5: PINE | R5: LAT | S5: MVI | T5: CALL | U5: CANAL | V5: MC PHEE | W5: RELEASE | X5: OUTFLOW | Y5: OUTFLOW | Z5: OUTFLOW | AB5: TMP | AC5: TMP | AD5: "NOV"
A7: SEASON BAL
A8: YTD | B8: 6911.91 | C8: 329680 | W8: 6452
A10: 1 | B10: 6911.81 | C10: 329276 | D10: =C10-C8 -> -404 | E10: =C10-152000 -> 177276 | F10: =D10/$D$2 -> -203.68036 | G10: 73 | H10: 1 | I10: =G10+H10 -> 74 | J10: =IF(L10>0,L10,0) -> 0 | K10: =I10+J10 -> 74 | L10: =F10-(I10-X10) -> -31.680363 | M10: 128 | O10: =23.85+24.66*1.05 -> 49.743 | P10: =M10-(N10+O10) -> 78.257 | Q10: 0 | R10: 33 | S10: =SUM(P10:R10) -> 111.257 | U10: 0 | V10: 85 | W10: =(W7+W8)-45-2 -> 6405 | X10: =N10+O10+S10+U10+V10 -> 246 | Y10: =IF(L10<0,L10*-1,0) -> 31.680363 | Z10: =X10+Y10 -> 277.68036 | AA10: 0 | AB10: 72 | AC10: 34 | AD10: 1
A11: =A10+1 -> 2 | B11: 6911.7 | C11: 328831 | D11: =C11-C10 -> -445 | E11: =C11-152000 -> 176831 | F11: =D11/$D$2 -> -224.35089 | G11: 70 | H11: 0.93 | I11: =G11+H11 -> 70.93 | J11: =IF(L11>0,L11,0) -> 0 | K11: =I11+J11 -> 70.93 | L11: =F11-(I11-X11) -> -25.280895 | M11: 154 | O11: =37.71+39.18*1.05 -> 78.849 | P11: =M11-(N11+O11) -> 75.151 | Q11: 0 | R11: 31 | S11: =SUM(P11:R11) -> 106.151 | U11: 0 | V11: 85 | W11: =W10-45-2 -> 6358 | X11: =N11+O11+S11+U11+V11 -> 270 | Y11: =IF(L11<0,L11*-1,0) -> 25.280895 | Z11: =X11+Y11 -> 295.28089 | AA11: 0 | AB11: 76 | AC11: 30 | AD11: =AD10+1 -> 2
A12: =A11+1 -> 3 | B12: 6911.59 | C12: 328386 | D12: =C12-C11 -> -445 | E12: =C12-152000 -> 176386 | F12: =D12/$D$2 -> -224.35089 | G12: 62 | H12: 1.2 | I12: =G12+H12 -> 63.2 | J12: =IF(L12>0,L12,0) -> 0 | K12: =I12+J12 -> 63.2 | L12: =F12-(I12-X12) -> -20.550895 | M12: 151 | O12: =37.95+39.43*1.05 -> 79.3515 | P12: =M12-(N12+O12) -> 71.6485 | Q12: 0 | R12: 31 | S12: =SUM(P12:R12) -> 102.6485 | U12: 0 | V12: 85 | W12: =W11-45-2 -> 6311 | X12: =N12+O12+S12+U12+V12 -> 267 | Y12: =IF(L12<0,L12*-1,0) -> 20.550895 | Z12: =X12+Y12 -> 287.55089 | AA12: 0 | AB12: 64 | AC12: 28 | AD12: =AD11+1 -> 3
A13: =A12+1 -> 4 | B13: 6911.5 | C13: 328022 | D13: =C13-C12 -> -364 | E13: =C13-152000 -> 176022 | F13: =D13/$D$2 -> -183.51399 | G13: 61 | H13: 1.1 | I13: =G13+H13 -> 62.1 | J13: =IF(L13>0,L13,0) -> 10.38601 | K13: =I13+J13 -> 72.48601 | L13: =F13-(I13-X13) -> 10.38601 | M13: 140 | O13: =33.88+36.42*1.05 -> 72.121 | P13: =M13-(N13+O13) -> 67.879 | Q13: 0 | R13: 31 | S13: =SUM(P13:R13) -> 98.879 | U13: 0 | V13: 85 | W13: =W12-45-2 -> 6264 | X13: =N13+O13+S13+U13+V13 -> 256 | Y13: =IF(L13<0,L13*-1,0) -> 0 | Z13: =X13+Y13 -> 256 | AA13: 0 | AB13: 69 | AC13: 32 | AD13: =AD12+1 -> 4
A14: =A13+1 -> 5 | B14: 6911.43 | C14: 327739 | D14: =C14-C13 -> -283 | E14: =C14-152000 -> 175739 | F14: =D14/$D$2 -> -142.67709 | G14: 63 | H14: 0.94 | I14: =G14+H14 -> 63.94 | J14: =IF(L14>0,L14,0) -> 0 | K14: =I14+J14 -> 63.94 | L14: =F14-(I14-X14) -> -0.61708596 | M14: 90 | O14: =15.55+17.16*1.05 -> 33.568 | P14: =M14-(N14+O14) -> 56.432 | Q14: 0 | R14: 31 | S14: =SUM(P14:R14) -> 87.432 | U14: 0 | V14: 85 | W14: =W13-45-2 -> 6217 | X14: =N14+O14+S14+U14+V14 -> 206 | Y14: =IF(L14<0,L14*-1,0) -> 0.61708596 | Z14: =X14+Y14 -> 206.61709 | AA14: 0 | AB14: 68 | AC14: 30 | AD14: =AD13+1 -> 5
A15: =A14+1 -> 6 | B15: 6911.38 | C15: 327536 | D15: =C15-C14 -> -203 | E15: =C15-152000 -> 175536 | F15: =D15/$D$2 -> -102.34434 | G15: 62 | H15: 0.94 | I15: =G15+H15 -> 62.94 | J15: =IF(L15>0,L15,0) -> 21.715659 | K15: =I15+J15 -> 84.655659 | L15: =F15-(I15-X15) -> 21.715659 | M15: 71 | O15: =2.83+3.07*1.05 -> 6.0535 | P15: =M15-(N15+O15) -> 64.9465 | Q15: 0 | R15: 31 | S15: =SUM(P15:R15) -> 95.9465 | U15: 0 | V15: 85 | W15: =W14-45-2 -> 6170 | X15: =N15+O15+S15+U15+V15 -> 187 | Y15: =IF(L15<0,L15*-1,0) -> 0 | Z15: =X15+Y15 -> 187 | AA15: 0 | AB15: 74 | AC15: 36 | AD15: =AD14+1 -> 6
A16: =A15+1 -> 7 | B16: 6911.32 | C16: 327294 | D16: =C16-C15 -> -242 | E16: =C16-152000 -> 175294 | F16: =D16/$D$2 -> -122.00655 | G16: 62 | H16: 1 | I16: =G16+H16 -> 63 | J16: =IF(L16>0,L16,0) -> 1.9934459 | K16: =I16+J16 -> 64.993446 | L16: =F16-(I16-X16) -> 1.9934459 | M16: 72 | O16: =2.67+3.07*1.05 -> 5.8935 | P16: =M16-(N16+O16) -> 66.1065 | Q16: 0 | R16: 30 | S16: =SUM(P16:R16) -> 96.1065 | U16: 0 | V16: 85 | W16: =W15-45-2 -> 6123 | X16: =N16+O16+S16+U16+V16 -> 187 | Y16: =IF(L16<0,L16*-1,0) -> 0 | Z16: =X16+Y16 -> 187 | AA16: 0 | AB16: 71 | AC16: 38 | AD16: =AD15+1 -> 7
A17: =A16+1 -> 8 | B17: 6911.26 | C17: 327051 | D17: =C17-C16 -> -243 | E17: =C17-152000 -> 175051 | F17: =D17/$D$2 -> -122.51071 | G17: 67 | H17: 1.1 | I17: =G17+H17 -> 68.1 | J17: =IF(L17>0,L17,0) -> 0 | K17: =I17+J17 -> 68.1 | L17: =F17-(I17-X17) -> -0.61071339 | M17: 74 | O17: =13.1+13.1*1.05 -> 26.855 | P17: =M17-(N17+O17) -> 47.145 | Q17: 0 | R17: 30 | S17: =SUM(P17:R17) -> 77.145 | U17: 0 | V17: 86 | W17: =W16-45-2 -> 6076 | X17: =N17+O17+S17+U17+V17 -> 190 | Y17: =IF(L17<0,L17*-1,0) -> 0.61071339 | Z17: =X17+Y17 -> 190.61071 | AA17: 0 | AB17: 66 | AC17: 44 | AD17: =AD16+1 -> 8
A18: =A17+1 -> 9 | B18: 6911.19 | C18: 326768 | D18: =C18-C17 -> -283 | E18: =C18-152000 -> 174768 | F18: =D18/$D$2 -> -142.67709 | G18: 67 | H18: 1.2 | I18: =G18+H18 -> 68.2 | J18: =IF(L18>0,L18,0) -> 12.122914 | K18: =I18+J18 -> 80.322914 | L18: =F18-(I18-X18) -> 12.122914 | M18: 106 | O18: =17.85+16.93*1.05 -> 35.6265 | P18: =M18-(N18+O18) -> 70.3735 | Q18: 0 | R18: 30 | S18: =SUM(P18:R18) -> 100.3735 | U18: 0 | V18: 87 | W18: =W17-45-2 -> 6029 | X18: =N18+O18+S18+U18+V18 -> 223 | Y18: =IF(L18<0,L18*-1,0) -> 0 | Z18: =X18+Y18 -> 223 | AA18: 0 | AB18: 62 | AC18: 28 | AD18: =AD17+1 -> 9
A19: =A18+1 -> 10 | B19: 6911.14 | C19: 326566 | D19: =C19-C18 -> -202 | E19: =C19-152000 -> 174566 | F19: =D19/$D$2 -> -101.84018 | G19: 60 | H19: 1.2 | I19: =G19+H19 -> 61.2 | J19: =IF(L19>0,L19,0) -> 13.959819 | K19: =I19+J19 -> 75.159819 | L19: =F19-(I19-X19) -> 13.959819 | M19: 60 | O19: =15.16+16*1.05 -> 31.96 | P19: =M19-(N19+O19) -> 28.04 | Q19: 0 | R19: 30 | S19: =SUM(P19:R19) -> 58.04 | U19: 0 | V19: 87 | W19: =W18-45-2 -> 5982 | X19: =N19+O19+S19+U19+V19 -> 177 | Y19: =IF(L19<0,L19*-1,0) -> 0 | Z19: =X19+Y19 -> 177 | AA19: 0 | AB19: 66 | AC19: 30 | AD19: =AD18+1 -> 10
A20: =A19+1 -> 11 | B20: 6911.09 | C20: 326363 | D20: =C20-C19 -> -203 | E20: =C20-152000 -> 174363 | F20: =D20/$D$2 -> -102.34434 | G20: 58 | H20: 1.1 | I20: =G20+H20 -> 59.1 | J20: =IF(L20>0,L20,0) -> 0 | K20: =I20+J20 -> 59.1 | L20: =F20-(I20-X20) -> -4.4443408 | M20: 42 | O20: =10.41+10.39*1.05 -> 21.3195 | P20: =M20-(N20+O20) -> 20.6805 | Q20: 0 | R20: 28 | S20: =SUM(P20:R20) -> 48.6805 | U20: 0 | V20: 87 | W20: =W19-45-2 -> 5935 | X20: =N20+O20+S20+U20+V20 -> 157 | Y20: =IF(L20<0,L20*-1,0) -> 4.4443408 | Z20: =X20+Y20 -> 161.44434 | AA20: 0 | AB20: 71 | AC20: 33 | AD20: =AD19+1 -> 11
A21: =A20+1 -> 12 | B21: 6911.04 | C21: 326161 | D21: =C21-C20 -> -202 | E21: =C21-152000 -> 174161 | F21: =D21/$D$2 -> -101.84018 | G21: 54 | H21: 0.97 | I21: =G21+H21 -> 54.97 | J21: =IF(L21>0,L21,0) -> 0 | K21: =I21+J21 -> 54.97 | L21: =F21-(I21-X21) -> -5.8101815 | M21: 38 | O21: 0 | P21: =M21-(N21+O21) -> 38 | Q21: 0 | R21: 26 | S21: =SUM(P21:R21) -> 64 | U21: 0 | V21: 87 | W21: =W20-45-2 -> 5888 | X21: =N21+O21+S21+U21+V21 -> 151 | Y21: =IF(L21<0,L21*-1,0) -> 5.8101815 | Z21: =X21+Y21 -> 156.81018 | AA21: 0 | AB21: 72 | AC21: 33 | AD21: =AD20+1 -> 12
A22: =A21+1 -> 13 | B22: 6910.99 | C22: 325959 | D22: =C22-C21 -> -202 | E22: =C22-152000 -> 173959 | F22: =D22/$D$2 -> -101.84018 | G22: 53 | H22: 0.9 | I22: =G22+H22 -> 53.9 | J22: =IF(L22>0,L22,0) -> 0 | K22: =I22+J22 -> 53.9 | L22: =F22-(I22-X22) -> -6.7401815 | M22: 37 | O22: 0 | P22: =M22-(N22+O22) -> 37 | Q22: 0 | R22: 25 | S22: =SUM(P22:R22) -> 62 | U22: 0 | V22: 87 | W22: =W21-45-2 -> 5841 | X22: =N22+O22+S22+U22+V22 -> 149 | Y22: =IF(L22<0,L22*-1,0) -> 6.7401815 | Z22: =X22+Y22 -> 155.74018 | AA22: 0 | AB22: 72 | AC22: 32 | AD22: =AD21+1 -> 13
A23: =A22+1 -> 14 | B23: 6910.94 | C23: 325759 | D23: =C23-C22 -> -200 | E23: =C23-152000 -> 173759 | F23: =D23/$D$2 -> -100.83186 | G23: 53 | H23: 0.84 | I23: =G23+H23 -> 53.84 | J23: =IF(L23>0,L23,0) -> 0 | K23: =I23+J23 -> 53.84 | L23: =F23-(I23-X23) -> -5.6718629 | M23: 37 | O23: 0 | P23: =M23-(N23+O23) -> 37 | Q23: 0 | R23: 25 | S23: =SUM(P23:R23) -> 62 | U23: 0 | V23: 87 | W23: =W22-45-2 -> 5794 | X23: =N23+O23+S23+U23+V23 -> 149 | Y23: =IF(L23<0,L23*-1,0) -> 5.6718629 | Z23: =X23+Y23 -> 154.67186 | AA23: 0 | AB23: 72 | AC23: 33 | AD23: =AD22+1 -> 14
A24: =A23+1 -> 15 | B24: 6910.89 | C24: 325558 | D24: =C24-C23 -> -201 | E24: =C24-152000 -> 173558 | F24: =D24/$D$2 -> -101.33602 | G24: 57 | H24: 0.89 | I24: =G24+H24 -> 57.89 | J24: =IF(L24>0,L24,0) -> 0 | K24: =I24+J24 -> 57.89 | L24: =F24-(I24-X24) -> -18.226022 | M24: 37 | O24: 0 | P24: =M24-(N24+O24) -> 37 | Q24: 0 | R24: 24 | S24: =SUM(P24:R24) -> 61 | U24: 0 | V24: 80 | W24: =W23-45-2 -> 5747 | X24: =N24+O24+S24+U24+V24 -> 141 | Y24: =IF(L24<0,L24*-1,0) -> 18.226022 | Z24: =X24+Y24 -> 159.22602 | AA24: 0 | AB24: 72 | AC24: 31 | AD24: =AD23+1 -> 15
A25: =A24+1 -> 16 | B25: 6910.84 | C25: 325357 | D25: =C25-C24 -> -201 | E25: =C25-152000 -> 173357 | F25: =D25/$D$2 -> -101.33602 | G25: 53 | H25: 0.84 | I25: =G25+H25 -> 53.84 | J25: =IF(L25>0,L25,0) -> 0 | K25: =I25+J25 -> 53.84 | L25: =F25-(I25-X25) -> -17.176022 | M25: 39 | O25: 0 | P25: =M25-(N25+O25) -> 39 | Q25: 0 | R25: 24 | S25: =SUM(P25:R25) -> 63 | U25: 0 | V25: 75 | W25: =W24-45-2 -> 5700 | X25: =N25+O25+S25+U25+V25 -> 138 | Y25: =IF(L25<0,L25*-1,0) -> 17.176022 | Z25: =X25+Y25 -> 155.17602 | AA25: 0 | AB25: 69 | AC25: 34 | AD25: =AD24+1 -> 16
A26: =A25+1 -> 17 | B26: 6910.8 | C26: 325197 | D26: =C26-C25 -> -160 | E26: =C26-152000 -> 173197 | F26: =D26/$D$2 -> -80.66549 | G26: 53 | H26: 0.88 | I26: =G26+H26 -> 53.88 | J26: =IF(L26>0,L26,0) -> 0 | K26: =I26+J26 -> 53.88 | L26: =F26-(I26-X26) -> -11.54549 | M26: 37 | O26: 0 | P26: =M26-(N26+O26) -> 37 | Q26: 0 | R26: 22 | S26: =SUM(P26:R26) -> 59 | U26: 0 | V26: 64 | W26: =W25-45-2 -> 5653 | X26: =N26+O26+S26+U26+V26 -> 123 | Y26: =IF(L26<0,L26*-1,0) -> 11.54549 | Z26: =X26+Y26 -> 134.54549 | AA26: 0 | AB26: 66 | AC26: 36 | AD26: =AD25+1 -> 17
A27: =A26+1 -> 18 | B27: 6910.78 | C27: 325117 | D27: =C27-C26 -> -80 | E27: =C27-152000 -> 173117 | F27: =D27/$D$2 -> -40.332745 | G27: 51 | H27: 0.97 | I27: =G27+H27 -> 51.97 | J27: =IF(L27>0,L27,0) -> 20.697255 | K27: =I27+J27 -> 72.667255 | L27: =F27-(I27-X27) -> 20.697255 | M27: 37 | O27: 0 | P27: =M27-(N27+O27) -> 37 | Q27: 0 | R27: 20 | S27: =SUM(P27:R27) -> 57 | U27: 0 | V27: 56 | W27: =W26-45-2 -> 5606 | X27: =N27+O27+S27+U27+V27 -> 113 | Y27: =IF(L27<0,L27*-1,0) -> 0 | Z27: =X27+Y27 -> 113 | AA27: 0 | AB27: 48 | AC27: 24 | AD27: =AD26+1 -> 18
A28: =A27+1 -> 19 | B28: 6910.75 | C28: 324996 | D28: =C28-C27 -> -121 | E28: =C28-152000 -> 172996 | F28: =D28/$D$2 -> -61.003277 | G28: 45 | H28: 1.1 | I28: =G28+H28 -> 46.1 | J28: =IF(L28>0,L28,0) -> 5.896723 | K28: =I28+J28 -> 51.996723 | L28: =F28-(I28-X28) -> 5.896723 | M28: 37 | O28: 0 | P28: =M28-(N28+O28) -> 37 | Q28: 0 | R28: 20 | S28: =SUM(P28:R28) -> 57 | U28: 0 | V28: 56 | W28: =W27-45-2 -> 5559 | X28: =N28+O28+S28+U28+V28 -> 113 | Y28: =IF(L28<0,L28*-1,0) -> 0 | Z28: =X28+Y28 -> 113 | AA28: 0 | AB28: 56 | AC28: 20 | AD28: =AD27+1 -> 19
A29: =A28+1 -> 20 | B29: 6910.72 | C29: 324876 | D29: =C29-C28 -> -120 | E29: =C29-152000 -> 172876 | F29: =D29/$D$2 -> -60.499118 | G29: 39 | H29: 0.93 | I29: =G29+H29 -> 39.93 | J29: =IF(L29>0,L29,0) -> 12.570882 | K29: =I29+J29 -> 52.500882 | L29: =F29-(I29-X29) -> 12.570882 | M29: 37 | O29: 0 | P29: =M29-(N29+O29) -> 37 | Q29: 0 | R29: 20 | S29: =SUM(P29:R29) -> 57 | U29: 0 | V29: 56 | W29: =W28-45-2 -> 5512 | X29: =N29+O29+S29+U29+V29 -> 113 | Y29: =IF(L29<0,L29*-1,0) -> 0 | Z29: =X29+Y29 -> 113 | AA29: 0 | AB29: 54 | AC29: 28 | AD29: =AD28+1 -> 20
A30: =A29+1 -> 21 | B30: 6910.7 | C30: 324796 | D30: =C30-C29 -> -80 | E30: =C30-152000 -> 172796 | F30: =D30/$D$2 -> -40.332745 | G30: 40 | H30: 0.88 | I30: =G30+H30 -> 40.88 | J30: =IF(L30>0,L30,0) -> 29.787255 | K30: =I30+J30 -> 70.667255 | L30: =F30-(I30-X30) -> 29.787255 | M30: 37 | O30: 0 | P30: =M30-(N30+O30) -> 37 | Q30: 0 | R30: 18 | S30: =SUM(P30:R30) -> 55 | U30: 0 | V30: 56 | W30: =W29-45-2 -> 5465 | X30: =N30+O30+S30+U30+V30 -> 111 | Y30: =IF(L30<0,L30*-1,0) -> 0 | Z30: =X30+Y30 -> 111 | AA30: 0.05 | AB30: 42 | AC30: 22 | AD30: =AD29+1 -> 21
A31: =A30+1 -> 22 | B31: 6910.64 | C31: 324555 | D31: =C31-C30 -> -241 | E31: =C31-152000 -> 172555 | F31: =D31/$D$2 -> -121.50239 | G31: 38 | H31: 1 | I31: =G31+H31 -> 39 | J31: =IF(L31>0,L31,0) -> 12.497605 | K31: =I31+J31 -> 51.497605 | L31: =F31-(I31-X31) -> 12.497605 | M31: 35 | O31: 0 | P31: =M31-(N31+O31) -> 35 | Q31: 82 | R31: 0 | S31: =SUM(P31:R31) -> 117 | U31: 0 | V31: 56 | W31: =W30-45-2 -> 5418 | X31: =N31+O31+S31+U31+V31 -> 173 | Y31: =IF(L31<0,L31*-1,0) -> 0 | Z31: =X31+Y31 -> 173 | AA31: 0 | AB31: 29 | AC31: 21 | AD31: =AD30+1 -> 22
A32: =A31+1 -> 23 | B32: 6910.55 | C32: 324194 | D32: =C32-C31 -> -361 | E32: =C32-152000 -> 172194 | F32: =D32/$D$2 -> -182.00151 | G32: 34 | H32: 0.92 | I32: =G32+H32 -> 34.92 | J32: =IF(L32>0,L32,0) -> 0 | K32: =I32+J32 -> 34.92 | L32: =F32-(I32-X32) -> -5.3215125 | M32: 7.6 | O32: 0 | P32: =M32-(N32+O32) -> 7.6 | Q32: 148 | R32: 0 | S32: =SUM(P32:R32) -> 155.6 | U32: 0 | V32: 56 | W32: =W31-45-2 -> 5371 | X32: =N32+O32+S32+U32+V32 -> 211.6 | Y32: =IF(L32<0,L32*-1,0) -> 5.3215125 | Z32: =X32+Y32 -> 216.92151 | AA32: 0 | AB32: 36 | AC32: 8 | AD32: =AD31+1 -> 23
... A38: =A37+1 -> 29 | B38: 6910.11 | C38: 322428 | D38: =C38-C37 -> -80 | E38: =C38-152000 -> 170428 | F38: =D38/$D$2 -> -40.332745 | G38: 56 | H38: 0.88 | I38: =G38+H38 -> 56.88 | J38: =IF(L38>0,L38,0) -> 12.187255 | K38: =I38+J38 -> 69.067255 | L38: =F38-(I38-X38) -> 12.187255 | M38: 3.4 | O38: 0 | P38: =M38-(N38+O38) -> 3.4 | Q38: 50 | R38: 0 | S38: =SUM(P38:R38) -> 53.4 | U38: 0 | V38: 56 | W38: =W37-45-2 -> 5089 | X38: =N38+O38+S38+U38+V38 -> 109.4 | Y38: =IF(L38<0,L38*-1,0) -> 0 | Z38: =X38+Y38 -> 109.4 | AA38: 0 | AB38: 65 | AC38: 33 | AD38: =AD37+1 -> 29
A39: 30 | B39: 6910.12 | C39: 322468 | D39: =C39-C38 -> 40 | E39: =C39-152000 -> 170468 | F39: =D39/$D$2 -> 20.166373 | G39: 58 | H39: 0.85 | I39: =G39+H39 -> 58.85 | J39: =IF(L39>0,L39,0) -> 20.516373 | K39: =I39+J39 -> 79.366373 | L39: =F39-(I39-X39) -> 20.516373 | M39: 3.2 | O39: 0 | P39: =M39-(N39+O39) -> 3.2 | Q39: 0 | R39: 0 | S39: =SUM(P39:R39) -> 3.2 | U39: 0 | V39: 56 | W39: =W38-45-2 -> 5042 | X39: =N39+O39+S39+U39+V39 -> 59.2 | Y39: =IF(L39<0,L39*-1,0) -> 0 | Z39: =X39+Y39 -> 59.2 | AA39: 0 | AB39: 64 | AC39: 32 | AD39: 30
A41: MONTH / CFS | F41: =SUM(F10:F39) -> -3635.997 | G41: =SUM(G10:G39) -> 1605 | H41: =SUM(H10:H39) -> 28.73 | I41: =SUM(I10:I39) -> 1633.73 | J41: =SUM(J10:J39) -> 234.69852 | K41: =SUM(K10:K39) -> 1868.4285 | L41: =SUM(L10:L39) -> 12.373025 | M41: =SUM(M10:M39) -> 1528.1 | ... S41: =SUM(S10:S39) -> 2690.7595 | U41: =SUM(U10:U39) -> 0 | V41: =SUM(V10:V39) -> 2150 | X41: =SUM(X10:X39) -> 5282.1 | Y41: =SUM(Y10:Y39) -> 222.3255 | Z41: =SUM(Z10:Z39) -> 5504.4255 | AA41: =SUM(AA10:AA39) -> 0.05 | AB41: =AVERAGE(AB10:AB39) -> 61.066667 | AC41: =AVERAGE(AC10:AC39) -> 27.633333 | AD41: AVE
A42: MONTH / AF | D42: =SUM(D10:D39) -> -7212 | F42: =F41*$D$2 -> -7212 | G42: =G41*$D$2 -> 3183.5175 | H42: =H41*$D$2 -> 56.985955 | I42: =I41*$D$2 -> 3240.5035 | J42: =J41*$D$2 -> 465.52452 | K42: =K41*$D$2 -> 3706.028 | L42: =L41*$D$2 -> 24.541895 | M42: =M41*$D$2 -> 3030.9864 | ... S42: =S41*$D$2 -> 5337.1215 | U42: =U41*$D$2 -> 0 | V42: =V41*$D$2 -> 4264.525 | X42: =X41*$D$2 -> 10477.045 | Y42: =Y41*$D$2 -> 440.98262 | Z42: =Z41*$D$2 -> 10918.028 | AB42: =MAX(AB10:AB39) -> 76 | AC42: =MAX(AC10:AC39) -> 44 | AD42: HI
A44: SEASON / CFS | AB44: =MIN(AB10:AB39) -> 29 | AC44: =MIN(AC10:AC39) -> 8 | AD44: LO
A45: SEASON / AF
A47: YTD / CFS | F47: =F8+F41 -> -3635.997 | G47: =G8+G41 -> 1605 | H47: =H8+H41 -> 28.73 | I47: =I8+I41 -> 1633.73 | J47: =J8+J41 -> 234.69852 | K47: =K8+K41 -> 1868.4285 | L47: =L8+L41 -> 12.373025 | M47: =M8+M41 -> 1528.1 | ... S47: =S8+S41 -> 2690.7595 | U47: =U8+U41 -> 0 | V47: =V8+V41 -> 2150 | W47: =W39 -> 5042 | X47: =X8+X41 -> 5282.1 | Y47: =Y8+Y41 -> 222.3255 | Z47: =Z8+Z41 -> 5504.4255 | AA47: =AA8+AA41 -> 0.05
A48: YTD / AF | D48: =D8+D42 -> -7212 | E48: =E39 -> 170468 | F48: =F47*$D$2 -> -7212 | G48: =G47*$D$2 -> 3183.5175 | H48: =H47*$D$2 -> 56.985955 | I48: =I47*$D$2 -> 3240.5035 | J48: =J47*$D$2 -> 465.52452 | K48: =K47*$D$2 -> 3706.028 | L48: =L47*$D$2 -> 24.541895 | M48: =M47*$D$2 -> 3030.9864 | ... Z48: =Z47*$D$2 -> 10918.028

Sheet DEC
K1: MC PHEE RESERVOIR IN/OUT FLOW TABULATION
A2: AF/cfs CONVERT FACTOR | D2: 1.9835 | K2: DECEMBER "99"
A4: DATE | B4: RESERV | C4: RESERV | D4: AC FT | E4: ACTIVE | F4: CONV TO | G4: DOLORES | H4: LOST | I4: RECORDED | J4: CALC | K4: TOTAL | L4: CALC | M4: DOLORES TUNNEL | Q4: LONE | R4: U | S4: TOTAL | T4: MVI | U4: DV CR | V4: BELOW | W4: REMAIN | X4: RECORDED | Y4: CALC | Z4: TOTAL | AA4: RAIN | AB4: MAX | AC4: MIN | AD4: DATE
A5: "DEC" | B5: ELEV | C5: AC FT | D5: CHANGE | E5: CAP | F5: CFS | G5: RIVER | H5: CANYON | I5: INFLOW | J5: INFLOW | K5: INFLOW | L5: INF/OTF | M5: TOT DIV | N5: WETLAND | O5: UTE F&R | P5: MVI,CTZ | Q5: PINE | R5: LAT | S5: MVI | T5: CALL | U5: CANAL | V5: MC PHEE | W5: RELEASE | X5: OUTFLOW | Y5: OUTFLOW | Z5: OUTFLOW | AB5: TMP | AC5: TMP | AD5: "DEC"
A7: SEASON BAL
A8: YTD | B8: =NOV!B39 -> 6910.12 | C8: =NOV!C39 -> 322468 | D8: =NOV!$D$48 -> -7212 | E8: =NOV!$E$39 -> 170468 | F8: =NOV!F47 -> -3635.997 | G8: =NOV!G47 -> 1605 | H8: =NOV!H47 -> 28.73 | I8: =NOV!I47 -> 1633.73 | J8: =NOV!J47 -> 234.69852 | K8: =NOV!K47 -> 1868.4285 | L8: =NOV!L47 -> 12.373025 | M8: =NOV!M47 -> 1528.1 | ... AA8: =NOV!AA47 -> 0.05
A10: 1 | B10: 6910.12 | C10: 322468 | D10: =C10-C8 -> 0 | E10: =C10-152000 -> 170468 | F10: =D10/$D$2 -> 0 | G10: 58 | H10: 0.92 | I10: =G10+H10 -> 58.92 | J10: =IF(L10>0,L10,0) -> 0.15 | K10: =I10+J10 -> 59.07 | L10: =F10-(I10-X10) -> 0.15 | M10: 3.1 | O10: 0 | P10: =M10-(N10+O10) -> 3.1 | Q10: 0 | R10: 0 | S10: =SUM(P10:R10) -> 3.1 | U10: 0 | V10: 55.97 | W10: =W8-45-2 -> 4995 | X10: =N10+O10+S10+U10+V10 -> 59.07 | Y10: =IF(L10<0,L10*-1,0) -> 0 | Z10: =X10+Y10 -> 59.07 | AA10: 0.01 | AB10: 60 | AC10: 31 | AD10: 1
A11: =A10+1 -> 2 | B11: 6910.11 | C11: 322428 | D11: =C11-C10 -> -40 | E11: =C11-152000 -> 170428 | F11: =D11/$D$2 -> -20.166373 | G11: 61 | H11: 1 | I11: =G11+H11 -> 62 | J11: =IF(L11>0,L11,0) -> 0 | K11: =I11+J11 -> 62 | L11: =F11-(I11-X11) -> -23.066373 | M11: 3.1 | O11: 0 | P11: =M11-(N11+O11) -> 3.1 | Q11: 0 | R11: 0 | S11: =SUM(P11:R11) -> 3.1 | U11: 0 | V11: 56 | W11: =W10-45-2 -> 4948 | X11: =N11+O11+S11+U11+V11 -> 59.1 | Y11: =IF(L11<0,L11*-1,0) -> 23.066373 | Z11: =X11+Y11 -> 82.166373 | AA11: 0 | AB11: 43 | AC11: 18 | AD11: =AD10+1 -> 2
A12: =A11+1 -> 3 | B12: 6910.1 | C12: 322388 | D12: =C12-C11 -> -40 | E12: =C12-152000 -> 170388 | F12: =D12/$D$2 -> -20.166373 | G12: 57 | H12: 1.1 | I12: =G12+H12 -> 58.1 | J12: =IF(L12>0,L12,0) -> 0 | K12: =I12+J12 -> 58.1 | L12: =F12-(I12-X12) -> -19.166373 | M12: 3.1 | O12: 0 | P12: =M12-(N12+O12) -> 3.1 | Q12: 0 | R12: 0 | S12: =SUM(P12:R12) -> 3.1 | U12: 0 | V12: 56 | W12: =W11-45-2 -> 4901 | X12: =N12+O12+S12+U12+V12 -> 59.1 | Y12: =IF(L12<0,L12*-1,0) -> 19.166373 | Z12: =X12+Y12 -> 78.266373 | AA12: 0 | AB12: 42 | AC12: 19 | AD12: =AD11+1 -> 3
A13: =A12+1 -> 4 | B13: 6910.09 | C13: 322348 | D13: =C13-C12 -> -40 | E13: =C13-152000 -> 170348 | F13: =D13/$D$2 -> -20.166373 | G13: 47 | H13: 0.9 | I13: =G13+H13 -> 47.9 | J13: =IF(L13>0,L13,0) -> 0 | K13: =I13+J13 -> 47.9 | L13: =F13-(I13-X13) -> -8.7663726 | M13: 3.3 | O13: 0 | P13: =M13-(N13+O13) -> 3.3 | Q13: 0 | R13: 0 | S13: =SUM(P13:R13) -> 3.3 | U13: 0 | V13: 56 | W13: =W12-45-2 -> 4854 | X13: =N13+O13+S13+U13+V13 -> 59.3 | Y13: =IF(L13<0,L13*-1,0) -> 8.7663726 | Z13: =X13+Y13 -> 68.066373 | AA13: 0 | AB13: 40 | AC13: 20 | AD13: =AD12+1 -> 4
A14: =A13+1 -> 5 | B14: 6910.08 | C14: 322307 | D14: =C14-C13 -> -41 | E14: =C14-152000 -> 170307 | F14: =D14/$D$2 -> -20.670532 | G14: 50 | H14: 0.74 | I14: =G14+H14 -> 50.74 | J14: =IF(L14>0,L14,0) -> 0 | K14: =I14+J14 -> 50.74 | L14: =F14-(I14-X14) -> -11.210532 | M14: 4.2 | O14: 0 | P14: =M14-(N14+O14) -> 4.2 | Q14: 0 | R14: 0 | S14: =SUM(P14:R14) -> 4.2 | U14: 0 | V14: 56 | W14: =W13-45-2 -> 4807 | X14: =N14+O14+S14+U14+V14 -> 60.2 | Y14: =IF(L14<0,L14*-1,0) -> 11.210532 | Z14: =X14+Y14 -> 71.410532 | AA14: 0 | AB14: 46 | AC14: 8 | AD14: =AD13+1 -> 5
A15: =A14+1 -> 6 | B15: 6910.07 | C15: 322267 | D15: =C15-C14 -> -40 | E15: =C15-152000 -> 170267 | F15: =D15/$D$2 -> -20.166373 | G15: 50 | H15: 0.7 | I15: =G15+H15 -> 50.7 | J15: =IF(L15>0,L15,0) -> 0 | K15: =I15+J15 -> 50.7 | L15: =F15-(I15-X15) -> -9.7663726 | M15: 5.1 | O15: 0 | P15: =M15-(N15+O15) -> 5.1 | Q15: 0 | R15: 0 | S15: =SUM(P15:R15) -> 5.1 | U15: 0 | V15: 56 | W15: =W14-45-2 -> 4760 | X15: =N15+O15+S15+U15+V15 -> 61.1 | Y15: =IF(L15<0,L15*-1,0) -> 9.7663726 | Z15: =X15+Y15 -> 70.866373 | AA15: 0 | AB15: 44 | AC15: 14 | AD15: =AD14+1 -> 6
A16: =A15+1 -> 7 | B16: 6910.06 | C16: 322227 | D16: =C16-C15 -> -40 | E16: =C16-152000 -> 170227 | F16: =D16/$D$2 -> -20.166373 | G16: 48 | H16: 0.7 | I16: =G16+H16 -> 48.7 | J16: =IF(L16>0,L16,0) -> 0 | K16: =I16+J16 -> 48.7 | L16: =F16-(I16-X16) -> -9.6663726 | M16: 5.2 | O16: 0 | P16: =M16-(N16+O16) -> 5.2 | Q16: 0 | R16: 0 | S16: =SUM(P16:R16) -> 5.2 | U16: 0 | V16: 54 | W16: =W15-45-2 -> 4713 | X16: =N16+O16+S16+U16+V16 -> 59.2 | Y16: =IF(L16<0,L16*-1,0) -> 9.6663726 | Z16: =X16+Y16 -> 68.866373 | AA16: 0 | AB16: 47 | AC16: 24 | AD16: =AD15+1 -> 7
A17: =A16+1 -> 8 | B17: 6910.05 | C17: 322187 | D17: =C17-C16 -> -40 | E17: =C17-152000 -> 170187 | F17: =D17/$D$2 -> -20.166373 | G17: 52 | H17: 0.7 | I17: =G17+H17 -> 52.7 | J17: =IF(L17>0,L17,0) -> 0 | K17: =I17+J17 -> 52.7 | L17: =F17-(I17-X17) -> -14.766373 | M17: 5.1 | O17: 0 | P17: =M17-(N17+O17) -> 5.1 | Q17: 0 | R17: 0 | S17: =SUM(P17:R17) -> 5.1 | U17: 0 | V17: 53 | W17: =W16-45-2 -> 4666 | X17: =N17+O17+S17+U17+V17 -> 58.1 | Y17: =IF(L17<0,L17*-1,0) -> 14.766373 | Z17: =X17+Y17 -> 72.866373 | AA17: 0 | AB17: 38 | AC17: 22 | AD17: =AD16+1 -> 8
A18: =A17+1 -> 9 | B18: 6910.04 | C18: 322147 | D18: =C18-C17 -> -40 | E18: =C18-152000 -> 170147 | F18: =D18/$D$2 -> -20.166373 | G18: 48 | H18: 0.7 | I18: =G18+H18 -> 48.7 | J18: =IF(L18>0,L18,0) -> 0 | K18: =I18+J18 -> 48.7 | L18: =F18-(I18-X18) -> -10.966373 | M18: 4.9 | O18: 0 | P18: =M18-(N18+O18) -> 4.9 | Q18: 0 | R18: 0 | S18: =SUM(P18:R18) -> 4.9 | U18: 0 | V18: 53 | W18: =W17-45-2 -> 4619 | X18: =N18+O18+S18+U18+V18 -> 57.9 | Y18: =IF(L18<0,L18*-1,0) -> 10.966373 | Z18: =X18+Y18 -> 68.866373 | AA18: 0 | AB18: 38 | AC18: 7 | AD18: =AD17+1 -> 9
A19: =A18+1 -> 10 | B19: 6910.03 | C19: 322107 | D19: =C19-C18 -> -40 | E19: =C19-152000 -> 170107 | F19: =D19/$D$2 -> -20.166373 | G19: 50 | H19: 0.68 | I19: =G19+H19 -> 50.68 | J19: =IF(L19>0,L19,0) -> 0 | K19: =I19+J19 -> 50.68 | L19: =F19-(I19-X19) -> -13.546373 | M19: 4.3 | O19: 0 | P19: =M19-(N19+O19) -> 4.3 | Q19: 0 | R19: 0 | S19: =SUM(P19:R19) -> 4.3 | U19: 0 | V19: 53 | W19: =W18-45-2 -> 4572 | X19: =N19+O19+S19+U19+V19 -> 57.3 | Y19: =IF(L19<0,L19*-1,0) -> 13.546373 | Z19: =X19+Y19 -> 70.846373 | AA19: 0 | AB19: 40 | AC19: 19 | AD19: =AD18+1 -> 10
A20: =A19+1 -> 11 | B20: 6910.02 | C20: 322067 | D20: =C20-C19 -> -40 | E20: =C20-152000 -> 170067 | F20: =D20/$D$2 -> -20.166373 | G20: 54 | H20: 0.68 | I20: =G20+H20 -> 54.68 | J20: =IF(L20>0,L20,0) -> 0 | K20: =I20+J20 -> 54.68 | L20: =F20-(I20-X20) -> -17.746373 | M20: 4.1 | O20: 0 | P20: =M20-(N20+O20) -> 4.1 | Q20: 0 | R20: 0 | S20: =SUM(P20:R20) -> 4.1 | U20: 0 | V20: 53 | W20: =W19-45-2 -> 4525 | X20: =N20+O20+S20+U20+V20 -> 57.1 | Y20: =IF(L20<0,L20*-1,0) -> 17.746373 | Z20: =X20+Y20 -> 74.846373 | AA20: 0 | AB20: 40 | AC20: 20 | AD20: =AD19+1 -> 11
A21: =A20+1 -> 12 | B21: 6910.01 | C21: 322027 | D21: =C21-C20 -> -40 | E21: =C21-152000 -> 170027 | F21: =D21/$D$2 -> -20.166373 | G21: 48 | H21: 0.68 | I21: =G21+H21 -> 48.68 | J21: =IF(L21>0,L21,0) -> 0 | K21: =I21+J21 -> 48.68 | L21: =F21-(I21-X21) -> -11.746373 | M21: 4.1 | O21: 0 | P21: =M21-(N21+O21) -> 4.1 | Q21: 0 | R21: 0 | S21: =SUM(P21:R21) -> 4.1 | U21: 0 | V21: 53 | W21: =W20-45-2 -> 4478 | X21: =N21+O21+S21+U21+V21 -> 57.1 | Y21: =IF(L21<0,L21*-1,0) -> 11.746373 | Z21: =X21+Y21 -> 68.846373 | AA21: 0 | AB21: 46 | AC21: 15 | AD21: =AD20+1 -> 12
A22: =A21+1 -> 13 | B22: 6910 | C22: 321986 | D22: =C22-C21 -> -41 | E22: =C22-152000 -> 169986 | F22: =D22/$D$2 -> -20.670532 | G22: 47 | H22: 0.66 | I22: =G22+H22 -> 47.66 | J22: =IF(L22>0,L22,0) -> 0 | K22: =I22+J22 -> 47.66 | L22: =F22-(I22-X22) -> -10.930532 | M22: 4.4 | O22: 0 | P22: =M22-(N22+O22) -> 4.4 | Q22: 0 | R22: 0 | S22: =SUM(P22:R22) -> 4.4 | U22: 0 | V22: 53 | W22: =W21-45-2 -> 4431 | X22: =N22+O22+S22+U22+V22 -> 57.4 | Y22: =IF(L22<0,L22*-1,0) -> 10.930532 | Z22: =X22+Y22 -> 68.330532 | AA22: 0.01 | AB22: 40 | AC22: 13 | AD22: =AD21+1 -> 13
... A38: =A37+1 -> 29 | B38: 6909.93 | C38: 321708 | D38: =C38-C37 -> 0 | E38: =C38-152000 -> 169708 | F38: =D38/$D$2 -> 0 | G38: 50 | H38: 0.28 | I38: =G38+H38 -> 50.28 | J38: =IF(L38>0,L38,0) -> 7.12 | K38: =I38+J38 -> 57.4 | L38: =F38-(I38-X38) -> 7.12 | M38: 4.4 | O38: 0 | P38: =M38-(N38+O38) -> 4.4 | Q38: 0 | R38: 0 | S38: =SUM(P38:R38) -> 4.4 | U38: 0 | V38: 53 | W38: =W37-45-2 -> 3679 | X38: =N38+O38+S38+U38+V38 -> 57.4 | Y38: =IF(L38<0,L38*-1,0) -> 0 | Z38: =X38+Y38 -> 57.4 | AA38: 0 | AB38: 49 | AC38: 20 | AD38: =AD37+1 -> 29
A39: 30 | B39: 6909.93 | C39: 321708 | D39: =C39-C38 -> 0 | E39: =C39-152000 -> 169708 | F39: =D39/$D$2 -> 0 | G39: 49 | H39: 0.38 | I39: =G39+H39 -> 49.38 | J39: =IF(L39>0,L39,0) -> 8.02 | K39: =I39+J39 -> 57.4 | L39: =F39-(I39-X39) -> 8.02 | M39: 4.4 | O39: 0 | P39: =M39-(N39+O39) -> 4.4 | Q39: 0 | R39: 0 | S39: =SUM(P39:R39) -> 4.4 | U39: 0 | V39: 53 | W39: =W38-45-2 -> 3632 | X39: =N39+O39+S39+U39+V39 -> 57.4 | Y39: =IF(L39<0,L39*-1,0) -> 0 | Z39: =X39+Y39 -> 57.4 | AA39: 0 | AB39: 48 | AC39: 18 | AD39: 30
A40: 31 | B40: 6909.93 | C40: 321708 | D40: =C40-C39 -> 0 | E40: =C40-152000 -> 169708 | F40: =D40/$D$2 -> 0 | G40: 50 | H40: 0.58 | I40: =G40+H40 -> 50.58 | J40: =IF(L40>0,L40,0) -> 6.82 | K40: =I40+J40 -> 57.4 | L40: =F40-(I40-X40) -> 6.82 | M40: 4.4 | O40: 0 | P40: =M40-(N40+O40) -> 4.4 | Q40: 0 | R40: 0 | S40: =SUM(P40:R40) -> 4.4 | U40: 0 | V40: 53 | W40: =W39-45-2 -> 3585 | X40: =N40+O40+S40+U40+V40 -> 57.4 | Y40: =IF(L40<0,L40*-1,0) -> 0 | Z40: =X40+Y40 -> 57.4 | AA40: 0.28 | AB40: 51 | AC40: 17 | AD40: 31
A42: MONTH / CFS | F42: =SUM(F10:F40) -> -383.16108 | G42: =SUM(G10:G40) -> 1557 | H42: =SUM(H10:H40) -> 18.33 | I42: =SUM(I10:I40) -> 1575.33 | J42: =SUM(J10:J40) -> 82.06 | K42: =SUM(K10:K40) -> 1657.39 | L42: =SUM(L10:L40) -> -162.72108 | M42: =SUM(M10:M40) -> 133.8 | ... S42: =SUM(S10:S40) -> 133.8 | U42: =SUM(U10:U40) -> 0 | V42: =SUM(V10:V40) -> 1661.97 | X42: =SUM(X10:X40) -> 1795.77 | Y42: =SUM(Y10:Y40) -> 244.78108 | Z42: =SUM(Z10:Z40) -> 2040.5511 | AA42: =SUM(AA10:AA40) -> 0.33 | AB42: =AVERAGE(AB10:AB40) -> 44.483871 | AC42: =AVERAGE(AC10:AC40) -> 15.096774 | AD42: AVE
A43: MONTH / AF | D43: =SUM(D10:D40) -> -760 | F43: =F42*$D$2 -> -760 | G43: =G42*$D$2 -> 3088.3095 | H43: =H42*$D$2 -> 36.357555 | I43: =I42*$D$2 -> 3124.6671 | J43: =J42*$D$2 -> 162.76601 | K43: =K42*$D$2 -> 3287.4331 | L43: =L42*$D$2 -> -322.75726 | M43: =M42*$D$2 -> 265.3923 | ... S43: =S42*$D$2 -> 265.3923 | U43: =U42*$D$2 -> 0 | V43: =V42*$D$2 -> 3296.5175 | X43: =X42*$D$2 -> 3561.9098 | Y43: =Y42*$D$2 -> 485.52327 | Z43: =Z42*$D$2 -> 4047.4331 | AB43: =MAX(AB10:AB40) -> 60 | AC43: =MAX(AC10:AC40) -> 31 | AD43: HI
A45: SEASON / CFS | AB45: =MIN(AB10:AB40) -> 25 | AC45: =MIN(AC10:AC40) -> 3 | AD45: LO
A46: SEASON / AF
A48: YTD / CFS | F48: =F8+F42 -> -4019.1581 | G48: =G8+G42 -> 3162 | H48: =H8+H42 -> 47.06 | I48: =I8+I42 -> 3209.06 | J48: =J8+J42 -> 316.75852 | K48: =K8+K42 -> 3525.8185 | L48: =L8+L42 -> -150.34805 | M48: =M8+M42 -> 1661.9 | ... S48: =S8+S42 -> 2824.5595 | U48: =U8+U42 -> 0 | V48: =V8+V42 -> 3811.97 | W48: =W40 -> 3585 | X48: =X8+X42 -> 7077.87 | Y48: =Y8+Y42 -> 467.10657 | Z48: =Z8+Z42 -> 7544.9766 | AA48: =AA8+AA42 -> 0.38
A49: YTD / AF | D49: =D8+D43 -> -7972 | E49: =E40 -> 169708 | F49: =F48*$D$2 -> -7972 | G49: =G48*$D$2 -> 6271.827 | H49: =H48*$D$2 -> 93.34351 | I49: =I48*$D$2 -> 6365.1705 | J49: =J48*$D$2 -> 628.29053 | K49: =K48*$D$2 -> 6993.461 | L49: =L48*$D$2 -> -298.21537 | M49: =M48*$D$2 -> 3296.3787 | ... V49: =V48*$D$2 -> 7561.0425 | W49: =W40*$D$2 -> 7110.8475 | X49: =X48*$D$2 -> 14038.955 | Y49: =Y48*$D$2 -> 926.50589 | Z49: =Z48*$D$2 -> 14965.461

Sheet JAN
K1: MC PHEE RESERVOIR IN/OUT FLOW TABULATION
A2: AF/cfs CONVERT FACTOR | D2: 1.9835 | K2: JANUARY "2000"
A4: DATE | B4: RESERV | C4: RESERV | D4: AC FT | E4: ACTIVE | F4: CONV TO | G4: DOLORES | H4: LOST | I4: RECORDED | J4: CALC | K4: TOTAL | L4: CALC | M4: DOLORES TUNNEL | Q4: LONE | R4: U | S4: TOTAL | T4: MVI | U4: DV CR | V4: BELOW | W4: REMAIN | X4: RECORDED | Y4: CALC | Z4: TOTAL | AA4: RAIN | AB4: MAX | AC4: MIN | AD4: DATE
A5: "JAN" | B5: ELEV | C5: AC FT | D5: CHANGE | E5: CAP | F5: CFS | G5: RIVER | H5: CANYON | I5: INFLOW | J5: INFLOW | K5: INFLOW | L5: INF/OTF | M5: TOT DIV | N5: WETLAND | O5: UTE F&R | P5: MVI,CTZ | Q5: PINE | R5: LAT | S5: MVI | T5: CALL | U5: CANAL | V5: MC PHEE | W5: RELEASE | X5: OUTFLOW | Y5: OUTFLOW | Z5: OUTFLOW | AB5: TMP | AC5: TMP | AD5: "JAN"
A7: SEASON BAL
A8: YTD | B8: =DEC!B40 -> 6909.93 | C8: =DEC!C40 -> 321708 | D8: =DEC!$D$49 -> -7972 | E8: =DEC!$E$40 -> 169708 | F8: =DEC!F48 -> -4019.1581 | G8: =DEC!G48 -> 3162 | H8: =DEC!H48 -> 47.06 | I8: =DEC!I48 -> 3209.06 | J8: =DEC!J48 -> 316.75852 | K8: =DEC!K48 -> 3525.8185 | L8: =DEC!L48 -> -150.34805 | M8: =DEC!M48 -> 1661.9 | ... AA8: =DEC!AA48 -> 0.38
A10: 1 | B10: 6909.93 | C10: 321708 | D10: =C10-C8 -> 0 | E10: =C10-152000 -> 169708 | F10: =D10/$D$2 -> 0 | G10: 50 | H10: 0.6 | I10: =G10+H10 -> 50.6 | J10: =IF(L10>0,L10,0) -> 6.8 | K10: =I10+J10 -> 57.4 | L10: =F10-(I10-X10) -> 6.8 | M10: 4.4 | O10: 0 | P10: =M10-(N10+O10) -> 4.4 | Q10: 0 | R10: 0 | S10: =SUM(P10:R10) -> 4.4 | U10: 0 | V10: 53 | W10: =W8-45-2 -> 3538 | X10: =N10+O10+S10+U10+V10 -> 57.4 | Y10: =IF(L10<0,L10*-1,0) -> 0 | Z10: =X10+Y10 -> 57.4 | AA10: 0.3 | AB10: 28 | AC10: 24 | AD10: 1
A11: =A10+1 -> 2 | B11: 6909.92 | C11: 321668 | D11: =C11-C10 -> -40 | E11: =C11-152000 -> 169668 | F11: =D11/$D$2 -> -20.166373 | G11: 50 | H11: 0.7 | I11: =G11+H11 -> 50.7 | J11: =IF(L11>0,L11,0) -> 0 | K11: =I11+J11 -> 50.7 | L11: =F11-(I11-X11) -> -13.466373 | M11: 4.4 | O11: 0 | P11: =M11-(N11+O11) -> 4.4 | Q11: 0 | R11: 0 | S11: =SUM(P11:R11) -> 4.4 | U11: 0 | V11: 53 | W11: =W10-45-2 -> 3491 | X11: =N11+O11+S11+U11+V11 -> 57.4 | Y11: =IF(L11<0,L11*-1,0) -> 13.466373 | Z11: =X11+Y11 -> 70.866373 | AA11: 0.13 | AB11: 28 | AC11: 22 | AD11: =AD10+1 -> 2
A12: =A11+1 -> 3 | B12: 6909.92 | C12: 321668 | D12: =C12-C11 -> 0 | E12: =C12-152000 -> 169668 | F12: =D12/$D$2 -> 0 | G12: 50 | H12: 0.68 | I12: =G12+H12 -> 50.68 | J12: =IF(L12>0,L12,0) -> 6.72 | K12: =I12+J12 -> 57.4 | L12: =F12-(I12-X12) -> 6.72 | M12: 4.4 | O12: 0 | P12: =M12-(N12+O12) -> 4.4 | Q12: 0 | R12: 0 | S12: =SUM(P12:R12) -> 4.4 | U12: 0 | V12: 53 | W12: =W11-45-2 -> 3444 | X12: =N12+O12+S12+U12+V12 -> 57.4 | Y12: =IF(L12<0,L12*-1,0) -> 0 | Z12: =X12+Y12 -> 57.4 | AA12: 0 | AB12: 20 | AC12: 5 | AD12: =AD11+1 -> 3
A13: =A12+1 -> 4 | B13: 6909.91 | C13: 321628 | D13: =C13-C12 -> -40 | E13: =C13-152000 -> 169628 | F13: =D13/$D$2 -> -20.166373 | G13: 48 | H13: 0.68 | I13: =G13+H13 -> 48.68 | J13: =IF(L13>0,L13,0) -> 0 | K13: =I13+J13 -> 48.68 | L13: =F13-(I13-X13) -> -11.446373 | M13: 4.4 | O13: 0 | P13: =M13-(N13+O13) -> 4.4 | Q13: 0 | R13: 0 | S13: =SUM(P13:R13) -> 4.4 | U13: 0 | V13: 53 | W13: =W12-45-2 -> 3397 | X13: =N13+O13+S13+U13+V13 -> 57.4 | Y13: =IF(L13<0,L13*-1,0) -> 11.446373 | Z13: =X13+Y13 -> 68.846373 | AA13: 0 | AB13: 36 | AC13: -4 | AD13: =AD12+1 -> 4
A14: =A13+1 -> 5 | B14: 6909.91 | C14: 321628 | D14: =C14-C13 -> 0 | E14: =C14-152000 -> 169628 | F14: =D14/$D$2 -> 0 | G14: 49 | H14: 0.7 | I14: =G14+H14 -> 49.7 | J14: =IF(L14>0,L14,0) -> 7.7 | K14: =I14+J14 -> 57.4 | L14: =F14-(I14-X14) -> 7.7 | M14: 4.4 | O14: 0 | P14: =M14-(N14+O14) -> 4.4 | Q14: 0 | R14: 0 | S14: =SUM(P14:R14) -> 4.4 | U14: 0 | V14: 53 | W14: =W13-45-2 -> 3350 | X14: =N14+O14+S14+U14+V14 -> 57.4 | Y14: =IF(L14<0,L14*-1,0) -> 0 | Z14: =X14+Y14 -> 57.4 | AA14: 0 | AB14: 32 | AC14: 8 | AD14: =AD13+1 -> 5
A15: =A14+1 -> 6 | B15: 6909.9 | C15: 321588 | D15: =C15-C14 -> -40 | E15: =C15-152000 -> 169588 | F15: =D15/$D$2 -> -20.166373 | G15: 50 | H15: 0.72 | I15: =G15+H15 -> 50.72 | J15: =IF(L15>0,L15,0) -> 0 | K15: =I15+J15 -> 50.72 | L15: =F15-(I15-X15) -> -13.486373 | M15: 4.4 | O15: 0 | P15: =M15-(N15+O15) -> 4.4 | Q15: 0 | R15: 0 | S15: =SUM(P15:R15) -> 4.4 | U15: 0 | V15: 53 | W15: =W14-45-2 -> 3303 | X15: =N15+O15+S15+U15+V15 -> 57.4 | Y15: =IF(L15<0,L15*-1,0) -> 13.486373 | Z15: =X15+Y15 -> 70.886373 | AA15: 0 | AB15: 40 | AC15: 2 | AD15: =AD14+1 -> 6
A16: =A15+1 -> 7 | B16: 6909.9 | C16: 321588 | D16: =C16-C15 -> 0 | E16: =C16-152000 -> 169588 | F16: =D16/$D$2 -> 0 | G16: 50 | H16: 0.74 | I16: =G16+H16 -> 50.74 | J16: =IF(L16>0,L16,0) -> 6.66 | K16: =I16+J16 -> 57.4 | L16: =F16-(I16-X16) -> 6.66 | M16: 4.4 | O16: 0 | P16: =M16-(N16+O16) -> 4.4 | Q16: 0 | R16: 0 | S16: =SUM(P16:R16) -> 4.4 | U16: 0 | V16: 53 | W16: =W15-45-2 -> 3256 | X16: =N16+O16+S16+U16+V16 -> 57.4 | Y16: =IF(L16<0,L16*-1,0) -> 0 | Z16: =X16+Y16 -> 57.4 | AA16: 0 | AB16: 39 | AC16: 2 | AD16: =AD15+1 -> 7
A17: =A16+1 -> 8 | B17: 6909.89 | C17: 321549 | D17: =C17-C16 -> -39 | E17: =C17-152000 -> 169549 | F17: =D17/$D$2 -> -19.662213 | G17: 50 | H17: 0.76 | I17: =G17+H17 -> 50.76 | J17: =IF(L17>0,L17,0) -> 0 | K17: =I17+J17 -> 50.76 | L17: =F17-(I17-X17) -> -13.022213 | M17: 4.4 | O17: 0 | P17: =M17-(N17+O17) -> 4.4 | Q17: 0 | R17: 0 | S17: =SUM(P17:R17) -> 4.4 | U17: 0 | V17: 53 | W17: =W16-45-2 -> 3209 | X17: =N17+O17+S17+U17+V17 -> 57.4 | Y17: =IF(L17<0,L17*-1,0) -> 13.022213 | Z17: =X17+Y17 -> 70.422213 | AA17: 0 | AB17: 39 | AC17: 3 | AD17: =AD16+1 -> 8
A18: =A17+1 -> 9 | B18: 6909.89 | C18: 321549 | D18: =C18-C17 -> 0 | E18: =C18-152000 -> 169549 | F18: =D18/$D$2 -> 0 | G18: 50 | H18: 0.82 | I18: =G18+H18 -> 50.82 | J18: =IF(L18>0,L18,0) -> 6.58 | K18: =I18+J18 -> 57.4 | L18: =F18-(I18-X18) -> 6.58 | M18: 4.4 | O18: 0 | P18: =M18-(N18+O18) -> 4.4 | Q18: 0 | R18: 0 | S18: =SUM(P18:R18) -> 4.4 | U18: 0 | V18: 53 | W18: =W17-45-2 -> 3162 | X18: =N18+O18+S18+U18+V18 -> 57.4 | Y18: =IF(L18<0,L18*-1,0) -> 0 | Z18: =X18+Y18 -> 57.4 | AA18: 0 | AB18: 36 | AC18: 5 | AD18: =AD17+1 -> 9
A19: =A18+1 -> 10 | B19: 6909.89 | C19: 321549 | D19: =C19-C18 -> 0 | E19: =C19-152000 -> 169549 | F19: =D19/$D$2 -> 0 | G19: 50 | H19: 0.86 | I19: =G19+H19 -> 50.86 | J19: =IF(L19>0,L19,0) -> 6.54 | K19: =I19+J19 -> 57.4 | L19: =F19-(I19-X19) -> 6.54 | M19: 4.4 | O19: 0 | P19: =M19-(N19+O19) -> 4.4 | Q19: 0 | R19: 0 | S19: =SUM(P19:R19) -> 4.4 | U19: 0 | V19: 53 | W19: =W18-45-2 -> 3115 | X19: =N19+O19+S19+U19+V19 -> 57.4 | Y19: =IF(L19<0,L19*-1,0) -> 0 | Z19: =X19+Y19 -> 57.4 | AA19: 0 | AB19: 48 | AC19: 11 | AD19: =AD18+1 -> 10
A20: =A19+1 -> 11 | B20: 6909.89 | C20: 321549 | D20: =C20-C19 -> 0 | E20: =C20-152000 -> 169549 | F20: =D20/$D$2 -> 0 | G20: 50 | H20: 0.88 | I20: =G20+H20 -> 50.88 | J20: =IF(L20>0,L20,0) -> 6.52 | K20: =I20+J20 -> 57.4 | L20: =F20-(I20-X20) -> 6.52 | M20: 4.4 | O20: 0 | P20: =M20-(N20+O20) -> 4.4 | Q20: 0 | R20: 0 | S20: =SUM(P20:R20) -> 4.4 | U20: 0 | V20: 53 | W20: =W19-45-2 -> 3068 | X20: =N20+O20+S20+U20+V20 -> 57.4 | Y20: =IF(L20<0,L20*-1,0) -> 0 | Z20: =X20+Y20 -> 57.4 | AA20: 0 | AB20: 55 | AC20: 21 | AD20: =AD19+1 -> 11
A21: =A20+1 -> 12 | B21: 6909.88 | C21: 321509 | D21: =C21-C20 -> -40 | E21: =C21-152000 -> 169509 | F21: =D21/$D$2 -> -20.166373 | G21: 50 | H21: 0.9 | I21: =G21+H21 -> 50.9 | J21: =IF(L21>0,L21,0) -> 0 | K21: =I21+J21 -> 50.9 | L21: =F21-(I21-X21) -> -13.666373 | M21: 4.4 | O21: 0 | P21: =M21-(N21+O21) -> 4.4 | Q21: 0 | R21: 0 | S21: =SUM(P21:R21) -> 4.4 | U21: 0 | V21: 53 | W21: =W20-45-2 -> 3021 | X21: =N21+O21+S21+U21+V21 -> 57.4 | Y21: =IF(L21<0,L21*-1,0) -> 13.666373 | Z21: =X21+Y21 -> 71.066373 | AA21: 0 | AB21: 50 | AC21: 22 | AD21: =AD20+1 -> 12
A22: 13 | B22: 6909.89 | C22: 321549 | D22: =C22-C21 -> 40 | E22: =C22-152000 -> 169549 | F22: =D22/$D$2 -> 20.166373 | G22: 50 | H22: 0.92 | I22: =G22+H22 -> 50.92 | J22: =IF(L22>0,L22,0) -> 21.646373 | K22: =I22+J22 -> 72.566373 | L22: =F22-(I22-X22) -> 21.646373 | M22: 4.4 | O22: 0 | P22: =M22-(N22+O22) -> 4.4 | Q22: 0 | R22: 0 | S22: =SUM(P22:R22) -> 4.4 | U22: 0 | V22: 48 | W22: =W21-45-2 -> 2974 | X22: =N22+O22+S22+U22+V22 -> 52.4 | Y22: =IF(L22<0,L22*-1,0) -> 0 | Z22: =X22+Y22 -> 52.4 | AA22: 0 | AB22: 51 | AC22: 20 | AD22: =AD21+1 -> 13
A23: =A22+1 -> 14 | B23: 6909.9 | C23: 321588 | D23: =C23-C22 -> 39 | E23: =C23-152000 -> 169588 | F23: =D23/$D$2 -> 19.662213 | G23: 49 | H23: 0.96 | I23: =G23+H23 -> 49.96 | J23: =IF(L23>0,L23,0) -> 19.102213 | K23: =I23+J23 -> 69.062213 | L23: =F23-(I23-X23) -> 19.102213 | M23: 4.4 | O23: 0 | P23: =M23-(N23+O23) -> 4.4 | Q23: 0 | R23: 0 | S23: =SUM(P23:R23) -> 4.4 | U23: 0 | V23: 45 | W23: =W22-V23 -> 2929 | X23: =N23+O23+S23+U23+V23 -> 49.4 | Y23: =IF(L23<0,L23*-1,0) -> 0 | Z23: =X23+Y23 -> 49.4 | AA23: 0 | AB23: 50 | AC23: 23 | AD23: =AD22+1 -> 14
A24: =A23+1 -> 15 | B24: 6909.91 | C24: 321628 | D24: =C24-C23 -> 40 | E24: =C24-152000 -> 169628 | F24: =D24/$D$2 -> 20.166373 | G24: 48 | H24: 1.1 | I24: =G24+H24 -> 49.1 | J24: =IF(L24>0,L24,0) -> 20.466373 | K24: =I24+J24 -> 69.566373 | L24: =F24-(I24-X24) -> 20.466373 | M24: 4.4 | O24: 0 | P24: =M24-(N24+O24) -> 4.4 | Q24: 0 | R24: 0 | S24: =SUM(P24:R24) -> 4.4 | U24: 0 | V24: 45 | W24: =W23-V24 -> 2884 | X24: =N24+O24+S24+U24+V24 -> 49.4 | Y24: =IF(L24<0,L24*-1,0) -> 0 | Z24: =X24+Y24 -> 49.4 | AA24: 0 | AB24: 58 | AC24: 22 | AD24: =AD23+1 -> 15
A25: =A24+1 -> 16 | B25: 6909.92 | C25: 321668 | D25: =C25-C24 -> 40 | E25: =C25-152000 -> 169668 | F25: =D25/$D$2 -> 20.166373 | G25: 49 | H25: 1.4 | I25: =G25+H25 -> 50.4 | J25: =IF(L25>0,L25,0) -> 19.166373 | K25: =I25+J25 -> 69.566373 | L25: =F25-(I25-X25) -> 19.166373 | M25: 4.4 | O25: 0 | P25: =M25-(N25+O25) -> 4.4 | Q25: 0 | R25: 0 | S25: =SUM(P25:R25) -> 4.4 | U25: 0 | V25: 45 | W25: =W24-V25 -> 2839 | X25: =N25+O25+S25+U25+V25 -> 49.4 | Y25: =IF(L25<0,L25*-1,0) -> 0 | Z25: =X25+Y25 -> 49.4 | AA25: 0 | AB25: 60 | AC25: 28 | AD25: =AD24+1 -> 16
A26: =A25+1 -> 17 | B26: 6909.93 | C26: 321708 | D26: =C26-C25 -> 40 | E26: =C26-152000 -> 169708 | F26: =D26/$D$2 -> 20.166373 | G26: 50 | H26: 1.7 | I26: =G26+H26 -> 51.7 | J26: =IF(L26>0,L26,0) -> 17.666373 | K26: =I26+J26 -> 69.366373 | L26: =F26-(I26-X26) -> 17.666373 | M26: 4.2 | O26: 0 | P26: =M26-(N26+O26) -> 4.2 | Q26: 0 | R26: 0 | S26: =SUM(P26:R26) -> 4.2 | U26: 0 | V26: 45 | W26: =W25-V26 -> 2794 | X26: =N26+O26+S26+U26+V26 -> 49.2 | Y26: =IF(L26<0,L26*-1,0) -> 0 | Z26: =X26+Y26 -> 49.2 | AA26: 0 | AB26: 45 | AC26: 36 | AD26: =AD25+1 -> 17
A27: =A26+1 -> 18 | B27: 6909.93 | C27: 321708 | D27: =C27-C26 -> 0 | E27: =C27-152000 -> 169708 | F27: =D27/$D$2 -> 0 | G27: 50 | H27: 1.8 | I27: =G27+H27 -> 51.8 | J27: =IF(L27>0,L27,0) -> 7.2 | K27: =I27+J27 -> 59 | L27: =F27-(I27-X27) -> 7.2 | M27: 14 | N27: 10.08 | O27: 0 | P27: =M27-(N27+O27) -> 3.92 | Q27: 0 | R27: 0 | S27: =SUM(P27:R27) -> 3.92 | U27: 0 | V27: 45 | W27: =W26-V27 -> 2749 | X27: =N27+O27+S27+U27+V27 -> 59 | Y27: =IF(L27<0,L27*-1,0) -> 0 | Z27: =X27+Y27 -> 59 | AA27: 0 | AB27: 50 | AC27: 37 | AD27: =AD26+1 -> 18
A28: =A27+1 -> 19 | B28: 6909.94 | C28: 321748 | D28: =C28-C27 -> 40 | E28: =C28-152000 -> 169748 | F28: =D28/$D$2 -> 20.166373 | G28: 50 | H28: 1.4 | I28: =G28+H28 -> 51.4 | J28: =IF(L28>0,L28,0) -> 19.766373 | K28: =I28+J28 -> 71.166373 | L28: =F28-(I28-X28) -> 19.766373 | M28: 6 | N28: 2.03 | O28: 0 | P28: =M28-(N28+O28) -> 3.97 | Q28: 0 | R28: 0 | S28: =SUM(P28:R28) -> 3.97 | U28: 0 | V28: 45 | W28: =W27-V28 -> 2704 | X28: =N28+O28+S28+U28+V28 -> 51 | Y28: =IF(L28<0,L28*-1,0) -> 0 | Z28: =X28+Y28 -> 51 | AA28: 0 | AB28: 56 | AC28: 28 | AD28: =AD27+1 -> 19
A29: =A28+1 -> 20 | B29: 6909.94 | C29: 321748 | D29: =C29-C28 -> 0 | E29: =C29-152000 -> 169748 | F29: =D29/$D$2 -> 0 | G29: 50 | H29: 1.3 | I29: =G29+H29 -> 51.3 | J29: =IF(L29>0,L29,0) -> 3.6 | K29: =I29+J29 -> 54.9 | L29: =F29-(I29-X29) -> 3.6 | M29: 9.9 | N29: 4.64 | O29: 0 | P29: =M29-(N29+O29) -> 5.26 | Q29: 0 | R29: 0 | S29: =SUM(P29:R29) -> 5.26 | U29: 0 | V29: 45 | W29: =W28-V29 -> 2659 | X29: =N29+O29+S29+U29+V29 -> 54.9 | Y29: =IF(L29<0,L29*-1,0) -> 0 | Z29: =X29+Y29 -> 54.9 | AA29: 0 | AB29: 48 | AC29: 30 | AD29: =AD28+1 -> 20
A30: =A29+1 -> 21 | B30: 6909.94 | C30: 321748 | D30: =C30-C29 -> 0 | E30: =C30-152000 -> 169748 | F30: =D30/$D$2 -> 0 | G30: 50 | H30: 1.2 | I30: =G30+H30 -> 51.2 | J30: =IF(L30>0,L30,0) -> 4.8 | K30: =I30+J30 -> 56 | L30: =F30-(I30-X30) -> 4.8 | M30: 11 | N30: 7.42 | O30: 0 | P30: =M30-(N30+O30) -> 3.58 | Q30: 0 | R30: 0 | S30: =SUM(P30:R30) -> 3.58 | U30: 0 | V30: 45 | W30: =W29-V30 -> 2614 | X30: =N30+O30+S30+U30+V30 -> 56 | Y30: =IF(L30<0,L30*-1,0) -> 0 | Z30: =X30+Y30 -> 56 | AA30: 0 | AB30: 50 | AC30: 33 | AD30: =AD29+1 -> 21
A31: =A30+1 -> 22 | B31: 6909.95 | C31: 321787 | D31: =C31-C30 -> 39 | E31: =C31-152000 -> 169787 | F31: =D31/$D$2 -> 19.662213 | G31: 50 | H31: 1.1 | I31: =G31+H31 -> 51.1 | J31: =IF(L31>0,L31,0) -> 24.562213 | K31: =I31+J31 -> 75.662213 | L31: =F31-(I31-X31) -> 24.562213 | M31: 11 | N31: 7.42 | O31: 0 | P31: =M31-(N31+O31) -> 3.58 | Q31: 0 | R31: 0 | S31: =SUM(P31:R31) -> 3.58 | U31: 0 | V31: 45 | W31: =W30-V31 -> 2569 | X31: =N31+O31+S31+U31+V31 -> 56 | Y31: =IF(L31<0,L31*-1,0) -> 0 | Z31: =X31+Y31 -> 56 | AA31: 0 | AB31: 50 | AC31: 24 | AD31: =AD30+1 -> 22
A32: =A31+1 -> 23 | B32: 6909.95 | C32: 321787 | D32: =C32-C31 -> 0 | E32: =C32-152000 -> 169787 | F32: =D32/$D$2 -> 0 | G32: 48 | H32: 1 | I32: =G32+H32 -> 49 | J32: =IF(L32>0,L32,0) -> 7 | K32: =I32+J32 -> 56 | L32: =F32-(I32-X32) -> 7 | M32: 11 | N32: 7.42 | O32: 0 | P32: =M32-(N32+O32) -> 3.58 | Q32: 0 | R32: 0 | S32: =SUM(P32:R32) -> 3.58 | U32: 0 | V32: 45 | W32: =W31-V32 -> 2524 | X32: =N32+O32+S32+U32+V32 -> 56 | Y32: =IF(L32<0,L32*-1,0) -> 0 | Z32: =X32+Y32 -> 56 | AA32: 0 | AB32: 52 | AC32: 20 | AD32: =AD31+1 -> 23
A33: =A32+1 -> 24 | B33: 6909.98 | C33: 321907 | D33: =C33-C32 -> 120 | E33: =C33-152000 -> 169907 | F33: =D33/$D$2 -> 60.499118 | G33: 49 | H33: 1.4 | I33: =G33+H33 -> 50.4 | J33: =IF(L33>0,L33,0) -> 66.099118 | K33: =I33+J33 -> 116.49912 | L33: =F33-(I33-X33) -> 66.099118 | M33: 11 | N33: 7.42 | O33: 0 | P33: =M33-(N33+O33) -> 3.58 | Q33: 0 | R33: 0 | S33: =SUM(P33:R33) -> 3.58 | U33: 0 | V33: 45 | W33: =W32-V33 -> 2479 | X33: =N33+O33+S33+U33+V33 -> 56 | Y33: =IF(L33<0,L33*-1,0) -> 0 | Z33: =X33+Y33 -> 56 | AA33: 0.04 | AB33: 36 | AC33: 30 | AD33: =AD32+1 -> 24
A34: =A33+1 -> 25 | B34: 6910.02 | C34: 322067 | D34: =C34-C33 -> 160 | E34: =C34-152000 -> 170067 | F34: =D34/$D$2 -> 80.66549 | G34: 50 | H34: 1.5 | I34: =G34+H34 -> 51.5 | J34: =IF(L34>0,L34,0) -> 85.16549 | K34: =I34+J34 -> 136.66549 | L34: =F34-(I34-X34) -> 85.16549 | M34: 11 | N34: 6.9 | O34: 0 | P34: =M34-(N34+O34) -> 4.1 | Q34: 0 | R34: 0 | S34: =SUM(P34:R34) -> 4.1 | U34: 0 | V34: 45 | W34: =W33-V34 -> 2434 | X34: =N34+O34+S34+U34+V34 -> 56 | Y34: =IF(L34<0,L34*-1,0) -> 0 | Z34: =X34+Y34 -> 56 | AA34: 0.37 | AB34: 37 | AC34: 29 | AD34: =AD33+1 -> 25
A35: =A34+1 -> 26 | B35: 6910.07 | C35: 322267 | D35: =C35-C34 -> 200 | E35: =C35-152000 -> 170267 | F35: =D35/$D$2 -> 100.83186 | G35: 50 | H35: 1.8 | I35: =G35+H35 -> 51.8 | J35: =IF(L35>0,L35,0) -> 105.03186 | K35: =I35+J35 -> 156.83186 | L35: =F35-(I35-X35) -> 105.03186 | M35: 12 | N35: 7.93 | O35: 0 | P35: =M35-(N35+O35) -> 4.07 | Q35: 0 | R35: 0 | S35: =SUM(P35:R35) -> 4.07 | U35: 0 | V35: 44 | W35: =W34-V35 -> 2390 | X35: =N35+O35+S35+U35+V35 -> 56 | Y35: =IF(L35<0,L35*-1,0) -> 0 | Z35: =X35+Y35 -> 56 | AA35: 0.37 | AB35: 42 | AC35: 24 | AD35: =AD34+1 -> 26
A36: =A35+1 -> 27 | B36: 6910.06 | C36: 322227 | D36: =C36-C35 -> -40 | E36: =C36-152000 -> 170227 | F36: =D36/$D$2 -> -20.166373 | G36: 50 | H36: 2.2 | I36: =G36+H36 -> 52.2 | J36: =IF(L36>0,L36,0) -> 0 | K36: =I36+J36 -> 52.2 | L36: =F36-(I36-X36) -> -18.546373 | M36: 9.82 | N36: 5.12 | O36: 0 | P36: =M36-(N36+O36) -> 4.7 | Q36: 0 | R36: 0 | S36: =SUM(P36:R36) -> 4.7 | U36: 0 | V36: 44 | W36: =W35-V36 -> 2346 | X36: =N36+O36+S36+U36+V36 -> 53.82 | Y36: =IF(L36<0,L36*-1,0) -> 18.546373 | Z36: =X36+Y36 -> 72.366373 | AA36: 0 | AB36: 34 | AC36: 18 | AD36: =AD35+1 -> 27
A37: =A36+1 -> 28 | B37: 6910.05 | C37: 322187 | D37: =C37-C36 -> -40 | E37: =C37-152000 -> 170187 | F37: =D37/$D$2 -> -20.166373 | G37: 50 | H37: 1.6 | I37: =G37+H37 -> 51.6 | J37: =IF(L37>0,L37,0) -> 0 | K37: =I37+J37 -> 51.6 | L37: =F37-(I37-X37) -> -21.116373 | M37: 6.65 | O37: 0 | P37: =M37-(N37+O37) -> 6.65 | Q37: 0 | R37: 0 | S37: =SUM(P37:R37) -> 6.65 | U37: 0 | V37: 44 | W37: =W36-V37 -> 2302 | X37: =N37+O37+S37+U37+V37 -> 50.65 | Y37: =IF(L37<0,L37*-1,0) -> 21.116373 | Z37: =X37+Y37 -> 71.766373 | AA37: 0 | AB37: 35 | AC37: 10 | AD37: =AD36+1 -> 28
A38: =A37+1 -> 29 | B38: 6910.06 | C38: 322227 | D38: =C38-C37 -> 40 | E38: =C38-152000 -> 170227 | F38: =D38/$D$2 -> 20.166373 | G38: 48 | H38: 1.4 | I38: =G38+H38 -> 49.4 | J38: =IF(L38>0,L38,0) -> 21.056373 | K38: =I38+J38 -> 70.456373 | L38: =F38-(I38-X38) -> 21.056373 | M38: 6.29 | O38: 0 | P38: =M38-(N38+O38) -> 6.29 | Q38: 0 | R38: 0 | S38: =SUM(P38:R38) -> 6.29 | U38: 0 | V38: 44 | W38: =W37-V38 -> 2258 | X38: =N38+O38+S38+U38+V38 -> 50.29 | Y38: =IF(L38<0,L38*-1,0) -> 0 | Z38: =X38+Y38 -> 50.29 | AA38: 0 | AB38: 40 | AC38: 11 | AD38: =AD37+1 -> 29
A39: 30 | B39: 6910.07 | C39: 322267 | D39: =C39-C38 -> 40 | E39: =C39-152000 -> 170267 | F39: =D39/$D$2 -> 20.166373 | G39: 49 | H39: 1.3 | I39: =G39+H39 -> 50.3 | J39: =IF(L39>0,L39,0) -> 20.156373 | K39: =I39+J39 -> 70.456373 | L39: =F39-(I39-X39) -> 20.156373 | M39: 6.29 | O39: 0 | P39: =M39-(N39+O39) -> 6.29 | Q39: 0 | R39: 0 | S39: =SUM(P39:R39) -> 6.29 | U39: 0 | V39: 44 | W39: =W38-V39 -> 2214 | X39: =N39+O39+S39+U39+V39 -> 50.29 | Y39: =IF(L39<0,L39*-1,0) -> 0 | Z39: =X39+Y39 -> 50.29 | AA39: 0 | AB39: 42 | AC39: 11 | AD39: 30
A40: 31 | B40: 6910.07 | C40: 322267 | D40: =C40-C39 -> 0 | E40: =C40-152000 -> 170267 | F40: =D40/$D$2 -> 0 | G40: 50 | H40: 1.2 | I40: =G40+H40 -> 51.2 | J40: =IF(L40>0,L40,0) -> 0 | K40: =I40+J40 -> 51.2 | L40: =F40-(I40-X40) -> -1.69 | M40: 5.51 | O40: 0 | P40: =M40-(N40+O40) -> 5.51 | Q40: 0 | R40: 0 | S40: =SUM(P40:R40) -> 5.51 | U40: 0 | V40: 44 | W40: =W39-V40 -> 2170 | X40: =N40+O40+S40+U40+V40 -> 49.51 | Y40: =IF(L40<0,L40*-1,0) -> 1.69 | Z40: =X40+Y40 -> 51.2 | AA40: 0.15 | AB40: 31 | AC40: 26 | AD40: 31
AB41: 39
A42: MONTH / CFS | F42: =SUM(F10:F40) -> 281.82506 | G42: =SUM(G10:G40) -> 1537 | H42: =SUM(H10:H40) -> 35.32 | I42: =SUM(I10:I40) -> 1572.32 | J42: =SUM(J10:J40) -> 510.00551 | K42: =SUM(K10:K40) -> 2082.3255 | L42: =SUM(L10:L40) -> 403.56506 | M42: =SUM(M10:M40) -> 206.06 | ... S42: =SUM(S10:S40) -> 139.68 | U42: =SUM(U10:U40) -> 0 | V42: =SUM(V10:V40) -> 1488 | X42: =SUM(X10:X40) -> 1694.06 | Y42: =SUM(Y10:Y40) -> 106.44045 | Z42: =SUM(Z10:Z40) -> 1800.5004 | AA42: =SUM(AA10:AA40) -> 1.36 | AB42: =AVERAGE(AB10:AB40) -> 42.516129 | AC42: =AVERAGE(AC10:AC40) -> 18.741935 | AD42: AVE
A43: MONTH / AF | D43: =SUM(D10:D40) -> 559 | F43: =F42*$D$2 -> 559 | G43: =G42*$D$2 -> 3048.6395 | H43: =H42*$D$2 -> 70.05722 | I43: =I42*$D$2 -> 3118.6967 | J43: =J42*$D$2 -> 1011.5959 | K43: =K42*$D$2 -> 4130.2926 | L43: =L42*$D$2 -> 800.47129 | M43: =M42*$D$2 -> 408.72001 | ... S43: =S42*$D$2 -> 277.05528 | U43: =U42*$D$2 -> 0 | V43: =V42*$D$2 -> 2951.448 | X43: =X42*$D$2 -> 3360.168 | Y43: =Y42*$D$2 -> 211.12463 | Z43: =Z42*$D$2 -> 3571.2926 | AB43: =MAX(AB10:AB40) -> 60 | AC43: =MAX(AC10:AC40) -> 37 | AD43: HI
...

Sheet FEB
K1: MC PHEE RESERVOIR IN/OUT FLOW TABULATION
A2: AF/cfs CONVERT FACTOR | D2: 1.9835 | K2: FEBRUARY "2000"
A4: DATE | B4: RESERV | C4: RESERV | D4: AC FT | E4: ACTIVE | F4: CONV TO | G4: DOLORES | H4: LOST | I4: RECORDED | J4: CALC | K4: TOTAL | L4: CALC | M4: DOLORES TUNNEL | Q4: LONE | R4: U | S4: TOTAL | T4: MVI | U4: DV CR | V4: BELOW | W4: REMAIN | X4: RECORDED | Y4: CALC | Z4: TOTAL | AA4: RAIN | AB4: MAX | AC4: MIN | AD4: DATE
A5: FEB | B5: ELEV | C5: AC FT | D5: CHANGE | E5: CAP | F5: CFS | G5: RIVER | H5: CANYON | I5: INFLOW | J5: INFLOW | K5: INFLOW | L5: INF/OTF | M5: TOT DIV | N5: WETLAND | O5: UTE F&R | P5: MVI,CTZ | Q5: PINE | R5: LAT | S5: MVI | T5: CALL | U5: CANAL | V5: MC PHEE | W5: RELEASE | X5: OUTFLOW | Y5: OUTFLOW | Z5: OUTFLOW | AB5: TMP | AC5: TMP | AD5: FEB
A7: SEASON BAL
A8: YTD | B8: =JAN!B40 -> 6910.07 | C8: =JAN!C40 -> 322267 | D8: =JAN!$D$49 -> -7413 | E8: =JAN!$E$40 -> 170267 | F8: =JAN!F48 -> -3737.333 | G8: =JAN!G48 -> 4699 | H8: =JAN!H48 -> 82.38 | I8: =JAN!I48 -> 4781.38 | J8: =JAN!J48 -> 826.76403 | K8: =JAN!K48 -> 5608.144 | L8: =JAN!L48 -> 253.217 | M8: =JAN!M48 -> 1867.96 | ... AA8: =JAN!AA48 -> 1.74
A10: 1 | B10: 6910.08 | C10: 322307 | D10: =C10-C8 -> 40 | E10: =C10-152000 -> 170307 | F10: =D10/$D$2 -> 20.166373 | G10: 51 | H10: 1.2 | I10: =G10+H10 -> 52.2 | J10: =IF(L10>0,L10,0) -> 16.466373 | K10: =I10+J10 -> 68.666373 | L10: =F10-(I10-X10) -> 16.466373 | M10: 4.5 | N10: 0 | O10: 0 | P10: =M10-(N10+O10) -> 4.5 | Q10: 0 | R10: 0 | S10: =SUM(P10:R10) -> 4.5 | U10: 0 | V10: 44 | W10: =W8-40-2 -> 2128 | X10: =N10+O10+S10+U10+V10 -> 48.5 | Y10: =IF(L10<0,L10*-1,0) -> 0 | Z10: =X10+Y10 -> 48.5 | AA10: 0 | AB10: 46 | AC10: 10 | AD10: 1
A11: =A10+1 -> 2 | B11: 6910.08 | C11: 322307 | D11: =C11-C10 -> 0 | E11: =C11-152000 -> 170307 | F11: =D11/$D$2 -> 0 | G11: 50 | H11: 1.2 | I11: =G11+H11 -> 51.2 | J11: =IF(L11>0,L11,0) -> 0 | K11: =I11+J11 -> 51.2 | L11: =F11-(I11-X11) -> -4.3 | M11: 3.9 | N11: 0 | O11: 0 | P11: =M11-(N11+O11) -> 3.9 | Q11: 0 | R11: 0 | S11: =SUM(P11:R11) -> 3.9 | U11: 0 | V11: 43 | W11: =W10-40-2 -> 2086 | X11: =N11+O11+S11+U11+V11 -> 46.9 | Y11: =IF(L11<0,L11*-1,0) -> 4.3 | Z11: =X11+Y11 -> 51.2 | AA11: 0 | AB11: 48 | AC11: 8 | AD11: =AD10+1 -> 2
A12: =A11+1 -> 3 | B12: 6910.09 | C12: 322348 | D12: =C12-C11 -> 41 | E12: =C12-152000 -> 170348 | F12: =D12/$D$2 -> 20.670532 | G12: 51 | H12: 1.2 | I12: =G12+H12 -> 52.2 | J12: =IF(L12>0,L12,0) -> 15.170532 | K12: =I12+J12 -> 67.370532 | L12: =F12-(I12-X12) -> 15.170532 | M12: 3.7 | N12: 0 | O12: 0 | P12: =M12-(N12+O12) -> 3.7 | Q12: 0 | R12: 0 | S12: =SUM(P12:R12) -> 3.7 | U12: 0 | V12: 43 | W12: =W11-40-2 -> 2044 | X12: =N12+O12+S12+U12+V12 -> 46.7 | Y12: =IF(L12<0,L12*-1,0) -> 0 | Z12: =X12+Y12 -> 46.7 | AA12: 0 | AB12: 50 | AC12: 22 | AD12: =AD11+1 -> 3
A13: =A12+1 -> 4 | B13: 6910.1 | C13: 322388 | D13: =C13-C12 -> 40 | E13: =C13-152000 -> 170388 | F13: =D13/$D$2 -> 20.166373 | G13: 52 | H13: 1.2 | I13: =G13+H13 -> 53.2 | J13: =IF(L13>0,L13,0) -> 13.666373 | K13: =I13+J13 -> 66.866373 | L13: =F13-(I13-X13) -> 13.666373 | M13: 3.7 | N13: 0 | O13: 0 | P13: =M13-(N13+O13) -> 3.7 | Q13: 0 | R13: 0 | S13: =SUM(P13:R13) -> 3.7 | U13: 0 | V13: 43 | W13: =W12-40-2 -> 2002 | X13: =N13+O13+S13+U13+V13 -> 46.7 | Y13: =IF(L13<0,L13*-1,0) -> 0 | Z13: =X13+Y13 -> 46.7 | AA13: 0 | AB13: 47 | AC13: 24 | AD13: =AD12+1 -> 4
A14: =A13+1 -> 5 | B14: 6910.1 | C14: 322388 | D14: =C14-C13 -> 0 | E14: =C14-152000 -> 170388 | F14: =D14/$D$2 -> 0 | G14: 52 | H14: 1.2 | I14: =G14+H14 -> 53.2 | J14: =IF(L14>0,L14,0) -> 0 | K14: =I14+J14 -> 53.2 | L14: =F14-(I14-X14) -> -6.5 | M14: 3.7 | N14: 0 | O14: 0 | P14: =M14-(N14+O14) -> 3.7 | Q14: 0 | R14: 0 | S14: =SUM(P14:R14) -> 3.7 | U14: 0 | V14: 43 | W14: =W13-40-2 -> 1960 | X14: =N14+O14+S14+U14+V14 -> 46.7 | Y14: =IF(L14<0,L14*-1,0) -> 6.5 | Z14: =X14+Y14 -> 53.2 | AA14: 0 | AB14: 52 | AC14: 23 | AD14: =AD13+1 -> 5
A15: =A14+1 -> 6 | B15: 6910.11 | C15: 322428 | D15: =C15-C14 -> 40 | E15: =C15-152000 -> 170428 | F15: =D15/$D$2 -> 20.166373 | G15: 52 | H15: 1.1 | I15: =G15+H15 -> 53.1 | J15: =IF(L15>0,L15,0) -> 13.866373 | K15: =I15+J15 -> 66.966373 | L15: =F15-(I15-X15) -> 13.866373 | M15: 3.8 | N15: 0 | O15: 0 | P15: =M15-(N15+O15) -> 3.8 | Q15: 0 | R15: 0 | S15: =SUM(P15:R15) -> 3.8 | U15: 0 | V15: 43 | W15: =W14-40-2 -> 1918 | X15: =N15+O15+S15+U15+V15 -> 46.8 | Y15: =IF(L15<0,L15*-1,0) -> 0 | Z15: =X15+Y15 -> 46.8 | AA15: 0 | AB15: 58 | AC15: 26 | AD15: =AD14+1 -> 6
A16: =A15+1 -> 7 | B16: 6910.11 | C16: 322428 | D16: =C16-C15 -> 0 | E16: =C16-152000 -> 170428 | F16: =D16/$D$2 -> 0 | G16: 52 | H16: 1.1 | I16: =G16+H16 -> 53.1 | J16: =IF(L16>0,L16,0) -> 0 | K16: =I16+J16 -> 53.1 | L16: =F16-(I16-X16) -> -6 | M16: 4.1 | N16: 0 | O16: 0 | P16: =M16-(N16+O16) -> 4.1 | Q16: 0 | R16: 0 | S16: =SUM(P16:R16) -> 4.1 | U16: 0 | V16: 43 | W16: =W15-40-2 -> 1876 | X16: =N16+O16+S16+U16+V16 -> 47.1 | Y16: =IF(L16<0,L16*-1,0) -> 6 | Z16: =X16+Y16 -> 53.1 | AA16: 0 | AB16: 50 | AC16: 26 | AD16: =AD15+1 -> 7
A17: =A16+1 -> 8 | B17: 6910.12 | C17: 322468 | D17: =C17-C16 -> 40 | E17: =C17-152000 -> 170468 | F17: =D17/$D$2 -> 20.166373 | G17: 53 | H17: 1.2 | I17: =G17+H17 -> 54.2 | J17: =IF(L17>0,L17,0) -> 12.066373 | K17: =I17+J17 -> 66.266373 | L17: =F17-(I17-X17) -> 12.066373 | M17: 4.1 | N17: 0 | O17: 0 | P17: =M17-(N17+O17) -> 4.1 | Q17: 0 | R17: 0 | S17: =SUM(P17:R17) -> 4.1 | U17: 0 | V17: 42 | W17: =W16-V17 -> 1834 | X17: =N17+O17+S17+U17+V17 -> 46.1 | Y17: =IF(L17<0,L17*-1,0) -> 0 | Z17: =X17+Y17 -> 46.1 | AA17: 0 | AB17: 59 | AC17: 24 | AD17: =AD16+1 -> 8
A18: =A17+1 -> 9 | B18: 6910.12 | C18: 322468 | D18: =C18-C17 -> 0 | E18: =C18-152000 -> 170468 | F18: =D18/$D$2 -> 0 | G18: 55 | H18: 1.4 | I18: =G18+H18 -> 56.4 | J18: =IF(L18>0,L18,0) -> 0 | K18: =I18+J18 -> 56.4 | L18: =F18-(I18-X18) -> -11.3 | M18: 4.1 | N18: 0 | O18: 0 | P18: =M18-(N18+O18) -> 4.1 | Q18: 0 | R18: 0 | S18: =SUM(P18:R18) -> 4.1 | U18: 0 | V18: 41 | W18: =W17-V18 -> 1793 | X18: =N18+O18+S18+U18+V18 -> 45.1 | Y18: =IF(L18<0,L18*-1,0) -> 11.3 | Z18: =X18+Y18 -> 56.4 | AA18: 0 | AB18: 45 | AC18: 25 | AD18: =AD17+1 -> 9
A19: =A18+1 -> 10 | B19: 6910.15 | C19: 322588 | D19: =C19-C18 -> 120 | E19: =C19-152000 -> 170588 | F19: =D19/$D$2 -> 60.499118 | G19: 55 | H19: 1.6 | I19: =G19+H19 -> 56.6 | J19: =IF(L19>0,L19,0) -> 48.999118 | K19: =I19+J19 -> 105.59912 | L19: =F19-(I19-X19) -> 48.999118 | M19: 4.1 | N19: 0 | O19: 0 | P19: =M19-(N19+O19) -> 4.1 | Q19: 0 | R19: 0 | S19: =SUM(P19:R19) -> 4.1 | U19: 0 | V19: 41 | W19: =W18-V19 -> 1752 | X19: =N19+O19+S19+U19+V19 -> 45.1 | Y19: =IF(L19<0,L19*-1,0) -> 0 | Z19: =X19+Y19 -> 45.1 | AA19: 0.21 | AB19: 47 | AC19: 34 | AD19: =AD18+1 -> 10
A20: =A19+1 -> 11 | B20: 6910.17 | C20: 322669 | D20: =C20-C19 -> 81 | E20: =C20-152000 -> 170669 | F20: =D20/$D$2 -> 40.836904 | G20: 54 | H20: 1.5 | I20: =G20+H20 -> 55.5 | J20: =IF(L20>0,L20,0) -> 30.436904 | K20: =I20+J20 -> 85.936904 | L20: =F20-(I20-X20) -> 30.436904 | M20: 4.1 | N20: 0 | O20: 0 | P20: =M20-(N20+O20) -> 4.1 | Q20: 0 | R20: 0 | S20: =SUM(P20:R20) -> 4.1 | U20: 0 | V20: 41 | W20: =W19-V20 -> 1711 | X20: =N20+O20+S20+U20+V20 -> 45.1 | Y20: =IF(L20<0,L20*-1,0) -> 0 | Z20: =X20+Y20 -> 45.1 | AA20: 0 | AB20: 44 | AC20: 33 | AD20: =AD19+1 -> 11
A21: =A20+1 -> 12 | B21: 6910.21 | C21: 322829 | D21: =C21-C20 -> 160 | E21: =C21-152000 -> 170829 | F21: =D21/$D$2 -> 80.66549 | G21: 53 | H21: 1.4 | I21: =G21+H21 -> 54.4 | J21: =IF(L21>0,L21,0) -> 71.36549 | K21: =I21+J21 -> 125.76549 | L21: =F21-(I21-X21) -> 71.36549 | M21: 4.1 | N21: 0 | O21: 0 | P21: =M21-(N21+O21) -> 4.1 | Q21: 0 | R21: 0 | S21: =SUM(P21:R21) -> 4.1 | U21: 0 | V21: 41 | W21: =W20-V21 -> 1670 | X21: =N21+O21+S21+U21+V21 -> 45.1 | Y21: =IF(L21<0,L21*-1,0) -> 0 | Z21: =X21+Y21 -> 45.1 | AA21: 0.45 | AB21: 40 | AC21: 32 | AD21: =AD20+1 -> 12
A22: =A21+1 -> 13 | B22: 6910.23 | C22: 322909 | D22: =C22-C21 -> 80 | E22: =C22-152000 -> 170909 | F22: =D22/$D$2 -> 40.332745 | G22: 55 | H22: 1.4 | I22: =G22+H22 -> 56.4 | J22: =IF(L22>0,L22,0) -> 29.032745 | K22: =I22+J22 -> 85.432745 | L22: =F22-(I22-X22) -> 29.032745 | M22: 4.1 | N22: 0 | O22: 0 | P22: =M22-(N22+O22) -> 4.1 | Q22: 0 | R22: 0 | S22: =SUM(P22:R22) -> 4.1 | U22: 0 | V22: 41 | W22: =W21-V22 -> 1629 | X22: =N22+O22+S22+U22+V22 -> 45.1 | Y22: =IF(L22<0,L22*-1,0) -> 0 | Z22: =X22+Y22 -> 45.1 | AA22: 0 | AB22: 39 | AC22: 27 | AD22: =AD21+1 -> 13
A23: =A22+1 -> 14 | B23: 6910.25 | C23: 322990 | D23: =C23-C22 -> 81 | E23: =C23-152000 -> 170990 | F23: =D23/$D$2 -> 40.836904 | G23: 56 | H23: 1.4 | I23: =G23+H23 -> 57.4 | J23: =IF(L23>0,L23,0) -> 28.536904 | K23: =I23+J23 -> 85.936904 | L23: =F23-(I23-X23) -> 28.536904 | M23: 4.1 | N23: 0 | O23: 0 | P23: =M23-(N23+O23) -> 4.1 | Q23: 0 | R23: 0 | S23: =SUM(P23:R23) -> 4.1 | U23: 0 | V23: 41 | W23: =W22-V23 -> 1588 | X23: =N23+O23+S23+U23+V23 -> 45.1 | Y23: =IF(L23<0,L23*-1,0) -> 0 | Z23: =X23+Y23 -> 45.1 | AA23: 0 | AB23: 41 | AC23: 32 | AD23: =AD22+1 -> 14
A24: =A23+1 -> 15 | B24: 6910.27 | C24: 323070 | D24: =C24-C23 -> 80 | E24: =C24-152000 -> 171070 | F24: =D24/$D$2 -> 40.332745 | G24: 56 | H24: 1.5 | I24: =G24+H24 -> 57.5 | J24: =IF(L24>0,L24,0) -> 27.932745 | K24: =I24+J24 -> 85.432745 | L24: =F24-(I24-X24) -> 27.932745 | M24: 4.1 | N24: 0 | O24: 0 | P24: =M24-(N24+O24) -> 4.1 | Q24: 0 | R24: 0 | S24: =SUM(P24:R24) -> 4.1 | U24: 0 | V24: 41 | W24: =W23-V24 -> 1547 | X24: =N24+O24+S24+U24+V24 -> 45.1 | Y24: =IF(L24<0,L24*-1,0) -> 0 | Z24: =X24+Y24 -> 45.1 | AA24: 0 | AB24: 54 | AC24: 22 | AD24: =AD23+1 -> 15
A25: =A24+1 -> 16 | B25: 6910.3 | C25: 323190 | D25: =C25-C24 -> 120 | E25: =C25-152000 -> 171190 | F25: =D25/$D$2 -> 60.499118 | G25: 57 | H25: 1.8 | I25: =G25+H25 -> 58.8 | J25: =IF(L25>0,L25,0) -> 45.999118 | K25: =I25+J25 -> 104.79912 | L25: =F25-(I25-X25) -> 45.999118 | M25: 4.3 | N25: 0 | O25: 0 | P25: =M25-(N25+O25) -> 4.3 | Q25: 0 | R25: 0 | S25: =SUM(P25:R25) -> 4.3 | U25: 0 | V25: 40 | W25: =W24-V25 -> 1507 | X25: =N25+O25+S25+U25+V25 -> 44.3 | Y25: =IF(L25<0,L25*-1,0) -> 0 | Z25: =X25+Y25 -> 44.3 | AA25: 0.2 | AB25: 49 | AC25: 30 | AD25: =AD24+1 -> 16
A26: =A25+1 -> 17 | B26: 6910.31 | C26: 323230 | D26: =C26-C25 -> 40 | E26: =C26-152000 -> 171230 | F26: =D26/$D$2 -> 20.166373 | G26: 58 | H26: 1.8 | I26: =G26+H26 -> 59.8 | J26: =IF(L26>0,L26,0) -> 4.7663726 | K26: =I26+J26 -> 64.566373 | L26: =F26-(I26-X26) -> 4.7663726 | M26: 4.4 | N26: 0 | O26: 0 | P26: =M26-(N26+O26) -> 4.4 | Q26: 0 | R26: 0 | S26: =SUM(P26:R26) -> 4.4 | U26: 0 | V26: 40 | W26: =W25-V26 -> 1467 | X26: =N26+O26+S26+U26+V26 -> 44.4 | Y26: =IF(L26<0,L26*-1,0) -> 0 | Z26: =X26+Y26 -> 44.4 | AA26: 0.25 | AB26: 50 | AC26: 26 | AD26: =AD25+1 -> 17
A27: =A26+1 -> 18 | B27: 6910.32 | C27: 323271 | D27: =C27-C26 -> 41 | E27: =C27-152000 -> 171271 | F27: =D27/$D$2 -> 20.670532 | G27: 59 | H27: 1.8 | I27: =G27+H27 -> 60.8 | J27: =IF(L27>0,L27,0) -> 4.2705319 | K27: =I27+J27 -> 65.070532 | L27: =F27-(I27-X27) -> 4.2705319 | M27: 4.4 | N27: 0 | O27: 0 | P27: =M27-(N27+O27) -> 4.4 | Q27: 0 | R27: 0 | S27: =SUM(P27:R27) -> 4.4 | U27: 0 | V27: 40 | W27: =W26-V27 -> 1427 | X27: =N27+O27+S27+U27+V27 -> 44.4 | Y27: =IF(L27<0,L27*-1,0) -> 0 | Z27: =X27+Y27 -> 44.4 | AA27: 0 | AB27: 51 | AC27: 26 | AD27: =AD26+1 -> 18
