Workbook

Sheet NOV
K1: MCPHEE RESERVOIR INFLOW/OUTFLOW TABULATION
A2: AF/cfs CONVERT FACTOR | D2: 1.9835 | L2: NOVEMBER "2011"
D4: RESERVOIR | I4: INFLOW | X4: OUTFLOW | AP4: ADJUSTMENTS | AW4: WEATHER
A5: DATE | B5: RESERV | C5: RESERV | D5: AC FT | E5: ACTIVE | F5: CONV TO | G5: DOLORES | H5: LOST | I5: RECORD | J5: CALC | K5: TOTAL | L5: CALC | M5: DOLORES TUNNEL | V5: LONE | W5: U | X5: TOTAL | Y5: TOTAL | Z5: MVI | AA5: MVI | AB5: MVI | AC5: TO EX & | AD5: MVI | AE5: DV CR | AF5: D/S SENIOR | AH5: BELOW | AI5: FISH | AJ5: SPILL | AK5: RECORD | AL5: CALC | AM5: TOTAL | AN5: NAR | AO5: MVI | AP5: MVI | AQ5: MVI | AR5: DIST. | AS5: U/S | AT5: TOTTEN | AU5: UTES | AV5: RAIN | AW5: MAX | AX5: MIN | AZ5: TOTAL
A6: NOV | B6: ELEV | D6: CHANGE | E6: CAP | F6: CFS | G6: RIVER | H6: CAN | I6: INFLOW | J6: INFLOW | K6: INFLOW | L6: INF/OTF | M6: TOT DIV | N6: WET | O6: UTE | P6: QUEST | Q6: MWC | R6: CORTEZ | T6: UTE | U6: F-BAY | V6: PINE | W6: LAT | X6: MVI | Y6: MVI | Z6: CALL | AA6: CALL | AB6: APR- | AC6: U/S EX | AD6: PROJ | AE6: CANAL | AF6: MVIC | AG6: PROJ | AH6: MCP | AI6: LEFT | AK6: OTF | AL6: OTF | AM6: OTF | AN6: FILL | AO6: STOCK | AP6: STORED | AQ6: STORED | AR6: CLASS | AS6: USERS | AT6: (FRESH | AU6: FROM | AW6: TMP | AX6: TMP | AZ6: TUNNEL
N7: LAND | O7: F&R | Q7: NON - | R7: NON - | S7: PROJ | T7: PROJ | U7: BAL | X7: WATER | Y7: IRRIG. | Z7: STOR | AA7: SPILLED | AB7: JUNE | AF7: 1.7 | AG7: 1.3 | AI7: 31798 | AP7: Apr - Jun | AQ7: EVAP | AR7: "B" | AS7: EXCH | AT7: WATER) | AU7: DWCD | AZ7: Misc.
Q8: PROJ | R8: PROJ | X8: USED | Y8: WATER | AA8: OR | AB8: (DIV+
R9: 4.2 | Y9: USED | AA9: USED | AB9: CALL)
C10: AC. Ft. | E10: AC FT | G10: CFS | H10: CFS | I10: CFS | J10: CFS | K10: CFS | L10: CFS | M10: CFS | N10: CFS | O10: CFS | P10: CFS | Q10: CFS | R10: CFS | S10: CFS | T10: CFS | U10: CFS | V10: CFS | W10: CFS | X10: 153400 | Y10: 150400 | AB10: 72000 | AC10: CFS | AD10: CFS | AE10: CFS | AF10: CFS | AG10: CFS | AH10: CFS | AI10: CFS | AJ10: CFS | AK10: CFS | AL10: CFS | AM10: CFS | AN10: CFS | AO10: CFS | AP10: CFS | AQ10: AC.FT. | AR10: CFS | AS10: CFS | AT10: CFS | AU10: CFS | AZ10: Outflow
N11: 1.03 | O11: 1.05 | P11: 1.02 | Q11: 1.02 | R11: 1.04 | T11: 1.04 | X11: CFS | Y11: CFS | Z11: CFS | AA11: CFS | AB11: Ac. Ft. | AZ11: CFS
A12: SEASON BAL
A13: YTD | B13: 6902.69 | C13: 293611 | AI13: 5351 | AO13: 0
A15: 1 | B15: 6902.67 | C15: 293536 | D15: =C15-C13 -> -75 | E15: =C15-152000 -> 141536 | F15: =D15/$D$2 -> -37.811949 | G15: 80 | H15: 0 | I15: =G15+H15 -> 80 | J15: =IF(L15>0,L15,0) -> 0 | K15: =I15+J15 -> 80 | L15: =F15-(I15-AK15) -> -13.211949 | M15: 3.6 | N15: 0 | O15: 0 | P15: 0 | Q15: =876900/325851/1.9835*1.02 -> 1.3838817 | R15: =((2.4)*1.04)-T15 -> 1.8216619 | S15: 0 | T15: =(0.6117*1.06)*1.04 -> 0.67433808 | U15: =M15-(Q15+R15+S15+T15) -> -0.27988174 | V15: 73 | W15: 0 | X15: =M15-N15-P15-O15-Q15-R15-S15-T15-U15+V15+W15 -> 73 | Y15: =X15-AO15 -> 73 | AC15: 0 | AE15: 0 | AH15: 28 | AI15: =AI13-AH15 -> 5323 | AK15: =N15+O15+P15+Q15+R15+S15+T15+U15+X15+AE15+AH15 -> 104.6 | AL15: =IF(L15<0,L15*-1,0) -> 13.211949 | AM15: =AK15+AL15 -> 117.81195 | AN15: =V15 -> 73 | AU15: =21*1.05 -> 22.05 | AV15: 0 | AW15: 61 | AX15: 35 | AZ15: =SUM(N15,P15:U15) -> 3.6
A16: =A15+1 -> 2 | B16: 6902.65 | C16: 293460 | D16: =C16-C15 -> -76 | E16: =C16-152000 -> 141460 | F16: =D16/$D$2 -> -38.316108 | G16: 80 | H16: 0 | I16: =G16+H16 -> 80 | J16: =IF(L16>0,L16,0) -> 0 | K16: =I16+J16 -> 80 | L16: =F16-(I16-AK16) -> -14.416108 | M16: 3.9 | N16: 0 | O16: 0 | P16: 0 | Q16: =1003000/325851/1.9835*1.02 -> 1.5828867 | R16: =((2.4)*1.04)-T16 -> 1.8216619 | S16: 0 | T16: =(0.6117*1.06)*1.04 -> 0.67433808 | U16: =M16-(Q16+R16+S16+T16) -> -0.17888674 | V16: 72 | W16: 0 | X16: =M16-N16-P16-O16-Q16-R16-S16-T16-U16+V16+W16 -> 72 | Y16: =X16-AO16 -> 72 | AC16: 0 | AE16: 0 | AH16: 28 | AI16: =AI15-AH16 -> 5295 | AK16: =N16+O16+P16+Q16+R16+S16+T16+U16+X16+AE16+AH16 -> 103.9 | AL16: =IF(L16<0,L16*-1,0) -> 14.416108 | AM16: =AK16+AL16 -> 118.31611 | AN16: =V16 -> 72 | AU16: =20*1.05 -> 21 | AV16: 0 | AW16: 48 | AX16: 28 | AZ16: =SUM(N16,P16:U16) -> 3.9
A17: =A16+1 -> 3 | B17: 6902.63 | C17: 293385 | D17: =C17-C16 -> -75 | E17: =C17-152000 -> 141385 | F17: =D17/$D$2 -> -37.811949 | G17: 74 | H17: 0 | I17: =G17+H17 -> 74 | J17: =IF(L17>0,L17,0) -> 0 | K17: =I17+J17 -> 74 | L17: =F17-(I17-AK17) -> -10.911949 | M17: 3.9 | N17: 0 | O17: 0 | P17: 0 | Q17: =1034000/325851/1.9835*1.02 -> 1.6318095 | R17: =((2.2)*1.04)-T17 -> 1.6136619 | S17: 0 | T17: =(0.6117*1.06)*1.04 -> 0.67433808 | U17: =M17-(Q17+R17+S17+T17) -> -0.019809464 | V17: 69 | W17: 0 | X17: =M17-N17-P17-O17-Q17-R17-S17-T17-U17+V17+W17 -> 69 | Y17: =X17-AO17 -> 69 | AC17: 0 | AE17: 0 | AH17: 28 | AI17: =AI16-AH17 -> 5267 | AK17: =N17+O17+P17+Q17+R17+S17+T17+U17+X17+AE17+AH17 -> 100.9 | AL17: =IF(L17<0,L17*-1,0) -> 10.911949 | AM17: =AK17+AL17 -> 111.81195 | AN17: =V17 -> 69 | AU17: =1*1.05 -> 1.05 | AV17: 0 | AW17: 52 | AX17: 23 | AZ17: =SUM(N17,P17:U17) -> 3.9
A18: =A17+1 -> 4 | B18: 6902.61 | C18: 293310 | D18: =C18-C17 -> -75 | E18: =C18-152000 -> 141310 | F18: =D18/$D$2 -> -37.811949 | G18: 73 | H18: 0 | I18: =G18+H18 -> 73 | J18: =IF(L18>0,L18,0) -> 0 | K18: =I18+J18 -> 73 | L18: =F18-(I18-AK18) -> -10.911949 | M18: 3.9 | N18: 0 | O18: 0 | P18: 0 | Q18: =1049700/325851/1.9835*1.02 -> 1.6565865 | R18: =((2.2)*1.04)-T18 -> 1.7244531 | S18: 0 | T18: =(0.5112*1.06)*1.04 -> 0.56354688 | U18: =M18-(Q18+R18+S18+T18) -> -0.044586455 | V18: 68 | W18: 0 | X18: =M18-N18-P18-O18-Q18-R18-S18-T18-U18+V18+W18 -> 68 | Y18: =X18-AO18 -> 68 | AC18: 0 | AE18: 0 | AH18: 28 | AI18: =AI17-AH18 -> 5239 | AK18: =N18+O18+P18+Q18+R18+S18+T18+U18+X18+AE18+AH18 -> 99.9 | AL18: =IF(L18<0,L18*-1,0) -> 10.911949 | AM18: =AK18+AL18 -> 110.81195 | AN18: =V18 -> 68 | AU18: 0 | AV18: 0 | AW18: 54 | AX18: 35 | AZ18: =SUM(N18,P18:U18) -> 3.9
A19: =A18+1 -> 5 | B19: 6902.62 | C19: 293347 | D19: =C19-C18 -> 37 | E19: =C19-152000 -> 141347 | F19: =D19/$D$2 -> 18.653895 | G19: 92 | H19: 0 | I19: =G19+H19 -> 92 | J19: =IF(L19>0,L19,0) -> 26.153895 | K19: =I19+J19 -> 118.15389 | L19: =F19-(I19-AK19) -> 26.153895 | M19: 3.5 | N19: 0 | O19: 0 | P19: 0 | Q19: =884400/325851/1.9835*1.02 -> 1.3957179 | R19: =((2.2)*1.04)-T19 -> 1.7244531 | S19: 0 | T19: =(0.5112*1.06)*1.04 -> 0.56354688 | U19: =M19-(Q19+R19+S19+T19) -> -0.18371788 | V19: 68 | W19: 0 | X19: =M19-N19-P19-O19-Q19-R19-S19-T19-U19+V19+W19 -> 68 | Y19: =X19-AO19 -> 68 | AC19: 0 | AE19: 0 | AH19: 28 | AI19: =AI18-AH19 -> 5211 | AK19: =N19+O19+P19+Q19+R19+S19+T19+U19+X19+AE19+AH19 -> 99.5 | AL19: =IF(L19<0,L19*-1,0) -> 0 | AM19: =AK19+AL19 -> 99.5 | AN19: =V19 -> 68 | AU19: 0 | AV19: 0.15 | AW19: 50 | AX19: 22 | AZ19: =SUM(N19,P19:U19) -> 3.5
A20: =A19+1 -> 6 | B20: 6902.61 | C20: 293310 | D20: =C20-C19 -> -37 | E20: =C20-152000 -> 141310 | F20: =D20/$D$2 -> -18.653895 | G20: 84 | H20: 0 | I20: =G20+H20 -> 84 | J20: =IF(L20>0,L20,0) -> 0 | K20: =I20+J20 -> 84 | L20: =F20-(I20-AK20) -> -3.4538946 | M20: 3.2 | N20: 0 | O20: 0 | P20: 0 | Q20: =1076000/325851/1.9835*1.02 -> 1.6980919 | R20: =((2)*1.04)-T20 -> 1.5164531 | S20: 0 | T20: =(0.5112*1.06)*1.04 -> 0.56354688 | U20: =M20-(Q20+R20+S20+T20) -> -0.57809186 | V20: 68 | W20: 0 | X20: =M20-N20-P20-O20-Q20-R20-S20-T20-U20+V20+W20 -> 68 | Y20: =X20-AO20 -> 68 | AC20: 2.3 | AE20: 0 | AH20: 28 | AI20: =AI19-AH20 -> 5183 | AK20: =N20+O20+P20+Q20+R20+S20+T20+U20+X20+AE20+AH20 -> 99.2 | AL20: =IF(L20<0,L20*-1,0) -> 3.4538946 | AM20: =AK20+AL20 -> 102.65389 | AN20: =V20 -> 68 | AU20: 0 | AV20: 0.04 | AW20: 35 | AX20: 26 | AZ20: =SUM(N20,P20:U20) -> 3.2
A21: =A20+1 -> 7 | B21: 6902.59 | C21: 293235 | D21: =C21-C20 -> -75 | E21: =C21-152000 -> 141235 | F21: =D21/$D$2 -> -37.811949 | G21: 80 | H21: 0 | I21: =G21+H21 -> 80 | J21: =IF(L21>0,L21,0) -> 0 | K21: =I21+J21 -> 80 | L21: =F21-(I21-AK21) -> -13.811949 | M21: 15 | N21: 0 | O21: 0 | P21: 0 | Q21: =883500/325851/1.9835*1.02 -> 1.3942975 | R21: =((2)*1.04)-T21 -> 1.5164531 | S21: 0 | T21: =(0.5112*1.06)*1.04 -> 0.56354688 | U21: 0 | V21: 50 | W21: 10 | X21: =M21-N21-P21-O21-Q21-R21-S21-T21-U21+V21+W21 -> 71.525702 | Y21: =X21-AO21 -> 41.3 | AC21: 5.6 | AE21: 0 | AH21: 29 | AI21: =AI20-AH21 -> 5154 | AK21: =N21+O21+P21+Q21+R21+S21+T21+U21+X21+AE21+AH21 -> 104 | AL21: =IF(L21<0,L21*-1,0) -> 13.811949 | AM21: =AK21+AL21 -> 117.81195 | AN21: =V21-8.7 -> 41.3 | AO21: =X21-AN21 -> 30.225702 | AV21: 0.07 | AW21: 42 | AX21: 29 | AZ21: =SUM(N21,P21:U21) -> 3.4742975
A22: =A21+1 -> 8 | B22: 6902.57 | C22: 293159 | D22: =C22-C21 -> -76 | E22: =C22-152000 -> 141159 | F22: =D22/$D$2 -> -38.316108 | G22: 70 | H22: 0 | I22: =G22+H22 -> 70 | J22: =IF(L22>0,L22,0) -> 0 | K22: =I22+J22 -> 70 | L22: =F22-(I22-AK22) -> -5.3161079 | M22: 21 | N22: 0 | O22: 0 | P22: 0 | Q22: =960200/325851/1.9835*1.02 -> 1.5153418 | R22: =((2)*1.04)-T22 -> 1.5164531 | S22: 0 | T22: =(0.5112*1.06)*1.04 -> 0.56354688 | U22: 0 | V22: 39 | W22: 13 | X22: =M22-N22-P22-O22-Q22-R22-S22-T22-U22+V22+W22 -> 69.404658 | Y22: =X22-AO22 -> 26 | AC22: 0 | AE22: 0 | AH22: 30 | AI22: =AI21-AH22 -> 5124 | AK22: =N22+O22+P22+Q22+R22+S22+T22+U22+X22+AE22+AH22 -> 103 | AL22: =IF(L22<0,L22*-1,0) -> 5.3161079 | AM22: =AK22+AL22 -> 108.31611 | AN22: =V22-13 -> 26 | AO22: =X22-AN22 -> 43.404658 | AV22: 0 | AW22: 41 | AX22: 27 | AZ22: =SUM(N22,P22:U22) -> 3.5953418
A23: =A22+1 -> 9 | B23: 6902.55 | C23: 293084 | D23: =C23-C22 -> -75 | E23: =C23-152000 -> 141084 | F23: =D23/$D$2 -> -37.811949 | G23: 64 | H23: 0 | I23: =G23+H23 -> 64 | J23: =IF(L23>0,L23,0) -> 0.18805142 | K23: =I23+J23 -> 64.188051 | L23: =F23-(I23-AK23) -> 0.18805142 | M23: 23 | N23: 0 | O23: 0 | P23: 0 | Q23: =895600/325851/1.9835*1.02 -> 1.4133932 | R23: =((2)*1.04)-T23 -> 1.5164531 | S23: 0 | T23: =(0.5112*1.06)*1.04 -> 0.56354688 | U23: 0 | V23: 34 | W23: 15 | X23: =M23-N23-P23-O23-Q23-R23-S23-T23-U23+V23+W23 -> 68.506607 | Y23: =X23-AO23 -> 21 | AC23: 0 | AE23: 0 | AH23: 30 | AI23: =AI22-AH23 -> 5094 | AK23: =N23+O23+P23+Q23+R23+S23+T23+U23+X23+AE23+AH23 -> 102 | AL23: =IF(L23<0,L23*-1,0) -> 0 | AM23: =AK23+AL23 -> 102 | AN23: =V23-13 -> 21 | AO23: =X23-AN23 -> 47.506607 | AV23: 0 | AW23: 46 | AX23: 19 | AZ23: =SUM(N23,P23:U23) -> 3.4933932
A24: =A23+1 -> 10 | B24: 6902.53 | C24: 293009 | D24: =C24-C23 -> -75 | E24: =C24-152000 -> 141009 | F24: =D24/$D$2 -> -37.811949 | G24: 47 | H24: 0 | I24: =G24+H24 -> 47 | J24: =IF(L24>0,L24,0) -> 8.1880514 | K24: =I24+J24 -> 55.188051 | L24: =F24-(I24-AK24) -> 8.1880514 | M24: 24 | N24: 0 | O24: 0 | P24: 0 | Q24: =953400/325851/1.9835*1.02 -> 1.5046104 | R24: =((2)*1.04)-T24 -> 1.5164531 | S24: 0 | T24: =(0.5112*1.06)*1.04 -> 0.56354688 | U24: 0 | V24: 26 | W24: 13 | X24: =M24-N24-P24-O24-Q24-R24-S24-T24-U24+V24+W24 -> 59.41539 | Y24: =X24-AO24 -> 13 | AC24: 0 | AE24: 0 | AH24: 30 | AI24: =AI23-AH24 -> 5064 | AK24: =N24+O24+P24+Q24+R24+S24+T24+U24+X24+AE24+AH24 -> 93 | AL24: =IF(L24<0,L24*-1,0) -> 0 | AM24: =AK24+AL24 -> 93 | AN24: =V24-13 -> 13 | AO24: =X24-AN24 -> 46.41539 | AV24: 0 | AW24: 48 | AX24: 21 | AZ24: =SUM(N24,P24:U24) -> 3.5846104
A25: =A24+1 -> 11 | B25: 6902.51 | C25: 292934 | D25: =C25-C24 -> -75 | E25: =C25-152000 -> 140934 | F25: =D25/$D$2 -> -37.811949 | G25: 64 | H25: 0 | I25: =G25+H25 -> 64 | J25: =IF(L25>0,L25,0) -> 0 | K25: =I25+J25 -> 64 | L25: =F25-(I25-AK25) -> -20.311949 | M25: 21 | N25: 0 | O25: 0 | P25: 0 | Q25: =940300/325851/1.9835*1.02 -> 1.4839366 | R25: =((2)*1.04)-T25 -> 1.5483125 | S25: 0 | T25: =(0.4823*1.06)*1.04 -> 0.53168752 | U25: 0 | V25: 22 | W25: 8.5 | X25: =M25-N25-P25-O25-Q25-R25-S25-T25-U25+V25+W25 -> 47.936063 | Y25: =X25-AO25 -> 15.5 | AC25: 0 | AE25: 0 | AH25: 30 | AI25: =AI24-AH25 -> 5034 | AK25: =N25+O25+P25+Q25+R25+S25+T25+U25+X25+AE25+AH25 -> 81.5 | AL25: =IF(L25<0,L25*-1,0) -> 20.311949 | AM25: =AK25+AL25 -> 101.81195 | AN25: =V25-6.5 -> 15.5 | AO25: =X25-AN25 -> 32.436063 | AV25: 0 | AW25: 45 | AX25: 26 | AZ25: =SUM(N25,P25:U25) -> 3.5639366
A26: =A25+1 -> 12 | B26: 6902.5 | C26: 292896 | D26: =C26-C25 -> -38 | E26: =C26-152000 -> 140896 | F26: =D26/$D$2 -> -19.158054 | G26: 88 | H26: 0 | I26: =G26+H26 -> 88 | J26: =IF(L26>0,L26,0) -> 0 | K26: =I26+J26 -> 88 | L26: =F26-(I26-AK26) -> -28.558054 | M26: 6.6 | N26: 0 | O26: 0 | P26: 0 | Q26: =1084400/325851/1.9835*1.02 -> 1.7113483 | R26: =((2)*1.04)-T26 -> 1.5483125 | S26: 0 | T26: =(0.4823*1.06)*1.04 -> 0.53168752 | U26: 0 | V26: 42 | W26: 0 | X26: =M26-N26-P26-O26-Q26-R26-S26-T26-U26+V26+W26 -> 44.808652 | Y26: =X26-AO26 -> 42 | AC26: 29.6 | AE26: 0 | AH26: 30 | AI26: =AI25-AH26 -> 5004 | AK26: =N26+O26+P26+Q26+R26+S26+T26+U26+X26+AE26+AH26 -> 78.6 | AL26: =IF(L26<0,L26*-1,0) -> 28.558054 | AM26: =AK26+AL26 -> 107.15805 | AN26: =V26 -> 42 | AO26: =X26-AN26 -> 2.8086517 | AV26: 0 | AW26: 52 | AX26: 31 | AZ26: =SUM(N26,P26:U26) -> 3.7913483
A27: =A26+1 -> 13 | B27: 6902.52 | C27: 292971 | D27: =C27-C26 -> 75 | E27: =C27-152000 -> 140971 | F27: =D27/$D$2 -> 37.811949 | G27: 88 | H27: 0 | I27: =G27+H27 -> 88 | J27: =IF(L27>0,L27,0) -> 48.411949 | K27: =I27+J27 -> 136.41195 | L27: =F27-(I27-AK27) -> 48.411949 | M27: 3.6 | N27: 0 | O27: 0 | P27: 0 | Q27: =957600/325851/1.9835*1.02 -> 1.5112386 | R27: =((2)*1.04)-T27 -> 1.5483125 | S27: 0 | T27: =(0.4823*1.06)*1.04 -> 0.53168752 | U27: 0 | V27: 65 | W27: 0 | X27: =M27-N27-P27-O27-Q27-R27-S27-T27-U27+V27+W27 -> 65.008761 | Y27: =X27-AO27 -> 65.008761 | AC27: 18.3 | AE27: 0 | AH27: 30 | AI27: =AI26-AH27 -> 4974 | AK27: =N27+O27+P27+Q27+R27+S27+T27+U27+X27+AE27+AH27 -> 98.6 | AL27: =IF(L27<0,L27*-1,0) -> 0 | AM27: =AK27+AL27 -> 98.6 | AN27: =V27 -> 65 | AV27: 0.09 | AW27: 52 | AX27: 30 | AZ27: =SUM(N27,P27:U27) -> 3.5912386
A28: =A27+1 -> 14 | B28: 6902.5 | C28: 292896 | D28: =C28-C27 -> -75 | E28: =C28-152000 -> 140896 | F28: =D28/$D$2 -> -37.811949 | G28: 74 | H28: 0 | I28: =G28+H28 -> 74 | J28: =IF(L28>0,L28,0) -> 0 | K28: =I28+J28 -> 74 | L28: =F28-(I28-AK28) -> -2.2119486 | M28: 3.6 | N28: 0 | O28: 0 | P28: 0 | Q28: =878000/325851/1.9835*1.02 -> 1.3856177 | R28: =((2)*1.04)-T28 -> 1.5483125 | S28: 0 | T28: =(0.4823*1.06)*1.04 -> 0.53168752 | U28: =M28-(Q28+R28+S28+T28) -> 0.13438229 | V28: 76 | W28: 0 | X28: =M28-N28-P28-O28-Q28-R28-S28-T28-U28+V28+W28 -> 76 | Y28: =X28-AO28 -> 76 | AC28: 0 | AE28: 0 | AH28: 30 | AI28: =AI27-AH28 -> 4944 | AK28: =N28+O28+P28+Q28+R28+S28+T28+U28+X28+AE28+AH28 -> 109.6 | AL28: =IF(L28<0,L28*-1,0) -> 2.2119486 | AM28: =AK28+AL28 -> 111.81195 | AN28: =V28 -> 76 | AV28: 0 | AW28: 47 | AX28: 28 | AZ28: =SUM(N28,P28:U28) -> 3.6
A29: =A28+1 -> 15 | B29: 6902.48 | C29: 292821 | D29: =C29-C28 -> -75 | E29: =C29-152000 -> 140821 | F29: =D29/$D$2 -> -37.811949 | G29: 68 | H29: 0 | I29: =G29+H29 -> 68 | J29: =IF(L29>0,L29,0) -> 0 | K29: =I29+J29 -> 68 | L29: =F29-(I29-AK29) -> -4.5119486 | M29: 3.3 | N29: 0 | O29: 0 | P29: 0 | Q29: =906600/325851/1.9835*1.02 -> 1.4307529 | R29: =((2)*1.04)-T29 -> 1.5483125 | S29: 0 | T29: =(0.4823*1.06)*1.04 -> 0.53168752 | U29: =M29-(Q29+R29+S29+T29) -> -0.21075286 | V29: 68 | W29: 0 | X29: =M29-N29-P29-O29-Q29-R29-S29-T29-U29+V29+W29 -> 68 | Y29: =X29-AO29 -> 68 | AC29: 0 | AE29: 0 | AH29: 30 | AI29: =AI28-AH29 -> 4914 | AK29: =N29+O29+P29+Q29+R29+S29+T29+U29+X29+AE29+AH29 -> 101.3 | AL29: =IF(L29<0,L29*-1,0) -> 4.5119486 | AM29: =AK29+AL29 -> 105.81195 | AN29: =V29 -> 68 | AV29: 0 | AW29: 48 | AX29: 27 | AZ29: =SUM(N29,P29:U29) -> 3.3
A30: =A29+1 -> 16 | B30: 6902.46 | C30: 292745 | D30: =C30-C29 -> -76 | E30: =C30-152000 -> 140745 | F30: =D30/$D$2 -> -38.316108 | G30: 65 | H30: 0 | I30: =G30+H30 -> 65 | J30: =IF(L30>0,L30,0) -> 0 | K30: =I30+J30 -> 65 | L30: =F30-(I30-AK30) -> -10.116108 | M30: 3.2 | N30: 0 | O30: 0 | P30: 0 | Q30: =845400/325851/1.9835*1.02 -> 1.3341699 | R30: =((2)*1.04)-T30 -> 1.5483125 | S30: 0 | T30: =(0.4823*1.06)*1.04 -> 0.53168752 | U30: =M30-(Q30+R30+S30+T30) -> -0.21416994 | V30: 60 | W30: 0 | X30: =M30-N30-P30-O30-Q30-R30-S30-T30-U30+V30+W30 -> 60 | Y30: =X30-AO30 -> 60 | AC30: 0 | AE30: 0 | AH30: 30 | AI30: =AI29-AH30 -> 4884 | AK30: =N30+O30+P30+Q30+R30+S30+T30+U30+X30+AE30+AH30 -> 93.2 | AL30: =IF(L30<0,L30*-1,0) -> 10.116108 | AM30: =AK30+AL30 -> 103.31611 | AN30: =V30 -> 60 | AV30: 0 | AW30: 45 | AX30: 24 | AZ30: =SUM(N30,P30:U30) -> 3.2
A31: =A30+1 -> 17 | B31: 6902.44 | C31: 292670 | D31: =C31-C30 -> -75 | E31: =C31-152000 -> 140670 | F31: =D31/$D$2 -> -37.811949 | G31: 50 | H31: 0.25 | I31: =G31+H31 -> 50.25 | J31: =IF(L31>0,L31,0) -> 2.9380514 | K31: =I31+J31 -> 53.188051 | L31: =F31-(I31-AK31) -> 2.9380514 | M31: 4 | N31: 0 | O31: 0 | P31: 0 | Q31: =826300/325851/1.9835*1.02 -> 1.3040272 | R31: =((2)*1.04)-T31 -> 1.5483125 | S31: 0 | T31: =(0.4823*1.06)*1.04 -> 0.53168752 | U31: =M31-(Q31+R31+S31+T31) -> 0.61597277 | V31: 57 | W31: 0 | X31: =M31-N31-P31-O31-Q31-R31-S31-T31-U31+V31+W31 -> 57 | Y31: =X31-AO31 -> 57 | AC31: 0 | AE31: 0 | AH31: 30 | AI31: =AI30-AH31 -> 4854 | AK31: =N31+O31+P31+Q31+R31+S31+T31+U31+X31+AE31+AH31 -> 91 | AL31: =IF(L31<0,L31*-1,0) -> 0 | AM31: =AK31+AL31 -> 91 | AN31: =V31 -> 57 | AV31: 0 | AW31: 50 | AX31: 23 | AZ31: =SUM(N31,P31:U31) -> 4
A32: =A31+1 -> 18 | B32: 6902.42 | C32: 292595 | D32: =C32-C31 -> -75 | E32: =C32-152000 -> 140595 | F32: =D32/$D$2 -> -37.811949 | G32: 57 | H32: 0.31 | I32: =G32+H32 -> 57.31 | J32: =IF(L32>0,L32,0) -> 0 | K32: =I32+J32 -> 57.31 | L32: =F32-(I32-AK32) -> -5.8219486 | M32: 3.3 | N32: 0 | O32: 0 | P32: 0 | Q32: =868700/325851/1.9835*1.02 -> 1.3709409 | R32: =((2)*1.04)-T32 -> 1.6075114 | S32: 0 | T32: =(0.4286*1.06)*1.04 -> 0.47248864 | U32: =M32-(Q32+R32+S32+T32) -> -0.15094089 | V32: 56 | W32: 0 | X32: =M32-N32-P32-O32-Q32-R32-S32-T32-U32+V32+W32 -> 56 | Y32: =X32-AO32 -> 56 | AC32: 0 | AE32: 0 | AH32: 30 | AI32: =AI31-AH32 -> 4824 | AK32: =N32+O32+P32+Q32+R32+S32+T32+U32+X32+AE32+AH32 -> 89.3 | AL32: =IF(L32<0,L32*-1,0) -> 5.8219486 | AM32: =AK32+AL32 -> 95.121949 | AN32: =V32 -> 56 | AV32: 0 | AW32: 51 | AX32: 29 | AZ32: =SUM(N32,P32:U32) -> 3.3
A33: =A32+1 -> 19 | B33: 6902.4 | C33: 292520 | D33: =C33-C32 -> -75 | E33: =C33-152000 -> 140520 | F33: =D33/$D$2 -> -37.811949 | G33: 71 | H33: 0.42 | I33: =G33+H33 -> 71.42 | J33: =IF(L33>0,L33,0) -> 0 | K33: =I33+J33 -> 71.42 | L33: =F33-(I33-AK33) -> -19.431949 | M33: 3.8 | N33: 0 | O33: 0 | P33: 0 | Q33: =925100/325851/1.9835*1.02 -> 1.4599487 | R33: =((1.8)*1.04)-T33 -> 1.3995114 | S33: 0 | T33: =(0.4286*1.06)*1.04 -> 0.47248864 | U33: =M33-(Q33+R33+S33+T33) -> 0.46805132 | V33: 56 | W33: 0 | X33: =M33-N33-P33-O33-Q33-R33-S33-T33-U33+V33+W33 -> 56 | Y33: =X33-AO33 -> 56 | AC33: 13.3 | AE33: 0 | AH33: 30 | AI33: =AI32-AH33 -> 4794 | AK33: =N33+O33+P33+Q33+R33+S33+T33+U33+X33+AE33+AH33 -> 89.8 | AL33: =IF(L33<0,L33*-1,0) -> 19.431949 | AM33: =AK33+AL33 -> 109.23195 | AN33: =V33 -> 56 | AV33: 0 | AW33: 52 | AX33: 33 | AZ33: =SUM(N33,P33:U33) -> 3.8
A34: =A33+1 -> 20 | B34: 6902.38 | C34: 292444 | D34: =C34-C33 -> -76 | E34: =C34-152000 -> 140444 | F34: =D34/$D$2 -> -38.316108 | G34: 66 | H34: 0.52 | I34: =G34+H34 -> 66.52 | J34: =IF(L34>0,L34,0) -> 0 | K34: =I34+J34 -> 66.52 | L34: =F34-(I34-AK34) -> -15.236108 | M34: 2.6 | N34: 0 | O34: 0 | P34: 0 | Q34: =975500/325851/1.9835*1.02 -> 1.5394876 | R34: =((1.8)*1.04)-T34 -> 1.3995114 | S34: 0 | T34: =(0.4286*1.06)*1.04 -> 0.47248864 | U34: =M34-(Q34+R34+S34+T34) -> -0.81148756 | V34: 57 | W34: 0 | X34: =M34-N34-P34-O34-Q34-R34-S34-T34-U34+V34+W34 -> 57 | Y34: =X34-AO34 -> 57 | AC34: 16.3 | AE34: 0 | AH34: 30 | AI34: =AI33-AH34 -> 4764 | AK34: =N34+O34+P34+Q34+R34+S34+T34+U34+X34+AE34+AH34 -> 89.6 | AL34: =IF(L34<0,L34*-1,0) -> 15.236108 | AM34: =AK34+AL34 -> 104.83611 | AN34: =V34 -> 57 | AV34: 0 | AW34: 51 | AX34: 31 | AZ34: =SUM(N34,P34:U34) -> 2.6
A35: =A34+1 -> 21 | B35: 6902.36 | C35: 292369 | D35: =C35-C34 -> -75 | E35: =C35-152000 -> 140369 | F35: =D35/$D$2 -> -37.811949 | G35: 61 | H35: 0.56 | I35: =G35+H35 -> 61.56 | J35: =IF(L35>0,L35,0) -> 0 | K35: =I35+J35 -> 61.56 | L35: =F35-(I35-AK35) -> -0.47194858 | M35: 3.9 | N35: 0 | O35: 0 | P35: 0 | Q35: =973400/325851/1.9835*1.02 -> 1.5361734 | R35: =((1.8)*1.04)-T35 -> 1.3995114 | S35: 0 | T35: =(0.4286*1.06)*1.04 -> 0.47248864 | U35: =M35-(Q35+R35+S35+T35) -> 0.49182656 | V35: 65 | W35: 0 | X35: =M35-N35-P35-O35-Q35-R35-S35-T35-U35+V35+W35 -> 65 | Y35: =X35-AO35 -> 65 | AC35: 0 | AE35: 0 | AH35: 30 | AI35: =AI34-AH35 -> 4734 | AK35: =N35+O35+P35+Q35+R35+S35+T35+U35+X35+AE35+AH35 -> 98.9 | AL35: =IF(L35<0,L35*-1,0) -> 0.47194858 | AM35: =AK35+AL35 -> 99.371949 | AN35: =V35 -> 65 | AV35: 0.08 | AW35: 48 | AX35: 31 | AZ35: =SUM(N35,P35:U35) -> 3.9
A36: =A35+1 -> 22 | B36: 6902.33 | C36: 292256 | D36: =C36-C35 -> -113 | E36: =C36-152000 -> 140256 | F36: =D36/$D$2 -> -56.970003 | G36: 59 | H36: 0.61 | I36: =G36+H36 -> 59.61 | J36: =IF(L36>0,L36,0) -> 0 | K36: =I36+J36 -> 59.61 | L36: =F36-(I36-AK36) -> -26.480003 | M36: 3.1 | N36: 0 | O36: 0 | P36: 0 | Q36: =999200/325851/1.9835*1.02 -> 1.5768898 | R36: =((1.8)*1.04)-T36 -> 1.3995114 | S36: 0 | T36: =(0.4286*1.06)*1.04 -> 0.47248864 | U36: =M36-(Q36+R36+S36+T36) -> -0.34888976 | V36: 57 | W36: 0 | X36: =M36-N36-P36-O36-Q36-R36-S36-T36-U36+V36+W36 -> 57 | Y36: =X36-AO36 -> 57 | AC36: 2.1 | AE36: 0 | AH36: 30 | AI36: =AI35-AH36 -> 4704 | AK36: =N36+O36+P36+Q36+R36+S36+T36+U36+X36+AE36+AH36 -> 90.1 | AL36: =IF(L36<0,L36*-1,0) -> 26.480003 | AM36: =AK36+AL36 -> 116.58 | AN36: =V36 -> 57 | AV36: 0 | AW36: 49 | AX36: 27 | AZ36: =SUM(N36,P36:U36) -> 3.1
A37: =A36+1 -> 23 | B37: 6902.3 | C37: 292143 | D37: =C37-C36 -> -113 | E37: =C37-152000 -> 140143 | F37: =D37/$D$2 -> -56.970003 | G37: 50 | H37: 0.54 | I37: =G37+H37 -> 50.54 | J37: =IF(L37>0,L37,0) -> 0 | K37: =I37+J37 -> 50.54 | L37: =F37-(I37-AK37) -> -19.010003 | M37: 3.5 | N37: 0 | O37: 0 | P37: 0 | Q37: =807800/325851/1.9835*1.02 -> 1.2748314 | R37: =((1.8)*1.04)-T37 -> 1.3995114 | S37: 0 | T37: =(0.4286*1.06)*1.04 -> 0.47248864 | U37: =M37-(Q37+R37+S37+T37) -> 0.35316858 | V37: 55 | W37: 0 | X37: =M37-N37-P37-O37-Q37-R37-S37-T37-U37+V37+W37 -> 55 | Y37: =X37-AO37 -> 55 | AC37: 0 | AE37: 0 | AH37: 30 | AI37: =AI36-AH37 -> 4674 | AK37: =N37+O37+P37+Q37+R37+S37+T37+U37+X37+AE37+AH37 -> 88.5 | AL37: =IF(L37<0,L37*-1,0) -> 19.010003 | AM37: =AK37+AL37 -> 107.51 | AN37: =V37 -> 55 | AV37: 0 | AW37: 57 | AX37: 27 | AZ37: =SUM(N37,P37:U37) -> 3.5
A38: =A37+1 -> 24 | B38: 6902.27 | C38: 292030 | D38: =C38-C37 -> -113 | E38: =C38-152000 -> 140030 | F38: =D38/$D$2 -> -56.970003 | G38: 48 | H38: 0.51 | I38: =G38+H38 -> 48.51 | J38: =IF(L38>0,L38,0) -> 0 | K38: =I38+J38 -> 48.51 | L38: =F38-(I38-AK38) -> -16.580003 | M38: 3.9 | N38: 0 | O38: 0 | P38: 0 | Q38: =913500/325851/1.9835*1.02 -> 1.4416421 | R38: =((1.8)*1.04)-T38 -> 1.3995114 | S38: 0 | T38: =(0.4286*1.06)*1.04 -> 0.47248864 | U38: =M38-(Q38+R38+S38+T38) -> 0.58635789 | V38: 55 | W38: 0 | X38: =M38-N38-P38-O38-Q38-R38-S38-T38-U38+V38+W38 -> 55 | Y38: =X38-AO38 -> 55 | AC38: 0 | AE38: 0 | AH38: 30 | AI38: =AI37-AH38 -> 4644 | AK38: =N38+O38+P38+Q38+R38+S38+T38+U38+X38+AE38+AH38 -> 88.9 | AL38: =IF(L38<0,L38*-1,0) -> 16.580003 | AM38: =AK38+AL38 -> 105.48 | AN38: =V38 -> 55 | AV38: 0 | AW38: 56 | AX38: 30 | AZ38: =SUM(N38,P38:U38) -> 3.9
A39: =A38+1 -> 25 | B39: 6902.25 | C39: 291955 | D39: =C39-C38 -> -75 | E39: =C39-152000 -> 139955 | F39: =D39/$D$2 -> -37.811949 | G39: 72 | H39: 0.79 | I39: =G39+H39 -> 72.79 | J39: =IF(L39>0,L39,0) -> 0 | K39: =I39+J39 -> 72.79 | L39: =F39-(I39-AK39) -> -22.801949 | M39: 2.8 | N39: 0 | O39: 0 | P39: 0 | Q39: =851500/325851/1.9835*1.02 -> 1.3437967 | R39: =((1.8)*1.04)-T39 -> 1.386503 | S39: 0 | T39: =(0.4404*1.06)*1.04 -> 0.48549696 | U39: =M39-(Q39+R39+S39+T39) -> -0.41579667 | V39: 55 | W39: 0 | X39: =M39-N39-P39-O39-Q39-R39-S39-T39-U39+V39+W39 -> 55 | Y39: =X39-AO39 -> 55 | AC39: 11.9 | AE39: 0 | AH39: 30 | AI39: =AI38-AH39 -> 4614 | AK39: =N39+O39+P39+Q39+R39+S39+T39+U39+X39+AE39+AH39 -> 87.8 | AL39: =IF(L39<0,L39*-1,0) -> 22.801949 | AM39: =AK39+AL39 -> 110.60195 | AN39: =V39 -> 55 | AV39: 0.05 | AW39: 56 | AX39: 30 | AZ39: =SUM(N39,P39:U39) -> 2.8
A40: =A39+1 -> 26 | B40: 6902.23 | C40: 291880 | D40: =C40-C39 -> -75 | E40: =C40-152000 -> 139880 | F40: =D40/$D$2 -> -37.811949 | G40: 55 | H40: 0.72 | I40: =G40+H40 -> 55.72 | J40: =IF(L40>0,L40,0) -> 0 | K40: =I40+J40 -> 55.72 | L40: =F40-(I40-AK40) -> -4.2319486 | M40: 3.3 | N40: 0 | O40: 0 | P40: 0 | Q40: =851100/325851/1.9835*1.04 -> 1.369502 | R40: =((1.8)*1.04)-T40 -> 1.386503 | S40: 0 | T40: =(0.4404*1.06)*1.04 -> 0.48549696 | U40: =M40-(Q40+R40+S40+T40) -> 0.058498012 | V40: 56 | W40: 0 | X40: =M40-N40-P40-O40-Q40-R40-S40-T40-U40+V40+W40 -> 56 | Y40: =X40-AO40 -> 56 | AC40: 2.1 | AE40: 0 | AH40: 30 | AI40: =AI39-AH40 -> 4584 | AK40: =N40+O40+P40+Q40+R40+S40+T40+U40+X40+AE40+AH40 -> 89.3 | AL40: =IF(L40<0,L40*-1,0) -> 4.2319486 | AM40: =AK40+AL40 -> 93.531949 | AN40: =V40 -> 56 | AV40: 0 | AW40: 43 | AX40: 23 | AZ40: =SUM(N40,P40:U40) -> 3.3
A41: =A40+1 -> 27 | B41: 6902.21 | C41: 291805 | D41: =C41-C40 -> -75 | E41: =C41-152000 -> 139805 | F41: =D41/$D$2 -> -37.811949 | G41: 51 | H41: 0.49 | I41: =G41+H41 -> 51.49 | J41: =IF(L41>0,L41,0) -> 0.29805142 | K41: =I41+J41 -> 51.788051 | L41: =F41-(I41-AK41) -> 0.29805142 | M41: 3.6 | N41: 0 | O41: 0 | P41: 0 | Q41: =1024700/325851/1.9835*1.02 -> 1.6171326 | R41: =((1.8)*1.04)-T41 -> 1.386503 | S41: 0 | T41: =(0.4404*1.06)*1.04 -> 0.48549696 | U41: =M41-(Q41+R41+S41+T41) -> 0.11086735 | V41: 56 | W41: 0 | X41: =M41-N41-P41-O41-Q41-R41-S41-T41-U41+V41+W41 -> 56 | Y41: =X41-AO41 -> 56 | AC41: 1.7 | AE41: 0 | AH41: 30 | AI41: =AI40-AH41 -> 4554 | AK41: =N41+O41+P41+Q41+R41+S41+T41+U41+X41+AE41+AH41 -> 89.6 | AL41: =IF(L41<0,L41*-1,0) -> 0 | AM41: =AK41+AL41 -> 89.6 | AN41: =V41 -> 56 | AV41: 0 | AW41: 51 | AX41: 21 | AZ41: =SUM(N41,P41:U41) -> 3.6
A42: =A41+1 -> 28 | B42: 6902.2 | C42: 291767 | D42: =C42-C41 -> -38 | E42: =C42-152000 -> 139767 | F42: =D42/$D$2 -> -19.158054 | G42: 59 | H42: 0.58 | I42: =G42+H42 -> 59.58 | J42: =IF(L42>0,L42,0) -> 3.1619461 | K42: =I42+J42 -> 62.741946 | L42: =F42-(I42-AK42) -> 3.1619461 | M42: 2.9 | N42: 0 | O42: 0 | P42: 0 | Q42: =1022600/325851/1.9835*1.02 -> 1.6138185 | R42: =((1.8)*1.04)-T42 -> 1.386503 | S42: 0 | T42: =(0.4404*1.06)*1.04 -> 0.48549696 | U42: =M42-(Q42+R42+S42+T42) -> -0.58581853 | V42: 48 | W42: 0 | X42: =M42-N42-P42-O42-Q42-R42-S42-T42-U42+V42+W42 -> 48 | Y42: =X42-AO42 -> 48 | AC42: 17.1 | AE42: 0 | AH42: 31 | AI42: =AI41-AH42 -> 4523 | AK42: =N42+O42+P42+Q42+R42+S42+T42+U42+X42+AE42+AH42 -> 81.9 | AL42: =IF(L42<0,L42*-1,0) -> 0 | AM42: =AK42+AL42 -> 81.9 | AN42: =V42 -> 48 | AV42: 0 | AW42: 48 | AX42: 17 | AZ42: =SUM(N42,P42:U42) -> 2.9
...

Sheet DEC
K1: MCPHEE RESERVOIR INFLOW/OUTFLOW TABULATION
A2: AF/cfs CONVERT FACTOR | D2: 1.9835 | K2: DECEMBER "2011"
D4: RESERVOIR | I4: INFLOW | X4: OUTFLOW | AP4: ADJUSTMENTS | AW4: WEATHER
A5: DATE | B5: RESERV | C5: RESERV | D5: AC FT | E5: ACTIVE | F5: CONV TO | G5: DOLORES | H5: LOST | I5: RECORD | J5: CALC | K5: TOTAL | L5: CALC | M5: DOLORES TUNNEL | V5: LONE | W5: U | X5: TOTAL | Y5: TOTAL | Z5: MVI | AA5: MVI | AB5: MVI | AC5: TO EX & | AD5: MVI | AE5: DV CR | AF5: D/S SENIOR | AH5: BELOW | AI5: FISH | AJ5: SPILL | AK5: RECORD | AL5: CALC | AM5: TOTAL | AN5: NAR | AO5: MVI | AP5: MVI | AQ5: MVI | AR5: DIST. | AS5: U/S | AT5: TOTTEN | AU5: UTES | AV5: RAIN | AW5: MAX | AX5: MIN | AZ5: TOTAL
A6: DEC | B6: ELEV | D6: CHANGE | E6: CAP | F6: CFS | G6: RIVER | H6: CAN | I6: INFLOW | J6: INFLOW | K6: INFLOW | L6: INF/OTF | M6: TOT DIV | N6: WET | O6: UTE | P6: QUEST | Q6: MWC | R6: CORTEZ | T6: UTE | U6: F-BAY | V6: PINE | W6: LAT | X6: MVI | Y6: MVI | Z6: CALL | AA6: CALL | AB6: APR- | AC6: U/S EX | AD6: PROJ | AE6: CANAL | AF6: MVIC | AG6: PROJ | AH6: MCP | AI6: LEFT | AK6: OTF | AL6: OTF | AM6: OTF | AN6: FILLL | AO6: STOCK | AP6: STORED | AQ6: STORED | AR6: CLASS | AS6: USERS | AT6: (FRESH | AU6: FROM | AW6: TMP | AX6: TMP | AZ6: TUNNEL
N7: LAND | O7: F&R | Q7: NON - | R7: NON - | S7: PROJ | T7: PROJ | U7: BAL | X7: WATER | Y7: IRRIG. | Z7: STOR | AA7: SPILLED | AB7: JUNE | AF7: 1.7 | AG7: 1.3 | AP7: Apr - Jun | AQ7: EVAP | AR7: "B" | AS7: EXCH | AT7: WATER) | AU7: DWCD | AZ7: Misc.
Q8: PROJ | R8: PROJ | X8: USED | Y8: WATER | AA8: OR | AB8: (DIV+
R9: 4.2 | Y9: USED | AA9: USED | AB9: CALL)
C10: AC. Ft. | E10: AC FT | G10: CFS | H10: CFS | I10: CFS | J10: CFS | K10: CFS | L10: CFS | M10: CFS | N10: CFS | O10: CFS | P10: CFS | Q10: CFS | R10: CFS | S10: CFS | T10: CFS | U10: CFS | V10: CFS | W10: CFS | X10: 153400 | Y10: 150400 | AB10: 72000 | AC10: CFS | AD10: CFS | AE10: CFS | AF10: CFS | AG10: CFS | AH10: CFS | AI10: CFS | AJ10: CFS | AK10: CFS | AL10: CFS | AM10: CFS | AN10: CFS | AO10: CFS | AP10: CFS | AQ10: AC.FT. | AR10: CFS | AS10: CFS | AT10: CFS | AU10: CFS | AZ10: Outflow
N11: 1.03 | O11: 1.05 | P11: 1.02 | Q11: 1.02 | R11: 1.04 | T11: 1.04 | X11: CFS | Y11: CFS | Z11: CFS | AA11: CFS | AB11: Ac. Ft. | AZ11: CFS
A12: SEASON BAL
A13: YTD | B13: =NOV!B44 -> 6902.17 | C13: =NOV!C44 -> 291654 | D13: =NOV!D53 -> -1957 | E13: =NOV!E53 -> 139654 | F13: =NOV!F52 -> -986.63978 | G13: =NOV!G52 -> 2009 | H13: =NOV!H52 -> 8.24 | I13: =NOV!I52 -> 2016.62 | J13: =NOV!J52 -> 90.098046 | K13: =NOV!K52 -> 2106.718 | L13: =NOV!L52 -> -180.45978 | M13: =NOV!M52 -> 193.3 | ... Y13: =NOV!Y52 -> 1625.8088 | AC13: =NOV!AC52 -> 146.2 | AH13: =NOV!AH52 -> 890 | AI13: =NOV!AI52 -> 4461 | AK13: =NOV!AK52 -> 2822.8 | AL13: =NOV!AL52 -> 270.55782 | AM13: =NOV!AM52 -> 3093.3578 | AN13: =NOV!AN52 -> 1625.8 | AO13: =NOV!AO52 -> 202.79707 | AV13: =NOV!AV52 -> 0.48 | AZ13: =NOV!AZ52 -> 104.19417
A15: 1 | B15: 6902.16 | C15: 291616 | D15: =C15-C13 -> -38 | E15: =C15-152000 -> 139616 | F15: =D15/$D$2 -> -19.158054 | G15: 52 | H15: 0.62 | I15: =G15+H15 -> 52.62 | J15: =IF(L15>0,L15,0) -> 10.421946 | K15: =I15+J15 -> 63.041946 | L15: =F15-(I15-AK15) -> 10.421946 | M15: 3.2 | N15: 0 | O15: 0 | P15: 0 | Q15: =985000/325851/1.9835*1.02 -> 1.55448 | R15: =((1.8)*1.04)-T15 -> 1.2954448 | S15: 0 | T15: =(0.523*1.06)*1.04 -> 0.5765552 | U15: =M15-(Q15+R15+S15+T15) -> -0.22648 | V15: 48 | W15: 0 | X15: =M15-N15-P15-O15-Q15-R15-S15-T15-U15+V15+W15 -> 48 | Y15: =X15-AO15 -> 48 | AC15: 5 | AE15: 0 | AH15: 31 | AI15: =AI13-AH15 -> 4430 | AK15: =N15+O15+P15+Q15+R15+S15+T15+U15+X15+AE15+AH15 -> 82.2 | AL15: =IF(L15<0,L15*-1,0) -> 0 | AM15: =AK15+AL15 -> 82.2 | AN15: =V15 -> 48 | AO15: 0 | AV15: 0 | AW15: 53 | AX15: 28 | AZ15: =SUM(N15,P15:U15) -> 3.2
A16: =A15+1 -> 2 | B16: 6902.14 | C16: 291541 | D16: =C16-C15 -> -75 | E16: =C16-152000 -> 139541 | F16: =D16/$D$2 -> -37.811949 | G16: 58 | H16: 0.68 | I16: =G16+H16 -> 58.68 | J16: =IF(L16>0,L16,0) -> 0 | K16: =I16+J16 -> 58.68 | L16: =F16-(I16-AK16) -> -17.491949 | M16: 4 | N16: 0 | O16: 0 | P16: 0 | Q16: =857200/325851/1.9835*1.02 -> 1.3527921 | R16: =((1.8)*1.04)-T16 -> 1.2764835 | S16: 0 | T16: =(0.5402*1.06)*1.04 -> 0.59551648 | U16: =M16-(Q16+R16+S16+T16) -> 0.77520786 | V16: 44 | W16: 0 | X16: =M16-N16-P16-O16-Q16-R16-S16-T16-U16+V16+W16 -> 44 | Y16: =X16-AO16 -> 44 | AC16: 13.1 | AE16: 0 | AH16: 31 | AI16: =AI15-AH16 -> 4399 | AK16: =N16+O16+P16+Q16+R16+S16+T16+U16+X16+AE16+AH16 -> 79 | AL16: =IF(L16<0,L16*-1,0) -> 17.491949 | AM16: =AK16+AL16 -> 96.491949 | AN16: =V16 -> 44 | AO16: 0 | AV16: 0.05 | AW16: 38 | AX16: 27 | AZ16: =SUM(N16,P16:U16) -> 4
A17: =A16+1 -> 3 | B17: 6902.12 | C17: 291466 | D17: =C17-C16 -> -75 | E17: =C17-152000 -> 139466 | F17: =D17/$D$2 -> -37.811949 | G17: 57 | H17: 0.75 | I17: =G17+H17 -> 57.75 | J17: =IF(L17>0,L17,0) -> 0 | K17: =I17+J17 -> 57.75 | L17: =F17-(I17-AK17) -> -17.761949 | M17: 2.8 | N17: 0 | O17: 0 | P17: 0 | Q17: =774500/325851/1.9835*1.02 -> 1.2222789 | R17: =((1.8)*1.04)-T17 -> 1.2764835 | S17: 0 | T17: =(0.5402*1.06)*1.04 -> 0.59551648 | U17: =M17-(Q17+R17+S17+T17) -> -0.29427895 | V17: 44 | W17: 0 | X17: =M17-N17-P17-O17-Q17-R17-S17-T17-U17+V17+W17 -> 44 | Y17: =X17-AO17 -> 44 | AC17: 11.9 | AE17: 0 | AH17: 31 | AI17: =AI16-AH17 -> 4368 | AK17: =N17+O17+P17+Q17+R17+S17+T17+U17+X17+AE17+AH17 -> 77.8 | AL17: =IF(L17<0,L17*-1,0) -> 17.761949 | AM17: =AK17+AL17 -> 95.561949 | AN17: =V17 -> 44 | AO17: 0 | AV17: 0.04 | AW17: 33 | AX17: 21 | AZ17: =SUM(N17,P17:U17) -> 2.8
A18: =A17+1 -> 4 | B18: 6902.1 | C18: 291391 | D18: =C18-C17 -> -75 | E18: =C18-152000 -> 139391 | F18: =D18/$D$2 -> -37.811949 | G18: 57 | H18: 0.72 | I18: =G18+H18 -> 57.72 | J18: =IF(L18>0,L18,0) -> 0 | K18: =I18+J18 -> 57.72 | L18: =F18-(I18-AK18) -> -16.331949 | M18: 3.2 | N18: 0 | O18: 0 | P18: 0 | Q18: =1102900/325851/1.9835*1.02 -> 1.7405442 | R18: =((1.8)*1.04)-T18 -> 1.2764835 | S18: 0 | T18: =(0.5402*1.06)*1.04 -> 0.59551648 | U18: =M18-(Q18+R18+S18+T18) -> -0.41254416 | V18: 45 | W18: 0 | X18: =M18-N18-P18-O18-Q18-R18-S18-T18-U18+V18+W18 -> 45 | Y18: =X18-AO18 -> 45 | AC18: 11.2 | AE18: 0 | AH18: 31 | AI18: =AI17-AH18 -> 4337 | AK18: =N18+O18+P18+Q18+R18+S18+T18+U18+X18+AE18+AH18 -> 79.2 | AL18: =IF(L18<0,L18*-1,0) -> 16.331949 | AM18: =AK18+AL18 -> 95.531949 | AN18: =V18 -> 45 | AO18: 0 | AV18: 0.05 | AW18: 29 | AX18: 24 | AZ18: =SUM(N18,P18:U18) -> 3.2
A19: =A18+1 -> 5 | B19: 6902.08 | C19: 291315 | D19: =C19-C18 -> -76 | E19: =C19-152000 -> 139315 | F19: =D19/$D$2 -> -38.316108 | G19: 48 | H19: 0.69 | I19: =G19+H19 -> 48.69 | J19: =IF(L19>0,L19,0) -> 0 | K19: =I19+J19 -> 48.69 | L19: =F19-(I19-AK19) -> -8.4061079 | M19: 3.6 | N19: 0 | O19: 0 | P19: 0 | Q19: =869600/325851/1.9835*1.02 -> 1.3723612 | R19: =((1.8)*1.04)-T19 -> 1.2764835 | S19: 0 | T19: =(0.5402*1.06)*1.04 -> 0.59551648 | U19: =M19-(Q19+R19+S19+T19) -> 0.35563877 | V19: 45 | W19: 0 | X19: =M19-N19-P19-O19-Q19-R19-S19-T19-U19+V19+W19 -> 45 | Y19: =X19-AO19 -> 45 | AC19: 5.3 | AE19: 0 | AH19: 30 | AI19: =AI18-AH19 -> 4307 | AK19: =N19+O19+P19+Q19+R19+S19+T19+U19+X19+AE19+AH19 -> 78.6 | AL19: =IF(L19<0,L19*-1,0) -> 8.4061079 | AM19: =AK19+AL19 -> 87.006108 | AN19: =V19 -> 45 | AO19: 0 | AV19: 0.01 | AW19: 25 | AX19: 6 | AZ19: =SUM(N19,P19:U19) -> 3.6
A20: =A19+1 -> 6 | B20: 6902.06 | C20: 291240 | D20: =C20-C19 -> -75 | E20: =C20-152000 -> 139240 | F20: =D20/$D$2 -> -37.811949 | G20: 24 | H20: 0.61 | I20: =G20+H20 -> 24.61 | J20: =IF(L20>0,L20,0) -> 12.178051 | K20: =I20+J20 -> 36.788051 | L20: =F20-(I20-AK20) -> 12.178051 | M20: 3.6 | N20: 0 | O20: 0 | P20: 0 | Q20: =839200/325851/1.9835*1.02 -> 1.3243854 | R20: =((1.9)*1.04)-T20 -> 1.3804835 | S20: 0 | T20: =(0.5402*1.06)*1.04 -> 0.59551648 | U20: =M20-(Q20+R20+S20+T20) -> 0.2996146 | V20: 41 | W20: 0 | X20: =M20-N20-P20-O20-Q20-R20-S20-T20-U20+V20+W20 -> 41 | Y20: =X20-AO20 -> 41 | AC20: 0 | AE20: 0 | AH20: 30 | AI20: =AI19-AH20 -> 4277 | AK20: =N20+O20+P20+Q20+R20+S20+T20+U20+X20+AE20+AH20 -> 74.6 | AL20: =IF(L20<0,L20*-1,0) -> 0 | AM20: =AK20+AL20 -> 74.6 | AN20: =V20 -> 41 | AO20: 0 | AV20: 0 | AW20: 31 | AX20: -3 | AZ20: =SUM(N20,P20:U20) -> 3.6
A21: =A20+1 -> 7 | B21: 6902.04 | C21: 291165 | D21: =C21-C20 -> -75 | E21: =C21-152000 -> 139165 | F21: =D21/$D$2 -> -37.811949 | G21: 45 | H21: 0.63 | I21: =G21+H21 -> 45.63 | J21: =IF(L21>0,L21,0) -> 0 | K21: =I21+J21 -> 45.63 | L21: =F21-(I21-AK21) -> -11.041949 | M21: 3.4 | N21: 0 | O21: 0 | P21: 0 | Q21: =1104500/325851/1.9835*1.02 -> 1.7430692 | R21: =((1.9)*1.04)-T21 -> 1.3804835 | S21: 0 | T21: =(0.5402*1.06)*1.04 -> 0.59551648 | U21: =M21-(Q21+R21+S21+T21) -> -0.3190692 | V21: 39 | W21: 0 | X21: =M21-N21-P21-O21-Q21-R21-S21-T21-U21+V21+W21 -> 39 | Y21: =X21-AO21 -> 39 | AC21: 0 | AE21: 0 | AH21: 30 | AI21: =AI20-AH21 -> 4247 | AK21: =N21+O21+P21+Q21+R21+S21+T21+U21+X21+AE21+AH21 -> 72.4 | AL21: =IF(L21<0,L21*-1,0) -> 11.041949 | AM21: =AK21+AL21 -> 83.441949 | AN21: =V21 -> 39 | AO21: 0 | AV21: 0 | AW21: 36 | AX21: 5 | AZ21: =SUM(N21,P21:U21) -> 3.4
A22: =A21+1 -> 8 | B22: 6902.02 | C22: 291090 | D22: =C22-C21 -> -75 | E22: =C22-152000 -> 139090 | F22: =D22/$D$2 -> -37.811949 | G22: 45 | H22: 0.61 | I22: =G22+H22 -> 45.61 | J22: =IF(L22>0,L22,0) -> 0 | K22: =I22+J22 -> 45.61 | L22: =F22-(I22-AK22) -> -11.521949 | M22: 2.9 | N22: 0 | O22: 0 | P22: 0 | Q22: =837400/325851/1.9835*1.02 -> 1.3215447 | R22: =((1.9)*1.04)-T22 -> 1.3804835 | S22: 0 | T22: =(0.5402*1.06)*1.04 -> 0.59551648 | U22: =M22-(Q22+R22+S22+T22) -> -0.39754472 | V22: 39 | W22: 0 | X22: =M22-N22-P22-O22-Q22-R22-S22-T22-U22+V22+W22 -> 39 | Y22: =X22-AO22 -> 39 | AC22: 0 | AE22: 0 | AH22: 30 | AI22: =AI21-AH22 -> 4217 | AK22: =N22+O22+P22+Q22+R22+S22+T22+U22+X22+AE22+AH22 -> 71.9 | AL22: =IF(L22<0,L22*-1,0) -> 11.521949 | AM22: =AK22+AL22 -> 83.421949 | AN22: =V22 -> 39 | AO22: 0 | AV22: 0 | AW22: 38 | AX22: 10 | AZ22: =SUM(N22,P22:U22) -> 2.9
A23: =A22+1 -> 9 | B23: 6902 | C23: 291014 | D23: =C23-C22 -> -76 | E23: =C23-152000 -> 139014 | F23: =D23/$D$2 -> -38.316108 | G23: 48 | H23: 0.54 | I23: =G23+H23 -> 48.54 | J23: =IF(L23>0,L23,0) -> 0 | K23: =I23+J23 -> 48.54 | L23: =F23-(I23-AK23) -> -13.856108 | M23: 4 | N23: 0 | O23: 0 | P23: 0 | Q23: =962500/325851/1.9835*1.02 -> 1.5189716 | R23: =((2)*1.04)-T23 -> 1.3801965 | S23: 0 | T23: =(0.6348*1.06)*1.04 -> 0.69980352 | U23: =M23-(Q23+R23+S23+T23) -> 0.40102842 | V23: 39 | W23: 0 | X23: =M23-N23-P23-O23-Q23-R23-S23-T23-U23+V23+W23 -> 39 | Y23: =X23-AO23 -> 39 | AC23: 0 | AE23: 0 | AH23: 30 | AI23: =AI22-AH23 -> 4187 | AK23: =N23+O23+P23+Q23+R23+S23+T23+U23+X23+AE23+AH23 -> 73 | AL23: =IF(L23<0,L23*-1,0) -> 13.856108 | AM23: =AK23+AL23 -> 86.856108 | AN23: =V23 -> 39 | AO23: 0 | AV23: 0 | AW23: 39 | AX23: 9 | AZ23: =SUM(N23,P23:U23) -> 4
A24: =A23+1 -> 10 | B24: 6901.98 | C24: 290940 | D24: =C24-C23 -> -74 | E24: =C24-152000 -> 138940 | F24: =D24/$D$2 -> -37.307789 | G24: 44 | H24: 0.5 | I24: =G24+H24 -> 44.5 | J24: =IF(L24>0,L24,0) -> 0 | K24: =I24+J24 -> 44.5 | L24: =F24-(I24-AK24) -> -8.7077893 | M24: 4.1 | N24: 0 | O24: 0 | P24: 0 | Q24: =945300/325851/1.9835*1.02 -> 1.4918274 | R24: =((2)*1.04)-T24 -> 1.3801965 | S24: 0 | T24: =(0.6348*1.06)*1.04 -> 0.69980352 | U24: =M24-(Q24+R24+S24+T24) -> 0.52817264 | V24: 39 | W24: 0 | X24: =M24-N24-P24-O24-Q24-R24-S24-T24-U24+V24+W24 -> 39 | Y24: =X24-AO24 -> 39 | AC24: 0 | AE24: 0 | AH24: 30 | AI24: =AI23-AH24 -> 4157 | AK24: =N24+O24+P24+Q24+R24+S24+T24+U24+X24+AE24+AH24 -> 73.1 | AL24: =IF(L24<0,L24*-1,0) -> 8.7077893 | AM24: =AK24+AL24 -> 81.807789 | AN24: =V24 -> 39 | AO24: 0 | AV24: 0 | AW24: 44 | AX24: 14 | AZ24: =SUM(N24,P24:U24) -> 4.1
A25: =A24+1 -> 11 | B25: 6901.96 | C25: 290865 | D25: =C25-C24 -> -75 | E25: =C25-152000 -> 138865 | F25: =D25/$D$2 -> -37.811949 | G25: 40 | H25: 0.52 | I25: =G25+H25 -> 40.52 | J25: =IF(L25>0,L25,0) -> 0 | K25: =I25+J25 -> 40.52 | L25: =F25-(I25-AK25) -> -6.3319486 | M25: 3 | N25: 0 | O25: 0 | P25: 0 | Q25: =1061500/325851/1.9835*1.02 -> 1.6752087 | R25: =((2)*1.04)-T25 -> 1.3801965 | S25: 0 | T25: =(0.6348*1.06)*1.04 -> 0.69980352 | U25: =M25-(Q25+R25+S25+T25) -> -0.75520865 | V25: 39 | W25: 0 | X25: =M25-N25-P25-O25-Q25-R25-S25-T25-U25+V25+W25 -> 39 | Y25: =X25-AO25 -> 39 | AC25: 0 | AE25: 0 | AH25: 30 | AI25: =AI24-AH25 -> 4127 | AK25: =N25+O25+P25+Q25+R25+S25+T25+U25+X25+AE25+AH25 -> 72 | AL25: =IF(L25<0,L25*-1,0) -> 6.3319486 | AM25: =AK25+AL25 -> 78.331949 | AN25: =V25 -> 39 | AO25: 0 | AV25: 0 | AW25: 45 | AX25: 12 | AZ25: =SUM(N25,P25:U25) -> 3
A26: =A25+1 -> 12 | B26: 6901.94 | C26: 290790 | D26: =C26-C25 -> -75 | E26: =C26-152000 -> 138790 | F26: =D26/$D$2 -> -37.811949 | G26: 41 | H26: 0.64 | I26: =G26+H26 -> 41.64 | J26: =IF(L26>0,L26,0) -> 0 | K26: =I26+J26 -> 41.64 | L26: =F26-(I26-AK26) -> -3.4519486 | M26: 4 | N26: 0 | O26: 0 | P26: 0 | Q26: =999100/325851/1.9835*1.02 -> 1.5767319 | R26: =((2)*1.04)-T26 -> 1.3801965 | S26: 0 | T26: =(0.6348*1.06)*1.04 -> 0.69980352 | U26: =M26-(Q26+R26+S26+T26) -> 0.34326805 | V26: 42 | W26: 0 | X26: =M26-N26-P26-O26-Q26-R26-S26-T26-U26+V26+W26 -> 42 | Y26: =X26-AO26 -> 42 | AC26: 0 | AE26: 0 | AH26: 30 | AI26: =AI25-AH26 -> 4097 | AK26: =N26+O26+P26+Q26+R26+S26+T26+U26+X26+AE26+AH26 -> 76 | AL26: =IF(L26<0,L26*-1,0) -> 3.4519486 | AM26: =AK26+AL26 -> 79.451949 | AN26: =V26 -> 42 | AO26: 0 | AV26: 0.01 | AW26: 41 | AX26: 20 | AZ26: =SUM(N26,P26:U26) -> 4
A27: =A26+1 -> 13 | B27: 6901.92 | C27: 290716 | D27: =C27-C26 -> -74 | E27: =C27-152000 -> 138716 | F27: =D27/$D$2 -> -37.307789 | G27: 46 | H27: 0.74 | I27: =G27+H27 -> 46.74 | J27: =IF(L27>0,L27,0) -> 0 | K27: =I27+J27 -> 46.74 | L27: =F27-(I27-AK27) -> -6.5477893 | M27: 4.5 | N27: 0 | O27: 0 | P27: 0 | Q27: =942600/325851/1.9835*1.02 -> 1.4875663 | R27: =((2.2)*1.04)-T27 -> 1.5881965 | S27: 0 | T27: =(0.6348*1.06)*1.04 -> 0.69980352 | U27: =M27-(Q27+R27+S27+T27) -> 0.72443365 | V27: 43 | W27: 0 | X27: =M27-N27-P27-O27-Q27-R27-S27-T27-U27+V27+W27 -> 43 | Y27: =X27-AO27 -> 43 | AC27: 0 | AE27: 0 | AH27: 30 | AI27: =AI26-AH27 -> 4067 | AK27: =N27+O27+P27+Q27+R27+S27+T27+U27+X27+AE27+AH27 -> 77.5 | AL27: =IF(L27<0,L27*-1,0) -> 6.5477893 | AM27: =AK27+AL27 -> 84.047789 | AN27: =V27 -> 43 | AO27: 0 | AV27: 0.1 | AW27: 43 | AX27: 31 | AZ27: =SUM(N27,P27:U27) -> 4.5
A28: =A27+1 -> 14 | B28: 6901.9 | C28: 290641 | D28: =C28-C27 -> -75 | E28: =C28-152000 -> 138641 | F28: =D28/$D$2 -> -37.811949 | G28: 48 | H28: 0.82 | I28: =G28+H28 -> 48.82 | J28: =IF(L28>0,L28,0) -> 0 | K28: =I28+J28 -> 48.82 | L28: =F28-(I28-AK28) -> -10.331949 | M28: 3.3 | N28: 0 | O28: 0 | P28: 0 | Q28: =1028700/325851/1.9835*1.02 -> 1.6234453 | R28: =((2.4)*1.04)-T28 -> 1.7961965 | S28: 0 | T28: =(0.6348*1.06)*1.04 -> 0.69980352 | U28: =M28-(Q28+R28+S28+T28) -> -0.81944526 | V28: 43 | W28: 0 | X28: =M28-N28-P28-O28-Q28-R28-S28-T28-U28+V28+W28 -> 43 | Y28: =X28-AO28 -> 43 | AC28: 0 | AE28: 0 | AH28: 30 | AI28: =AI27-AH28 -> 4037 | AK28: =N28+O28+P28+Q28+R28+S28+T28+U28+X28+AE28+AH28 -> 76.3 | AL28: =IF(L28<0,L28*-1,0) -> 10.331949 | AM28: =AK28+AL28 -> 86.631949 | AN28: =V28 -> 43 | AO28: 0 | AV28: 0.05 | AW28: 35 | AX28: 22 | AZ28: =SUM(N28,P28:U28) -> 3.3
A29: =A28+1 -> 15 | B29: 6901.88 | C29: 290567 | D29: =C29-C28 -> -74 | E29: =C29-152000 -> 138567 | F29: =D29/$D$2 -> -37.307789 | G29: 43 | H29: 0.9 | I29: =G29+H29 -> 43.9 | J29: =IF(L29>0,L29,0) -> 0 | K29: =I29+J29 -> 43.9 | L29: =F29-(I29-AK29) -> -4.2077893 | M29: 4 | N29: 0 | O29: 0 | P29: 0 | Q29: =801800/325851/1.9835*1.02 -> 1.2653625 | R29: =((2.4)*1.04)-T29 -> 1.7961965 | S29: 0 | T29: =(0.6348*1.06)*1.04 -> 0.69980352 | U29: =M29-(Q29+R29+S29+T29) -> 0.2386375 | V29: 43 | W29: 0 | X29: =M29-N29-P29-O29-Q29-R29-S29-T29-U29+V29+W29 -> 43 | Y29: =X29-AO29 -> 43 | AC29: 0 | AE29: 0 | AH29: 30 | AI29: =AI28-AH29 -> 4007 | AK29: =N29+O29+P29+Q29+R29+S29+T29+U29+X29+AE29+AH29 -> 77 | AL29: =IF(L29<0,L29*-1,0) -> 4.2077893 | AM29: =AK29+AL29 -> 81.207789 | AN29: =V29 -> 43 | AO29: 0 | AV29: 0.05 | AW29: 36 | AX29: 16 | AZ29: =SUM(N29,P29:U29) -> 4
A30: =A29+1 -> 16 | B30: 6901.86 | C30: 290492 | D30: =C30-C29 -> -75 | E30: =C30-152000 -> 138492 | F30: =D30/$D$2 -> -37.811949 | G30: 41 | H30: 0.92 | I30: =G30+H30 -> 41.92 | J30: =IF(L30>0,L30,0) -> 0 | K30: =I30+J30 -> 41.92 | L30: =F30-(I30-AK30) -> -2.5319486 | M30: 4.2 | N30: 0 | O30: 0 | P30: 0 | Q30: =804900/325851/1.9835*1.02 -> 1.2702548 | R30: =((2.4)*1.04)-T30 -> 1.977431 | S30: 0 | T30: =(0.4704*1.06)*1.04 -> 0.51856896 | U30: =M30-(Q30+R30+S30+T30) -> 0.43374522 | V30: 43 | W30: 0 | X30: =M30-N30-P30-O30-Q30-R30-S30-T30-U30+V30+W30 -> 43 | Y30: =X30-AO30 -> 43 | AC30: 0 | AE30: 0 | AH30: 30 | AI30: =AI29-AH30 -> 3977 | AK30: =N30+O30+P30+Q30+R30+S30+T30+U30+X30+AE30+AH30 -> 77.2 | AL30: =IF(L30<0,L30*-1,0) -> 2.5319486 | AM30: =AK30+AL30 -> 79.731949 | AN30: =V30 -> 43 | AO30: 0 | AV30: 0.03 | AW30: 41 | AX30: 15 | AZ30: =SUM(N30,P30:U30) -> 4.2
A31: =A30+1 -> 17 | B31: 6901.84 | C31: 290417 | D31: =C31-C30 -> -75 | E31: =C31-152000 -> 138417 | F31: =D31/$D$2 -> -37.811949 | G31: 41 | H31: 0.91 | I31: =G31+H31 -> 41.91 | J31: =IF(L31>0,L31,0) -> 0 | K31: =I31+J31 -> 41.91 | L31: =F31-(I31-AK31) -> -2.5219486 | M31: 4.2 | N31: 0 | O31: 0 | P31: 0 | Q31: =951100/325851/1.9835*1.02 -> 1.5009806 | R31: =((2.4)*1.04)-T31 -> 1.977431 | S31: 0 | T31: =(0.4704*1.06)*1.04 -> 0.51856896 | U31: =M31-(Q31+R31+S31+T31) -> 0.20301936 | V31: 43 | W31: 0 | X31: =M31-N31-P31-O31-Q31-R31-S31-T31-U31+V31+W31 -> 43 | Y31: =X31-AO31 -> 43 | AC31: 0 | AE31: 0 | AH31: 30 | AI31: =AI30-AH31 -> 3947 | AK31: =N31+O31+P31+Q31+R31+S31+T31+U31+X31+AE31+AH31 -> 77.2 | AL31: =IF(L31<0,L31*-1,0) -> 2.5219486 | AM31: =AK31+AL31 -> 79.721949 | AN31: =V31 -> 43 | AO31: 0 | AV31: 0 | AW31: 49 | AX31: 18 | AZ31: =SUM(N31,P31:U31) -> 4.2
A32: =A31+1 -> 18 | B32: 6901.82 | C32: 290343 | D32: =C32-C31 -> -74 | E32: =C32-152000 -> 138343 | F32: =D32/$D$2 -> -37.307789 | G32: 44 | H32: 0.94 | I32: =G32+H32 -> 44.94 | J32: =IF(L32>0,L32,0) -> 0 | K32: =I32+J32 -> 44.94 | L32: =F32-(I32-AK32) -> -6.1477893 | M32: 3.1 | N32: 0 | O32: 0 | P32: 0 | Q32: =979000/325851/1.9835*1.02 -> 1.5450111 | R32: =((2.4)*1.04)-T32 -> 1.977431 | S32: 0 | T32: =(0.4704*1.06)*1.04 -> 0.51856896 | U32: =M32-(Q32+R32+S32+T32) -> -0.94101109 | V32: 43 | W32: 0 | X32: =M32-N32-P32-O32-Q32-R32-S32-T32-U32+V32+W32 -> 43 | Y32: =X32-AO32 -> 43 | AC32: 0 | AE32: 0 | AH32: 30 | AI32: =AI31-AH32 -> 3917 | AK32: =N32+O32+P32+Q32+R32+S32+T32+U32+X32+AE32+AH32 -> 76.1 | AL32: =IF(L32<0,L32*-1,0) -> 6.1477893 | AM32: =AK32+AL32 -> 82.247789 | AN32: =V32 -> 43 | AO32: 0 | AV32: 0 | AW32: 53 | AX32: 26 | AZ32: =SUM(N32,P32:U32) -> 3.1
A33: =A32+1 -> 19 | B33: 6901.8 | C33: 290268 | D33: =C33-C32 -> -75 | E33: =C33-152000 -> 138268 | F33: =D33/$D$2 -> -37.811949 | G33: 45 | H33: 1 | I33: =G33+H33 -> 46 | J33: =IF(L33>0,L33,0) -> 0 | K33: =I33+J33 -> 46 | L33: =F33-(I33-AK33) -> -6.7119486 | M33: 4.1 | N33: 0 | O33: 0 | P33: 0 | Q33: =963600/325851/1.9835*1.02 -> 1.5207075 | R33: =((2.2)*1.04)-T33 -> 1.769431 | S33: 0 | T33: =(0.4704*1.06)*1.04 -> 0.51856896 | U33: =M33-(Q33+R33+S33+T33) -> 0.29129246 | V33: 43 | W33: 0 | X33: =M33-N33-P33-O33-Q33-R33-S33-T33-U33+V33+W33 -> 43 | Y33: =X33-AO33 -> 43 | AC33: 0 | AE33: 0 | AH33: 30 | AI33: =AI32-AH33 -> 3887 | AK33: =N33+O33+P33+Q33+R33+S33+T33+U33+X33+AE33+AH33 -> 77.1 | AL33: =IF(L33<0,L33*-1,0) -> 6.7119486 | AM33: =AK33+AL33 -> 83.811949 | AN33: =V33 -> 43 | AO33: 0 | AV33: 0 | AW33: 40 | AX33: 30 | AZ33: =SUM(N33,P33:U33) -> 4.1
A34: =A33+1 -> 20 | B34: 6901.78 | C34: 290193 | D34: =C34-C33 -> -75 | E34: =C34-152000 -> 138193 | F34: =D34/$D$2 -> -37.811949 | G34: 44 | H34: 1 | I34: =G34+H34 -> 45 | J34: =IF(L34>0,L34,0) -> 0 | K34: =I34+J34 -> 45 | L34: =F34-(I34-AK34) -> -5.7119486 | M34: 4.1 | N34: 0 | O34: 0 | P34: 0 | Q34: =930900/325851/1.9835*1.02 -> 1.469102 | R34: =((2.2)*1.04)-T34 -> 1.769431 | S34: 0 | T34: =(0.4704*1.06)*1.04 -> 0.51856896 | U34: =M34-(Q34+R34+S34+T34) -> 0.34289804 | V34: 43 | W34: 0 | X34: =M34-N34-P34-O34-Q34-R34-S34-T34-U34+V34+W34 -> 43 | Y34: =X34-AO34 -> 43 | AC34: 0 | AE34: 0 | AH34: 30 | AI34: =AI33-AH34 -> 3857 | AK34: =N34+O34+P34+Q34+R34+S34+T34+U34+X34+AE34+AH34 -> 77.1 | AL34: =IF(L34<0,L34*-1,0) -> 5.7119486 | AM34: =AK34+AL34 -> 82.811949 | AN34: =V34 -> 43 | AO34: 0 | AV34: 0.07 | AW34: 36 | AX34: 26 | AZ34: =SUM(N34,P34:U34) -> 4.1
A35: =A34+1 -> 21 | B35: 6901.76 | C35: 290119 | D35: =C35-C34 -> -74 | E35: =C35-152000 -> 138119 | F35: =D35/$D$2 -> -37.307789 | G35: 44 | H35: 1 | I35: =G35+H35 -> 45 | J35: =IF(L35>0,L35,0) -> 0 | K35: =I35+J35 -> 45 | L35: =F35-(I35-AK35) -> -6.4077893 | M35: 2.9 | N35: 0 | O35: 0 | P35: 0 | Q35: =825400/325851/1.9835*1.02 -> 1.3026069 | R35: =((2.2)*1.04)-T35 -> 1.769431 | S35: 0 | T35: =(0.4704*1.06)*1.04 -> 0.51856896 | U35: =M35-(Q35+R35+S35+T35) -> -0.6906069 | V35: 43 | W35: 0 | X35: =M35-N35-P35-O35-Q35-R35-S35-T35-U35+V35+W35 -> 43 | Y35: =X35-AO35 -> 43 | AC35: 0 | AE35: 0 | AH35: 30 | AI35: =AI34-AH35 -> 3827 | AK35: =N35+O35+P35+Q35+R35+S35+T35+U35+X35+AE35+AH35 -> 75.9 | AL35: =IF(L35<0,L35*-1,0) -> 6.4077893 | AM35: =AK35+AL35 -> 82.307789 | AN35: =V35 -> 43 | AO35: 0 | AV35: 0 | AW35: 35 | AX35: 24 | AZ35: =SUM(N35,P35:U35) -> 2.9
A36: =A35+1 -> 22 | B36: 6901.74 | C36: 290044 | D36: =C36-C35 -> -75 | E36: =C36-152000 -> 138044 | F36: =D36/$D$2 -> -37.811949 | G36: 44 | H36: 0.96 | I36: =G36+H36 -> 44.96 | J36: =IF(L36>0,L36,0) -> 0 | K36: =I36+J36 -> 44.96 | L36: =F36-(I36-AK36) -> -5.6719486 | M36: 4.1 | N36: 0 | O36: 0 | P36: 0 | Q36: =938400/325851/1.9835*1.02 -> 1.4809381 | R36: =((2.4)*1.04)-T36 -> 1.977431 | S36: 0 | T36: =(0.4704*1.06)*1.04 -> 0.51856896 | U36: =M36-(Q36+R36+S36+T36) -> 0.12306189 | V36: 43 | W36: 0 | X36: =M36-N36-P36-O36-Q36-R36-S36-T36-U36+V36+W36 -> 43 | Y36: =X36-AO36 -> 43 | AC36: 0 | AE36: 0 | AH36: 30 | AI36: =AI35-AH36 -> 3797 | AK36: =N36+O36+P36+Q36+R36+S36+T36+U36+X36+AE36+AH36 -> 77.1 | AL36: =IF(L36<0,L36*-1,0) -> 5.6719486 | AM36: =AK36+AL36 -> 82.771949 | AN36: =V36 -> 43 | AO36: 0 | AV36: 0.01 | AW36: 28 | AX36: 11 | AZ36: =SUM(N36,P36:U36) -> 4.1
A37: =A36+1 -> 23 | B37: 6901.72 | C37: 289969 | D37: =C37-C36 -> -75 | E37: =C37-152000 -> 137969 | F37: =D37/$D$2 -> -37.811949 | G37: 41 | H37: 0.99 | I37: =G37+H37 -> 41.99 | J37: =IF(L37>0,L37,0) -> 0 | K37: =I37+J37 -> 41.99 | L37: =F37-(I37-AK37) -> -2.6019486 | M37: 4.2 | N37: 0 | O37: 0 | P37: 0 | Q37: =909400/325851/1.9835*1.02 -> 1.4351717 | R37: =((2.4)*1.04)-T37 -> 2.0027862 | S37: 0 | T37: =(0.4474*1.06)*1.04 -> 0.49321376 | U37: =M37-(Q37+R37+S37+T37) -> 0.26882831 | V37: 43 | W37: 0 | X37: =M37-N37-P37-O37-Q37-R37-S37-T37-U37+V37+W37 -> 43 | Y37: =X37-AO37 -> 43 | AC37: 0 | AE37: 0 | AH37: 30 | AI37: =AI36-AH37 -> 3767 | AK37: =N37+O37+P37+Q37+R37+S37+T37+U37+X37+AE37+AH37 -> 77.2 | AL37: =IF(L37<0,L37*-1,0) -> 2.6019486 | AM37: =AK37+AL37 -> 79.801949 | AN37: =V37 -> 43 | AO37: 0 | AV37: 0 | AW37: 37 | AX37: 10 | AZ37: =SUM(N37,P37:U37) -> 4.2
A38: =A37+1 -> 24 | B38: 6901.7 | C38: 289895 | D38: =C38-C37 -> -74 | E38: =C38-152000 -> 137895 | F38: =D38/$D$2 -> -37.307789 | G38: 39 | H38: 1 | I38: =G38+H38 -> 40 | J38: =IF(L38>0,L38,0) -> 0 | K38: =I38+J38 -> 40 | L38: =F38-(I38-AK38) -> -0.10778926 | M38: 4.2 | N38: 0 | O38: 0 | P38: 0 | Q38: =913100/325851/1.9835*1.02 -> 1.4410109 | R38: =((2.6)*1.04)-T38 -> 2.2107862 | S38: 0 | T38: =(0.4474*1.06)*1.04 -> 0.49321376 | U38: =M38-(Q38+R38+S38+T38) -> 0.054989147 | V38: 43 | W38: 0 | X38: =M38-N38-P38-O38-Q38-R38-S38-T38-U38+V38+W38 -> 43 | Y38: =X38-AO38 -> 43 | AC38: 0 | AE38: 0 | AH38: 30 | AI38: =AI37-AH38 -> 3737 | AK38: =N38+O38+P38+Q38+R38+S38+T38+U38+X38+AE38+AH38 -> 77.2 | AL38: =IF(L38<0,L38*-1,0) -> 0.10778926 | AM38: =AK38+AL38 -> 77.307789 | AN38: =V38 -> 43 | AO38: 0 | AV38: 0 | AW38: 41 | AX38: 10 | AZ38: =SUM(N38,P38:U38) -> 4.2
A39: =A38+1 -> 25 | B39: 6901.68 | C39: 289820 | D39: =C39-C38 -> -75 | E39: =C39-152000 -> 137820 | F39: =D39/$D$2 -> -37.811949 | G39: 38 | H39: 1 | I39: =G39+H39 -> 39 | J39: =IF(L39>0,L39,0) -> 0.38805142 | K39: =I39+J39 -> 39.388051 | L39: =F39-(I39-AK39) -> 0.38805142 | M39: 4.2 | N39: 0 | O39: 0 | P39: 0 | Q39: =1103800/325851/1.9835*1.02 -> 1.7419645 | R39: =((2.6)*1.04)-T39 -> 2.2107862 | S39: 0 | T39: =(0.4474*1.06)*1.04 -> 0.49321376 | U39: =M39-(Q39+R39+S39+T39) -> -0.24596449 | V39: 43 | W39: 0 | X39: =M39-N39-P39-O39-Q39-R39-S39-T39-U39+V39+W39 -> 43 | Y39: =X39-AO39 -> 43 | AC39: 0 | AE39: 0 | AH39: 30 | AI39: =AI38-AH39 -> 3707 | AK39: =N39+O39+P39+Q39+R39+S39+T39+U39+X39+AE39+AH39 -> 77.2 | AL39: =IF(L39<0,L39*-1,0) -> 0 | AM39: =AK39+AL39 -> 77.2 | AN39: =V39 -> 43 | AO39: 0 | AV39: 0 | AW39: 45 | AX39: 14 | AZ39: =SUM(N39,P39:U39) -> 4.2
A40: =A39+1 -> 26 | B40: 6901.66 | C40: 289745 | D40: =C40-C39 -> -75 | E40: =C40-152000 -> 137745 | F40: =D40/$D$2 -> -37.811949 | G40: 38 | H40: 0.96 | I40: =G40+H40 -> 38.96 | J40: =IF(L40>0,L40,0) -> 0.42805142 | K40: =I40+J40 -> 39.388051 | L40: =F40-(I40-AK40) -> 0.42805142 | M40: 4.2 | N40: 0 | O40: 0 | P40: 0 | Q40: =939600/325851/1.9835*1.02 -> 1.4828319 | R40: =((2.6)*1.04)-T40 -> 2.2107862 | S40: 0 | T40: =(0.4474*1.06)*1.04 -> 0.49321376 | U40: =M40-(Q40+R40+S40+T40) -> 0.013168112 | V40: 43 | W40: 0 | X40: =M40-N40-P40-O40-Q40-R40-S40-T40-U40+V40+W40 -> 43 | Y40: =X40-AO40 -> 43 | AC40: 0 | AE40: 0 | AH40: 30 | AI40: =AI39-AH40 -> 3677 | AK40: =N40+O40+P40+Q40+R40+S40+T40+U40+X40+AE40+AH40 -> 77.2 | AL40: =IF(L40<0,L40*-1,0) -> 0 | AM40: =AK40+AL40 -> 77.2 | AN40: =V40 -> 43 | AO40: 0 | AV40: 0 | AW40: 40 | AX40: 16 | AZ40: =SUM(N40,P40:U40) -> 4.2
A41: =A40+1 -> 27 | B41: 6901.64 | C41: 289671 | D41: =C41-C40 -> -74 | E41: =C41-152000 -> 137671 | F41: =D41/$D$2 -> -37.307789 | G41: 38 | H41: 0.95 | I41: =G41+H41 -> 38.95 | J41: =IF(L41>0,L41,0) -> 0.94221074 | K41: =I41+J41 -> 39.892211 | L41: =F41-(I41-AK41) -> 0.94221074 | M41: 4.2 | N41: 0 | O41: 0 | P41: 0 | Q41: =863700/325851/1.9835*1.02 -> 1.3630501 | R41: =((2.6)*1.04)-T41 -> 2.2107862 | S41: 0 | T41: =(0.4474*1.06)*1.04 -> 0.49321376 | U41: =M41-(Q41+R41+S41+T41) -> 0.13294987 | V41: 43 | W41: 0 | X41: =M41-N41-P41-O41-Q41-R41-S41-T41-U41+V41+W41 -> 43 | Y41: =X41-AO41 -> 43 | AC41: 0 | AE41: 0 | AH41: 30 | AI41: =AI40-AH41 -> 3647 | AK41: =N41+O41+P41+Q41+R41+S41+T41+U41+X41+AE41+AH41 -> 77.2 | AL41: =IF(L41<0,L41*-1,0) -> 0 | AM41: =AK41+AL41 -> 77.2 | AN41: =V41 -> 43 | AO41: 0 | AV41: 0 | AW41: 45 | AX41: 16 | AZ41: =SUM(N41,P41:U41) -> 4.2
A42: =A41+1 -> 28 | B42: 6901.62 | C42: 289596 | D42: =C42-C41 -> -75 | E42: =C42-152000 -> 137596 | F42: =D42/$D$2 -> -37.811949 | G42: 38 | H42: 0.97 | I42: =G42+H42 -> 38.97 | J42: =IF(L42>0,L42,0) -> 0.41805142 | K42: =I42+J42 -> 39.388051 | L42: =F42-(I42-AK42) -> 0.41805142 | M42: 4.2 | N42: 0 | O42: 0 | P42: 0 | Q42: =1054700/325851/1.9835*1.02 -> 1.6644772 | R42: =((2.4)*1.04)-T42 -> 2.0027862 | S42: 0 | T42: =(0.4474*1.06)*1.04 -> 0.49321376 | U42: =M42-(Q42+R42+S42+T42) -> 0.039522784 | V42: 43 | W42: 0 | X42: =M42-N42-P42-O42-Q42-R42-S42-T42-U42+V42+W42 -> 43 | Y42: =X42-AO42 -> 43 | AC42: 0 | AE42: 0 | AH42: 30 | AI42: =AI41-AH42 -> 3617 | AK42: =N42+O42+P42+Q42+R42+S42+T42+U42+X42+AE42+AH42 -> 77.2 | AL42: =IF(L42<0,L42*-1,0) -> 0 | AM42: =AK42+AL42 -> 77.2 | AN42: =V42 -> 43 | AO42: 0 | AV42: 0 | AW42: 44 | AX42: 15 | AZ42: =SUM(N42,P42:U42) -> 4.2
...

Sheet JAN
K1: MCPHEE RESERVOIR INFLOW/OUTFLOW TABULATION
A2: AF/cfs CONVERT FACTOR | D2: 1.9835 | K2: JANUARY "2012"
D4: RESERVOIR | I4: INFLOW | X4: OUTFLOW | AP4: ADJUSTMENTS | AW4: WEATHER
A5: DATE | B5: RESERV | C5: RESERV | D5: AC FT | E5: ACTIVE | F5: CONV TO | G5: DOLORES | H5: LOST | I5: RECORD | J5: CALC | K5: TOTAL | L5: CALC | M5: DOLORES TUNNEL | V5: LONE | W5: U | X5: TOTAL | Y5: TOTAL | Z5: MVI | AA5: MVI | AB5: MVI | AC5: TO EX & | AD5: MVI | AE5: DV CR | AF5: D/S SENIOR | AH5: BELOW | AI5: FISH | AJ5: SPILL | AK5: RECORD | AL5: CALC | AM5: TOTAL | AN5: NAR | AO5: MVI | AP5: MVI | AQ5: MVI | AR5: DIST. | AS5: U/S | AT5: TOTTEN | AU5: UTES | AV5: RAIN | AW5: MAX | AX5: MIN | AZ5: TOTAL
A6: DEC | B6: ELEV | D6: CHANGE | E6: CAP | F6: CFS | G6: RIVER | H6: CAN | I6: INFLOW | J6: INFLOW | K6: INFLOW | L6: INF/OTF | M6: TOT DIV | N6: WET | O6: UTE | P6: QUEST | Q6: MWC | R6: CORTEZ | T6: UTE | U6: F-BAY | V6: PINE | W6: LAT | X6: MVI | Y6: MVI | Z6: CALL | AA6: CALL | AB6: APR- | AC6: U/S EX | AD6: PROJ | AE6: CANAL | AF6: MVIC | AG6: PROJ | AH6: MCP | AI6: LEFT | AK6: OTF | AL6: OTF | AM6: OTF | AN6: FILL | AO6: STOCK | AP6: STORED | AQ6: STORED | AR6: CLASS | AS6: USERS | AT6: (FRESH | AU6: FROM | AW6: TMP | AX6: TMP | AZ6: TUNNEL
N7: LAND | O7: F&R | Q7: NON - | R7: NON - | S7: PROJ | T7: PROJ | U7: BAL | X7: WATER | Y7: IRRIG. | Z7: STOR | AA7: SPILLED | AB7: JUNE | AF7: 1.7 | AG7: 1.3 | AP7: Apr - Jun | AQ7: EVAP | AR7: "B" | AS7: EXCH | AT7: WATER) | AU7: DWCD | AZ7: Misc.
Q8: PROJ | R8: PROJ | X8: USED | Y8: WATER | AA8: OR | AB8: (DIV+
R9: 4.2 | Y9: USED | AA9: USED | AB9: CALL)
C10: AC. Ft. | E10: AC FT | G10: CFS | H10: CFS | I10: CFS | J10: CFS | K10: CFS | L10: CFS | M10: CFS | N10: CFS | O10: CFS | P10: CFS | Q10: CFS | R10: CFS | S10: CFS | T10: CFS | U10: CFS | V10: CFS | W10: CFS | X10: 153400 | Y10: 150400 | AB10: 72000 | AC10: CFS | AD10: CFS | AE10: CFS | AF10: CFS | AG10: CFS | AH10: CFS | AI10: CFS | AJ10: CFS | AK10: CFS | AL10: CFS | AM10: CFS | AN10: CFS | AO10: CFS | AP10: CFS | AQ10: AC.FT. | AR10: CFS | AS10: CFS | AT10: CFS | AU10: CFS | AZ10: Outflow
N11: 1.03 | O11: 1.05 | P11: 1.02 | Q11: 1.02 | R11: 1.04 | T11: 1.04 | X11: CFS | Y11: CFS | Z11: CFS | AA11: CFS | AB11: Ac. Ft. | AZ11: CFS
A12: SEASON BAL
A13: YTD | B13: =DEC!B45 -> 6901.56 | C13: =DEC!C45 -> 289372 | D13: =DEC!D54 -> -4239 | E13: =DEC!E54 -> 137372 | F13: =DEC!F53 -> -2137.1313 | G13: =DEC!G53 -> 3360 | H13: =DEC!H53 -> 34.11 | I13: =DEC!I53 -> 3393.49 | J13: =DEC!J53 -> 114.87441 | K13: =DEC!K53 -> 3508.3644 | L13: =DEC!L53 -> -336.12133 | M13: =DEC!M53 -> 310 | ... Y13: =DEC!Y53 -> 2946.8088 | AC13: =DEC!AC53 -> 192.7 | AH13: =DEC!AH53 -> 1824 | AI13: =DEC!AI53 -> 3527 | AK13: =DEC!AK53 -> 5194.5 | AL13: =DEC!AL53 -> 450.99574 | AM13: =DEC!AM53 -> 5645.4957 | AN13: =DEC!AN53 -> 2946.8 | AO13: =DEC!AO53 -> 202.79707 | AV13: =DEC!AV53 -> 0.95 | AZ13: =DEC!AZ53 -> 220.89417
A15: 1 | B15: 6901.54 | C15: 289297 | D15: =C15-C13 -> -75 | E15: =C15-152000 -> 137297 | F15: =D15/$D$2 -> -37.811949 | G15: 41 | H15: 0.89 | I15: =G15+H15 -> 41.89 | J15: =IF(L15>0,L15,0) -> 0 | K15: =I15+J15 -> 41.89 | L15: =F15-(I15-AK15) -> -3.1019486 | M15: 3.6 | N15: 0 | O15: 0 | P15: 0 | Q15: =950000/325851/1.9835*1.02 -> 1.4992447 | R15: =((2.2)*1.04)-T15 -> 1.8117632 | S15: 0 | T15: =(0.432*1.06)*1.04 -> 0.4762368 | U15: =M15-(Q15+R15+S15+T15) -> -0.18724467 | V15: 43 | W15: 0 | X15: =M15-N15-P15-O15-Q15-R15-S15-T15-U15+V15+W15 -> 43 | Y15: =X15-AO15 -> 43 | AC15: 0 | AE15: 0 | AH15: 30 | AI15: =AI13-AH15 -> 3497 | AK15: =N15+O15+P15+Q15+R15+S15+T15+U15+X15+AE15+AH15 -> 76.6 | AL15: =IF(L15<0,L15*-1,0) -> 3.1019486 | AM15: =AK15+AL15 -> 79.701949 | AN15: =X15 -> 43 | AO15: 0 | AV15: 0 | AW15: 48 | AX15: 16 | AZ15: =SUM(N15,P15:U15) -> 3.6
A16: =A15+1 -> 2 | B16: 6901.52 | C16: 289223 | D16: =C16-C15 -> -74 | E16: =C16-152000 -> 137223 | F16: =D16/$D$2 -> -37.307789 | G16: 42 | H16: 0.86 | I16: =G16+H16 -> 42.86 | J16: =IF(L16>0,L16,0) -> 0 | K16: =I16+J16 -> 42.86 | L16: =F16-(I16-AK16) -> -4.1677893 | M16: 3 | N16: 0 | O16: 0 | P16: 0 | Q16: =1037100/325851/1.9835*1.02 -> 1.6367017 | R16: =((1.8)*1.04)-T16 -> 1.3957632 | S16: 0 | T16: =(0.432*1.06)*1.04 -> 0.4762368 | U16: =M16-(Q16+R16+S16+T16) -> -0.50870174 | V16: 43 | W16: 0 | X16: =M16-N16-P16-O16-Q16-R16-S16-T16-U16+V16+W16 -> 43 | Y16: =X16-AO16 -> 43 | AC16: 0 | AE16: 0 | AH16: 30 | AI16: =AI15-AH16 -> 3467 | AK16: =N16+O16+P16+Q16+R16+S16+T16+U16+X16+AE16+AH16 -> 76 | AL16: =IF(L16<0,L16*-1,0) -> 4.1677893 | AM16: =AK16+AL16 -> 80.167789 | AN16: =X16 -> 43 | AO16: 0 | AV16: 0 | AW16: 53 | AX16: 18 | AZ16: =SUM(N16,P16:U16) -> 3
A17: =A16+1 -> 3 | B17: 6901.5 | C17: 289148 | D17: =C17-C16 -> -75 | E17: =C17-152000 -> 137148 | F17: =D17/$D$2 -> -37.811949 | G17: 42 | H17: 0.9 | I17: =G17+H17 -> 42.9 | J17: =IF(L17>0,L17,0) -> 0 | K17: =I17+J17 -> 42.9 | L17: =F17-(I17-AK17) -> -3.8119486 | M17: 3.9 | N17: 0 | O17: 0 | P17: 0 | Q17: =925000/325851/1.9835*1.02 -> 1.4597909 | R17: =((1.8)*1.04)-T17 -> 1.3957632 | S17: 0 | T17: =(0.432*1.06)*1.04 -> 0.4762368 | U17: =M17-(Q17+R17+S17+T17) -> 0.56820914 | V17: 43 | W17: 0 | X17: =M17-N17-P17-O17-Q17-R17-S17-T17-U17+V17+W17 -> 43 | Y17: =X17-AO17 -> 43 | AC17: 0 | AE17: 0 | AH17: 30 | AI17: =AI16-AH17 -> 3437 | AK17: =N17+O17+P17+Q17+R17+S17+T17+U17+X17+AE17+AH17 -> 76.9 | AL17: =IF(L17<0,L17*-1,0) -> 3.8119486 | AM17: =AK17+AL17 -> 80.711949 | AN17: =X17 -> 43 | AO17: 0 | AV17: 0 | AW17: 51 | AX17: 20 | AZ17: =SUM(N17,P17:U17) -> 3.9
