Workbook

Sheet NOV
K1: MC PHEE RESERVOIR IN/OUT FLOW TABULATION
A2: AF/cfs CONVERT FACTOR | D2: 1.9835 | L2: NOVEMBER "2000"
A4: DATE | B4: RESERV | C4: RESERV | D4: AC FT | E4: ACTIVE | F4: CONV TO | G4: DOLORES | H4: LOST | I4: RECORDED | J4: CALC | K4: TOTAL | L4: CALC | M4: DOLORES TUNNEL | Q4: LONE | R4: U | S4: TOTAL | T4: MVI | U4: DV CR | V4: BELOW | W4: REMAIN | X4: RECORDED | Y4: CALC | Z4: TOTAL | AA4: RAIN | AB4: MAX | AC4: MIN | AD4: DATE
A5: "NOV" | B5: ELEV | C5: AC FT | D5: CHANGE | E5: CAP | F5: CFS | G5: RIVER | H5: CANYON | I5: INFLOW | J5: INFLOW | K5: INFLOW | L5: INF/OTF | M5: TOT DIV | N5: WETLAND | O5: UTE F&R | P5: MVI,CTZ | Q5: PINE | R5: LAT | S5: MVI | T5: CALL | U5: CANAL | V5: MC PHEE | W5: RELEASE | X5: OUTFLOW | Y5: OUTFLOW | Z5: OUTFLOW | AB5: TMP | AC5: TMP | AD5: "NOV"
A7: SEASON BAL
A8: YTD | B8: 6880.43 | C8: 217465 | W8: 6003
A10: 1 | B10: 6880.45 | C10: 217525 | D10: =C10-C8 -> 60 | E10: =C10-152000 -> 65525 | F10: =D10/$D$2 -> 30.249559 | G10: 97 | H10: 0 | I10: =G10+H10 -> 97 | J10: =IF(L10>0,L10,0) -> 0 | K10: =I10+J10 -> 97 | L10: =F10-(I10-X10) -> -13.450441 | M10: 6.3 | N10: 0 | O10: 18.1 | P10: =M10-(N10+O10) -> -11.8 | Q10: 0 | R10: 0 | S10: =SUM(P10:R10) -> -11.8 | U10: 0 | V10: 47 | W10: =W8-40-2 -> 5961 | X10: =N10+O10+S10+U10+V10 -> 53.3 | Y10: =IF(L10<0,L10*-1,0) -> 13.450441 | Z10: =X10+Y10 -> 66.750441 | AA10: 0 | AB10: 36 | AC10: 24 | AD10: 1
A11: =A10+1 -> 2 | B11: 6880.47 | C11: 217586 | D11: =C11-C10 -> 61 | E11: =C11-152000 -> 65586 | F11: =D11/$D$2 -> 30.753718 | G11: 91 | H11: 0 | I11: =G11+H11 -> 91 | J11: =IF(L11>0,L11,0) -> 0 | K11: =I11+J11 -> 91 | L11: =F11-(I11-X11) -> -12.946282 | M11: 6.3 | N11: 0 | O11: 18.7 | P11: =M11-(N11+O11) -> -12.4 | Q11: 0 | R11: 0 | S11: =SUM(P11:R11) -> -12.4 | U11: 0 | V11: 41 | W11: =W10-V11 -> 5920 | X11: =N11+O11+S11+U11+V11 -> 47.3 | Y11: =IF(L11<0,L11*-1,0) -> 12.946282 | Z11: =X11+Y11 -> 60.246282 | AA11: 0 | AB11: 34 | AC11: 24 | AD11: =AD10+1 -> 2
A12: =A11+1 -> 3 | B12: 6880.49 | C12: 217646 | D12: =C12-C11 -> 60 | E12: =C12-152000 -> 65646 | F12: =D12/$D$2 -> 30.249559 | G12: 87 | H12: 0 | I12: =G12+H12 -> 87 | J12: =IF(L12>0,L12,0) -> 0 | K12: =I12+J12 -> 87 | L12: =F12-(I12-X12) -> -9.4504411 | M12: 6.3 | N12: 0 | O12: 7.1 | P12: =M12-(N12+O12) -> -0.8 | Q12: 0 | R12: 0 | S12: =SUM(P12:R12) -> -0.8 | U12: 0 | V12: 41 | W12: =W11-V12 -> 5879 | X12: =N12+O12+S12+U12+V12 -> 47.3 | Y12: =IF(L12<0,L12*-1,0) -> 9.4504411 | Z12: =X12+Y12 -> 56.750441 | AA12: 0 | AB12: 52 | AC12: 26 | AD12: =AD11+1 -> 3
A13: =A12+1 -> 4 | B13: 6880.53 | C13: 217767 | D13: =C13-C12 -> 121 | E13: =C13-152000 -> 65767 | F13: =D13/$D$2 -> 61.003277 | G13: 87 | H13: 0 | I13: =G13+H13 -> 87 | J13: =IF(L13>0,L13,0) -> 21.303277 | K13: =I13+J13 -> 108.30328 | L13: =F13-(I13-X13) -> 21.303277 | M13: 6.3 | N13: 0 | O13: 3.2 | P13: =M13-(N13+O13) -> 3.1 | Q13: 0 | R13: 0 | S13: =SUM(P13:R13) -> 3.1 | U13: 0 | V13: 41 | W13: =W12-V13 -> 5838 | X13: =N13+O13+S13+U13+V13 -> 47.3 | Y13: =IF(L13<0,L13*-1,0) -> 0 | Z13: =X13+Y13 -> 47.3 | AA13: 0 | AB13: 50 | AC13: 30 | AD13: =AD12+1 -> 4
A14: =A13+1 -> 5 | B14: 6880.59 | C14: 217948 | D14: =C14-C13 -> 181 | E14: =C14-152000 -> 65948 | F14: =D14/$D$2 -> 91.252836 | G14: 97 | H14: 0 | I14: =G14+H14 -> 97 | J14: =IF(L14>0,L14,0) -> 41.552836 | K14: =I14+J14 -> 138.55284 | L14: =F14-(I14-X14) -> 41.552836 | M14: 6.3 | N14: 0 | O14: 3.6 | P14: =M14-(N14+O14) -> 2.7 | Q14: 0 | R14: 0 | S14: =SUM(P14:R14) -> 2.7 | U14: 0 | V14: 41 | W14: =W13-V14 -> 5797 | X14: =N14+O14+S14+U14+V14 -> 47.3 | Y14: =IF(L14<0,L14*-1,0) -> 0 | Z14: =X14+Y14 -> 47.3 | AA14: 0.34 | AB14: 40 | AC14: 31 | AD14: =AD13+1 -> 5
A15: =A14+1 -> 6 | B15: 6880.63 | C15: 218069 | D15: =C15-C14 -> 121 | E15: =C15-152000 -> 66069 | F15: =D15/$D$2 -> 61.003277 | G15: 85 | H15: 0 | I15: =G15+H15 -> 85 | J15: =IF(L15>0,L15,0) -> 23.303277 | K15: =I15+J15 -> 108.30328 | L15: =F15-(I15-X15) -> 23.303277 | M15: 6.3 | N15: 0 | O15: =3.37*1.05 -> 3.5385 | P15: =M15-(N15+O15) -> 2.7615 | Q15: 0 | R15: 0 | S15: =SUM(P15:R15) -> 2.7615 | U15: 0 | V15: 41 | W15: =W14-V15 -> 5756 | X15: =N15+O15+S15+U15+V15 -> 47.3 | Y15: =IF(L15<0,L15*-1,0) -> 0 | Z15: =X15+Y15 -> 47.3 | AA15: 0 | AB15: 34 | AC15: 22 | AD15: =AD14+1 -> 6
A16: =A15+1 -> 7 | B16: 6880.63 | C16: 218069 | D16: =C16-C15 -> 0 | E16: =C16-152000 -> 66069 | F16: =D16/$D$2 -> 0 | G16: 71 | H16: 0 | I16: =G16+H16 -> 71 | J16: =IF(L16>0,L16,0) -> 0 | K16: =I16+J16 -> 71 | L16: =F16-(I16-X16) -> -23.7 | M16: 6.3 | N16: 0 | O16: =3.37*1.05 -> 3.5385 | P16: =M16-(N16+O16) -> 2.7615 | Q16: 0 | R16: 0 | S16: =SUM(P16:R16) -> 2.7615 | U16: 0 | V16: 41 | W16: =W15-V16 -> 5715 | X16: =N16+O16+S16+U16+V16 -> 47.3 | Y16: =IF(L16<0,L16*-1,0) -> 23.7 | Z16: =X16+Y16 -> 71 | AA16: 0 | AB16: 32 | AC16: 18 | AD16: =AD15+1 -> 7
A17: =A16+1 -> 8 | B17: 6880.63 | C17: 218069 | D17: =C17-C16 -> 0 | E17: =C17-152000 -> 66069 | F17: =D17/$D$2 -> 0 | G17: 72 | H17: 0 | I17: =G17+H17 -> 72 | J17: =IF(L17>0,L17,0) -> 0 | K17: =I17+J17 -> 72 | L17: =F17-(I17-X17) -> -24.8 | M17: 6.2 | N17: 0 | O17: =3.37*1.05 -> 3.5385 | P17: =M17-(N17+O17) -> 2.6615 | Q17: 0 | R17: 0 | S17: =SUM(P17:R17) -> 2.6615 | U17: 0 | V17: 41 | W17: =W16-V17 -> 5674 | X17: =N17+O17+S17+U17+V17 -> 47.2 | Y17: =IF(L17<0,L17*-1,0) -> 24.8 | Z17: =X17+Y17 -> 72 | AA17: 0 | AB17: 42 | AC17: 12 | AD17: =AD16+1 -> 8
A18: =A17+1 -> 9 | B18: 6880.65 | C18: 218130 | D18: =C18-C17 -> 61 | E18: =C18-152000 -> 66130 | F18: =D18/$D$2 -> 30.753718 | G18: 72 | H18: 0 | I18: =G18+H18 -> 72 | J18: =IF(L18>0,L18,0) -> 6.6537182 | K18: =I18+J18 -> 78.653718 | L18: =F18-(I18-X18) -> 6.6537182 | M18: 5.9 | N18: 0 | O18: =1.58+3.54*1.05 -> 5.297 | P18: =M18-(N18+O18) -> 0.603 | Q18: 0 | R18: 0 | S18: =SUM(P18:R18) -> 0.603 | U18: 0 | V18: 42 | W18: =W17-V18 -> 5632 | X18: =N18+O18+S18+U18+V18 -> 47.9 | Y18: =IF(L18<0,L18*-1,0) -> 0 | Z18: =X18+Y18 -> 47.9 | AA18: 0 | AB18: 34 | AC18: 17 | AD18: =AD17+1 -> 9
A19: =A18+1 -> 10 | B19: 6880.67 | C19: 218190 | D19: =C19-C18 -> 60 | E19: =C19-152000 -> 66190 | F19: =D19/$D$2 -> 30.249559 | G19: 73 | H19: 0 | I19: =G19+H19 -> 73 | J19: =IF(L19>0,L19,0) -> 4.1495589 | K19: =I19+J19 -> 77.149559 | L19: =F19-(I19-X19) -> 4.1495589 | M19: 5.9 | N19: 0 | O19: =1.68*1.05 -> 1.764 | P19: =M19-(N19+O19) -> 4.136 | Q19: 0 | R19: 0 | S19: =SUM(P19:R19) -> 4.136 | U19: 0 | V19: 41 | W19: =W18-V19 -> 5591 | X19: =N19+O19+S19+U19+V19 -> 46.9 | Y19: =IF(L19<0,L19*-1,0) -> 0 | Z19: =X19+Y19 -> 46.9 | AA19: 0 | AB19: 28 | AC19: 19 | AD19: =AD18+1 -> 10
A20: =A19+1 -> 11 | B20: 6880.69 | C20: 218251 | D20: =C20-C19 -> 61 | E20: =C20-152000 -> 66251 | F20: =D20/$D$2 -> 30.753718 | G20: 74 | H20: 0 | I20: =G20+H20 -> 74 | J20: =IF(L20>0,L20,0) -> 3.6537182 | K20: =I20+J20 -> 77.653718 | L20: =F20-(I20-X20) -> 3.6537182 | M20: 5.9 | N20: 0 | O20: =0.78*1.05 -> 0.819 | P20: =M20-(N20+O20) -> 5.081 | Q20: 0 | R20: 0 | S20: =SUM(P20:R20) -> 5.081 | U20: 0 | V20: 41 | W20: =W19-V20 -> 5550 | X20: =N20+O20+S20+U20+V20 -> 46.9 | Y20: =IF(L20<0,L20*-1,0) -> 0 | Z20: =X20+Y20 -> 46.9 | AA20: 0.57 | AB20: 28 | AC20: 24 | AD20: =AD19+1 -> 11
A21: =A20+1 -> 12 | B21: 6880.7 | C21: 218281 | D21: =C21-C20 -> 30 | E21: =C21-152000 -> 66281 | F21: =D21/$D$2 -> 15.124779 | G21: 71 | H21: 0 | I21: =G21+H21 -> 71 | J21: =IF(L21>0,L21,0) -> 0 | K21: =I21+J21 -> 71 | L21: =F21-(I21-X21) -> -8.9752206 | M21: 5.9 | N21: 0 | O21: =0.63*1.05 -> 0.6615 | P21: =M21-(N21+O21) -> 5.2385 | Q21: 0 | R21: 0 | S21: =SUM(P21:R21) -> 5.2385 | U21: 0 | V21: 41 | W21: =W20-V21 -> 5509 | X21: =N21+O21+S21+U21+V21 -> 46.9 | Y21: =IF(L21<0,L21*-1,0) -> 8.9752206 | Z21: =X21+Y21 -> 55.875221 | AA21: 0 | AB21: 22 | AC21: 17 | AD21: =AD20+1 -> 12
A22: =A21+1 -> 13 | B22: 6880.7 | C22: 218281 | D22: =C22-C21 -> 0 | E22: =C22-152000 -> 66281 | F22: =D22/$D$2 -> 0 | G22: 54 | H22: 0 | I22: =G22+H22 -> 54 | J22: =IF(L22>0,L22,0) -> 0 | K22: =I22+J22 -> 54 | L22: =F22-(I22-X22) -> -7.3 | M22: 5.7 | N22: 0 | O22: =4.33*1.05 -> 4.5465 | P22: =M22-(N22+O22) -> 1.1535 | Q22: 0 | R22: 0 | S22: =SUM(P22:R22) -> 1.1535 | U22: 0 | V22: 41 | W22: =W21-V22 -> 5468 | X22: =N22+O22+S22+U22+V22 -> 46.7 | Y22: =IF(L22<0,L22*-1,0) -> 7.3 | Z22: =X22+Y22 -> 54 | AA22: 0 | AB22: 32 | AC22: 2 | AD22: =AD21+1 -> 13
A23: =A22+1 -> 14 | B23: 6880.71 | C23: 218311 | D23: =C23-C22 -> 30 | E23: =C23-152000 -> 66311 | F23: =D23/$D$2 -> 15.124779 | G23: 56 | H23: 0 | I23: =G23+H23 -> 56 | J23: =IF(L23>0,L23,0) -> 5.6247794 | K23: =I23+J23 -> 61.624779 | L23: =F23-(I23-X23) -> 5.6247794 | M23: 5.5 | N23: 0 | O23: 4.6 | P23: =M23-(N23+O23) -> 0.9 | Q23: 0 | R23: 0 | S23: =SUM(P23:R23) -> 0.9 | U23: 0 | V23: 41 | W23: =W22-V23 -> 5427 | X23: =N23+O23+S23+U23+V23 -> 46.5 | Y23: =IF(L23<0,L23*-1,0) -> 0 | Z23: =X23+Y23 -> 46.5 | AA23: 0 | AB23: 36 | AC23: 4 | AD23: =AD22+1 -> 14
A24: =A23+1 -> 15 | B24: 6880.71 | C24: 218311 | D24: =C24-C23 -> 0 | E24: =C24-152000 -> 66311 | F24: =D24/$D$2 -> 0 | G24: 56 | H24: 0 | I24: =G24+H24 -> 56 | J24: =IF(L24>0,L24,0) -> 0 | K24: =I24+J24 -> 56 | L24: =F24-(I24-X24) -> -9.5 | M24: 5.5 | N24: 0 | O24: 0.88 | P24: =M24-(N24+O24) -> 4.62 | Q24: 0 | R24: 0 | S24: =SUM(P24:R24) -> 4.62 | U24: 0 | V24: 41 | W24: =W23-V24 -> 5386 | X24: =N24+O24+S24+U24+V24 -> 46.5 | Y24: =IF(L24<0,L24*-1,0) -> 9.5 | Z24: =X24+Y24 -> 56 | AA24: 0 | AB24: 32 | AC24: 12 | AD24: =AD23+1 -> 15
A25: =A24+1 -> 16 | B25: 6880.72 | C25: 218341 | D25: =C25-C24 -> 30 | E25: =C25-152000 -> 66341 | F25: =D25/$D$2 -> 15.124779 | G25: 56 | H25: 0 | I25: =G25+H25 -> 56 | J25: =IF(L25>0,L25,0) -> 5.5247794 | K25: =I25+J25 -> 61.524779 | L25: =F25-(I25-X25) -> 5.5247794 | M25: 5.4 | N25: 0 | O25: 0 | P25: =M25-(N25+O25) -> 5.4 | Q25: 0 | R25: 0 | S25: =SUM(P25:R25) -> 5.4 | U25: 0 | V25: 41 | W25: =W24-V25 -> 5345 | X25: =N25+O25+S25+U25+V25 -> 46.4 | Y25: =IF(L25<0,L25*-1,0) -> 0 | Z25: =X25+Y25 -> 46.4 | AA25: 0.44 | AB25: 35 | AC25: 8 | AD25: =AD24+1 -> 16
A26: =A25+1 -> 17 | B26: 6880.72 | C26: 218341 | D26: =C26-C25 -> 0 | E26: =C26-152000 -> 66341 | F26: =D26/$D$2 -> 0 | G26: 58 | H26: 0 | I26: =G26+H26 -> 58 | J26: =IF(L26>0,L26,0) -> 0 | K26: =I26+J26 -> 58 | L26: =F26-(I26-X26) -> -11.9 | M26: 5.1 | N26: 0 | O26: 0 | P26: =M26-(N26+O26) -> 5.1 | Q26: 0 | R26: 0 | S26: =SUM(P26:R26) -> 5.1 | U26: 0 | V26: 41 | W26: =W25-V26 -> 5304 | X26: =N26+O26+S26+U26+V26 -> 46.1 | Y26: =IF(L26<0,L26*-1,0) -> 11.9 | Z26: =X26+Y26 -> 58 | AA26: 0 | AB26: 28 | AC26: 3 | AD26: =AD25+1 -> 17
A27: =A26+1 -> 18 | B27: 6880.73 | C27: 218372 | D27: =C27-C26 -> 31 | E27: =C27-152000 -> 66372 | F27: =D27/$D$2 -> 15.628939 | G27: 59 | H27: 0 | I27: =G27+H27 -> 59 | J27: =IF(L27>0,L27,0) -> 2.7289387 | K27: =I27+J27 -> 61.728939 | L27: =F27-(I27-X27) -> 2.7289387 | M27: 5.1 | N27: 0 | O27: 0 | P27: =M27-(N27+O27) -> 5.1 | Q27: 0 | R27: 0 | S27: =SUM(P27:R27) -> 5.1 | U27: 0 | V27: 41 | W27: =W26-V27 -> 5263 | X27: =N27+O27+S27+U27+V27 -> 46.1 | Y27: =IF(L27<0,L27*-1,0) -> 0 | Z27: =X27+Y27 -> 46.1 | AA27: 0 | AB27: 32 | AC27: 3 | AD27: =AD26+1 -> 18
A28: =A27+1 -> 19 | B28: 6880.73 | C28: 218372 | D28: =C28-C27 -> 0 | E28: =C28-152000 -> 66372 | F28: =D28/$D$2 -> 0 | G28: 51 | H28: 0 | I28: =G28+H28 -> 51 | J28: =IF(L28>0,L28,0) -> 0 | K28: =I28+J28 -> 51 | L28: =F28-(I28-X28) -> -4.9 | M28: 5.1 | N28: 0 | O28: 0 | P28: =M28-(N28+O28) -> 5.1 | Q28: 0 | R28: 0 | S28: =SUM(P28:R28) -> 5.1 | U28: 0 | V28: 41 | W28: =W27-V28 -> 5222 | X28: =N28+O28+S28+U28+V28 -> 46.1 | Y28: =IF(L28<0,L28*-1,0) -> 4.9 | Z28: =X28+Y28 -> 51 | AA28: 0 | AB28: 42 | AC28: 14 | AD28: =AD27+1 -> 19
A29: =A28+1 -> 20 | B29: 6880.74 | C29: 218402 | D29: =C29-C28 -> 30 | E29: =C29-152000 -> 66402 | F29: =D29/$D$2 -> 15.124779 | G29: 54 | H29: 0 | I29: =G29+H29 -> 54 | J29: =IF(L29>0,L29,0) -> 7.2247794 | K29: =I29+J29 -> 61.224779 | L29: =F29-(I29-X29) -> 7.2247794 | M29: 5.1 | N29: 0 | O29: 0 | P29: =M29-(N29+O29) -> 5.1 | Q29: 0 | R29: 0 | S29: =SUM(P29:R29) -> 5.1 | U29: 0 | V29: 41 | W29: =W28-V29 -> 5181 | X29: =N29+O29+S29+U29+V29 -> 46.1 | Y29: =IF(L29<0,L29*-1,0) -> 0 | Z29: =X29+Y29 -> 46.1 | AA29: 0 | AB29: 50 | AC29: 16 | AD29: =AD28+1 -> 20
A30: =A29+1 -> 21 | B30: 6880.74 | C30: 218402 | D30: =C30-C29 -> 0 | E30: =C30-152000 -> 66402 | F30: =D30/$D$2 -> 0 | G30: 57 | H30: 0 | I30: =G30+H30 -> 57 | J30: =IF(L30>0,L30,0) -> 0 | K30: =I30+J30 -> 57 | L30: =F30-(I30-X30) -> -10.9 | M30: 5.1 | N30: 0 | O30: 0 | P30: =M30-(N30+O30) -> 5.1 | Q30: 0 | R30: 0 | S30: =SUM(P30:R30) -> 5.1 | U30: 0 | V30: 41 | W30: =W29-V30 -> 5140 | X30: =N30+O30+S30+U30+V30 -> 46.1 | Y30: =IF(L30<0,L30*-1,0) -> 10.9 | Z30: =X30+Y30 -> 57 | AA30: 0 | AB30: 48 | AC30: 18 | AD30: =AD29+1 -> 21
A31: =A30+1 -> 22 | B31: 6880.75 | C31: 218432 | D31: =C31-C30 -> 30 | E31: =C31-152000 -> 66432 | F31: =D31/$D$2 -> 15.124779 | G31: 64 | H31: 0 | I31: =G31+H31 -> 64 | J31: =IF(L31>0,L31,0) -> 0 | K31: =I31+J31 -> 64 | L31: =F31-(I31-X31) -> -2.7752206 | M31: 5.1 | N31: 0 | O31: 0 | P31: =M31-(N31+O31) -> 5.1 | Q31: 0 | R31: 0 | S31: =SUM(P31:R31) -> 5.1 | U31: 0 | V31: 41 | W31: =W30-V31 -> 5099 | X31: =N31+O31+S31+U31+V31 -> 46.1 | Y31: =IF(L31<0,L31*-1,0) -> 2.7752206 | Z31: =X31+Y31 -> 48.875221 | AA31: 0.09 | AB31: 51 | AC31: 24 | AD31: =AD30+1 -> 22
A32: =A31+1 -> 23 | B32: 6880.75 | C32: 218432 | D32: =C32-C31 -> 0 | E32: =C32-152000 -> 66432 | F32: =D32/$D$2 -> 0 | G32: 62 | H32: 0 | I32: =G32+H32 -> 62 | J32: =IF(L32>0,L32,0) -> 0 | K32: =I32+J32 -> 62 | L32: =F32-(I32-X32) -> -15.9 | M32: 5.1 | N32: 0 | O32: 0 | P32: =M32-(N32+O32) -> 5.1 | Q32: 0 | R32: 0 | S32: =SUM(P32:R32) -> 5.1 | U32: 0 | V32: 41 | W32: =W31-V32 -> 5058 | X32: =N32+O32+S32+U32+V32 -> 46.1 | Y32: =IF(L32<0,L32*-1,0) -> 15.9 | Z32: =X32+Y32 -> 62 | AA32: 0 | AB32: 53 | AC32: 25 | AD32: =AD31+1 -> 23
A33: =A32+1 -> 24 | B33: 6880.75 | C33: 218432 | D33: =C33-C32 -> 0 | E33: =C33-152000 -> 66432 | F33: =D33/$D$2 -> 0 | G33: 56 | H33: 0.24 | I33: =G33+H33 -> 56.24 | J33: =IF(L33>0,L33,0) -> 0 | K33: =I33+J33 -> 56.24 | L33: =F33-(I33-X33) -> -10.14 | M33: 5.1 | N33: 0 | O33: 0 | P33: =M33-(N33+O33) -> 5.1 | Q33: 0 | R33: 0 | S33: =SUM(P33:R33) -> 5.1 | U33: 0 | V33: 41 | W33: =W32-V33 -> 5017 | X33: =N33+O33+S33+U33+V33 -> 46.1 | Y33: =IF(L33<0,L33*-1,0) -> 10.14 | Z33: =X33+Y33 -> 56.24 | AA33: 0 | AB33: 44 | AC33: 15 | AD33: =AD32+1 -> 24
A34: =A33+1 -> 25 | B34: 6880.76 | C34: 218462 | D34: =C34-C33 -> 30 | E34: =C34-152000 -> 66462 | F34: =D34/$D$2 -> 15.124779 | G34: 61 | H34: 0.61 | I34: =G34+H34 -> 61.61 | J34: =IF(L34>0,L34,0) -> 0.11477943 | K34: =I34+J34 -> 61.724779 | L34: =F34-(I34-X34) -> 0.11477943 | M34: 5.6 | N34: 0 | O34: 0 | P34: =M34-(N34+O34) -> 5.6 | Q34: 0 | R34: 0 | S34: =SUM(P34:R34) -> 5.6 | U34: 0 | V34: 41 | W34: =W33-V34 -> 4976 | X34: =N34+O34+S34+U34+V34 -> 46.6 | Y34: =IF(L34<0,L34*-1,0) -> 0 | Z34: =X34+Y34 -> 46.6 | AA34: 0 | AB34: 42 | AC34: 18 | AD34: =AD33+1 -> 25
... A38: =A37+1 -> 29 | B38: 6880.79 | C38: 218553 | D38: =C38-C37 -> 30 | E38: =C38-152000 -> 66553 | F38: =D38/$D$2 -> 15.124779 | G38: 60 | H38: 0.58 | I38: =G38+H38 -> 60.58 | J38: =IF(L38>0,L38,0) -> 0.64477943 | K38: =I38+J38 -> 61.224779 | L38: =F38-(I38-X38) -> 0.64477943 | M38: 5.1 | N38: 0 | O38: 0 | P38: =M38-(N38+O38) -> 5.1 | Q38: 0 | R38: 0 | S38: =SUM(P38:R38) -> 5.1 | U38: 0 | V38: 41 | W38: =W37-V38 -> 4812 | X38: =N38+O38+S38+U38+V38 -> 46.1 | Y38: =IF(L38<0,L38*-1,0) -> 0 | Z38: =X38+Y38 -> 46.1 | AA38: 0 | AB38: 54 | AC38: 23 | AD38: =AD37+1 -> 29
A39: 30 | B39: 6880.8 | C39: 218583 | D39: =C39-C38 -> 30 | E39: =C39-152000 -> 66583 | F39: =D39/$D$2 -> 15.124779 | G39: 63 | H39: 0.63 | I39: =G39+H39 -> 63.63 | J39: =IF(L39>0,L39,0) -> 0 | K39: =I39+J39 -> 63.63 | L39: =F39-(I39-X39) -> -2.4052206 | M39: 5.1 | N39: 0 | O39: 0 | P39: =M39-(N39+O39) -> 5.1 | Q39: 0 | R39: 0 | S39: =SUM(P39:R39) -> 5.1 | U39: 0 | V39: 41 | W39: =W38-V39 -> 4771 | X39: =N39+O39+S39+U39+V39 -> 46.1 | Y39: =IF(L39<0,L39*-1,0) -> 2.4052206 | Z39: =X39+Y39 -> 48.505221 | AA39: 0 | AB39: 50 | AC39: 29 | AD39: 30
A41: MONTH / CFS | F41: =SUM(F10:F39) -> 563.65011 | G41: =SUM(G10:G39) -> 2021 | H41: =SUM(H10:H39) -> 3.8 | I41: =SUM(I10:I39) -> 2024.8 | J41: =SUM(J10:J39) -> 124.68294 | K41: =SUM(K10:K39) -> 2149.4829 | L41: =SUM(L10:L39) -> -55.049887 | M41: =SUM(M10:M39) -> 169.1 | ... S41: =SUM(S10:S39) -> 89.2165 | U41: =SUM(U10:U39) -> 0 | V41: =SUM(V10:V39) -> 1237 | X41: =SUM(X10:X39) -> 1406.1 | Y41: =SUM(Y10:Y39) -> 179.73283 | Z41: =SUM(Z10:Z39) -> 1585.8328 | AA41: =SUM(AA10:AA39) -> 1.44 | AB41: =AVERAGE(AB10:AB39) -> 39.9 | AC41: =AVERAGE(AC10:AC39) -> 18 | AD41: Avg
A42: MONTH / AF | D42: =SUM(D10:D39) -> 1118 | F42: =F41*$D$2 -> 1118 | G42: =G41*$D$2 -> 4008.6535 | H42: =H41*$D$2 -> 7.5373 | I42: =I41*$D$2 -> 4016.1908 | J42: =J41*$D$2 -> 247.30861 | K42: =K41*$D$2 -> 4263.4994 | L42: =L41*$D$2 -> -109.19145 | M42: =M41*$D$2 -> 335.40985 | ... S42: =S41*$D$2 -> 176.96093 | U42: =U41*$D$2 -> 0 | V42: =V41*$D$2 -> 2453.5895 | X42: =X41*$D$2 -> 2788.9994 | Y42: =Y41*$D$2 -> 356.50006 | Z42: =Z41*$D$2 -> 3145.4994 | AB42: =MAX(AB10:AB39) -> 54 | AC42: =MAX(AC10:AC39) -> 31 | AD42: HI
A44: SEASON / CFS | AB44: =MIN(AB10:AB39) -> 22 | AC44: =MIN(AC10:AC39) -> 2 | AD44: LO
A45: SEASON / AF
A47: YTD / CFS | F47: =F8+F41 -> 563.65011 | G47: =G8+G41 -> 2021 | H47: =H8+H41 -> 3.8 | I47: =I8+I41 -> 2024.8 | J47: =J8+J41 -> 124.68294 | K47: =K8+K41 -> 2149.4829 | L47: =L8+L41 -> -55.049887 | M47: =M8+M41 -> 169.1 | ... S47: =S8+S41 -> 89.2165 | U47: =U8+U41 -> 0 | V47: =V8+V41 -> 1237 | W47: =W39 -> 4771 | X47: =X8+X41 -> 1406.1 | Y47: =Y8+Y41 -> 179.73283 | Z47: =Z8+Z41 -> 1585.8328 | AA47: =AA8+AA41 -> 1.44
A48: YTD / AF | D48: =D8+D42 -> 1118 | E48: =E39 -> 66583 | F48: =F47*$D$2 -> 1118 | G48: =G47*$D$2 -> 4008.6535 | H48: =H47*$D$2 -> 7.5373 | I48: =I47*$D$2 -> 4016.1908 | J48: =J47*$D$2 -> 247.30861 | K48: =K47*$D$2 -> 4263.4994 | L48: =L47*$D$2 -> -109.19145 | M48: =M47*$D$2 -> 335.40985 | ... Z48: =Z47*$D$2 -> 3145.4994

Sheet DEC
K1: MC PHEE RESERVOIR IN/OUT FLOW TABULATION
A2: AF/cfs CONVERT FACTOR | D2: 1.9835 | K2: DECEMBER "2000"
A4: DATE | B4: RESERV | C4: RESERV | D4: AC FT | E4: ACTIVE | F4: CONV TO | G4: DOLORES | H4: LOST | I4: RECORDED | J4: CALC | K4: TOTAL | L4: CALC | M4: DOLORES TUNNEL | Q4: LONE | R4: U | S4: TOTAL | T4: MVI | U4: DV CR | V4: BELOW | W4: REMAIN | X4: RECORDED | Y4: CALC | Z4: TOTAL | AA4: RAIN | AB4: MAX | AC4: MIN | AD4: DATE
A5: "DEC" | B5: ELEV | C5: AC FT | D5: CHANGE | E5: CAP | F5: CFS | G5: RIVER | H5: CANYON | I5: INFLOW | J5: INFLOW | K5: INFLOW | L5: INF/OTF | M5: TOT DIV | N5: WETLAND | O5: UTE F&R | P5: MVI,CTZ | Q5: PINE | R5: LAT | S5: MVI | T5: CALL | U5: CANAL | V5: MC PHEE | W5: RELEASE | X5: OUTFLOW | Y5: OUTFLOW | Z5: OUTFLOW | AB5: TMP | AC5: TMP | AD5: "DEC"
A7: SEASON BAL
A8: YTD | B8: =NOV!B39 -> 6880.8 | C8: =NOV!C39 -> 218583 | D8: =NOV!$D$48 -> 1118 | E8: =NOV!$E$39 -> 66583 | F8: =NOV!F47 -> 563.65011 | G8: =NOV!G47 -> 2021 | H8: =NOV!H47 -> 3.8 | I8: =NOV!I47 -> 2024.8 | J8: =NOV!J47 -> 124.68294 | K8: =NOV!K47 -> 2149.4829 | L8: =NOV!L47 -> -55.049887 | M8: =NOV!M47 -> 169.1 | ... AA8: =NOV!AA47 -> 1.44
A10: 1 | B10: 6880.81 | C10: 218614 | D10: =C10-C8 -> 31 | E10: =C10-152000 -> 66614 | F10: =D10/$D$2 -> 15.628939 | G10: 61 | H10: 0.65 | I10: =G10+H10 -> 61.65 | J10: =IF(L10>0,L10,0) -> 0.078938745 | K10: =I10+J10 -> 61.728939 | L10: =F10-(I10-X10) -> 0.078938745 | M10: 5.1 | N10: 0 | O10: 0 | P10: =M10-(N10+O10) -> 5.1 | Q10: 0 | R10: 0 | S10: =SUM(P10:R10) -> 5.1 | U10: 0 | V10: 41 | W10: =W8-V10 -> 4730 | X10: =N10+O10+S10+U10+V10 -> 46.1 | Y10: =IF(L10<0,L10*-1,0) -> 0 | Z10: =X10+Y10 -> 46.1 | AA10: 0 | AB10: 51 | AC10: 25 | AD10: 1
A11: =A10+1 -> 2 | B11: 6880.82 | C11: 218644 | D11: =C11-C10 -> 30 | E11: =C11-152000 -> 66644 | F11: =D11/$D$2 -> 15.124779 | G11: 62 | H11: 0.6 | I11: =G11+H11 -> 62.6 | J11: =IF(L11>0,L11,0) -> 0 | K11: =I11+J11 -> 62.6 | L11: =F11-(I11-X11) -> -1.3752206 | M11: 5.1 | N11: 0 | O11: 0 | P11: =M11-(N11+O11) -> 5.1 | Q11: 0 | R11: 0 | S11: =SUM(P11:R11) -> 5.1 | U11: 0 | V11: 41 | W11: =W10-V11 -> 4689 | X11: =N11+O11+S11+U11+V11 -> 46.1 | Y11: =IF(L11<0,L11*-1,0) -> 1.3752206 | Z11: =X11+Y11 -> 47.475221 | AA11: 0 | AB11: 49 | AC11: 30 | AD11: =AD10+1 -> 2
A12: =A11+1 -> 3 | B12: 6880.83 | C12: 218674 | D12: =C12-C11 -> 30 | E12: =C12-152000 -> 66674 | F12: =D12/$D$2 -> 15.124779 | G12: 57 | H12: 0.63 | I12: =G12+H12 -> 57.63 | J12: =IF(L12>0,L12,0) -> 3.5947794 | K12: =I12+J12 -> 61.224779 | L12: =F12-(I12-X12) -> 3.5947794 | M12: 5.1 | N12: 0 | O12: 0 | P12: =M12-(N12+O12) -> 5.1 | Q12: 0 | R12: 0 | S12: =SUM(P12:R12) -> 5.1 | U12: 0 | V12: 41 | W12: =W11-V12 -> 4648 | X12: =N12+O12+S12+U12+V12 -> 46.1 | Y12: =IF(L12<0,L12*-1,0) -> 0 | Z12: =X12+Y12 -> 46.1 | AA12: 0 | AB12: 51 | AC12: 27 | AD12: =AD11+1 -> 3
A13: =A12+1 -> 4 | B13: 6880.83 | C13: 218674 | D13: =C13-C12 -> 0 | E13: =C13-152000 -> 66674 | F13: =D13/$D$2 -> 0 | G13: 55 | H13: 0.57 | I13: =G13+H13 -> 55.57 | J13: =IF(L13>0,L13,0) -> 0 | K13: =I13+J13 -> 55.57 | L13: =F13-(I13-X13) -> -9.47 | M13: 5.1 | N13: 0 | O13: 0 | P13: =M13-(N13+O13) -> 5.1 | Q13: 0 | R13: 0 | S13: =SUM(P13:R13) -> 5.1 | U13: 0 | V13: 41 | W13: =W12-V13 -> 4607 | X13: =N13+O13+S13+U13+V13 -> 46.1 | Y13: =IF(L13<0,L13*-1,0) -> 9.47 | Z13: =X13+Y13 -> 55.57 | AA13: 0 | AB13: 52 | AC13: 23 | AD13: =AD12+1 -> 4
A14: =A13+1 -> 5 | B14: 6880.83 | C14: 218674 | D14: =C14-C13 -> 0 | E14: =C14-152000 -> 66674 | F14: =D14/$D$2 -> 0 | G14: 60 | H14: 0.57 | I14: =G14+H14 -> 60.57 | J14: =IF(L14>0,L14,0) -> 0 | K14: =I14+J14 -> 60.57 | L14: =F14-(I14-X14) -> -14.57 | M14: 5 | N14: 0 | O14: 0 | P14: =M14-(N14+O14) -> 5 | Q14: 0 | R14: 0 | S14: =SUM(P14:R14) -> 5 | U14: 0 | V14: 41 | W14: =W13-V14 -> 4566 | X14: =N14+O14+S14+U14+V14 -> 46 | Y14: =IF(L14<0,L14*-1,0) -> 14.57 | Z14: =X14+Y14 -> 60.57 | AA14: 0 | AB14: 51 | AC14: 22 | AD14: =AD13+1 -> 5
A15: =A14+1 -> 6 | B15: 6800.83 | C15: 218674 | D15: =C15-C14 -> 0 | E15: =C15-152000 -> 66674 | F15: =D15/$D$2 -> 0 | G15: 55 | H15: 0.55 | I15: =G15+H15 -> 55.55 | J15: =IF(L15>0,L15,0) -> 0 | K15: =I15+J15 -> 55.55 | L15: =F15-(I15-X15) -> -9.75 | M15: 4.8 | N15: 0 | O15: 0 | P15: =M15-(N15+O15) -> 4.8 | Q15: 0 | R15: 0 | S15: =SUM(P15:R15) -> 4.8 | U15: 0 | V15: 41 | W15: =W14-V15 -> 4525 | X15: =N15+O15+S15+U15+V15 -> 45.8 | Y15: =IF(L15<0,L15*-1,0) -> 9.75 | Z15: =X15+Y15 -> 55.55 | AA15: 0 | AB15: 54 | AC15: 21 | AD15: =AD14+1 -> 6
A16: =A15+1 -> 7 | B16: 6880.84 | C16: 218704 | D16: =C16-C15 -> 30 | E16: =C16-152000 -> 66704 | F16: =D16/$D$2 -> 15.124779 | G16: 55 | H16: 0.55 | I16: =G16+H16 -> 55.55 | J16: =IF(L16>0,L16,0) -> 5.3747794 | K16: =I16+J16 -> 60.924779 | L16: =F16-(I16-X16) -> 5.3747794 | M16: 4.8 | N16: 0 | O16: 0 | P16: =M16-(N16+O16) -> 4.8 | Q16: 0 | R16: 0 | S16: =SUM(P16:R16) -> 4.8 | U16: 0 | V16: 41 | W16: =W15-V16 -> 4484 | X16: =N16+O16+S16+U16+V16 -> 45.8 | Y16: =IF(L16<0,L16*-1,0) -> 0 | Z16: =X16+Y16 -> 45.8 | AA16: 0 | AB16: 51 | AC16: 23 | AD16: =AD15+1 -> 7
A17: =A16+1 -> 8 | B17: 6880.85 | C17: 218734 | D17: =C17-C16 -> 30 | E17: =C17-152000 -> 66734 | F17: =D17/$D$2 -> 15.124779 | G17: 58 | H17: 0.59 | I17: =G17+H17 -> 58.59 | J17: =IF(L17>0,L17,0) -> 2.3347794 | K17: =I17+J17 -> 60.924779 | L17: =F17-(I17-X17) -> 2.3347794 | M17: 4.8 | N17: 0 | O17: 0 | P17: =M17-(N17+O17) -> 4.8 | Q17: 0 | R17: 0 | S17: =SUM(P17:R17) -> 4.8 | U17: 0 | V17: 41 | W17: =W16-V17 -> 4443 | X17: =N17+O17+S17+U17+V17 -> 45.8 | Y17: =IF(L17<0,L17*-1,0) -> 0 | Z17: =X17+Y17 -> 45.8 | AA17: 0.15 | AB17: 45 | AC17: 25 | AD17: =AD16+1 -> 8
A18: =A17+1 -> 9 | B18: 6880.86 | C18: 218765 | D18: =C18-C17 -> 31 | E18: =C18-152000 -> 66765 | F18: =D18/$D$2 -> 15.628939 | G18: 58 | H18: 0.73 | I18: =G18+H18 -> 58.73 | J18: =IF(L18>0,L18,0) -> 2.6989387 | K18: =I18+J18 -> 61.428939 | L18: =F18-(I18-X18) -> 2.6989387 | M18: 4.8 | N18: 0 | O18: 0 | P18: =M18-(N18+O18) -> 4.8 | Q18: 0 | R18: 0 | S18: =SUM(P18:R18) -> 4.8 | U18: 0 | V18: 41 | W18: =W17-V18 -> 4402 | X18: =N18+O18+S18+U18+V18 -> 45.8 | Y18: =IF(L18<0,L18*-1,0) -> 0 | Z18: =X18+Y18 -> 45.8 | AA18: 0 | AB18: 41 | AC18: 31 | AD18: =AD17+1 -> 9
A19: =A18+1 -> 10 | B19: 6880.87 | C19: 218795 | D19: =C19-C18 -> 30 | E19: =C19-152000 -> 66795 | F19: =D19/$D$2 -> 15.124779 | G19: 55 | H19: 0.88 | I19: =G19+H19 -> 55.88 | J19: =IF(L19>0,L19,0) -> 5.0447794 | K19: =I19+J19 -> 60.924779 | L19: =F19-(I19-X19) -> 5.0447794 | M19: 4.8 | N19: 0 | O19: 0 | P19: =M19-(N19+O19) -> 4.8 | Q19: 0 | R19: 0 | S19: =SUM(P19:R19) -> 4.8 | U19: 0 | V19: 41 | W19: =W18-V19 -> 4361 | X19: =N19+O19+S19+U19+V19 -> 45.8 | Y19: =IF(L19<0,L19*-1,0) -> 0 | Z19: =X19+Y19 -> 45.8 | AA19: 0.1 | AB19: 46 | AC19: 36 | AD19: =AD18+1 -> 10
A20: =A19+1 -> 11 | B20: 6880.88 | C20: 218825 | D20: =C20-C19 -> 30 | E20: =C20-152000 -> 66825 | F20: =D20/$D$2 -> 15.124779 | G20: 51 | H20: 0.9 | I20: =G20+H20 -> 51.9 | J20: =IF(L20>0,L20,0) -> 9.0247794 | K20: =I20+J20 -> 60.924779 | L20: =F20-(I20-X20) -> 9.0247794 | M20: 4.8 | N20: 0 | O20: 0 | P20: =M20-(N20+O20) -> 4.8 | Q20: 0 | R20: 0 | S20: =SUM(P20:R20) -> 4.8 | U20: 0 | V20: 41 | W20: =W19-V20 -> 4320 | X20: =N20+O20+S20+U20+V20 -> 45.8 | Y20: =IF(L20<0,L20*-1,0) -> 0 | Z20: =X20+Y20 -> 45.8 | AA20: 0 | AB20: 36 | AC20: 21 | AD20: =AD19+1 -> 11
A21: =A20+1 -> 12 | B21: 6880.89 | C21: 218855 | D21: =C21-C20 -> 30 | E21: =C21-152000 -> 66855 | F21: =D21/$D$2 -> 15.124779 | G21: 53 | H21: 0.93 | I21: =G21+H21 -> 53.93 | J21: =IF(L21>0,L21,0) -> 6.9947794 | K21: =I21+J21 -> 60.924779 | L21: =F21-(I21-X21) -> 6.9947794 | M21: 4.8 | N21: 0 | O21: 0 | P21: =M21-(N21+O21) -> 4.8 | Q21: 0 | R21: 0 | S21: =SUM(P21:R21) -> 4.8 | U21: 0 | V21: 41 | W21: =W20-V21 -> 4279 | X21: =N21+O21+S21+U21+V21 -> 45.8 | Y21: =IF(L21<0,L21*-1,0) -> 0 | Z21: =X21+Y21 -> 45.8 | AA21: 0.13 | AB21: 39 | AC21: 16 | AD21: =AD20+1 -> 12
A22: =A21+1 -> 13 | B22: 6880.9 | C22: 218886 | D22: =C22-C21 -> 31 | E22: =C22-152000 -> 66886 | F22: =D22/$D$2 -> 15.628939 | G22: 52 | H22: 0.89 | I22: =G22+H22 -> 52.89 | J22: =IF(L22>0,L22,0) -> 8.5389387 | K22: =I22+J22 -> 61.428939 | L22: =F22-(I22-X22) -> 8.5389387 | M22: 4.8 | N22: 0 | O22: 0 | P22: =M22-(N22+O22) -> 4.8 | Q22: 0 | R22: 0 | S22: =SUM(P22:R22) -> 4.8 | U22: 0 | V22: 41 | W22: =W21-V22 -> 4238 | X22: =N22+O22+S22+U22+V22 -> 45.8 | Y22: =IF(L22<0,L22*-1,0) -> 0 | Z22: =X22+Y22 -> 45.8 | AA22: 0 | AB22: 37 | AC22: 13 | AD22: =AD21+1 -> 13
... A38: =A37+1 -> 29 | B38: 6880.96 | C38: 219067 | D38: =C38-C37 -> 0 | E38: =C38-152000 -> 67067 | F38: =D38/$D$2 -> 0 | G38: 42 | H38: 0.74 | I38: =G38+H38 -> 42.74 | J38: =IF(L38>0,L38,0) -> 4.06 | K38: =I38+J38 -> 46.8 | L38: =F38-(I38-X38) -> 4.06 | M38: 4.8 | N38: 0 | O38: 0 | P38: =M38-(N38+O38) -> 4.8 | Q38: 0 | R38: 0 | S38: =SUM(P38:R38) -> 4.8 | U38: 0 | V38: 42 | W38: =W37-V38 -> 3571 | X38: =N38+O38+S38+U38+V38 -> 46.8 | Y38: =IF(L38<0,L38*-1,0) -> 0 | Z38: =X38+Y38 -> 46.8 | AA38: 0 | AB38: 46 | AC38: 18 | AD38: =AD37+1 -> 29
A39: 30 | B39: 6880.96 | C39: 219067 | D39: =C39-C38 -> 0 | E39: =C39-152000 -> 67067 | F39: =D39/$D$2 -> 0 | G39: 43 | H39: 0.71 | I39: =G39+H39 -> 43.71 | J39: =IF(L39>0,L39,0) -> 3.09 | K39: =I39+J39 -> 46.8 | L39: =F39-(I39-X39) -> 3.09 | M39: 4.8 | N39: 0 | O39: 0 | P39: =M39-(N39+O39) -> 4.8 | Q39: 0 | R39: 0 | S39: =SUM(P39:R39) -> 4.8 | U39: 0 | V39: 42 | W39: =W38-V39 -> 3529 | X39: =N39+O39+S39+U39+V39 -> 46.8 | Y39: =IF(L39<0,L39*-1,0) -> 0 | Z39: =X39+Y39 -> 46.8 | AA39: 0 | AB39: 45 | AC39: 18 | AD39: 30
A40: 31 | B40: 6880.96 | C40: 219067 | D40: =C40-C39 -> 0 | E40: =C40-152000 -> 67067 | F40: =D40/$D$2 -> 0 | G40: 43 | H40: 0.7 | I40: =G40+H40 -> 43.7 | J40: =IF(L40>0,L40,0) -> 3.1 | K40: =I40+J40 -> 46.8 | L40: =F40-(I40-X40) -> 3.1 | M40: 4.8 | N40: 0 | O40: 0 | P40: =M40-(N40+O40) -> 4.8 | Q40: 0 | R40: 0 | S40: =SUM(P40:R40) -> 4.8 | U40: 0 | V40: 42 | W40: =W39-V40 -> 3487 | X40: =N40+O40+S40+U40+V40 -> 46.8 | Y40: =IF(L40<0,L40*-1,0) -> 0 | Z40: =X40+Y40 -> 46.8 | AA40: 0 | AB40: 49 | AC40: 21 | AD40: 31
A42: MONTH / CFS | F42: =SUM(F10:F40) -> 244.01311 | G42: =SUM(G10:G40) -> 1497 | H42: =SUM(H10:H40) -> 22.78 | I42: =SUM(I10:I40) -> 1519.78 | J42: =SUM(J10:J40) -> 195.74833 | K42: =SUM(K10:K40) -> 1715.5283 | L42: =SUM(L10:L40) -> 158.43311 | M42: =SUM(M10:M40) -> 150.2 | ... S42: =SUM(S10:S40) -> 150.2 | U42: =SUM(U10:U40) -> 0 | V42: =SUM(V10:V40) -> 1284 | X42: =SUM(X10:X40) -> 1434.2 | Y42: =SUM(Y10:Y40) -> 37.315221 | Z42: =SUM(Z10:Z40) -> 1471.5152 | AA42: =SUM(AA10:AA40) -> 0.38 | AB42: =AVERAGE(AB10:AB40) -> 44.806452 | AC42: =AVERAGE(AC10:AC40) -> 19.677419 | AD42: Avg
A43: MONTH / AF | D43: =SUM(D10:D40) -> 484 | F43: =F42*$D$2 -> 484 | G43: =G42*$D$2 -> 2969.2995 | H43: =H42*$D$2 -> 45.18413 | I43: =I42*$D$2 -> 3014.4836 | J43: =J42*$D$2 -> 388.26681 | K43: =K42*$D$2 -> 3402.7504 | L43: =L42*$D$2 -> 314.25207 | M43: =M42*$D$2 -> 297.9217 | ... S43: =S42*$D$2 -> 297.9217 | U43: =U42*$D$2 -> 0 | V43: =V42*$D$2 -> 2546.814 | X43: =X42*$D$2 -> 2844.7357 | Y43: =Y42*$D$2 -> 74.01474 | Z43: =Z42*$D$2 -> 2918.7504 | AB43: =MAX(AB10:AB40) -> 54 | AC43: =MAX(AC10:AC40) -> 36 | AD43: HI
A45: SEASON / CFS | AB45: =MIN(AB10:AB40) -> 36 | AC45: =MIN(AC10:AC40) -> 4 | AD45: LO
A46: SEASON / AF
A48: YTD / CFS | F48: =F8+F42 -> 807.66322 | G48: =G8+G42 -> 3518 | H48: =H8+H42 -> 26.58 | I48: =I8+I42 -> 3544.58 | J48: =J8+J42 -> 320.43127 | K48: =K8+K42 -> 3865.0113 | L48: =L8+L42 -> 103.38322 | M48: =M8+M42 -> 319.3 | ... S48: =S8+S42 -> 239.4165 | U48: =U8+U42 -> 0 | V48: =V8+V42 -> 2521 | W48: =W40 -> 3487 | X48: =X8+X42 -> 2840.3 | Y48: =Y8+Y42 -> 217.04805 | Z48: =Z8+Z42 -> 3057.348 | AA48: =AA8+AA42 -> 1.82
A49: YTD / AF | D49: =D8+D43 -> 1602 | E49: =E40 -> 67067 | F49: =F48*$D$2 -> 1602 | G49: =G48*$D$2 -> 6977.953 | H49: =H48*$D$2 -> 52.72143 | I49: =I48*$D$2 -> 7030.6744 | J49: =J48*$D$2 -> 635.57542 | K49: =K48*$D$2 -> 7666.2499 | L49: =L48*$D$2 -> 205.06062 | M49: =M48*$D$2 -> 633.33155 | ... Z49: =Z48*$D$2 -> 6064.2499

Sheet JAN
K1: MC PHEE RESERVOIR IN/OUT FLOW TABULATION
A2: AF/cfs CONVERT FACTOR | D2: 1.9835 | K2: JANUARY "2001"
A4: DATE | B4: RESERV | C4: RESERV | D4: AC FT | E4: ACTIVE | F4: CONV TO | G4: DOLORES | H4: LOST | I4: RECORDED | J4: CALC | K4: TOTAL | L4: CALC | M4: DOLORES TUNNEL | Q4: LONE | R4: U | S4: TOTAL | T4: MVI | U4: DV CR | V4: BELOW | W4: REMAIN | X4: RECORDED | Y4: CALC | Z4: TOTAL | AA4: RAIN | AB4: MAX | AC4: MIN | AD4: DATE
A5: "JAN" | B5: ELEV | C5: AC FT | D5: CHANGE | E5: CAP | F5: CFS | G5: RIVER | H5: CANYON | I5: INFLOW | J5: INFLOW | K5: INFLOW | L5: INF/OTF | M5: TOT DIV | N5: WETLAND | O5: UTE F&R | P5: MVI,CTZ | Q5: PINE | R5: LAT | S5: MVI | T5: CALL | U5: CANAL | V5: MC PHEE | W5: RELEASE | X5: OUTFLOW | Y5: OUTFLOW | Z5: OUTFLOW | AB5: TMP | AC5: TMP | AD5: "JAN"
A7: SEASON BAL
A8: YTD | B8: =DEC!B40 -> 6880.96 | C8: =DEC!C40 -> 219067 | D8: =DEC!$D$49 -> 1602 | E8: =DEC!$E$40 -> 67067 | F8: =DEC!F48 -> 807.66322 | G8: =DEC!G48 -> 3518 | H8: =DEC!H48 -> 26.58 | I8: =DEC!I48 -> 3544.58 | J8: =DEC!J48 -> 320.43127 | K8: =DEC!K48 -> 3865.0113 | L8: =DEC!L48 -> 103.38322 | M8: =DEC!M48 -> 319.3 | ... AA8: =DEC!AA48 -> 1.82
A10: 1 | B10: 6880.96 | C10: 219067 | D10: =C10-C8 -> 0 | E10: =C10-152000 -> 67067 | F10: =D10/$D$2 -> 0 | G10: 42 | H10: 0.69 | I10: =G10+H10 -> 42.69 | J10: =IF(L10>0,L10,0) -> 4.11 | K10: =I10+J10 -> 46.8 | L10: =F10-(I10-X10) -> 4.11 | M10: 4.8 | N10: 0 | O10: 0 | P10: =M10-(N10+O10) -> 4.8 | Q10: 0 | R10: 0 | S10: =SUM(P10:R10) -> 4.8 | U10: 0 | V10: 42 | W10: =W8-V10 -> 3445 | X10: =N10+O10+S10+U10+V10 -> 46.8 | Y10: =IF(L10<0,L10*-1,0) -> 0 | Z10: =X10+Y10 -> 46.8 | AA10: 0 | AB10: 45 | AC10: 20 | AD10: 1
A11: =A10+1 -> 2 | B11: 6880.96 | C11: 219067 | D11: =C11-C10 -> 0 | E11: =C11-152000 -> 67067 | F11: =D11/$D$2 -> 0 | G11: 42 | H11: 0.65 | I11: =G11+H11 -> 42.65 | J11: =IF(L11>0,L11,0) -> 4.15 | K11: =I11+J11 -> 46.8 | L11: =F11-(I11-X11) -> 4.15 | M11: 4.8 | N11: 0 | O11: 0 | P11: =M11-(N11+O11) -> 4.8 | Q11: 0 | R11: 0 | S11: =SUM(P11:R11) -> 4.8 | U11: 0 | V11: 42 | W11: =W10-V11 -> 3403 | X11: =N11+O11+S11+U11+V11 -> 46.8 | Y11: =IF(L11<0,L11*-1,0) -> 0 | Z11: =X11+Y11 -> 46.8 | AA11: 0 | AB11: 46 | AC11: 18 | AD11: =AD10+1 -> 2
A12: =A11+1 -> 3 | B12: 6880.96 | C12: 219067 | D12: =C12-C11 -> 0 | E12: =C12-152000 -> 67067 | F12: =D12/$D$2 -> 0 | G12: 42 | H12: 0.62 | I12: =G12+H12 -> 42.62 | J12: =IF(L12>0,L12,0) -> 4.18 | K12: =I12+J12 -> 46.8 | L12: =F12-(I12-X12) -> 4.18 | M12: 4.8 | N12: 0 | O12: 0 | P12: =M12-(N12+O12) -> 4.8 | Q12: 0 | R12: 0 | S12: =SUM(P12:R12) -> 4.8 | U12: 0 | V12: 42 | W12: =W11-V12 -> 3361 | X12: =N12+O12+S12+U12+V12 -> 46.8 | Y12: =IF(L12<0,L12*-1,0) -> 0 | Z12: =X12+Y12 -> 46.8 | AA12: 0 | AB12: 48 | AC12: 20 | AD12: =AD11+1 -> 3
A13: =A12+1 -> 4 | B13: 6880.96 | C13: 219067 | D13: =C13-C12 -> 0 | E13: =C13-152000 -> 67067 | F13: =D13/$D$2 -> 0 | G13: 43 | H13: 0.59 | I13: =G13+H13 -> 43.59 | J13: =IF(L13>0,L13,0) -> 3.21 | K13: =I13+J13 -> 46.8 | L13: =F13-(I13-X13) -> 3.21 | M13: 4.8 | N13: 0 | O13: 0 | P13: =M13-(N13+O13) -> 4.8 | Q13: 0 | R13: 0 | S13: =SUM(P13:R13) -> 4.8 | U13: 0 | V13: 42 | W13: =W12-V13 -> 3319 | X13: =N13+O13+S13+U13+V13 -> 46.8 | Y13: =IF(L13<0,L13*-1,0) -> 0 | Z13: =X13+Y13 -> 46.8 | AA13: 0 | AB13: 48 | AC13: 22 | AD13: =AD12+1 -> 4
A14: =A13+1 -> 5 | B14: 6880.96 | C14: 219067 | D14: =C14-C13 -> 0 | E14: =C14-152000 -> 67067 | F14: =D14/$D$2 -> 0 | G14: 43 | H14: 0.65 | I14: =G14+H14 -> 43.65 | J14: =IF(L14>0,L14,0) -> 3.15 | K14: =I14+J14 -> 46.8 | L14: =F14-(I14-X14) -> 3.15 | M14: 4.8 | N14: 0 | O14: 0 | P14: =M14-(N14+O14) -> 4.8 | Q14: 0 | R14: 0 | S14: =SUM(P14:R14) -> 4.8 | U14: 0 | V14: 42 | W14: =W13-V14 -> 3277 | X14: =N14+O14+S14+U14+V14 -> 46.8 | Y14: =IF(L14<0,L14*-1,0) -> 0 | Z14: =X14+Y14 -> 46.8 | AA14: 0 | AB14: 53 | AC14: 22 | AD14: =AD13+1 -> 5
A15: =A14+1 -> 6 | B15: 6880.96 | C15: 219067 | D15: =C15-C14 -> 0 | E15: =C15-152000 -> 67067 | F15: =D15/$D$2 -> 0 | G15: 43 | H15: 0.67 | I15: =G15+H15 -> 43.67 | J15: =IF(L15>0,L15,0) -> 3.13 | K15: =I15+J15 -> 46.8 | L15: =F15-(I15-X15) -> 3.13 | M15: 4.8 | N15: 0 | O15: 0 | P15: =M15-(N15+O15) -> 4.8 | Q15: 0 | R15: 0 | S15: =SUM(P15:R15) -> 4.8 | U15: 0 | V15: 42 | W15: =W14-V15 -> 3235 | X15: =N15+O15+S15+U15+V15 -> 46.8 | Y15: =IF(L15<0,L15*-1,0) -> 0 | Z15: =X15+Y15 -> 46.8 | AA15: 0 | AB15: 50 | AC15: 24 | AD15: =AD14+1 -> 6
A16: =A15+1 -> 7 | B16: 6880.96 | C16: 219067 | D16: =C16-C15 -> 0 | E16: =C16-152000 -> 67067 | F16: =D16/$D$2 -> 0 | G16: 43 | H16: 0.66 | I16: =G16+H16 -> 43.66 | J16: =IF(L16>0,L16,0) -> 3.14 | K16: =I16+J16 -> 46.8 | L16: =F16-(I16-X16) -> 3.14 | M16: 4.8 | N16: 0 | O16: 0 | P16: =M16-(N16+O16) -> 4.8 | Q16: 0 | R16: 0 | S16: =SUM(P16:R16) -> 4.8 | U16: 0 | V16: 42 | W16: =W15-V16 -> 3193 | X16: =N16+O16+S16+U16+V16 -> 46.8 | Y16: =IF(L16<0,L16*-1,0) -> 0 | Z16: =X16+Y16 -> 46.8 | AA16: 0 | AB16: 50 | AC16: 23 | AD16: =AD15+1 -> 7
A17: =A16+1 -> 8 | B17: 6880.96 | C17: 219067 | D17: =C17-C16 -> 0 | E17: =C17-152000 -> 67067 | F17: =D17/$D$2 -> 0 | G17: 43 | H17: 0.65 | I17: =G17+H17 -> 43.65 | J17: =IF(L17>0,L17,0) -> 4.15 | K17: =I17+J17 -> 47.8 | L17: =F17-(I17-X17) -> 4.15 | M17: 4.8 | N17: 0 | O17: 0 | P17: =M17-(N17+O17) -> 4.8 | Q17: 0 | R17: 0 | S17: =SUM(P17:R17) -> 4.8 | U17: 0 | V17: 43 | W17: =W16-V17 -> 3150 | X17: =N17+O17+S17+U17+V17 -> 47.8 | Y17: =IF(L17<0,L17*-1,0) -> 0 | Z17: =X17+Y17 -> 47.8 | AA17: 0 | AB17: 47 | AC17: 18 | AD17: =AD16+1 -> 8
A18: =A17+1 -> 9 | B18: 6880.96 | C18: 219067 | D18: =C18-C17 -> 0 | E18: =C18-152000 -> 67067 | F18: =D18/$D$2 -> 0 | G18: 44 | H18: 0.61 | I18: =G18+H18 -> 44.61 | J18: =IF(L18>0,L18,0) -> 3.19 | K18: =I18+J18 -> 47.8 | L18: =F18-(I18-X18) -> 3.19 | M18: 4.8 | N18: 0 | O18: 0 | P18: =M18-(N18+O18) -> 4.8 | Q18: 0 | R18: 0 | S18: =SUM(P18:R18) -> 4.8 | U18: 0 | V18: 43 | W18: =W17-V18 -> 3107 | X18: =N18+O18+S18+U18+V18 -> 47.8 | Y18: =IF(L18<0,L18*-1,0) -> 0 | Z18: =X18+Y18 -> 47.8 | AA18: 0 | AB18: 42 | AC18: 20 | AD18: =AD17+1 -> 9
A19: =A18+1 -> 10 | B19: 6880.96 | C19: 219067 | D19: =C19-C18 -> 0 | E19: =C19-152000 -> 67067 | F19: =D19/$D$2 -> 0 | G19: 43 | H19: 0.55 | I19: =G19+H19 -> 43.55 | J19: =IF(L19>0,L19,0) -> 4.25 | K19: =I19+J19 -> 47.8 | L19: =F19-(I19-X19) -> 4.25 | M19: 4.8 | N19: 0 | O19: 0 | P19: =M19-(N19+O19) -> 4.8 | Q19: 0 | R19: 0 | S19: =SUM(P19:R19) -> 4.8 | U19: 0 | V19: 43 | W19: =W18-V19 -> 3064 | X19: =N19+O19+S19+U19+V19 -> 47.8 | Y19: =IF(L19<0,L19*-1,0) -> 0 | Z19: =X19+Y19 -> 47.8 | AA19: 0 | AB19: 38 | AC19: 17 | AD19: =AD18+1 -> 10
A20: =A19+1 -> 11 | B20: 6880.96 | C20: 219067 | D20: =C20-C19 -> 0 | E20: =C20-152000 -> 67067 | F20: =D20/$D$2 -> 0 | G20: 43 | H20: 0.51 | I20: =G20+H20 -> 43.51 | J20: =IF(L20>0,L20,0) -> 4.29 | K20: =I20+J20 -> 47.8 | L20: =F20-(I20-X20) -> 4.29 | M20: 4.8 | N20: 0 | O20: 0 | P20: =M20-(N20+O20) -> 4.8 | Q20: 0 | R20: 0 | S20: =SUM(P20:R20) -> 4.8 | U20: 0 | V20: 43 | W20: =W19-V20 -> 3021 | X20: =N20+O20+S20+U20+V20 -> 47.8 | Y20: =IF(L20<0,L20*-1,0) -> 0 | Z20: =X20+Y20 -> 47.8 | AA20: 0 | AB20: 45 | AC20: 18 | AD20: =AD19+1 -> 11
A21: =A20+1 -> 12 | B21: 6881 | C21: 219188 | D21: =C21-C20 -> 121 | E21: =C21-152000 -> 67188 | F21: =D21/$D$2 -> 61.003277 | G21: 43 | H21: 0.48 | I21: =G21+H21 -> 43.48 | J21: =IF(L21>0,L21,0) -> 64.123277 | K21: =I21+J21 -> 107.60328 | L21: =F21-(I21-X21) -> 64.123277 | M21: 4.6 | N21: 0 | O21: 0 | P21: =M21-(N21+O21) -> 4.6 | Q21: 0 | R21: 0 | S21: =SUM(P21:R21) -> 4.6 | U21: 0 | V21: 42 | W21: =W20-V21 -> 2979 | X21: =N21+O21+S21+U21+V21 -> 46.6 | Y21: =IF(L21<0,L21*-1,0) -> 0 | Z21: =X21+Y21 -> 46.6 | AA21: 0.29 | AB21: 43 | AC21: 25 | AD21: =AD20+1 -> 12
A22: 13 | B22: 6881.02 | C22: 219249 | D22: =C22-C21 -> 61 | E22: =C22-152000 -> 67249 | F22: =D22/$D$2 -> 30.753718 | G22: 43 | H22: 0.47 | I22: =G22+H22 -> 43.47 | J22: =IF(L22>0,L22,0) -> 34.683718 | K22: =I22+J22 -> 78.153718 | L22: =F22-(I22-X22) -> 34.683718 | M22: 4.4 | N22: 0 | O22: 0 | P22: =M22-(N22+O22) -> 4.4 | Q22: 0 | R22: 0 | S22: =SUM(P22:R22) -> 4.4 | U22: 0 | V22: 43 | W22: =W21-V22 -> 2936 | X22: =N22+O22+S22+U22+V22 -> 47.4 | Y22: =IF(L22<0,L22*-1,0) -> 0 | Z22: =X22+Y22 -> 47.4 | AA22: 0.11 | AB22: 30 | AC22: 14 | AD22: =AD21+1 -> 13
A23: =A22+1 -> 14 | B23: 6881.02 | C23: 219249 | D23: =C23-C22 -> 0 | E23: =C23-152000 -> 67249 | F23: =D23/$D$2 -> 0 | G23: 43 | H23: 0.47 | I23: =G23+H23 -> 43.47 | J23: =IF(L23>0,L23,0) -> 2.93 | K23: =I23+J23 -> 46.4 | L23: =F23-(I23-X23) -> 2.93 | M23: 4.4 | N23: 0 | O23: 0 | P23: =M23-(N23+O23) -> 4.4 | Q23: 0 | R23: 0 | S23: =SUM(P23:R23) -> 4.4 | U23: 0 | V23: 42 | W23: =W22-V23 -> 2894 | X23: =N23+O23+S23+U23+V23 -> 46.4 | Y23: =IF(L23<0,L23*-1,0) -> 0 | Z23: =X23+Y23 -> 46.4 | AA23: 0 | AB23: 33 | AC23: 8 | AD23: =AD22+1 -> 14
A24: =A23+1 -> 15 | B24: 6881.03 | C24: 219280 | D24: =C24-C23 -> 31 | E24: =C24-152000 -> 67280 | F24: =D24/$D$2 -> 15.628939 | G24: 42 | H24: 0.44 | I24: =G24+H24 -> 42.44 | J24: =IF(L24>0,L24,0) -> 19.588939 | K24: =I24+J24 -> 62.028939 | L24: =F24-(I24-X24) -> 19.588939 | M24: 4.4 | N24: 0 | O24: 0 | P24: =M24-(N24+O24) -> 4.4 | Q24: 0 | R24: 0 | S24: =SUM(P24:R24) -> 4.4 | U24: 0 | V24: 42 | W24: =W23-V24 -> 2852 | X24: =N24+O24+S24+U24+V24 -> 46.4 | Y24: =IF(L24<0,L24*-1,0) -> 0 | Z24: =X24+Y24 -> 46.4 | AA24: 0 | AB24: 34 | AC24: 9 | AD24: =AD23+1 -> 15
A25: =A24+1 -> 16 | B25: 6881.04 | C25: 219311 | D25: =C25-C24 -> 31 | E25: =C25-152000 -> 67311 | F25: =D25/$D$2 -> 15.628939 | G25: 41 | H25: 0.4 | I25: =G25+H25 -> 41.4 | J25: =IF(L25>0,L25,0) -> 20.628939 | K25: =I25+J25 -> 62.028939 | L25: =F25-(I25-X25) -> 20.628939 | M25: 4.4 | N25: 0 | O25: 0 | P25: =M25-(N25+O25) -> 4.4 | Q25: 0 | R25: 0 | S25: =SUM(P25:R25) -> 4.4 | U25: 0 | V25: 42 | W25: =W24-V25 -> 2810 | X25: =N25+O25+S25+U25+V25 -> 46.4 | Y25: =IF(L25<0,L25*-1,0) -> 0 | Z25: =X25+Y25 -> 46.4 | AA25: 0.06 | AB25: 33 | AC25: 12 | AD25: =AD24+1 -> 16
A26: =A25+1 -> 17 | B26: 6881.04 | C26: 219311 | D26: =C26-C25 -> 0 | E26: =C26-152000 -> 67311 | F26: =D26/$D$2 -> 0 | G26: 40 | H26: 0.52 | I26: =G26+H26 -> 40.52 | J26: =IF(L26>0,L26,0) -> 5.88 | K26: =I26+J26 -> 46.4 | L26: =F26-(I26-X26) -> 5.88 | M26: 4.4 | N26: 0 | O26: 0 | P26: =M26-(N26+O26) -> 4.4 | Q26: 0 | R26: 0 | S26: =SUM(P26:R26) -> 4.4 | U26: 0 | V26: 42 | W26: =W25-V26 -> 2768 | X26: =N26+O26+S26+U26+V26 -> 46.4 | Y26: =IF(L26<0,L26*-1,0) -> 0 | Z26: =X26+Y26 -> 46.4 | AA26: 0 | AB26: 29 | AC26: 8 | AD26: =AD25+1 -> 17
A27: =A26+1 -> 18 | B27: 6881.03 | C27: 219280 | D27: =C27-C26 -> -31 | E27: =C27-152000 -> 67280 | F27: =D27/$D$2 -> -15.628939 | G27: 38 | H27: 0.53 | I27: =G27+H27 -> 38.53 | J27: =IF(L27>0,L27,0) -> 0 | K27: =I27+J27 -> 38.53 | L27: =F27-(I27-X27) -> -8.7589387 | M27: 4.4 | N27: 0 | O27: 0 | P27: =M27-(N27+O27) -> 4.4 | Q27: 0 | R27: 0 | S27: =SUM(P27:R27) -> 4.4 | U27: 0 | V27: 41 | W27: =W26-V27 -> 2727 | X27: =N27+O27+S27+U27+V27 -> 45.4 | Y27: =IF(L27<0,L27*-1,0) -> 8.7589387 | Z27: =X27+Y27 -> 54.158939 | AA27: 0 | AB27: 34 | AC27: 4 | AD27: =AD26+1 -> 18
A28: =A27+1 -> 19 | B28: 6881.02 | C28: 219249 | D28: =C28-C27 -> -31 | E28: =C28-152000 -> 67249 | F28: =D28/$D$2 -> -15.628939 | G28: 38 | H28: 0.5 | I28: =G28+H28 -> 38.5 | J28: =IF(L28>0,L28,0) -> 0 | K28: =I28+J28 -> 38.5 | L28: =F28-(I28-X28) -> -8.6289387 | M28: 4.5 | N28: 0 | O28: 0 | P28: =M28-(N28+O28) -> 4.5 | Q28: 0 | R28: 0 | S28: =SUM(P28:R28) -> 4.5 | U28: 0 | V28: 41 | W28: =W27-V28 -> 2686 | X28: =N28+O28+S28+U28+V28 -> 45.5 | Y28: =IF(L28<0,L28*-1,0) -> 8.6289387 | Z28: =X28+Y28 -> 54.128939 | AA28: 0 | AB28: 34 | AC28: 4 | AD28: =AD27+1 -> 19
A29: =A28+1 -> 20 | B29: 6881.01 | C29: 219219 | D29: =C29-C28 -> -30 | E29: =C29-152000 -> 67219 | F29: =D29/$D$2 -> -15.124779 | G29: 39 | H29: 0.43 | I29: =G29+H29 -> 39.43 | J29: =IF(L29>0,L29,0) -> 0 | K29: =I29+J29 -> 39.43 | L29: =F29-(I29-X29) -> -8.7547794 | M29: 4.8 | N29: 0 | O29: 0 | P29: =M29-(N29+O29) -> 4.8 | Q29: 0 | R29: 0 | S29: =SUM(P29:R29) -> 4.8 | U29: 0 | V29: 41 | W29: =W28-V29 -> 2645 | X29: =N29+O29+S29+U29+V29 -> 45.8 | Y29: =IF(L29<0,L29*-1,0) -> 8.7547794 | Z29: =X29+Y29 -> 54.554779 | AA29: 0 | AB29: 36 | AC29: 10 | AD29: =AD28+1 -> 20
A30: =A29+1 -> 21 | B30: 6881.02 | C30: 219249 | D30: =C30-C29 -> 30 | E30: =C30-152000 -> 67249 | F30: =D30/$D$2 -> 15.124779 | G30: 40 | H30: 0.47 | I30: =G30+H30 -> 40.47 | J30: =IF(L30>0,L30,0) -> 20.454779 | K30: =I30+J30 -> 60.924779 | L30: =F30-(I30-X30) -> 20.454779 | M30: 4.8 | N30: 0 | O30: 0 | P30: =M30-(N30+O30) -> 4.8 | Q30: 0 | R30: 0 | S30: =SUM(P30:R30) -> 4.8 | U30: 0 | V30: 41 | W30: =W29-V30 -> 2604 | X30: =N30+O30+S30+U30+V30 -> 45.8 | Y30: =IF(L30<0,L30*-1,0) -> 0 | Z30: =X30+Y30 -> 45.8 | AA30: 0 | AB30: 40 | AC30: 8 | AD30: =AD29+1 -> 21
A31: =A30+1 -> 22 | B31: 6881.03 | C31: 219280 | D31: =C31-C30 -> 31 | E31: =C31-152000 -> 67280 | F31: =D31/$D$2 -> 15.628939 | G31: 40 | H31: 0.64 | I31: =G31+H31 -> 40.64 | J31: =IF(L31>0,L31,0) -> 19.788939 | K31: =I31+J31 -> 60.428939 | L31: =F31-(I31-X31) -> 19.788939 | M31: 4.8 | N31: 0 | O31: 0 | P31: =M31-(N31+O31) -> 4.8 | Q31: 0 | R31: 0 | S31: =SUM(P31:R31) -> 4.8 | U31: 0 | V31: 40 | W31: =W30-V31 -> 2564 | X31: =N31+O31+S31+U31+V31 -> 44.8 | Y31: =IF(L31<0,L31*-1,0) -> 0 | Z31: =X31+Y31 -> 44.8 | AA31: 0 | AB31: 43 | AC31: 14 | AD31: =AD30+1 -> 22
A32: =A31+1 -> 23 | B32: 6881.04 | C32: 219311 | D32: =C32-C31 -> 31 | E32: =C32-152000 -> 67311 | F32: =D32/$D$2 -> 15.628939 | G32: 40 | H32: 0.7 | I32: =G32+H32 -> 40.7 | J32: =IF(L32>0,L32,0) -> 19.728939 | K32: =I32+J32 -> 60.428939 | L32: =F32-(I32-X32) -> 19.728939 | M32: 4.8 | N32: 0 | O32: 0 | P32: =M32-(N32+O32) -> 4.8 | Q32: 0 | R32: 0 | S32: =SUM(P32:R32) -> 4.8 | U32: 0 | V32: 40 | W32: =W31-V32 -> 2524 | X32: =N32+O32+S32+U32+V32 -> 44.8 | Y32: =IF(L32<0,L32*-1,0) -> 0 | Z32: =X32+Y32 -> 44.8 | AA32: 0 | AB32: 39 | AC32: 20 | AD32: =AD31+1 -> 23
A33: =A32+1 -> 24 | B33: 6881.05 | C33: 219341 | D33: =C33-C32 -> 30 | E33: =C33-152000 -> 67341 | F33: =D33/$D$2 -> 15.124779 | G33: 40 | H33: 0.7 | I33: =G33+H33 -> 40.7 | J33: =IF(L33>0,L33,0) -> 18.224779 | K33: =I33+J33 -> 58.924779 | L33: =F33-(I33-X33) -> 18.224779 | M33: 4.8 | N33: 0 | O33: 0 | P33: =M33-(N33+O33) -> 4.8 | Q33: 0 | R33: 0 | S33: =SUM(P33:R33) -> 4.8 | U33: 0 | V33: 39 | W33: =W32-V33 -> 2485 | X33: =N33+O33+S33+U33+V33 -> 43.8 | Y33: =IF(L33<0,L33*-1,0) -> 0 | Z33: =X33+Y33 -> 43.8 | AA33: 0 | AB33: 43 | AC33: 16 | AD33: =AD32+1 -> 24
A34: =A33+1 -> 25 | B34: 6881.08 | C34: 219433 | D34: =C34-C33 -> 92 | E34: =C34-152000 -> 67433 | F34: =D34/$D$2 -> 46.382657 | G34: 39 | H34: 0.67 | I34: =G34+H34 -> 39.67 | J34: =IF(L34>0,L34,0) -> 51.512657 | K34: =I34+J34 -> 91.182657 | L34: =F34-(I34-X34) -> 51.512657 | M34: 4.8 | N34: 0 | O34: 0 | P34: =M34-(N34+O34) -> 4.8 | Q34: 0 | R34: 0 | S34: =SUM(P34:R34) -> 4.8 | U34: 0 | V34: 40 | W34: =W33-V34 -> 2445 | X34: =N34+O34+S34+U34+V34 -> 44.8 | Y34: =IF(L34<0,L34*-1,0) -> 0 | Z34: =X34+Y34 -> 44.8 | AA34: 0.32 | AB34: 36 | AC34: 11 | AD34: =AD33+1 -> 25
... A38: =A37+1 -> 29 | B38: 6881.16 | C38: 219678 | D38: =C38-C37 -> 0 | E38: =C38-152000 -> 67678 | F38: =D38/$D$2 -> 0 | G38: 39 | H38: 0.54 | I38: =G38+H38 -> 39.54 | J38: =IF(L38>0,L38,0) -> 6.26 | K38: =I38+J38 -> 45.8 | L38: =F38-(I38-X38) -> 6.26 | M38: 4.8 | N38: 0 | O38: 0 | P38: =M38-(N38+O38) -> 4.8 | Q38: 0 | R38: 0 | S38: =SUM(P38:R38) -> 4.8 | U38: 0 | V38: 41 | W38: =W37-V38 -> 2285 | X38: =N38+O38+S38+U38+V38 -> 45.8 | Y38: =IF(L38<0,L38*-1,0) -> 0 | Z38: =X38+Y38 -> 45.8 | AA38: 0 | AB38: 32 | AC38: 8 | AD38: =AD37+1 -> 29
A39: 30 | B39: 6881.16 | C39: 219678 | D39: =C39-C38 -> 0 | E39: =C39-152000 -> 67678 | F39: =D39/$D$2 -> 0 | G39: 38 | H39: 0.49 | I39: =G39+H39 -> 38.49 | J39: =IF(L39>0,L39,0) -> 7.31 | K39: =I39+J39 -> 45.8 | L39: =F39-(I39-X39) -> 7.31 | M39: 4.8 | N39: 0 | O39: 0 | P39: =M39-(N39+O39) -> 4.8 | Q39: 0 | R39: 0 | S39: =SUM(P39:R39) -> 4.8 | U39: 0 | V39: 41 | W39: =W38-V39 -> 2244 | X39: =N39+O39+S39+U39+V39 -> 45.8 | Y39: =IF(L39<0,L39*-1,0) -> 0 | Z39: =X39+Y39 -> 45.8 | AA39: 0 | AB39: 29 | AC39: 11 | AD39: 30
A40: 31 | B40: 6881.16 | C40: 219678 | D40: =C40-C39 -> 0 | E40: =C40-152000 -> 67678 | F40: =D40/$D$2 -> 0 | G40: 37 | H40: 0.46 | I40: =G40+H40 -> 37.46 | J40: =IF(L40>0,L40,0) -> 8.34 | K40: =I40+J40 -> 45.8 | L40: =F40-(I40-X40) -> 8.34 | M40: 4.8 | N40: 0 | O40: 0 | P40: =M40-(N40+O40) -> 4.8 | Q40: 0 | R40: 0 | S40: =SUM(P40:R40) -> 4.8 | U40: 0 | V40: 41 | W40: =W39-V40 -> 2203 | X40: =N40+O40+S40+U40+V40 -> 45.8 | Y40: =IF(L40<0,L40*-1,0) -> 0 | Z40: =X40+Y40 -> 45.8 | AA40: 0 | AB40: 29 | AC40: 1 | AD40: 31
AB41: 39
A42: MONTH / CFS | F42: =SUM(F10:F40) -> 308.04134 | G42: =SUM(G10:G40) -> 1267 | H42: =SUM(H10:H40) -> 17.56 | I42: =SUM(I10:I40) -> 1284.56 | J42: =SUM(J10:J40) -> 479.524 | K42: =SUM(K10:K40) -> 1764.084 | L42: =SUM(L10:L40) -> 453.38134 | M42: =SUM(M10:M40) -> 145.9 | ... S42: =SUM(S10:S40) -> 145.9 | U42: =SUM(U10:U40) -> 0 | V42: =SUM(V10:V40) -> 1284 | X42: =SUM(X10:X40) -> 1429.9 | Y42: =SUM(Y10:Y40) -> 26.142657 | Z42: =SUM(Z10:Z40) -> 1456.0427 | AA42: =SUM(AA10:AA40) -> 1.23 | AB42: =AVERAGE(AB10:AB40) -> 39 | AC42: =AVERAGE(AC10:AC40) -> 14.935484 | AD42: AVE
A43: MONTH / AF | D43: =SUM(D10:D40) -> 611 | F43: =F42*$D$2 -> 611 | G43: =G42*$D$2 -> 2513.0945 | H43: =H42*$D$2 -> 34.83026 | I43: =I42*$D$2 -> 2547.9248 | J43: =J42*$D$2 -> 951.13585 | K43: =K42*$D$2 -> 3499.0606 | L43: =L42*$D$2 -> 899.28189 | M43: =M42*$D$2 -> 289.39265 | ... S43: =S42*$D$2 -> 289.39265 | U43: =U42*$D$2 -> 0 | V43: =V42*$D$2 -> 2546.814 | X43: =X42*$D$2 -> 2836.2067 | Y43: =Y42*$D$2 -> 51.85396 | Z43: =Z42*$D$2 -> 2888.0606 | AB43: =MAX(AB10:AB40) -> 53 | AC43: =MAX(AC10:AC40) -> 27 | AD43: HI
A45: SEASON / CFS | AB45: =MIN(AB10:AB40) -> 28 | AC45: =MIN(AC10:AC40) -> 1 | AD45: LO
A46: SEASON / AF
A48: YTD / CFS | F48: =F8+F42 -> 1115.7046 | G48: =G8+G42 -> 4785 | H48: =H8+H42 -> 44.14 | I48: =I8+I42 -> 4829.14 | J48: =J8+J42 -> 799.95527 | K48: =K8+K42 -> 5629.0953 | L48: =L8+L42 -> 556.76456 | M48: =M8+M42 -> 465.2 | ... S48: =S8+S42 -> 385.3165 | U48: =U8+U42 -> 0 | V48: =V8+V42 -> 3805 | W48: =W40 -> 2203 | X48: =X8+X42 -> 4270.2 | Y48: =Y8+Y42 -> 243.1907 | Z48: =Z8+Z42 -> 4513.3907 | AA48: =AA8+AA42 -> 3.05
...

Sheet FEB
K1: MC PHEE RESERVOIR IN/OUT FLOW TABULATION
A2: AF/cfs CONVERT FACTOR | D2: 1.9835 | K2: FEBRUARY "2001"
A4: DATE | B4: RESERV | C4: RESERV | D4: AC FT | E4: ACTIVE | F4: CONV TO | G4: DOLORES | H4: LOST | I4: RECORDED | J4: CALC | K4: TOTAL | L4: CALC | M4: DOLORES TUNNEL | Q4: LONE | R4: U | S4: TOTAL | T4: MVI | U4: DV CR | V4: BELOW | W4: REMAIN | X4: RECORDED | Y4: CALC | Z4: TOTAL | AA4: RAIN | AB4: MAX | AC4: MIN | AD4: DATE
A5: FEB | B5: ELEV | C5: AC FT | D5: CHANGE | E5: CAP | F5: CFS | G5: RIVER | H5: CANYON | I5: INFLOW | J5: INFLOW | K5: INFLOW | L5: INF/OTF | M5: TOT DIV | N5: WETLAND | O5: UTE F&R | P5: MVI,CTZ | Q5: PINE | R5: LAT | S5: MVI | T5: CALL | U5: CANAL | V5: MC PHEE | W5: RELEASE | X5: OUTFLOW | Y5: OUTFLOW | Z5: OUTFLOW | AB5: TMP | AC5: TMP | AD5: FEB
A7: SEASON BAL
A8: YTD | B8: =JAN!B40 -> 6881.16 | C8: =JAN!C40 -> 219678 | D8: =JAN!$D$49 -> 2213 | E8: =JAN!$E$40 -> 67678 | F8: =JAN!F48 -> 1115.7046 | G8: =JAN!G48 -> 4785 | H8: =JAN!H48 -> 44.14 | I8: =JAN!I48 -> 4829.14 | J8: =JAN!J48 -> 799.95527 | K8: =JAN!K48 -> 5629.0953 | L8: =JAN!L48 -> 556.76456 | M8: =JAN!M48 -> 465.2 | ... AA8: =JAN!AA48 -> 3.05
A10: 1 | B10: 6881.17 | C10: 219709 | D10: =C10-C8 -> 31 | E10: =C10-152000 -> 67709 | F10: =D10/$D$2 -> 15.628939 | G10: 34 | H10: 0.44 | I10: =G10+H10 -> 34.44 | J10: =IF(L10>0,L10,0) -> 26.988939 | K10: =I10+J10 -> 61.428939 | L10: =F10-(I10-X10) -> 26.988939 | M10: 4.8 | N10: 0 | O10: 0 | P10: =M10-(N10+O10) -> 4.8 | Q10: 0 | R10: 0 | S10: =SUM(P10:R10) -> 4.8 | U10: 0 | V10: 41 | W10: =W8-V10 -> 2162 | X10: =N10+O10+S10+U10+V10 -> 45.8 | Y10: =IF(L10<0,L10*-1,0) -> 0 | Z10: =X10+Y10 -> 45.8 | AA10: 0 | AB10: 37 | AC10: 0 | AD10: 1
A11: =A10+1 -> 2 | B11: 6881.17 | C11: 219709 | D11: =C11-C10 -> 0 | E11: =C11-152000 -> 67709 | F11: =D11/$D$2 -> 0 | G11: 39 | H11: 0.42 | I11: =G11+H11 -> 39.42 | J11: =IF(L11>0,L11,0) -> 6.38 | K11: =I11+J11 -> 45.8 | L11: =F11-(I11-X11) -> 6.38 | M11: 4.8 | N11: 0 | O11: 0 | P11: =M11-(N11+O11) -> 4.8 | Q11: 0 | R11: 0 | S11: =SUM(P11:R11) -> 4.8 | U11: 0 | V11: 41 | W11: =W10-V11 -> 2121 | X11: =N11+O11+S11+U11+V11 -> 45.8 | Y11: =IF(L11<0,L11*-1,0) -> 0 | Z11: =X11+Y11 -> 45.8 | AA11: 0 | AB11: 38 | AC11: 9 | AD11: =AD10+1 -> 2
A12: =A11+1 -> 3 | B12: 6881.17 | C12: 219709 | D12: =C12-C11 -> 0 | E12: =C12-152000 -> 67709 | F12: =D12/$D$2 -> 0 | G12: 40 | H12: 0.58 | I12: =G12+H12 -> 40.58 | J12: =IF(L12>0,L12,0) -> 5.22 | K12: =I12+J12 -> 45.8 | L12: =F12-(I12-X12) -> 5.22 | M12: 4.8 | N12: 0 | O12: 0 | P12: =M12-(N12+O12) -> 4.8 | Q12: 0 | R12: 0 | S12: =SUM(P12:R12) -> 4.8 | U12: 0 | V12: 41 | W12: =W11-V12 -> 2080 | X12: =N12+O12+S12+U12+V12 -> 45.8 | Y12: =IF(L12<0,L12*-1,0) -> 0 | Z12: =X12+Y12 -> 45.8 | AA12: 0 | AB12: 47 | AC12: 13 | AD12: =AD11+1 -> 3
A13: =A12+1 -> 4 | B13: 6881.17 | C13: 219709 | D13: =C13-C12 -> 0 | E13: =C13-152000 -> 67709 | F13: =D13/$D$2 -> 0 | G13: 40 | H13: 0.72 | I13: =G13+H13 -> 40.72 | J13: =IF(L13>0,L13,0) -> 5.08 | K13: =I13+J13 -> 45.8 | L13: =F13-(I13-X13) -> 5.08 | M13: 4.8 | N13: 0 | O13: 0 | P13: =M13-(N13+O13) -> 4.8 | Q13: 0 | R13: 0 | S13: =SUM(P13:R13) -> 4.8 | U13: 0 | V13: 41 | W13: =W12-V13 -> 2039 | X13: =N13+O13+S13+U13+V13 -> 45.8 | Y13: =IF(L13<0,L13*-1,0) -> 0 | Z13: =X13+Y13 -> 45.8 | AA13: 0 | AB13: 48 | AC13: 25 | AD13: =AD12+1 -> 4
A14: =A13+1 -> 5 | B14: 6881.17 | C14: 219709 | D14: =C14-C13 -> 0 | E14: =C14-152000 -> 67709 | F14: =D14/$D$2 -> 0 | G14: 42 | H14: 0.8 | I14: =G14+H14 -> 42.8 | J14: =IF(L14>0,L14,0) -> 3 | K14: =I14+J14 -> 45.8 | L14: =F14-(I14-X14) -> 3 | M14: 4.8 | N14: 0 | O14: 0 | P14: =M14-(N14+O14) -> 4.8 | Q14: 0 | R14: 0 | S14: =SUM(P14:R14) -> 4.8 | U14: 0 | V14: 41 | W14: =W13-V14 -> 1998 | X14: =N14+O14+S14+U14+V14 -> 45.8 | Y14: =IF(L14<0,L14*-1,0) -> 0 | Z14: =X14+Y14 -> 45.8 | AA14: 0 | AB14: 50 | AC14: 21 | AD14: =AD13+1 -> 5
A15: =A14+1 -> 6 | B15: 6881.17 | C15: 219709 | D15: =C15-C14 -> 0 | E15: =C15-152000 -> 67709 | F15: =D15/$D$2 -> 0 | G15: 43 | H15: 0.9 | I15: =G15+H15 -> 43.9 | J15: =IF(L15>0,L15,0) -> 1.9 | K15: =I15+J15 -> 45.8 | L15: =F15-(I15-X15) -> 1.9 | M15: 4.8 | N15: 0 | O15: 0 | P15: =M15-(N15+O15) -> 4.8 | Q15: 0 | R15: 0 | S15: =SUM(P15:R15) -> 4.8 | U15: 0 | V15: 41 | W15: =W14-V15 -> 1957 | X15: =N15+O15+S15+U15+V15 -> 45.8 | Y15: =IF(L15<0,L15*-1,0) -> 0 | Z15: =X15+Y15 -> 45.8 | AA15: 0 | AB15: 50 | AC15: 25 | AD15: =AD14+1 -> 6
A16: =A15+1 -> 7 | B16: 6881.2 | C16: 219801 | D16: =C16-C15 -> 92 | E16: =C16-152000 -> 67801 | F16: =D16/$D$2 -> 46.382657 | G16: 43 | H16: 1.1 | I16: =G16+H16 -> 44.1 | J16: =IF(L16>0,L16,0) -> 43.082657 | K16: =I16+J16 -> 87.182657 | L16: =F16-(I16-X16) -> 43.082657 | M16: 4.8 | N16: 0 | O16: 0 | P16: =M16-(N16+O16) -> 4.8 | Q16: 0 | R16: 0 | S16: =SUM(P16:R16) -> 4.8 | U16: 0 | V16: 36 | W16: =W15-V16 -> 1921 | X16: =N16+O16+S16+U16+V16 -> 40.8 | Y16: =IF(L16<0,L16*-1,0) -> 0 | Z16: =X16+Y16 -> 40.8 | AA16: 0.01 | AB16: 47 | AC16: 32 | AD16: =AD15+1 -> 7
A17: =A16+1 -> 8 | B17: 6881.21 | C17: 219832 | D17: =C17-C16 -> 31 | E17: =C17-152000 -> 67832 | F17: =D17/$D$2 -> 15.628939 | G17: 43 | H17: 1.5 | I17: =G17+H17 -> 44.5 | J17: =IF(L17>0,L17,0) -> 14.928939 | K17: =I17+J17 -> 59.428939 | L17: =F17-(I17-X17) -> 14.928939 | M17: 4.8 | N17: 0 | O17: 0 | P17: =M17-(N17+O17) -> 4.8 | Q17: 0 | R17: 0 | S17: =SUM(P17:R17) -> 4.8 | U17: 0 | V17: 39 | W17: =W16-V17 -> 1882 | X17: =N17+O17+S17+U17+V17 -> 43.8 | Y17: =IF(L17<0,L17*-1,0) -> 0 | Z17: =X17+Y17 -> 43.8 | AA17: 0.08 | AB17: 36 | AC17: 21 | AD17: =AD16+1 -> 8
A18: =A17+1 -> 9 | B18: 6881.22 | C18: 219862 | D18: =C18-C17 -> 30 | E18: =C18-152000 -> 67862 | F18: =D18/$D$2 -> 15.124779 | G18: 44 | H18: 2 | I18: =G18+H18 -> 46 | J18: =IF(L18>0,L18,0) -> 13.924779 | K18: =I18+J18 -> 59.924779 | L18: =F18-(I18-X18) -> 13.924779 | M18: 4.8 | N18: 0 | O18: 0 | P18: =M18-(N18+O18) -> 4.8 | Q18: 0 | R18: 0 | S18: =SUM(P18:R18) -> 4.8 | U18: 0 | V18: 40 | W18: =W17-V18 -> 1842 | X18: =N18+O18+S18+U18+V18 -> 44.8 | Y18: =IF(L18<0,L18*-1,0) -> 0 | Z18: =X18+Y18 -> 44.8 | AA18: 0 | AB18: 32 | AC18: 7 | AD18: =AD17+1 -> 9
A19: =A18+1 -> 10 | B19: 6881.23 | C19: 219893 | D19: =C19-C18 -> 31 | E19: =C19-152000 -> 67893 | F19: =D19/$D$2 -> 15.628939 | G19: 44 | H19: 2.6 | I19: =G19+H19 -> 46.6 | J19: =IF(L19>0,L19,0) -> 13.828939 | K19: =I19+J19 -> 60.428939 | L19: =F19-(I19-X19) -> 13.828939 | M19: 4.8 | N19: 0 | O19: 0 | P19: =M19-(N19+O19) -> 4.8 | Q19: 0 | R19: 0 | S19: =SUM(P19:R19) -> 4.8 | U19: 0 | V19: 40 | W19: =W18-V19 -> 1802 | X19: =N19+O19+S19+U19+V19 -> 44.8 | Y19: =IF(L19<0,L19*-1,0) -> 0 | Z19: =X19+Y19 -> 44.8 | AA19: 0 | AB19: 41 | AC19: 12 | AD19: =AD18+1 -> 10
A20: =A19+1 -> 11 | B20: 6881.24 | C20: 219924 | D20: =C20-C19 -> 31 | E20: =C20-152000 -> 67924 | F20: =D20/$D$2 -> 15.628939 | G20: 44 | H20: 2.4 | I20: =G20+H20 -> 46.4 | J20: =IF(L20>0,L20,0) -> 14.028939 | K20: =I20+J20 -> 60.428939 | L20: =F20-(I20-X20) -> 14.028939 | M20: 4.8 | N20: 0 | O20: 0 | P20: =M20-(N20+O20) -> 4.8 | Q20: 0 | R20: 0 | S20: =SUM(P20:R20) -> 4.8 | U20: 0 | V20: 40 | W20: =W19-V20 -> 1762 | X20: =N20+O20+S20+U20+V20 -> 44.8 | Y20: =IF(L20<0,L20*-1,0) -> 0 | Z20: =X20+Y20 -> 44.8 | AA20: 0 | AB20: 41 | AC20: 26 | AD20: =AD19+1 -> 11
A21: =A20+1 -> 12 | B21: 6881.24 | C21: 219924 | D21: =C21-C20 -> 0 | E21: =C21-152000 -> 67924 | F21: =D21/$D$2 -> 0 | G21: 44 | H21: 2.1 | I21: =G21+H21 -> 46.1 | J21: =IF(L21>0,L21,0) -> 0 | K21: =I21+J21 -> 46.1 | L21: =F21-(I21-X21) -> -1.3 | M21: 4.8 | N21: 0 | O21: 0 | P21: =M21-(N21+O21) -> 4.8 | Q21: 0 | R21: 0 | S21: =SUM(P21:R21) -> 4.8 | U21: 0 | V21: 40 | W21: =W20-V21 -> 1722 | X21: =N21+O21+S21+U21+V21 -> 44.8 | Y21: =IF(L21<0,L21*-1,0) -> 1.3 | Z21: =X21+Y21 -> 46.1 | AA21: 0 | AB21: 46 | AC21: 24 | AD21: =AD20+1 -> 12
A22: =A21+1 -> 13 | B22: 6881.25 | C22: 219954 | D22: =C22-C21 -> 30 | E22: =C22-152000 -> 67954 | F22: =D22/$D$2 -> 15.124779 | G22: 43 | H22: 1.9 | I22: =G22+H22 -> 44.9 | J22: =IF(L22>0,L22,0) -> 16.024779 | K22: =I22+J22 -> 60.924779 | L22: =F22-(I22-X22) -> 16.024779 | M22: 4.8 | N22: 0 | O22: 0 | P22: =M22-(N22+O22) -> 4.8 | Q22: 0 | R22: 0 | S22: =SUM(P22:R22) -> 4.8 | U22: 0 | V22: 41 | W22: =W21-V22 -> 1681 | X22: =N22+O22+S22+U22+V22 -> 45.8 | Y22: =IF(L22<0,L22*-1,0) -> 0 | Z22: =X22+Y22 -> 45.8 | AA22: 0.12 | AB22: 47 | AC22: 25 | AD22: =AD21+1 -> 13
... A36: =A35+1 -> 27 | B36: 6881.47 | C36: 220629 | D36: =C36-C35 -> 62 | E36: =C36-152000 -> 68629 | F36: =D36/$D$2 -> 31.257877 | G36: 46 | H36: 2.3 | I36: =G36+H36 -> 48.3 | J36: =IF(L36>0,L36,0) -> 29.557877 | K36: =I36+J36 -> 77.857877 | L36: =F36-(I36-X36) -> 29.557877 | M36: 4.6 | N36: 0 | O36: 0 | P36: =M36-(N36+O36) -> 4.6 | Q36: 0 | R36: 0 | S36: =SUM(P36:R36) -> 4.6 | U36: 0 | V36: 42 | W36: =W35-V36 -> 1098 | X36: =N36+O36+S36+U36+V36 -> 46.6 | Y36: =IF(L36<0,L36*-1,0) -> 0 | Z36: =X36+Y36 -> 46.6 | AA36: 0.12 | AB36: 41 | AC36: 30 | AD36: =AD35+1 -> 27
A37: 28 | B37: 6881.5 | C37: 220721 | D37: =C37-C36 -> 92 | E37: =C37-152000 -> 68721 | F37: =D37/$D$2 -> 46.382657 | G37: 49 | H37: 2.4 | I37: =G37+H37 -> 51.4 | J37: =IF(L37>0,L37,0) -> 41.382657 | K37: =I37+J37 -> 92.782657 | L37: =F37-(I37-X37) -> 41.382657 | M37: 4.4 | N37: 0 | O37: 0 | P37: =M37-(N37+O37) -> 4.4 | Q37: 0 | R37: 0 | S37: =SUM(P37:R37) -> 4.4 | U37: 0 | V37: 42 | W37: =W36-V37 -> 1056 | X37: =N37+O37+S37+U37+V37 -> 46.4 | Y37: =IF(L37<0,L37*-1,0) -> 0 | Z37: =X37+Y37 -> 46.4 | AA37: 0.46 | AB37: 39 | AC37: 21 | AD37: 28
A39: MONTH / CFS | F39: =SUM(F10:F37) -> 525.83816 | G39: =SUM(G10:G37) -> 1195 | H39: =SUM(H10:H37) -> 45.16 | I39: =SUM(I10:I37) -> 1240.16 | J39: =SUM(J10:J37) -> 566.77816 | K39: =SUM(K10:K37) -> 1806.9382 | L39: =SUM(L10:L37) -> 565.47816 | M39: =SUM(M10:M37) -> 132.8 | ... S39: =SUM(S10:S37) -> 132.8 | U39: =SUM(U10:U37) -> 0 | V39: =SUM(V10:V37) -> 1147 | X39: =SUM(X10:X37) -> 1279.8 | Y39: =SUM(Y10:Y37) -> 1.3 | Z39: =SUM(Z10:Z37) -> 1281.1 | AA39: =SUM(AA10:AA37) -> 1.29 | AB39: =AVERAGE(AB10:AB37) -> 43.071429 | AC39: =AVERAGE(AC10:AC37) -> 20.642857 | AD39: AVE
A40: MONTH / AF | D40: =SUM(D10:D37) -> 1043 | F40: =F39*$D$2 -> 1043 | G40: =G39*$D$2 -> 2370.2825 | H40: =H39*$D$2 -> 89.57486 | I40: =I39*$D$2 -> 2459.8574 | J40: =J39*$D$2 -> 1124.2045 | K40: =K39*$D$2 -> 3584.0619 | L40: =L39*$D$2 -> 1121.6259 | M40: =M39*$D$2 -> 263.4088 | ... S40: =S39*$D$2 -> 263.4088 | U40: =U39*$D$2 -> 0 | V40: =V39*$D$2 -> 2275.0745 | X40: =X39*$D$2 -> 2538.4833 | Y40: =Y39*$D$2 -> 2.57855 | Z40: =Z39*$D$2 -> 2541.0619 | AB40: =MAX(AB10:AB37) -> 52 | AC40: =MAX(AC10:AC37) -> 32 | AD40: HI
A42: SEASON / CFS | AB42: =MIN(AB10:AB37) -> 32 | AC42: =MIN(AC10:AC37) -> 0 | AD42: LO
A43: SEASON / AF
A45: YTD / CFS | F45: =F8+F39 -> 1641.5427 | G45: =G8+G39 -> 5980 | H45: =H8+H39 -> 89.3 | I45: =I8+I39 -> 6069.3 | J45: =J8+J39 -> 1366.7334 | K45: =K8+K39 -> 7436.0334 | L45: =L8+L39 -> 1122.2427 | M45: =M8+M39 -> 598 | ... S45: =S8+S39 -> 518.1165 | U45: =U8+U39 -> 0 | V45: =V8+V39 -> 4952 | W45: =W37 -> 1056 | X45: =X8+X39 -> 5550 | Y45: =Y8+Y39 -> 244.4907 | Z45: =Z8+Z39 -> 5794.4907 | AA45: =AA8+AA39 -> 4.34
A46: YTD / AF | D46: =D8+D40 -> 3256 | E46: =E37 -> 68721 | F46: =F45*$D$2 -> 3256 | G46: =G45*$D$2 -> 11861.33 | H46: =H45*$D$2 -> 177.12655 | I46: =I45*$D$2 -> 12038.457 | J46: =J45*$D$2 -> 2710.9158 | K46: =K45*$D$2 -> 14749.372 | L46: =L45*$D$2 -> 2225.9684 | M46: =M45*$D$2 -> 1186.133 | ... Z46: =Z45*$D$2 -> 11493.372

Sheet MAR
K1: MC PHEE RESERVOIR IN/OUT FLOW TABULATION
A2: AF/cfs CONVERT FACTOR | D2: 1.9835 | K2: MARCH "2001"
