Workbook

Sheet NOV
K1: MCPHEE RESERVOIR INFLOW/OUTFLOW TABULATION
A2: AF/cfs CONVERT FACTOR | D2: 1.9835 | L2: NOVEMBER "2008"
D4: RESERVOIR | W4: INFLOW/OUTFLOW (CFS) | AP4: ADJUSTMENTS | AW4: WEATHER
A5: DATE | B5: RESERV | C5: RESERV | D5: AC FT | E5: ACTIVE | F5: CONV TO | G5: DOLORES | H5: LOST | I5: RECORD | J5: CALC | K5: TOTAL | L5: CALC | M5: DOLORES TUNNEL | U5: LONE | V5: U | W5: TOTAL | X5: TOTAL | Y5: TOTAL | Z5: TOTAl | AA5: MVI | AB5: MVI | AC5: TO EX & | AD5: MVI | AE5: DV CR | AF5: D/S SENIOR | AH5: BELOW | AI5: FISH | AJ5: SPILL | AK5: RECORD | AL5: CALC | AM5: TOTAL | AN5: NAR | AO5: MVI | AP5: MVI | AQ5: MVI | AR5: DIST. | AS5: U/S | AT5: TOTTEN | AU5: UTES | AV5: RAIN | AW5: MAX | AX5: MIN | AZ5: TOTAL
A6: NOV | B6: ELEV | D6: CHANGE | E6: CAP | F6: CFS | G6: RIVER | H6: CAN | I6: INFLOW | J6: INFLOW | K6: INFLOW | L6: INF/OTF | M6: TOT DIV | N6: WET | O6: UTE | P6: QUEST | Q6: MWC | R6: CTZ | S6: CTZ & | T6: F-BAY | U6: PINE | V6: LAT | W6: MVI | X6: MVI | Y6: MVI | Z6: MVI | AA6: CALL | AB6: APR- | AC6: U/S EX | AD6: PROJ | AE6: CANAL | AF6: MVIC | AG6: PROJ | AH6: MCP | AI6: LEFT | AK6: OTF | AL6: OTF | AM6: OTF | AN6: CALL | AO6: STOCK | AP6: STORED | AQ6: STORED | AR6: CLASS | AS6: USERS | AT6: (FRESH | AU6: FROM | AW6: TMP | AX6: TMP | AZ6: TUNNEL
N7: LAND | O7: F&R | S7: UTE | T7: SPILL | W7: 153400 | X7: IRRIG. | Y7: IRRIG. | Z7: 105500 | AB7: JUNE | AF7: 1.7 | AG7: 1.3 | AI7: 31798 | AP7: Apr - Jun | AQ7: EVAP | AR7: "B" | AS7: EXCH | AT7: WATER) | AU7: MVIC | AZ7: Misc.
C8: AC. Ft. | E8: AC FT | G8: CFS | H8: CFS | I8: CFS | J8: CFS | K8: CFS | L8: CFS | M8: CFS | N8: CFS | O8: CFS | P8: CFS | Q8: CFS | R8: CFS | S8: PROJ | T8: CFS | U8: CFS | V8: CFS | W8: CFS | X8: 150400 | Y8: 150400 | Z8: Ac. Ft. | AA8: CFS | AB8: 72000 | AC8: CFS | AD8: CFS | AE8: CFS | AF8: CFS | AG8: CFS | AH8: CFS | AI8: CFS | AJ8: CFS | AK8: CFS | AL8: CFS | AM8: CFS | AN8: AC FT | AO8: CFS | AP8: CFS | AQ8: AC.FT. | AR8: CFS | AS8: CFS | AT8: CFS | AU8: CFS | AZ8: Outflow
N9: 1.03 | O9: 1.05 | P9: 1.02 | Q9: 1.02 | R9: 1.04 | S9: CFS | X9: CFS | Y9: Ac. Ft. | AB9: Ac. Ft. | AZ9: CFS
A10: SEASON BAL
A11: YTD | B11: 6900.33 | C11: 284801 | AI11: 6078 | AO11: 0
A13: 1 | B13: 6900.32 | C13: 284764 | D13: =C13-C11 -> -37 | E13: =C13-152000 -> 132764 | F13: =D13/$D$2 -> -18.653895 | G13: 53 | H13: 0 | I13: =G13+H13 -> 53 | J13: =IF(L13>0,L13,0) -> 10.146105 | K13: =I13+J13 -> 63.146105 | L13: =F13-(I13-AK13) -> 10.146105 | M13: 4.8 | N13: 0 | O13: 0 | P13: 0 | Q13: =1.58*1.02 -> 1.6116 | R13: 2.61 | S13: 0 | T13: 0 | U13: 42 | V13: 0 | W13: =M13-N13-P13-O13-Q13-R13-S13-T13+U13+V13 -> 42.5784 | X13: =W13-AO13 -> 42.5784 | Y13: =X13*1.9835 -> 84.454256 | Z13: =W13*(26300/37500)*1.9835 -> 59.230585 | AE13: 0 | AH13: 35 | AI13: =AI11-AH13 -> 6043 | AK13: =N13+O13+P13+Q13+R13+S13+T13+W13+AE13+AH13 -> 81.8 | AL13: =IF(L13<0,L13*-1,0) -> 0 | AM13: =AK13+AL13 -> 81.8 | AN13: =U13*1.9835 -> 83.307 | AV13: 0 | AW13: 68 | AX13: 37 | AZ13: =SUM(N13,P13:T13) -> 4.2216
A14: =A13+1 -> 2 | B14: 6900.3 | C14: 284690 | D14: =C14-C13 -> -74 | E14: =C14-152000 -> 132690 | F14: =D14/$D$2 -> -37.307789 | G14: 54 | H14: 0 | I14: =G14+H14 -> 54 | J14: =IF(L14>0,L14,0) -> 0 | K14: =I14+J14 -> 54 | L14: =F14-(I14-AK14) -> -8.7077893 | M14: 4.6 | N14: 0 | O14: 0 | P14: 0 | Q14: =1.58*1.02 -> 1.6116 | R14: 2.52 | S14: 0 | T14: 0 | U14: 42 | V14: 0 | W14: =M14-N14-P14-O14-Q14-R14-S14-T14+U14+V14 -> 42.4684 | X14: =W14-AO14 -> 42.4684 | Y14: =Y13+(X14*1.9835) -> 168.69033 | Z14: =Z13+X14*(26300/37500)*1.9835 -> 118.30815 | AE14: 0 | AH14: 36 | AI14: =AI13-AH14 -> 6007 | AK14: =N14+O14+P14+Q14+R14+S14+T14+W14+AE14+AH14 -> 82.6 | AL14: =IF(L14<0,L14*-1,0) -> 8.7077893 | AM14: =AK14+AL14 -> 91.307789 | AN14: =(U14*1.9835)+AN13 -> 166.614 | AV14: 0 | AW14: 66 | AX14: 39 | AZ14: =SUM(N14,P14:T14) -> 4.1316
A15: =A14+1 -> 3 | B15: 6900.28 | C15: 284616 | D15: =C15-C14 -> -74 | E15: =C15-152000 -> 132616 | F15: =D15/$D$2 -> -37.307789 | G15: 62 | H15: 0 | I15: =G15+H15 -> 62 | J15: =IF(L15>0,L15,0) -> 0 | K15: =I15+J15 -> 62 | L15: =F15-(I15-AK15) -> -13.807789 | M15: 5.5 | N15: 0 | O15: 0 | P15: 0 | Q15: =1.58*1.02 -> 1.6116 | R15: 2.68 | S15: 0 | T15: 0 | U15: 44 | V15: 0 | W15: =M15-N15-P15-O15-Q15-R15-S15-T15+U15+V15 -> 45.2084 | X15: =W15-AO15 -> 45.2084 | Y15: =Y14+(X15*1.9835) -> 258.36119 | Z15: =Z14+X15*(26300/37500)*1.9835 -> 181.19731 | AE15: 0 | AH15: 36 | AI15: =AI14-AH15 -> 5971 | AK15: =N15+O15+P15+Q15+R15+S15+T15+W15+AE15+AH15 -> 85.5 | AL15: =IF(L15<0,L15*-1,0) -> 13.807789 | AM15: =AK15+AL15 -> 99.307789 | AN15: =(U15*1.9835)+AN14 -> 253.888 | AV15: 0 | AW15: 60 | AX15: 39 | AZ15: =SUM(N15,P15:T15) -> 4.2916
A16: =A15+1 -> 4 | B16: 6900.24 | C16: 284468 | D16: =C16-C15 -> -148 | E16: =C16-152000 -> 132468 | F16: =D16/$D$2 -> -74.615579 | G16: 61 | H16: 0 | I16: =G16+H16 -> 61 | J16: =IF(L16>0,L16,0) -> 0 | K16: =I16+J16 -> 61 | L16: =F16-(I16-AK16) -> -35.015579 | M16: 13 | N16: 0 | O16: 0 | P16: 0 | Q16: =1.58*1.02 -> 1.6116 | R16: 2.31 | S16: 0 | T16: 0 | U16: 46 | V16: 5.6 | W16: =M16-N16-P16-O16-Q16-R16-S16-T16+U16+V16 -> 60.6784 | X16: =W16-AO16 -> 13.74 | Y16: =Y15+(X16*1.9835) -> 285.61448 | Z16: =Z15+X16*(26300/37500)*1.9835 -> 200.31095 | AE16: 0 | AH16: 36 | AI16: =AI15-AH16 -> 5935 | AK16: =N16+O16+P16+Q16+R16+S16+T16+W16+AE16+AH16 -> 100.6 | AL16: =IF(L16<0,L16*-1,0) -> 35.015579 | AM16: =AK16+AL16 -> 135.61558 | AN16: =(U16-13.74)*1.9835+AN15 -> 317.87571 | AO16: =W16-13.74 -> 46.9384 | AV16: 0.02 | AW16: 53 | AX16: 28 | AZ16: =SUM(N16,P16:T16) -> 3.9216
A17: =A16+1 -> 5 | B17: 6900.19 | C17: 284283 | D17: =C17-C16 -> -185 | E17: =C17-152000 -> 132283 | F17: =D17/$D$2 -> -93.269473 | G17: 69 | H17: 0 | I17: =G17+H17 -> 69 | J17: =IF(L17>0,L17,0) -> 0 | K17: =I17+J17 -> 69 | L17: =F17-(I17-AK17) -> -31.269473 | M17: 34 | N17: 0 | O17: 0 | P17: 0 | Q17: =1.58*1.02 -> 1.6116 | R17: 2.25 | S17: 0 | T17: 0 | U17: 46 | V17: 15 | W17: =M17-N17-P17-O17-Q17-R17-S17-T17+U17+V17 -> 91.1384 | X17: =W17-AO17 -> 22 | Y17: =Y16+(X17*1.9835) -> 329.25148 | Z17: =Z16+X17*(26300/37500)*1.9835 -> 230.91504 | AE17: 0 | AH17: 36 | AI17: =AI16-AH17 -> 5899 | AK17: =N17+O17+P17+Q17+R17+S17+T17+W17+AE17+AH17 -> 131 | AL17: =IF(L17<0,L17*-1,0) -> 31.269473 | AM17: =AK17+AL17 -> 162.26947 | AN17: =(U17-22)*1.9835+AN16 -> 365.47971 | AO17: =W17-22 -> 69.1384 | AV17: 0.06 | AW17: 36 | AX17: 19 | AZ17: =SUM(N17,P17:T17) -> 3.8616
A18: =A17+1 -> 6 | B18: 6900.12 | C18: 284024 | D18: =C18-C17 -> -259 | E18: =C18-152000 -> 132024 | F18: =D18/$D$2 -> -130.57726 | G18: 47 | H18: 0 | I18: =G18+H18 -> 47 | J18: =IF(L18>0,L18,0) -> 0 | K18: =I18+J18 -> 47 | L18: =F18-(I18-AK18) -> -41.577262 | M18: 38 | N18: 0 | O18: 0 | P18: 0 | Q18: =1.58*1.02 -> 1.6116 | R18: 2.73 | S18: 0 | T18: 0 | U18: 46 | V18: 16 | W18: =M18-N18-P18-O18-Q18-R18-S18-T18+U18+V18 -> 95.6584 | X18: =W18-AO18 -> 21.96 | Y18: =Y17+(X18*1.9835) -> 372.80914 | Z18: =Z17+X18*(26300/37500)*1.9835 -> 261.46348 | AE18: 0 | AH18: 36 | AI18: =AI17-AH18 -> 5863 | AK18: =N18+O18+P18+Q18+R18+S18+T18+W18+AE18+AH18 -> 136 | AL18: =IF(L18<0,L18*-1,0) -> 41.577262 | AM18: =AK18+AL18 -> 177.57726 | AN18: =(U18-22)*1.9835+AN17 -> 413.08371 | AO18: =W18-21.96 -> 73.6984 | AV18: 0 | AW18: 37 | AX18: 9 | AZ18: =SUM(N18,P18:T18) -> 4.3416
A19: =A18+1 -> 7 | B19: 6900.08 | C19: 283876 | D19: =C19-C18 -> -148 | E19: =C19-152000 -> 131876 | F19: =D19/$D$2 -> -74.615579 | G19: 35 | H19: 0 | I19: =G19+H19 -> 35 | J19: =IF(L19>0,L19,0) -> 22.384421 | K19: =I19+J19 -> 57.384421 | L19: =F19-(I19-AK19) -> 22.384421 | M19: 38 | N19: 0 | O19: 0 | P19: 0 | Q19: =1.58*1.02 -> 1.6116 | R19: 2.18 | S19: 0 | T19: 0 | U19: 46 | V19: 12 | W19: =M19-N19-P19-O19-Q19-R19-S19-T19+U19+V19 -> 92.2084 | X19: =W19-AO19 -> 22.01 | Y19: =Y18+(X19*1.9835) -> 416.46597 | Z19: =Z18+X19*(26300/37500)*1.9835 -> 292.08147 | AE19: 0 | AH19: 36 | AI19: =AI18-AH19 -> 5827 | AK19: =N19+O19+P19+Q19+R19+S19+T19+W19+AE19+AH19 -> 132 | AL19: =IF(L19<0,L19*-1,0) -> 0 | AM19: =AK19+AL19 -> 132 | AN19: =(U19-22)*1.9835+AN18 -> 460.68771 | AO19: =W19-22.01 -> 70.1984 | AV19: 0 | AW19: 49 | AX19: 12 | AZ19: =SUM(N19,P19:T19) -> 3.7916
A20: =A19+1 -> 8 | B20: 6900.04 | C20: 283728 | D20: =C20-C19 -> -148 | E20: =C20-152000 -> 131728 | F20: =D20/$D$2 -> -74.615579 | G20: 67 | H20: 0 | I20: =G20+H20 -> 67 | J20: =IF(L20>0,L20,0) -> 0 | K20: =I20+J20 -> 67 | L20: =F20-(I20-AK20) -> -10.615579 | M20: 38 | N20: 0 | O20: 0 | P20: 0 | Q20: =1.58*1.02 -> 1.6116 | R20: 2.53 | S20: 0 | T20: 0 | U20: 45 | V20: 12 | W20: =M20-N20-P20-O20-Q20-R20-S20-T20+U20+V20 -> 90.8584 | X20: =W20-AO20 -> 21.96 | Y20: =Y19+(X20*1.9835) -> 460.02363 | Z20: =Z19+X20*(26300/37500)*1.9835 -> 322.62991 | AE20: 0 | AH20: 36 | AI20: =AI19-AH20 -> 5791 | AK20: =N20+O20+P20+Q20+R20+S20+T20+W20+AE20+AH20 -> 131 | AL20: =IF(L20<0,L20*-1,0) -> 10.615579 | AM20: =AK20+AL20 -> 141.61558 | AN20: =(U20-22)*1.9835+AN19 -> 506.30821 | AO20: =W20-21.96 -> 68.8984 | AV20: 0 | AW20: 53 | AX20: 25 | AZ20: =SUM(N20,P20:T20) -> 4.1416
A21: =A20+1 -> 9 | B21: 6900 | C21: 283580 | D21: =C21-C20 -> -148 | E21: =C21-152000 -> 131580 | F21: =D21/$D$2 -> -74.615579 | G21: 71 | H21: 0 | I21: =G21+H21 -> 71 | J21: =IF(L21>0,L21,0) -> 0 | K21: =I21+J21 -> 71 | L21: =F21-(I21-AK21) -> -14.615579 | M21: 38 | N21: 0 | O21: 0 | P21: 0 | Q21: =1.58*1.02 -> 1.6116 | R21: 2.36 | S21: 0 | T21: 0 | U21: 45 | V21: 12 | W21: =M21-N21-P21-O21-Q21-R21-S21-T21+U21+V21 -> 91.0284 | X21: =W21-AO21 -> 22.03 | Y21: =Y20+(X21*1.9835) -> 503.72014 | Z21: =Z20+X21*(26300/37500)*1.9835 -> 353.27572 | AE21: 0 | AH21: 36 | AI21: =AI20-AH21 -> 5755 | AK21: =N21+O21+P21+Q21+R21+S21+T21+W21+AE21+AH21 -> 131 | AL21: =IF(L21<0,L21*-1,0) -> 14.615579 | AM21: =AK21+AL21 -> 145.61558 | AN21: =(U21-22)*1.9835+AN20 -> 551.92871 | AO21: =W21-22.03 -> 68.9984 | AV21: 0 | AW21: 52 | AX21: 26 | AZ21: =SUM(N21,P21:T21) -> 3.9716
A22: =A21+1 -> 10 | B22: 6899.96 | C22: 283433 | D22: =C22-C21 -> -147 | E22: =C22-152000 -> 131433 | F22: =D22/$D$2 -> -74.111419 | G22: 69 | H22: 0 | I22: =G22+H22 -> 69 | J22: =IF(L22>0,L22,0) -> 0 | K22: =I22+J22 -> 69 | L22: =F22-(I22-AK22) -> -40.411419 | M22: 15 | N22: 0 | O22: 0 | P22: 0 | Q22: =1.58*1.02 -> 1.6116 | R22: 2.37 | S22: 0 | T22: 0 | U22: 48 | V22: 3.7 | W22: =M22-N22-P22-O22-Q22-R22-S22-T22+U22+V22 -> 62.7184 | X22: =W22-AO22 -> 7.32 | Y22: =Y21+(X22*1.9835) -> 518.23936 | Z22: =Z21+X22*(26300/37500)*1.9835 -> 363.45854 | AE22: 0 | AH22: 36 | AI22: =AI21-AH22 -> 5719 | AK22: =N22+O22+P22+Q22+R22+S22+T22+W22+AE22+AH22 -> 102.7 | AL22: =IF(L22<0,L22*-1,0) -> 40.411419 | AM22: =AK22+AL22 -> 143.11142 | AN22: =(U22-7.33)*1.9835+AN21 -> 632.59766 | AO22: =W22-7.32 -> 55.3984 | AV22: 0.12 | AW22: 40 | AX22: 27 | AZ22: =SUM(N22,P22:T22) -> 3.9816
A23: =A22+1 -> 11 | B23: 6899.92 | C23: 283286 | D23: =C23-C22 -> -147 | E23: =C23-152000 -> 131286 | F23: =D23/$D$2 -> -74.111419 | G23: 61 | H23: 0 | I23: =G23+H23 -> 61 | J23: =IF(L23>0,L23,0) -> 0 | K23: =I23+J23 -> 61 | L23: =F23-(I23-AK23) -> -34.911419 | M23: 3.2 | N23: 0 | O23: 0 | P23: 0 | Q23: =1.58*1.02 -> 1.6116 | R23: 1.79 | S23: 0 | T23: =M23-(Q23+R23+S23) -> -0.2016 | U23: 61 | V23: 0 | W23: =M23-N23-P23-O23-Q23-R23-S23-T23+U23+V23 -> 61 | X23: =W23-AO23 -> 61 | Y23: =Y22+(X23*1.9835) -> 639.23286 | Z23: =Z22+X23*(26300/37500)*1.9835 -> 448.31531 | AE23: 0 | AH23: 36 | AI23: =AI22-AH23 -> 5683 | AK23: =N23+O23+P23+Q23+R23+S23+T23+W23+AE23+AH23 -> 100.2 | AL23: =IF(L23<0,L23*-1,0) -> 34.911419 | AM23: =AK23+AL23 -> 135.11142 | AN23: =(U23*1.9835)+AN22 -> 753.59115 | AV23: 0 | AW23: 48 | AX23: 27 | AZ23: =SUM(N23,P23:T23) -> 3.2
A24: =A23+1 -> 12 | B24: 6899.88 | C24: 283139 | D24: =C24-C23 -> -147 | E24: =C24-152000 -> 131139 | F24: =D24/$D$2 -> -74.111419 | G24: 56 | H24: 0 | I24: =G24+H24 -> 56 | J24: =IF(L24>0,L24,0) -> 0 | K24: =I24+J24 -> 56 | L24: =F24-(I24-AK24) -> -28.711419 | M24: 3.4 | N24: 0 | O24: 0 | P24: 0 | Q24: =1.58*1.02 -> 1.6116 | R24: 2.31 | S24: 0 | T24: =M24-(Q24+R24+S24) -> -0.5216 | U24: 62 | V24: 0 | W24: =M24-N24-P24-O24-Q24-R24-S24-T24+U24+V24 -> 62 | X24: =W24-AO24 -> 62 | Y24: =Y23+(X24*1.9835) -> 762.20986 | Z24: =Z23+X24*(26300/37500)*1.9835 -> 534.56318 | AE24: 0 | AH24: 36 | AI24: =AI23-AH24 -> 5647 | AK24: =N24+O24+P24+Q24+R24+S24+T24+W24+AE24+AH24 -> 101.4 | AL24: =IF(L24<0,L24*-1,0) -> 28.711419 | AM24: =AK24+AL24 -> 130.11142 | AN24: =(U24*1.9835)+AN23 -> 876.56816 | AV24: 0 | AW24: 50 | AX24: 22 | AZ24: =SUM(N24,P24:T24) -> 3.4
A25: =A24+1 -> 13 | B25: 6899.84 | C25: 282992 | D25: =C25-C24 -> -147 | E25: =C25-152000 -> 130992 | F25: =D25/$D$2 -> -74.111419 | G25: 54 | H25: 0 | I25: =G25+H25 -> 54 | J25: =IF(L25>0,L25,0) -> 0 | K25: =I25+J25 -> 54 | L25: =F25-(I25-AK25) -> -27.611419 | M25: 3.5 | N25: 0 | O25: 0 | P25: 0 | Q25: =1.58*1.02 -> 1.6116 | R25: 2.88 | S25: 0 | T25: =M25-(Q25+R25+S25) -> -0.9916 | U25: 61 | V25: 0 | W25: =M25-N25-P25-O25-Q25-R25-S25-T25+U25+V25 -> 61 | X25: =W25-AO25 -> 61 | Y25: =Y24+(X25*1.9835) -> 883.20336 | Z25: =Z24+X25*(26300/37500)*1.9835 -> 619.41996 | AE25: 0 | AH25: 36 | AI25: =AI24-AH25 -> 5611 | AK25: =N25+O25+P25+Q25+R25+S25+T25+W25+AE25+AH25 -> 100.5 | AL25: =IF(L25<0,L25*-1,0) -> 27.611419 | AM25: =AK25+AL25 -> 128.11142 | AN25: =(U25*1.9835)+AN24 -> 997.56165 | AV25: 0 | AW25: 60 | AX25: 27 | AZ25: =SUM(N25,P25:T25) -> 3.5
A26: =A25+1 -> 14 | B26: 6899.79 | C26: 282808 | D26: =C26-C25 -> -184 | E26: =C26-152000 -> 130808 | F26: =D26/$D$2 -> -92.765314 | G26: 54 | H26: 0 | I26: =G26+H26 -> 54 | J26: =IF(L26>0,L26,0) -> 0 | K26: =I26+J26 -> 54 | L26: =F26-(I26-AK26) -> -45.065314 | M26: 3.7 | N26: 0 | O26: 0 | P26: 0 | Q26: =1.58*1.02 -> 1.6116 | R26: 3.96 | S26: 0 | T26: =M26-(Q26+R26+S26) -> -1.8716 | U26: 62 | V26: 0 | W26: =M26-N26-P26-O26-Q26-R26-S26-T26+U26+V26 -> 62 | X26: =W26-AO26 -> 62 | Y26: =Y25+(X26*1.9835) -> 1006.1804 | Z26: =Z25+X26*(26300/37500)*1.9835 -> 705.66783 | AE26: 0 | AH26: 36 | AI26: =AI25-AH26 -> 5575 | AK26: =N26+O26+P26+Q26+R26+S26+T26+W26+AE26+AH26 -> 101.7 | AL26: =IF(L26<0,L26*-1,0) -> 45.065314 | AM26: =AK26+AL26 -> 146.76531 | AN26: =(U26*1.9835)+AN25 -> 1120.5387 | AV26: 0 | AW26: 51 | AX26: 24 | AZ26: =SUM(N26,P26:T26) -> 3.7
A27: =A26+1 -> 15 | B27: 6899.74 | C27: 282625 | D27: =C27-C26 -> -183 | E27: =C27-152000 -> 130625 | F27: =D27/$D$2 -> -92.261155 | G27: 47 | H27: 0 | I27: =G27+H27 -> 47 | J27: =IF(L27>0,L27,0) -> 0 | K27: =I27+J27 -> 47 | L27: =F27-(I27-AK27) -> -37.561155 | M27: 3.7 | N27: 0 | O27: 0 | P27: 0 | Q27: =1.58*1.02 -> 1.6116 | R27: 2.53 | S27: 0 | T27: =M27-(Q27+R27+S27) -> -0.4416 | U27: 62 | V27: 0 | W27: =M27-N27-P27-O27-Q27-R27-S27-T27+U27+V27 -> 62 | X27: =W27-AO27 -> 62 | Y27: =Y26+(X27*1.9835) -> 1129.1574 | Z27: =Z26+X27*(26300/37500)*1.9835 -> 791.91569 | AE27: 0 | AH27: 36 | AI27: =AI26-AH27 -> 5539 | AK27: =N27+O27+P27+Q27+R27+S27+T27+W27+AE27+AH27 -> 101.7 | AL27: =IF(L27<0,L27*-1,0) -> 37.561155 | AM27: =AK27+AL27 -> 139.26115 | AN27: =(U27*1.9835)+AN26 -> 1243.5157 | AV27: 0 | AW27: 56 | AX27: 24 | AZ27: =SUM(N27,P27:T27) -> 3.7
A28: =A27+1 -> 16 | B28: 6899.69 | C28: 282441 | D28: =C28-C27 -> -184 | E28: =C28-152000 -> 130441 | F28: =D28/$D$2 -> -92.765314 | G28: 48 | H28: 0 | I28: =G28+H28 -> 48 | J28: =IF(L28>0,L28,0) -> 0 | K28: =I28+J28 -> 48 | L28: =F28-(I28-AK28) -> -39.065314 | M28: 3.7 | N28: 0 | O28: 0 | P28: 0 | Q28: =1.58*1.02 -> 1.6116 | R28: 2.49 | S28: 0 | T28: =M28-(Q28+R28+S28) -> -0.4016 | U28: 62 | V28: 0 | W28: =M28-N28-P28-O28-Q28-R28-S28-T28+U28+V28 -> 62 | X28: =W28-AO28 -> 62 | Y28: =Y27+(X28*1.9835) -> 1252.1344 | Z28: =Z27+X28*(26300/37500)*1.9835 -> 878.16356 | AE28: 0 | AH28: 36 | AI28: =AI27-AH28 -> 5503 | AK28: =N28+O28+P28+Q28+R28+S28+T28+W28+AE28+AH28 -> 101.7 | AL28: =IF(L28<0,L28*-1,0) -> 39.065314 | AM28: =AK28+AL28 -> 140.76531 | AN28: =(U28*1.9835)+AN27 -> 1366.4927 | AV28: 0 | AW28: 59 | AX28: 26 | AZ28: =SUM(N28,P28:T28) -> 3.7
A29: =A28+1 -> 17 | B29: 6899.67 | C29: 282368 | D29: =C29-C28 -> -73 | E29: =C29-152000 -> 130368 | F29: =D29/$D$2 -> -36.80363 | G29: 55 | H29: 0 | I29: =G29+H29 -> 55 | J29: =IF(L29>0,L29,0) -> 2.7963701 | K29: =I29+J29 -> 57.79637 | L29: =F29-(I29-AK29) -> 2.7963701 | M29: 3.6 | N29: 0 | O29: 0 | P29: 0 | Q29: =1.58*1.02 -> 1.6116 | R29: 2.22 | S29: 0 | T29: =M29-(Q29+R29+S29) -> -0.2316 | U29: 55 | V29: 0 | W29: =M29-N29-P29-O29-Q29-R29-S29-T29+U29+V29 -> 55 | X29: =W29-AO29 -> 55 | Y29: =Y28+(X29*1.9835) -> 1361.2269 | Z29: =Z28+X29*(26300/37500)*1.9835 -> 954.67377 | AE29: 0 | AH29: 36 | AI29: =AI28-AH29 -> 5467 | AK29: =N29+O29+P29+Q29+R29+S29+T29+W29+AE29+AH29 -> 94.6 | AL29: =IF(L29<0,L29*-1,0) -> 0 | AM29: =AK29+AL29 -> 94.6 | AN29: =(U29*1.9835)+AN28 -> 1475.5852 | AV29: 0 | AW29: 64 | AX29: 31 | AZ29: =SUM(N29,P29:T29) -> 3.6
A30: =A29+1 -> 18 | B30: 6899.65 | C30: 282294 | D30: =C30-C29 -> -74 | E30: =C30-152000 -> 130294 | F30: =D30/$D$2 -> -37.307789 | G30: 54 | H30: 0 | I30: =G30+H30 -> 54 | J30: =IF(L30>0,L30,0) -> 0.39221074 | K30: =I30+J30 -> 54.392211 | L30: =F30-(I30-AK30) -> 0.39221074 | M30: 3.7 | N30: 0 | O30: 0 | P30: 0 | Q30: =1.58*1.02 -> 1.6116 | R30: 2.71 | S30: 0 | T30: =M30-(Q30+R30+S30) -> -0.6216 | U30: 52 | V30: 0 | W30: =M30-N30-P30-O30-Q30-R30-S30-T30+U30+V30 -> 52 | X30: =W30-AO30 -> 52 | Y30: =Y29+(X30*1.9835) -> 1464.3689 | Z30: =Z29+X30*(26300/37500)*1.9835 -> 1027.0107 | AE30: 0 | AH30: 36 | AI30: =AI29-AH30 -> 5431 | AK30: =N30+O30+P30+Q30+R30+S30+T30+W30+AE30+AH30 -> 91.7 | AL30: =IF(L30<0,L30*-1,0) -> 0 | AM30: =AK30+AL30 -> 91.7 | AN30: =(U30*1.9835)+AN29 -> 1578.7272 | AV30: 0 | AW30: 65 | AX30: 32 | AZ30: =SUM(N30,P30:T30) -> 3.7
A31: =A30+1 -> 19 | B31: 6899.63 | C31: 282221 | D31: =C31-C30 -> -73 | E31: =C31-152000 -> 130221 | F31: =D31/$D$2 -> -36.80363 | G31: 50 | H31: 0 | I31: =G31+H31 -> 50 | J31: =IF(L31>0,L31,0) -> 4.8963701 | K31: =I31+J31 -> 54.89637 | L31: =F31-(I31-AK31) -> 4.8963701 | M31: 3.7 | N31: 0 | O31: 0 | P31: 0 | Q31: =1.58*1.02 -> 1.6116 | R31: 3.76 | S31: 0 | T31: =M31-(Q31+R31+S31) -> -1.6716 | U31: 52 | V31: 0 | W31: =M31-N31-P31-O31-Q31-R31-S31-T31+U31+V31 -> 52 | X31: =W31-AO31 -> 52 | Y31: =Y30+(X31*1.9835) -> 1567.5109 | Z31: =Z30+X31*(26300/37500)*1.9835 -> 1099.3476 | AE31: 0 | AH31: 36 | AI31: =AI30-AH31 -> 5395 | AK31: =N31+O31+P31+Q31+R31+S31+T31+W31+AE31+AH31 -> 91.7 | AL31: =IF(L31<0,L31*-1,0) -> 0 | AM31: =AK31+AL31 -> 91.7 | AN31: =(U31*1.9835)+AN30 -> 1681.8692 | AV31: 0 | AW31: 62 | AX31: 30 | AZ31: =SUM(N31,P31:T31) -> 3.7
A32: =A31+1 -> 20 | B32: 6899.6 | C32: 282110 | D32: =C32-C31 -> -111 | E32: =C32-152000 -> 130110 | F32: =D32/$D$2 -> -55.961684 | G32: 47 | H32: 0 | I32: =G32+H32 -> 47 | J32: =IF(L32>0,L32,0) -> 0 | K32: =I32+J32 -> 47 | L32: =F32-(I32-AK32) -> -15.161684 | M32: 3.8 | N32: 0 | O32: 0 | P32: 0 | Q32: =1.58*1.02 -> 1.6116 | R32: 1.76 | S32: 0 | T32: =M32-(Q32+R32+S32) -> 0.4284 | U32: 48 | V32: 0 | W32: =M32-N32-P32-O32-Q32-R32-S32-T32+U32+V32 -> 48 | X32: =W32-AO32 -> 48 | Y32: =Y31+(X32*1.9835) -> 1662.7189 | Z32: =Z31+X32*(26300/37500)*1.9835 -> 1166.1202 | AE32: 0 | AH32: 36 | AI32: =AI31-AH32 -> 5359 | AK32: =N32+O32+P32+Q32+R32+S32+T32+W32+AE32+AH32 -> 87.8 | AL32: =IF(L32<0,L32*-1,0) -> 15.161684 | AM32: =AK32+AL32 -> 102.96168 | AN32: =(U32*1.9835)+AN31 -> 1777.0772 | AV32: 0 | AW32: 58 | AX32: 26 | AZ32: =SUM(N32,P32:T32) -> 3.8
A33: =A32+1 -> 21 | B33: 6899.57 | C33: 282000 | D33: =C33-C32 -> -110 | E33: =C33-152000 -> 130000 | F33: =D33/$D$2 -> -55.457525 | G33: 48 | H33: 0 | I33: =G33+H33 -> 48 | J33: =IF(L33>0,L33,0) -> 0 | K33: =I33+J33 -> 48 | L33: =F33-(I33-AK33) -> -22.457525 | M33: 4 | N33: 0 | O33: 0 | P33: 0 | Q33: =1.58*1.02 -> 1.6116 | R33: 2.38 | S33: 0 | T33: =M33-(Q33+R33+S33) -> 0.0084 | U33: 41 | V33: 0 | W33: =M33-N33-P33-O33-Q33-R33-S33-T33+U33+V33 -> 41 | X33: =W33-AO33 -> 41 | Y33: =Y32+(X33*1.9835) -> 1744.0424 | Z33: =Z32+X33*(26300/37500)*1.9835 -> 1223.155 | AE33: 0 | AH33: 36 | AI33: =AI32-AH33 -> 5323 | AK33: =N33+O33+P33+Q33+R33+S33+T33+W33+AE33+AH33 -> 81 | AL33: =IF(L33<0,L33*-1,0) -> 22.457525 | AM33: =AK33+AL33 -> 103.45752 | AN33: =(U33*1.9835)+AN32 -> 1858.4007 | AV33: 0 | AW33: 51 | AX33: 22 | AZ33: =SUM(N33,P33:T33) -> 4
A34: =A33+1 -> 22 | B34: 6899.55 | C34: 281927 | D34: =C34-C33 -> -73 | E34: =C34-152000 -> 129927 | F34: =D34/$D$2 -> -36.80363 | G34: 42 | H34: 0 | I34: =G34+H34 -> 42 | J34: =IF(L34>0,L34,0) -> 2.1963701 | K34: =I34+J34 -> 44.19637 | L34: =F34-(I34-AK34) -> 2.1963701 | M34: 4 | N34: 0 | O34: 0 | P34: 0 | Q34: =1.58*1.02 -> 1.6116 | R34: 2.49 | S34: 0 | T34: =M34-(Q34+R34+S34) -> -0.1016 | U34: 41 | V34: 0 | W34: =M34-N34-P34-O34-Q34-R34-S34-T34+U34+V34 -> 41 | X34: =W34-AO34 -> 41 | Y34: =Y33+(X34*1.9835) -> 1825.3659 | Z34: =Z33+X34*(26300/37500)*1.9835 -> 1280.1899 | AE34: 0 | AH34: 36 | AI34: =AI33-AH34 -> 5287 | AK34: =N34+O34+P34+Q34+R34+S34+T34+W34+AE34+AH34 -> 81 | AL34: =IF(L34<0,L34*-1,0) -> 0 | AM34: =AK34+AL34 -> 81 | AN34: =(U34*1.9835)+AN33 -> 1939.7242 | AV34: 0 | AW34: 56 | AX34: 22 | AZ34: =SUM(N34,P34:T34) -> 4
... A41: =A40+1 -> 29 | B41: 6899.52 | C41: 281817 | D41: =C41-C40 -> -73 | E41: =C41-152000 -> 129817 | F41: =D41/$D$2 -> -36.80363 | G41: 57 | H41: 0 | I41: =G41+H41 -> 57 | J41: =IF(L41>0,L41,0) -> 0 | K41: =I41+J41 -> 57 | L41: =F41-(I41-AK41) -> -28.10363 | M41: 3.7 | N41: 0 | O41: 0 | P41: 0 | Q41: =1.58*1.02 -> 1.6116 | R41: 1.76 | S41: 0 | T41: =M41-(Q41+R41+S41) -> 0.3284 | U41: 26 | V41: 0 | W41: =M41-N41-P41-O41-Q41-R41-S41-T41+U41+V41 -> 26 | X41: =W41-AO41 -> 26 | Y41: =Y40+(X41*1.9835) -> 2249.8349 | Z41: =Z40+X41*(26300/37500)*1.9835 -> 1577.8842 | AE41: 0 | AH41: 36 | AI41: =AI40-AH41 -> 5035 | AK41: =N41+O41+P41+Q41+R41+S41+T41+W41+AE41+AH41 -> 65.7 | AL41: =IF(L41<0,L41*-1,0) -> 28.10363 | AM41: =AK41+AL41 -> 93.80363 | AN41: =(U41*1.9835)+AN40 -> 2364.1932 | AV41: 0 | AW41: 45 | AX41: 24 | AZ41: =SUM(N41,P41:T41) -> 3.7
A42: 30 | B42: 6899.5 | C42: 281743 | D42: =C42-C41 -> -74 | E42: =C42-152000 -> 129743 | F42: =D42/$D$2 -> -37.307789 | G42: 59 | H42: 0 | I42: =G42+H42 -> 59 | J42: =IF(L42>0,L42,0) -> 0 | K42: =I42+J42 -> 59 | L42: =F42-(I42-AK42) -> -30.607789 | M42: 3.7 | N42: 0 | O42: 0 | P42: 0 | Q42: =1.58*1.02 -> 1.6116 | R42: 2.47 | S42: 0 | T42: =M42-(Q42+R42+S42) -> -0.3816 | U42: 26 | V42: 0 | W42: =M42-N42-P42-O42-Q42-R42-S42-T42+U42+V42 -> 26 | X42: =W42-AO42 -> 26 | Y42: =Y41+(X42*1.9835) -> 2301.4059 | Z42: =Z41+X42*(26300/37500)*1.9835 -> 1614.0526 | AE42: 0 | AH42: 36 | AI42: =AI41-AH42 -> 4999 | AK42: =N42+O42+P42+Q42+R42+S42+T42+W42+AE42+AH42 -> 65.7 | AL42: =IF(L42<0,L42*-1,0) -> 30.607789 | AM42: =AK42+AL42 -> 96.307789 | AN42: =(U42*1.9835)+AN41 -> 2415.7642 | AV42: 0 | AW42: 47 | AX42: 28 | AZ42: =SUM(N42,P42:T42) -> 3.7
A44: MONTH / CFS | F44: =SUM(F13:F42) -> -1541.7192 | G44: =SUM(G13:G42) -> 1625 | H44: =SUM(H13:H42) -> 0 | I44: =SUM(I13:I42) -> 1625 | J44: =SUM(J13:J42) -> 201.43469 | K44: =SUM(K13:K42) -> 1826.4347 | L44: =SUM(L13:L42) -> -359.61918 | M44: =SUM(M13:M42) -> 302.8 | ... O44: =SUM(O13:O42) -> 0 | Q44: =SUM(Q13:Q42) -> 48.348 | R44: =SUM(R13:R42) -> 73.27 | S44: =SUM(S14:S42) -> 0 | T44: =SUM(T14:T42) -> -7.062 | U44: =SUM(U13:U42) -> 1349 | V44: =SUM(V13:V42) -> 76.3 | W44: =SUM(W13:W42) -> 1613.544 | X44: =SUM(X13:X42) -> 1160.2752 | AH44: =SUM(AH13:AH42) -> 1079 | AJ44: =SUM(AJ13:AJ42) -> 0 | AK44: =SUM(AK13:AK42) -> 2807.1 | AL44: =SUM(AL13:AL42) -> 561.05387 | AM44: =SUM(AM13:AM42) -> 3368.1539 | AO44: =SUM(AO13:AO42) -> 453.2688 | AV44: =SUM(AV13:AV42) -> 0.85 | AW44: =AVERAGE(AW13:AW42) -> 52.933333 | AX44: =AVERAGE(AX13:AX43) -> 25.8 | AY44: Avg | AZ44: =SUM(AZ13:AZ42) -> 114.556
A45: MONTH / AF | D45: =SUM(D13:D42) -> -3058 | F45: =F44*$D$2 -> -3058 | G45: =G44*$D$2 -> 3223.1875 | H45: =H44*$D$2 -> 0 | I45: =I44*$D$2 -> 3223.1875 | J45: =J44*$D$2 -> 399.5457 | K45: =K44*$D$2 -> 3622.7332 | L45: =L44*$D$2 -> -713.30465 | M45: =M44*$D$2 -> 600.6038 | ... O45: =O44*$D$2 -> 0 | Q45: =Q44*$D$2 -> 95.898258 | R45: =R44*$D$2 -> 145.33104 | S45: =S44*$D$2 -> 0 | T45: =T44*$D$2 -> -14.007477 | U45: =U44*$D$2 -> 2675.7415 | V45: =V44*$D$2 -> 151.34105 | W45: =W44*$D$2 -> 3200.4645 | X45: =X44*$D$2 -> 2301.4059 | AH45: =AH44*$D$2 -> 2140.1965 | AJ45: =AJ44*$D$2 -> 0 | AK45: =AK44*$D$2 -> 5567.8828 | AL45: =AL44*$D$2 -> 1112.8503 | AM45: =AM44*$D$2 -> 6680.7332 | AO45: =AO44*$D$2 -> 899.05866 | AW45: =MAX(AW13:AW42) -> 68 | AX45: =MAX(AX13:AX43) -> 39 | AY45: HI | AZ45: =AZ44*$D$2 -> 227.22183
A47: SEASON / CFS | AW47: =MIN(AW13:AW42) -> 36 | AX47: =MIN(AX13:AX43) -> 9 | AY47: LO
A48: SEASON / AF
A50: YTD / CFS | F50: =F11+F44 -> -1541.7192 | G50: =G11+G44 -> 1625 | H50: =H11+H44 -> 0 | I50: =I11+I44 -> 1625 | J50: =J11+J44 -> 201.43469 | K50: =K11+K44 -> 1826.4347 | L50: =L11+L44 -> -359.61918 | M50: =M11+M44 -> 302.8 | N50: =N11+N44 -> 0 | O50: 0 | Q50: =Q11+Q44 -> 48.348 | R50: =R11+R44 -> 73.27 | S50: =S11+S44 -> 0 | T50: =T11+T44 -> -7.062 | U50: =U11+U44 -> 1349 | V50: =V11+V44 -> 76.3 | W50: =W11+W44 -> 1613.544 | X50: =X11+X44 -> 1160.2752 | AH50: =AH11+AH44 -> 1079 | AI50: =AI42 -> 4999 | AJ50: =AJ11+AJ44 -> 0 | AK50: =AK11+AK44 -> 2807.1 | AL50: =AL11+AL44 -> 561.05387 | AM50: =AM11+AM44 -> 3368.1539 | AO50: =AO11+AO44 -> 453.2688 | AV50: =AV11+AV44 -> 0.85 | AZ50: =AZ11+AZ44 -> 114.556
A51: YTD / AF | D51: =D11+D45 -> -3058 | E51: =E42 -> 129743 | F51: =F50*$D$2 -> -3058 | G51: =G50*$D$2 -> 3223.1875 | H51: =H50*$D$2 -> 0 | I51: =I50*$D$2 -> 3223.1875 | J51: =J50*$D$2 -> 399.5457 | K51: =K50*$D$2 -> 3622.7332 | L51: =L50*$D$2 -> -713.30465 | M51: =M50*$D$2 -> 600.6038 | ... O51: =O50*$D$2 -> 0 | Q51: =Q50*$D$2 -> 95.898258 | R51: =R50*$D$2 -> 145.33104 | S51: =S50*$D$2 -> 0 | T51: =T50*$D$2 -> -14.007477 | U51: =U50*$D$2 -> 2675.7415 | V51: =V50*$D$2 -> 151.34105 | W51: =W50*$D$2 -> 3200.4645 | X51: =X50*$D$2 -> 2301.4059 | AH51: =AH50*$D$2 -> 2140.1965 | AI51: =AI50*$D$2 -> 9915.5165 | AJ51: =AJ50*$D$2 -> 0 | AK51: =AK50*$D$2 -> 5567.8828 | AL51: =AL50*$D$2 -> 1112.8503 | AM51: =AM50*$D$2 -> 6680.7332 | AN51: =AN42 -> 2415.7642 | AO51: =AO50*$D$2 -> 899.05866 | AZ51: =AZ50*$D$2 -> 227.22183

Sheet DEC
K1: MCPHEE RESERVOIR INFLOW/OUTFLOW TABULATION
A2: AF/cfs CONVERT FACTOR | D2: 1.9835 | K2: DECEMBER "2008"
D4: RESERVOIR | W4: INFLOW/OUTFLOW (CFS) | AP4: ADJUSTMENTS | AW4: WEATHER
A5: DATE | B5: RESERV | C5: RESERV | D5: AC FT | E5: ACTIVE | F5: CONV TO | G5: DOLORES | H5: LOST | I5: RECORD | J5: CALC | K5: TOTAL | L5: CALC | M5: DOLORES TUNNEL | U5: LONE | V5: U | W5: TOTAL | X5: TOTAL | Y5: TOTAL | Z5: TOTAl | AA5: MVI | AB5: MVI | AC5: TO EX & | AD5: MVI | AE5: DV CR | AF5: D/S SENIOR | AH5: BELOW | AI5: FISH | AJ5: SPILL | AK5: RECORD | AL5: CALC | AM5: TOTAL | AN5: NAR | AO5: MVI | AP5: MVI | AQ5: MVI | AR5: DIST. | AS5: U/S | AT5: TOTTEN | AU5: UTES | AV5: RAIN | AW5: MAX | AX5: MIN | AZ5: TOTAL
A6: DEC | B6: ELEV | D6: CHANGE | E6: CAP | F6: CFS | G6: RIVER | H6: CAN | I6: INFLOW | J6: INFLOW | K6: INFLOW | L6: INF/OTF | M6: TOT DIV | N6: WET | O6: UTE | P6: QUEST | Q6: MWC | R6: CTZ | S6: CTZ & | T6: F-BAY | U6: PINE | V6: LAT | W6: MVI | X6: MVI | Y6: MVI | Z6: MVI | AA6: CALL | AB6: APR- | AC6: U/S EX | AD6: PROJ | AE6: CANAL | AF6: MVIC | AG6: PROJ | AH6: MCP | AI6: LEFT | AK6: OTF | AL6: OTF | AM6: OTF | AN6: CALL | AO6: STOCK | AP6: STORED | AQ6: STORED | AR6: CLASS | AS6: USERS | AT6: (FRESH | AU6: FROM | AW6: TMP | AX6: TMP | AZ6: TUNNEL
N7: LAND | O7: F&R | S7: UTE | T7: SPILL | W7: 153400 | X7: IRRIG. | Y7: IRRIG. | Z7: 105500 | AB7: JUNE | AF7: 1.7 | AG7: 1.3 | AI7: 31798 | AP7: Apr - Jun | AQ7: EVAP | AR7: "B" | AS7: EXCH | AT7: WATER) | AU7: MVIC | AZ7: Misc.
C8: AC. Ft. | E8: AC FT | G8: CFS | H8: CFS | I8: CFS | J8: CFS | K8: CFS | L8: CFS | M8: CFS | N8: CFS | O8: CFS | P8: CFS | Q8: CFS | R8: CFS | S8: PROJ | T8: CFS | U8: CFS | V8: CFS | W8: CFS | X8: 150400 | Y8: 150400 | Z8: Ac. Ft. | AA8: CFS | AB8: 72000 | AC8: CFS | AD8: CFS | AE8: CFS | AF8: CFS | AG8: CFS | AH8: CFS | AI8: CFS | AJ8: CFS | AK8: CFS | AL8: CFS | AM8: CFS | AN8: AC FT | AO8: CFS | AP8: CFS | AQ8: AC.FT. | AR8: CFS | AS8: CFS | AT8: CFS | AU8: CFS | AZ8: Outflow
N9: 1.03 | O9: 1.05 | P9: 1.02 | Q9: 1.02 | R9: 1.04 | S9: CFS | X9: CFS | Y9: Ac. Ft. | AB9: Ac. Ft. | AZ9: CFS
A10: SEASON BAL
A11: YTD | B11: =NOV!B42 -> 6899.5 | C11: =NOV!C42 -> 281743 | D11: =NOV!D51 -> -3058 | E11: =NOV!E51 -> 129743 | F11: =NOV!F50 -> -1541.7192 | G11: =NOV!G50 -> 1625 | H11: =NOV!H50 -> 0 | I11: =NOV!I50 -> 1625 | J11: =NOV!J50 -> 201.43469 | K11: =NOV!K50 -> 1826.4347 | L11: =NOV!L50 -> -359.61918 | M11: =NOV!M50 -> 302.8 | ... O11: =NOV!O50 -> 0 | Q11: =NOV!Q50 -> 48.348 | R11: =NOV!R50 -> 73.27 | S11: =NOV!S50 -> 0 | T11: =NOV!T50 -> -7.062 | U11: =NOV!U50 -> 1349 | V11: =NOV!V50 -> 76.3 | W11: =NOV!W50 -> 1613.544 | X11: =NOV!X50 -> 1160.2752 | Y11: =NOV!Y42 -> 2301.4059 | Z11: =NOV!Z42 -> 1614.0526 | AH11: =NOV!AH50 -> 1079 | AI11: =NOV!AI50 -> 4999 | AJ11: =NOV!AJ50 -> 0 | AK11: =NOV!AK50 -> 2807.1 | AL11: =NOV!AL50 -> 561.05387 | AM11: =NOV!AM50 -> 3368.1539 | AN11: =NOV!AN51 -> 2415.7642 | AO11: =NOV!AO50 -> 453.2688 | AV11: =NOV!AV50 -> 0.85 | AZ11: =NOV!AZ50 -> 114.556
A13: 1 | B13: 6899.49 | C13: 281706 | D13: =C13-C11 -> -37 | E13: =C13-152000 -> 129706 | F13: =D13/$D$2 -> -18.653895 | G13: 54 | H13: 0.4 | I13: =G13+H13 -> 54.4 | J13: =IF(L13>0,L13,0) -> 0 | K13: =I13+J13 -> 54.4 | L13: =F13-(I13-AK13) -> -0.35389463 | M13: 3.7 | N13: 0 | O13: 0 | P13: 0 | Q13: =1.53*1.02 -> 1.5606 | R13: 2.47 | S13: 0 | T13: =M13-(Q13+R13+S13) -> -0.3306 | U13: 33 | V13: 0 | W13: =M13-N13-O13-P13-Q13-R13-S13-T13+U13+V13 -> 33 | X13: =W13-AO13 -> 33 | Y13: =Y11+(X13*1.9835) -> 2366.8614 | Z13: =Z11+X13*(26300/37500)*1.9835 -> 1659.9588 | AE13: 0 | AH13: 36 | AI13: =AI11-AH13 -> 4963 | AK13: =N13+O13+P13+Q13+R13+S13+T13+W13+AE13+AH13 -> 72.7 | AL13: =IF(L13<0,L13*-1,0) -> 0.35389463 | AM13: =AK13+AL13 -> 73.053895 | AN13: =AN11+(W13*1.9835) -> 2481.2197 | AO13: 0 | AV13: 0 | AW13: 53 | AX13: 28 | AZ13: =SUM(N13,P13:T13) -> 3.7
A14: =A13+1 -> 2 | B14: 6899.47 | C14: 281633 | D14: =C14-C13 -> -73 | E14: =C14-152000 -> 129633 | F14: =D14/$D$2 -> -36.80363 | G14: 50 | H14: 0.49 | I14: =G14+H14 -> 50.49 | J14: =IF(L14>0,L14,0) -> 0 | K14: =I14+J14 -> 50.49 | L14: =F14-(I14-AK14) -> -8.7936299 | M14: 3.5 | N14: 0 | O14: 0 | P14: 0 | Q14: =1.53*1.02 -> 1.5606 | R14: 2.19 | S14: 0 | T14: =M14-(Q14+R14+S14) -> -0.2506 | U14: 39 | V14: 0 | W14: =M14-N14-O14-P14-Q14-R14-S14-T14+U14+V14 -> 39 | X14: =W14-AO14 -> 39 | Y14: =Y13+(X14*1.9835) -> 2444.2179 | Z14: =Z13+X14*(26300/37500)*1.9835 -> 1714.2115 | AE14: 0 | AH14: 36 | AI14: =AI13-AH14 -> 4927 | AK14: =N14+O14+P14+Q14+R14+S14+T14+W14+AE14+AH14 -> 78.5 | AL14: =IF(L14<0,L14*-1,0) -> 8.7936299 | AM14: =AK14+AL14 -> 87.29363 | AN14: =AN13+(W14*1.9835) -> 2558.5762 | AO14: 0 | AV14: 0 | AW14: 51 | AX14: 28 | AZ14: =SUM(N14,P14:T14) -> 3.5
A15: =A14+1 -> 3 | B15: 6899.45 | C15: 281559 | D15: =C15-C14 -> -74 | E15: =C15-152000 -> 129559 | F15: =D15/$D$2 -> -37.307789 | G15: 55 | H15: 0.47 | I15: =G15+H15 -> 55.47 | J15: =IF(L15>0,L15,0) -> 0 | K15: =I15+J15 -> 55.47 | L15: =F15-(I15-AK15) -> -12.377789 | M15: 3.4 | N15: 0 | O15: 0 | P15: 0 | Q15: =1.53*1.02 -> 1.5606 | R15: 2.38 | S15: 0 | T15: =M15-(Q15+R15+S15) -> -0.5406 | U15: 41 | V15: 0 | W15: =M15-N15-O15-P15-Q15-R15-S15-T15+U15+V15 -> 41 | X15: =W15-AO15 -> 41 | Y15: =Y14+(X15*1.9835) -> 2525.5414 | Z15: =Z14+X15*(26300/37500)*1.9835 -> 1771.2463 | AE15: 0 | AH15: 36 | AI15: =AI14-AH15 -> 4891 | AK15: =N15+O15+P15+Q15+R15+S15+T15+W15+AE15+AH15 -> 80.4 | AL15: =IF(L15<0,L15*-1,0) -> 12.377789 | AM15: =AK15+AL15 -> 92.777789 | AN15: =AN14+(W15*1.9835) -> 2639.8997 | AO15: 0 | AV15: 0 | AW15: 45 | AX15: 22 | AZ15: =SUM(N15,P15:T15) -> 3.4
A16: =A15+1 -> 4 | B16: 6899.42 | C16: 281449 | D16: =C16-C15 -> -110 | E16: =C16-152000 -> 129449 | F16: =D16/$D$2 -> -55.457525 | G16: 35 | H16: 0.37 | I16: =G16+H16 -> 35.37 | J16: =IF(L16>0,L16,0) -> 0 | K16: =I16+J16 -> 35.37 | L16: =F16-(I16-AK16) -> -10.327525 | M16: 3.5 | N16: 0 | O16: 0 | P16: 0 | Q16: =1.53*1.02 -> 1.5606 | R16: 2.23 | S16: 0 | T16: =M16-(Q16+R16+S16) -> -0.2906 | U16: 41 | V16: 0 | W16: =M16-N16-O16-P16-Q16-R16-S16-T16+U16+V16 -> 41 | X16: =W16-AO16 -> 41 | Y16: =Y15+(X16*1.9835) -> 2606.8649 | Z16: =Z15+X16*(26300/37500)*1.9835 -> 1828.2812 | AE16: 0 | AH16: 36 | AI16: =AI15-AH16 -> 4855 | AK16: =N16+O16+P16+Q16+R16+S16+T16+W16+AE16+AH16 -> 80.5 | AL16: =IF(L16<0,L16*-1,0) -> 10.327525 | AM16: =AK16+AL16 -> 90.827525 | AN16: =AN15+(W16*1.9835) -> 2721.2232 | AO16: 0 | AV16: 0 | AW16: 42 | AX16: 21 | AZ16: =SUM(N16,P16:T16) -> 3.5
A17: =A16+1 -> 5 | B17: 6899.39 | C17: 281339 | D17: =C17-C16 -> -110 | E17: =C17-152000 -> 129339 | F17: =D17/$D$2 -> -55.457525 | G17: 35 | H17: 0.24 | I17: =G17+H17 -> 35.24 | J17: =IF(L17>0,L17,0) -> 0 | K17: =I17+J17 -> 35.24 | L17: =F17-(I17-AK17) -> -9.9975246 | M17: 3.7 | N17: 0 | O17: 0 | P17: 0 | Q17: =1.53*1.02 -> 1.5606 | R17: 2.56 | S17: 0 | T17: =M17-(Q17+R17+S17) -> -0.4206 | U17: 41 | V17: 0 | W17: =M17-N17-O17-P17-Q17-R17-S17-T17+U17+V17 -> 41 | X17: =W17-AO17 -> 41 | Y17: =Y16+(X17*1.9835) -> 2688.1884 | Z17: =Z16+X17*(26300/37500)*1.9835 -> 1885.3161 | AE17: 0 | AH17: 36 | AI17: =AI16-AH17 -> 4819 | AK17: =N17+O17+P17+Q17+R17+S17+T17+W17+AE17+AH17 -> 80.7 | AL17: =IF(L17<0,L17*-1,0) -> 9.9975246 | AM17: =AK17+AL17 -> 90.697525 | AN17: =AN16+(W17*1.9835) -> 2802.5467 | AO17: 0 | AV17: 0 | AW17: 43 | AX17: 19 | AZ17: =SUM(N17,P17:T17) -> 3.7
A18: =A17+1 -> 6 | B18: 6899.37 | C18: 281266 | D18: =C18-C17 -> -73 | E18: =C18-152000 -> 129266 | F18: =D18/$D$2 -> -36.80363 | G18: 43 | H18: 0.22 | I18: =G18+H18 -> 43.22 | J18: =IF(L18>0,L18,0) -> 0.67637005 | K18: =I18+J18 -> 43.89637 | L18: =F18-(I18-AK18) -> 0.67637005 | M18: 3.7 | N18: 0 | O18: 0 | P18: 0 | Q18: =1.53*1.02 -> 1.5606 | R18: 2.77 | S18: 0 | T18: =M18-(Q18+R18+S18) -> -0.6306 | U18: 41 | V18: 0 | W18: =M18-N18-O18-P18-Q18-R18-S18-T18+U18+V18 -> 41 | X18: =W18-AO18 -> 41 | Y18: =Y17+(X18*1.9835) -> 2769.5119 | Z18: =Z17+X18*(26300/37500)*1.9835 -> 1942.351 | AE18: 0 | AH18: 36 | AI18: =AI17-AH18 -> 4783 | AK18: =N18+O18+P18+Q18+R18+S18+T18+W18+AE18+AH18 -> 80.7 | AL18: =IF(L18<0,L18*-1,0) -> 0 | AM18: =AK18+AL18 -> 80.7 | AN18: =AN17+(W18*1.9835) -> 2883.8702 | AO18: 0 | AV18: 0 | AW18: 51 | AX18: 19 | AZ18: =SUM(N18,P18:T18) -> 3.7
A19: =A18+1 -> 7 | B19: 6899.36 | C19: 281229 | D19: =C19-C18 -> -37 | E19: =C19-152000 -> 129229 | F19: =D19/$D$2 -> -18.653895 | G19: 45 | H19: 0.27 | I19: =G19+H19 -> 45.27 | J19: =IF(L19>0,L19,0) -> 16.776105 | K19: =I19+J19 -> 62.046105 | L19: =F19-(I19-AK19) -> 16.776105 | M19: 3.7 | N19: 0 | O19: 0 | P19: 0 | Q19: =1.53*1.02 -> 1.5606 | R19: 2.53 | S19: 0 | T19: =M19-(Q19+R19+S19) -> -0.3906 | U19: 41 | V19: 0 | W19: =M19-N19-O19-P19-Q19-R19-S19-T19+U19+V19 -> 41 | X19: =W19-AO19 -> 41 | Y19: =Y18+(X19*1.9835) -> 2850.8354 | Z19: =Z18+X19*(26300/37500)*1.9835 -> 1999.3859 | AE19: 0 | AH19: 36 | AI19: =AI18-AH19 -> 4747 | AK19: =N19+O19+P19+Q19+R19+S19+T19+W19+AE19+AH19 -> 80.7 | AL19: =IF(L19<0,L19*-1,0) -> 0 | AM19: =AK19+AL19 -> 80.7 | AN19: =AN18+(W19*1.9835) -> 2965.1937 | AO19: 0 | AV19: 0 | AW19: 51 | AX19: 25 | AZ19: =SUM(N19,P19:T19) -> 3.7
A20: =A19+1 -> 8 | B20: 6899.41 | C20: 281412 | D20: =C20-C19 -> 183 | E20: =C20-152000 -> 129412 | F20: =D20/$D$2 -> 92.261155 | G20: 49 | H20: 0.52 | I20: =G20+H20 -> 49.52 | J20: =IF(L20>0,L20,0) -> 127.14115 | K20: =I20+J20 -> 176.66115 | L20: =F20-(I20-AK20) -> 127.14115 | M20: 3.4 | N20: 0 | O20: 0 | P20: 0 | Q20: =1.53*1.02 -> 1.5606 | R20: 2.34 | S20: 0 | T20: =M20-(Q20+R20+S20) -> -0.5006 | U20: 45 | V20: 0 | W20: =M20-N20-O20-P20-Q20-R20-S20-T20+U20+V20 -> 45 | X20: =W20-AO20 -> 45 | Y20: =Y19+(X20*1.9835) -> 2940.0929 | Z20: =Z19+X20*(26300/37500)*1.9835 -> 2061.9851 | AE20: 0 | AH20: 36 | AI20: =AI19-AH20 -> 4711 | AK20: =N20+O20+P20+Q20+R20+S20+T20+W20+AE20+AH20 -> 84.4 | AL20: =IF(L20<0,L20*-1,0) -> 0 | AM20: =AK20+AL20 -> 84.4 | AN20: =AN19+(W20*1.9835) -> 3054.4512 | AO20: 0 | AV20: 0.28 | AW20: 36 | AX20: 22 | AZ20: =SUM(N20,P20:T20) -> 3.4
A21: =A20+1 -> 9 | B21: 6899.39 | C21: 281339 | D21: =C21-C20 -> -73 | E21: =C21-152000 -> 129339 | F21: =D21/$D$2 -> -36.80363 | G21: 54 | H21: 0.53 | I21: =G21+H21 -> 54.53 | J21: =IF(L21>0,L21,0) -> 0 | K21: =I21+J21 -> 54.53 | L21: =F21-(I21-AK21) -> -4.2336299 | M21: 3.1 | N21: 0 | O21: 0 | P21: 0 | Q21: =1.53*1.02 -> 1.5606 | R21: 2.14 | S21: 0 | T21: =M21-(Q21+R21+S21) -> -0.6006 | U21: 48 | V21: 0 | W21: =M21-N21-O21-P21-Q21-R21-S21-T21+U21+V21 -> 48 | X21: =W21-AO21 -> 48 | Y21: =Y20+(X21*1.9835) -> 3035.3009 | Z21: =Z20+X21*(26300/37500)*1.9835 -> 2128.7577 | AE21: 0 | AH21: 36 | AI21: =AI20-AH21 -> 4675 | AK21: =N21+O21+P21+Q21+R21+S21+T21+W21+AE21+AH21 -> 87.1 | AL21: =IF(L21<0,L21*-1,0) -> 4.2336299 | AM21: =AK21+AL21 -> 91.33363 | AN21: =AN20+(W21*1.9835) -> 3149.6592 | AO21: 0 | AV21: 0.28 | AW21: 32 | AX21: 12 | AZ21: =SUM(N21,P21:T21) -> 3.1
A22: =A21+1 -> 10 | B22: 6899.37 | C22: 281266 | D22: =C22-C21 -> -73 | E22: =C22-152000 -> 129266 | F22: =D22/$D$2 -> -36.80363 | G22: 54 | H22: 0.34 | I22: =G22+H22 -> 54.34 | J22: =IF(L22>0,L22,0) -> 0 | K22: =I22+J22 -> 54.34 | L22: =F22-(I22-AK22) -> -3.8436299 | M22: 3.3 | N22: 0 | O22: 0 | P22: 0 | Q22: =1.53*1.02 -> 1.5606 | R22: 1.89 | S22: 0 | T22: =M22-(Q22+R22+S22) -> -0.1506 | U22: 48 | V22: 0 | W22: =M22-N22-O22-P22-Q22-R22-S22-T22+U22+V22 -> 48 | X22: =W22-AO22 -> 48 | Y22: =Y21+(X22*1.9835) -> 3130.5089 | Z22: =Z21+X22*(26300/37500)*1.9835 -> 2195.5302 | AE22: 0 | AH22: 36 | AI22: =AI21-AH22 -> 4639 | AK22: =N22+O22+P22+Q22+R22+S22+T22+W22+AE22+AH22 -> 87.3 | AL22: =IF(L22<0,L22*-1,0) -> 3.8436299 | AM22: =AK22+AL22 -> 91.14363 | AN22: =AN21+(W22*1.9835) -> 3244.8672 | AO22: 0 | AV22: 0 | AW22: 45 | AX22: 11 | AZ22: =SUM(N22,P22:T22) -> 3.3
A23: =A22+1 -> 11 | B23: 6899.35 | C23: 281192 | D23: =C23-C22 -> -74 | E23: =C23-152000 -> 129192 | F23: =D23/$D$2 -> -37.307789 | G23: 54 | H23: 0.34 | I23: =G23+H23 -> 54.34 | J23: =IF(L23>0,L23,0) -> 0 | K23: =I23+J23 -> 54.34 | L23: =F23-(I23-AK23) -> -4.3477893 | M23: 3.3 | N23: 0 | O23: 0 | P23: 0 | Q23: =1.53*1.02 -> 1.5606 | R23: 1.97 | S23: 0 | T23: =M23-(Q23+R23+S23) -> -0.2306 | U23: 48 | V23: 0 | W23: =M23-N23-O23-P23-Q23-R23-S23-T23+U23+V23 -> 48 | X23: =W23-AO23 -> 48 | Y23: =Y22+(X23*1.9835) -> 3225.7169 | Z23: =Z22+X23*(26300/37500)*1.9835 -> 2262.3028 | AE23: 0 | AH23: 36 | AI23: =AI22-AH23 -> 4603 | AK23: =N23+O23+P23+Q23+R23+S23+T23+W23+AE23+AH23 -> 87.3 | AL23: =IF(L23<0,L23*-1,0) -> 4.3477893 | AM23: =AK23+AL23 -> 91.647789 | AN23: =AN22+(W23*1.9835) -> 3340.0752 | AO23: 0 | AV23: 0 | AW23: 45 | AX23: 18 | AZ23: =SUM(N23,P23:T23) -> 3.3
A24: =A23+1 -> 12 | B24: 6899.33 | C24: 281119 | D24: =C24-C23 -> -73 | E24: =C24-152000 -> 129119 | F24: =D24/$D$2 -> -36.80363 | G24: 54 | H24: 0.32 | I24: =G24+H24 -> 54.32 | J24: =IF(L24>0,L24,0) -> 0 | K24: =I24+J24 -> 54.32 | L24: =F24-(I24-AK24) -> -4.0236299 | M24: 3.1 | N24: 0 | O24: 0 | P24: 0 | Q24: =1.53*1.02 -> 1.5606 | R24: 2.03 | S24: 0 | T24: =M24-(Q24+R24+S24) -> -0.4906 | U24: 48 | V24: 0 | W24: =M24-N24-O24-P24-Q24-R24-S24-T24+U24+V24 -> 48 | X24: =W24-AO24 -> 48 | Y24: =Y23+(X24*1.9835) -> 3320.9249 | Z24: =Z23+X24*(26300/37500)*1.9835 -> 2329.0753 | AE24: 0 | AH24: 36 | AI24: =AI23-AH24 -> 4567 | AK24: =N24+O24+P24+Q24+R24+S24+T24+W24+AE24+AH24 -> 87.1 | AL24: =IF(L24<0,L24*-1,0) -> 4.0236299 | AM24: =AK24+AL24 -> 91.12363 | AN24: =AN23+(W24*1.9835) -> 3435.2832 | AO24: 0 | AV24: 0 | AW24: 44 | AX24: 21 | AZ24: =SUM(N24,P24:T24) -> 3.1
A25: =A24+1 -> 13 | B25: 6899.31 | C25: 281045 | D25: =C25-C24 -> -74 | E25: =C25-152000 -> 129045 | F25: =D25/$D$2 -> -37.307789 | G25: 53 | H25: 0.47 | I25: =G25+H25 -> 53.47 | J25: =IF(L25>0,L25,0) -> 0 | K25: =I25+J25 -> 53.47 | L25: =F25-(I25-AK25) -> -3.6777893 | M25: 3.1 | N25: 0 | O25: 0 | P25: 0 | Q25: =1.53*1.02 -> 1.5606 | R25: 2.1 | S25: 0 | T25: =M25-(Q25+R25+S25) -> -0.5606 | U25: 48 | V25: 0 | W25: =M25-N25-O25-P25-Q25-R25-S25-T25+U25+V25 -> 48 | X25: =W25-AO25 -> 48 | Y25: =Y24+(X25*1.9835) -> 3416.1329 | Z25: =Z24+X25*(26300/37500)*1.9835 -> 2395.8478 | AE25: 0 | AH25: 36 | AI25: =AI24-AH25 -> 4531 | AK25: =N25+O25+P25+Q25+R25+S25+T25+W25+AE25+AH25 -> 87.1 | AL25: =IF(L25<0,L25*-1,0) -> 3.6777893 | AM25: =AK25+AL25 -> 90.777789 | AN25: =AN24+(W25*1.9835) -> 3530.4912 | AO25: 0 | AV25: 0 | AW25: 43 | AX25: 29 | AZ25: =SUM(N25,P25:T25) -> 3.1
... A41: =A40+1 -> 29 | B41: 6898.76 | C41: 279031 | D41: =C41-C40 -> -256 | E41: =C41-152000 -> 127031 | F41: =D41/$D$2 -> -129.06478 | G41: 28 | H41: 1.7 | I41: =G41+H41 -> 29.7 | J41: =IF(L41>0,L41,0) -> 14.335216 | K41: =I41+J41 -> 44.035216 | L41: =F41-(I41-AK41) -> 14.335216 | M41: 3.1 | N41: 0 | O41: 0 | P41: 0 | Q41: =1.53*1.02 -> 1.5606 | R41: 2.49 | S41: 0 | T41: =M41-(Q41+R41+S41) -> -0.9506 | U41: 134 | V41: 0 | W41: =M41-N41-O41-P41-Q41-R41-S41-T41+U41+V41 -> 134 | X41: =W41-AO41 -> 134 | Y41: =Y40+(X41*1.9835) -> 6200.9669 | Z41: =Z40+X41*(26300/37500)*1.9835 -> 4348.9448 | AE41: 0 | AH41: 36 | AI41: =AI40-AH41 -> 3955 | AK41: =N41+O41+P41+Q41+R41+S41+T41+W41+AE41+AH41 -> 173.1 | AL41: =IF(L41<0,L41*-1,0) -> 0 | AM41: =AK41+AL41 -> 173.1 | AN41: =AN40+(W41*1.9835) -> 6315.3252 | AO41: 0 | AV41: 0 | AW41: 34 | AX41: 8 | AZ41: =SUM(N41,P41:T41) -> 3.1
A42: 30 | B42: 6898.74 | C42: 278959 | D42: =C42-C41 -> -72 | E42: =C42-152000 -> 126959 | F42: =D42/$D$2 -> -36.299471 | G42: 28 | H42: 1.9 | I42: =G42+H42 -> 29.9 | J42: =IF(L42>0,L42,0) -> 14.900529 | K42: =I42+J42 -> 44.800529 | L42: =F42-(I42-AK42) -> 14.900529 | M42: 3.1 | N42: 0 | O42: 0 | P42: 0 | Q42: =1.53*1.02 -> 1.5606 | R42: 2.42 | S42: 0 | T42: =M42-(Q42+R42+S42) -> -0.8806 | U42: 42 | V42: 0 | W42: =M42-N42-O42-P42-Q42-R42-S42-T42+U42+V42 -> 42 | X42: =W42-AO42 -> 42 | Y42: =Y41+(X42*1.9835) -> 6284.2739 | Z42: =Z41+X42*(26300/37500)*1.9835 -> 4407.3707 | AE42: 0 | AH42: 36 | AI42: =AI41-AH42 -> 3919 | AK42: =N42+O42+P42+Q42+R42+S42+T42+W42+AE42+AH42 -> 81.1 | AL42: =IF(L42<0,L42*-1,0) -> 0 | AM42: =AK42+AL42 -> 81.1 | AN42: =AN41+(W42*1.9835) -> 6398.6322 | AO42: 0 | AV42: 0 | AW42: 38 | AX42: 9 | AZ42: =SUM(N42,P42:T42) -> 3.1
A43: 31 | B43: 6898.75 | C43: 278995 | D43: =C43-C42 -> 36 | E43: =C43-152000 -> 126995 | F43: =D43/$D$2 -> 18.149735 | G43: 28 | H43: 1.9 | I43: =G43+H43 -> 29.9 | J43: =IF(L43>0,L43,0) -> 27.349735 | K43: =I43+J43 -> 57.249735 | L43: =F43-(I43-AK43) -> 27.349735 | M43: 3.1 | N43: 0 | O43: 0 | P43: 0 | Q43: =1.53*1.02 -> 1.5606 | R43: 2.77 | S43: 0 | T43: =M43-(Q43+R43+S43) -> -1.2306 | U43: 0 | V43: 0 | W43: =M43-N43-O43-P43-Q43-R43-S43-T43+U43+V43 -> 0 | X43: =W43-AO43 -> 0 | Y43: =Y42+(X43*1.9835) -> 6284.2739 | Z43: =Z42+X43*(26300/37500)*1.9835 -> 4407.3707 | AE43: 0 | AH43: 36 | AI43: =AI42-AH43 -> 3883 | AK43: =N43+O43+P43+Q43+R43+S43+T43+W43+AE43+AH43 -> 39.1 | AL43: =IF(L43<0,L43*-1,0) -> 0 | AM43: =AK43+AL43 -> 39.1 | AN43: =AN42+(W43*1.9835) -> 6398.6322 | AO43: 0 | AV43: 0 | AW43: 36 | AX43: 9 | AZ43: =SUM(N43,P43:T43) -> 3.1
W44: =M44-N44-O44-Q44-R44-S44+U44+V44 -> 0 | X44: =N44-O44-P44-R44-S44-T44+V44+W44 -> 0 | AK44: =N44+O44+Q44+R44+S44+W44+AE44+AH44 -> 0
A45: MONTH / CFS | F45: =SUM(F13:F43) -> -1385.4298 | G45: =SUM(G13:G43) -> 1235 | H45: =SUM(H13:H43) -> 23.7 | I45: =SUM(I13:I43) -> 1258.7 | J45: =SUM(J13:J43) -> 650.2574 | K45: =SUM(K13:K43) -> 1908.9574 | L45: =SUM(L13:L43) -> 579.2702 | M45: =SUM(M13:M44) -> 99.4 | N45: =SUM(N13:N43) -> 0 | O45: =SUM(O13:O43) -> 0 | Q45: =SUM(Q13:Q43) -> 48.3786 | R45: =SUM(R13:R43) -> 69.95 | S45: =SUM(S13:S43) -> 0 | T45: =SUM(T13:T43) -> -18.9286 | U45: =SUM(U13:U43) -> 2008 | V45: =SUM(V13:V43) -> 0 | W45: =SUM(W13:W43) -> 2008 | X45: =SUM(X13:X43) -> 2008 | AH45: =SUM(AH13:AH44) -> 1116 | AJ45: =SUM(AJ14:AJ43) -> 0 | AK45: =SUM(AK13:AK44) -> 3223.4 | AL45: =SUM(AL13:AL43) -> 70.987194 | AM45: =SUM(AM13:AM43) -> 3294.3872 | AO45: =SUM(AO13:AO43) -> 0 | AV45: =SUM(AV13:AV43) -> 1.5 | AW45: =AVERAGE(AW13:AW43) -> 38.032258 | AX45: =AVERAGE(AX13:AX43) -> 14.935484 | AY45: Avg | AZ45: =SUM(AZ13:AZ43) -> 99.4
A46: MONTH / AF | D46: =SUM(D13:D43) -> -2748 | F46: =F45*$D$2 -> -2748 | G46: =G45*$D$2 -> 2449.6225 | H46: =H45*$D$2 -> 47.00895 | I46: =I45*$D$2 -> 2496.6314 | J46: =J45*$D$2 -> 1289.7856 | K46: =K45*$D$2 -> 3786.417 | L46: =L45*$D$2 -> 1148.9824 | M46: =M45*$D$2 -> 197.1599 | ... O46: =O45*$D$2 -> 0 | Q46: =Q45*$D$2 -> 95.958953 | R46: =R45*$D$2 -> 138.74582 | S46: =S45*$D$2 -> 0 | T46: =T45*$D$2 -> -37.544878 | U46: =U45*$D$2 -> 3982.868 | V46: =V45*$D$2 -> 0 | W46: =W45*$D$2 -> 3982.868 | X46: =X45*$D$2 -> 3982.868 | AH46: =AH45*$D$2 -> 2213.586 | AJ46: =AJ45*$D$2 -> 0 | AK46: =AK45*$D$2 -> 6393.6139 | AL46: =AL45*$D$2 -> 140.8031 | AM46: =AM45*$D$2 -> 6534.417 | AO46: =AO45*$D$2 -> 0 | AW46: =MAX(AW13:AW43) -> 53 | AX46: =MAX(AX13:AX43) -> 29 | AY46: HI | AZ46: =AZ45*$D$2 -> 197.1599
A48: SEASON / CFS | AW48: =MIN(AW13:AW43) -> 17 | AX48: =MIN(AX13:AX43) -> -4 | AY48: LO
A49: SEASON / AF
A51: YTD / CFS | F51: =F11+F45 -> -2927.149 | G51: =G11+G45 -> 2860 | H51: =H11+H45 -> 23.7 | I51: =I11+I45 -> 2883.7 | J51: =J11+J45 -> 851.69208 | K51: =K11+K45 -> 3735.3921 | L51: =L11+L45 -> 219.65102 | M51: =M11+M45 -> 402.2 | N51: =N11+N45 -> 0 | O51: 0 | Q51: =Q11+Q45 -> 96.7266 | R51: =R11+R45 -> 143.22 | S51: =S11+S45 -> 0 | T51: =T11+T45 -> -25.9906 | U51: =U11+U45 -> 3357 | V51: =V11+V45 -> 76.3 | W51: =W11+W45 -> 3621.544 | X51: =X11+X45 -> 3168.2752 | AH51: =AH11+AH45 -> 2195 | AI51: =AI43 -> 3883 | AJ51: =AJ12+AJ45 -> 0 | AK51: =AK11+AK45 -> 6030.5 | AL51: =AL11+AL45 -> 632.04106 | AM51: =AM11+AM45 -> 6662.5411 | AO51: =AO11+AO45 -> 453.2688 | AV51: =AV11+AV45 -> 2.35 | AZ51: =AZ11+AZ45 -> 213.956
A52: YTD / AF | D52: =D11+D46 -> -5806 | E52: =E43 -> 126995 | F52: =F51*$D$2 -> -5806 | G52: =G51*$D$2 -> 5672.81 | H52: =H51*$D$2 -> 47.00895 | I52: =I51*$D$2 -> 5719.8189 | J52: =J51*$D$2 -> 1689.3312 | K52: =K51*$D$2 -> 7409.1502 | L52: =L51*$D$2 -> 435.6778 | M52: =M51*$D$2 -> 797.7637 | ... O52: =O51*$D$2 -> 0 | Q52: =Q51*$D$2 -> 191.85721 | R52: =R51*$D$2 -> 284.07687 | S52: =S51*$D$2 -> 0 | T52: =T51*$D$2 -> -51.552355 | U52: =U51*$D$2 -> 6658.6095 | V52: =V51*$D$2 -> 151.34105 | W52: =W51*$D$2 -> 7183.3325 | X52: =X51*$D$2 -> 6284.2739 | AH52: =AH51*$D$2 -> 4353.7825 | AI52: =AI51*$D$2 -> 7701.9305 | AJ52: =AJ51*$D$2 -> 0 | AK52: =AK51*$D$2 -> 11961.497 | AL52: =AL51*$D$2 -> 1253.6535 | AM52: =AM51*$D$2 -> 13215.15 | AN52: =AN43 -> 6398.6322 | AO52: =AO51*$D$2 -> 899.05866 | AZ52: =AZ51*$D$2 -> 424.38173

Sheet JAN
K1: MCPHEE RESERVOIR INFLOW/OUTFLOW TABULATION
A2: AF/cfs CONVERT FACTOR | D2: 1.9835 | K2: JANUARY "2009"
D4: RESERVOIR | W4: INFLOW/OUTFLOW (CFS) | AP4: ADJUSTMENTS | AW4: WEATHER
A5: DATE | B5: RESERV | C5: RESERV | D5: AC FT | E5: ACTIVE | F5: CONV TO | G5: DOLORES | H5: LOST | I5: RECORD | J5: CALC | K5: TOTAL | L5: CALC | M5: DOLORES TUNNEL | U5: LONE | V5: U | W5: TOTAL | X5: TOTAL | Y5: TOTAL | Z5: TOTAl | AA5: MVI | AB5: MVI | AC5: TO EX & | AD5: MVI | AE5: DV CR | AF5: D/S SENIOR | AH5: BELOW | AI5: FISH | AJ5: SPILL | AK5: RECORD | AL5: CALC | AM5: TOTAL | AN5: NAR | AO5: MVI | AP5: MVI | AQ5: MVI | AR5: DIST. | AS5: U/S | AT5: TOTTEN | AU5: UTES | AV5: RAIN | AW5: MAX | AX5: MIN | AZ5: TOTAL
A6: JAN | B6: ELEV | D6: CHANGE | E6: CAP | F6: CFS | G6: RIVER | H6: CAN | I6: INFLOW | J6: INFLOW | K6: INFLOW | L6: INF/OTF | M6: TOT DIV | N6: WET | O6: UTE | P6: QUEST | Q6: MWC | R6: CTZ | S6: CTZ & | T6: F-BAY | U6: PINE | V6: LAT | W6: MVI | X6: MVI | Y6: MVI | Z6: MVI | AA6: CALL | AB6: APR- | AC6: U/S EX | AD6: PROJ | AE6: CANAL | AF6: MVIC | AG6: PROJ | AH6: MCP | AI6: LEFT | AK6: OTF | AL6: OTF | AM6: OTF | AN6: CALL | AO6: STOCK | AP6: STORED | AQ6: STORED | AR6: CLASS | AS6: USERS | AT6: (FRESH | AU6: FROM | AW6: TMP | AX6: TMP | AZ6: TUNNEL
N7: LAND | O7: F&R | S7: UTE | T7: SPILL | W7: 153400 | X7: IRRIG. | Y7: IRRIG. | Z7: 105500 | AB7: JUNE | AF7: 1.7 | AG7: 1.3 | AI7: 31798 | AP7: Apr - Jun | AQ7: EVAP | AR7: "B" | AS7: EXCH | AT7: WATER) | AU7: MVIC | AZ7: Outflow
C8: AC. Ft. | E8: AC FT | G8: CFS | H8: CFS | I8: CFS | J8: CFS | K8: CFS | L8: CFS | M8: CFS | N8: CFS | O8: CFS | P8: CFS | Q8: CFS | R8: CFS | S8: PROJ | T8: CFS | U8: CFS | V8: CFS | W8: CFS | X8: 150400 | Y8: 150400 | Z8: Ac. Ft. | AA8: CFS | AB8: 72000 | AC8: CFS | AD8: CFS | AE8: CFS | AF8: CFS | AG8: CFS | AH8: CFS | AI8: CFS | AJ8: CFS | AK8: CFS | AL8: CFS | AM8: CFS | AN8: AC FT | AO8: CFS | AP8: CFS | AQ8: AC.FT. | AR8: CFS | AS8: CFS | AT8: CFS | AU8: CFS | AZ8: CFS
N9: 1.03 | O9: 1.05 | P9: 1.02 | Q9: 1.02 | R9: 1.04 | S9: CFS | X9: CFS | Y9: Ac. Ft. | AB9: Ac. Ft.
A10: SEASON BAL
A11: YTD | B11: =DEC!B43 -> 6898.75 | C11: =DEC!C43 -> 278995 | D11: =DEC!D52 -> -5806 | E11: =DEC!E52 -> 126995 | F11: =DEC!F51 -> -2927.149 | G11: =DEC!G51 -> 2860 | H11: =DEC!H51 -> 23.7 | I11: =DEC!I51 -> 2883.7 | J11: =DEC!J51 -> 851.69208 | K11: =DEC!K51 -> 3735.3921 | L11: =DEC!L51 -> 219.65102 | M11: =DEC!M51 -> 402.2 | ... O11: =DEC!O51 -> 0 | Q11: =DEC!Q51 -> 96.7266 | R11: =DEC!R51 -> 143.22 | S11: =DEC!S51 -> 0 | T11: =DEC!T51 -> -25.9906 | U11: =DEC!U51 -> 3357 | V11: =DEC!V51 -> 76.3 | W11: =DEC!W51 -> 3621.544 | X11: =DEC!X51 -> 3168.2752 | Y11: =DEC!Y43 -> 6284.2739 | Z11: =DEC!Z43 -> 4407.3707 | AH11: =DEC!AH51 -> 2195 | AI11: =DEC!AI51 -> 3883 | AJ11: =DEC!AJ51 -> 0 | AK11: =DEC!AK51 -> 6030.5 | AL11: =DEC!AL51 -> 632.04106 | AM11: =DEC!AM51 -> 6662.5411 | AN11: =DEC!AN52 -> 6398.6322 | AO11: =DEC!AO51 -> 453.2688 | AV11: =DEC!AV51 -> 2.35 | AZ11: =DEC!AZ51 -> 213.956
A13: 1 | B13: 6898.76 | C13: 279031 | D13: =C13-C11 -> 36 | E13: =C13-152000 -> 127031 | F13: =D13/$D$2 -> 18.149735 | G13: 28 | H13: 1.9 | I13: =G13+H13 -> 29.9 | J13: =IF(L13>0,L13,0) -> 27.349735 | K13: =I13+J13 -> 57.249735 | L13: =F13-(I13-AK13) -> 27.349735 | M13: 3.1 | N13: 0 | O13: 0 | P13: 0 | Q13: =1.52*1.02 -> 1.5504 | R13: 2.49 | S13: 0 | T13: =M13-(Q13+R13+S13) -> -0.9404 | U13: 0 | V13: 0 | W13: =M13-N13-O13-P13-Q13-R13-S13-T13+U13+V13 -> 0 | X13: =W13-AO13 -> 0 | Y13: =Y11+(X13*1.9835) -> 6284.2739 | Z13: =Z11+X13*(26300/37500)*1.9835 -> 4407.3707 | AE13: 0 | AH13: 36 | AI13: =AI11-AH13 -> 3847 | AK13: =N13+O13+P13+Q13+R13+S13+T13+W13+AE13+AH13 -> 39.1 | AL13: =IF(L13<0,L13*-1,0) -> 0 | AM13: =AK13+AL13 -> 39.1 | AN13: =AN11+(W13*1.9835) -> 6398.6322 | AO13: 0 | AV13: 0 | AW13: 35 | AX13: 4 | AZ13: =SUM(N13,P13:T13) -> 3.1
A14: =A13+1 -> 2 | B14: 6898.78 | C14: 279104 | D14: =C14-C13 -> 73 | E14: =C14-152000 -> 127104 | F14: =D14/$D$2 -> 36.80363 | G14: 28 | H14: 1.9 | I14: =G14+H14 -> 29.9 | J14: =IF(L14>0,L14,0) -> 46.00363 | K14: =I14+J14 -> 75.90363 | L14: =F14-(I14-AK14) -> 46.00363 | M14: 3.1 | N14: 0 | O14: 0 | P14: 0 | Q14: =1.52*1.02 -> 1.5504 | R14: 2.51 | S14: 0 | T14: =M14-(Q14+R14+S14) -> -0.9604 | U14: 0 | V14: 0 | W14: =M14-N14-O14-P14-Q14-R14-S14-T14+U14+V14 -> 0 | X14: =W14-AO14 -> 0 | Y14: =Y13+(X14*1.9835) -> 6284.2739 | Z14: =Z13+X14*(26300/37500)*1.9835 -> 4407.3707 | AE14: 0 | AH14: 36 | AI14: =AI13-AH14 -> 3811 | AK14: =N14+O14+P14+Q14+R14+S14+T14+W14+AE14+AH14 -> 39.1 | AL14: =IF(L14<0,L14*-1,0) -> 0 | AM14: =AK14+AL14 -> 39.1 | AN14: =AN13+(W14*1.9835) -> 6398.6322 | AO14: 0 | AV14: 0 | AW14: 41 | AX14: 6 | AZ14: =SUM(N14,P14:T14) -> 3.1
A15: =A14+1 -> 3 | B15: 6898.8 | C15: 279177 | D15: =C15-C14 -> 73 | E15: =C15-152000 -> 127177 | F15: =D15/$D$2 -> 36.80363 | G15: 30 | H15: 1.6 | I15: =G15+H15 -> 31.6 | J15: =IF(L15>0,L15,0) -> 44.30363 | K15: =I15+J15 -> 75.90363 | L15: =F15-(I15-AK15) -> 44.30363 | M15: 3.1 | N15: 0 | O15: 0 | P15: 0 | Q15: =1.52*1.02 -> 1.5504 | R15: 2.62 | S15: 0 | T15: =M15-(Q15+R15+S15) -> -1.0704 | U15: 0 | V15: 0 | W15: =M15-N15-O15-P15-Q15-R15-S15-T15+U15+V15 -> 0 | X15: =W15-AO15 -> 0 | Y15: =Y14+(X15*1.9835) -> 6284.2739 | Z15: =Z14+X15*(26300/37500)*1.9835 -> 4407.3707 | AE15: 0 | AH15: 36 | AI15: =AI14-AH15 -> 3775 | AK15: =N15+O15+P15+Q15+R15+S15+T15+W15+AE15+AH15 -> 39.1 | AL15: =IF(L15<0,L15*-1,0) -> 0 | AM15: =AK15+AL15 -> 39.1 | AN15: =AN14+(W15*1.9835) -> 6398.6322 | AO15: 0 | AV15: 0.02 | AW15: 37 | AX15: 17 | AZ15: =SUM(N15,P15:T15) -> 3.1
A16: =A15+1 -> 4 | B16: 6898.81 | C16: 279214 | D16: =C16-C15 -> 37 | E16: =C16-152000 -> 127214 | F16: =D16/$D$2 -> 18.653895 | G16: 30 | H16: 1.5 | I16: =G16+H16 -> 31.5 | J16: =IF(L16>0,L16,0) -> 26.253895 | K16: =I16+J16 -> 57.753895 | L16: =F16-(I16-AK16) -> 26.253895 | M16: 3.1 | N16: 0 | O16: 0 | P16: 0 | Q16: =1.52*1.02 -> 1.5504 | R16: 2.45 | S16: 0 | T16: =M16-(Q16+R16+S16) -> -0.9004 | U16: 0 | V16: 0 | W16: =M16-N16-O16-P16-Q16-R16-S16-T16+U16+V16 -> 0 | X16: =W16-AO16 -> 0 | Y16: =Y15+(X16*1.9835) -> 6284.2739 | Z16: =Z15+X16*(26300/37500)*1.9835 -> 4407.3707 | AE16: 0 | AH16: 36 | AI16: =AI15-AH16 -> 3739 | AK16: =N16+O16+P16+Q16+R16+S16+T16+W16+AE16+AH16 -> 39.1 | AL16: =IF(L16<0,L16*-1,0) -> 0 | AM16: =AK16+AL16 -> 39.1 | AN16: =AN15+(W16*1.9835) -> 6398.6322 | AO16: 0 | AV16: 0.02 | AW16: 31 | AX16: 19 | AZ16: =SUM(N16,P16:T16) -> 3.1
A17: =A16+1 -> 5 | B17: 6898.82 | C17: 279250 | D17: =C17-C16 -> 36 | E17: =C17-152000 -> 127250 | F17: =D17/$D$2 -> 18.149735 | G17: 30 | H17: 1.3 | I17: =G17+H17 -> 31.3 | J17: =IF(L17>0,L17,0) -> 25.149735 | K17: =I17+J17 -> 56.449735 | L17: =F17-(I17-AK17) -> 25.149735 | M17: 3.3 | N17: 0 | O17: 0 | P17: 0 | Q17: =1.52*1.02 -> 1.5504 | R17: 2.46 | S17: 0 | T17: =M17-(Q17+R17+S17) -> -0.7104 | U17: 0 | V17: 0 | W17: =M17-N17-O17-P17-Q17-R17-S17-T17+U17+V17 -> 0 | X17: =W17-AO17 -> 0 | Y17: =Y16+(X17*1.9835) -> 6284.2739 | Z17: =Z16+X17*(26300/37500)*1.9835 -> 4407.3707 | AE17: 0 | AH17: 35 | AI17: =AI16-AH17 -> 3704 | AK17: =N17+O17+P17+Q17+R17+S17+T17+W17+AE17+AH17 -> 38.3 | AL17: =IF(L17<0,L17*-1,0) -> 0 | AM17: =AK17+AL17 -> 38.3 | AN17: =AN16+(W17*1.9835) -> 6398.6322 | AO17: 0 | AV17: 0 | AW17: 28 | AX17: 8 | AZ17: =SUM(N17,P17:T17) -> 3.3
A18: =A17+1 -> 6 | B18: 6898.83 | C18: 279287 | D18: =C18-C17 -> 37 | E18: =C18-152000 -> 127287 | F18: =D18/$D$2 -> 18.653895 | G18: 30 | H18: 1 | I18: =G18+H18 -> 31 | J18: =IF(L18>0,L18,0) -> 24.953895 | K18: =I18+J18 -> 55.953895 | L18: =F18-(I18-AK18) -> 24.953895 | M18: 3.3 | N18: 0 | O18: 0 | P18: 0 | Q18: =1.52*1.02 -> 1.5504 | R18: 2.37 | S18: 0 | T18: =M18-(Q18+R18+S18) -> -0.6204 | U18: 0 | V18: 0 | W18: =M18-N18-O18-P18-Q18-R18-S18-T18+U18+V18 -> 0 | X18: =W18-AO18 -> 0 | Y18: =Y17+(X18*1.9835) -> 6284.2739 | Z18: =Z17+X18*(26300/37500)*1.9835 -> 4407.3707 | AE18: 0 | AH18: 34 | AI18: =AI17-AH18 -> 3670 | AK18: =N18+O18+P18+Q18+R18+S18+T18+W18+AE18+AH18 -> 37.3 | AL18: =IF(L18<0,L18*-1,0) -> 0 | AM18: =AK18+AL18 -> 37.3 | AN18: =AN17+(W18*1.9835) -> 6398.6322 | AO18: 0 | AV18: 0 | AW18: 33 | AX18: -2 | AZ18: =SUM(N18,P18:T18) -> 3.3
A19: =A18+1 -> 7 | B19: 6898.83 | C19: 279287 | D19: =C19-C18 -> 0 | E19: =C19-152000 -> 127287 | F19: =D19/$D$2 -> 0 | G19: 29 | H19: 0.88 | I19: =G19+H19 -> 29.88 | J19: =IF(L19>0,L19,0) -> 38.42 | K19: =I19+J19 -> 68.3 | L19: =F19-(I19-AK19) -> 38.42 | M19: 3.3 | N19: 0 | O19: 0 | P19: 0 | Q19: =1.52*1.02 -> 1.5504 | R19: 2.25 | S19: 0 | T19: =M19-(Q19+R19+S19) -> -0.5004 | U19: 31 | V19: 0 | W19: =M19-N19-O19-P19-Q19-R19-S19-T19+U19+V19 -> 31 | X19: =W19-AO19 -> 31 | Y19: =Y18+(X19*1.9835) -> 6345.7624 | Z19: =Z18+X19*(26300/37500)*1.9835 -> 4450.4947 | AE19: 0 | AH19: 34 | AI19: =AI18-AH19 -> 3636 | AK19: =N19+O19+P19+Q19+R19+S19+T19+W19+AE19+AH19 -> 68.3 | AL19: =IF(L19<0,L19*-1,0) -> 0 | AM19: =AK19+AL19 -> 68.3 | AN19: =AN18+(W19*1.9835) -> 6460.1207 | AO19: 0 | AV19: 0 | AW19: 35 | AX19: -4 | AZ19: =SUM(N19,P19:T19) -> 3.3
A20: =A19+1 -> 8 | B20: 6898.81 | C20: 279214 | D20: =C20-C19 -> -73 | E20: =C20-152000 -> 127214 | F20: =D20/$D$2 -> -36.80363 | G20: 28 | H20: 0.83 | I20: =G20+H20 -> 28.83 | J20: =IF(L20>0,L20,0) -> 18.76637 | K20: =I20+J20 -> 47.59637 | L20: =F20-(I20-AK20) -> 18.76637 | M20: 3.4 | N20: 0 | O20: 0 | P20: 0 | Q20: =1.52*1.02 -> 1.5504 | R20: 2.42 | S20: 0 | T20: =M20-(Q20+R20+S20) -> -0.5704 | U20: 47 | V20: 0 | W20: =M20-N20-O20-P20-Q20-R20-S20-T20+U20+V20 -> 47 | X20: =W20-AO20 -> 47 | Y20: =Y19+(X20*1.9835) -> 6438.9869 | Z20: =Z19+X20*(26300/37500)*1.9835 -> 4515.8761 | AE20: 0 | AH20: 34 | AI20: =AI19-AH20 -> 3602 | AK20: =N20+O20+P20+Q20+R20+S20+T20+W20+AE20+AH20 -> 84.4 | AL20: =IF(L20<0,L20*-1,0) -> 0 | AM20: =AK20+AL20 -> 84.4 | AN20: =AN19+(W20*1.9835) -> 6553.3452 | AO20: 0 | AV20: 0 | AW20: 34 | AX20: 5 | AZ20: =SUM(N20,P20:T20) -> 3.4
A21: =A20+1 -> 9 | B21: 6898.8 | C21: 279177 | D21: =C21-C20 -> -37 | E21: =C21-152000 -> 127177 | F21: =D21/$D$2 -> -18.653895 | G21: 27 | H21: 0.75 | I21: =G21+H21 -> 27.75 | J21: =IF(L21>0,L21,0) -> 35.996105 | K21: =I21+J21 -> 63.746105 | L21: =F21-(I21-AK21) -> 35.996105 | M21: 3.4 | N21: 0 | O21: 0 | P21: 0 | Q21: =1.52*1.02 -> 1.5504 | R21: 2.57 | S21: 0 | T21: =M21-(Q21+R21+S21) -> -0.7204 | U21: 45 | V21: 0 | W21: =M21-N21-O21-P21-Q21-R21-S21-T21+U21+V21 -> 45 | X21: =W21-AO21 -> 45 | Y21: =Y20+(X21*1.9835) -> 6528.2444 | Z21: =Z20+X21*(26300/37500)*1.9835 -> 4578.4754 | AE21: 0 | AH21: 34 | AI21: =AI20-AH21 -> 3568 | AK21: =N21+O21+P21+Q21+R21+S21+T21+W21+AE21+AH21 -> 82.4 | AL21: =IF(L21<0,L21*-1,0) -> 0 | AM21: =AK21+AL21 -> 82.4 | AN21: =AN20+(W21*1.9835) -> 6642.6027 | AO21: 0 | AV21: 0 | AW21: 35 | AX21: 6 | AZ21: =SUM(N21,P21:T21) -> 3.4
A22: =A21+1 -> 10 | B22: 6898.79 | C22: 279141 | D22: =C22-C21 -> -36 | E22: =C22-152000 -> 127141 | F22: =D22/$D$2 -> -18.149735 | G22: 26 | H22: 0.75 | I22: =G22+H22 -> 26.75 | J22: =IF(L22>0,L22,0) -> 37.500265 | K22: =I22+J22 -> 64.250265 | L22: =F22-(I22-AK22) -> 37.500265 | M22: 3.4 | N22: 0 | O22: 0 | P22: 0 | Q22: =1.52*1.02 -> 1.5504 | R22: 2.38 | S22: 0 | T22: =M22-(Q22+R22+S22) -> -0.5304 | U22: 45 | V22: 0 | W22: =M22-N22-O22-P22-Q22-R22-S22-T22+U22+V22 -> 45 | X22: =W22-AO22 -> 45 | Y22: =Y21+(X22*1.9835) -> 6617.5019 | Z22: =Z21+X22*(26300/37500)*1.9835 -> 4641.0746 | AE22: 0 | AH22: 34 | AI22: =AI21-AH22 -> 3534 | AK22: =N22+O22+P22+Q22+R22+S22+T22+W22+AE22+AH22 -> 82.4 | AL22: =IF(L22<0,L22*-1,0) -> 0 | AM22: =AK22+AL22 -> 82.4 | AN22: =AN21+(W22*1.9835) -> 6731.8602 | AO22: 0 | AV22: 0 | AW22: 38 | AX22: 7 | AZ22: =SUM(N22,P22:T22) -> 3.4
A23: =A22+1 -> 11 | B23: 6898.77 | C23: 279068 | D23: =C23-C22 -> -73 | E23: =C23-152000 -> 127068 | F23: =D23/$D$2 -> -36.80363 | G23: 14 | H23: 0.66 | I23: =G23+H23 -> 14.66 | J23: =IF(L23>0,L23,0) -> 30.93637 | K23: =I23+J23 -> 45.59637 | L23: =F23-(I23-AK23) -> 30.93637 | M23: 3.4 | N23: 0 | O23: 0 | P23: 0 | Q23: =1.52*1.02 -> 1.5504 | R23: 2.31 | S23: 0 | T23: =M23-(Q23+R23+S23) -> -0.4604 | U23: 45 | V23: 0 | W23: =M23-N23-O23-P23-Q23-R23-S23-T23+U23+V23 -> 45 | X23: =W23-AO23 -> 45 | Y23: =Y22+(X23*1.9835) -> 6706.7594 | Z23: =Z22+X23*(26300/37500)*1.9835 -> 4703.6739 | AE23: 0 | AH23: 34 | AI23: =AI22-AH23 -> 3500 | AK23: =N23+O23+P23+Q23+R23+S23+T23+W23+AE23+AH23 -> 82.4 | AL23: =IF(L23<0,L23*-1,0) -> 0 | AM23: =AK23+AL23 -> 82.4 | AN23: =AN22+(W23*1.9835) -> 6821.1177 | AO23: 0 | AV23: 0 | AW23: 39 | AX23: 8 | AZ23: =SUM(N23,P23:T23) -> 3.4
A24: =A23+1 -> 12 | B24: 6898.74 | C24: 278959 | D24: =C24-C23 -> -109 | E24: =C24-152000 -> 126959 | F24: =D24/$D$2 -> -54.953365 | G24: 11 | H24: 0.61 | I24: =G24+H24 -> 11.61 | J24: =IF(L24>0,L24,0) -> 21.836635 | K24: =I24+J24 -> 33.446635 | L24: =F24-(I24-AK24) -> 21.836635 | M24: 3.4 | N24: 0 | O24: 0 | P24: 0 | Q24: =1.52*1.02 -> 1.5504 | R24: 2.27 | S24: 0 | T24: =M24-(Q24+R24+S24) -> -0.4204 | U24: 51 | V24: 0 | W24: =M24-N24-O24-P24-Q24-R24-S24-T24+U24+V24 -> 51 | X24: =W24-AO24 -> 51 | Y24: =Y23+(X24*1.9835) -> 6807.9179 | Z24: =Z23+X24*(26300/37500)*1.9835 -> 4774.6197 | AE24: 0 | AH24: 34 | AI24: =AI23-AH24 -> 3466 | AK24: =N24+O24+P24+Q24+R24+S24+T24+W24+AE24+AH24 -> 88.4 | AL24: =IF(L24<0,L24*-1,0) -> 0 | AM24: =AK24+AL24 -> 88.4 | AN24: =AN23+(W24*1.9835) -> 6922.2762 | AO24: 0 | AV24: 0 | AW24: 42 | AX24: 1 | AZ24: =SUM(N24,P24:T24) -> 3.4
