Workbook

Sheet NOV
K1: MCPHEE RESERVOIR INFLOW/OUTFLOW TABULATION
A2: AF/cfs CONVERT FACTOR | D2: 1.9835 | L2: NOVEMBER "2004"
D4: RESERVOIR | S4: INFLOW/OUTFLOW (CFS) | AG4: WEATHER | AK4: ADJUSTMENTS
A5: DATE | B5: RESERV | C5: RESERV | D5: AC FT | E5: ACTIVE | F5: CONV TO | G5: DOLORES | H5: LOST | I5: RECORD | J5: CALC | K5: TOTAL | L5: CALC | M5: DOLORES TUNNEL | S5: LONE | T5: U | U5: TOTAL | V5: MVI | W5: MVI | X5: DV CR | Y5: D/S SENIOR | AA5: BELOW | AB5: FISH | AC5: RECORD | AD5: CALC | AE5: TOTAL | AF5: RAIN | AG5: MAX | AH5: MIN | AI5: NAR. | AJ5: MVI | AK5: MVI | AL5: MVI | AM5: U/S | AN5: TOTTEN
A6: NOV | B6: ELEV | C6: AC FT | D6: CHANGE | E6: CAP | F6: CFS | G6: RIVER | H6: CAN | I6: INFLOW | J6: INFLOW | K6: INFLOW | L6: INF/OTF | M6: TOT DIV | N6: WET | O6: UTE | P6: MWC | Q6: CTZ | R6: CTZ & | S6: PINE | T6: LAT | U6: MVI | V6: CALL | W6: PROJ & | X6: CANAL | Y6: MVIC | Z6: PROJ | AA6: MCP | AB6: LEFT | AC6: OTF | AD6: OTF | AE6: OTF | AG6: TMP | AH6: TMP | AI6: CALL | AJ6: STOCK | AK6: STORED | AL6: STORED | AM6: USERS | AN6: (FRESH
E7: AC FT | N7: LAND | O7: F&R | R7: UTE | W7: TO EX & | AI7: AC.FT. | AJ7: CFS | AK7: Apr-Jun | AL7: EVAP | AM7: EXCH | AN7: WATER)
N8: 1.03 | O8: 1.05 | P8: 1.02 | Q8: 1.04 | R8: PROJ | W8: U/S EX | AL8: AC.FT
A9: SEASON BAL
A10: YTD | B10: 6876.98 | C10: 207246 | AB10: 4051 | AJ10: 352
A12: 1 | B12: 6877.03 | C12: 207391 | D12: =C12-C10 -> 145 | E12: =C12-152000 -> 55391 | F12: =D12/$D$2 -> 73.103101 | G12: 145 | H12: 0 | I12: =G12+H12 -> 145 | J12: =IF(L12>0,L12,0) -> 44.503101 | K12: =I12+J12 -> 189.5031 | L12: =F12-(I12-AC12) -> 44.503101 | M12: 5.4 | N12: 0 | O12: 0 | P12: =1.33*1.02 -> 1.3566 | Q12: =2.75*1.04 -> 2.86 | R12: 0 | S12: 80 | T12: 0 | U12: =M12-N12-O12-P12-Q12-R16+S12+T12 -> 81.1834 | X12: 0 | AA12: 31 | AB12: =AB10-AA12 -> 4020 | AC12: =N12+O12+P12+Q12+R16+U12+X12+AA12 -> 116.4 | AD12: =IF(L12<0,L12*-1,0) -> 0 | AE12: =AC12+AD12 -> 116.4 | AF12: 0 | AG12: 38 | AH12: 25 | AI12: =AI11+(U12*1.9835) -> 161.02727 | AJ12: 0
A13: =A12+1 -> 2 | B13: 6876.93 | C13: 207101 | D13: =C13-C12 -> -290 | E13: =C13-152000 -> 55101 | F13: =D13/$D$2 -> -146.2062 | G13: 113 | H13: 0 | I13: =G13+H13 -> 113 | J13: =IF(L13>0,L13,0) -> 0 | K13: =I13+J13 -> 113 | L13: =F13-(I13-AC13) -> -103.2062 | M13: 5 | N13: 0 | O13: 0 | P13: =1.33*1.02 -> 1.3566 | Q13: =2.07*1.04 -> 2.1528 | R13: 0 | S13: 123 | T13: 0 | U13: =M13-N13-O13-P13-Q13-R13+S13+T13 -> 124.4906 | X13: 0 | AA13: 28 | AB13: =AB12-AA13 -> 3992 | AC13: =N13+O13+P13+Q13+R17+U13+X13+AA13 -> 156 | AD13: =IF(L13<0,L13*-1,0) -> 103.2062 | AE13: =AC13+AD13 -> 259.2062 | AF13: 0 | AG13: 49 | AH13: 21 | AI13: =AI12+(U13*1.9835) -> 407.95438 | AJ13: 0
A14: =A13+1 -> 3 | B14: 6876.93 | C14: 207101 | D14: =C14-C13 -> 0 | E14: =C14-152000 -> 55101 | F14: =D14/$D$2 -> 0 | G14: 117 | H14: 0 | I14: =G14+H14 -> 117 | J14: =IF(L14>0,L14,0) -> 27.8 | K14: =I14+J14 -> 144.8 | L14: =F14-(I14-AC14) -> 27.8 | M14: 4.8 | N14: 0 | O14: 0 | P14: =1.33*1.02 -> 1.3566 | Q14: =2.73*1.04 -> 2.8392 | R14: 0 | S14: 112 | T14: 0 | U14: =M14-N14-O14-P14-Q14-R14+S14+T14 -> 112.6042 | X14: 0 | AA14: 28 | AB14: =AB13-AA14 -> 3964 | AC14: =N14+O14+P14+Q14+R18+U14+X14+AA14 -> 144.8 | AD14: =IF(L14<0,L14*-1,0) -> 0 | AE14: =AC14+AD14 -> 144.8 | AF14: 0 | AG14: 51 | AH14: 21 | AI14: =AI13+(U14*1.9835) -> 631.30481 | AJ14: 0
A15: =A14+1 -> 4 | B15: 6876.91 | C15: 207044 | D15: =C15-C14 -> -57 | E15: =C15-152000 -> 55044 | F15: =D15/$D$2 -> -28.737081 | G15: 122 | H15: 0 | I15: =G15+H15 -> 122 | J15: =IF(L15>0,L15,0) -> 0 | K15: =I15+J15 -> 122 | L15: =F15-(I15-AC15) -> -18.837081 | M15: 4.9 | N15: 0 | O15: 0 | P15: =1.33*1.02 -> 1.3566 | Q15: =2.62*1.04 -> 2.7248 | R15: 0 | S15: 99 | T15: 0 | U15: =M15-N15-O15-P15-Q15-R15+S15+T15 -> 99.8186 | X15: 0 | AA15: 28 | AB15: =AB14-AA15 -> 3936 | AC15: =N15+O15+P15+Q15+R19+U15+X15+AA15 -> 131.9 | AD15: =IF(L15<0,L15*-1,0) -> 18.837081 | AE15: =AC15+AD15 -> 150.73708 | AF15: 0 | AG15: 60 | AH15: 28 | AI15: =AI14+(U15*1.9835) -> 829.295 | AJ15: 0
A16: =A15+1 -> 5 | B16: 6876.9 | C16: 207015 | D16: =C16-C15 -> -29 | E16: =C16-152000 -> 55015 | F16: =D16/$D$2 -> -14.62062 | G16: 116 | H16: 0 | I16: =G16+H16 -> 116 | J16: =IF(L16>0,L16,0) -> 1.2793799 | K16: =I16+J16 -> 117.27938 | L16: =F16-(I16-AC16) -> 1.2793799 | M16: 4.9 | N16: 0 | O16: 0 | P16: =1.33*1.02 -> 1.3566 | Q16: =2.23*1.04 -> 2.3192 | R16: 0 | S16: 99 | T16: 0 | U16: =M16-N16-O16-P16-Q16-R16+S16+T16 -> 100.2242 | X16: 0 | AA16: 28 | AB16: =AB15-AA16 -> 3908 | AC16: =N16+O16+P16+Q16+R20+U16+X16+AA16 -> 131.9 | AD16: =IF(L16<0,L16*-1,0) -> 0 | AE16: =AC16+AD16 -> 131.9 | AF16: 0 | AG16: 63 | AH16: 31 | AI16: =AI15+(U16*1.9835) -> 1028.0897 | AJ16: 0
A17: =A16+1 -> 6 | B17: 6876.9 | C17: 207015 | D17: =C17-C16 -> 0 | E17: =C17-152000 -> 55015 | F17: =D17/$D$2 -> 0 | G17: 115 | H17: 0 | I17: =G17+H17 -> 115 | J17: =IF(L17>0,L17,0) -> 16.9 | K17: =I17+J17 -> 131.9 | L17: =F17-(I17-AC17) -> 16.9 | M17: 4.9 | N17: 0 | O17: 0 | P17: =1.33*1.02 -> 1.3566 | Q17: =2.07*1.04 -> 2.1528 | R17: 0 | S17: 99 | T17: 0 | U17: =M17-N17-O17-P17-Q17-R17+S17+T17 -> 100.3906 | X17: 0 | AA17: 28 | AB17: =AB16-AA17 -> 3880 | AC17: =N17+O17+P17+Q17+R21+U17+X17+AA17 -> 131.9 | AD17: =IF(L17<0,L17*-1,0) -> 0 | AE17: =AC17+AD17 -> 131.9 | AF17: 0 | AG17: 64 | AH17: 31 | AI17: =AI16+(U17*1.9835) -> 1227.2145 | AJ17: 0
A18: =A17+1 -> 7 | B18: 6876.81 | C18: 206755 | D18: =C18-C17 -> -260 | E18: =C18-152000 -> 54755 | F18: =D18/$D$2 -> -131.08142 | G18: 110 | H18: 0 | I18: =G18+H18 -> 110 | J18: =IF(L18>0,L18,0) -> 0 | K18: =I18+J18 -> 110 | L18: =F18-(I18-AC18) -> -108.88142 | M18: 5.2 | N18: 0 | O18: 0 | P18: =1.33*1.02 -> 1.3566 | Q18: =2.16*1.04 -> 2.2464 | R18: 0 | S18: 99 | T18: 0 | U18: =M18-N18-O18-P18-Q18-R18+S18+T18 -> 100.597 | X18: 0 | AA18: 28 | AB18: =AB17-AA18 -> 3852 | AC18: =N18+O18+P18+Q18+R22+U18+X18+AA18 -> 132.2 | AD18: =IF(L18<0,L18*-1,0) -> 108.88142 | AE18: =AC18+AD18 -> 241.08142 | AF18: 0 | AG18: 64 | AH18: 34 | AI18: =AI17+(U18*1.9835) -> 1426.7486 | AJ18: 0
A19: =A18+1 -> 8 | B19: 6876.8 | C19: 206726 | D19: =C19-C18 -> -29 | E19: =C19-152000 -> 54726 | F19: =D19/$D$2 -> -14.62062 | G19: 117 | H19: 0 | I19: =G19+H19 -> 117 | J19: =IF(L19>0,L19,0) -> 20.77938 | K19: =I19+J19 -> 137.77938 | L19: =F19-(I19-AC19) -> 20.77938 | M19: 5.4 | N19: 0 | O19: 0 | P19: =1.33*1.02 -> 1.3566 | Q19: =1.98*1.04 -> 2.0592 | R19: 0 | S19: 119 | T19: 0 | U19: =M19-N19-O19-P19-Q19-R19+S19+T19 -> 120.9842 | X19: 0 | AA19: 28 | AB19: =AB18-AA19 -> 3824 | AC19: =N19+O19+P19+Q19+R23+U19+X19+AA19 -> 152.4 | AD19: =IF(L19<0,L19*-1,0) -> 0 | AE19: =AC19+AD19 -> 152.4 | AF19: 0.08 | AG19: 59 | AH19: 43 | AI19: =AI18+(U19*1.9835) -> 1666.7208 | AJ19: 0
A20: =A19+1 -> 9 | B20: 6876.86 | C20: 206899 | D20: =C20-C19 -> 173 | E20: =C20-152000 -> 54899 | F20: =D20/$D$2 -> 87.219561 | G20: 153 | H20: 0 | I20: =G20+H20 -> 153 | J20: =IF(L20>0,L20,0) -> 101.51956 | K20: =I20+J20 -> 254.51956 | L20: =F20-(I20-AC20) -> 101.51956 | M20: 5.3 | N20: 0 | O20: 0 | P20: =1.33*1.02 -> 1.3566 | Q20: =2.03*1.04 -> 2.1112 | R20: 0 | S20: 135 | T20: 0 | U20: =M20-N20-O20-P20-Q20-R20+S20+T20 -> 136.8322 | X20: 0 | AA20: 27 | AB20: =AB19-AA20 -> 3797 | AC20: =N20+O20+P20+Q20+R24+U20+X20+AA20 -> 167.3 | AD20: =IF(L20<0,L20*-1,0) -> 0 | AE20: =AC20+AD20 -> 167.3 | AF20: 0.86 | AG20: 42 | AH20: 29 | AI20: =AI19+(U20*1.9835) -> 1938.1274 | AJ20: 0
A21: =A20+1 -> 10 | B21: 6876.86 | C21: 206899 | D21: =C21-C20 -> 0 | E21: =C21-152000 -> 54899 | F21: =D21/$D$2 -> 0 | G21: 140 | H21: 0 | I21: =G21+H21 -> 140 | J21: =IF(L21>0,L21,0) -> 12.4 | K21: =I21+J21 -> 152.4 | L21: =F21-(I21-AC21) -> 12.4 | M21: 5.4 | N21: 0 | O21: 0 | P21: =1.33*1.02 -> 1.3566 | Q21: =2.24*1.04 -> 2.3296 | R21: 0 | S21: 122 | T21: 0 | U21: =M21-N21-O21-P21-Q21-R21+S21+T21 -> 123.7138 | X21: 0 | AA21: 25 | AB21: =AB20-AA21 -> 3772 | AC21: =N21+O21+P21+Q21+R25+U21+X21+AA21 -> 152.4 | AD21: =IF(L21<0,L21*-1,0) -> 0 | AE21: =AC21+AD21 -> 152.4 | AF21: 0 | AG21: 51 | AH21: 28 | AI21: =AI20+(U21*1.9835) -> 2183.5138 | AJ21: 0
A22: =A21+1 -> 11 | B22: 6876.84 | C22: 206841 | D22: =C22-C21 -> -58 | E22: =C22-152000 -> 54841 | F22: =D22/$D$2 -> -29.24124 | G22: 142 | H22: 0 | I22: =G22+H22 -> 142 | J22: =IF(L22>0,L22,0) -> 0 | K22: =I22+J22 -> 142 | L22: =F22-(I22-AC22) -> -19.04124 | M22: 5.2 | N22: 0 | O22: 0 | P22: =1.33*1.02 -> 1.3566 | Q22: =2.01*1.04 -> 2.0904 | R22: 0 | S22: 122 | T22: 0 | U22: =M22-N22-O22-P22-Q22-R22+S22+T22 -> 123.753 | X22: 0 | AA22: 25 | AB22: =AB21-AA22 -> 3747 | AC22: =N22+O22+P22+Q22+R26+U22+X22+AA22 -> 152.2 | AD22: =IF(L22<0,L22*-1,0) -> 19.04124 | AE22: =AC22+AD22 -> 171.24124 | AF22: 0 | AG22: 50 | AH22: 33 | AI22: =AI21+(U22*1.9835) -> 2428.9778 | AJ22: 0
A23: =A22+1 -> 12 | B23: 6876.83 | C23: 206813 | D23: =C23-C22 -> -28 | E23: =C23-152000 -> 54813 | F23: =D23/$D$2 -> -14.116461 | G23: 138 | H23: 0.15 | I23: =G23+H23 -> 138.15 | J23: =IF(L23>0,L23,0) -> 0 | K23: =I23+J23 -> 138.15 | L23: =F23-(I23-AC23) -> -0.066460802 | M23: 5.2 | N23: 0 | O23: 0 | P23: =1.33*1.02 -> 1.3566 | Q23: =2.1*1.04 -> 2.184 | R23: 0 | S23: 122 | T23: 0 | U23: =M23-N23-O23-P23-Q23-R23+S23+T23 -> 123.6594 | X23: 0 | AA23: 25 | AB23: =AB22-AA23 -> 3722 | AC23: =N23+O23+P23+Q23+R27+U23+X23+AA23 -> 152.2 | AD23: =IF(L23<0,L23*-1,0) -> 0.066460802 | AE23: =AC23+AD23 -> 152.26646 | AF23: 0.01 | AG23: 43 | AH23: 36 | AI23: =AI22+(U23*1.9835) -> 2674.2563 | AJ23: 0
A24: =A23+1 -> 13 | B24: 6876.83 | C24: 206813 | D24: =C24-C23 -> 0 | E24: =C24-152000 -> 54813 | F24: =D24/$D$2 -> 0 | G24: 133 | H24: 0.3 | I24: =G24+H24 -> 133.3 | J24: =IF(L24>0,L24,0) -> 18.9 | K24: =I24+J24 -> 152.2 | L24: =F24-(I24-AC24) -> 18.9 | M24: 5.2 | N24: 0 | O24: 0 | P24: =1.33*1.02 -> 1.3566 | Q24: =2.1*1.04 -> 2.184 | R24: 0 | S24: 122 | T24: 0 | U24: =M24-N24-O24-P24-Q24-R24+S24+T24 -> 123.6594 | X24: 0 | AA24: 25 | AB24: =AB23-AA24 -> 3697 | AC24: =N24+O24+P24+Q24+R28+U24+X24+AA24 -> 152.2 | AD24: =IF(L24<0,L24*-1,0) -> 0 | AE24: =AC24+AD24 -> 152.2 | AF24: 0.01 | AG24: 41 | AH24: 31 | AI24: =AI23+(U24*1.9835) -> 2919.5347 | AJ24: 0
A25: =A24+1 -> 14 | B25: 6876.81 | C25: 206755 | D25: =C25-C24 -> -58 | E25: =C25-152000 -> 54755 | F25: =D25/$D$2 -> -29.24124 | G25: 125 | H25: 0.3 | I25: =G25+H25 -> 125.3 | J25: =IF(L25>0,L25,0) -> 0 | K25: =I25+J25 -> 125.3 | L25: =F25-(I25-AC25) -> -2.2412402 | M25: 5.3 | N25: 0 | O25: 0 | P25: =1.33*1.02 -> 1.3566 | Q25: =3.71*1.04 -> 3.8584 | R25: 0 | S25: 122 | T25: 0 | U25: =M25-N25-O25-P25-Q25-R25+S25+T25 -> 122.085 | X25: 0 | AA25: 25 | AB25: =AB24-AA25 -> 3672 | AC25: =N25+O25+P25+Q25+R29+U25+X25+AA25 -> 152.3 | AD25: =IF(L25<0,L25*-1,0) -> 2.2412402 | AE25: =AC25+AD25 -> 154.54124 | AF25: 0 | AG25: 46 | AH25: 26 | AI25: =AI24+(U25*1.9835) -> 3161.6903 | AJ25: 0
A26: =A25+1 -> 15 | B26: 6876.76 | C26: 206610 | D26: =C26-C25 -> -145 | E26: =C26-152000 -> 54610 | F26: =D26/$D$2 -> -73.103101 | G26: 114 | H26: 0.3 | I26: =G26+H26 -> 114.3 | J26: =IF(L26>0,L26,0) -> 0 | K26: =I26+J26 -> 114.3 | L26: =F26-(I26-AC26) -> -15.603101 | M26: 16 | N26: 0 | O26: 0 | P26: =1.33*1.02 -> 1.3566 | Q26: =3.21*1.04 -> 3.3384 | R26: 0 | S26: 122 | T26: 8.8 | U26: =M26-N26-O26-P26-Q26-R26+S26+T26 -> 142.105 | X26: 0 | AA26: 25 | AB26: =AB25-AA26 -> 3647 | AC26: =N26+O26+P26+Q26+R30+U26+X26+AA26 -> 171.8 | AD26: =IF(L26<0,L26*-1,0) -> 15.603101 | AE26: =AC26+AD26 -> 187.4031 | AF26: 0 | AG26: 50 | AH26: 46 | AI26: =AI25+(S26-17.81)*1.9835 -> 3368.3511 | AJ26: =U26-106.09 -> 36.015
A27: =A26+1 -> 16 | B27: 6876.72 | C27: 206495 | D27: =C27-C26 -> -115 | E27: =C27-152000 -> 54495 | F27: =D27/$D$2 -> -57.978321 | G27: 119 | H27: 0.29 | I27: =G27+H27 -> 119.29 | J27: =IF(L27>0,L27,0) -> 8.7316789 | K27: =I27+J27 -> 128.02168 | L27: =F27-(I27-AC27) -> 8.7316789 | M27: 28 | N27: 0 | O27: 0 | P27: =1.33*1.02 -> 1.3566 | Q27: =2.16*1.04 -> 2.2464 | R27: 0 | S27: 122 | T27: 11 | U27: =M27-N27-O27-P27-Q27-R27+S27+T27 -> 157.397 | X27: 0 | AA27: 25 | AB27: =AB26-AA27 -> 3622 | AC27: =N27+O27+P27+Q27+R31+U27+X27+AA27 -> 186 | AD27: =IF(L27<0,L27*-1,0) -> 0 | AE27: =AC27+AD27 -> 186 | AF27: 0 | AG27: 53 | AH27: 33 | AI27: =AI26+(S27-15.25)*1.9835 -> 3580.0898 | AJ27: =U27-108.63 -> 48.767
A28: =A27+1 -> 17 | B28: 6876.68 | C28: 206379 | D28: =C28-C27 -> -116 | E28: =C28-152000 -> 54379 | F28: =D28/$D$2 -> -58.48248 | G28: 114 | H28: 0.28 | I28: =G28+H28 -> 114.28 | J28: =IF(L28>0,L28,0) -> 10.63752 | K28: =I28+J28 -> 124.91752 | L28: =F28-(I28-AC28) -> 10.63752 | M28: 27 | N28: 0 | O28: 0 | P28: =1.33*1.02 -> 1.3566 | Q28: =2.1*1.04 -> 2.184 | R28: 0 | S28: 122 | T28: 9.4 | U28: =M28-N28-O28-P28-Q28-R28+S28+T28 -> 154.8594 | X28: 0 | AA28: 25 | AB28: =AB27-AA28 -> 3597 | AC28: =N28+O28+P28+Q28+R32+U28+X28+AA28 -> 183.4 | AD28: =IF(L28<0,L28*-1,0) -> 0 | AE28: =AC28+AD28 -> 183.4 | AF28: 0 | AG28: 56 | AH28: 29 | AI28: =AI27+(S28-14)*1.9835 -> 3794.3078 | AJ28: =U28-109.69 -> 45.1694
A29: =A28+1 -> 18 | B29: 6876.63 | C29: 206235 | D29: =C29-C28 -> -144 | E29: =C29-152000 -> 54235 | F29: =D29/$D$2 -> -72.598941 | G29: 109 | H29: 0.27 | I29: =G29+H29 -> 109.27 | J29: =IF(L29>0,L29,0) -> 0 | K29: =I29+J29 -> 109.27 | L29: =F29-(I29-AC29) -> -25.268941 | M29: 16 | N29: 0 | O29: 0 | P29: =1.33*1.02 -> 1.3566 | Q29: =2.39*1.04 -> 2.4856 | R29: 0 | S29: 110 | T29: 4.6 | U29: =M29-N29-O29-P29-Q29-R29+S29+T29 -> 126.7578 | X29: 0 | AA29: 26 | AB29: =AB28-AA29 -> 3571 | AC29: =N29+O29+P29+Q29+R33+U29+X29+AA29 -> 156.6 | AD29: =IF(L29<0,L29*-1,0) -> 25.268941 | AE29: =AC29+AD29 -> 181.86894 | AF29: 0 | AG29: 53 | AH29: 30 | AI29: =AI28+(S29-14*1.9835) -> 3876.5388 | AJ29: =U29-97.12 -> 29.6378
A30: =A29+1 -> 19 | B30: 6876.58 | C30: 206090 | D30: =C30-C29 -> -145 | E30: =C30-152000 -> 54090 | F30: =D30/$D$2 -> -73.103101 | G30: 107 | H30: 0.28 | I30: =G30+H30 -> 107.28 | J30: =IF(L30>0,L30,0) -> 0 | K30: =I30+J30 -> 107.28 | L30: =F30-(I30-AC30) -> -51.883101 | M30: 5.5 | N30: 0 | O30: 0 | P30: =1.33*1.02 -> 1.3566 | Q30: =2.05*1.04 -> 2.132 | R30: 0 | S30: 97 | T30: 0 | U30: =M30-N30-O30-P30-Q30-R30+S30+T30 -> 99.0114 | X30: 0 | AA30: 26 | AB30: =AB29-AA30 -> 3545 | AC30: =N30+O30+P30+Q30+R34+U30+X30+AA30 -> 128.5 | AD30: =IF(L30<0,L30*-1,0) -> 51.883101 | AE30: =AC30+AD30 -> 180.3831 | AF30: 0 | AG30: 50 | AH30: 28 | AI30: =AI29+(U30-5.83)*1.9835 -> 4061.3641 | AJ30: 5.83
A31: =A30+1 -> 20 | B31: 6876.65 | C31: 206293 | D31: =C31-C30 -> 203 | E31: =C31-152000 -> 54293 | F31: =D31/$D$2 -> 102.34434 | G31: 107 | H31: 0.32 | I31: =G31+H31 -> 107.32 | J31: =IF(L31>0,L31,0) -> 123.52434 | K31: =I31+J31 -> 230.84434 | L31: =F31-(I31-AC31) -> 123.52434 | M31: 5.5 | N31: 0 | O31: 0 | P31: =1.33*1.02 -> 1.3566 | Q31: =2.33*1.04 -> 2.4232 | R31: 0 | S31: 97 | T31: 0 | U31: =M31-N31-O31-P31-Q31-R31+S31+T31 -> 98.7202 | X31: 0 | AA31: 26 | AB31: =AB30-AA31 -> 3519 | AC31: =N31+O31+P31+Q31+R35+U31+X31+AA31 -> 128.5 | AD31: =IF(L31<0,L31*-1,0) -> 0 | AE31: =AC31+AD31 -> 128.5 | AF31: 0.67 | AG31: 44 | AH31: 29 | AI31: =AI30+(U31*1.9835) -> 4257.1756 | AJ31: 0
A32: =A31+1 -> 21 | B32: 6876.71 | C32: 206466 | D32: =C32-C31 -> 173 | E32: =C32-152000 -> 54466 | F32: =D32/$D$2 -> 87.219561 | G32: 107 | H32: 0.5 | I32: =G32+H32 -> 107.5 | J32: =IF(L32>0,L32,0) -> 108.21956 | K32: =I32+J32 -> 215.71956 | L32: =F32-(I32-AC32) -> 108.21956 | M32: 5.5 | N32: 0 | O32: 0 | P32: =1.33*1.02 -> 1.3566 | Q32: =2.4*1.04 -> 2.496 | R32: 0 | S32: 97 | T32: 0 | U32: =M32-N32-O32-P32-Q32-R32+S32+T32 -> 98.6474 | X32: 0 | AA32: 26 | AB32: =AB31-AA32 -> 3493 | AC32: =N32+O32+P32+Q32+R36+U32+X32+AA32 -> 128.5 | AD32: =IF(L32<0,L32*-1,0) -> 0 | AE32: =AC32+AD32 -> 128.5 | AF32: 0.26 | AG32: 40 | AH32: 31 | AI32: =AI31+(U32*1.9835) -> 4452.8427 | AJ32: 0
A33: =A32+1 -> 22 | B33: 6876.65 | C33: 206293 | D33: =C33-C32 -> -173 | E33: =C33-152000 -> 54293 | F33: =D33/$D$2 -> -87.219561 | G33: 104 | H33: 0.53 | I33: =G33+H33 -> 104.53 | J33: =IF(L33>0,L33,0) -> 0 | K33: =I33+J33 -> 104.53 | L33: =F33-(I33-AC33) -> -72.849561 | M33: 4.9 | N33: 0 | O33: 0 | P33: =1.33*1.02 -> 1.3566 | Q33: =2.07*1.04 -> 2.1528 | R33: 0 | S33: 88 | T33: 0 | U33: =M33-N33-O33-P33-Q33-R33+S33+T33 -> 89.3906 | X33: 0 | AA33: 26 | AB33: =AB32-AA33 -> 3467 | AC33: =N33+O33+P33+Q33+R37+U33+X33+AA33 -> 118.9 | AD33: =IF(L33<0,L33*-1,0) -> 72.849561 | AE33: =AC33+AD33 -> 191.74956 | AF33: 0 | AG33: 48 | AH33: 31 | AI33: =AI32+(U33*1.9835) -> 4630.149 | AJ33: 0
A34: =A33+1 -> 23 | B34: 6876.64 | C34: 206264 | D34: =C34-C33 -> -29 | E34: =C34-152000 -> 54264 | F34: =D34/$D$2 -> -14.62062 | G34: 103 | H34: 0.53 | I34: =G34+H34 -> 103.53 | J34: =IF(L34>0,L34,0) -> 8.5493799 | K34: =I34+J34 -> 112.07938 | L34: =F34-(I34-AC34) -> 8.5493799 | M34: 4.7 | N34: 0 | O34: 0 | P34: =1.33*1.02 -> 1.3566 | Q34: =2.34*1.04 -> 2.4336 | R34: 0 | S34: 96 | T34: 0 | U34: =M34-N34-O34-P34-Q34-R34+S34+T34 -> 96.9098 | X34: 0 | AA34: 26 | AB34: =AB33-AA34 -> 3441 | AC34: =N34+O34+P34+Q34+R38+U34+X34+AA34 -> 126.7 | AD34: =IF(L34<0,L34*-1,0) -> 0 | AE34: =AC34+AD34 -> 126.7 | AF34: 0 | AG34: 44 | AH34: 27 | AI34: =AI33+(U34*1.9835) -> 4822.3695 | AJ34: 0
A35: =A34+1 -> 24 | B35: 6876.63 | C35: 206235 | D35: =C35-C34 -> -29 | E35: =C35-152000 -> 54235 | F35: =D35/$D$2 -> -14.62062 | G35: 93 | H35: 0.4 | I35: =G35+H35 -> 93.4 | J35: =IF(L35>0,L35,0) -> 18.87938 | K35: =I35+J35 -> 112.27938 | L35: =F35-(I35-AC35) -> 18.87938 | M35: 4.9 | N35: 0 | O35: 0 | P35: =1.33*1.02 -> 1.3566 | Q35: =2.36*1.04 -> 2.4544 | R35: 0 | S35: 97 | T35: 0 | U35: =M35-N35-O35-P35-Q35-R35+S35+T35 -> 98.089 | X35: 0 | AA35: 25 | AB35: =AB34-AA35 -> 3416 | AC35: =N35+O35+P35+Q35+R39+U35+X35+AA35 -> 126.9 | AD35: =IF(L35<0,L35*-1,0) -> 0 | AE35: =AC35+AD35 -> 126.9 | AF35: 0 | AG35: 44 | AH35: 23 | AI35: =AI34+(U35*1.9835) -> 5016.9291 | AJ35: 0
A36: =A35+1 -> 25 | B36: 6876.61 | C36: 206177 | D36: =C36-C35 -> -58 | E36: =C36-152000 -> 54177 | F36: =D36/$D$2 -> -29.24124 | G36: 85 | H36: 0.32 | I36: =G36+H36 -> 85.32 | J36: =IF(L36>0,L36,0) -> 12.33876 | K36: =I36+J36 -> 97.65876 | L36: =F36-(I36-AC36) -> 12.33876 | M36: 4.9 | N36: 0 | O36: 0 | P36: =1.33*1.02 -> 1.3566 | Q36: =2.1*1.04 -> 2.184 | R36: 0 | S36: 97 | T36: 0 | U36: =M36-N36-O36-P36-Q36-R36+S36+T36 -> 98.3594 | X36: 0 | AA36: 25 | AB36: =AB35-AA36 -> 3391 | AC36: =N36+O36+P36+Q36+R40+U36+X36+AA36 -> 126.9 | AD36: =IF(L36<0,L36*-1,0) -> 0 | AE36: =AC36+AD36 -> 126.9 | AF36: 0 | AG36: 46 | AH36: 22 | AI36: =AI35+(U36*1.9835) -> 5212.0249 | AJ36: 0
A37: =A36+1 -> 26 | B37: 6876.6 | C37: 206148 | D37: =C37-C36 -> -29 | E37: =C37-152000 -> 54148 | F37: =D37/$D$2 -> -14.62062 | G37: 76 | H37: 0.35 | I37: =G37+H37 -> 76.35 | J37: =IF(L37>0,L37,0) -> 34.72938 | K37: =I37+J37 -> 111.07938 | L37: =F37-(I37-AC37) -> 34.72938 | M37: 4.7 | N37: 0 | O37: 0 | P37: =1.33*1.02 -> 1.3566 | Q37: =2.29*1.04 -> 2.3816 | R37: 0 | S37: 96 | T37: 0 | U37: =M37-N37-O37-P37-Q37-R37+S37+T37 -> 96.9618 | X37: 0 | AA37: 25 | AB37: =AB36-AA37 -> 3366 | AC37: =N37+O37+P37+Q37+R41+U37+X37+AA37 -> 125.7 | AD37: =IF(L37<0,L37*-1,0) -> 0 | AE37: =AC37+AD37 -> 125.7 | AF37: 0.04 | AG37: 39 | AH37: 21 | AI37: =AI36+(U37*1.9835) -> 5404.3487 | AJ37: 0
A38: =A37+1 -> 27 | B38: 6876.55 | C38: 206004 | D38: =C38-C37 -> -144 | E38: =C38-152000 -> 54004 | F38: =D38/$D$2 -> -72.598941 | G38: 76 | H38: 0.33 | I38: =G38+H38 -> 76.33 | J38: =IF(L38>0,L38,0) -> 0 | K38: =I38+J38 -> 76.33 | L38: =F38-(I38-AC38) -> -22.328941 | M38: 4.6 | N38: 0 | O38: 0 | P38: =1.33*1.02 -> 1.3566 | Q38: =2.47*1.04 -> 2.5688 | R38: 0 | S38: 96 | T38: 0 | U38: =M38-N38-O38-P38-Q38-R38+S38+T38 -> 96.6746 | X38: 0 | AA38: 26 | AB38: =AB37-AA38 -> 3340 | AC38: =N38+O38+P38+Q38+R42+U38+X38+AA38 -> 126.6 | AD38: =IF(L38<0,L38*-1,0) -> 22.328941 | AE38: =AC38+AD38 -> 148.92894 | AF38: 0 | AG38: 40 | AH38: 21 | AI38: =AI37+(U38*1.9835) -> 5596.1027 | AJ38: 0
A39: =A38+1 -> 28 | B39: 6876.5 | C39: 205859 | D39: =C39-C38 -> -145 | E39: =C39-152000 -> 53859 | F39: =D39/$D$2 -> -73.103101 | G39: 74 | H39: 0.36 | I39: =G39+H39 -> 74.36 | J39: =IF(L39>0,L39,0) -> 0 | K39: =I39+J39 -> 74.36 | L39: =F39-(I39-AC39) -> -20.763101 | M39: 4.7 | N39: 0 | O39: 0 | P39: =1.33*1.02 -> 1.3566 | Q39: =2.21*1.04 -> 2.2984 | R39: 0 | S39: 96 | T39: 0 | U39: =M39-N39-O39-P39-Q39-R39+S39+T39 -> 97.045 | X39: 0 | AA39: 26 | AB39: =AB38-AA39 -> 3314 | AC39: =N39+O39+P39+Q39+R43+U39+X39+AA39 -> 126.7 | AD39: =IF(L39<0,L39*-1,0) -> 20.763101 | AE39: =AC39+AD39 -> 147.4631 | AF39: 0.15 | AG39: 39 | AH39: 14 | AI39: =AI38+(U39*1.9835) -> 5788.5915 | AJ39: 0
A40: =A39+1 -> 29 | B40: 6876.47 | C40: 205773 | D40: =C40-C39 -> -86 | E40: =C40-152000 -> 53773 | F40: =D40/$D$2 -> -43.357701 | G40: 59 | H40: 0.3 | I40: =G40+H40 -> 59.3 | J40: =IF(L40>0,L40,0) -> 13.142299 | K40: =I40+J40 -> 72.442299 | L40: =F40-(I40-AC40) -> 13.142299 | M40: 4.8 | N40: 0 | O40: 0 | P40: =1.33*1.02 -> 1.3566 | Q40: =2.21*1.04 -> 2.2984 | R40: 0 | S40: 85 | T40: 0 | U40: =M40-N40-O40-P40-Q40-R40+S40+T40 -> 86.145 | X40: 0 | AA40: 26 | AB40: =AB39-AA40 -> 3288 | AC40: =N40+O40+P40+Q40+R44+U40+X40+AA40 -> 115.8 | AD40: =IF(L40<0,L40*-1,0) -> 0 | AE40: =AC40+AD40 -> 115.8 | AF40: 0 | AG40: 28 | AH40: 10 | AI40: =AI39+(U40*1.9835) -> 5959.4601 | AJ40: 0
A41: 30 | B41: 6876.4 | C41: 205571 | D41: =C41-C40 -> -202 | E41: =C41-152000 -> 53571 | F41: =D41/$D$2 -> -101.84018 | G41: 35 | H41: 0.22 | I41: =G41+H41 -> 35.22 | J41: =IF(L41>0,L41,0) -> 0 | K41: =I41+J41 -> 35.22 | L41: =F41-(I41-AC41) -> -27.660181 | M41: 4.4 | N41: 0 | O41: 0 | P41: =1.33*1.02 -> 1.3566 | Q41: =2.21*1.04 -> 2.2984 | R41: 0 | S41: 79 | T41: 0 | U41: =M41-N41-O41-P41-Q41-R41+S41+T41 -> 79.745 | X41: 0 | AA41: 26 | AB41: =AB40-AA41 -> 3262 | AC41: =N41+O41+P41+Q41+R45+U41+X41+AA41 -> 109.4 | AD41: =IF(L41<0,L41*-1,0) -> 27.660181 | AE41: =AC41+AD41 -> 137.06018 | AF41: 0 | AG41: 30 | AH41: 2 | AI41: =AI40+(U41*1.9835) -> 6117.6343 | AJ41: 0
A43: MONTH / CFS | F43: =SUM(F12:F41) -> -844.46685 | G43: =SUM(G12:G41) -> 3268 | H43: =SUM(H12:H41) -> 6.33 | I43: =SUM(I12:I41) -> 3274.33 | J43: =SUM(J12:J41) -> 582.83372 | K43: =SUM(K12:K41) -> 3857.1637 | L43: =SUM(L12:L41) -> 94.203148 | M43: =SUM(M12:M41) -> 218.2 | ... Q43: =SUM(Q12:Q41) -> 72.488 | R43: =SUM(R13:R41) -> 0 | S43: =SUM(S12:S41) -> 3172 | T43: =SUM(T12:T41) -> 33.8 | U43: =SUM(U12:U41) -> 3310.814 | AA43: =SUM(AA12:AA41) -> 789 | AC43: =SUM(AC12:AC41) -> 4213 | AD43: =SUM(AD12:AD41) -> 488.63057 | AE43: =SUM(AE12:AE41) -> 4701.6306 | AF43: =SUM(AF12:AF41) -> 2.08 | AG43: =AVERAGE(AG12:AG41) -> 47.5 | AH43: =AVERAGE(AH12:AH42) -> 27.133333 | AI43: Avg | AJ43: =SUM(AJ12:AJ41) -> 165.4192
...

Sheet DEC
K1: MCPHEE RESERVOIR INFLOW/OUTFLOW TABULATION
A2: AF/cfs CONVERT FACTOR | D2: 1.9835 | K2: DECEMBER "2004"
D4: RESERVOIR | S4: INFLOW/OUTFLOW (CFS) | AG4: WEATHER | AK4: ADJUSTMENTS
A5: DATE | B5: RESERV | C5: RESERV | D5: AC FT | E5: ACTIVE | F5: CONV TO | G5: DOLORES | H5: LOST | I5: RECORD | J5: CALC | K5: TOTAL | L5: CALC | M5: DOLORES TUNNEL | S5: LONE | T5: U | U5: TOTAL | V5: MVI | W5: MVI | X5: DV CR | Y5: D/S SENIOR | AA5: BELOW | AB5: FISH | AC5: RECORD | AD5: CALC | AE5: TOTAL | AF5: RAIN | AG5: MAX | AH5: MIN | AI5: NAR | AJ5: MVI | AK5: MVI | AL5: MVI | AM5: U/S | AN5: TOTTEN
A6: DEC | B6: ELEV | C6: AC FT | D6: CHANGE | E6: CAP | F6: CFS | G6: RIVER | H6: CAN | I6: INFLOW | J6: INFLOW | K6: INFLOW | L6: INF/OTF | M6: TOT DIV | N6: WET | O6: UTE | P6: MWC | Q6: CTZ | R6: CTZ & | S6: PINE | T6: LAT | U6: MVI | V6: CALL | W6: PROJ & | X6: CANAL | AA6: MCP | AB6: LEFT | AC6: OTF | AD6: OTF | AE6: OTF | AG6: TMP | AH6: TMP | AI6: CALL | AJ6: STOCK | AK6: STORED | AL6: STORED | AM6: USERS | AN6: (FRESH
E7: AC FT | N7: LAND | O7: F&R | R7: UTE | W7: TO EX & | AI7: AC.FT. | AJ7: AC.FT. | AK7: Apr-Jun | AL7: EVAP | AM7: EXCH | AN7: WATER)
N8: 1.03 | O8: 1.05 | P8: 1.02 | Q8: 1.04 | R8: PROJ | W8: U/S EX | AL8: AC.FT.
A9: SEASON BAL
A10: YTD | B10: =NOV!B41 -> 6876.4 | C10: =NOV!C41 -> 205571 | D10: =NOV!D50 -> -1675 | E10: =NOV!E50 -> 53571 | F10: =NOV!F49 -> -844.46685 | G10: =NOV!G49 -> 3268 | H10: =NOV!H49 -> 6.33 | I10: =NOV!I49 -> 3274.33 | J10: =NOV!J49 -> 582.83372 | K10: =NOV!K49 -> 3857.1637 | L10: =NOV!L49 -> 94.203148 | M10: =NOV!M49 -> 218.2 | ... U10: =NOV!U49 -> 3310.814 | AA10: =NOV!AA49 -> 789 | AB10: =NOV!AB49 -> 3262 | AC10: =NOV!AC49 -> 4213 | AD10: =NOV!AD49 -> 488.63057 | AE10: =NOV!AE49 -> 4701.6306 | AF10: =NOV!AF49 -> 2.08 | AI10: =NOV!AI50 -> 6117.6343 | AJ10: =NOV!AJ49 -> 517.4192
A12: 1 | B12: 6876.36 | C12: 205455 | D12: =C12-C10 -> -116 | E12: =C12-152000 -> 53455 | F12: =D12/$D$2 -> -58.48248 | G12: 37 | H12: 0.14 | I12: =G12+H12 -> 37.14 | J12: =IF(L12>0,L12,0) -> 4.6775195 | K12: =I12+J12 -> 41.81752 | L12: =F12-(I12-AC12) -> 4.6775195 | M12: 4.3 | N12: 0 | O12: 0 | P12: =1.44*1.02 -> 1.4688 | Q12: =2.1*1.04 -> 2.184 | R12: 0 | S12: 71 | T12: 0 | U12: =M12-N12-O12-P12-Q12-R12+S12+T12 -> 71.6472 | AA12: 25 | AB12: =AB10-AA12 -> 3237 | AC12: =N12+O12+P12+Q12+R12+U12+X12+AA12 -> 100.3 | AD12: =IF(L12<0,L12*-1,0) -> 0 | AE12: =AC12+AD12 -> 100.3 | AF12: 0.03 | AG12: 34 | AH12: 2 | AI12: =AI10+(U12*1.9835) -> 6259.7465 | AJ12: 0
A13: =A12+1 -> 2 | B13: 6876.33 | C13: 205368 | D13: =C13-C12 -> -87 | E13: =C13-152000 -> 53368 | F13: =D13/$D$2 -> -43.86186 | G13: 39 | H13: 0.09 | I13: =G13+H13 -> 39.09 | J13: =IF(L13>0,L13,0) -> 6.3481397 | K13: =I13+J13 -> 45.43814 | L13: =F13-(I13-AC13) -> 6.3481397 | M13: 4.3 | N13: 0 | O13: 0 | P13: =1.44*1.02 -> 1.4688 | Q13: =2.4*1.04 -> 2.496 | R13: 0 | S13: 60 | T13: 0 | U13: =M13-N13-O13-P13-Q13-R13+S13+T13 -> 60.3352 | AA13: 25 | AB13: =AB12-AA13 -> 3212 | AC13: =N13+O13+P13+Q13+R13+U13+X13+AA13 -> 89.3 | AD13: =IF(L13<0,L13*-1,0) -> 0 | AE13: =AC13+AD13 -> 89.3 | AF13: 0 | AG13: 37 | AH13: 9 | AI13: =AI12+(U13*1.9835) -> 6379.4214 | AJ13: 0
A14: =A13+1 -> 3 | B14: 6876.3 | C14: 205282 | D14: =C14-C13 -> -86 | E14: =C14-152000 -> 53282 | F14: =D14/$D$2 -> -43.357701 | G14: 42 | H14: 0.05 | I14: =G14+H14 -> 42.05 | J14: =IF(L14>0,L14,0) -> 2.892299 | K14: =I14+J14 -> 44.942299 | L14: =F14-(I14-AC14) -> 2.892299 | M14: 4.3 | N14: 0 | O14: 0 | P14: =1.44*1.02 -> 1.4688 | Q14: =2.36*1.04 -> 2.4544 | R14: 0 | S14: 59 | T14: 0 | U14: =M14-N14-P14-Q14-R14+S14+T14 -> 59.3768 | AA14: 25 | AB14: =AB13-AA14 -> 3187 | AC14: =N14+O14+P14+Q14+R14+U14+X14+AA14 -> 88.3 | AD14: =IF(L14<0,L14*-1,0) -> 0 | AE14: =AC14+AD14 -> 88.3 | AF14: 0 | AG14: 38 | AH14: 10 | AI14: =AI13+(U14*1.9835) -> 6497.1953 | AJ14: 0
A15: =A14+1 -> 4 | B15: 6876.27 | C15: 205195 | D15: =C15-C14 -> -87 | E15: =C15-152000 -> 53195 | F15: =D15/$D$2 -> -43.86186 | G15: 55 | H15: 0.03 | I15: =G15+H15 -> 55.03 | J15: =IF(L15>0,L15,0) -> 0 | K15: =I15+J15 -> 55.03 | L15: =F15-(I15-AC15) -> -10.59186 | M15: 4.3 | N15: 0 | O15: 0 | P15: =1.44*1.02 -> 1.4688 | Q15: =2.08*1.04 -> 2.1632 | R15: 0 | S15: 59 | T15: 0 | U15: =M15-N15-P15-Q15-R15+S15+T15 -> 59.668 | AA15: 25 | AB15: =AB14-AA15 -> 3162 | AC15: =N15+O15+P15+Q15+R15+U15+X15+AA15 -> 88.3 | AD15: =IF(L15<0,L15*-1,0) -> 10.59186 | AE15: =AC15+AD15 -> 98.89186 | AF15: 0.03 | AG15: 44 | AH15: 14 | AI15: =AI14+(U15*1.9835) -> 6615.5468 | AJ15: 0
A16: =A15+1 -> 5 | B16: 6876.3 | C16: 205282 | D16: =C16-C15 -> 87 | E16: =C16-152000 -> 53282 | F16: =D16/$D$2 -> 43.86186 | G16: 61 | H16: 0.04 | I16: =G16+H16 -> 61.04 | J16: =IF(L16>0,L16,0) -> 70.12186 | K16: =I16+J16 -> 131.16186 | L16: =F16-(I16-AC16) -> 70.12186 | M16: 4.3 | N16: 0 | O16: 0 | P16: =1.44*1.02 -> 1.4688 | Q16: =2.34*1.04 -> 2.4336 | R16: 0 | S16: 59 | T16: 0 | U16: =M16-N16-P16-Q16-R16+S16+T16 -> 59.3976 | AA16: 24 | AB16: =AB15-AA16 -> 3138 | AC16: =N16+O16+P16+Q16+R16+U16+X16+AA16 -> 87.3 | AD16: =IF(L16<0,L16*-1,0) -> 0 | AE16: =AC16+AD16 -> 87.3 | AF16: 0.21 | AG16: 32 | AH16: 16 | AI16: =AI15+(U16*1.9835) -> 6733.3619 | AJ16: 0
A17: =A16+1 -> 6 | B17: 6876.34 | C17: 205397 | D17: =C17-C16 -> 115 | E17: =C17-152000 -> 53397 | F17: =D17/$D$2 -> 57.978321 | G17: 56 | H17: 0.1 | I17: =G17+H17 -> 56.1 | J17: =IF(L17>0,L17,0) -> 81.278321 | K17: =I17+J17 -> 137.37832 | L17: =F17-(I17-AC17) -> 81.278321 | M17: 4.4 | N17: 0 | O17: 0 | P17: =1.44*1.02 -> 1.4688 | Q17: =2.4*1.04 -> 2.496 | R17: 0 | S17: 51 | T17: 0 | U17: =M17-N17-P17-Q17-R17+S17+T17 -> 51.4352 | AA17: 24 | AB17: =AB16-AA17 -> 3114 | AC17: =N17+O17+P17+Q17+R17+U17+X17+AA17 -> 79.4 | AD17: =IF(L17<0,L17*-1,0) -> 0 | AE17: =AC17+AD17 -> 79.4 | AF17: 0 | AG17: 32 | AH17: 18 | AI17: =AI16+(U17*1.9835) -> 6835.3836 | AJ17: 0
A18: =A17+1 -> 7 | B18: 6876.33 | C18: 205368 | D18: =C18-C17 -> -29 | E18: =C18-152000 -> 53368 | F18: =D18/$D$2 -> -14.62062 | G18: 55 | H18: 0.18 | I18: =G18+H18 -> 55.18 | J18: =IF(L18>0,L18,0) -> 3.7993799 | K18: =I18+J18 -> 58.97938 | L18: =F18-(I18-AC18) -> 3.7993799 | M18: 4.6 | N18: 0 | O18: 0 | P18: =1.44*1.02 -> 1.4688 | Q18: =2.34*1.04 -> 2.4336 | R18: 0 | S18: 45 | T18: 0 | U18: =M18-N18-P18-Q18-R18+S18+T18 -> 45.6976 | AA18: 24 | AB18: =AB17-AA18 -> 3090 | AC18: =N18+O18+P18+Q18+R18+U18+X18+AA18 -> 73.6 | AD18: =IF(L18<0,L18*-1,0) -> 0 | AE18: =AC18+AD18 -> 73.6 | AF18: 0 | AG18: 31 | AH18: 23 | AI18: =AI17+(U18*1.9835) -> 6926.0248 | AJ18: 0
A19: =A18+1 -> 8 | B19: 6876.37 | C19: 205484 | D19: =C19-C18 -> 116 | E19: =C19-152000 -> 53484 | F19: =D19/$D$2 -> 58.48248 | G19: 57 | H19: 0.41 | I19: =G19+H19 -> 57.41 | J19: =IF(L19>0,L19,0) -> 76.67248 | K19: =I19+J19 -> 134.08248 | L19: =F19-(I19-AC19) -> 76.67248 | M19: 4.6 | N19: 0 | O19: 0 | P19: =1.44*1.02 -> 1.4688 | Q19: =2.31*1.04 -> 2.4024 | R19: 0 | S19: 47 | T19: 0 | U19: =M19-N19-P19-Q19-R19+S19+T19 -> 47.7288 | AA19: 24 | AB19: =AB18-AA19 -> 3066 | AC19: =N19+O19+P19+Q19+R19+U19+X19+AA19 -> 75.6 | AD19: =IF(L19<0,L19*-1,0) -> 0 | AE19: =AC19+AD19 -> 75.6 | AF19: 0.04 | AG19: 35 | AH19: 25 | AI19: =AI18+(U19*1.9835) -> 7020.6949 | AJ19: 0
A20: =A19+1 -> 9 | B20: 6876.41 | C20: 205599 | D20: =C20-C19 -> 115 | E20: =C20-152000 -> 53599 | F20: =D20/$D$2 -> 57.978321 | G20: 51 | H20: 0.43 | I20: =G20+H20 -> 51.43 | J20: =IF(L20>0,L20,0) -> 85.148321 | K20: =I20+J20 -> 136.57832 | L20: =F20-(I20-AC20) -> 85.148321 | M20: 4.6 | N20: 0 | O20: 0 | P20: =1.44*1.02 -> 1.4688 | Q20: =2.4*1.04 -> 2.496 | R20: 0 | S20: 51 | T20: 0 | U20: =M20-N20-P20-Q20-R20+S20+T20 -> 51.6352 | AA20: 23 | AB20: =AB19-AA20 -> 3043 | AC20: =N20+O20+P20+Q20+R20+U20+X20+AA20 -> 78.6 | AD20: =IF(L20<0,L20*-1,0) -> 0 | AE20: =AC20+AD20 -> 78.6 | AF20: 0 | AG20: 42 | AH20: 27 | AI20: =AI19+(U20*1.9835) -> 7123.1133 | AJ20: 0
A21: =A20+1 -> 10 | B21: 6876.4 | C21: 205571 | D21: =C21-C20 -> -28 | E21: =C21-152000 -> 53571 | F21: =D21/$D$2 -> -14.116461 | G21: 53 | H21: 0.05 | I21: =G21+H21 -> 53.05 | J21: =IF(L21>0,L21,0) -> 11.433539 | K21: =I21+J21 -> 64.483539 | L21: =F21-(I21-AC21) -> 11.433539 | M21: 4.6 | N21: 0 | O21: 0 | P21: =1.44*1.02 -> 1.4688 | Q21: =2.03*1.04 -> 2.1112 | R21: 0 | S21: 51 | T21: 0 | U21: =M21-N21-P21-Q21-R21+S21+T21 -> 52.02 | AA21: 23 | AB21: =AB20-AA21 -> 3020 | AC21: =N21+O21+P21+Q21+R21+U21+X21+AA21 -> 78.6 | AD21: =IF(L21<0,L21*-1,0) -> 0 | AE21: =AC21+AD21 -> 78.6 | AF21: 0 | AG21: 51 | AH21: 27 | AI21: =AI20+(U21*1.9835) -> 7226.295 | AJ21: 0
A22: =A21+1 -> 11 | B22: 6876.39 | C22: 205542 | D22: =C22-C21 -> -29 | E22: =C22-152000 -> 53542 | F22: =D22/$D$2 -> -14.62062 | G22: 58 | H22: 0.73 | I22: =G22+H22 -> 58.73 | J22: =IF(L22>0,L22,0) -> 5.2493799 | K22: =I22+J22 -> 63.97938 | L22: =F22-(I22-AC22) -> 5.2493799 | M22: 4.6 | N22: 0 | O22: 0 | P22: =1.44*1.02 -> 1.4688 | Q22: =2.15*1.04 -> 2.236 | R22: 0 | S22: 51 | T22: 0 | U22: =M22-N22-P22-Q22-R22+S22+T22 -> 51.8952 | AA22: 23 | AB22: =AB21-AA22 -> 2997 | AC22: =N22+O22+P22+Q22+R22+U22+X22+AA22 -> 78.6 | AD22: =IF(L22<0,L22*-1,0) -> 0 | AE22: =AC22+AD22 -> 78.6 | AF22: 0 | AG22: 52 | AH22: 26 | AI22: =AI21+(U22*1.9835) -> 7329.2291 | AJ22: 0
A23: =A22+1 -> 12 | B23: 6876.38 | C23: 205513 | D23: =C23-C22 -> -29 | E23: =C23-152000 -> 53513 | F23: =D23/$D$2 -> -14.62062 | G23: 64 | H23: 0.8 | I23: =G23+H23 -> 64.8 | J23: =IF(L23>0,L23,0) -> 0 | K23: =I23+J23 -> 64.8 | L23: =F23-(I23-AC23) -> -0.82062012 | M23: 4.6 | N23: 0 | O23: 0 | P23: =1.44*1.02 -> 1.4688 | Q23: =2.12*1.04 -> 2.2048 | R23: 0 | S23: 51 | T23: 0 | U23: =M23-N23-P23-Q23-R23+S23+T23 -> 51.9264 | AA23: 23 | AB23: =AB22-AA23 -> 2974 | AC23: =N23+O23+P23+Q23+R23+U23+X23+AA23 -> 78.6 | AD23: =IF(L23<0,L23*-1,0) -> 0.82062012 | AE23: =AC23+AD23 -> 79.42062 | AF23: 0 | AG23: 53 | AH23: 25 | AI23: =AI22+(U23*1.9835) -> 7432.2251 | AJ23: 0
A24: =A23+1 -> 13 | B24: 6876.37 | C24: 205484 | D24: =C24-C23 -> -29 | E24: =C24-152000 -> 53484 | F24: =D24/$D$2 -> -14.62062 | G24: 64 | H24: 0.79 | I24: =G24+H24 -> 64.79 | J24: =IF(L24>0,L24,0) -> 0.18937988 | K24: =I24+J24 -> 64.97938 | L24: =F24-(I24-AC24) -> 0.18937988 | M24: 4.6 | N24: 0 | O24: 0 | P24: =1.44*1.02 -> 1.4688 | Q24: =2*1.04 -> 2.08 | R24: 0 | S24: 51 | T24: 0 | U24: =M24-N24-P24-Q24-R24+S24+T24 -> 52.0512 | AA24: 24 | AB24: =AB23-AA24 -> 2950 | AC24: =N24+O24+P24+Q24+R24+U24+X24+AA24 -> 79.6 | AD24: =IF(L24<0,L24*-1,0) -> 0 | AE24: =AC24+AD24 -> 79.6 | AF24: 0 | AG24: 49 | AH24: 24 | AI24: =AI23+(U24*1.9835) -> 7535.4687 | AJ24: 0
A25: =A24+1 -> 14 | B25: 6876.36 | C25: 205455 | D25: =C25-C24 -> -29 | E25: =C25-152000 -> 53455 | F25: =D25/$D$2 -> -14.62062 | G25: 55 | H25: 0.77 | I25: =G25+H25 -> 55.77 | J25: =IF(L25>0,L25,0) -> 10.20938 | K25: =I25+J25 -> 65.97938 | L25: =F25-(I25-AC25) -> 10.20938 | M25: 4.6 | N25: 0 | O25: 0 | P25: =1.44*1.02 -> 1.4688 | Q25: =2.5*1.04 -> 2.6 | R25: 0 | S25: 51 | T25: 0 | U25: =M25-N25-P25-Q25-R25+S25+T25 -> 51.5312 | AA25: 25 | AB25: =AB24-AA25 -> 2925 | AC25: =N25+O25+P25+Q25+R25+U25+X25+AA25 -> 80.6 | AD25: =IF(L25<0,L25*-1,0) -> 0 | AE25: =AC25+AD25 -> 80.6 | AF25: 0 | AG25: 47 | AH25: 24 | AI25: =AI24+(U25*1.9835) -> 7637.6808 | AJ25: 0
A26: =A25+1 -> 15 | B26: 6876.36 | C26: 205455 | D26: =C26-C25 -> 0 | E26: =C26-152000 -> 53455 | F26: =D26/$D$2 -> 0 | G26: 55 | H26: 0.77 | I26: =G26+H26 -> 55.77 | J26: =IF(L26>0,L26,0) -> 24.13 | K26: =I26+J26 -> 79.9 | L26: =F26-(I26-AC26) -> 24.13 | M26: 4.9 | N26: 0 | O26: 0 | P26: =1.44*1.02 -> 1.4688 | Q26: =2.05*1.04 -> 2.132 | R26: 0 | S26: 51 | T26: 0 | U26: =M26-N26-P26-Q26-R26+S26+T26 -> 52.2992 | AA26: 24 | AB26: =AB25-AA26 -> 2901 | AC26: =N26+O26+P26+Q26+R26+U26+X26+AA26 -> 79.9 | AD26: =IF(L26<0,L26*-1,0) -> 0 | AE26: =AC26+AD26 -> 79.9 | AF26: 0 | AG26: 45 | AH26: 22 | AI26: =AI25+(U26*1.9835) -> 7741.4163 | AJ26: 0
A27: =A26+1 -> 16 | B27: 6876.36 | C27: 205455 | D27: =C27-C26 -> 0 | E27: =C27-152000 -> 53455 | F27: =D27/$D$2 -> 0 | G27: 45 | H27: 0.76 | I27: =G27+H27 -> 45.76 | J27: =IF(L27>0,L27,0) -> 35.44 | K27: =I27+J27 -> 81.2 | L27: =F27-(I27-AC27) -> 35.44 | M27: 5.2 | N27: 0 | O27: 0 | P27: =1.44*1.02 -> 1.4688 | Q27: =2.2*1.04 -> 2.288 | R27: 0 | S27: 51 | T27: 0 | U27: =M27-N27-P27-Q27-R27+S27+T27 -> 52.4432 | AA27: 25 | AB27: =AB26-AA27 -> 2876 | AC27: =N27+O27+P27+Q27+R27+U27+X27+AA27 -> 81.2 | AD27: =IF(L27<0,L27*-1,0) -> 0 | AE27: =AC27+AD27 -> 81.2 | AF27: 0 | AG27: 42 | AH27: 24 | AI27: =AI26+(U27*1.9835) -> 7845.4374 | AJ27: 0
A28: =A27+1 -> 17 | B28: 6876.35 | C28: 205426 | D28: =C28-C27 -> -29 | E28: =C28-152000 -> 53426 | F28: =D28/$D$2 -> -14.62062 | G28: 51 | H28: 0.68 | I28: =G28+H28 -> 51.68 | J28: =IF(L28>0,L28,0) -> 14.59938 | K28: =I28+J28 -> 66.27938 | L28: =F28-(I28-AC28) -> 14.59938 | M28: 4.9 | N28: 0 | O28: 0 | P28: =1.44*1.02 -> 1.4688 | Q28: =2.36*1.04 -> 2.4544 | R28: 0 | S28: 51 | T28: 0 | U28: =M28-N28-P28-Q28-R28+S28+T28 -> 51.9768 | AA28: 25 | AB28: =AB27-AA28 -> 2851 | AC28: =N28+O28+P28+Q28+R28+U28+X28+AA28 -> 80.9 | AD28: =IF(L28<0,L28*-1,0) -> 0 | AE28: =AC28+AD28 -> 80.9 | AF28: 0 | AG28: 41 | AH28: 19 | AI28: =AI27+(U28*1.9835) -> 7948.5334 | AJ28: 0
A29: =A28+1 -> 18 | B29: 6876.34 | C29: 205397 | D29: =C29-C28 -> -29 | E29: =C29-152000 -> 53397 | F29: =D29/$D$2 -> -14.62062 | G29: 45 | H29: 0.58 | I29: =G29+H29 -> 45.58 | J29: =IF(L29>0,L29,0) -> 20.69938 | K29: =I29+J29 -> 66.27938 | L29: =F29-(I29-AC29) -> 20.69938 | M29: 4.9 | N29: 0 | O29: 0 | P29: =1.44*1.02 -> 1.4688 | Q29: =2.27*1.04 -> 2.3608 | R29: 0 | S29: 51 | T29: 0 | U29: =M29-N29-P29-Q29-R29+S29+T29 -> 52.0704 | AA29: 25 | AB29: =AB28-AA29 -> 2826 | AC29: =N29+O29+P29+Q29+R29+U29+X29+AA29 -> 80.9 | AD29: =IF(L29<0,L29*-1,0) -> 0 | AE29: =AC29+AD29 -> 80.9 | AF29: 0 | AG29: 46 | AH29: 24 | AI29: =AI28+(U29*1.9835) -> 8051.815 | AJ29: 0
A30: =A29+1 -> 19 | B30: 6876.33 | C30: 205368 | D30: =C30-C29 -> -29 | E30: =C30-152000 -> 53368 | F30: =D30/$D$2 -> -14.62062 | G30: 45 | H30: 0.51 | I30: =G30+H30 -> 45.51 | J30: =IF(L30>0,L30,0) -> 20.76938 | K30: =I30+J30 -> 66.27938 | L30: =F30-(I30-AC30) -> 20.76938 | M30: 4.9 | N30: 0 | O30: 0 | P30: =1.44*1.02 -> 1.4688 | Q30: =2.18*1.04 -> 2.2672 | R30: 0 | S30: 51 | T30: 0 | U30: =M30-N30-P30-Q30-R30+S30+T30 -> 52.164 | AA30: 25 | AB30: =AB29-AA30 -> 2801 | AC30: =N30+O30+P30+Q30+R30+U30+X30+AA30 -> 80.9 | AD30: =IF(L30<0,L30*-1,0) -> 0 | AE30: =AC30+AD30 -> 80.9 | AF30: 0 | AG30: 48 | AH30: 22 | AI30: =AI29+(U30*1.9835) -> 8155.2823 | AJ30: 0
A31: =A30+1 -> 20 | B31: 6876.31 | C31: 205311 | D31: =C31-C30 -> -57 | E31: =C31-152000 -> 53311 | F31: =D31/$D$2 -> -28.737081 | G31: 50 | H31: 0.44 | I31: =G31+H31 -> 50.44 | J31: =IF(L31>0,L31,0) -> 1.7229191 | K31: =I31+J31 -> 52.162919 | L31: =F31-(I31-AC31) -> 1.7229191 | M31: 4.9 | N31: 0 | O31: 0 | P31: =1.44*1.02 -> 1.4688 | Q31: =2.39*1.04 -> 2.4856 | R31: 0 | S31: 51 | T31: 0 | U31: =M31-N31-P31-Q31-R31+S31+T31 -> 51.9456 | AA31: 25 | AB31: =AB30-AA31 -> 2776 | AC31: =N31+O31+P31+Q31+R31+U31+X31+AA31 -> 80.9 | AD31: =IF(L31<0,L31*-1,0) -> 0 | AE31: =AC31+AD31 -> 80.9 | AF31: 0 | AG31: 48 | AH31: 22 | AI31: =AI30+(U31*1.9835) -> 8258.3164 | AJ31: 0
A32: =A31+1 -> 21 | B32: 6876.28 | C32: 205224 | D32: =C32-C31 -> -87 | E32: =C32-152000 -> 53224 | F32: =D32/$D$2 -> -43.86186 | G32: 44 | H32: 0.43 | I32: =G32+H32 -> 44.43 | J32: =IF(L32>0,L32,0) -> 0 | K32: =I32+J32 -> 44.43 | L32: =F32-(I32-AC32) -> -1.4918603 | M32: 4.8 | N32: 0 | O32: 0 | P32: =1.44*1.02 -> 1.4688 | Q32: =2.18*1.04 -> 2.2672 | R32: 0 | S32: 57 | T32: 0 | U32: =M32-N32-P32-Q32-R32+S32+T32 -> 58.064 | AA32: 25 | AB32: =AB31-AA32 -> 2751 | AC32: =N32+O32+P32+Q32+R32+U32+X32+AA32 -> 86.8 | AD32: =IF(L32<0,L32*-1,0) -> 1.4918603 | AE32: =AC32+AD32 -> 88.29186 | AF32: 0 | AG32: 41 | AH32: 20 | AI32: =AI31+(U32*1.9835) -> 8373.4863 | AJ32: 0
A33: =A32+1 -> 22 | B33: 6876.26 | C33: 205166 | D33: =C33-C32 -> -58 | E33: =C33-152000 -> 53166 | F33: =D33/$D$2 -> -29.24124 | G33: 24 | H33: 0.34 | I33: =G33+H33 -> 24.34 | J33: =IF(L33>0,L33,0) -> 36.01876 | K33: =I33+J33 -> 60.35876 | L33: =F33-(I33-AC33) -> 36.01876 | M33: 4.6 | N33: 0 | O33: 0 | P33: =1.44*1.02 -> 1.4688 | Q33: =2.27*1.04 -> 2.3608 | R33: 0 | S33: 60 | T33: 0 | U33: =M33-N33-O33-P33-Q33-R33+S33+T33 -> 60.7704 | AA33: 25 | AB33: =AB32-AA33 -> 2726 | AC33: =N33+O33+P33+Q33+R33+U33+X33+AA33 -> 89.6 | AD33: =IF(L33<0,L33*-1,0) -> 0 | AE33: =AC33+AD33 -> 89.6 | AF33: 0 | AG33: 32 | AH33: 14 | AI33: =AI32+(U33*1.9835) -> 8494.0244 | AJ33: 0
A34: =A33+1 -> 23 | B34: 6876.23 | C34: 205080 | D34: =C34-C33 -> -86 | E34: =C34-152000 -> 53080 | F34: =D34/$D$2 -> -43.357701 | G34: 14 | H34: 0.34 | I34: =G34+H34 -> 14.34 | J34: =IF(L34>0,L34,0) -> 31.902299 | K34: =I34+J34 -> 46.242299 | L34: =F34-(I34-AC34) -> 31.902299 | M34: 4.6 | N34: 0 | O34: 0 | P34: =1.44*1.02 -> 1.4688 | Q34: =2.35*1.04 -> 2.444 | R34: 0 | S34: 60 | T34: 0 | U34: =M34-N34-O34-P34-Q34-R34+S34+T34 -> 60.6872 | AA34: 25 | AB34: =AB33-AA34 -> 2701 | AC34: =N34+O34+P34+Q34+R34+U34+X34+AA34 -> 89.6 | AD34: =IF(L34<0,L34*-1,0) -> 0 | AE34: =AC34+AD34 -> 89.6 | AF34: 0 | AG34: 26 | AH34: 7 | AI34: =AI33+(U34*1.9835) -> 8614.3975 | AJ34: 0
A35: =A34+1 -> 24 | B35: 6876.2 | C35: 204993 | D35: =C35-C34 -> -87 | E35: =C35-152000 -> 52993 | F35: =D35/$D$2 -> -43.86186 | G35: 22 | H35: 0.34 | I35: =G35+H35 -> 22.34 | J35: =IF(L35>0,L35,0) -> 23.69814 | K35: =I35+J35 -> 46.03814 | L35: =F35-(I35-AC35) -> 23.69814 | M35: 4.9 | N35: 0 | O35: 0 | P35: =1.44*1.02 -> 1.4688 | Q35: =1.99*1.04 -> 2.0696 | R35: 0 | S35: 60 | T35: 0 | U35: =M35-N35-O35-P35-Q35-R35+S35+T35 -> 61.3616 | AA35: 25 | AB35: =AB34-AA35 -> 2676 | AC35: =N35+O35+P35+Q35+R35+U35+X35+AA35 -> 89.9 | AD35: =IF(L35<0,L35*-1,0) -> 0 | AE35: =AC35+AD35 -> 89.9 | AF35: 0 | AG35: 33 | AH35: 6 | AI35: =AI34+(U35*1.9835) -> 8736.1082 | AJ35: 0
A36: =A35+1 -> 25 | B36: 6876.17 | C36: 204906 | D36: =C36-C35 -> -87 | E36: =C36-152000 -> 52906 | F36: =D36/$D$2 -> -43.86186 | G36: 30 | H36: 0.18 | I36: =G36+H36 -> 30.18 | J36: =IF(L36>0,L36,0) -> 15.85814 | K36: =I36+J36 -> 46.03814 | L36: =F36-(I36-AC36) -> 15.85814 | M36: 4.9 | N36: 0 | O36: 0 | P36: =1.44*1.02 -> 1.4688 | Q36: =2.38*1.04 -> 2.4752 | R36: 0 | S36: 60 | T36: 0 | U36: =M36-N36-O36-P36-Q36-R36+S36+T36 -> 60.956 | AA36: 25 | AB36: =AB35-AA36 -> 2651 | AC36: =N36+O36+P36+Q36+R36+U36+X36+AA36 -> 89.9 | AD36: =IF(L36<0,L36*-1,0) -> 0 | AE36: =AC36+AD36 -> 89.9 | AF36: 0 | AG36: 43 | AH36: 6 | AI36: =AI35+(U36*1.9835) -> 8857.0144 | AJ36: 0
A37: =A36+1 -> 26 | B37: 6876.13 | C37: 204791 | D37: =C37-C36 -> -115 | E37: =C37-152000 -> 52791 | F37: =D37/$D$2 -> -57.978321 | G37: 36 | H37: 0.09 | I37: =G37+H37 -> 36.09 | J37: =IF(L37>0,L37,0) -> 0 | K37: =I37+J37 -> 36.09 | L37: =F37-(I37-AC37) -> -3.9683211 | M37: 5.1 | N37: 0 | O37: 0 | P37: =1.44*1.02 -> 1.4688 | Q37: =2.08*1.04 -> 2.1632 | R37: 0 | S37: 60 | T37: 0 | U37: =M37-N37-O37-P37-Q37-R37+S37+T37 -> 61.468 | AA37: 25 | AB37: =AB36-AA37 -> 2626 | AC37: =N37+O37+P37+Q37+R37+U37+X37+AA37 -> 90.1 | AD37: =IF(L37<0,L37*-1,0) -> 3.9683211 | AE37: =AC37+AD37 -> 94.068321 | AF37: 0 | AG37: 51 | AH37: 20 | AI37: =AI36+(U37*1.9835) -> 8978.9362 | AJ37: 0
A38: =A37+1 -> 27 | B38: 6876.12 | C38: 204762 | D38: =C38-C37 -> -29 | E38: =C38-152000 -> 52762 | F38: =D38/$D$2 -> -14.62062 | G38: 42 | H38: 0.05 | I38: =G38+H38 -> 42.05 | J38: =IF(L38>0,L38,0) -> 33.52938 | K38: =I38+J38 -> 75.57938 | L38: =F38-(I38-AC38) -> 33.52938 | M38: 5.2 | N38: 0 | O38: 0 | P38: =1.44*1.02 -> 1.4688 | Q38: =1.93*1.04 -> 2.0072 | R38: 0 | S38: 60 | T38: 0 | U38: =M38-N38-O38-P38-Q38-R38+S38+T38 -> 61.724 | AA38: 25 | AB38: =AB37-AA38 -> 2601 | AC38: =N38+O38+P38+Q38+R38+U38+X38+AA38 -> 90.2 | AD38: =IF(L38<0,L38*-1,0) -> 0 | AE38: =AC38+AD38 -> 90.2 | AF38: 0 | AG38: 50 | AH38: 28 | AI38: =AI37+(U38*1.9835) -> 9101.3658 | AJ38: 0
A39: =A38+1 -> 28 | B39: 6876.11 | C39: 204733 | D39: =C39-C38 -> -29 | E39: =C39-152000 -> 52733 | F39: =D39/$D$2 -> -14.62062 | G39: 64 | H39: 0.1 | I39: =G39+H39 -> 64.1 | J39: =IF(L39>0,L39,0) -> 11.27938 | K39: =I39+J39 -> 75.37938 | L39: =F39-(I39-AC39) -> 11.27938 | M39: 5 | N39: 0 | O39: 0 | P39: =1.44*1.02 -> 1.4688 | Q39: =2.14*1.04 -> 2.2256 | R39: 0 | S39: 60 | T39: 0 | U39: =M39-N39-O39-P39-Q39-R39+S39+T39 -> 61.3056 | AA39: 25 | AB39: =AB38-AA39 -> 2576 | AC39: =N39+O39+P39+Q39+R39+U39+X39+AA39 -> 90 | AD39: =IF(L39<0,L39*-1,0) -> 0 | AE39: =AC39+AD39 -> 90 | AF39: 0.02 | AG39: 51 | AH39: 28 | AI39: =AI38+(U39*1.9835) -> 9222.9654 | AJ39: 0
A40: =A39+1 -> 29 | B40: 6876.18 | C40: 204935 | D40: =C40-C39 -> 202 | E40: =C40-152000 -> 52935 | F40: =D40/$D$2 -> 101.84018 | G40: 98 | H40: 0.43 | I40: =G40+H40 -> 98.43 | J40: =IF(L40>0,L40,0) -> 94.010181 | K40: =I40+J40 -> 192.44018 | L40: =F40-(I40-AC40) -> 94.010181 | M40: 4.6 | N40: 0 | O40: 0 | P40: =1.44*1.02 -> 1.4688 | Q40: =2.39*1.04 -> 2.4856 | R40: 0 | S40: 60 | T40: 0 | U40: =M40-N40-O40-P40-Q40-R40+S40+T40 -> 60.6456 | AA40: 26 | AB40: =AB39-AA40 -> 2550 | AC40: =N40+O40+P40+Q40+R40+U40+X40+AA40 -> 90.6 | AD40: =IF(L40<0,L40*-1,0) -> 0 | AE40: =AC40+AD40 -> 90.6 | AF40: 0.58 | AG40: 46 | AH40: 32 | AI40: =AI39+(U40*1.9835) -> 9343.256 | AJ40: 0
A41: 30 | B41: 6876.21 | C41: 205022 | D41: =C41-C40 -> 87 | E41: =C41-152000 -> 53022 | F41: =D41/$D$2 -> 43.86186 | G41: 76 | H41: 0.98 | I41: =G41+H41 -> 76.98 | J41: =IF(L41>0,L41,0) -> 56.48186 | K41: =I41+J41 -> 133.46186 | L41: =F41-(I41-AC41) -> 56.48186 | M41: 4.6 | N41: 0 | O41: 0 | P41: =1.44*1.02 -> 1.4688 | Q41: =2.51*1.04 -> 2.6104 | R41: 0 | S41: 60 | T41: 0 | U41: =M41-N41-O41-P41-Q41-R41+S41+T41 -> 60.5208 | AA41: 25 | AB41: =AB40-AA41 -> 2525 | AC41: =N41+O41+P41+Q41+R41+U41+X41+AA41 -> 89.6 | AD41: =IF(L41<0,L41*-1,0) -> 0 | AE41: =AC41+AD41 -> 89.6 | AF41: 0 | AG41: 42 | AH41: 29 | AI41: =AI40+(U41*1.9835) -> 9463.299 | AJ41: 0
A42: 31 | B42: 6876.25 | C42: 205137 | D42: =C42-C41 -> 115 | E42: =C42-152000 -> 53137 | F42: =D42/$D$2 -> 57.978321 | G42: 64 | H42: 0.78 | I42: =G42+H42 -> 64.78 | J42: =IF(L42>0,L42,0) -> 82.998321 | K42: =I42+J42 -> 147.77832 | L42: =F42-(I42-AC42) -> 82.998321 | M42: 4.8 | N42: 0 | O42: 0 | P42: =1.44*1.02 -> 1.4688 | Q42: =2.41*1.04 -> 2.5064 | R42: 0 | S42: 60 | T42: 0 | U42: =M42-N42-O42-P42-Q42-R42+S42+T42 -> 60.8248 | AA42: 25 | AB42: =AB41-AA42 -> 2500 | AC42: =N42+O42+P42+Q42+R42+U42+X42+AA42 -> 89.8 | AD42: =IF(L42<0,L42*-1,0) -> 0 | AE42: =AC42+AD42 -> 89.8 | AF42: 0 | AG42: 45 | AH42: 32 | AI42: =AI41+(U42*1.9835) -> 9583.945 | AJ42: 0
...

Sheet JAN
K1: MCPHEE RESERVOIR INFLOW/OUTFLOW TABULATION
A2: AF/cfs CONVERT FACTOR | D2: 1.9835 | K2: JANUARY "2005"
D4: RESERVOIR | S4: INFLOW/OUTFLOW (CFS) | AG4: WEATHER | AK4: ADJUSTMENTS
A5: DATE | B5: RESERV | C5: RESERV | D5: AC FT | E5: ACTIVE | F5: CONV TO | G5: DOLORES | H5: LOST | I5: RECORD | J5: CALC | K5: TOTAL | L5: CALC | M5: DOLORES TUNNEL | S5: LONE | T5: U | U5: TOTAL | V5: MVI | W5: MVI | X5: DV CR | Y5: D/S SENIOR | AA5: BELOW | AB5: FISH | AC5: RECORD | AD5: CALC | AE5: TOTAL | AF5: RAIN | AG5: MAX | AH5: MIN | AI5: NAR | AJ5: MVI | AK5: MVI | AL5: MVI | AM5: U/S | AN5: TOTTEN
A6: JAN | B6: ELEV | C6: AC FT | D6: CHANGE | E6: CAP | F6: CFS | G6: RIVER | H6: CAN | I6: INFLOW | J6: INFLOW | K6: INFLOW | L6: INF/OTF | M6: TOT DIV | N6: WET | O6: UTE | P6: MWC | Q6: CTZ | R6: CTZ & | S6: PINE | T6: LAT | U6: MVI | V6: CALL | W6: PROJ & | X6: CANAL | AA6: MCP | AB6: LEFT | AC6: OTF | AD6: OTF | AE6: OTF | AG6: TMP | AH6: TMP | AI6: CALL | AJ6: STOCK | AK6: STORED | AL6: STORED | AM6: USERS | AN6: (FRESH
E7: AC FT | N7: LAND | O7: F&R | R7: UTE | W7: TO EX & | AI7: AC.FT. | AJ7: AC.FT. | AK7: Apr-Jun | AL7: EVAP | AM7: EXCH | AN7: WATER)
N8: 1.03 | O8: 1.05 | P8: 1.02 | Q8: 1.04 | R8: PROJ | W8: U/S EX | AL8: AC.FT.
A9: SEASON BAL
A10: YTD | B10: =DEC!B42 -> 6876.25 | C10: =DEC!C42 -> 205137 | D10: =DEC!D51 -> -2109 | E10: =DEC!E51 -> 53137 | F10: =DEC!F50 -> -1063.272 | G10: =DEC!G50 -> 4820 | H10: =DEC!H50 -> 18.74 | I10: =DEC!I50 -> 4838.74 | J10: =DEC!J50 -> 1443.9912 | K10: =DEC!K50 -> 6282.7312 | L10: =DEC!L50 -> 938.48801 | M10: =DEC!M50 -> 363.7 | ... U10: =DEC!U50 -> 5058.3868 | AA10: =DEC!AA50 -> 1551 | AB10: =DEC!AB50 -> 2500 | AC10: =DEC!AC50 -> 6840.5 | AD10: =DEC!AD50 -> 505.50323 | AE10: =DEC!AE50 -> 7346.0032 | AF10: =DEC!AF50 -> 2.99 | AI10: =DEC!AI51 -> 9583.945
A12: 1 | B12: 6876.26 | C12: 205166 | D12: =C12-C10 -> 29 | E12: =C12-152000 -> 53166 | F12: =D12/$D$2 -> 14.62062 | G12: 50 | H12: 1 | I12: =G12+H12 -> 51 | J12: =IF(L12>0,L12,0) -> 53.52062 | K12: =I12+J12 -> 104.52062 | L12: =F12-(I12-AC12) -> 53.52062 | M12: 4.9 | N12: 0 | O12: 0 | P12: =1.55*1.02 -> 1.581 | Q12: =4.2 -> 4.2 | R12: 0.97 | S12: 60 | U12: =M12-N12-O12-P12-Q12-R12+S12+T12 -> 58.149 | AA12: 25 | AB12: =AB10-AA12 -> 2475 | AC12: =N12+O12+P12+Q12+R12+U12+X12+AA12 -> 89.9 | AD12: =IF(L12<0,L12*-1,0) -> 0 | AE12: =AC12+AD12 -> 89.9 | AF12: 0 | AG12: 43 | AH12: 26.25 | AI12: =AI10+(U12*1.9835) -> 9699.2835 | AJ12: 0
A13: =A12+1 -> 2 | B13: 6876.23 | C13: 205080 | D13: =C13-C12 -> -86 | E13: =C13-152000 -> 53080 | F13: =D13/$D$2 -> -43.357701 | G13: 50 | H13: 1.1 | I13: =G13+H13 -> 51.1 | J13: =IF(L13>0,L13,0) -> 0 | K13: =I13+J13 -> 51.1 | L13: =F13-(I13-AC13) -> -4.557701 | M13: 4.9 | N13: 0 | O13: 0 | P13: =1.55*1.02 -> 1.581 | Q13: =2.2*1.04 -> 2.288 | R13: 0 | S13: 60 | U13: =M13-N13-O13-P13-Q13-R13+S13+T13 -> 61.031 | AA13: 25 | AB13: =AB12-AA13 -> 2450 | AC13: =N13+O13+P13+Q13+R13+U13+X13+AA13 -> 89.9 | AD13: =IF(L13<0,L13*-1,0) -> 4.557701 | AE13: =AC13+AD13 -> 94.457701 | AF13: 0 | AG13: 45 | AH13: 25 | AI13: =AI12+(U13*1.9835) -> 9820.3385 | AJ13: 0
A14: =A13+1 -> 3 | B14: 6876.22 | C14: 205051 | D14: =C14-C13 -> -29 | E14: =C14-152000 -> 53051 | F14: =D14/$D$2 -> -14.62062 | G14: 57 | H14: 1.2 | I14: =G14+H14 -> 58.2 | J14: =IF(L14>0,L14,0) -> 20.07938 | K14: =I14+J14 -> 78.27938 | L14: =F14-(I14-AC14) -> 20.07938 | M14: 4.9 | N14: 0 | O14: 0 | P14: =1.55*1.02 -> 1.581 | Q14: =2.47*1.04 -> 2.5688 | R14: 0 | S14: 63 | U14: =M14-N14-O14-P14-Q14-R14+S14+T14 -> 63.7502 | AA14: 25 | AB14: =AB13-AA14 -> 2425 | AC14: =N14+O14+P14+Q14+R14+U14+X14+AA14 -> 92.9 | AD14: =IF(L14<0,L14*-1,0) -> 0 | AE14: =AC14+AD14 -> 92.9 | AF14: 0.06 | AG14: 41 | AH14: 29 | AI14: =AI13+(U14*1.9835) -> 9946.787 | AJ14: 0
A15: =A14+1 -> 4 | B15: 6876.3 | C15: 205282 | D15: =C15-C14 -> 231 | E15: =C15-152000 -> 53282 | F15: =D15/$D$2 -> 116.4608 | G15: 47 | H15: 1.3 | I15: =G15+H15 -> 48.3 | J15: =IF(L15>0,L15,0) -> 172.0608 | K15: =I15+J15 -> 220.3608 | L15: =F15-(I15-AC15) -> 172.0608 | M15: 4.9 | N15: 0 | O15: 0 | P15: =1.55*1.02 -> 1.581 | Q15: =2.41*1.04 -> 2.5064 | R15: 0 | S15: 74 | U15: =M15-N15-O15-P15-Q15-R15+S15+T15 -> 74.8126 | AA15: 25 | AB15: =AB14-AA15 -> 2400 | AC15: =N15+O15+P15+Q15+R15+U15+X15+AA15 -> 103.9 | AD15: =IF(L15<0,L15*-1,0) -> 0 | AE15: =AC15+AD15 -> 103.9 | AF15: 0.6 | AG15: 39 | AH15: 28 | AI15: =AI14+(U15*1.9835) -> 10095.178 | AJ15: 0
A16: =A15+1 -> 5 | B16: 6876.31 | C16: 205311 | D16: =C16-C15 -> 29 | E16: =C16-152000 -> 53311 | F16: =D16/$D$2 -> 14.62062 | G16: 51 | H16: 2.5 | I16: =G16+H16 -> 53.5 | J16: =IF(L16>0,L16,0) -> 66.22062 | K16: =I16+J16 -> 119.72062 | L16: =F16-(I16-AC16) -> 66.22062 | M16: 5.1 | N16: 0 | O16: 0 | P16: =1.55*1.02 -> 1.581 | Q16: =2.13*1.04 -> 2.2152 | R16: 0 | S16: 76 | U16: =M16-N16-O16-P16-Q16-R16+S16+T16 -> 77.3038 | AA16: 24 | AB16: =AB15-AA16 -> 2376 | AC16: =N16+O16+P16+Q16+R16+U16+X16+AA16 -> 105.1 | AD16: =IF(L16<0,L16*-1,0) -> 0 | AE16: =AC16+AD16 -> 105.1 | AF16: 0.45 | AG16: 31 | AH16: 23 | AI16: =AI15+(U16*1.9835) -> 10248.51 | AJ16: 0
A17: =A16+1 -> 6 | B17: 6876.28 | C17: 205224 | D17: =C17-C16 -> -87 | E17: =C17-152000 -> 53224 | F17: =D17/$D$2 -> -43.86186 | G17: 42 | H17: 1.7 | I17: =G17+H17 -> 43.7 | J17: =IF(L17>0,L17,0) -> 17.63814 | K17: =I17+J17 -> 61.33814 | L17: =F17-(I17-AC17) -> 17.63814 | M17: 5.2 | N17: 0 | O17: 0 | P17: =1.55*1.02 -> 1.581 | Q17: =2.39*1.04 -> 2.4856 | R17: 0 | S17: 76 | U17: =M17-N17-O17-P17-Q17-R17+S17+T17 -> 77.1334 | AA17: 24 | AB17: =AB16-AA17 -> 2352 | AC17: =N17+O17+P17+Q17+R17+U17+X17+AA17 -> 105.2 | AD17: =IF(L17<0,L17*-1,0) -> 0 | AE17: =AC17+AD17 -> 105.2 | AF17: 0.06 | AG17: 28 | AH17: 12 | AI17: =AI16+(U17*1.9835) -> 10401.504 | AJ17: 0
A18: =A17+1 -> 7 | B18: 6876.26 | C18: 205166 | D18: =C18-C17 -> -58 | E18: =C18-152000 -> 53166 | F18: =D18/$D$2 -> -29.24124 | G18: 44 | H18: 1.4 | I18: =G18+H18 -> 45.4 | J18: =IF(L18>0,L18,0) -> 30.55876 | K18: =I18+J18 -> 75.95876 | L18: =F18-(I18-AC18) -> 30.55876 | M18: 5.2 | N18: 0 | O18: 0 | P18: =1.55*1.02 -> 1.581 | Q18: =2.63*1.04 -> 2.7352 | R18: 0 | S18: 76 | U18: =M18-N18-O18-P18-Q18-R18+S18+T18 -> 76.8838 | AA18: 24 | AB18: =AB17-AA18 -> 2328 | AC18: =N18+O18+P18+Q18+R18+U18+X18+AA18 -> 105.2 | AD18: =IF(L18<0,L18*-1,0) -> 0 | AE18: =AC18+AD18 -> 105.2 | AF18: 0.06 | AG18: 28 | AH18: 12 | AI18: =AI17+(U18*1.9835) -> 10554.003 | AJ18: 0
A19: =A18+1 -> 8 | B19: 6876.28 | C19: 205224 | D19: =C19-C18 -> 58 | E19: =C19-152000 -> 53224 | F19: =D19/$D$2 -> 29.24124 | G19: 41 | H19: 1.2 | I19: =G19+H19 -> 42.2 | J19: =IF(L19>0,L19,0) -> 92.04124 | K19: =I19+J19 -> 134.24124 | L19: =F19-(I19-AC19) -> 92.04124 | M19: 5 | N19: 0 | O19: 0 | P19: =1.55*1.02 -> 1.581 | Q19: =1.91*1.04 -> 1.9864 | R19: 0 | S19: 76 | U19: =M19-N19-O19-P19-Q19-R19+S19+T19 -> 77.4326 | AA19: 24 | AB19: =AB18-AA19 -> 2304 | AC19: =N19+O19+P19+Q19+R19+U19+X19+AA19 -> 105 | AD19: =IF(L19<0,L19*-1,0) -> 0 | AE19: =AC19+AD19 -> 105 | AF19: 0.23 | AG19: 38 | AH19: 26 | AI19: =AI18+(U19*1.9835) -> 10707.591 | AJ19: 0
A20: =A19+1 -> 9 | B20: 6876.3 | C20: 205282 | D20: =C20-C19 -> 58 | E20: =C20-152000 -> 53282 | F20: =D20/$D$2 -> 29.24124 | G20: 72 | H20: 1.3 | I20: =G20+H20 -> 73.3 | J20: =IF(L20>0,L20,0) -> 61.94124 | K20: =I20+J20 -> 135.24124 | L20: =F20-(I20-AC20) -> 61.94124 | M20: 5 | N20: 0 | O20: 0 | P20: =1.55*1.02 -> 1.581 | Q20: =2.33*1.04 -> 2.4232 | R20: 0 | S20: 76 | U20: =M20-N20-O20-P20-Q20-R20+S20+T20 -> 76.9958 | AA20: 25 | AB20: =AB19-AA20 -> 2279 | AC20: =N20+O20+P20+Q20+R20+U20+X20+AA20 -> 106 | AD20: =IF(L20<0,L20*-1,0) -> 0 | AE20: =AC20+AD20 -> 106 | AF20: 0.46 | AG20: 41 | AH20: 34 | AI20: =AI19+(U20*1.9835) -> 10860.312 | AJ20: 0
A21: =A20+1 -> 10 | B21: 6876.41 | C21: 205599 | D21: =C21-C20 -> 317 | E21: =C21-152000 -> 53599 | F21: =D21/$D$2 -> 159.8185 | G21: 103 | H21: 2.2 | I21: =G21+H21 -> 105.2 | J21: =IF(L21>0,L21,0) -> 162.0185 | K21: =I21+J21 -> 267.2185 | L21: =F21-(I21-AC21) -> 162.0185 | M21: 5.4 | N21: 0 | O21: 0 | P21: =1.55*1.02 -> 1.581 | Q21: =2.3*1.04 -> 2.392 | R21: 0 | S21: 77 | U21: =M21-N21-O21-P21-Q21-R21+S21+T21 -> 78.427 | AA21: 25 | AB21: =AB20-AA21 -> 2254 | AC21: =N21+O21+P21+Q21+R21+U21+X21+AA21 -> 107.4 | AD21: =IF(L21<0,L21*-1,0) -> 0 | AE21: =AC21+AD21 -> 107.4 | AF21: 0.72 | AG21: 45 | AH21: 34 | AI21: =AI20+(U21*1.9835) -> 11015.872 | AJ21: 0
A22: =A21+1 -> 11 | B22: 6876.55 | C22: 206004 | D22: =C22-C21 -> 405 | E22: =C22-152000 -> 54004 | F22: =D22/$D$2 -> 204.18452 | G22: 74 | H22: 6.6 | I22: =G22+H22 -> 80.6 | J22: =IF(L22>0,L22,0) -> 231.88452 | K22: =I22+J22 -> 312.48452 | L22: =F22-(I22-AC22) -> 231.88452 | M22: 5.3 | N22: 0 | O22: 0 | P22: =1.55*1.02 -> 1.581 | Q22: =2.41*1.04 -> 2.5064 | R22: 0 | S22: 77 | U22: =M22-N22-O22-P22-Q22-R22+S22+T22 -> 78.2126 | AA22: 26 | AB22: =AB21-AA22 -> 2228 | AC22: =N22+O22+P22+Q22+R22+U22+X22+AA22 -> 108.3 | AD22: =IF(L22<0,L22*-1,0) -> 0 | AE22: =AC22+AD22 -> 108.3 | AF22: 0.61 | AG22: 43 | AH22: 25 | AI22: =AI21+(U22*1.9835) -> 11171.006 | AJ22: 0
A23: =A22+1 -> 12 | B23: 6876.65 | C23: 206293 | D23: =C23-C22 -> 289 | E23: =C23-152000 -> 54293 | F23: =D23/$D$2 -> 145.70204 | G23: 47 | H23: 10 | I23: =G23+H23 -> 57 | J23: =IF(L23>0,L23,0) -> 209.70204 | K23: =I23+J23 -> 266.70204 | L23: =F23-(I23-AC23) -> 209.70204 | M23: 5 | N23: 0 | O23: 0 | P23: =1.55*1.02 -> 1.581 | Q23: =2.34*1.04 -> 2.4336 | R23: 0 | S23: 91 | U23: =M23-N23-O23-P23-Q23-R23+S23+T23 -> 91.9854 | AA23: 25 | AB23: =AB22-AA23 -> 2203 | AC23: =N23+O23+P23+Q23+R23+U23+X23+AA23 -> 121 | AD23: =IF(L23<0,L23*-1,0) -> 0 | AE23: =AC23+AD23 -> 121 | AF23: 0 | AG23: 34 | AH23: 19 | AI23: =AI22+(U23*1.9835) -> 11353.459 | AJ23: 0
A24: 13 | B24: 6876.73 | C24: 206524 | D24: =C24-C23 -> 231 | E24: =C24-152000 -> 54524 | F24: =D24/$D$2 -> 116.4608 | G24: 52 | H24: 12 | I24: =G24+H24 -> 64 | J24: =IF(L24>0,L24,0) -> 179.7608 | K24: =I24+J24 -> 243.7608 | L24: =F24-(I24-AC24) -> 179.7608 | M24: 4.3 | N24: 0 | O24: 0 | P24: =1.55*1.02 -> 1.581 | Q24: =2.22*1.04 -> 2.3088 | R24: 0 | S24: 99 | U24: =M24-N24-O24-P24-Q24-R24+S24+T24 -> 99.4102 | AA24: 24 | AB24: =AB23-AA24 -> 2179 | AC24: =N24+O24+P24+Q24+R24+U24+X24+AA24 -> 127.3 | AD24: =IF(L24<0,L24*-1,0) -> 0 | AE24: =AC24+AD24 -> 127.3 | AF24: 0 | AG24: 37 | AH24: 9 | AI24: =AI23+(U24*1.9835) -> 11550.64 | AJ24: 0
A25: =A24+1 -> 14 | B25: 6876.77 | C25: 206639 | D25: =C25-C24 -> 115 | E25: =C25-152000 -> 54639 | F25: =D25/$D$2 -> 57.978321 | G25: 53 | H25: 10 | I25: =G25+H25 -> 63 | J25: =IF(L25>0,L25,0) -> 121.97832 | K25: =I25+J25 -> 184.97832 | L25: =F25-(I25-AC25) -> 121.97832 | M25: 4 | N25: 0 | O25: 0 | P25: =1.55*1.02 -> 1.581 | Q25: =2.34*1.04 -> 2.4336 | R25: 0 | S25: 99 | U25: =M25-N25-O25-P25-Q25-R25+S25+T25 -> 98.9854 | AA25: 24 | AB25: =AB24-AA25 -> 2155 | AC25: =N25+O25+P25+Q25+R25+U25+X25+AA25 -> 127 | AD25: =IF(L25<0,L25*-1,0) -> 0 | AE25: =AC25+AD25 -> 127 | AF25: 0 | AG25: 43 | AH25: 18 | AI25: =AI24+(U25*1.9835) -> 11746.977 | AJ25: 0
A26: =A25+1 -> 15 | B26: 6876.76 | C26: 206610 | D26: =C26-C25 -> -29 | E26: =C26-152000 -> 54610 | F26: =D26/$D$2 -> -14.62062 | G26: 50 | H26: 6.9 | I26: =G26+H26 -> 56.9 | J26: =IF(L26>0,L26,0) -> 55.47938 | K26: =I26+J26 -> 112.37938 | L26: =F26-(I26-AC26) -> 55.47938 | M26: 4 | N26: 0 | O26: 0 | P26: =1.55*1.02 -> 1.581 | Q26: =1.95*1.04 -> 2.028 | R26: 0 | S26: 99 | U26: =M26-N26-O26-P26-Q26-R26+S26+T26 -> 99.391 | AA26: 24 | AB26: =AB25-AA26 -> 2131 | AC26: =N26+O26+P26+Q26+R26+U26+X26+AA26 -> 127 | AD26: =IF(L26<0,L26*-1,0) -> 0 | AE26: =AC26+AD26 -> 127 | AF26: 0 | AG26: 45 | AH26: 18 | AI26: =AI25+(U26*1.9835) -> 11944.119 | AJ26: 0
A27: =A26+1 -> 16 | B27: 6876.75 | C27: 206581 | D27: =C27-C26 -> -29 | E27: =C27-152000 -> 54581 | F27: =D27/$D$2 -> -14.62062 | G27: 52 | H27: 6.1 | I27: =G27+H27 -> 58.1 | J27: =IF(L27>0,L27,0) -> 54.47938 | K27: =I27+J27 -> 112.57938 | L27: =F27-(I27-AC27) -> 54.47938 | M27: 4.2 | N27: 0 | O27: 0 | P27: =1.55*1.02 -> 1.581 | Q27: =2.24*1.04 -> 2.3296 | R27: 0 | S27: 99 | U27: =M27-N27-O27-P27-Q27-R27+S27+T27 -> 99.2894 | AA27: 24 | AB27: =AB26-AA27 -> 2107 | AC27: =N27+O27+P27+Q27+R27+U27+X27+AA27 -> 127.2 | AD27: =IF(L27<0,L27*-1,0) -> 0 | AE27: =AC27+AD27 -> 127.2 | AF27: 0 | AG27: 46 | AH27: 23 | AI27: =AI26+(U27*1.9835) -> 12141.06 | AJ27: 0
A28: =A27+1 -> 17 | B28: 6876.74 | C28: 206553 | D28: =C28-C27 -> -28 | E28: =C28-152000 -> 54553 | F28: =D28/$D$2 -> -14.116461 | G28: 52 | H28: 5.8 | I28: =G28+H28 -> 57.8 | J28: =IF(L28>0,L28,0) -> 57.283539 | K28: =I28+J28 -> 115.08354 | L28: =F28-(I28-AC28) -> 57.283539 | M28: 5.2 | N28: 0 | O28: 0 | P28: =1.55*1.02 -> 1.581 | Q28: =2.29*1.04 -> 2.3816 | R28: 0 | S28: 99 | U28: =M28-N28-O28-P28-Q28-R28+S28+T28 -> 100.2374 | AA28: 25 | AB28: =AB27-AA28 -> 2082 | AC28: =N28+O28+P28+Q28+R28+U28+X28+AA28 -> 129.2 | AD28: =IF(L28<0,L28*-1,0) -> 0 | AE28: =AC28+AD28 -> 129.2 | AF28: 0 | AG28: 50 | AH28: 25 | AI28: =AI27+(U28*1.9835) -> 12339.881 | AJ28: 0
A29: =A28+1 -> 18 | B29: 6876.72 | C29: 206495 | D29: =C29-C28 -> -58 | E29: =C29-152000 -> 54495 | F29: =D29/$D$2 -> -29.24124 | G29: 52 | H29: 4.6 | I29: =G29+H29 -> 56.6 | J29: =IF(L29>0,L29,0) -> 43.35876 | K29: =I29+J29 -> 99.95876 | L29: =F29-(I29-AC29) -> 43.35876 | M29: 5.2 | N29: 0 | O29: 0 | P29: =1.55*1.02 -> 1.581 | Q29: =2.32*1.04 -> 2.4128 | R29: 0 | S29: 99 | U29: =M29-N29-O29-P29-Q29-R29+S29+T29 -> 100.2062 | AA29: 25 | AB29: =AB28-AA29 -> 2057 | AC29: =N29+O29+P29+Q29+R29+U29+X29+AA29 -> 129.2 | AD29: =IF(L29<0,L29*-1,0) -> 0 | AE29: =AC29+AD29 -> 129.2 | AF29: 0 | AG29: 50 | AH29: 25 | AI29: =AI28+(U29*1.9835) -> 12538.64 | AJ29: 0
A30: =A29+1 -> 19 | B30: 6876.7 | C30: 206437 | D30: =C30-C29 -> -58 | E30: =C30-152000 -> 54437 | F30: =D30/$D$2 -> -29.24124 | G30: 64 | H30: 4.5 | I30: =G30+H30 -> 68.5 | J30: =IF(L30>0,L30,0) -> 31.35876 | K30: =I30+J30 -> 99.85876 | L30: =F30-(I30-AC30) -> 31.35876 | M30: 5.1 | N30: 0 | O30: 0 | P30: =1.55*1.02 -> 1.581 | Q30: =2.26*1.04 -> 2.3504 | R30: 0 | S30: 99 | U30: =M30-N30-O30-P30-Q30-R30+S30+T30 -> 100.1686 | AA30: 25 | AB30: =AB29-AA30 -> 2032 | AC30: =N30+O30+P30+Q30+R30+U30+X30+AA30 -> 129.1 | AD30: =IF(L30<0,L30*-1,0) -> 0 | AE30: =AC30+AD30 -> 129.1 | AF30: 0 | AG30: 52 | AH30: 26 | AI30: =AI29+(U30*1.9835) -> 12737.324 | AJ30: 0
A31: =A30+1 -> 20 | B31: 6876.68 | C31: 206379 | D31: =C31-C30 -> -58 | E31: =C31-152000 -> 54379 | F31: =D31/$D$2 -> -29.24124 | G31: 74 | H31: 4.5 | I31: =G31+H31 -> 78.5 | J31: =IF(L31>0,L31,0) -> 21.25876 | K31: =I31+J31 -> 99.75876 | L31: =F31-(I31-AC31) -> 21.25876 | M31: 5 | N31: 0 | O31: 0 | P31: =1.55*1.02 -> 1.581 | Q31: =2.8*1.04 -> 2.912 | R31: 0 | S31: 99 | U31: =M31-N31-O31-P31-Q31-R31+S31+T31 -> 99.507 | AA31: 25 | AB31: =AB30-AA31 -> 2007 | AC31: =N31+O31+P31+Q31+R31+U31+X31+AA31 -> 129 | AD31: =IF(L31<0,L31*-1,0) -> 0 | AE31: =AC31+AD31 -> 129 | AF31: 0 | AG31: 55 | AH31: 28 | AI31: =AI30+(U31*1.9835) -> 12934.696 | AJ31: 0
