Workbook

Sheet NOV
K1: MC PHEE RESERVOIR IN/OUT FLOW TABULATION
A2: AF/cfs CONVERT FACTOR | D2: 1.9835 | L2: NOVEMBER "1887"
A4: DATE | B4: RESERV | C4: RESERV | D4: AC FT | E4: ACTIVE | F4: CONV TO | G4: DOLORES | H4: LOST | I4: RECORDED | J4: CALC | K4: TOTAL | L4: CALC | M4: TUNNEL | Q4: LONE | R4: U | S4: TOTAL | T4: MVI | U4: DV CR | V4: BELOW | W4: RECORDED | X4: CALC | Y4: TOTAL | Z4: RAIN | AA4: MAX | AB4: MIN | AC4: DATE
A5: "NOV" | B5: ELEV | C5: AC FT | D5: CHANGE | E5: CAP | F5: CFS | G5: RIVER | H5: CANYON | I5: INFLOW | J5: INFLOW | K5: INFLOW | L5: INF/OTF | M5: TOT DIV | N5: WETLAND | O5: UTE F&R | P5: MVI,CTZ | Q5: PINE | R5: LAT | S5: MVI | T5: CALL | U5: CANAL | V5: MC PHEE | W5: OUTFLOW | X5: OUTFLOW | Y5: OUTFLOW | AA5: TMP | AB5: TMP | AC5: "NOV"
A7: SEASON BAL
A8: YTD | B8: 6911.03 | C8: 326121
A10: 1 | B10: 6911.08 | C10: 326323 | D10: =C10-C8 -> 202 | E10: =C10-152000 -> 174323 | F10: =D10/$D$2 -> 101.84018 | G10: 142 | H10: 0 | I10: =G10+H10 -> 142 | J10: =IF(L10>0,L10,0) -> 62.840181 | K10: =I10+J10 -> 204.84018 | L10: =F10-(I10-W10) -> 62.840181 | M10: 30 | O10: 0 | P10: =M10-(N10+O10) -> 30 | Q10: 0 | R10: 0 | S10: =SUM(P10:R10) -> 30 | U10: 0 | V10: 73 | W10: =N10+O10+S10+U10+V10 -> 103 | X10: =IF(L10<0,L10*-1,0) -> 0 | Y10: =W10+X10 -> 103 | Z10: 0.72 | AA10: 61 | AB10: 32 | AC10: 1
A11: =A10+1 -> 2 | B11: 6911.08 | C11: 326323 | D11: =C11-C10 -> 0 | E11: =C11-152000 -> 174323 | F11: =D11/$D$2 -> 0 | G11: 199 | H11: 0 | I11: =G11+H11 -> 199 | J11: =IF(L11>0,L11,0) -> 0 | K11: =I11+J11 -> 199 | L11: =F11-(I11-W11) -> -96 | M11: 29 | O11: 0 | P11: =M11-(N11+O11) -> 29 | Q11: 0 | R11: 0 | S11: =SUM(P11:R11) -> 29 | U11: 0 | V11: 74 | W11: =N11+O11+S11+U11+V11 -> 103 | X11: =IF(L11<0,L11*-1,0) -> 96 | Y11: =W11+X11 -> 199 | Z11: 0.04 | AA11: 53 | AB11: 38 | AC11: =AC10+1 -> 2
A12: =A11+1 -> 3 | B12: 6911.2 | C12: 326808 | D12: =C12-C11 -> 485 | E12: =C12-152000 -> 174808 | F12: =D12/$D$2 -> 244.51727 | G12: 179 | H12: 0 | I12: =G12+H12 -> 179 | J12: =IF(L12>0,L12,0) -> 170.51727 | K12: =I12+J12 -> 349.51727 | L12: =F12-(I12-W12) -> 170.51727 | M12: 28 | O12: 0 | P12: =M12-(N12+O12) -> 28 | Q12: 0 | R12: 0 | S12: =SUM(P12:R12) -> 28 | U12: 0 | V12: 77 | W12: =N12+O12+S12+U12+V12 -> 105 | X12: =IF(L12<0,L12*-1,0) -> 0 | Y12: =W12+X12 -> 105 | Z12: 0 | AA12: 53 | AB12: 37 | AC12: =AC11+1 -> 3
A13: =A12+1 -> 4 | B13: 6911.21 | C13: 326849 | D13: =C13-C12 -> 41 | E13: =C13-152000 -> 174849 | F13: =D13/$D$2 -> 20.670532 | G13: 162 | H13: 0 | I13: =G13+H13 -> 162 | J13: =IF(L13>0,L13,0) -> 0 | K13: =I13+J13 -> 162 | L13: =F13-(I13-W13) -> -31.329468 | M13: 28 | O13: 0 | P13: =M13-(N13+O13) -> 28 | Q13: 0 | R13: 0 | S13: =SUM(P13:R13) -> 28 | U13: 0 | V13: 82 | W13: =N13+O13+S13+U13+V13 -> 110 | X13: =IF(L13<0,L13*-1,0) -> 31.329468 | Y13: =W13+X13 -> 141.32947 | Z13: 0 | AA13: 52 | AB13: 33 | AC13: =AC12+1 -> 4
A14: =A13+1 -> 5 | B14: 6911.29 | C14: 327172 | D14: =C14-C13 -> 323 | E14: =C14-152000 -> 175172 | F14: =D14/$D$2 -> 162.84346 | G14: 151 | H14: 0 | I14: =G14+H14 -> 151 | J14: =IF(L14>0,L14,0) -> 121.84346 | K14: =I14+J14 -> 272.84346 | L14: =F14-(I14-W14) -> 121.84346 | M14: 28 | O14: 0 | P14: =M14-(N14+O14) -> 28 | Q14: 0 | R14: 0 | S14: =SUM(P14:R14) -> 28 | U14: 0 | V14: 82 | W14: =N14+O14+S14+U14+V14 -> 110 | X14: =IF(L14<0,L14*-1,0) -> 0 | Y14: =W14+X14 -> 110 | Z14: 0.02 | AA14: 58 | AB14: 33 | AC14: =AC13+1 -> 5
A15: =A14+1 -> 6 | B15: 6911.49 | C15: 327981 | D15: =C15-C14 -> 809 | E15: =C15-152000 -> 175981 | F15: =D15/$D$2 -> 407.86489 | G15: 263 | H15: 0 | I15: =G15+H15 -> 263 | J15: =IF(L15>0,L15,0) -> 253.86489 | K15: =I15+J15 -> 516.86489 | L15: =F15-(I15-W15) -> 253.86489 | M15: 28 | O15: 0 | P15: =M15-(N15+O15) -> 28 | Q15: 0 | R15: 0 | S15: =SUM(P15:R15) -> 28 | U15: 0 | V15: 81 | W15: =N15+O15+S15+U15+V15 -> 109 | X15: =IF(L15<0,L15*-1,0) -> 0 | Y15: =W15+X15 -> 109 | Z15: 1.12 | AA15: 59 | AB15: 32 | AC15: =AC14+1 -> 6
A16: =A15+1 -> 7 | B16: 6911.63 | C16: 328548 | D16: =C16-C15 -> 567 | E16: =C16-152000 -> 176548 | F16: =D16/$D$2 -> 285.85833 | G16: 268 | H16: 0 | I16: =G16+H16 -> 268 | J16: =IF(L16>0,L16,0) -> 126.85833 | K16: =I16+J16 -> 394.85833 | L16: =F16-(I16-W16) -> 126.85833 | M16: 28 | O16: 0 | P16: =M16-(N16+O16) -> 28 | Q16: 0 | R16: 0 | S16: =SUM(P16:R16) -> 28 | U16: 0 | V16: 81 | W16: =N16+O16+S16+U16+V16 -> 109 | X16: =IF(L16<0,L16*-1,0) -> 0 | Y16: =W16+X16 -> 109 | Z16: 0.41 | AA16: 62 | AB16: 31 | AC16: =AC15+1 -> 7
A17: =A16+1 -> 8 | B17: 6911.7 | C17: 328831 | D17: =C17-C16 -> 283 | E17: =C17-152000 -> 176831 | F17: =D17/$D$2 -> 142.67709 | G17: 208 | H17: 0 | I17: =G17+H17 -> 208 | J17: =IF(L17>0,L17,0) -> 43.677086 | K17: =I17+J17 -> 251.67709 | L17: =F17-(I17-W17) -> 43.677086 | M17: 28 | O17: 0 | P17: =M17-(N17+O17) -> 28 | Q17: 0 | R17: 0 | S17: =SUM(P17:R17) -> 28 | U17: 0 | V17: 81 | W17: =N17+O17+S17+U17+V17 -> 109 | X17: =IF(L17<0,L17*-1,0) -> 0 | Y17: =W17+X17 -> 109 | Z17: 0 | AA17: 65 | AB17: 28 | AC17: =AC16+1 -> 8
A18: =A17+1 -> 9 | B18: 6911.72 | C18: 328912 | D18: =C18-C17 -> 81 | E18: =C18-152000 -> 176912 | F18: =D18/$D$2 -> 40.836904 | G18: 183 | H18: 0 | I18: =G18+H18 -> 183 | J18: =IF(L18>0,L18,0) -> 0 | K18: =I18+J18 -> 183 | L18: =F18-(I18-W18) -> -33.163096 | M18: 28 | O18: 0 | P18: =M18-(N18+O18) -> 28 | Q18: 0 | R18: 0 | S18: =SUM(P18:R18) -> 28 | U18: 0 | V18: 81 | W18: =N18+O18+S18+U18+V18 -> 109 | X18: =IF(L18<0,L18*-1,0) -> 33.163096 | Y18: =W18+X18 -> 142.1631 | Z18: 0 | AA18: 64 | AB18: 29 | AC18: =AC17+1 -> 9
A19: =A18+1 -> 10 | B19: 6911.73 | C19: 328952 | D19: =C19-C18 -> 40 | E19: =C19-152000 -> 176952 | F19: =D19/$D$2 -> 20.166373 | G19: 170 | H19: 0 | I19: =G19+H19 -> 170 | J19: =IF(L19>0,L19,0) -> 0 | K19: =I19+J19 -> 170 | L19: =F19-(I19-W19) -> -41.833627 | M19: 28 | O19: 0 | P19: =M19-(N19+O19) -> 28 | Q19: 0 | R19: 0 | S19: =SUM(P19:R19) -> 28 | U19: 0 | V19: 80 | W19: =N19+O19+S19+U19+V19 -> 108 | X19: =IF(L19<0,L19*-1,0) -> 41.833627 | Y19: =W19+X19 -> 149.83363 | Z19: 0 | AA19: 63 | AB19: 30 | AC19: =AC18+1 -> 10
A20: =A19+1 -> 11 | B20: 6911.73 | C20: 328952 | D20: =C20-C19 -> 0 | E20: =C20-152000 -> 176952 | F20: =D20/$D$2 -> 0 | G20: 160 | H20: 0 | I20: =G20+H20 -> 160 | J20: =IF(L20>0,L20,0) -> 0 | K20: =I20+J20 -> 160 | L20: =F20-(I20-W20) -> -53 | M20: 28 | O20: 0 | P20: =M20-(N20+O20) -> 28 | Q20: 0 | R20: 0 | S20: =SUM(P20:R20) -> 28 | U20: 0 | V20: 79 | W20: =N20+O20+S20+U20+V20 -> 107 | X20: =IF(L20<0,L20*-1,0) -> 53 | Y20: =W20+X20 -> 160 | Z20: 0 | AA20: 52 | AB20: 30 | AC20: =AC19+1 -> 11
A21: =A20+1 -> 12 | B21: 6911.72 | C21: 328912 | D21: =C21-C20 -> -40 | E21: =C21-152000 -> 176912 | F21: =D21/$D$2 -> -20.166373 | G21: 135 | H21: 0 | I21: =G21+H21 -> 135 | J21: =IF(L21>0,L21,0) -> 0 | K21: =I21+J21 -> 135 | L21: =F21-(I21-W21) -> -29.166373 | M21: 28 | O21: 0 | P21: =M21-(N21+O21) -> 28 | Q21: 17 | R21: 0 | S21: =SUM(P21:R21) -> 45 | U21: 0 | V21: 81 | W21: =N21+O21+S21+U21+V21 -> 126 | X21: =IF(L21<0,L21*-1,0) -> 29.166373 | Y21: =W21+X21 -> 155.16637 | Z21: 0 | AA21: 50 | AB21: 26 | AC21: =AC20+1 -> 12
A22: =A21+1 -> 13 | B22: 6911.7 | C22: 328831 | D22: =C22-C21 -> -81 | E22: =C22-152000 -> 176831 | F22: =D22/$D$2 -> -40.836904 | G22: 129 | H22: 0 | I22: =G22+H22 -> 129 | J22: =IF(L22>0,L22,0) -> 1.1630955 | K22: =I22+J22 -> 130.1631 | L22: =F22-(I22-W22) -> 1.1630955 | M22: 27 | O22: 0 | P22: =M22-(N22+O22) -> 27 | Q22: 47 | R22: 17 | S22: =SUM(P22:R22) -> 91 | U22: 0 | V22: 80 | W22: =N22+O22+S22+U22+V22 -> 171 | X22: =IF(L22<0,L22*-1,0) -> 0 | Y22: =W22+X22 -> 171 | Z22: 0 | AA22: 51 | AB22: 26 | AC22: =AC21+1 -> 13
... A38: =A37+1 -> 29 | B38: 6911.26 | C38: 327051 | D38: =C38-C37 -> -81 | E38: =C38-152000 -> 175051 | F38: =D38/$D$2 -> -40.836904 | G38: 102 | H38: 0 | I38: =G38+H38 -> 102 | J38: =IF(L38>0,L38,0) -> 0 | K38: =I38+J38 -> 102 | L38: =F38-(I38-W38) -> -55.836904 | M38: 5 | O38: 0 | P38: =M38-(N38+O38) -> 5 | Q38: 0 | R38: 2 | S38: =SUM(P38:R38) -> 7 | U38: 0 | V38: 80 | W38: =N38+O38+S38+U38+V38 -> 87 | X38: =IF(L38<0,L38*-1,0) -> 55.836904 | Y38: =W38+X38 -> 142.8369 | Z38: 0 | AA38: 43 | AB38: 15 | AC38: =AC37+1 -> 29
A39: 30 | B39: 6911.24 | C39: 326970 | D39: =C39-C38 -> -81 | E39: =C39-152000 -> 174970 | F39: =D39/$D$2 -> -40.836904 | G39: 129 | H39: 0 | I39: =G39+H39 -> 129 | J39: =IF(L39>0,L39,0) -> 0 | K39: =I39+J39 -> 129 | L39: =F39-(I39-W39) -> -83.836904 | M39: 5 | O39: 0 | P39: =M39-(N39+O39) -> 5 | Q39: 0 | R39: 0 | S39: =SUM(P39:R39) -> 5 | U39: 0 | V39: 81 | W39: =N39+O39+S39+U39+V39 -> 86 | X39: =IF(L39<0,L39*-1,0) -> 83.836904 | Y39: =W39+X39 -> 169.8369 | Z39: 0 | AA39: 39 | AB39: 16 | AC39: 30
A41: MONTH / CFS | F41: =SUM(F10:F39) -> 428.03126 | G41: =SUM(G10:G39) -> 4084 | H41: =SUM(H10:H39) -> 0 | I41: =SUM(I10:I39) -> 4084 | J41: =SUM(J10:J39) -> 897.76431 | K41: =SUM(K10:K39) -> 4981.7643 | L41: =SUM(L10:L39) -> 10.031258 | M41: =SUM(M10:M39) -> 651 | ... S41: =SUM(S10:S39) -> 1288 | U41: =SUM(U10:U39) -> 0 | V41: =SUM(V10:V39) -> 2378 | W41: =SUM(W10:W39) -> 3666 | X41: =SUM(X10:X39) -> 887.73305 | Y41: =SUM(Y10:Y39) -> 4553.733 | Z41: =SUM(Z10:Z39) -> 3.05 | AA41: =AVERAGE(AA10:AA39) -> 51.266667 | AB41: =AVERAGE(AB10:AB39) -> 22.6 | AC41: AVE
A42: MONTH / AF | D42: =SUM(D10:D39) -> 849 | F42: =F41*$D$2 -> 849 | G42: =G41*$D$2 -> 8100.614 | H42: =H41*$D$2 -> 0 | I42: =I41*$D$2 -> 8100.614 | J42: =J41*$D$2 -> 1780.7155 | K42: =K41*$D$2 -> 9881.3295 | L42: =L41*$D$2 -> 19.897 | M42: =M41*$D$2 -> 1291.2585 | ... S42: =S41*$D$2 -> 2554.748 | U42: =U41*$D$2 -> 0 | V42: =V41*$D$2 -> 4716.763 | W42: =W41*$D$2 -> 7271.511 | X42: =X41*$D$2 -> 1760.8185 | Y42: =Y41*$D$2 -> 9032.3295 | AA42: =MAX(AA10:AA39) -> 65 | AB42: =MAX(AB10:AB39) -> 38 | AC42: HI
A44: SEASON / CFS | AA44: =MIN(AA10:AA39) -> 39 | AB44: =MIN(AB10:AB39) -> 8 | AC44: LO
A45: SEASON / AF
A47: YTD / CFS | F47: =F8+F41 -> 428.03126 | G47: =G8+G41 -> 4084 | H47: =H8+H41 -> 0 | I47: =I8+I41 -> 4084 | J47: =J8+J41 -> 897.76431 | K47: =K8+K41 -> 4981.7643 | L47: =L8+L41 -> 10.031258 | M47: =M8+M41 -> 651 | ... S47: =S8+S41 -> 1288 | U47: =U8+U41 -> 0 | V47: =V8+V41 -> 2378 | W47: =W8+W41 -> 3666 | X47: =X8+X41 -> 887.73305 | Y47: =Y8+Y41 -> 4553.733 | Z47: =Z8+Z41 -> 3.05
A48: YTD / AF | D48: =D8+D42 -> 849 | E48: =E39 -> 174970 | F48: =F47*$D$2 -> 849 | G48: =G47*$D$2 -> 8100.614 | H48: =H47*$D$2 -> 0 | I48: =I47*$D$2 -> 8100.614 | J48: =J47*$D$2 -> 1780.7155 | K48: =K47*$D$2 -> 9881.3295 | L48: =L47*$D$2 -> 19.897 | M48: =M47*$D$2 -> 1291.2585 | ... Y48: =Y47*$D$2 -> 9032.3295

Sheet DEC
K1: MC PHEE RESERVOIR IN/OUT FLOW TABULATION
A2: AF/cfs CONVERT FACTOR | D2: 1.9835 | K2: DECEMBER "1987"
A4: DATE | B4: RESERV | C4: RESERV | D4: AC FT | E4: ACTIVE | F4: CONV TO | G4: DOLORES | H4: LOST | I4: RECORDED | J4: CALC | K4: TOTAL | L4: CALC | M4: TUNNEL | Q4: LONE | R4: U | S4: TOTAL | T4: MVI | U4: DV CR | V4: BELOW | W4: RECORDED | X4: CALC | Y4: TOTAL | Z4: RAIN | AA4: MAX | AB4: MIN | AC4: DATE
A5: "DEC" | B5: ELEV | C5: AC FT | D5: CHANGE | E5: CAP | F5: CFS | G5: RIVER | H5: CANYON | I5: INFLOW | J5: INFLOW | K5: INFLOW | L5: INF/OTF | M5: TOT DIV | N5: WETLAND | O5: UTE F&R | P5: MVI,CTZ | Q5: PINE | R5: LAT | S5: MVI | T5: CALL | U5: CANAL | V5: MC PHEE | W5: OUTFLOW | X5: OUTFLOW | Y5: OUTFLOW | AA5: TMP | AB5: TMP | AC5: "DEC"
A7: SEASON BAL
A8: YTD | B8: =NOV!B39 -> 6911.24 | C8: =NOV!C39 -> 326970 | D8: =NOV!$D$48 -> 849 | E8: =NOV!$E$39 -> 174970 | F8: =NOV!F47 -> 428.03126 | G8: =NOV!G47 -> 4084 | H8: =NOV!H47 -> 0 | I8: =NOV!I47 -> 4084 | J8: =NOV!J47 -> 897.76431 | K8: =NOV!K47 -> 4981.7643 | L8: =NOV!L47 -> 10.031258 | M8: =NOV!M47 -> 651 | ... Z8: =NOV!Z47 -> 3.05
A10: 1 | B10: 6911.25 | C10: 327011 | D10: =C10-C8 -> 41 | E10: =C10-152000 -> 175011 | F10: =D10/$D$2 -> 20.670532 | G10: 106 | H10: 0 | I10: =G10+H10 -> 106 | J10: =IF(L10>0,L10,0) -> 0.67053189 | K10: =I10+J10 -> 106.67053 | L10: =F10-(I10-W10) -> 0.67053189 | M10: 5 | O10: 0 | P10: =M10-(N10+O10) -> 5 | Q10: 0 | R10: 0 | S10: =SUM(P10:R10) -> 5 | U10: 0 | V10: 81 | W10: =N10+O10+S10+U10+V10 -> 86 | X10: =IF(L10<0,L10*-1,0) -> 0 | Y10: =W10+X10 -> 86 | Z10: 0 | AA10: 42 | AB10: 14 | AC10: 1
A11: =A10+1 -> 2 | B11: 6911.27 | C11: 327092 | D11: =C11-C10 -> 81 | E11: =C11-152000 -> 175092 | F11: =D11/$D$2 -> 40.836904 | G11: 125 | H11: 0 | I11: =G11+H11 -> 125 | J11: =IF(L11>0,L11,0) -> 0 | K11: =I11+J11 -> 125 | L11: =F11-(I11-W11) -> -0.16309554 | M11: 4 | O11: 0 | P11: =M11-(N11+O11) -> 4 | Q11: 0 | R11: 0 | S11: =SUM(P11:R11) -> 4 | U11: 0 | V11: 80 | W11: =N11+O11+S11+U11+V11 -> 84 | X11: =IF(L11<0,L11*-1,0) -> 0.16309554 | Y11: =W11+X11 -> 84.163096 | Z11: 0 | AA11: 44 | AB11: 15 | AC11: =AC10+1 -> 2
A12: =A11+1 -> 3 | B12: 6911.28 | C12: 327132 | D12: =C12-C11 -> 40 | E12: =C12-152000 -> 175132 | F12: =D12/$D$2 -> 20.166373 | G12: 105 | H12: 0 | I12: =G12+H12 -> 105 | J12: =IF(L12>0,L12,0) -> 0 | K12: =I12+J12 -> 105 | L12: =F12-(I12-W12) -> -0.83362743 | M12: 4 | O12: 0 | P12: =M12-(N12+O12) -> 4 | Q12: 0 | R12: 0 | S12: =SUM(P12:R12) -> 4 | U12: 0 | V12: 80 | W12: =N12+O12+S12+U12+V12 -> 84 | X12: =IF(L12<0,L12*-1,0) -> 0.83362743 | Y12: =W12+X12 -> 84.833627 | Z12: 0 | AA12: 53 | AB12: 19 | AC12: =AC11+1 -> 3
A13: =A12+1 -> 4 | B13: 6911.29 | C13: 327172 | D13: =C13-C12 -> 40 | E13: =C13-152000 -> 175172 | F13: =D13/$D$2 -> 20.166373 | G13: 105 | H13: 0 | I13: =G13+H13 -> 105 | J13: =IF(L13>0,L13,0) -> 0 | K13: =I13+J13 -> 105 | L13: =F13-(I13-W13) -> -0.83362743 | M13: 4 | O13: 0 | P13: =M13-(N13+O13) -> 4 | Q13: 0 | R13: 0 | S13: =SUM(P13:R13) -> 4 | U13: 0 | V13: 80 | W13: =N13+O13+S13+U13+V13 -> 84 | X13: =IF(L13<0,L13*-1,0) -> 0.83362743 | Y13: =W13+X13 -> 84.833627 | Z13: 0.03 | AA13: 40 | AB13: 14 | AC13: =AC12+1 -> 4
A14: =A13+1 -> 5 | B14: 6911.31 | C14: 327253 | D14: =C14-C13 -> 81 | E14: =C14-152000 -> 175253 | F14: =D14/$D$2 -> 40.836904 | G14: 125 | H14: 0 | I14: =G14+H14 -> 125 | J14: =IF(L14>0,L14,0) -> 0.83690446 | K14: =I14+J14 -> 125.8369 | L14: =F14-(I14-W14) -> 0.83690446 | M14: 5 | O14: 0 | P14: =M14-(N14+O14) -> 5 | Q14: 0 | R14: 0 | S14: =SUM(P14:R14) -> 5 | U14: 0 | V14: 80 | W14: =N14+O14+S14+U14+V14 -> 85 | X14: =IF(L14<0,L14*-1,0) -> 0 | Y14: =W14+X14 -> 85 | Z14: 0 | AA14: 41 | AB14: 21 | AC14: =AC13+1 -> 5
A15: =A14+1 -> 6 | B15: 6911.32 | C15: 327294 | D15: =C15-C14 -> 41 | E15: =C15-152000 -> 175294 | F15: =D15/$D$2 -> 20.670532 | G15: 105 | H15: 0 | I15: =G15+H15 -> 105 | J15: =IF(L15>0,L15,0) -> 0.67053189 | K15: =I15+J15 -> 105.67053 | L15: =F15-(I15-W15) -> 0.67053189 | M15: 5 | O15: 0 | P15: =M15-(N15+O15) -> 5 | Q15: 0 | R15: 0 | S15: =SUM(P15:R15) -> 5 | U15: 0 | V15: 80 | W15: =N15+O15+S15+U15+V15 -> 85 | X15: =IF(L15<0,L15*-1,0) -> 0 | Y15: =W15+X15 -> 85 | Z15: 0 | AA15: 41 | AB15: 24 | AC15: =AC14+1 -> 6
A16: =A15+1 -> 7 | B16: 6911.33 | C16: 327334 | D16: =C16-C15 -> 40 | E16: =C16-152000 -> 175334 | F16: =D16/$D$2 -> 20.166373 | G16: 99 | H16: 0 | I16: =G16+H16 -> 99 | J16: =IF(L16>0,L16,0) -> 0.16637257 | K16: =I16+J16 -> 99.166373 | L16: =F16-(I16-W16) -> 0.16637257 | M16: 5 | O16: 0 | P16: =M16-(N16+O16) -> 5 | Q16: 0 | R16: 0 | S16: =SUM(P16:R16) -> 5 | U16: 0 | V16: 74 | W16: =N16+O16+S16+U16+V16 -> 79 | X16: =IF(L16<0,L16*-1,0) -> 0 | Y16: =W16+X16 -> 79 | Z16: 0 | AA16: 50 | AB16: 15 | AC16: =AC15+1 -> 7
A17: =A16+1 -> 8 | B17: 6911.32 | C17: 327294 | D17: =C17-C16 -> -40 | E17: =C17-152000 -> 175294 | F17: =D17/$D$2 -> -20.166373 | G17: 59 | H17: 0 | I17: =G17+H17 -> 59 | J17: =IF(L17>0,L17,0) -> 0 | K17: =I17+J17 -> 59 | L17: =F17-(I17-W17) -> -0.16637257 | M17: 4 | O17: 0 | P17: =M17-(N17+O17) -> 4 | Q17: 0 | R17: 0 | S17: =SUM(P17:R17) -> 4 | U17: 0 | V17: 75 | W17: =N17+O17+S17+U17+V17 -> 79 | X17: =IF(L17<0,L17*-1,0) -> 0.16637257 | Y17: =W17+X17 -> 79.166373 | Z17: 0 | AA17: 51 | AB17: 17 | AC17: =AC16+1 -> 8
A18: =A17+1 -> 9 | B18: 6911.31 | C18: 327253 | D18: =C18-C17 -> -41 | E18: =C18-152000 -> 175253 | F18: =D18/$D$2 -> -20.670532 | G18: 63 | H18: 0 | I18: =G18+H18 -> 63 | J18: =IF(L18>0,L18,0) -> 0 | K18: =I18+J18 -> 63 | L18: =F18-(I18-W18) -> -0.67053189 | M18: 4 | O18: 0 | P18: =M18-(N18+O18) -> 4 | Q18: 0 | R18: 0 | S18: =SUM(P18:R18) -> 4 | U18: 0 | V18: 79 | W18: =N18+O18+S18+U18+V18 -> 83 | X18: =IF(L18<0,L18*-1,0) -> 0.67053189 | Y18: =W18+X18 -> 83.670532 | Z18: 0 | AA18: 51 | AB18: 18 | AC18: =AC17+1 -> 9
A19: =A18+1 -> 10 | B19: 6911.3 | C19: 327213 | D19: =C19-C18 -> -40 | E19: =C19-152000 -> 175213 | F19: =D19/$D$2 -> -20.166373 | G19: 61 | H19: 0 | I19: =G19+H19 -> 61 | J19: =IF(L19>0,L19,0) -> 0 | K19: =I19+J19 -> 61 | L19: =F19-(I19-W19) -> -1.1663726 | M19: 4 | O19: 0 | P19: =M19-(N19+O19) -> 4 | Q19: 0 | R19: 0 | S19: =SUM(P19:R19) -> 4 | U19: 0 | V19: 76 | W19: =N19+O19+S19+U19+V19 -> 80 | X19: =IF(L19<0,L19*-1,0) -> 1.1663726 | Y19: =W19+X19 -> 81.166373 | Z19: 0 | AA19: 51 | AB19: 19 | AC19: =AC18+1 -> 10
A20: =A19+1 -> 11 | B20: 6911.29 | C20: 327172 | D20: =C20-C19 -> -41 | E20: =C20-152000 -> 175172 | F20: =D20/$D$2 -> -20.670532 | G20: 64 | H20: 0 | I20: =G20+H20 -> 64 | J20: =IF(L20>0,L20,0) -> 0 | K20: =I20+J20 -> 64 | L20: =F20-(I20-W20) -> -1.6705319 | M20: 4 | O20: 0 | P20: =M20-(N20+O20) -> 4 | Q20: 0 | R20: 0 | S20: =SUM(P20:R20) -> 4 | U20: 0 | V20: 79 | W20: =N20+O20+S20+U20+V20 -> 83 | X20: =IF(L20<0,L20*-1,0) -> 1.6705319 | Y20: =W20+X20 -> 84.670532 | Z20: 0 | AA20: 42 | AB20: 19 | AC20: =AC19+1 -> 11
A21: =A20+1 -> 12 | B21: 6911.27 | C21: 327092 | D21: =C21-C20 -> -80 | E21: =C21-152000 -> 175092 | F21: =D21/$D$2 -> -40.332745 | G21: 42 | H21: 0 | I21: =G21+H21 -> 42 | J21: =IF(L21>0,L21,0) -> 0.66725485 | K21: =I21+J21 -> 42.667255 | L21: =F21-(I21-W21) -> 0.66725485 | M21: 4 | O21: 0 | P21: =M21-(N21+O21) -> 4 | Q21: 0 | R21: 0 | S21: =SUM(P21:R21) -> 4 | U21: 0 | V21: 79 | W21: =N21+O21+S21+U21+V21 -> 83 | X21: =IF(L21<0,L21*-1,0) -> 0 | Y21: =W21+X21 -> 83 | Z21: 0 | AA21: 30 | AB21: 16 | AC21: =AC20+1 -> 12
A22: =A21+1 -> 13 | B22: 6911.25 | C22: 327011 | D22: =C22-C21 -> -81 | E22: =C22-152000 -> 175011 | F22: =D22/$D$2 -> -40.836904 | G22: 42 | H22: 0 | I22: =G22+H22 -> 42 | J22: =IF(L22>0,L22,0) -> 0 | K22: =I22+J22 -> 42 | L22: =F22-(I22-W22) -> -0.83690446 | M22: 4 | O22: 0 | P22: =M22-(N22+O22) -> 4 | Q22: 0 | R22: 0 | S22: =SUM(P22:R22) -> 4 | U22: 0 | V22: 78 | W22: =N22+O22+S22+U22+V22 -> 82 | X22: =IF(L22<0,L22*-1,0) -> 0.83690446 | Y22: =W22+X22 -> 82.836904 | Z22: 0.15 | AA22: 19 | AB22: 13 | AC22: =AC21+1 -> 13
... A38: =A37+1 -> 29 | B38: 6911.1 | C38: 326404 | D38: =C38-C37 -> -40 | E38: =C38-152000 -> 174404 | F38: =D38/$D$2 -> -20.166373 | G38: 59 | H38: 0 | I38: =G38+H38 -> 59 | J38: =IF(L38>0,L38,0) -> 0 | K38: =I38+J38 -> 59 | L38: =F38-(I38-W38) -> -0.16637257 | M38: 4 | O38: 0 | P38: =M38-(N38+O38) -> 4 | Q38: 0 | R38: 0 | S38: =SUM(P38:R38) -> 4 | U38: 0 | V38: 75 | W38: =N38+O38+S38+U38+V38 -> 79 | X38: =IF(L38<0,L38*-1,0) -> 0.16637257 | Y38: =W38+X38 -> 79.166373 | Z38: 0.1 | AA38: 34 | AB38: 16 | AC38: =AC37+1 -> 29
A39: 30 | B39: 6911.08 | C39: 326323 | D39: =C39-C38 -> -81 | E39: =C39-152000 -> 174323 | F39: =D39/$D$2 -> -40.836904 | G39: 42 | H39: 0 | I39: =G39+H39 -> 42 | J39: =IF(L39>0,L39,0) -> 0.16309554 | K39: =I39+J39 -> 42.163096 | L39: =F39-(I39-W39) -> 0.16309554 | M39: 4 | O39: 0 | P39: =M39-(N39+O39) -> 4 | Q39: 0 | R39: 0 | S39: =SUM(P39:R39) -> 4 | U39: 0 | V39: 79 | W39: =N39+O39+S39+U39+V39 -> 83 | X39: =IF(L39<0,L39*-1,0) -> 0 | Y39: =W39+X39 -> 83 | Z39: 0.01 | AA39: 26 | AB39: 16 | AC39: 30
A40: 31 | B40: 6911.06 | C40: 326242 | D40: =C40-C39 -> -81 | E40: =C40-152000 -> 174242 | F40: =D40/$D$2 -> -40.836904 | G40: 44 | H40: 0 | I40: =G40+H40 -> 44 | J40: =IF(L40>0,L40,0) -> 0 | K40: =I40+J40 -> 44 | L40: =F40-(I40-W40) -> -0.83690446 | M40: 4 | O40: 0 | P40: =M40-(N40+O40) -> 4 | Q40: 0 | R40: 0 | S40: =SUM(P40:R40) -> 4 | U40: 0 | V40: 80 | W40: =N40+O40+S40+U40+V40 -> 84 | X40: =IF(L40<0,L40*-1,0) -> 0.83690446 | Y40: =W40+X40 -> 84.836904 | Z40: 0 | AA40: 28 | AB40: 0 | AC40: 31
A42: MONTH / CFS | F42: =SUM(F10:F40) -> -367.02798 | G42: =SUM(G10:G40) -> 2216 | H42: =SUM(H10:H40) -> 0 | I42: =SUM(I10:I40) -> 2216 | J42: =SUM(J10:J40) -> 4.1746912 | K42: =SUM(K10:K40) -> 2220.1747 | L42: =SUM(L10:L40) -> -14.027981 | M42: =SUM(M10:M40) -> 131 | ... S42: =SUM(S10:S40) -> 131 | U42: =SUM(U10:U40) -> 0 | V42: =SUM(V10:V40) -> 2438 | W42: =SUM(W10:W40) -> 2569 | X42: =SUM(X10:X40) -> 18.202672 | Y42: =SUM(Y10:Y40) -> 2587.2027 | Z42: =SUM(Z10:Z40) -> 1.09 | AA42: =AVERAGE(AA10:AA40) -> 36.032258 | AB42: =AVERAGE(AB10:AB40) -> 14.516129 | AC42: AVE
A43: MONTH / AF | D43: =SUM(D10:D40) -> -728 | F43: =F42*$D$2 -> -728 | G43: =G42*$D$2 -> 4395.436 | H43: =H42*$D$2 -> 0 | I43: =I42*$D$2 -> 4395.436 | J43: =J42*$D$2 -> 8.2805 | K43: =K42*$D$2 -> 4403.7165 | L43: =L42*$D$2 -> -27.8245 | M43: =M42*$D$2 -> 259.8385 | ... S43: =S42*$D$2 -> 259.8385 | U43: =U42*$D$2 -> 0 | V43: =V42*$D$2 -> 4835.773 | W43: =W42*$D$2 -> 5095.6115 | X43: =X42*$D$2 -> 36.105 | Y43: =Y42*$D$2 -> 5131.7165 | AA43: =MAX(AA10:AA40) -> 53 | AB43: =MAX(AB10:AB40) -> 29 | AC43: HI
A45: SEASON / CFS | AA45: =MIN(AA10:AA40) -> 19 | AB45: =MIN(AB10:AB40) -> 0 | AC45: LO
A46: SEASON / AF
A48: YTD / CFS | F48: =F8+F42 -> 61.003277 | G48: =G8+G42 -> 6300 | H48: =H8+H42 -> 0 | I48: =I8+I42 -> 6300 | J48: =J8+J42 -> 901.939 | K48: =K8+K42 -> 7201.939 | L48: =L8+L42 -> -3.996723 | M48: =M8+M42 -> 782 | ... S48: =S8+S42 -> 1419 | U48: =U8+U42 -> 0 | V48: =V8+V42 -> 4816 | W48: =W8+W42 -> 6235 | X48: =X8+X42 -> 905.93572 | Y48: =Y8+Y42 -> 7140.9357 | Z48: =Z8+Z42 -> 4.14
A49: YTD / AF | D49: =D8+D43 -> 121 | E49: =E40 -> 174242 | F49: =F48*$D$2 -> 121 | G49: =G48*$D$2 -> 12496.05 | H49: =H48*$D$2 -> 0 | I49: =I48*$D$2 -> 12496.05 | J49: =J48*$D$2 -> 1788.996 | K49: =K48*$D$2 -> 14285.046 | L49: =L48*$D$2 -> -7.9275 | M49: =M48*$D$2 -> 1551.097 | ... Y49: =Y48*$D$2 -> 14164.046

Sheet JAN
K1: MC PHEE RESERVOIR IN/OUT FLOW TABULATION
A2: AF/cfs CONVERT FACTOR | D2: 1.9835 | K2: JANUARY "1988"
A4: DATE | B4: RESERV | C4: RESERV | D4: AC FT | E4: ACTIVE | F4: CONV TO | G4: DOLORES | H4: LOST | I4: RECORDED | J4: CALC | K4: TOTAL | L4: CALC | M4: TUNNEL | Q4: LONE | R4: U | S4: TOTAL | T4: MVI | U4: DV CR | V4: BELOW | W4: RECORDED | X4: CALC | Y4: TOTAL | Z4: RAIN | AA4: MAX | AB4: MIN | AC4: DATE
A5: "JAN" | B5: ELEV | C5: AC FT | D5: CHANGE | E5: CAP | F5: CFS | G5: RIVER | H5: CANYON | I5: INFLOW | J5: INFLOW | K5: INFLOW | L5: INF/OTF | M5: TOT DIV | N5: WETLAND | O5: UTE F&R | P5: MVI,CTZ | Q5: PINE | R5: LAT | S5: MVI | T5: CALL | U5: CANAL | V5: MC PHEE | W5: OUTFLOW | X5: OUTFLOW | Y5: OUTFLOW | AA5: TMP | AB5: TMP | AC5: "JAN"
A7: SEASON BAL
A8: YTD | B8: =DEC!B40 -> 6911.06 | C8: =DEC!C40 -> 326242 | D8: =DEC!$D$49 -> 121 | E8: =DEC!$E$40 -> 174242 | F8: =DEC!F48 -> 61.003277 | G8: =DEC!G48 -> 6300 | H8: =DEC!H48 -> 0 | I8: =DEC!I48 -> 6300 | J8: =DEC!J48 -> 901.939 | K8: =DEC!K48 -> 7201.939 | L8: =DEC!L48 -> -3.996723 | M8: =DEC!M48 -> 782 | ... Z8: =DEC!Z48 -> 4.14
A10: 1 | B10: 6911.05 | C10: 326202 | D10: =C10-C8 -> -40 | E10: =C10-152000 -> 174202 | F10: =D10/$D$2 -> -20.166373 | G10: 64 | H10: 0 | I10: =G10+H10 -> 64 | J10: =IF(L10>0,L10,0) -> 0 | K10: =I10+J10 -> 64 | L10: =F10-(I10-W10) -> -0.16637257 | M10: 5 | O10: 0 | P10: =M10-(N10+O10) -> 5 | Q10: 0 | R10: 0 | S10: =SUM(P10:R10) -> 5 | U10: 0 | V10: 79 | W10: =N10+O10+S10+U10+V10 -> 84 | X10: =IF(L10<0,L10*-1,0) -> 0.16637257 | Y10: =W10+X10 -> 84.166373 | Z10: 0 | AA10: 28 | AB10: -1 | AC10: 1
A11: =A10+1 -> 2 | B11: 6911.04 | C11: 326161 | D11: =C11-C10 -> -41 | E11: =C11-152000 -> 174161 | F11: =D11/$D$2 -> -20.670532 | G11: 64 | H11: 0 | I11: =G11+H11 -> 64 | J11: =IF(L11>0,L11,0) -> 0 | K11: =I11+J11 -> 64 | L11: =F11-(I11-W11) -> -0.67053189 | M11: 5 | O11: 0 | P11: =M11-(N11+O11) -> 5 | Q11: 0 | R11: 0 | S11: =SUM(P11:R11) -> 5 | U11: 0 | V11: 79 | W11: =N11+O11+S11+U11+V11 -> 84 | X11: =IF(L11<0,L11*-1,0) -> 0.67053189 | Y11: =W11+X11 -> 84.670532 | Z11: 0 | AA11: 26 | AB11: 0 | AC11: =AC10+1 -> 2
A12: =A11+1 -> 3 | B12: 6911.03 | C12: 326121 | D12: =C12-C11 -> -40 | E12: =C12-152000 -> 174121 | F12: =D12/$D$2 -> -20.166373 | G12: 63 | H12: 0 | I12: =G12+H12 -> 63 | J12: =IF(L12>0,L12,0) -> 0.83362743 | K12: =I12+J12 -> 63.833627 | L12: =F12-(I12-W12) -> 0.83362743 | M12: 5 | O12: 0 | P12: =M12-(N12+O12) -> 5 | Q12: 0 | R12: 0 | S12: =SUM(P12:R12) -> 5 | U12: 0 | V12: 79 | W12: =N12+O12+S12+U12+V12 -> 84 | X12: =IF(L12<0,L12*-1,0) -> 0 | Y12: =W12+X12 -> 84 | Z12: 0 | AA12: 30 | AB12: -3 | AC12: =AC11+1 -> 3
A13: =A12+1 -> 4 | B13: 6911.02 | C13: 326080 | D13: =C13-C12 -> -41 | E13: =C13-152000 -> 174080 | F13: =D13/$D$2 -> -20.670532 | G13: 63 | H13: 0 | I13: =G13+H13 -> 63 | J13: =IF(L13>0,L13,0) -> 0.32946811 | K13: =I13+J13 -> 63.329468 | L13: =F13-(I13-W13) -> 0.32946811 | M13: 5 | O13: 0 | P13: =M13-(N13+O13) -> 5 | Q13: 0 | R13: 0 | S13: =SUM(P13:R13) -> 5 | U13: 0 | V13: 79 | W13: =N13+O13+S13+U13+V13 -> 84 | X13: =IF(L13<0,L13*-1,0) -> 0 | Y13: =W13+X13 -> 84 | Z13: 0.18 | AA13: 27 | AB13: 20 | AC13: =AC12+1 -> 4
A14: =A13+1 -> 5 | B14: 6911.01 | C14: 326040 | D14: =C14-C13 -> -40 | E14: =C14-152000 -> 174040 | F14: =D14/$D$2 -> -20.166373 | G14: 58 | H14: 0 | I14: =G14+H14 -> 58 | J14: =IF(L14>0,L14,0) -> 0.83362743 | K14: =I14+J14 -> 58.833627 | L14: =F14-(I14-W14) -> 0.83362743 | M14: 5 | O14: 0 | P14: =M14-(N14+O14) -> 5 | Q14: 0 | R14: 0 | S14: =SUM(P14:R14) -> 5 | U14: 0 | V14: 74 | W14: =N14+O14+S14+U14+V14 -> 79 | X14: =IF(L14<0,L14*-1,0) -> 0 | Y14: =W14+X14 -> 79 | Z14: 0.43 | AA14: 35 | AB14: 20 | AC14: =AC13+1 -> 5
A15: =A14+1 -> 6 | B15: 6911 | C15: 325999 | D15: =C15-C14 -> -41 | E15: =C15-152000 -> 173999 | F15: =D15/$D$2 -> -20.670532 | G15: 59 | H15: 0 | I15: =G15+H15 -> 59 | J15: =IF(L15>0,L15,0) -> 0 | K15: =I15+J15 -> 59 | L15: =F15-(I15-W15) -> -0.67053189 | M15: 4 | O15: 0 | P15: =M15-(N15+O15) -> 4 | Q15: 0 | R15: 0 | S15: =SUM(P15:R15) -> 4 | U15: 0 | V15: 75 | W15: =N15+O15+S15+U15+V15 -> 79 | X15: =IF(L15<0,L15*-1,0) -> 0.67053189 | Y15: =W15+X15 -> 79.670532 | Z15: 0.49 | AA15: 33 | AB15: 21 | AC15: =AC14+1 -> 6
A16: =A15+1 -> 7 | B16: 6910.99 | C16: 325959 | D16: =C16-C15 -> -40 | E16: =C16-152000 -> 173959 | F16: =D16/$D$2 -> -20.166373 | G16: 59 | H16: 0 | I16: =G16+H16 -> 59 | J16: =IF(L16>0,L16,0) -> 0 | K16: =I16+J16 -> 59 | L16: =F16-(I16-W16) -> -0.16637257 | M16: 4 | O16: 0 | P16: =M16-(N16+O16) -> 4 | Q16: 0 | R16: 0 | S16: =SUM(P16:R16) -> 4 | U16: 0 | V16: 75 | W16: =N16+O16+S16+U16+V16 -> 79 | X16: =IF(L16<0,L16*-1,0) -> 0.16637257 | Y16: =W16+X16 -> 79.166373 | Z16: 0 | AA16: 36 | AB16: 10 | AC16: =AC15+1 -> 7
A17: =A16+1 -> 8 | B17: 6910.98 | C17: 325919 | D17: =C17-C16 -> -40 | E17: =C17-152000 -> 173919 | F17: =D17/$D$2 -> -20.166373 | G17: 59 | H17: 0 | I17: =G17+H17 -> 59 | J17: =IF(L17>0,L17,0) -> 0 | K17: =I17+J17 -> 59 | L17: =F17-(I17-W17) -> -0.16637257 | M17: 4 | O17: 0 | P17: =M17-(N17+O17) -> 4 | Q17: 0 | R17: 0 | S17: =SUM(P17:R17) -> 4 | U17: 0 | V17: 75 | W17: =N17+O17+S17+U17+V17 -> 79 | X17: =IF(L17<0,L17*-1,0) -> 0.16637257 | Y17: =W17+X17 -> 79.166373 | Z17: 0.09 | AA17: 32 | AB17: 5 | AC17: =AC16+1 -> 8
A18: =A17+1 -> 9 | B18: 6910.97 | C18: 325879 | D18: =C18-C17 -> -40 | E18: =C18-152000 -> 173879 | F18: =D18/$D$2 -> -20.166373 | G18: 59 | H18: 0 | I18: =G18+H18 -> 59 | J18: =IF(L18>0,L18,0) -> 0 | K18: =I18+J18 -> 59 | L18: =F18-(I18-W18) -> -0.16637257 | M18: 4 | O18: 0 | P18: =M18-(N18+O18) -> 4 | Q18: 0 | R18: 0 | S18: =SUM(P18:R18) -> 4 | U18: 0 | V18: 75 | W18: =N18+O18+S18+U18+V18 -> 79 | X18: =IF(L18<0,L18*-1,0) -> 0.16637257 | Y18: =W18+X18 -> 79.166373 | Z18: 0 | AA18: 34 | AB18: 5 | AC18: =AC17+1 -> 9
A19: =A18+1 -> 10 | B19: 6910.96 | C19: 325839 | D19: =C19-C18 -> -40 | E19: =C19-152000 -> 173839 | F19: =D19/$D$2 -> -20.166373 | G19: 59 | H19: 0 | I19: =G19+H19 -> 59 | J19: =IF(L19>0,L19,0) -> 0 | K19: =I19+J19 -> 59 | L19: =F19-(I19-W19) -> -0.16637257 | M19: 4 | O19: 0 | P19: =M19-(N19+O19) -> 4 | Q19: 0 | R19: 0 | S19: =SUM(P19:R19) -> 4 | U19: 0 | V19: 75 | W19: =N19+O19+S19+U19+V19 -> 79 | X19: =IF(L19<0,L19*-1,0) -> 0.16637257 | Y19: =W19+X19 -> 79.166373 | Z19: 0 | AA19: 36 | AB19: 14 | AC19: =AC18+1 -> 10
A20: =A19+1 -> 11 | B20: 6910.95 | C20: 325799 | D20: =C20-C19 -> -40 | E20: =C20-152000 -> 173799 | F20: =D20/$D$2 -> -20.166373 | G20: 60 | H20: 0 | I20: =G20+H20 -> 60 | J20: =IF(L20>0,L20,0) -> 0 | K20: =I20+J20 -> 60 | L20: =F20-(I20-W20) -> -0.16637257 | M20: 4 | O20: 0 | P20: =M20-(N20+O20) -> 4 | Q20: 0 | R20: 0 | S20: =SUM(P20:R20) -> 4 | U20: 0 | V20: 76 | W20: =N20+O20+S20+U20+V20 -> 80 | X20: =IF(L20<0,L20*-1,0) -> 0.16637257 | Y20: =W20+X20 -> 80.166373 | Z20: 0 | AA20: 40 | AB20: 22 | AC20: =AC19+1 -> 11
A21: =A20+1 -> 12 | B21: 6910.94 | C21: 325759 | D21: =C21-C20 -> -40 | E21: =C21-152000 -> 173759 | F21: =D21/$D$2 -> -20.166373 | G21: 60 | H21: 0 | I21: =G21+H21 -> 60 | J21: =IF(L21>0,L21,0) -> 0 | K21: =I21+J21 -> 60 | L21: =F21-(I21-W21) -> -0.16637257 | M21: 4 | O21: 0 | P21: =M21-(N21+O21) -> 4 | Q21: 0 | R21: 0 | S21: =SUM(P21:R21) -> 4 | U21: 0 | V21: 76 | W21: =N21+O21+S21+U21+V21 -> 80 | X21: =IF(L21<0,L21*-1,0) -> 0.16637257 | Y21: =W21+X21 -> 80.166373 | Z21: 0 | AA21: 31 | AB21: 3 | AC21: =AC20+1 -> 12
A22: 13 | B22: 6910.93 | C22: 325718 | D22: =C22-C21 -> -41 | E22: =C22-152000 -> 173718 | F22: =D22/$D$2 -> -20.670532 | G22: 61 | H22: 0 | I22: =G22+H22 -> 61 | J22: =IF(L22>0,L22,0) -> 0.32946811 | K22: =I22+J22 -> 61.329468 | L22: =F22-(I22-W22) -> 0.32946811 | M22: 4 | O22: 0 | P22: =M22-(N22+O22) -> 4 | Q22: 0 | R22: 0 | S22: =SUM(P22:R22) -> 4 | U22: 0 | V22: 78 | W22: =N22+O22+S22+U22+V22 -> 82 | X22: =IF(L22<0,L22*-1,0) -> 0 | Y22: =W22+X22 -> 82 | Z22: 0 | AA22: 35 | AB22: 1 | AC22: =AC21+1 -> 13
A23: =A22+1 -> 14 | B23: 6910.92 | C23: 325678 | D23: =C23-C22 -> -40 | E23: =C23-152000 -> 173678 | F23: =D23/$D$2 -> -20.166373 | G23: 62 | H23: 0 | I23: =G23+H23 -> 62 | J23: =IF(L23>0,L23,0) -> 0 | K23: =I23+J23 -> 62 | L23: =F23-(I23-W23) -> -0.16637257 | M23: 4 | O23: 0 | P23: =M23-(N23+O23) -> 4 | Q23: 0 | R23: 0 | S23: =SUM(P23:R23) -> 4 | U23: 0 | V23: 78 | W23: =N23+O23+S23+U23+V23 -> 82 | X23: =IF(L23<0,L23*-1,0) -> 0.16637257 | Y23: =W23+X23 -> 82.166373 | Z23: 0 | AA23: 36 | AB23: 2 | AC23: =AC22+1 -> 14
A24: =A23+1 -> 15 | B24: 6910.91 | C24: 325638 | D24: =C24-C23 -> -40 | E24: =C24-152000 -> 173638 | F24: =D24/$D$2 -> -20.166373 | G24: 62 | H24: 0 | I24: =G24+H24 -> 62 | J24: =IF(L24>0,L24,0) -> 0 | K24: =I24+J24 -> 62 | L24: =F24-(I24-W24) -> -0.16637257 | M24: 4 | O24: 0 | P24: =M24-(N24+O24) -> 4 | Q24: 0 | R24: 0 | S24: =SUM(P24:R24) -> 4 | U24: 0 | V24: 78 | W24: =N24+O24+S24+U24+V24 -> 82 | X24: =IF(L24<0,L24*-1,0) -> 0.16637257 | Y24: =W24+X24 -> 82.166373 | Z24: 0.04 | AA24: 34 | AB24: 7 | AC24: =AC23+1 -> 15
A25: =A24+1 -> 16 | B25: 6910.9 | C25: 325598 | D25: =C25-C24 -> -40 | E25: =C25-152000 -> 173598 | F25: =D25/$D$2 -> -20.166373 | G25: 62 | H25: 0 | I25: =G25+H25 -> 62 | J25: =IF(L25>0,L25,0) -> 0 | K25: =I25+J25 -> 62 | L25: =F25-(I25-W25) -> -0.16637257 | M25: 4 | O25: 0 | P25: =M25-(N25+O25) -> 4 | Q25: 0 | R25: 0 | S25: =SUM(P25:R25) -> 4 | U25: 0 | V25: 78 | W25: =N25+O25+S25+U25+V25 -> 82 | X25: =IF(L25<0,L25*-1,0) -> 0.16637257 | Y25: =W25+X25 -> 82.166373 | Z25: 0.1 | AA25: 32 | AB25: 12 | AC25: =AC24+1 -> 16
A26: =A25+1 -> 17 | B26: 6910.89 | C26: 325558 | D26: =C26-C25 -> -40 | E26: =C26-152000 -> 173558 | F26: =D26/$D$2 -> -20.166373 | G26: 62 | H26: 0 | I26: =G26+H26 -> 62 | J26: =IF(L26>0,L26,0) -> 0 | K26: =I26+J26 -> 62 | L26: =F26-(I26-W26) -> -0.16637257 | M26: 4 | O26: 0 | P26: =M26-(N26+O26) -> 4 | Q26: 0 | R26: 0 | S26: =SUM(P26:R26) -> 4 | U26: 0 | V26: 78 | W26: =N26+O26+S26+U26+V26 -> 82 | X26: =IF(L26<0,L26*-1,0) -> 0.16637257 | Y26: =W26+X26 -> 82.166373 | Z26: 0.67 | AA26: 30 | AB26: 14 | AC26: =AC25+1 -> 17
A27: =A26+1 -> 18 | B27: 6910.88 | C27: 325518 | D27: =C27-C26 -> -40 | E27: =C27-152000 -> 173518 | F27: =D27/$D$2 -> -20.166373 | G27: 62 | H27: 0 | I27: =G27+H27 -> 62 | J27: =IF(L27>0,L27,0) -> 0 | K27: =I27+J27 -> 62 | L27: =F27-(I27-W27) -> -0.16637257 | M27: 4 | N27: 0 | O27: 0 | P27: =M27-(N27+O27) -> 4 | Q27: 0 | R27: 0 | S27: =SUM(P27:R27) -> 4 | U27: 0 | V27: 78 | W27: =N27+O27+S27+U27+V27 -> 82 | X27: =IF(L27<0,L27*-1,0) -> 0.16637257 | Y27: =W27+X27 -> 82.166373 | Z27: 0 | AA27: 30 | AB27: 22 | AC27: =AC26+1 -> 18
A28: =A27+1 -> 19 | B28: 6910.87 | C28: 325478 | D28: =C28-C27 -> -40 | E28: =C28-152000 -> 173478 | F28: =D28/$D$2 -> -20.166373 | G28: 62 | H28: 0 | I28: =G28+H28 -> 62 | J28: =IF(L28>0,L28,0) -> 0 | K28: =I28+J28 -> 62 | L28: =F28-(I28-W28) -> -0.16637257 | M28: 4 | N28: 0 | O28: 0 | P28: =M28-(N28+O28) -> 4 | Q28: 0 | R28: 0 | S28: =SUM(P28:R28) -> 4 | U28: 0 | V28: 78 | W28: =N28+O28+S28+U28+V28 -> 82 | X28: =IF(L28<0,L28*-1,0) -> 0.16637257 | Y28: =W28+X28 -> 82.166373 | Z28: 0 | AA28: 24 | AB28: 10 | AC28: =AC27+1 -> 19
A29: =A28+1 -> 20 | B29: 6910.86 | C29: 325438 | D29: =C29-C28 -> -40 | E29: =C29-152000 -> 173438 | F29: =D29/$D$2 -> -20.166373 | G29: 62 | H29: 0 | I29: =G29+H29 -> 62 | J29: =IF(L29>0,L29,0) -> 0 | K29: =I29+J29 -> 62 | L29: =F29-(I29-W29) -> -0.16637257 | M29: 4 | N29: 0 | O29: 0 | P29: =M29-(N29+O29) -> 4 | Q29: 0 | R29: 0 | S29: =SUM(P29:R29) -> 4 | U29: 0 | V29: 78 | W29: =N29+O29+S29+U29+V29 -> 82 | X29: =IF(L29<0,L29*-1,0) -> 0.16637257 | Y29: =W29+X29 -> 82.166373 | Z29: 0 | AA29: 20 | AB29: -1 | AC29: =AC28+1 -> 20
A30: =A29+1 -> 21 | B30: 6910.85 | C30: 325397 | D30: =C30-C29 -> -41 | E30: =C30-152000 -> 173397 | F30: =D30/$D$2 -> -20.670532 | G30: 62 | H30: 0 | I30: =G30+H30 -> 62 | J30: =IF(L30>0,L30,0) -> 0 | K30: =I30+J30 -> 62 | L30: =F30-(I30-W30) -> -0.67053189 | M30: 4 | N30: 0 | O30: 0 | P30: =M30-(N30+O30) -> 4 | Q30: 0 | R30: 0 | S30: =SUM(P30:R30) -> 4 | U30: 0 | V30: 78 | W30: =N30+O30+S30+U30+V30 -> 82 | X30: =IF(L30<0,L30*-1,0) -> 0.67053189 | Y30: =W30+X30 -> 82.670532 | Z30: 0 | AA30: 20 | AB30: 0 | AC30: =AC29+1 -> 21
A31: =A30+1 -> 22 | B31: 6910.84 | C31: 325357 | D31: =C31-C30 -> -40 | E31: =C31-152000 -> 173357 | F31: =D31/$D$2 -> -20.166373 | G31: 62 | H31: 0 | I31: =G31+H31 -> 62 | J31: =IF(L31>0,L31,0) -> 0 | K31: =I31+J31 -> 62 | L31: =F31-(I31-W31) -> -0.16637257 | M31: 4 | N31: 0 | O31: 0 | P31: =M31-(N31+O31) -> 4 | Q31: 0 | R31: 0 | S31: =SUM(P31:R31) -> 4 | U31: 0 | V31: 78 | W31: =N31+O31+S31+U31+V31 -> 82 | X31: =IF(L31<0,L31*-1,0) -> 0.16637257 | Y31: =W31+X31 -> 82.166373 | Z31: 0 | AA31: 22 | AB31: -4 | AC31: =AC30+1 -> 22
A32: =A31+1 -> 23 | B32: 6910.83 | C32: 325317 | D32: =C32-C31 -> -40 | E32: =C32-152000 -> 173317 | F32: =D32/$D$2 -> -20.166373 | G32: 62 | H32: 0 | I32: =G32+H32 -> 62 | J32: =IF(L32>0,L32,0) -> 0 | K32: =I32+J32 -> 62 | L32: =F32-(I32-W32) -> -0.16637257 | M32: 4 | N32: 0 | O32: 0 | P32: =M32-(N32+O32) -> 4 | Q32: 0 | R32: 0 | S32: =SUM(P32:R32) -> 4 | U32: 0 | V32: 78 | W32: =N32+O32+S32+U32+V32 -> 82 | X32: =IF(L32<0,L32*-1,0) -> 0.16637257 | Y32: =W32+X32 -> 82.166373 | Z32: 0 | AA32: 24 | AB32: 10 | AC32: =AC31+1 -> 23
A33: =A32+1 -> 24 | B33: 6910.82 | C33: 325277 | D33: =C33-C32 -> -40 | E33: =C33-152000 -> 173277 | F33: =D33/$D$2 -> -20.166373 | G33: 62 | H33: 0 | I33: =G33+H33 -> 62 | J33: =IF(L33>0,L33,0) -> 0 | K33: =I33+J33 -> 62 | L33: =F33-(I33-W33) -> -0.16637257 | M33: 4 | N33: 0 | O33: 0 | P33: =M33-(N33+O33) -> 4 | Q33: 0 | R33: 0 | S33: =SUM(P33:R33) -> 4 | U33: 0 | V33: 78 | W33: =N33+O33+S33+U33+V33 -> 82 | X33: =IF(L33<0,L33*-1,0) -> 0.16637257 | Y33: =W33+X33 -> 82.166373 | Z33: 0 | AA33: 25 | AB33: 6 | AC33: =AC32+1 -> 24
A34: =A33+1 -> 25 | B34: 6910.81 | C34: 325237 | D34: =C34-C33 -> -40 | E34: =C34-152000 -> 173237 | F34: =D34/$D$2 -> -20.166373 | G34: 62 | H34: 0 | I34: =G34+H34 -> 62 | J34: =IF(L34>0,L34,0) -> 0 | K34: =I34+J34 -> 62 | L34: =F34-(I34-W34) -> -0.16637257 | M34: 4 | N34: 0 | O34: 0 | P34: =M34-(N34+O34) -> 4 | Q34: 0 | R34: 0 | S34: =SUM(P34:R34) -> 4 | U34: 0 | V34: 78 | W34: =N34+O34+S34+U34+V34 -> 82 | X34: =IF(L34<0,L34*-1,0) -> 0.16637257 | Y34: =W34+X34 -> 82.166373 | Z34: 0 | AA34: 29 | AB34: -3 | AC34: =AC33+1 -> 25
A35: =A34+1 -> 26 | B35: 6910.8 | C35: 325197 | D35: =C35-C34 -> -40 | E35: =C35-152000 -> 173197 | F35: =D35/$D$2 -> -20.166373 | G35: 62 | H35: 0 | I35: =G35+H35 -> 62 | J35: =IF(L35>0,L35,0) -> 0.83362743 | K35: =I35+J35 -> 62.833627 | L35: =F35-(I35-W35) -> 0.83362743 | M35: 4 | N35: 0 | O35: 0 | P35: =M35-(N35+O35) -> 4 | Q35: 0 | R35: 0 | S35: =SUM(P35:R35) -> 4 | U35: 0 | V35: 79 | W35: =N35+O35+S35+U35+V35 -> 83 | X35: =IF(L35<0,L35*-1,0) -> 0 | Y35: =W35+X35 -> 83 | Z35: 0 | AA35: 34 | AB35: 1 | AC35: =AC34+1 -> 26
A36: =A35+1 -> 27 | B36: 6910.78 | C36: 325117 | D36: =C36-C35 -> -80 | E36: =C36-152000 -> 173117 | F36: =D36/$D$2 -> -40.332745 | G36: 45 | H36: 0 | I36: =G36+H36 -> 45 | J36: =IF(L36>0,L36,0) -> 0 | K36: =I36+J36 -> 45 | L36: =F36-(I36-W36) -> -0.33274515 | M36: 4 | N36: 0 | O36: 0 | P36: =M36-(N36+O36) -> 4 | Q36: 0 | R36: 0 | S36: =SUM(P36:R36) -> 4 | U36: 0 | V36: 81 | W36: =N36+O36+S36+U36+V36 -> 85 | X36: =IF(L36<0,L36*-1,0) -> 0.33274515 | Y36: =W36+X36 -> 85.332745 | Z36: 0 | AA36: 48 | AB36: 1 | AC36: =AC35+1 -> 27
A37: =A36+1 -> 28 | B37: 6910.77 | C37: 325076 | D37: =C37-C36 -> -41 | E37: =C37-152000 -> 173076 | F37: =D37/$D$2 -> -20.670532 | G37: 65 | H37: 0 | I37: =G37+H37 -> 65 | J37: =IF(L37>0,L37,0) -> 0 | K37: =I37+J37 -> 65 | L37: =F37-(I37-W37) -> -0.67053189 | M37: 4 | N37: 0 | O37: 0 | P37: =M37-(N37+O37) -> 4 | Q37: 0 | R37: 0 | S37: =SUM(P37:R37) -> 4 | U37: 0 | V37: 81 | W37: =N37+O37+S37+U37+V37 -> 85 | X37: =IF(L37<0,L37*-1,0) -> 0.67053189 | Y37: =W37+X37 -> 85.670532 | Z37: 0 | AA37: 48 | AB37: 12 | AC37: =AC36+1 -> 28
A38: =A37+1 -> 29 | B38: 6910.76 | C38: 325036 | D38: =C38-C37 -> -40 | E38: =C38-152000 -> 173036 | F38: =D38/$D$2 -> -20.166373 | G38: 64 | H38: 0 | I38: =G38+H38 -> 64 | J38: =IF(L38>0,L38,0) -> 0.83362743 | K38: =I38+J38 -> 64.833627 | L38: =F38-(I38-W38) -> 0.83362743 | M38: 4 | O38: 0 | P38: =M38-(N38+O38) -> 4 | Q38: 0 | R38: 0 | S38: =SUM(P38:R38) -> 4 | U38: 0 | V38: 81 | W38: =N38+O38+S38+U38+V38 -> 85 | X38: =IF(L38<0,L38*-1,0) -> 0 | Y38: =W38+X38 -> 85 | Z38: 0 | AA38: 49 | AB38: 22 | AC38: =AC37+1 -> 29
A39: 30 | B39: 6910.75 | C39: 324996 | D39: =C39-C38 -> -40 | E39: =C39-152000 -> 172996 | F39: =D39/$D$2 -> -20.166373 | G39: 63 | H39: 0 | I39: =G39+H39 -> 63 | J39: =IF(L39>0,L39,0) -> 0 | K39: =I39+J39 -> 63 | L39: =F39-(I39-W39) -> -0.16637257 | M39: 4 | O39: 0 | P39: =M39-(N39+O39) -> 4 | Q39: 0 | R39: 0 | S39: =SUM(P39:R39) -> 4 | U39: 0 | V39: 79 | W39: =N39+O39+S39+U39+V39 -> 83 | X39: =IF(L39<0,L39*-1,0) -> 0.16637257 | Y39: =W39+X39 -> 83.166373 | Z39: 0 | AA39: 43 | AB39: 21 | AC39: 30
A40: 31 | B40: 6910.74 | C40: 324956 | D40: =C40-C39 -> -40 | E40: =C40-152000 -> 172956 | F40: =D40/$D$2 -> -20.166373 | G40: 63 | H40: 0 | I40: =G40+H40 -> 63 | J40: =IF(L40>0,L40,0) -> 0 | K40: =I40+J40 -> 63 | L40: =F40-(I40-W40) -> -0.16637257 | M40: 4 | O40: 0 | P40: =M40-(N40+O40) -> 4 | Q40: 0 | R40: 0 | S40: =SUM(P40:R40) -> 4 | U40: 0 | V40: 79 | W40: =N40+O40+S40+U40+V40 -> 83 | X40: =IF(L40<0,L40*-1,0) -> 0.16637257 | Y40: =W40+X40 -> 83.166373 | Z40: 0 | AA40: 40 | AB40: 18 | AC40: 31
AA41: 39
A42: MONTH / CFS | F42: =SUM(F10:F40) -> -648.34888 | G42: =SUM(G10:G40) -> 1894 | H42: =SUM(H10:H40) -> 0 | I42: =SUM(I10:I40) -> 1894 | J42: =SUM(J10:J40) -> 3.9934459 | K42: =SUM(K10:K40) -> 1897.9934 | L42: =SUM(L10:L40) -> -2.3488782 | M42: =SUM(M10:M41) -> 129 | N42: =SUM(N10:N40) -> 0 | O42: =SUM(O10:O40) -> 0 | P42: =SUM(P10:P40) -> 129 | Q42: =SUM(Q10:Q40) -> 0 | R42: =SUM(R10:R40) -> 0 | S42: =SUM(S10:S40) -> 129 | U42: =SUM(U10:U40) -> 0 | V42: =SUM(V10:V40) -> 2411 | W42: =SUM(W10:W40) -> 2540 | X42: =SUM(X10:X40) -> 6.3423242 | Y42: =SUM(Y10:Y40) -> 2546.3423 | Z42: =SUM(Z10:Z40) -> 2 | AA42: =AVERAGE(AA10:AA40) -> 32.612903 | AB42: =AVERAGE(AB10:AB40) -> 8.6129032 | AC42: AVE
A43: MONTH / AF | D43: =SUM(D10:D40) -> -1286 | F43: =F42*$D$2 -> -1286 | G43: =G42*$D$2 -> 3756.749 | H43: =H42*$D$2 -> 0 | I43: =I42*$D$2 -> 3756.749 | J43: =J42*$D$2 -> 7.921 | K43: =K42*$D$2 -> 3764.67 | L43: =L42*$D$2 -> -4.659 | M43: =M42*$D$2 -> 255.8715 | ... S43: =S42*$D$2 -> 255.8715 | U43: =U42*$D$2 -> 0 | V43: =V42*$D$2 -> 4782.2185 | W43: =W42*$D$2 -> 5038.09 | X43: =X42*$D$2 -> 12.58 | Y43: =Y42*$D$2 -> 5050.67 | AA43: =MAX(AA10:AA40) -> 49 | AB43: =MAX(AB10:AB40) -> 22 | AC43: HI
...

Sheet FEB
K1: MC PHEE RESERVOIR IN/OUT FLOW TABULATION
A2: AF/cfs CONVERT FACTOR | D2: 1.9835 | K2: FEBRUARY "1988"
A4: DATE | B4: RESERV | C4: RESERV | D4: AC FT | E4: ACTIVE | F4: CONV TO | G4: DOLORES | H4: LOST | I4: RECORDED | J4: CALC | K4: TOTAL | L4: CALC | M4: TUNNEL | Q4: LONE | R4: U | S4: TOTAL | T4: MVI | U4: DV CR | V4: BELOW | W4: RECORDED | X4: CALC | Y4: TOTAL | Z4: RAIN | AA4: MAX | AB4: MIN | AC4: DATE
A5: FEB | B5: ELEV | C5: AC FT | D5: CHANGE | E5: CAP | F5: CFS | G5: RIVER | H5: CANYON | I5: INFLOW | J5: INFLOW | K5: INFLOW | L5: INF/OTF | M5: TOT DIV | N5: WETLAND | O5: UTE F&R | P5: MVI,CTZ | Q5: PINE | R5: LAT | S5: MVI | T5: CALL | U5: CANAL | V5: MC PHEE | W5: OUTFLOW | X5: OUTFLOW | Y5: OUTFLOW | AA5: TMP | AB5: TMP | AC5: FEB
A7: SEASON BAL
A8: YTD | B8: =JAN!B40 -> 6910.74 | C8: =JAN!C40 -> 324956 | D8: =JAN!$D$49 -> -1165 | E8: =JAN!$E$40 -> 172956 | F8: =JAN!F48 -> -587.3456 | G8: =JAN!G48 -> 8194 | H8: =JAN!H48 -> 0 | I8: =JAN!I48 -> 8194 | J8: =JAN!J48 -> 905.93244 | K8: =JAN!K48 -> 9099.9324 | L8: =JAN!L48 -> -6.3456012 | M8: =JAN!M48 -> 911 | ... Z8: =JAN!Z48 -> 6.14
A10: 1 | B10: 6910.73 | C10: 324916 | D10: =C10-C8 -> -40 | E10: =C10-152000 -> 172916 | F10: =D10/$D$2 -> -20.166373 | G10: 64 | H10: 0 | I10: =G10+H10 -> 64 | J10: =IF(L10>0,L10,0) -> 0 | K10: =I10+J10 -> 64 | L10: =F10-(I10-W10) -> -0.16637257 | M10: 5 | N10: 0 | O10: 0 | P10: =M10-(N10+O10) -> 5 | Q10: 0 | R10: 0 | S10: =SUM(P10:R10) -> 5 | U10: 0 | V10: 79 | W10: =N10+O10+S10+U10+V10 -> 84 | X10: =IF(L10<0,L10*-1,0) -> 0.16637257 | Y10: =W10+X10 -> 84.166373 | Z10: 0.1 | AA10: 38 | AB10: 16 | AC10: 1
A11: =A10+1 -> 2 | B11: 6910.72 | C11: 324876 | D11: =C11-C10 -> -40 | E11: =C11-152000 -> 172876 | F11: =D11/$D$2 -> -20.166373 | G11: 64 | H11: 0 | I11: =G11+H11 -> 64 | J11: =IF(L11>0,L11,0) -> 0 | K11: =I11+J11 -> 64 | L11: =F11-(I11-W11) -> -0.16637257 | M11: 5 | N11: 0 | O11: 0 | P11: =M11-(N11+O11) -> 5 | Q11: 0 | R11: 0 | S11: =SUM(P11:R11) -> 5 | U11: 0 | V11: 79 | W11: =N11+O11+S11+U11+V11 -> 84 | X11: =IF(L11<0,L11*-1,0) -> 0.16637257 | Y11: =W11+X11 -> 84.166373 | Z11: 0.53 | AA11: 34 | AB11: 26 | AC11: =AC10+1 -> 2
A12: =A11+1 -> 3 | B12: 6910.71 | C12: 324836 | D12: =C12-C11 -> -40 | E12: =C12-152000 -> 172836 | F12: =D12/$D$2 -> -20.166373 | G12: 63 | H12: 0 | I12: =G12+H12 -> 63 | J12: =IF(L12>0,L12,0) -> 0.83362743 | K12: =I12+J12 -> 63.833627 | L12: =F12-(I12-W12) -> 0.83362743 | M12: 5 | N12: 0 | O12: 0 | P12: =M12-(N12+O12) -> 5 | Q12: 0 | R12: 0 | S12: =SUM(P12:R12) -> 5 | U12: 0 | V12: 79 | W12: =N12+O12+S12+U12+V12 -> 84 | X12: =IF(L12<0,L12*-1,0) -> 0 | Y12: =W12+X12 -> 84 | Z12: 0 | AA12: 36 | AB12: 24 | AC12: =AC11+1 -> 3
A13: =A12+1 -> 4 | B13: 6910.7 | C13: 324796 | D13: =C13-C12 -> -40 | E13: =C13-152000 -> 172796 | F13: =D13/$D$2 -> -20.166373 | G13: 63 | H13: 0 | I13: =G13+H13 -> 63 | J13: =IF(L13>0,L13,0) -> 0.83362743 | K13: =I13+J13 -> 63.833627 | L13: =F13-(I13-W13) -> 0.83362743 | M13: 5 | N13: 0 | O13: 0 | P13: =M13-(N13+O13) -> 5 | Q13: 0 | R13: 0 | S13: =SUM(P13:R13) -> 5 | U13: 0 | V13: 79 | W13: =N13+O13+S13+U13+V13 -> 84 | X13: =IF(L13<0,L13*-1,0) -> 0 | Y13: =W13+X13 -> 84 | Z13: 0 | AA13: 39 | AB13: 4 | AC13: =AC12+1 -> 4
A14: =A13+1 -> 5 | B14: 6910.69 | C14: 324755 | D14: =C14-C13 -> -41 | E14: =C14-152000 -> 172755 | F14: =D14/$D$2 -> -20.670532 | G14: 63 | H14: 0 | I14: =G14+H14 -> 63 | J14: =IF(L14>0,L14,0) -> 0 | K14: =I14+J14 -> 63 | L14: =F14-(I14-W14) -> -0.67053189 | M14: 4 | N14: 0 | O14: 0 | P14: =M14-(N14+O14) -> 4 | Q14: 0 | R14: 0 | S14: =SUM(P14:R14) -> 4 | U14: 0 | V14: 79 | W14: =N14+O14+S14+U14+V14 -> 83 | X14: =IF(L14<0,L14*-1,0) -> 0.67053189 | Y14: =W14+X14 -> 83.670532 | Z14: 0 | AA14: 39 | AB14: 5 | AC14: =AC13+1 -> 5
A15: =A14+1 -> 6 | B15: 6910.68 | C15: 324715 | D15: =C15-C14 -> -40 | E15: =C15-152000 -> 172715 | F15: =D15/$D$2 -> -20.166373 | G15: 63 | H15: 0 | I15: =G15+H15 -> 63 | J15: =IF(L15>0,L15,0) -> 0 | K15: =I15+J15 -> 63 | L15: =F15-(I15-W15) -> -0.16637257 | M15: 4 | N15: 0 | O15: 0 | P15: =M15-(N15+O15) -> 4 | Q15: 0 | R15: 0 | S15: =SUM(P15:R15) -> 4 | U15: 0 | V15: 79 | W15: =N15+O15+S15+U15+V15 -> 83 | X15: =IF(L15<0,L15*-1,0) -> 0.16637257 | Y15: =W15+X15 -> 83.166373 | Z15: 0 | AA15: 38 | AB15: 7 | AC15: =AC14+1 -> 6
A16: =A15+1 -> 7 | B16: 6910.67 | C16: 324675 | D16: =C16-C15 -> -40 | E16: =C16-152000 -> 172675 | F16: =D16/$D$2 -> -20.166373 | G16: 63 | H16: 0 | I16: =G16+H16 -> 63 | J16: =IF(L16>0,L16,0) -> 0 | K16: =I16+J16 -> 63 | L16: =F16-(I16-W16) -> -0.16637257 | M16: 4 | N16: 0 | O16: 0 | P16: =M16-(N16+O16) -> 4 | Q16: 0 | R16: 0 | S16: =SUM(P16:R16) -> 4 | U16: 0 | V16: 79 | W16: =N16+O16+S16+U16+V16 -> 83 | X16: =IF(L16<0,L16*-1,0) -> 0.16637257 | Y16: =W16+X16 -> 83.166373 | Z16: 0 | AA16: 40 | AB16: 6 | AC16: =AC15+1 -> 7
A17: =A16+1 -> 8 | B17: 6910.66 | C17: 324635 | D17: =C17-C16 -> -40 | E17: =C17-152000 -> 172635 | F17: =D17/$D$2 -> -20.166373 | G17: 62 | H17: 0 | I17: =G17+H17 -> 62 | J17: =IF(L17>0,L17,0) -> 0 | K17: =I17+J17 -> 62 | L17: =F17-(I17-W17) -> -0.16637257 | M17: 4 | N17: 0 | O17: 0 | P17: =M17-(N17+O17) -> 4 | Q17: 0 | R17: 0 | S17: =SUM(P17:R17) -> 4 | U17: 0 | V17: 78 | W17: =N17+O17+S17+U17+V17 -> 82 | X17: =IF(L17<0,L17*-1,0) -> 0.16637257 | Y17: =W17+X17 -> 82.166373 | Z17: 0 | AA17: 39 | AB17: 0 | AC17: =AC16+1 -> 8
A18: =A17+1 -> 9 | B18: 6910.65 | C18: 324595 | D18: =C18-C17 -> -40 | E18: =C18-152000 -> 172595 | F18: =D18/$D$2 -> -20.166373 | G18: 61 | H18: 0 | I18: =G18+H18 -> 61 | J18: =IF(L18>0,L18,0) -> 0 | K18: =I18+J18 -> 61 | L18: =F18-(I18-W18) -> -0.16637257 | M18: 4 | N18: 0 | O18: 0 | P18: =M18-(N18+O18) -> 4 | Q18: 0 | R18: 0 | S18: =SUM(P18:R18) -> 4 | U18: 0 | V18: 77 | W18: =N18+O18+S18+U18+V18 -> 81 | X18: =IF(L18<0,L18*-1,0) -> 0.16637257 | Y18: =W18+X18 -> 81.166373 | Z18: 0 | AA18: 43 | AB18: 8 | AC18: =AC17+1 -> 9
A19: =A18+1 -> 10 | B19: 6910.64 | C19: 324555 | D19: =C19-C18 -> -40 | E19: =C19-152000 -> 172555 | F19: =D19/$D$2 -> -20.166373 | G19: 61 | H19: 0 | I19: =G19+H19 -> 61 | J19: =IF(L19>0,L19,0) -> 0 | K19: =I19+J19 -> 61 | L19: =F19-(I19-W19) -> -0.16637257 | M19: 4 | N19: 0 | O19: 0 | P19: =M19-(N19+O19) -> 4 | Q19: 0 | R19: 0 | S19: =SUM(P19:R19) -> 4 | U19: 0 | V19: 77 | W19: =N19+O19+S19+U19+V19 -> 81 | X19: =IF(L19<0,L19*-1,0) -> 0.16637257 | Y19: =W19+X19 -> 81.166373 | Z19: 0 | AA19: 37 | AB19: 14 | AC19: =AC18+1 -> 10
A20: =A19+1 -> 11 | B20: 6910.63 | C20: 324515 | D20: =C20-C19 -> -40 | E20: =C20-152000 -> 172515 | F20: =D20/$D$2 -> -20.166373 | G20: 61 | H20: 0 | I20: =G20+H20 -> 61 | J20: =IF(L20>0,L20,0) -> 0 | K20: =I20+J20 -> 61 | L20: =F20-(I20-W20) -> -0.16637257 | M20: 4 | N20: 0 | O20: 0 | P20: =M20-(N20+O20) -> 4 | Q20: 0 | R20: 0 | S20: =SUM(P20:R20) -> 4 | U20: 0 | V20: 77 | W20: =N20+O20+S20+U20+V20 -> 81 | X20: =IF(L20<0,L20*-1,0) -> 0.16637257 | Y20: =W20+X20 -> 81.166373 | Z20: 0 | AA20: 43 | AB20: 6 | AC20: =AC19+1 -> 11
A21: =A20+1 -> 12 | B21: 6910.62 | C21: 324474 | D21: =C21-C20 -> -41 | E21: =C21-152000 -> 172474 | F21: =D21/$D$2 -> -20.670532 | G21: 61 | H21: 0 | I21: =G21+H21 -> 61 | J21: =IF(L21>0,L21,0) -> 0.32946811 | K21: =I21+J21 -> 61.329468 | L21: =F21-(I21-W21) -> 0.32946811 | M21: 5 | N21: 0 | O21: 0 | P21: =M21-(N21+O21) -> 5 | Q21: 0 | R21: 0 | S21: =SUM(P21:R21) -> 5 | U21: 0 | V21: 77 | W21: =N21+O21+S21+U21+V21 -> 82 | X21: =IF(L21<0,L21*-1,0) -> 0 | Y21: =W21+X21 -> 82 | Z21: 0 | AA21: 44 | AB21: 12 | AC21: =AC20+1 -> 12
A22: =A21+1 -> 13 | B22: 6910.61 | C22: 324434 | D22: =C22-C21 -> -40 | E22: =C22-152000 -> 172434 | F22: =D22/$D$2 -> -20.166373 | G22: 61 | H22: 0 | I22: =G22+H22 -> 61 | J22: =IF(L22>0,L22,0) -> 0.83362743 | K22: =I22+J22 -> 61.833627 | L22: =F22-(I22-W22) -> 0.83362743 | M22: 5 | N22: 0 | O22: 0 | P22: =M22-(N22+O22) -> 5 | Q22: 0 | R22: 0 | S22: =SUM(P22:R22) -> 5 | U22: 0 | V22: 77 | W22: =N22+O22+S22+U22+V22 -> 82 | X22: =IF(L22<0,L22*-1,0) -> 0 | Y22: =W22+X22 -> 82 | Z22: 0 | AA22: 45 | AB22: 10 | AC22: =AC21+1 -> 13
... A36: =A35+1 -> 27 | B36: 6910.59 | C36: 324354 | D36: =C36-C35 -> 80 | E36: =C36-152000 -> 172354 | F36: =D36/$D$2 -> 40.332745 | G36: 122 | H36: 0 | I36: =G36+H36 -> 122 | J36: =IF(L36>0,L36,0) -> 0 | K36: =I36+J36 -> 122 | L36: =F36-(I36-W36) -> -0.66725485 | M36: 4 | N36: 0 | O36: 0 | P36: =M36-(N36+O36) -> 4 | Q36: 0 | R36: 0 | S36: =SUM(P36:R36) -> 4 | U36: 0 | V36: 77 | W36: =N36+O36+S36+U36+V36 -> 81 | X36: =IF(L36<0,L36*-1,0) -> 0.66725485 | Y36: =W36+X36 -> 81.667255 | Z36: 0 | AA36: 54 | AB36: 23 | AC36: =AC35+1 -> 27
A37: 28 | B37: 6910.62 | C37: 324474 | D37: =C37-C36 -> 120 | E37: =C37-152000 -> 172474 | F37: =D37/$D$2 -> 60.499118 | G37: 142 | H37: 0 | I37: =G37+H37 -> 142 | J37: =IF(L37>0,L37,0) -> 0 | K37: =I37-J37 -> 142 | L37: =F37-(I37-W37) -> -0.50088228 | M37: 4 | N37: 0 | O37: 0 | P37: =M37-(N37+O37) -> 4 | Q37: 0 | R37: 0 | S37: =SUM(P37:R37) -> 4 | U37: 0 | V37: 77 | W37: =N37+O37+S37+U37+V37 -> 81 | X37: =IF(L37<0,L37*-1,0) -> 0.50088228 | Y37: =W37+X37 -> 81.500882 | Z37: 0 | AA37: 53 | AB37: 34 | AC37: 28
A38: 29 | B38: 6910.65 | C38: 324595 | D38: =C38-C37 -> 121 | E38: =C38-152000 -> 172595 | F38: =D38/$D$2 -> 61.003277 | G38: 142 | H38: 0 | I38: =G38+H38 -> 142 | J38: =IF(L38>0,L38,0) -> 0.0032770355 | K38: =I38+J38 -> 142.00328 | L38: =F38-(I38-W38) -> 0.0032770355 | M38: 4 | N38: 0 | O38: 0 | P38: =M38-(N38+O38) -> 4 | Q38: 0 | R38: 0 | S38: =SUM(P38:R38) -> 4 | U38: 0 | V38: 77 | W38: =N38+O38+S38+U38+V38 -> 81 | X38: =IF(L38<0,L38*-1,0) -> 0 | Y38: =W38+X38 -> 81 | Z38: 0.02 | AA38: 53 | AB38: 24 | AC38: 29
A40: MONTH / CFS | F40: =SUM(F10:F38) -> -182.00151 | G40: =SUM(G10:G38) -> 2189 | H40: =SUM(H10:H39) -> 0 | I40: =SUM(I10:I38) -> 2189 | J40: =SUM(J10:J38) -> 5.5008823 | K40: =SUM(K10:K38) -> 2194.5009 | L40: =SUM(L10:L38) -> -1.0015125 | M40: =SUM(M10:M38) -> 123 | N40: =SUM(N10:N38) -> 0 | O40: =SUM(O10:O38) -> 0 | P40: =SUM(P10:P38) -> 123 | ... S40: =SUM(S10:S38) -> 123 | U40: =SUM(U10:U38) -> 0 | V40: =SUM(V10:V38) -> 2247 | W40: =SUM(W10:W38) -> 2370 | X40: =SUM(X10:X38) -> 6.5023948 | Y40: =SUM(Y10:Y38) -> 2376.5024 | Z40: =SUM(Z10:Z38) -> 0.65 | AA40: =AVERAGE(AA10:AA38) -> 42.862069 | AB40: =AVERAGE(AB10:AB38) -> 12.793103 | AC40: AVE
A41: MONTH / AF | D41: =SUM(D10:D38) -> -361 | F41: =F40*$D$2 -> -361 | G41: =G40*$D$2 -> 4341.8815 | H41: =H40*$D$2 -> 0 | I41: =I40*$D$2 -> 4341.8815 | J41: =J40*$D$2 -> 10.911 | K41: =K40*$D$2 -> 4352.7925 | L41: =L40*$D$2 -> -1.9865 | M41: =M40*$D$2 -> 243.9705 | ... S41: =S40*$D$2 -> 243.9705 | U41: =U40*$D$2 -> 0 | V41: =V40*$D$2 -> 4456.9245 | W41: =W40*$D$2 -> 4700.895 | X41: =X40*$D$2 -> 12.8975 | Y41: =Y40*$D$2 -> 4713.7925 | AA41: =MAX(AA10:AA38) -> 54 | AB41: =MAX(AB10:AB38) -> 34 | AC41: HI
A43: SEASON / CFS | AA43: =MIN(AA10:AA38) -> 34 | AB43: =MIN(AB10:AB38) -> 0 | AC43: LO
A44: SEASON / AF
A46: YTD / CFS | F46: =F8+F40 -> -769.34711 | G46: =G8+G40 -> 10383 | H46: =H8+H40 -> 0 | I46: =I8+I40 -> 10383 | J46: =J8+J40 -> 911.43332 | K46: =K8+K40 -> 11294.433 | L46: =L8+L40 -> -7.3471137 | M46: =M8+M40 -> 1034 | ... S46: =S8+S40 -> 1671 | U46: =U8+U40 -> 0 | V46: =V8+V40 -> 9474 | W46: =W8+W40 -> 11145 | X46: =X8+X40 -> 918.78044 | Y46: =Y8+Y40 -> 12063.78 | Z46: =Z8+Z40 -> 6.79
A47: YTD / AF | D47: =D8+D41 -> -1526 | E47: =E38 -> 172595 | F47: =F46*$D$2 -> -1526 | G47: =G46*$D$2 -> 20594.68 | H47: =H46*$D$2 -> 0 | I47: =I46*$D$2 -> 20594.68 | J47: =J46*$D$2 -> 1807.828 | K47: =K46*$D$2 -> 22402.508 | L47: =L46*$D$2 -> -14.573 | M47: =M46*$D$2 -> 2050.939 | ... Y47: =Y46*$D$2 -> 23928.508

Sheet MAR
K1: MC PHEE RESERVOIR IN/OUT FLOW TABULATION
A2: AF/cfs CONVERT FACTOR | D2: 1.9835 | K2: MARCH "1988"
A4: DATE | B4: RESERV | C4: RESERV | D4: AC FT | E4: ACTIVE | F4: CONV TO | G4: DOLORES | H4: LOST | I4: RECORDED | J4: CALC | K4: TOTAL | L4: CALC | M4: TUNNEL | Q4: LONE | R4: U | S4: TOTAL | T4: MVI | U4: DV CR | V4: BELOW | W4: RECORDED | X4: CALC | Y4: TOTAL | Z4: RAIN | AA4: MAX | AB4: MIN | AC4: DATE
A5: MAR | B5: ELEV | C5: AC FT | D5: CHANGE | E5: CAP | F5: CFS | G5: RIVER | H5: CANYON | I5: INFLOW | J5: INFLOW | K5: INFLOW | L5: INF/OTF | M5: TOT DIV | N5: WETLAND | O5: UTE F&R | P5: MVI,CTZ | Q5: PINE | R5: LAT | S5: MVI | T5: CALL | U5: CANAL | V5: MC PHEE | W5: OUTFLOW | X5: OUTFLOW | Y5: OUTFLOW | AA5: TMP | AB5: TMP | AC5: MAR
A7: SEASON BAL
A8: YTD | B8: =FEB!B38 -> 6910.65 | C8: =FEB!C38 -> 324595 | D8: =FEB!$D$47 -> -1526 | E8: =FEB!$E$47 -> 172595 | F8: =FEB!F46 -> -769.34711 | G8: =FEB!G46 -> 10383 | H8: =FEB!H46 -> 0 | I8: =FEB!I46 -> 10383 | J8: =FEB!J46 -> 911.43332 | K8: =FEB!K46 -> 11294.433 | L8: =FEB!L46 -> -7.3471137 | M8: =FEB!M46 -> 1034 | ... Z8: =FEB!Z46 -> 6.79
A10: 1 | B10: 6910.69 | C10: 324755 | D10: =C10-C8 -> 160 | E10: =C10-152000 -> 172755 | F10: =D10/$D$2 -> 80.66549 | G10: 162 | H10: 0 | I10: =G10+H10 -> 162 | J10: =IF(L10>0,L10,0) -> 0 | K10: =I10+J10 -> 162 | L10: =F10-(I10-W10) -> -1.3345097 | M10: 4 | N10: 0 | O10: 0 | P10: =M10-(N10+O10) -> 4 | Q10: 0 | R10: 0 | S10: =SUM(P10:R10) -> 4 | U10: 0 | V10: 76 | W10: =N10+O10+S10+U10+V10 -> 80 | X10: =IF(L10<0,L10*-1,0) -> 1.3345097 | Y10: =W10+X10 -> 81.33451 | Z10: 0 | AA10: 49 | AB10: 25 | AC10: 1
A11: =A10+1 -> 2 | B11: 6910.75 | C11: 324996 | D11: =C11-C10 -> 241 | E11: =C11-152000 -> 172996 | F11: =D11/$D$2 -> 121.50239 | G11: 205 | H11: 0 | I11: =G11+H11 -> 205 | J11: =IF(L11>0,L11,0) -> 0 | K11: =I11+J11 -> 205 | L11: =F11-(I11-W11) -> -1.4976052 | M11: 6 | N11: 0 | O11: 0 | P11: =M11-(N11+O11) -> 6 | Q11: 0 | R11: 0 | S11: =SUM(P11:R11) -> 6 | U11: 0 | V11: 76 | W11: =N11+O11+S11+U11+V11 -> 82 | X11: =IF(L11<0,L11*-1,0) -> 1.4976052 | Y11: =W11+X11 -> 83.497605 | Z11: 0 | AA11: 46 | AB11: 24 | AC11: =AC10+1 -> 2
A12: =A11+1 -> 3 | B12: 6910.8 | C12: 325197 | D12: =C12-C11 -> 201 | E12: =C12-152000 -> 173197 | F12: =D12/$D$2 -> 101.33602 | G12: 188 | H12: 0 | I12: =G12+H12 -> 188 | J12: =IF(L12>0,L12,0) -> 0 | K12: =I12+J12 -> 188 | L12: =F12-(I12-W12) -> -0.66397782 | M12: 9 | N12: 0 | O12: 0 | P12: =M12-(N12+O12) -> 9 | Q12: 0 | R12: 0 | S12: =SUM(P12:R12) -> 9 | U12: 0 | V12: 77 | W12: =N12+O12+S12+U12+V12 -> 86 | X12: =IF(L12<0,L12*-1,0) -> 0.66397782 | Y12: =W12+X12 -> 86.663978 | Z12: 0 | AA12: 44 | AB12: 21 | AC12: =AC11+1 -> 3
A13: =A12+1 -> 4 | B13: 6910.86 | C13: 325438 | D13: =C13-C12 -> 241 | E13: =C13-152000 -> 173438 | F13: =D13/$D$2 -> 121.50239 | G13: 210 | H13: 0 | I13: =G13+H13 -> 210 | J13: =IF(L13>0,L13,0) -> 0 | K13: =I13+J13 -> 210 | L13: =F13-(I13-W13) -> -1.4976052 | M13: 11 | N13: 0 | O13: 0 | P13: =M13-(N13+O13) -> 11 | Q13: 0 | R13: 0 | S13: =SUM(P13:R13) -> 11 | U13: 0 | V13: 76 | W13: =N13+O13+S13+U13+V13 -> 87 | X13: =IF(L13<0,L13*-1,0) -> 1.4976052 | Y13: =W13+X13 -> 88.497605 | Z13: 0 | AA13: 51 | AB13: 19 | AC13: =AC12+1 -> 4
A14: =A13+1 -> 5 | B14: 6910.93 | C14: 325718 | D14: =C14-C13 -> 280 | E14: =C14-152000 -> 173718 | F14: =D14/$D$2 -> 141.16461 | G14: 233 | H14: 0 | I14: =G14+H14 -> 233 | J14: =IF(L14>0,L14,0) -> 0 | K14: =I14+J14 -> 233 | L14: =F14-(I14-W14) -> -0.83539198 | M14: 14 | N14: 0 | O14: 0 | P14: =M14-(N14+O14) -> 14 | Q14: 0 | R14: 0 | S14: =SUM(P14:R14) -> 14 | U14: 0 | V14: 77 | W14: =N14+O14+S14+U14+V14 -> 91 | X14: =IF(L14<0,L14*-1,0) -> 0.83539198 | Y14: =W14+X14 -> 91.835392 | Z14: 0 | AA14: 56 | AB14: 20 | AC14: =AC13+1 -> 5
A15: =A14+1 -> 6 | B15: 6911.01 | C15: 326040 | D15: =C15-C14 -> 322 | E15: =C15-152000 -> 174040 | F15: =D15/$D$2 -> 162.3393 | G15: 128 | H15: 0 | I15: =G15+H15 -> 128 | J15: =IF(L15>0,L15,0) -> 124.3393 | K15: =I15+J15 -> 252.3393 | L15: =F15-(I15-W15) -> 124.3393 | M15: 14 | N15: 0 | O15: 0 | P15: =M15-(N15+O15) -> 14 | Q15: 0 | R15: 0 | S15: =SUM(P15:R15) -> 14 | U15: 0 | V15: 76 | W15: =N15+O15+S15+U15+V15 -> 90 | X15: =IF(L15<0,L15*-1,0) -> 0 | Y15: =W15+X15 -> 90 | Z15: 0.02 | AA15: 48 | AB15: 22 | AC15: =AC14+1 -> 6
A16: =A15+1 -> 7 | B16: 6911.02 | C16: 326080 | D16: =C16-C15 -> 40 | E16: =C16-152000 -> 174080 | F16: =D16/$D$2 -> 20.166373 | G16: 123 | H16: 0 | I16: =G16+H16 -> 123 | J16: =IF(L16>0,L16,0) -> 0 | K16: =I16+J16 -> 123 | L16: =F16-(I16-W16) -> -8.8336274 | M16: 17 | N16: 0 | O16: 0 | P16: =M16-(N16+O16) -> 17 | Q16: 0 | R16: 0 | S16: =SUM(P16:R16) -> 17 | U16: 0 | V16: 77 | W16: =N16+O16+S16+U16+V16 -> 94 | X16: =IF(L16<0,L16*-1,0) -> 8.8336274 | Y16: =W16+X16 -> 102.83363 | Z16: 0 | AA16: 34 | AB16: 18 | AC16: =AC15+1 -> 7
A17: =A16+1 -> 8 | B17: 6911.03 | C17: 326121 | D17: =C17-C16 -> 41 | E17: =C17-152000 -> 174121 | F17: =D17/$D$2 -> 20.670532 | G17: 95 | H17: 0 | I17: =G17+H17 -> 95 | J17: =IF(L17>0,L17,0) -> 20.670532 | K17: =I17+J17 -> 115.67053 | L17: =F17-(I17-W17) -> 20.670532 | M17: 19 | N17: 0 | O17: 0 | P17: =M17-(N17+O17) -> 19 | Q17: 0 | R17: 0 | S17: =SUM(P17:R17) -> 19 | U17: 0 | V17: 76 | W17: =N17+O17+S17+U17+V17 -> 95 | X17: =IF(L17<0,L17*-1,0) -> 0 | Y17: =W17+X17 -> 95 | Z17: 0 | AA17: 39 | AB17: 10 | AC17: =AC16+1 -> 8
A18: =A17+1 -> 9 | B18: 6911.04 | C18: 326161 | D18: =C18-C17 -> 40 | E18: =C18-152000 -> 174161 | F18: =D18/$D$2 -> 20.166373 | G18: 96 | H18: 0 | I18: =G18+H18 -> 96 | J18: =IF(L18>0,L18,0) -> 18.166373 | K18: =I18+J18 -> 114.16637 | L18: =F18-(I18-W18) -> 18.166373 | M18: 19 | N18: 0 | O18: 0 | P18: =M18-(N18+O18) -> 19 | Q18: 0 | R18: 0 | S18: =SUM(P18:R18) -> 19 | U18: 0 | V18: 75 | W18: =N18+O18+S18+U18+V18 -> 94 | X18: =IF(L18<0,L18*-1,0) -> 0 | Y18: =W18+X18 -> 94 | Z18: 0.03 | AA18: 42 | AB18: 13 | AC18: =AC17+1 -> 9
A19: =A18+1 -> 10 | B19: 6911.05 | C19: 326202 | D19: =C19-C18 -> 41 | E19: =C19-152000 -> 174202 | F19: =D19/$D$2 -> 20.670532 | G19: 118 | H19: 0 | I19: =G19+H19 -> 118 | J19: =IF(L19>0,L19,0) -> 0 | K19: =I19+J19 -> 118 | L19: =F19-(I19-W19) -> -2.3294681 | M19: 19 | N19: 0 | O19: 0 | P19: =M19-(N19+O19) -> 19 | Q19: 0 | R19: 0 | S19: =SUM(P19:R19) -> 19 | U19: 0 | V19: 76 | W19: =N19+O19+S19+U19+V19 -> 95 | X19: =IF(L19<0,L19*-1,0) -> 2.3294681 | Y19: =W19+X19 -> 97.329468 | Z19: 0.22 | AA19: 30 | AB19: 20 | AC19: =AC18+1 -> 10
A20: =A19+1 -> 11 | B20: 6911.07 | C20: 326283 | D20: =C20-C19 -> 81 | E20: =C20-152000 -> 174283 | F20: =D20/$D$2 -> 40.836904 | G20: 95 | H20: 0 | I20: =G20+H20 -> 95 | J20: =IF(L20>0,L20,0) -> 36.836904 | K20: =I20+J20 -> 131.8369 | L20: =F20-(I20-W20) -> 36.836904 | M20: 15 | N20: 0 | O20: 0 | P20: =M20-(N20+O20) -> 15 | Q20: 0 | R20: 0 | S20: =SUM(P20:R20) -> 15 | U20: 0 | V20: 76 | W20: =N20+O20+S20+U20+V20 -> 91 | X20: =IF(L20<0,L20*-1,0) -> 0 | Y20: =W20+X20 -> 91 | Z20: 0 | AA20: 32 | AB20: 9 | AC20: =AC19+1 -> 11
A21: =A20+1 -> 12 | B21: 6911.08 | C21: 326323 | D21: =C21-C20 -> 40 | E21: =C21-152000 -> 174323 | F21: =D21/$D$2 -> 20.166373 | G21: 81 | H21: 0 | I21: =G21+H21 -> 81 | J21: =IF(L21>0,L21,0) -> 28.166373 | K21: =I21+J21 -> 109.16637 | L21: =F21-(I21-W21) -> 28.166373 | M21: 13 | N21: 0 | O21: 0 | P21: =M21-(N21+O21) -> 13 | Q21: 0 | R21: 0 | S21: =SUM(P21:R21) -> 13 | U21: 0 | V21: 76 | W21: =N21+O21+S21+U21+V21 -> 89 | X21: =IF(L21<0,L21*-1,0) -> 0 | Y21: =W21+X21 -> 89 | Z21: 0 | AA21: 31 | AB21: 12 | AC21: =AC20+1 -> 12
A22: =A21+1 -> 13 | B22: 6911.09 | C22: 326363 | D22: =C22-C21 -> 40 | E22: =C22-152000 -> 174363 | F22: =D22/$D$2 -> 20.166373 | G22: 99 | H22: 0 | I22: =G22+H22 -> 99 | J22: =IF(L22>0,L22,0) -> 11.166373 | K22: =I22+J22 -> 110.16637 | L22: =F22-(I22-W22) -> 11.166373 | M22: 13 | N22: 0 | O22: 0 | P22: =M22-(N22+O22) -> 13 | Q22: 0 | R22: 0 | S22: =SUM(P22:R22) -> 13 | U22: 0 | V22: 77 | W22: =N22+O22+S22+U22+V22 -> 90 | X22: =IF(L22<0,L22*-1,0) -> 0 | Y22: =W22+X22 -> 90 | Z22: 0 | AA22: 33 | AB22: 14 | AC22: =AC21+1 -> 13
