Workbook

Sheet NOV
K1: MCPHEE RESERVOIR INFLOW/OUTFLOW TABULATION
A2: AF/cfs CONVERT FACTOR | D2: 1.9835 | L2: NOVEMBER "2012"
D4: RESERVOIR | I4: INFLOW | X4: OUTFLOW | AP4: ADJUSTMENTS | AW4: WEATHER
A5: DATE | B5: RESERV | C5: RESERV | D5: AC FT | E5: ACTIVE | F5: CONV TO | G5: DOLORES | H5: LOST | I5: RECORD | J5: CALC | K5: TOTAL | L5: CALC | M5: DOLORES TUNNEL | V5: LONE | W5: U | X5: TOTAL | Y5: TOTAL | Z5: MVI | AA5: MVI | AB5: MVI | AC5: TO EX & | AD5: MVI | AE5: DV CR | AF5: D/S SENIOR | AH5: BELOW | AI5: FISH | AJ5: SPILL | AK5: RECORD | AL5: CALC | AM5: TOTAL | AN5: NAR | AO5: MVI | AP5: MVI | AQ5: MVI | AR5: DIST. | AS5: U/S | AT5: TOTTEN | AU5: UTES | AV5: RAIN | AW5: MAX | AX5: MIN | AZ5: TOTAL
A6: NOV | B6: ELEV | D6: CHANGE | E6: CAP | F6: CFS | G6: RIVER | H6: CAN | I6: INFLOW | J6: INFLOW | K6: INFLOW | L6: INF/OTF | M6: TOT DIV | N6: WET | O6: UTE | P6: QUEST | Q6: MWC | R6: CORTEZ | T6: UTE | U6: F-BAY | V6: PINE | W6: LAT | X6: MVI | Y6: MVI | Z6: CALL | AA6: CALL | AB6: APR- | AC6: U/S EX | AD6: PROJ | AE6: CANAL | AF6: MVIC | AG6: PROJ | AH6: MCP | AI6: LEFT | AK6: OTF | AL6: OTF | AM6: OTF | AN6: FILL | AO6: STOCK | AP6: STORED | AQ6: STORED | AR6: CLASS | AS6: USERS | AT6: (FRESH | AU6: FROM | AW6: TMP | AX6: TMP | AZ6: TUNNEL
N7: LAND | O7: F&R | Q7: NON - | R7: NON - | S7: PROJ | T7: PROJ | U7: BAL | X7: WATER | Y7: IRRIG. | Z7: STOR | AA7: SPILLED | AB7: JUNE | AF7: 1.7 | AG7: 1.3 | AI7: 31798 | AP7: Apr - Jun | AQ7: EVAP | AR7: "B" | AS7: EXCH | AT7: WATER) | AU7: DWCD | AZ7: Misc.
Q8: PROJ | R8: PROJ | X8: USED | Y8: WATER | AA8: OR | AB8: (DIV+
R9: 4.2 | Y9: USED | AA9: USED | AB9: CALL)
C10: AC. Ft. | E10: AC FT | G10: CFS | H10: CFS | I10: CFS | J10: CFS | K10: CFS | L10: CFS | M10: CFS | N10: CFS | O10: CFS | P10: CFS | Q10: CFS | R10: CFS | S10: CFS | T10: CFS | U10: CFS | V10: CFS | W10: CFS | X10: 153400 | Y10: 150400 | AB10: 72000 | AC10: CFS | AD10: CFS | AE10: CFS | AF10: CFS | AG10: CFS | AH10: CFS | AI10: CFS | AJ10: CFS | AK10: CFS | AL10: CFS | AM10: CFS | AN10: CFS | AO10: CFS | AP10: CFS | AQ10: AC.FT. | AR10: CFS | AS10: CFS | AT10: CFS | AU10: CFS | AZ10: Outflow
N11: 1.03 | O11: 1.05 | P11: 1.02 | Q11: 1.02 | R11: 1.04 | T11: 1.04 | X11: CFS | Y11: CFS | Z11: CFS | AA11: CFS | AB11: Ac. Ft. | AZ11: CFS
A12: SEASON BAL
A13: YTD | B13: 6872.71 | C13: 195155 | AI13: 4247
A15: 1 | B15: 6872.7 | C15: 195127 | D15: =C15-C13 -> -28 | E15: =C15-152000 -> 43127 | F15: =D15/$D$2 -> -14.116461 | G15: 29 | H15: 0 | I15: =G15+H15 -> 29 | J15: =IF(L15>0,L15,0) -> 0 | K15: =I15+J15 -> 29 | L15: =F15-(I15-AK15) -> -9.8164608 | M15: 4.27 | N15: 0 | O15: =4.6*1.05 -> 4.83 | P15: 0 | Q15: =924900/325851/1.9835*1.02 -> 1.459633 | R15: =((2.3)*1.04)-T15 -> 1.9792614 | S15: 0 | T15: =(0.3744*1.06)*1.04 -> 0.41273856 | U15: =M15-(Q15+R15+S15+T15) -> 0.41836695 | V15: 0 | W15: 0 | X15: =M15-N15-P15-Q15-R15-S15-T15-U15+V15+W15 -> 0 | Y15: =X15-AO15 -> 0 | AE15: 0 | AH15: 24.2 | AI15: =AI13-AH15 -> 4222.8 | AK15: =N15+O15+P15+Q15+R15+S15+T15+U15+X15+AE15+AH15 -> 33.3 | AL15: =IF(L15<0,L15*-1,0) -> 9.8164608 | AM15: =AK15+AL15 -> 43.116461 | AV15: 0 | AW15: 71 | AX15: 34 | AZ15: =SUM(N15,P15:U15) -> 4.27
A16: =A15+1 -> 2 | B16: 6872.69 | C16: 195100 | D16: =C16-C15 -> -27 | E16: =C16-152000 -> 43100 | F16: =D16/$D$2 -> -13.612301 | G16: 29 | H16: 0 | I16: =G16+H16 -> 29 | J16: =IF(L16>0,L16,0) -> 0 | K16: =I16+J16 -> 29 | L16: =F16-(I16-AK16) -> -14.832301 | M16: 3.58 | N16: 0 | O16: 0 | P16: 0 | Q16: =982700/325851/1.9835*1.02 -> 1.5508503 | R16: =((2.3)*1.04)-T16 -> 1.8559029 | S16: 0 | T16: =(0.4863*1.06)*1.04 -> 0.53609712 | U16: =M16-(Q16+R16+S16+T16) -> -0.36285025 | V16: 0 | W16: 0 | X16: =M16-N16-P16-O16-Q16-R16-S16-T16-U16+V16+W16 -> 0 | Y16: =X16-AO16 -> 0 | AE16: 0 | AH16: 24.2 | AI16: =AI15-AH16 -> 4198.6 | AK16: =N16+O16+P16+Q16+R16+S16+T16+U16+X16+AE16+AH16 -> 27.78 | AL16: =IF(L16<0,L16*-1,0) -> 14.832301 | AM16: =AK16+AL16 -> 42.612301 | AV16: 0 | AW16: 65 | AX16: 35 | AZ16: =SUM(N16,P16:U16) -> 3.58
A17: =A16+1 -> 3 | B17: 6872.69 | C17: 195100 | D17: =C17-C16 -> 0 | E17: =C17-152000 -> 43100 | F17: =D17/$D$2 -> 0 | G17: 28 | H17: 0 | I17: =G17+H17 -> 28 | J17: =IF(L17>0,L17,0) -> 0.8 | K17: =I17+J17 -> 28.8 | L17: =F17-(I17-AK17) -> 0.8 | M17: 4.4 | N17: 0 | O17: 0 | P17: 0 | Q17: =1131900/325851/1.9835*1.02 -> 1.7863106 | R17: =((2.3)*1.04)-T17 -> 1.8559029 | S17: 0 | T17: =(0.4863*1.06)*1.04 -> 0.53609712 | U17: =M17-(Q17+R17+S17+T17) -> 0.22168943 | V17: 0 | W17: 0 | X17: =M17-N17-P17-O17-Q17-R17-S17-T17-U17+V17+W17 -> 0 | Y17: =X17-AO17 -> 0 | AE17: 0 | AH17: 24.4 | AI17: =AI16-AH17 -> 4174.2 | AK17: =N17+O17+P17+Q17+R17+S17+T17+U17+X17+AE17+AH17 -> 28.8 | AL17: =IF(L17<0,L17*-1,0) -> 0 | AM17: =AK17+AL17 -> 28.8 | AV17: 0 | AW17: 66 | AX17: 31 | AZ17: =SUM(N17,P17:U17) -> 4.4
A18: =A17+1 -> 4 | B18: 6872.69 | C18: 195100 | D18: =C18-C17 -> 0 | E18: =C18-152000 -> 43100 | F18: =D18/$D$2 -> 0 | G18: 27 | H18: 0 | I18: =G18+H18 -> 27 | J18: =IF(L18>0,L18,0) -> 1.79 | K18: =I18+J18 -> 28.79 | L18: =F18-(I18-AK18) -> 1.79 | M18: 4.19 | N18: 0 | O18: 0 | P18: 0 | Q18: =1211700/325851/1.9835*1.02 -> 1.9122471 | R18: =((2.3)*1.04)-T18 -> 1.8559029 | S18: 0 | T18: =(0.4863*1.06)*1.04 -> 0.53609712 | U18: =M18-(Q18+R18+S18+T18) -> -0.11424713 | V18: 0 | W18: 0 | X18: =M18-N18-P18-O18-Q18-R18-S18-T18-U18+V18+W18 -> -4.4408921e-16 | Y18: =X18-AO18 -> -4.4408921e-16 | AE18: 0 | AH18: 24.6 | AI18: =AI17-AH18 -> 4149.6 | AK18: =N18+O18+P18+Q18+R18+S18+T18+U18+X18+AE18+AH18 -> 28.79 | AL18: =IF(L18<0,L18*-1,0) -> 0 | AM18: =AK18+AL18 -> 28.79 | AV18: 0 | AW18: 67 | AX18: 30 | AZ18: =SUM(N18,P18:U18) -> 4.19
A19: =A18+1 -> 5 | B19: 6872.64 | C19: 194962 | D19: =C19-C18 -> -138 | E19: =C19-152000 -> 42962 | F19: =D19/$D$2 -> -69.573985 | G19: 29 | H19: 0 | I19: =G19+H19 -> 29 | J19: =IF(L19>0,L19,0) -> 0 | K19: =I19+J19 -> 29 | L19: =F19-(I19-AK19) -> -5.0684854 | M19: 31 | N19: 0 | O19: =3.91*1.05 -> 4.1055 | P19: 0 | Q19: =1029600/325851/1.9835*1.02 -> 1.6248656 | R19: =((2.3)*1.04)-T19 -> 1.8559029 | S19: 0 | T19: =(0.4863*1.06)*1.04 -> 0.53609712 | U19: 0 | V19: 20.1 | W19: 13.6 | X19: =M19-N19-P19-Q19-R19-S19-T19-U19+V19+W19 -> 60.683134 | Y19: =X19-AO19 -> 0 | AE19: 0 | AH19: 24.7 | AI19: =AI18-AH19 -> 4124.9 | AK19: =N19+O19+P19+Q19+R19+S19+T19+U19+X19+AE19+AH19 -> 93.5055 | AL19: =IF(L19<0,L19*-1,0) -> 5.0684854 | AM19: =AK19+AL19 -> 98.573985 | AO19: =X19-AN19 -> 60.683134 | AV19: 0 | AW19: 71 | AX19: 38 | AZ19: =SUM(N19,P19:U19) -> 4.0168656
A20: =A19+1 -> 6 | B20: 6872.56 | C20: 194742 | D20: =C20-C19 -> -220 | E20: =C20-152000 -> 42742 | F20: =D20/$D$2 -> -110.91505 | G20: 29 | H20: 0 | I20: =G20+H20 -> 29 | J20: =IF(L20>0,L20,0) -> 0 | K20: =I20+J20 -> 29 | L20: =F20-(I20-AK20) -> -20.715049 | M20: 46.2 | N20: 0 | O20: 0 | P20: 0 | Q20: =1071200/325851/1.9835*1.02 -> 1.6905167 | R20: =((2.4)*1.04)-T20 -> 1.9599029 | S20: 0 | T20: =(0.4863*1.06)*1.04 -> 0.53609712 | U20: 0 | V20: 29 | W20: 19.2 | X20: =M20-N20-P20-O20-Q20-R20-S20-T20-U20+V20+W20 -> 90.213483 | Y20: =X20-AO20 -> 0 | AE20: 0 | AH20: 24.8 | AI20: =AI19-AH20 -> 4100.1 | AK20: =N20+O20+P20+Q20+R20+S20+T20+U20+X20+AE20+AH20 -> 119.2 | AL20: =IF(L20<0,L20*-1,0) -> 20.715049 | AM20: =AK20+AL20 -> 139.91505 | AO20: =X20-AN20 -> 90.213483 | AV20: 0 | AW20: 71 | AX20: 38 | AZ20: =SUM(N20,P20:U20) -> 4.1865167
A21: =A20+1 -> 7 | B21: 6872.49 | C21: 194549 | D21: =C21-C20 -> -193 | E21: =C21-152000 -> 42549 | F21: =D21/$D$2 -> -97.302748 | G21: 29 | H21: 0 | I21: =G21+H21 -> 29 | J21: =IF(L21>0,L21,0) -> 0 | K21: =I21+J21 -> 29 | L21: =F21-(I21-AK21) -> -8.1027477 | M21: 45.3 | N21: 0 | O21: 0 | P21: 0 | Q21: =1066900/325851/1.9835*1.02 -> 1.6837307 | R21: =((2.3)*1.04)-T21 -> 1.8559029 | S21: 0 | T21: =(0.4863*1.06)*1.04 -> 0.53609712 | U21: 0 | V21: 28.8 | W21: 19.3 | X21: =M21-N21-P21-O21-Q21-R21-S21-T21-U21+V21+W21 -> 89.324269 | Y21: =X21-AO21 -> 18 | AE21: 0 | AH21: 24.8 | AI21: =AI20-AH21 -> 4075.3 | AK21: =N21+O21+P21+Q21+R21+S21+T21+U21+X21+AE21+AH21 -> 118.2 | AL21: =IF(L21<0,L21*-1,0) -> 8.1027477 | AM21: =AK21+AL21 -> 126.30275 | AN21: 18 | AO21: =X21-AN21 -> 71.324269 | AV21: 0 | AW21: 69 | AX21: 33 | AZ21: =SUM(N21,P21:U21) -> 4.0757307
A22: =A21+1 -> 8 | B22: 6872.43 | C22: 194384 | D22: =C22-C21 -> -165 | E22: =C22-152000 -> 42384 | F22: =D22/$D$2 -> -83.186287 | G22: 28 | H22: 0 | I22: =G22+H22 -> 28 | J22: =IF(L22>0,L22,0) -> 12.413713 | K22: =I22+J22 -> 40.413713 | L22: =F22-(I22-AK22) -> 12.413713 | M22: 45 | N22: 0 | O22: 0 | P22: 0 | Q22: =1015700/325851/1.9835*1.02 -> 1.6029293 | R22: =((2.3)*1.04)-T22 -> 1.8559029 | S22: 0 | T22: =(0.4863*1.06)*1.04 -> 0.53609712 | U22: 0 | V22: 34.5 | W22: 19.4 | X22: =M22-N22-P22-O22-Q22-R22-S22-T22-U22+V22+W22 -> 94.905071 | Y22: =X22-AO22 -> 34.5 | AE22: 0 | AH22: 24.7 | AI22: =AI21-AH22 -> 4050.6 | AK22: =N22+O22+P22+Q22+R22+S22+T22+U22+X22+AE22+AH22 -> 123.6 | AL22: =IF(L22<0,L22*-1,0) -> 0 | AM22: =AK22+AL22 -> 123.6 | AN22: =V22 -> 34.5 | AO22: =X22-AN22 -> 60.405071 | AV22: 0 | AW22: 67 | AX22: 37 | AZ22: =SUM(N22,P22:U22) -> 3.9949293
A23: =A22+1 -> 9 | B23: 6872.42 | C23: 194357 | D23: =C23-C22 -> -27 | E23: =C23-152000 -> 42357 | F23: =D23/$D$2 -> -13.612301 | G23: 35 | H23: 0 | I23: =G23+H23 -> 35 | J23: =IF(L23>0,L23,0) -> 51.787699 | K23: =I23+J23 -> 86.787699 | L23: =F23-(I23-AK23) -> 51.787699 | M23: 32.1 | N23: 0 | O23: 0 | P23: 0 | Q23: =805700/325851/1.9835*1.02 -> 1.2715173 | R23: =((2.3)*1.04)-T23 -> 1.829335 | S23: 0 | T23: =(0.5104*1.06)*1.04 -> 0.56266496 | U23: 0 | V23: 30.5 | W23: 12.9 | X23: =M23-N23-P23-O23-Q23-R23-S23-T23-U23+V23+W23 -> 71.836483 | Y23: =X23-AO23 -> 30.5 | AE23: 0 | AH23: 24.9 | AI23: =AI22-AH23 -> 4025.7 | AK23: =N23+O23+P23+Q23+R23+S23+T23+U23+X23+AE23+AH23 -> 100.4 | AL23: =IF(L23<0,L23*-1,0) -> 0 | AM23: =AK23+AL23 -> 100.4 | AN23: =V23 -> 30.5 | AO23: =X23-AN23 -> 41.336483 | AV23: 0.23 | AW23: 62 | AX23: 42 | AZ23: =SUM(N23,P23:U23) -> 3.6635173
A24: =A23+1 -> 10 | B24: 6872.46 | C24: 194467 | D24: =C24-C23 -> 110 | E24: =C24-152000 -> 42467 | F24: =D24/$D$2 -> 55.457525 | G24: 53 | H24: 0 | I24: =G24+H24 -> 53 | J24: =IF(L24>0,L24,0) -> 52.027525 | K24: =I24+J24 -> 105.02752 | L24: =F24-(I24-AK24) -> 52.027525 | M24: 4.27 | N24: 0 | O24: 0 | P24: 0 | Q24: =1065500/325851/1.9835*1.02 -> 1.6815213 | R24: =((2.3)*1.04)-T24 -> 1.829335 | S24: 0 | T24: =(0.5104*1.06)*1.04 -> 0.56266496 | U24: =M24-(Q24+R24+S24+T24) -> 0.19647874 | V24: 20.3 | W24: 0 | X24: =M24-N24-P24-O24-Q24-R24-S24-T24-U24+V24+W24 -> 20.3 | Y24: =X24-AO24 -> 20.3 | AE24: 0 | AH24: 25 | AI24: =AI23-AH24 -> 4000.7 | AK24: =N24+O24+P24+Q24+R24+S24+T24+U24+X24+AE24+AH24 -> 49.57 | AL24: =IF(L24<0,L24*-1,0) -> 0 | AM24: =AK24+AL24 -> 49.57 | AN24: =V24 -> 20.3 | AO24: =X24-AN24 -> 0 | AV24: 0.12 | AW24: 50 | AX24: 16 | AZ24: =SUM(N24,P24:U24) -> 4.27
A25: =A24+1 -> 11 | B25: 6872.42 | C25: 194357 | D25: =C25-C24 -> -110 | E25: =C25-152000 -> 42357 | F25: =D25/$D$2 -> -55.457525 | G25: 38 | H25: 0 | I25: =G25+H25 -> 38 | J25: =IF(L25>0,L25,0) -> 0 | K25: =I25+J25 -> 38 | L25: =F25-(I25-AK25) -> -41.917525 | M25: 3.94 | N25: 0 | O25: 0 | P25: 0 | Q25: =1072500/325851/1.9835*1.02 -> 1.6925683 | R25: =((2.3)*1.04)-T25 -> 1.829335 | S25: 0 | T25: =(0.5104*1.06)*1.04 -> 0.56266496 | U25: =M25-(Q25+R25+S25+T25) -> -0.14456833 | V25: 22.7 | W25: 0 | X25: =M25-N25-P25-O25-Q25-R25-S25-T25-U25+V25+W25 -> 22.7 | Y25: =X25-AO25 -> 22.7 | AE25: 0 | AH25: 24.9 | AI25: =AI24-AH25 -> 3975.8 | AK25: =N25+O25+P25+Q25+R25+S25+T25+U25+X25+AE25+AH25 -> 51.54 | AL25: =IF(L25<0,L25*-1,0) -> 41.917525 | AM25: =AK25+AL25 -> 93.457525 | AN25: =V25 -> 22.7 | AO25: =X25-AN25 -> 0 | AV25: 0 | AW25: 33 | AX25: 12 | AZ25: =SUM(N25,P25:U25) -> 3.94
A26: =A25+1 -> 12 | B26: 6872.41 | C26: 194329 | D26: =C26-C25 -> -28 | E26: =C26-152000 -> 42329 | F26: =D26/$D$2 -> -14.116461 | G26: 27 | H26: 0 | I26: =G26+H26 -> 27 | J26: =IF(L26>0,L26,0) -> 0 | K26: =I26+J26 -> 27 | L26: =F26-(I26-AK26) -> -1.8064608 | M26: 3.91 | N26: 0 | O26: 0 | P26: 0 | Q26: =1116500/325851/1.9835*1.02 -> 1.762007 | R26: =((2.3)*1.04)-T26 -> 1.829335 | S26: 0 | T26: =(0.5104*1.06)*1.04 -> 0.56266496 | U26: =M26-(Q26+R26+S26+T26) -> -0.24400703 | V26: 10.5 | W26: 0 | X26: =M26-N26-P26-O26-Q26-R26-S26-T26-U26+V26+W26 -> 10.5 | Y26: =X26-AO26 -> 10.5 | AE26: 0 | AH26: 24.9 | AI26: =AI25-AH26 -> 3950.9 | AK26: =N26+O26+P26+Q26+R26+S26+T26+U26+X26+AE26+AH26 -> 39.31 | AL26: =IF(L26<0,L26*-1,0) -> 1.8064608 | AM26: =AK26+AL26 -> 41.116461 | AN26: =V26 -> 10.5 | AO26: =X26-AN26 -> 0 | AV26: 0.03 | AW26: 45 | AX26: 12 | AZ26: =SUM(N26,P26:U26) -> 3.91
A27: =A26+1 -> 13 | B27: 6872.4 | C27: 194302 | D27: =C27-C26 -> -27 | E27: =C27-152000 -> 42302 | F27: =D27/$D$2 -> -13.612301 | G27: 35 | H27: 0 | I27: =G27+H27 -> 35 | J27: =IF(L27>0,L27,0) -> 0 | K27: =I27+J27 -> 35 | L27: =F27-(I27-AK27) -> -18.802301 | M27: 3.44 | N27: 0 | O27: 0 | P27: 0 | Q27: =841800/325851/1.9835*1.02 -> 1.3284886 | R27: =((0)*1.04)-T27 -> -0.56266496 | S27: 0 | T27: =(0.5104*1.06)*1.04 -> 0.56266496 | U27: =M27-(Q27+R27+S27+T27) -> 2.1115114 | V27: 2.07 | W27: 0 | X27: =M27-N27-P27-O27-Q27-R27-S27-T27-U27+V27+W27 -> 2.07 | Y27: =X27-AO27 -> 2.07 | AE27: 0 | AH27: 24.3 | AI27: =AI26-AH27 -> 3926.6 | AK27: =N27+O27+P27+Q27+R27+S27+T27+U27+X27+AE27+AH27 -> 29.81 | AL27: =IF(L27<0,L27*-1,0) -> 18.802301 | AM27: =AK27+AL27 -> 48.612301 | AN27: =V27 -> 2.07 | AO27: =X27-AN27 -> 0 | AV27: 0.01 | AW27: 54 | AX27: 22 | AZ27: =SUM(N27,P27:U27) -> 3.44
A28: =A27+1 -> 14 | B28: 6872.39 | C28: 194279 | D28: =C28-C27 -> -23 | E28: =C28-152000 -> 42279 | F28: =D28/$D$2 -> -11.595664 | G28: 40 | H28: 0 | I28: =G28+H28 -> 40 | J28: =IF(L28>0,L28,0) -> 0 | K28: =I28+J28 -> 40 | L28: =F28-(I28-AK28) -> -24.135664 | M28: 4.36 | N28: 0 | O28: 0 | P28: 0 | Q28: =943200/325851/1.9835*1.02 -> 1.4885132 | R28: =((2.3)*1.04)-T28 -> 1.829335 | S28: 0 | T28: =(0.5104*1.06)*1.04 -> 0.56266496 | U28: =M28-(Q28+R28+S28+T28) -> 0.47948676 | V28: 0 | W28: 0 | X28: =M28-N28-P28-O28-Q28-R28-S28-T28-U28+V28+W28 -> 0 | Y28: =X28-AO28 -> 0 | AE28: 0 | AH28: 23.1 | AI28: =AI27-AH28 -> 3903.5 | AK28: =N28+O28+P28+Q28+R28+S28+T28+U28+X28+AE28+AH28 -> 27.46 | AL28: =IF(L28<0,L28*-1,0) -> 24.135664 | AM28: =AK28+AL28 -> 51.595664 | AN28: =V28 -> 0 | AO28: =X28-AN28 -> 0 | AV28: 0 | AW28: 57 | AX28: 24 | AZ28: =SUM(N28,P28:U28) -> 4.36
A29: =A28+1 -> 15 | B29: 6872.38 | C29: 194246 | D29: =C29-C28 -> -33 | E29: =C29-152000 -> 42246 | F29: =D29/$D$2 -> -16.637257 | G29: 40 | H29: 0 | I29: =G29+H29 -> 40 | J29: =IF(L29>0,L29,0) -> 0 | K29: =I29+J29 -> 40 | L29: =F29-(I29-AK29) -> -22.137257 | M29: 4.61 | N29: 0 | O29: 0 | P29: 0 | Q29: =886700/325851/1.9835*1.02 -> 1.3993476 | R29: =((2.3)*1.04)-T29 -> 1.829335 | S29: 0 | T29: =(0.5104*1.06)*1.04 -> 0.56266496 | U29: =M29-(Q29+R29+S29+T29) -> 0.81865237 | V29: 6.99 | W29: 0 | X29: =M29-N29-P29-O29-Q29-R29-S29-T29-U29+V29+W29 -> 6.99 | Y29: =X29-AO29 -> 6.99 | AE29: 0 | AH29: 22.9 | AI29: =AI28-AH29 -> 3880.6 | AK29: =N29+O29+P29+Q29+R29+S29+T29+U29+X29+AE29+AH29 -> 34.5 | AL29: =IF(L29<0,L29*-1,0) -> 22.137257 | AM29: =AK29+AL29 -> 56.637257 | AN29: =V29 -> 6.99 | AO29: =X29-AN29 -> 0 | AV29: 0 | AW29: 60 | AX29: 26 | AZ29: =SUM(N29,P29:U29) -> 4.61
A30: =A29+1 -> 16 | B30: 6872.36 | C30: 194191 | D30: =C30-C29 -> -55 | E30: =C30-152000 -> 42191 | F30: =D30/$D$2 -> -27.728762 | G30: 44 | H30: 0 | I30: =G30+H30 -> 44 | J30: =IF(L30>0,L30,0) -> 0 | K30: =I30+J30 -> 44 | L30: =F30-(I30-AK30) -> -20.598762 | M30: 4.63 | N30: 0 | O30: 0 | P30: 0 | Q30: =888000/325851/1.9835*1.02 -> 1.4013992 | R30: =((2.3)*1.04)-T30 -> 1.8902978 | S30: 0 | T30: =(0.4551*1.06)*1.04 -> 0.50170224 | U30: =M30-(Q30+R30+S30+T30) -> 0.83660077 | V30: 23.6 | W30: 0 | X30: =M30-N30-P30-O30-Q30-R30-S30-T30-U30+V30+W30 -> 23.6 | Y30: =X30-AO30 -> 23.6 | AE30: 0 | AH30: 22.9 | AI30: =AI29-AH30 -> 3857.7 | AK30: =N30+O30+P30+Q30+R30+S30+T30+U30+X30+AE30+AH30 -> 51.13 | AL30: =IF(L30<0,L30*-1,0) -> 20.598762 | AM30: =AK30+AL30 -> 71.728762 | AN30: =V30 -> 23.6 | AO30: =X30-AN30 -> 0 | AV30: 0 | AW30: 61 | AX30: 34 | AZ30: =SUM(N30,P30:U30) -> 4.63
A31: =A30+1 -> 17 | B31: 6872.35 | C31: 194164 | D31: =C31-C30 -> -27 | E31: =C31-152000 -> 42164 | F31: =D31/$D$2 -> -13.612301 | G31: 46 | H31: 0 | I31: =G31+H31 -> 46 | J31: =IF(L31>0,L31,0) -> 0 | K31: =I31+J31 -> 46 | L31: =F31-(I31-AK31) -> -5.3523015 | M31: 3.96 | N31: 0 | O31: 0 | P31: 0 | Q31: =994300/325851/1.9835*1.02 -> 1.5691568 | R31: =((2.5)*1.04)-T31 -> 2.0982978 | S31: 0 | T31: =(0.4551*1.06)*1.04 -> 0.50170224 | U31: =M31-(Q31+R31+S31+T31) -> -0.20915682 | V31: 27.4 | W31: 0 | X31: =M31-N31-P31-O31-Q31-R31-S31-T31-U31+V31+W31 -> 27.4 | Y31: =X31-AO31 -> 27.4 | AE31: 0 | AH31: 22.9 | AI31: =AI30-AH31 -> 3834.8 | AK31: =N31+O31+P31+Q31+R31+S31+T31+U31+X31+AE31+AH31 -> 54.26 | AL31: =IF(L31<0,L31*-1,0) -> 5.3523015 | AM31: =AK31+AL31 -> 59.612301 | AN31: =V31 -> 27.4 | AO31: =X31-AN31 -> 0 | AV31: 0 | AW31: 61 | AX31: 36 | AZ31: =SUM(N31,P31:U31) -> 3.96
A32: =A31+1 -> 18 | B32: 6872.34 | C32: 194136 | D32: =C32-C31 -> -28 | E32: =C32-152000 -> 42136 | F32: =D32/$D$2 -> -14.116461 | G32: 43 | H32: 0 | I32: =G32+H32 -> 43 | J32: =IF(L32>0,L32,0) -> 0 | K32: =I32+J32 -> 43 | L32: =F32-(I32-AK32) -> -6.2664608 | M32: 3.85 | N32: 0 | O32: 0 | P32: 0 | Q32: =1146000/325851/1.9835*1.02 -> 1.8085625 | R32: =((2.5)*1.04)-T32 -> 2.0982978 | S32: 0 | T32: =(0.4551*1.06)*1.04 -> 0.50170224 | U32: =M32-(Q32+R32+S32+T32) -> -0.55856252 | V32: 24.1 | W32: 0 | X32: =M32-N32-P32-O32-Q32-R32-S32-T32-U32+V32+W32 -> 24.1 | Y32: =X32-AO32 -> 24.1 | AE32: 0 | AH32: 22.9 | AI32: =AI31-AH32 -> 3811.9 | AK32: =N32+O32+P32+Q32+R32+S32+T32+U32+X32+AE32+AH32 -> 50.85 | AL32: =IF(L32<0,L32*-1,0) -> 6.2664608 | AM32: =AK32+AL32 -> 57.116461 | AN32: =V32 -> 24.1 | AO32: =X32-AN32 -> 0 | AV32: 0.02 | AW32: 57 | AX32: 33 | AZ32: =SUM(N32,P32:U32) -> 3.85
A33: =A32+1 -> 19 | B33: 6872.33 | C33: 194109 | D33: =C33-C32 -> -27 | E33: =C33-152000 -> 42109 | F33: =D33/$D$2 -> -13.612301 | G33: 37 | H33: 0 | I33: =G33+H33 -> 37 | J33: =IF(L33>0,L33,0) -> 0.60769851 | K33: =I33+J33 -> 37.607699 | L33: =F33-(I33-AK33) -> 0.60769851 | M33: 4.62 | N33: 0 | O33: 0 | P33: 0 | Q33: =956900/325851/1.9835*1.02 -> 1.5101339 | R33: =((2.4)*1.04)-T33 -> 1.9942978 | S33: 0 | T33: =(0.4551*1.06)*1.04 -> 0.50170224 | U33: =M33-(Q33+R33+S33+T33) -> 0.61386608 | V33: 23 | W33: 0 | X33: =M33-N33-P33-O33-Q33-R33-S33-T33-U33+V33+W33 -> 23 | Y33: =X33-AO33 -> 23 | AE33: 0 | AH33: 23.6 | AI33: =AI32-AH33 -> 3788.3 | AK33: =N33+O33+P33+Q33+R33+S33+T33+U33+X33+AE33+AH33 -> 51.22 | AL33: =IF(L33<0,L33*-1,0) -> 0 | AM33: =AK33+AL33 -> 51.22 | AN33: =V33 -> 23 | AO33: =X33-AN33 -> 0 | AV33: 0 | AW33: 58 | AX33: 31 | AZ33: =SUM(N33,P33:U33) -> 4.62
A34: =A33+1 -> 20 | B34: 6872.31 | C34: 194054 | D34: =C34-C33 -> -55 | E34: =C34-152000 -> 42054 | F34: =D34/$D$2 -> -27.728762 | G34: 30 | H34: 0 | I34: =G34+H34 -> 30 | J34: =IF(L34>0,L34,0) -> 0 | K34: =I34+J34 -> 30 | L34: =F34-(I34-AK34) -> -6.9387623 | M34: 4.39 | N34: 0 | O34: 0 | P34: 0 | Q34: =944100/325851/1.9835*1.02 -> 1.4899336 | R34: =((2.4)*1.04)-T34 -> 1.9942978 | S34: 0 | T34: =(0.4551*1.06)*1.04 -> 0.50170224 | U34: =M34-(Q34+R34+S34+T34) -> 0.40406643 | V34: 22.2 | W34: 0 | X34: =M34-N34-P34-O34-Q34-R34-S34-T34-U34+V34+W34 -> 22.2 | Y34: =X34-AO34 -> 22.2 | AE34: 0 | AH34: 24.2 | AI34: =AI33-AH34 -> 3764.1 | AK34: =N34+O34+P34+Q34+R34+S34+T34+U34+X34+AE34+AH34 -> 50.79 | AL34: =IF(L34<0,L34*-1,0) -> 6.9387623 | AM34: =AK34+AL34 -> 57.728762 | AN34: =V34 -> 22.2 | AO34: =X34-AN34 -> 0 | AV34: 0 | AW34: 61 | AX34: 29 | AZ34: =SUM(N34,P34:U34) -> 4.39
A35: =A34+1 -> 21 | B35: 6872.29 | C35: 193999 | D35: =C35-C34 -> -55 | E35: =C35-152000 -> 41999 | F35: =D35/$D$2 -> -27.728762 | G35: 28 | H35: 0 | I35: =G35+H35 -> 28 | J35: =IF(L35>0,L35,0) -> 0 | K35: =I35+J35 -> 28 | L35: =F35-(I35-AK35) -> -5.2687623 | M35: 4.06 | N35: 0 | O35: 0 | P35: 0 | Q35: =902300/325851/1.9835*1.02 -> 1.4239668 | R35: =((2.4)*1.04)-T35 -> 1.9942978 | S35: 0 | T35: =(0.4551*1.06)*1.04 -> 0.50170224 | U35: =M35-(Q35+R35+S35+T35) -> 0.14003319 | V35: 22.2 | W35: 0 | X35: =M35-N35-P35-O35-Q35-R35-S35-T35-U35+V35+W35 -> 22.2 | Y35: =X35-AO35 -> 22.2 | AE35: 0 | AH35: 24.2 | AI35: =AI34-AH35 -> 3739.9 | AK35: =N35+O35+P35+Q35+R35+S35+T35+U35+X35+AE35+AH35 -> 50.46 | AL35: =IF(L35<0,L35*-1,0) -> 5.2687623 | AM35: =AK35+AL35 -> 55.728762 | AN35: =V35 -> 22.2 | AO35: =X35-AN35 -> 0 | AV35: 0 | AW35: 61 | AX35: 30 | AZ35: =SUM(N35,P35:U35) -> 4.06
A36: =A35+1 -> 22 | B36: 6872.28 | C36: 193971 | D36: =C36-C35 -> -28 | E36: =C36-152000 -> 41971 | F36: =D36/$D$2 -> -14.116461 | G36: 28 | H36: 0 | I36: =G36+H36 -> 28 | J36: =IF(L36>0,L36,0) -> 8.2735392 | K36: =I36+J36 -> 36.273539 | L36: =F36-(I36-AK36) -> 8.2735392 | M36: 3.99 | N36: 0 | O36: 0 | P36: 0 | Q36: =973500/325851/1.9835*1.02 -> 1.5363313 | R36: =((2.4)*1.04)-T36 -> 1.9942978 | S36: 0 | T36: =(0.4551*1.06)*1.04 -> 0.50170224 | U36: =M36-(Q36+R36+S36+T36) -> -0.042331251 | V36: 22.2 | W36: 0 | X36: =M36-N36-P36-O36-Q36-R36-S36-T36-U36+V36+W36 -> 22.2 | Y36: =X36-AO36 -> 22.2 | AE36: 0 | AH36: 24.2 | AI36: =AI35-AH36 -> 3715.7 | AK36: =N36+O36+P36+Q36+R36+S36+T36+U36+X36+AE36+AH36 -> 50.39 | AL36: =IF(L36<0,L36*-1,0) -> 0 | AM36: =AK36+AL36 -> 50.39 | AN36: =V36 -> 22.2 | AO36: =X36-AN36 -> 0 | AV36: 0 | AW36: 63 | AX36: 30 | AZ36: =SUM(N36,P36:U36) -> 3.99
A37: =A36+1 -> 23 | B37: 6872.26 | C37: 193916 | D37: =C37-C36 -> -55 | E37: =C37-152000 -> 41916 | F37: =D37/$D$2 -> -27.728762 | G37: 28 | H37: 0 | I37: =G37+H37 -> 28 | J37: =IF(L37>0,L37,0) -> 0 | K37: =I37+J37 -> 28 | L37: =F37-(I37-AK37) -> -5.3287623 | M37: 4 | N37: 0 | O37: 0 | P37: 0 | Q37: =911400/325851/1.9835*1.02 -> 1.438328 | R37: =((2.4)*1.04)-T37 -> 1.8853806 | S37: 0 | T37: =(0.5539*1.06)*1.04 -> 0.61061936 | U37: =M37-(Q37+R37+S37+T37) -> 0.065672006 | V37: 22.2 | W37: 0 | X37: =M37-N37-P37-O37-Q37-R37-S37-T37-U37+V37+W37 -> 22.2 | Y37: =X37-AO37 -> 22.2 | AE37: 0 | AH37: 24.2 | AI37: =AI36-AH37 -> 3691.5 | AK37: =N37+O37+P37+Q37+R37+S37+T37+U37+X37+AE37+AH37 -> 50.4 | AL37: =IF(L37<0,L37*-1,0) -> 5.3287623 | AM37: =AK37+AL37 -> 55.728762 | AN37: =V37 -> 22.2 | AO37: =X37-AN37 -> 0 | AV37: 0 | AW37: 62 | AX37: 29 | AZ37: =SUM(N37,P37:U37) -> 4
A38: =A37+1 -> 24 | B38: 6872.24 | C38: 193861 | D38: =C38-C37 -> -55 | E38: =C38-152000 -> 41861 | F38: =D38/$D$2 -> -27.728762 | G38: 28 | H38: 0 | I38: =G38+H38 -> 28 | J38: =IF(L38>0,L38,0) -> 0 | K38: =I38+J38 -> 28 | L38: =F38-(I38-AK38) -> -5.4287623 | M38: 3.9 | N38: 0 | O38: 0 | P38: 0 | Q38: =949000/325851/1.9835*1.02 -> 1.4976665 | R38: =((2.2)*1.04)-T38 -> 1.6773806 | S38: 0 | T38: =(0.5539*1.06)*1.04 -> 0.61061936 | U38: =M38-(Q38+R38+S38+T38) -> 0.11433348 | V38: 22.2 | W38: 0 | X38: =M38-N38-P38-O38-Q38-R38-S38-T38-U38+V38+W38 -> 22.2 | Y38: =X38-AO38 -> 22.2 | AE38: 0 | AH38: 24.2 | AI38: =AI37-AH38 -> 3667.3 | AK38: =N38+O38+P38+Q38+R38+S38+T38+U38+X38+AE38+AH38 -> 50.3 | AL38: =IF(L38<0,L38*-1,0) -> 5.4287623 | AM38: =AK38+AL38 -> 55.728762 | AN38: =V38 -> 22.2 | AO38: =X38-AN38 -> 0 | AV38: 0 | AW38: 60 | AX38: 27 | AZ38: =SUM(N38,P38:U38) -> 3.9
A39: =A38+1 -> 25 | B39: 6872.21 | C39: 193779 | D39: =C39-C38 -> -82 | E39: =C39-152000 -> 41779 | F39: =D39/$D$2 -> -41.341064 | G39: 27 | H39: 0 | I39: =G39+H39 -> 27 | J39: =IF(L39>0,L39,0) -> 0 | K39: =I39+J39 -> 27 | L39: =F39-(I39-AK39) -> -18.041064 | M39: 3.9 | N39: 0 | O39: 0 | P39: 0 | Q39: =1096300/325851/1.9835*1.02 -> 1.7301284 | R39: =((2.2)*1.04)-T39 -> 1.6773806 | S39: 0 | T39: =(0.5539*1.06)*1.04 -> 0.61061936 | U39: =M39-(Q39+R39+S39+T39) -> -0.11812835 | V39: 22.2 | W39: 0 | X39: =M39-N39-P39-O39-Q39-R39-S39-T39-U39+V39+W39 -> 22.2 | Y39: =X39-AO39 -> 22.2 | AE39: 0 | AH39: 24.2 | AI39: =AI38-AH39 -> 3643.1 | AK39: =N39+O39+P39+Q39+R39+S39+T39+U39+X39+AE39+AH39 -> 50.3 | AL39: =IF(L39<0,L39*-1,0) -> 18.041064 | AM39: =AK39+AL39 -> 68.341064 | AN39: =V39 -> 22.2 | AO39: =X39-AN39 -> 0 | AV39: 0 | AW39: 61 | AX39: 27 | AZ39: =SUM(N39,P39:U39) -> 3.9
A40: =A39+1 -> 26 | B40: 6872.19 | C40: 193724 | D40: =C40-C39 -> -55 | E40: =C40-152000 -> 41724 | F40: =D40/$D$2 -> -27.728762 | G40: 27 | H40: 0 | I40: =G40+H40 -> 27 | J40: =IF(L40>0,L40,0) -> 0 | K40: =I40+J40 -> 27 | L40: =F40-(I40-AK40) -> -4.7187623 | M40: 3.61 | N40: 0 | O40: 0 | P40: 0 | Q40: =1104000/325851/1.9835*1.04 -> 1.7764425 | R40: =((2.2)*1.04)-T40 -> 1.6773806 | S40: 0 | T40: =(0.5539*1.06)*1.04 -> 0.61061936 | U40: =M40-(Q40+R40+S40+T40) -> -0.45444248 | V40: 22.2 | W40: 0 | X40: =M40-N40-P40-O40-Q40-R40-S40-T40-U40+V40+W40 -> 22.2 | Y40: =X40-AO40 -> 22.2 | AE40: 0 | AH40: 24.2 | AI40: =AI39-AH40 -> 3618.9 | AK40: =N40+O40+P40+Q40+R40+S40+T40+U40+X40+AE40+AH40 -> 50.01 | AL40: =IF(L40<0,L40*-1,0) -> 4.7187623 | AM40: =AK40+AL40 -> 54.728762 | AN40: =V40 -> 22.2 | AO40: =X40-AN40 -> 0 | AV40: 0 | AW40: 56 | AX40: 26 | AZ40: =SUM(N40,P40:U40) -> 3.61
A41: =A40+1 -> 27 | B41: 6872.17 | C41: 193669 | D41: =C41-C40 -> -55 | E41: =C41-152000 -> 41669 | F41: =D41/$D$2 -> -27.728762 | G41: 26 | H41: 0 | I41: =G41+H41 -> 26 | J41: =IF(L41>0,L41,0) -> 0 | K41: =I41+J41 -> 26 | L41: =F41-(I41-AK41) -> -2.4887623 | M41: 4.14 | N41: 0 | O41: 0 | P41: 0 | Q41: =865600/325851/1.9835*1.02 -> 1.3660486 | R41: =((2.2)*1.04)-T41 -> 1.6773806 | S41: 0 | T41: =(0.5539*1.06)*1.04 -> 0.61061936 | U41: =M41-(Q41+R41+S41+T41) -> 0.48595138 | V41: 22.2 | W41: 0 | X41: =M41-N41-P41-O41-Q41-R41-S41-T41-U41+V41+W41 -> 22.2 | Y41: =X41-AO41 -> 22.2 | AE41: 0 | AH41: 24.9 | AI41: =AI40-AH41 -> 3594 | AK41: =N41+O41+P41+Q41+R41+S41+T41+U41+X41+AE41+AH41 -> 51.24 | AL41: =IF(L41<0,L41*-1,0) -> 2.4887623 | AM41: =AK41+AL41 -> 53.728762 | AN41: =V41 -> 22.2 | AO41: =X41-AN41 -> 0 | AV41: 0 | AW41: 54 | AX41: 23 | AZ41: =SUM(N41,P41:U41) -> 4.14
A42: =A41+1 -> 28 | B42: 6872.15 | C42: 193614 | D42: =C42-C41 -> -55 | E42: =C42-152000 -> 41614 | F42: =D42/$D$2 -> -27.728762 | G42: 26 | H42: 0 | I42: =G42+H42 -> 26 | J42: =IF(L42>0,L42,0) -> 0 | K42: =I42+J42 -> 26 | L42: =F42-(I42-AK42) -> -2.6687623 | M42: 4.06 | N42: 0 | O42: 0 | P42: 0 | Q42: =934300/325851/1.9835*1.02 -> 1.4744677 | R42: =((2.2)*1.04)-T42 -> 1.6773806 | S42: 0 | T42: =(0.5539*1.06)*1.04 -> 0.61061936 | U42: =M42-(Q42+R42+S42+T42) -> 0.29753232 | V42: 22.2 | W42: 0 | X42: =M42-N42-P42-O42-Q42-R42-S42-T42-U42+V42+W42 -> 22.2 | Y42: =X42-AO42 -> 22.2 | AE42: 0 | AH42: 24.8 | AI42: =AI41-AH42 -> 3569.2 | AK42: =N42+O42+P42+Q42+R42+S42+T42+U42+X42+AE42+AH42 -> 51.06 | AL42: =IF(L42<0,L42*-1,0) -> 2.6687623 | AM42: =AK42+AL42 -> 53.728762 | AN42: =V42 -> 22.2 | AO42: =X42-AN42 -> 0 | AV42: 0 | AW42: 57 | AX42: 28 | AZ42: =SUM(N42,P42:U42) -> 4.06
...

Sheet DEC
K1: MCPHEE RESERVOIR INFLOW/OUTFLOW TABULATION
A2: AF/cfs CONVERT FACTOR | D2: 1.9835 | K2: DECEMBER "2012"
D4: RESERVOIR | I4: INFLOW | X4: OUTFLOW | AP4: ADJUSTMENTS | AW4: WEATHER
A5: DATE | B5: RESERV | C5: RESERV | D5: AC FT | E5: ACTIVE | F5: CONV TO | G5: DOLORES | H5: LOST | I5: RECORD | J5: CALC | K5: TOTAL | L5: CALC | M5: DOLORES TUNNEL | V5: LONE | W5: U | X5: TOTAL | Y5: TOTAL | Z5: MVI | AA5: MVI | AB5: MVI | AC5: TO EX & | AD5: MVI | AE5: DV CR | AF5: D/S SENIOR | AH5: BELOW | AI5: FISH | AJ5: SPILL | AK5: RECORD | AL5: CALC | AM5: TOTAL | AN5: NAR | AO5: MVI | AP5: MVI | AQ5: MVI | AR5: DIST. | AS5: U/S | AT5: TOTTEN | AU5: UTES | AV5: RAIN | AW5: MAX | AX5: MIN | AZ5: TOTAL
A6: DEC | B6: ELEV | D6: CHANGE | E6: CAP | F6: CFS | G6: RIVER | H6: CAN | I6: INFLOW | J6: INFLOW | K6: INFLOW | L6: INF/OTF | M6: TOT DIV | N6: WET | O6: UTE | P6: QUEST | Q6: MWC | R6: CORTEZ | T6: UTE | U6: F-BAY | V6: PINE | W6: LAT | X6: MVI | Y6: MVI | Z6: CALL | AA6: CALL | AB6: APR- | AC6: U/S EX | AD6: PROJ | AE6: CANAL | AF6: MVIC | AG6: PROJ | AH6: MCP | AI6: LEFT | AK6: OTF | AL6: OTF | AM6: OTF | AN6: FILLL | AO6: STOCK | AP6: STORED | AQ6: STORED | AR6: CLASS | AS6: USERS | AT6: (FRESH | AU6: FROM | AW6: TMP | AX6: TMP | AZ6: TUNNEL
N7: LAND | O7: F&R | Q7: NON - | R7: NON - | S7: PROJ | T7: PROJ | U7: BAL | X7: WATER | Y7: IRRIG. | Z7: STOR | AA7: SPILLED | AB7: JUNE | AF7: 1.7 | AG7: 1.3 | AP7: Apr - Jun | AQ7: EVAP | AR7: "B" | AS7: EXCH | AT7: WATER) | AU7: DWCD | AZ7: Misc.
Q8: PROJ | R8: PROJ | X8: USED | Y8: WATER | AA8: OR | AB8: (DIV+
R9: 4.2 | Y9: USED | AA9: USED | AB9: CALL)
C10: AC. Ft. | E10: AC FT | G10: CFS | H10: CFS | I10: CFS | J10: CFS | K10: CFS | L10: CFS | M10: CFS | N10: CFS | O10: CFS | P10: CFS | Q10: CFS | R10: CFS | S10: CFS | T10: CFS | U10: CFS | V10: CFS | W10: CFS | X10: 153400 | Y10: 150400 | AB10: 72000 | AC10: CFS | AD10: CFS | AE10: CFS | AF10: CFS | AG10: CFS | AH10: CFS | AI10: CFS | AJ10: CFS | AK10: CFS | AL10: CFS | AM10: CFS | AN10: CFS | AO10: CFS | AP10: CFS | AQ10: AC.FT. | AR10: CFS | AS10: CFS | AT10: CFS | AU10: CFS | AZ10: Outflow
N11: 1.03 | O11: 1.05 | P11: 1.02 | Q11: 1.02 | R11: 1.04 | T11: 1.04 | X11: CFS | Y11: CFS | Z11: CFS | AA11: CFS | AB11: Ac. Ft. | AZ11: CFS
A12: SEASON BAL
A13: YTD | B13: =NOV!B44 -> 6872.11 | C13: =NOV!C44 -> 193503 | D13: =NOV!D53 -> -1652 | E13: =NOV!E53 -> 41503 | F13: =NOV!F52 -> -832.87119 | G13: =NOV!G52 -> 980 | H13: =NOV!H52 -> 0.62 | I13: =NOV!I52 -> 980 | J13: =NOV!J52 -> 127.70017 | K13: =NOV!K52 -> 1107.7002 | L13: =NOV!L52 -> -144.95569 | M13: =NOV!M52 -> 301.32 | ... Y13: =NOV!Y52 -> 487.86 | AC13: =NOV!AC52 -> 0 | AH13: =NOV!AH52 -> 725.5 | AI13: =NOV!AI52 -> 3521.5 | AK13: =NOV!AK52 -> 1667.9155 | AL13: =NOV!AL52 -> 272.65586 | AM13: =NOV!AM52 -> 1940.5714 | AN13: =NOV!AN52 -> 487.86 | AO13: =NOV!AO52 -> 323.96244 | AV13: =NOV!AV52 -> 0.41 | AZ13: =NOV!AZ52 -> 121.65756
A15: 1 | B15: 6872.09 | C15: 193448 | D15: =C15-C13 -> -55 | E15: =C15-152000 -> 41448 | F15: =D15/$D$2 -> -27.728762 | G15: 37 | H15: 0 | I15: =G15+H15 -> 37 | J15: =IF(L15>0,L15,0) -> 0 | K15: =I15+J15 -> 37 | L15: =F15-(I15-AK15) -> -15.348762 | M15: 3.58 | N15: 0 | O15: 0 | P15: 0 | Q15: =1006700/325851/1.9835*1.02 -> 1.5887259 | R15: =((2.2)*1.04)-T15 -> 1.766675 | S15: 0 | T15: =(0.4729*1.06)*1.04 -> 0.52132496 | U15: =M15-(Q15+R15+S15+T15) -> -0.29672591 | V15: 22.2 | W15: 0 | X15: =M15-N15-P15-O15-Q15-R15-S15-T15-U15+V15+W15 -> 22.2 | Y15: =X15-AO15 -> 22.2 | AC15: 0 | AE15: 0 | AH15: 23.6 | AI15: =AI13-AH15 -> 3497.9 | AK15: =N15+O15+P15+Q15+R15+S15+T15+U15+X15+AE15+AH15 -> 49.38 | AL15: =IF(L15<0,L15*-1,0) -> 15.348762 | AM15: =AK15+AL15 -> 64.728762 | AN15: =V15 -> 22.2 | AO15: 0 | AV15: 0 | AW15: 54 | AX15: 29 | AZ15: =SUM(N15,P15:U15) -> 3.58
A16: =A15+1 -> 2 | B16: 6872.07 | C16: 193393 | D16: =C16-C15 -> -55 | E16: =C16-152000 -> 41393 | F16: =D16/$D$2 -> -27.728762 | G16: 32 | H16: 0 | I16: =G16+H16 -> 32 | J16: =IF(L16>0,L16,0) -> 0 | K16: =I16+J16 -> 32 | L16: =F16-(I16-AK16) -> -9.6587623 | M16: 4.27 | N16: 0 | O16: 0 | P16: 0 | Q16: =1104600/325851/1.9835*1.02 -> 1.743227 | R16: =((2.2)*1.04)-T16 -> 1.766675 | S16: 0 | T16: =(0.4729*1.06)*1.04 -> 0.52132496 | U16: =M16-(Q16+R16+S16+T16) -> 0.23877298 | V16: 22.2 | W16: 0 | X16: =M16-N16-P16-O16-Q16-R16-S16-T16-U16+V16+W16 -> 22.2 | Y16: =X16-AO16 -> 22.2 | AC16: 0 | AE16: 0 | AH16: 23.6 | AI16: =AI15-AH16 -> 3474.3 | AK16: =N16+O16+P16+Q16+R16+S16+T16+U16+X16+AE16+AH16 -> 50.07 | AL16: =IF(L16<0,L16*-1,0) -> 9.6587623 | AM16: =AK16+AL16 -> 59.728762 | AN16: =V16 -> 22.2 | AO16: 0 | AV16: 0 | AW16: 56 | AX16: 31 | AZ16: =SUM(N16,P16:U16) -> 4.27
A17: =A16+1 -> 3 | B17: 6872.05 | C17: 193338 | D17: =C17-C16 -> -55 | E17: =C17-152000 -> 41338 | F17: =D17/$D$2 -> -27.728762 | G17: 37 | H17: 0 | I17: =G17+H17 -> 37 | J17: =IF(L17>0,L17,0) -> 0 | K17: =I17+J17 -> 37 | L17: =F17-(I17-AK17) -> -16.078762 | M17: 4.25 | N17: 0 | O17: 0 | P17: 0 | Q17: =916900/325851/1.9835*1.02 -> 1.4470078 | R17: =((2)*1.04)-T17 -> 1.558675 | S17: 0 | T17: =(0.4729*1.06)*1.04 -> 0.52132496 | U17: =M17-(Q17+R17+S17+T17) -> 0.72299217 | V17: 20.8 | W17: 0 | X17: =M17-N17-P17-O17-Q17-R17-S17-T17-U17+V17+W17 -> 20.8 | Y17: =X17-AO17 -> 20.8 | AC17: 0 | AE17: 0 | AH17: 23.6 | AI17: =AI16-AH17 -> 3450.7 | AK17: =N17+O17+P17+Q17+R17+S17+T17+U17+X17+AE17+AH17 -> 48.65 | AL17: =IF(L17<0,L17*-1,0) -> 16.078762 | AM17: =AK17+AL17 -> 64.728762 | AN17: =V17 -> 20.8 | AO17: 0 | AV17: 0 | AW17: 51 | AX17: 28 | AZ17: =SUM(N17,P17:U17) -> 4.25
A18: =A17+1 -> 4 | B18: 6872.03 | C18: 193283 | D18: =C18-C17 -> -55 | E18: =C18-152000 -> 41283 | F18: =D18/$D$2 -> -27.728762 | G18: 30 | H18: 0 | I18: =G18+H18 -> 30 | J18: =IF(L18>0,L18,0) -> 0 | K18: =I18+J18 -> 30 | L18: =F18-(I18-AK18) -> -12.948762 | M18: 3.28 | N18: 0 | O18: 0 | P18: 0 | Q18: =875300/325851/1.9835*1.02 -> 1.3813567 | R18: =((2)*1.04)-T18 -> 1.558675 | S18: 0 | T18: =(0.4729*1.06)*1.04 -> 0.52132496 | U18: =M18-(Q18+R18+S18+T18) -> -0.1813567 | V18: 17.9 | W18: 0 | X18: =M18-N18-P18-O18-Q18-R18-S18-T18-U18+V18+W18 -> 17.9 | Y18: =X18-AO18 -> 17.9 | AC18: 0 | AE18: 0 | AH18: 23.6 | AI18: =AI17-AH18 -> 3427.1 | AK18: =N18+O18+P18+Q18+R18+S18+T18+U18+X18+AE18+AH18 -> 44.78 | AL18: =IF(L18<0,L18*-1,0) -> 12.948762 | AM18: =AK18+AL18 -> 57.728762 | AN18: =V18 -> 17.9 | AO18: 0 | AV18: 0 | AW18: 50 | AX18: 24 | AZ18: =SUM(N18,P18:U18) -> 3.28
A19: =A18+1 -> 5 | B19: 6872.01 | C19: 193228 | D19: =C19-C18 -> -55 | E19: =C19-152000 -> 41228 | F19: =D19/$D$2 -> -27.728762 | G19: 28 | H19: 0 | I19: =G19+H19 -> 28 | J19: =IF(L19>0,L19,0) -> 0 | K19: =I19+J19 -> 28 | L19: =F19-(I19-AK19) -> -6.1887623 | M19: 7.94 | N19: 0 | O19: 0 | P19: 0 | Q19: =981400/325851/1.9835*1.02 -> 1.5487987 | R19: =((2)*1.04)-T19 -> 1.558675 | S19: 0 | T19: =(0.4729*1.06)*1.04 -> 0.52132496 | U19: =M19-(Q19+R19+S19+T19) -> 4.3112013 | V19: 18 | W19: 0 | X19: =M19-N19-P19-O19-Q19-R19-S19-T19-U19+V19+W19 -> 18 | Y19: =X19-AO19 -> 18 | AC19: 0 | AE19: 0 | AH19: 23.6 | AI19: =AI18-AH19 -> 3403.5 | AK19: =N19+O19+P19+Q19+R19+S19+T19+U19+X19+AE19+AH19 -> 49.54 | AL19: =IF(L19<0,L19*-1,0) -> 6.1887623 | AM19: =AK19+AL19 -> 55.728762 | AN19: =V19 -> 18 | AO19: 0 | AV19: 0 | AW19: 57 | AX19: 28 | AZ19: =SUM(N19,P19:U19) -> 7.94
A20: =A19+1 -> 6 | B20: 6871.99 | C20: 193174 | D20: =C20-C19 -> -54 | E20: =C20-152000 -> 41174 | F20: =D20/$D$2 -> -27.224603 | G20: 32 | H20: 0 | I20: =G20+H20 -> 32 | J20: =IF(L20>0,L20,0) -> 0 | K20: =I20+J20 -> 32 | L20: =F20-(I20-AK20) -> -12.994603 | M20: 4.33 | N20: 0 | O20: 0 | P20: 0 | Q20: =859600/325851/1.9835*1.02 -> 1.3565797 | R20: =((2)*1.04)-T20 -> 1.558675 | S20: 0 | T20: =(0.4729*1.06)*1.04 -> 0.52132496 | U20: =M20-(Q20+R20+S20+T20) -> 0.89342029 | V20: 18.3 | W20: 0 | X20: =M20-N20-P20-O20-Q20-R20-S20-T20-U20+V20+W20 -> 18.3 | Y20: =X20-AO20 -> 18.3 | AC20: 0 | AE20: 0 | AH20: 23.6 | AI20: =AI19-AH20 -> 3379.9 | AK20: =N20+O20+P20+Q20+R20+S20+T20+U20+X20+AE20+AH20 -> 46.23 | AL20: =IF(L20<0,L20*-1,0) -> 12.994603 | AM20: =AK20+AL20 -> 59.224603 | AN20: =V20 -> 18.3 | AO20: 0 | AV20: 0 | AW20: 50 | AX20: 30 | AZ20: =SUM(N20,P20:U20) -> 4.33
A21: =A20+1 -> 7 | B21: 6871.97 | C21: 193119 | D21: =C21-C20 -> -55 | E21: =C21-152000 -> 41119 | F21: =D21/$D$2 -> -27.728762 | G21: 31 | H21: 0 | I21: =G21+H21 -> 31 | J21: =IF(L21>0,L21,0) -> 0 | K21: =I21+J21 -> 31 | L21: =F21-(I21-AK21) -> -13.238762 | M21: 3.59 | N21: 0 | O21: 0 | P21: 0 | Q21: =886700/325851/1.9835*1.02 -> 1.3993476 | R21: =((2)*1.04)-T21 -> 1.5827074 | S21: 0 | T21: =(0.4511*1.06)*1.04 -> 0.49729264 | U21: =M21-(Q21+R21+S21+T21) -> 0.11065237 | V21: 18.3 | W21: 0 | X21: =M21-N21-P21-O21-Q21-R21-S21-T21-U21+V21+W21 -> 18.3 | Y21: =X21-AO21 -> 18.3 | AC21: 0 | AE21: 0 | AH21: 23.6 | AI21: =AI20-AH21 -> 3356.3 | AK21: =N21+O21+P21+Q21+R21+S21+T21+U21+X21+AE21+AH21 -> 45.49 | AL21: =IF(L21<0,L21*-1,0) -> 13.238762 | AM21: =AK21+AL21 -> 58.728762 | AN21: =V21 -> 18.3 | AO21: 0 | AV21: 0 | AW21: 49 | AX21: 27 | AZ21: =SUM(N21,P21:U21) -> 3.59
A22: =A21+1 -> 8 | B22: 6871.95 | C22: 193065 | D22: =C22-C21 -> -54 | E22: =C22-152000 -> 41065 | F22: =D22/$D$2 -> -27.224603 | G22: 26 | H22: 0 | I22: =G22+H22 -> 26 | J22: =IF(L22>0,L22,0) -> 0 | K22: =I22+J22 -> 26 | L22: =F22-(I22-AK22) -> -7.974603 | M22: 3.35 | N22: 0 | O22: 0 | P22: 0 | Q22: =908300/325851/1.9835*1.02 -> 1.4334357 | R22: =((2)*1.04)-T22 -> 1.5827074 | S22: 0 | T22: =(0.4511*1.06)*1.04 -> 0.49729264 | U22: =M22-(Q22+R22+S22+T22) -> -0.16343572 | V22: 18.3 | W22: 0 | X22: =M22-N22-P22-O22-Q22-R22-S22-T22-U22+V22+W22 -> 18.3 | Y22: =X22-AO22 -> 18.3 | AC22: 0 | AE22: 0 | AH22: 23.6 | AI22: =AI21-AH22 -> 3332.7 | AK22: =N22+O22+P22+Q22+R22+S22+T22+U22+X22+AE22+AH22 -> 45.25 | AL22: =IF(L22<0,L22*-1,0) -> 7.974603 | AM22: =AK22+AL22 -> 53.224603 | AN22: =V22 -> 18.3 | AO22: 0 | AV22: 0 | AW22: 46 | AX22: 23 | AZ22: =SUM(N22,P22:U22) -> 3.35
A23: =A22+1 -> 9 | B23: 6871.93 | C23: 193011 | D23: =C23-C22 -> -54 | E23: =C23-152000 -> 41011 | F23: =D23/$D$2 -> -27.224603 | G23: 23 | H23: 0 | I23: =G23+H23 -> 23 | J23: =IF(L23>0,L23,0) -> 0 | K23: =I23+J23 -> 23 | L23: =F23-(I23-AK23) -> -4.774603 | M23: 3.55 | N23: 0 | O23: 0 | P23: 0 | Q23: =875300/325851/1.9835*1.02 -> 1.3813567 | R23: =((2)*1.04)-T23 -> 1.5827074 | S23: 0 | T23: =(0.4511*1.06)*1.04 -> 0.49729264 | U23: =M23-(Q23+R23+S23+T23) -> 0.088643304 | V23: 18.3 | W23: 0 | X23: =M23-N23-P23-O23-Q23-R23-S23-T23-U23+V23+W23 -> 18.3 | Y23: =X23-AO23 -> 18.3 | AC23: 0 | AE23: 0 | AH23: 23.6 | AI23: =AI22-AH23 -> 3309.1 | AK23: =N23+O23+P23+Q23+R23+S23+T23+U23+X23+AE23+AH23 -> 45.45 | AL23: =IF(L23<0,L23*-1,0) -> 4.774603 | AM23: =AK23+AL23 -> 50.224603 | AN23: =V23 -> 18.3 | AO23: 0 | AV23: 0 | AW23: 31 | AX23: 12 | AZ23: =SUM(N23,P23:U23) -> 3.55
A24: =A23+1 -> 10 | B24: 6871.92 | C24: 192983 | D24: =C24-C23 -> -28 | E24: =C24-152000 -> 40983 | F24: =D24/$D$2 -> -14.116461 | G24: 19 | H24: 0 | I24: =G24+H24 -> 19 | J24: =IF(L24>0,L24,0) -> 1.9935392 | K24: =I24+J24 -> 20.993539 | L24: =F24-(I24-AK24) -> 1.9935392 | M24: 3.35 | N24: 0 | O24: 0 | P24: 0 | Q24: =1027100/325851/1.9835*1.02 -> 1.6209202 | R24: =((2)*1.04)-T24 -> 1.5827074 | S24: 0 | T24: =(0.4511*1.06)*1.04 -> 0.49729264 | U24: =M24-(Q24+R24+S24+T24) -> -0.35092021 | V24: 8.16 | W24: 0 | X24: =M24-N24-P24-O24-Q24-R24-S24-T24-U24+V24+W24 -> 8.16 | Y24: =X24-AO24 -> 8.16 | AC24: 0 | AE24: 0 | AH24: 23.6 | AI24: =AI23-AH24 -> 3285.5 | AK24: =N24+O24+P24+Q24+R24+S24+T24+U24+X24+AE24+AH24 -> 35.11 | AL24: =IF(L24<0,L24*-1,0) -> 0 | AM24: =AK24+AL24 -> 35.11 | AN24: =V24 -> 8.16 | AO24: 0 | AV24: 0 | AW24: 33 | AX24: 10 | AZ24: =SUM(N24,P24:U24) -> 3.35
A25: =A24+1 -> 11 | B25: 6871.91 | C25: 192956 | D25: =C25-C24 -> -27 | E25: =C25-152000 -> 40956 | F25: =D25/$D$2 -> -13.612301 | G25: 19 | H25: 0 | I25: =G25+H25 -> 19 | J25: =IF(L25>0,L25,0) -> 0 | K25: =I25+J25 -> 19 | L25: =F25-(I25-AK25) -> -4.1223015 | M25: 3.69 | N25: 0 | O25: 0 | P25: 0 | Q25: =828500/325851/1.9835*1.02 -> 1.3074992 | R25: =((2)*1.04)-T25 -> 1.5827074 | S25: 0 | T25: =(0.4511*1.06)*1.04 -> 0.49729264 | U25: =M25-(Q25+R25+S25+T25) -> 0.30250083 | V25: 0 | W25: 0 | X25: =M25-N25-P25-O25-Q25-R25-S25-T25-U25+V25+W25 -> 0 | Y25: =X25-AO25 -> 0 | AC25: 0 | AE25: 0 | AH25: 24.8 | AI25: =AI24-AH25 -> 3260.7 | AK25: =N25+O25+P25+Q25+R25+S25+T25+U25+X25+AE25+AH25 -> 28.49 | AL25: =IF(L25<0,L25*-1,0) -> 4.1223015 | AM25: =AK25+AL25 -> 32.612301 | AN25: =V25 -> 0 | AO25: 0 | AV25: 0 | AW25: 37 | AX25: 3 | AZ25: =SUM(N25,P25:U25) -> 3.69
A26: =A25+1 -> 12 | B26: 6871.9 | C26: 192929 | D26: =C26-C25 -> -27 | E26: =C26-152000 -> 40929 | F26: =D26/$D$2 -> -13.612301 | G26: 22 | H26: 0 | I26: =G26+H26 -> 22 | J26: =IF(L26>0,L26,0) -> 0 | K26: =I26+J26 -> 22 | L26: =F26-(I26-AK26) -> -5.2623015 | M26: 3.55 | N26: 0 | O26: 0 | P26: 0 | Q26: =838700/325851/1.9835*1.02 -> 1.3235963 | R26: =((2)*1.04)-T26 -> 1.5827074 | S26: 0 | T26: =(0.4511*1.06)*1.04 -> 0.49729264 | U26: =M26-(Q26+R26+S26+T26) -> 0.14640368 | V26: 0 | W26: 0 | X26: =M26-N26-P26-O26-Q26-R26-S26-T26-U26+V26+W26 -> 0 | Y26: =X26-AO26 -> 0 | AC26: 0 | AE26: 0 | AH26: 26.8 | AI26: =AI25-AH26 -> 3233.9 | AK26: =N26+O26+P26+Q26+R26+S26+T26+U26+X26+AE26+AH26 -> 30.35 | AL26: =IF(L26<0,L26*-1,0) -> 5.2623015 | AM26: =AK26+AL26 -> 35.612301 | AN26: =V26 -> 0 | AO26: 0 | AV26: 0 | AW26: 40 | AX26: 7 | AZ26: =SUM(N26,P26:U26) -> 3.55
A27: =A26+1 -> 13 | B27: 6871.89 | C27: 192902 | D27: =C27-C26 -> -27 | E27: =C27-152000 -> 40902 | F27: =D27/$D$2 -> -13.612301 | G27: 24 | H27: 0 | I27: =G27+H27 -> 24 | J27: =IF(L27>0,L27,0) -> 0 | K27: =I27+J27 -> 24 | L27: =F27-(I27-AK27) -> -7.0623015 | M27: 3.75 | N27: 0 | O27: 0 | P27: 0 | Q27: =967800/325851/1.9835*1.02 -> 1.5273358 | R27: =((2)*1.04)-T27 -> 1.5827074 | S27: 0 | T27: =(0.4511*1.06)*1.04 -> 0.49729264 | U27: =M27-(Q27+R27+S27+T27) -> 0.14266422 | V27: 0 | W27: 0 | X27: =M27-N27-P27-O27-Q27-R27-S27-T27-U27+V27+W27 -> 0 | Y27: =X27-AO27 -> 0 | AC27: 0 | AE27: 0 | AH27: 26.8 | AI27: =AI26-AH27 -> 3207.1 | AK27: =N27+O27+P27+Q27+R27+S27+T27+U27+X27+AE27+AH27 -> 30.55 | AL27: =IF(L27<0,L27*-1,0) -> 7.0623015 | AM27: =AK27+AL27 -> 37.612301 | AN27: =V27 -> 0 | AO27: 0 | AV27: 0 | AW27: 50 | AX27: 28 | AZ27: =SUM(N27,P27:U27) -> 3.75
A28: =A27+1 -> 14 | B28: 6871.9 | C28: 192929 | D28: =C28-C27 -> 27 | E28: =C28-152000 -> 40929 | F28: =D28/$D$2 -> 13.612301 | G28: 24 | H28: 0 | I28: =G28+H28 -> 24 | J28: =IF(L28>0,L28,0) -> 19.962301 | K28: =I28+J28 -> 43.962301 | L28: =F28-(I28-AK28) -> 19.962301 | M28: 3.55 | N28: 0 | O28: 0 | P28: 0 | Q28: =811900/325851/1.9835*1.02 -> 1.2813018 | R28: =((2)*1.04)-T28 -> 1.4810661 | S28: 0 | T28: =(0.5433*1.06)*1.04 -> 0.59893392 | U28: =M28-(Q28+R28+S28+T28) -> 0.18869816 | V28: 0 | W28: 0 | X28: =M28-N28-P28-O28-Q28-R28-S28-T28-U28+V28+W28 -> 0 | Y28: =X28-AO28 -> 0 | AC28: 0 | AE28: 0 | AH28: 26.8 | AI28: =AI27-AH28 -> 3180.3 | AK28: =N28+O28+P28+Q28+R28+S28+T28+U28+X28+AE28+AH28 -> 30.35 | AL28: =IF(L28<0,L28*-1,0) -> 0 | AM28: =AK28+AL28 -> 30.35 | AN28: =V28 -> 0 | AO28: 0 | AV28: 0.67 | AW28: 42 | AX28: 27 | AZ28: =SUM(N28,P28:U28) -> 3.55
A29: =A28+1 -> 15 | B29: 6871.94 | C29: 193038 | D29: =C29-C28 -> 109 | E29: =C29-152000 -> 41038 | F29: =D29/$D$2 -> 54.953365 | G29: 25 | H29: 0 | I29: =G29+H29 -> 25 | J29: =IF(L29>0,L29,0) -> 70.603365 | K29: =I29+J29 -> 95.603365 | L29: =F29-(I29-AK29) -> 70.603365 | M29: 3.55 | N29: 0 | O29: 0 | P29: 0 | Q29: =857600/325851/1.9835*1.02 -> 1.3534234 | R29: =((2)*1.04)-T29 -> 1.4810661 | S29: 0 | T29: =(0.5433*1.06)*1.04 -> 0.59893392 | U29: =M29-(Q29+R29+S29+T29) -> 0.1165766 | V29: 10.3 | W29: 0 | X29: =M29-N29-P29-O29-Q29-R29-S29-T29-U29+V29+W29 -> 10.3 | Y29: =X29-AO29 -> 10.3 | AC29: 27.7 | AE29: 0 | AH29: 26.8 | AI29: =AI28-AH29 -> 3153.5 | AK29: =N29+O29+P29+Q29+R29+S29+T29+U29+X29+AE29+AH29 -> 40.65 | AL29: =IF(L29<0,L29*-1,0) -> 0 | AM29: =AK29+AL29 -> 40.65 | AN29: =V29 -> 10.3 | AO29: 0 | AV29: 0.343 | AW29: 34 | AX29: 25 | AZ29: =SUM(N29,P29:U29) -> 3.55
A30: =A29+1 -> 16 | B30: 6871.92 | C30: 192983 | D30: =C30-C29 -> -55 | E30: =C30-152000 -> 40983 | F30: =D30/$D$2 -> -27.728762 | G30: 26 | H30: 0 | I30: =G30+H30 -> 26 | J30: =IF(L30>0,L30,0) -> 0 | K30: =I30+J30 -> 26 | L30: =F30-(I30-AK30) -> -5.2087623 | M30: 3.42 | N30: 0 | O30: 0 | P30: 0 | Q30: =830600/325851/1.9835*1.02 -> 1.3108133 | R30: =((2)*1.04)-T30 -> 1.4810661 | S30: 0 | T30: =(0.5433*1.06)*1.04 -> 0.59893392 | U30: =M30-(Q30+R30+S30+T30) -> 0.029186711 | V30: 18.3 | W30: 0 | X30: =M30-N30-P30-O30-Q30-R30-S30-T30-U30+V30+W30 -> 18.3 | Y30: =X30-AO30 -> 18.3 | AC30: 0 | AE30: 0 | AH30: 26.8 | AI30: =AI29-AH30 -> 3126.7 | AK30: =N30+O30+P30+Q30+R30+S30+T30+U30+X30+AE30+AH30 -> 48.52 | AL30: =IF(L30<0,L30*-1,0) -> 5.2087623 | AM30: =AK30+AL30 -> 53.728762 | AN30: =V30 -> 18.3 | AO30: 0 | AV30: 0 | AW30: 31 | AX30: 19 | AZ30: =SUM(N30,P30:U30) -> 3.42
A31: =A30+1 -> 17 | B31: 6871.89 | C31: 192902 | D31: =C31-C30 -> -81 | E31: =C31-152000 -> 40902 | F31: =D31/$D$2 -> -40.836904 | G31: 27 | H31: 0 | I31: =G31+H31 -> 27 | J31: =IF(L31>0,L31,0) -> 0 | K31: =I31+J31 -> 27 | L31: =F31-(I31-AK31) -> -19.646904 | M31: 3.09 | N31: 0 | O31: 0 | P31: 0 | Q31: =850500/325851/1.9835*1.02 -> 1.3422185 | R31: =((2)*1.04)-T31 -> 1.4810661 | S31: 0 | T31: =(0.5433*1.06)*1.04 -> 0.59893392 | U31: =M31-(Q31+R31+S31+T31) -> -0.33221852 | V31: 18.3 | W31: 0 | X31: =M31-N31-P31-O31-Q31-R31-S31-T31-U31+V31+W31 -> 18.3 | Y31: =X31-AO31 -> 18.3 | AC31: 0 | AE31: 0 | AH31: 26.8 | AI31: =AI30-AH31 -> 3099.9 | AK31: =N31+O31+P31+Q31+R31+S31+T31+U31+X31+AE31+AH31 -> 48.19 | AL31: =IF(L31<0,L31*-1,0) -> 19.646904 | AM31: =AK31+AL31 -> 67.836904 | AN31: =V31 -> 18.3 | AO31: 0 | AV31: 0 | AW31: 36 | AX31: 22 | AZ31: =SUM(N31,P31:U31) -> 3.09
A32: =A31+1 -> 18 | B32: 6871.86 | C32: 192820 | D32: =C32-C31 -> -82 | E32: =C32-152000 -> 40820 | F32: =D32/$D$2 -> -41.341064 | G32: 26 | H32: 0 | I32: =G32+H32 -> 26 | J32: =IF(L32>0,L32,0) -> 0 | K32: =I32+J32 -> 26 | L32: =F32-(I32-AK32) -> -18.901064 | M32: 3.34 | N32: 0 | O32: 0 | P32: 0 | Q32: =903600/325851/1.9835*1.02 -> 1.4260184 | R32: =((2)*1.04)-T32 -> 1.4810661 | S32: 0 | T32: =(0.5433*1.06)*1.04 -> 0.59893392 | U32: =M32-(Q32+R32+S32+T32) -> -0.16601841 | V32: 18.3 | W32: 0 | X32: =M32-N32-P32-O32-Q32-R32-S32-T32-U32+V32+W32 -> 18.3 | Y32: =X32-AO32 -> 18.3 | AC32: 0 | AE32: 0 | AH32: 26.8 | AI32: =AI31-AH32 -> 3073.1 | AK32: =N32+O32+P32+Q32+R32+S32+T32+U32+X32+AE32+AH32 -> 48.44 | AL32: =IF(L32<0,L32*-1,0) -> 18.901064 | AM32: =AK32+AL32 -> 67.341064 | AN32: =V32 -> 18.3 | AO32: 0 | AV32: 0.01 | AW32: 35 | AX32: 25 | AZ32: =SUM(N32,P32:U32) -> 3.34
A33: =A32+1 -> 19 | B33: 6871.87 | C33: 192848 | D33: =C33-C32 -> 28 | E33: =C33-152000 -> 40848 | F33: =D33/$D$2 -> 14.116461 | G33: 25 | H33: 0 | I33: =G33+H33 -> 25 | J33: =IF(L33>0,L33,0) -> 37.566461 | K33: =I33+J33 -> 62.566461 | L33: =F33-(I33-AK33) -> 37.566461 | M33: 3.35 | N33: 0 | O33: 0 | P33: 0 | Q33: =926300/325851/1.9835*1.02 -> 1.4618425 | R33: =((2)*1.04)-T33 -> 1.4810661 | S33: 0 | T33: =(0.5433*1.06)*1.04 -> 0.59893392 | U33: =M33-(Q33+R33+S33+T33) -> -0.19184246 | V33: 18.3 | W33: 0 | X33: =M33-N33-P33-O33-Q33-R33-S33-T33-U33+V33+W33 -> 18.3 | Y33: =X33-AO33 -> 18.3 | AC33: 0 | AE33: 0 | AH33: 26.8 | AI33: =AI32-AH33 -> 3046.3 | AK33: =N33+O33+P33+Q33+R33+S33+T33+U33+X33+AE33+AH33 -> 48.45 | AL33: =IF(L33<0,L33*-1,0) -> 0 | AM33: =AK33+AL33 -> 48.45 | AN33: =V33 -> 18.3 | AO33: 0 | AV33: 0.01 | AW33: 38 | AX33: 3 | AZ33: =SUM(N33,P33:U33) -> 3.35
A34: =A33+1 -> 20 | B34: 6871.85 | C34: 192793 | D34: =C34-C33 -> -55 | E34: =C34-152000 -> 40793 | F34: =D34/$D$2 -> -27.728762 | G34: 22 | H34: 0 | I34: =G34+H34 -> 22 | J34: =IF(L34>0,L34,0) -> 0 | K34: =I34+J34 -> 22 | L34: =F34-(I34-AK34) -> -0.18876229 | M34: 4.44 | N34: 0 | O34: 0 | P34: 0 | Q34: =1005400/325851/1.9835*1.02 -> 1.5866743 | R34: =((2)*1.04)-T34 -> 1.4810661 | S34: 0 | T34: =(0.5433*1.06)*1.04 -> 0.59893392 | U34: =M34-(Q34+R34+S34+T34) -> 0.77332569 | V34: 18.3 | W34: 0 | X34: =M34-N34-P34-O34-Q34-R34-S34-T34-U34+V34+W34 -> 18.3 | Y34: =X34-AO34 -> 18.3 | AC34: 0 | AE34: 0 | AH34: 26.8 | AI34: =AI33-AH34 -> 3019.5 | AK34: =N34+O34+P34+Q34+R34+S34+T34+U34+X34+AE34+AH34 -> 49.54 | AL34: =IF(L34<0,L34*-1,0) -> 0.18876229 | AM34: =AK34+AL34 -> 49.728762 | AN34: =V34 -> 18.3 | AO34: 0 | AV34: 0.01 | AW34: 34 | AX34: -4 | AZ34: =SUM(N34,P34:U34) -> 4.44
A35: =A34+1 -> 21 | B35: 6871.83 | C35: 192739 | D35: =C35-C34 -> -54 | E35: =C35-152000 -> 40739 | F35: =D35/$D$2 -> -27.224603 | G35: 23 | H35: 0 | I35: =G35+H35 -> 23 | J35: =IF(L35>0,L35,0) -> 0 | K35: =I35+J35 -> 23 | L35: =F35-(I35-AK35) -> -0.85460297 | M35: 4.27 | N35: 0 | O35: 0 | P35: 0 | Q35: =1036700/325851/1.9835*1.02 -> 1.6360705 | R35: =((2)*1.04)-T35 -> 1.2605861 | S35: 0 | T35: =(0.7433*1.06)*1.04 -> 0.81941392 | U35: =M35-(Q35+R35+S35+T35) -> 0.55392952 | V35: 18.3 | W35: 0 | X35: =M35-N35-P35-O35-Q35-R35-S35-T35-U35+V35+W35 -> 18.3 | Y35: =X35-AO35 -> 18.3 | AC35: 0 | AE35: 0 | AH35: 26.8 | AI35: =AI34-AH35 -> 2992.7 | AK35: =N35+O35+P35+Q35+R35+S35+T35+U35+X35+AE35+AH35 -> 49.37 | AL35: =IF(L35<0,L35*-1,0) -> 0.85460297 | AM35: =AK35+AL35 -> 50.224603 | AN35: =V35 -> 18.3 | AO35: 0 | AV35: 0.01 | AW35: 50 | AX35: 10 | AZ35: =SUM(N35,P35:U35) -> 4.27
A36: =A35+1 -> 22 | B36: 6871.8 | C36: 192657 | D36: =C36-C35 -> -82 | E36: =C36-152000 -> 40657 | F36: =D36/$D$2 -> -41.341064 | G36: 24 | H36: 0 | I36: =G36+H36 -> 24 | J36: =IF(L36>0,L36,0) -> 0 | K36: =I36+J36 -> 24 | L36: =F36-(I36-AK36) -> -15.991064 | M36: 4.25 | N36: 0 | O36: 0 | P36: 0 | Q36: =909100/325851/1.9835*1.02 -> 1.4346982 | R36: =((2.1)*1.04)-T36 -> 1.3645861 | S36: 0 | T36: =(0.7433*1.06)*1.04 -> 0.81941392 | U36: =M36-(Q36+R36+S36+T36) -> 0.63130176 | V36: 18.3 | W36: 0 | X36: =M36-N36-P36-O36-Q36-R36-S36-T36-U36+V36+W36 -> 18.3 | Y36: =X36-AO36 -> 18.3 | AC36: 0 | AE36: 0 | AH36: 26.8 | AI36: =AI35-AH36 -> 2965.9 | AK36: =N36+O36+P36+Q36+R36+S36+T36+U36+X36+AE36+AH36 -> 49.35 | AL36: =IF(L36<0,L36*-1,0) -> 15.991064 | AM36: =AK36+AL36 -> 65.341064 | AN36: =V36 -> 18.3 | AO36: 0 | AV36: 0.05 | AW36: 46 | AX36: 14 | AZ36: =SUM(N36,P36:U36) -> 4.25
A37: =A36+1 -> 23 | B37: 6871.79 | C37: 192630 | D37: =C37-C36 -> -27 | E37: =C37-152000 -> 40630 | F37: =D37/$D$2 -> -13.612301 | G37: 25 | H37: 0 | I37: =G37+H37 -> 25 | J37: =IF(L37>0,L37,0) -> 10.397699 | K37: =I37+J37 -> 35.397699 | L37: =F37-(I37-AK37) -> 10.397699 | M37: 3.91 | N37: 0 | O37: 0 | P37: 0 | Q37: =1070900/325851/1.9835*1.02 -> 1.6900433 | R37: =((2.1)*1.04)-T37 -> 1.3645861 | S37: 0 | T37: =(0.7433*1.06)*1.04 -> 0.81941392 | U37: =M37-(Q37+R37+S37+T37) -> 0.035956717 | V37: 18.3 | W37: 0 | X37: =M37-N37-P37-O37-Q37-R37-S37-T37-U37+V37+W37 -> 18.3 | Y37: =X37-AO37 -> 18.3 | AC37: 0 | AE37: 0 | AH37: 26.8 | AI37: =AI36-AH37 -> 2939.1 | AK37: =N37+O37+P37+Q37+R37+S37+T37+U37+X37+AE37+AH37 -> 49.01 | AL37: =IF(L37<0,L37*-1,0) -> 0 | AM37: =AK37+AL37 -> 49.01 | AN37: =V37 -> 18.3 | AO37: 0 | AV37: 0.05 | AW37: 48 | AX37: 23 | AZ37: =SUM(N37,P37:U37) -> 3.91
A38: =A37+1 -> 24 | B38: 6871.81 | C38: 192685 | D38: =C38-C37 -> 55 | E38: =C38-152000 -> 40685 | F38: =D38/$D$2 -> 27.728762 | G38: 25 | H38: 0 | I38: =G38+H38 -> 25 | J38: =IF(L38>0,L38,0) -> 51.728762 | K38: =I38+J38 -> 76.728762 | L38: =F38-(I38-AK38) -> 51.728762 | M38: 3.9 | N38: 0 | O38: 0 | P38: 0 | Q38: =1004000/325851/1.9835*1.02 -> 1.5844649 | R38: =((2.1)*1.04)-T38 -> 1.3645861 | S38: 0 | T38: =(0.7433*1.06)*1.04 -> 0.81941392 | U38: =M38-(Q38+R38+S38+T38) -> 0.1315351 | V38: 18.3 | W38: 0 | X38: =M38-N38-P38-O38-Q38-R38-S38-T38-U38+V38+W38 -> 18.3 | Y38: =X38-AO38 -> 18.3 | AC38: 0 | AE38: 0 | AH38: 26.8 | AI38: =AI37-AH38 -> 2912.3 | AK38: =N38+O38+P38+Q38+R38+S38+T38+U38+X38+AE38+AH38 -> 49 | AL38: =IF(L38<0,L38*-1,0) -> 0 | AM38: =AK38+AL38 -> 49 | AN38: =V38 -> 18.3 | AO38: 0 | AV38: 0.07 | AW38: 38 | AX38: 20 | AZ38: =SUM(N38,P38:U38) -> 3.9
A39: =A38+1 -> 25 | B39: 6871.8 | C39: 192657 | D39: =C39-C38 -> -28 | E39: =C39-152000 -> 40657 | F39: =D39/$D$2 -> -14.116461 | G39: 25 | H39: 0 | I39: =G39+H39 -> 25 | J39: =IF(L39>0,L39,0) -> 9.8835392 | K39: =I39+J39 -> 34.883539 | L39: =F39-(I39-AK39) -> 9.8835392 | M39: 3.9 | N39: 0 | O39: 0 | P39: 0 | Q39: =866700/325851/1.9835*1.02 -> 1.3677846 | R39: =((2.2)*1.04)-T39 -> 1.4685861 | S39: 0 | T39: =(0.7433*1.06)*1.04 -> 0.81941392 | U39: =M39-(Q39+R39+S39+T39) -> 0.24421541 | V39: 18.3 | W39: 0 | X39: =M39-N39-P39-O39-Q39-R39-S39-T39-U39+V39+W39 -> 18.3 | Y39: =X39-AO39 -> 18.3 | AC39: 0 | AE39: 0 | AH39: 26.8 | AI39: =AI38-AH39 -> 2885.5 | AK39: =N39+O39+P39+Q39+R39+S39+T39+U39+X39+AE39+AH39 -> 49 | AL39: =IF(L39<0,L39*-1,0) -> 0 | AM39: =AK39+AL39 -> 49 | AN39: =V39 -> 18.3 | AO39: 0 | AV39: 0.01 | AW39: 35 | AX39: 11 | AZ39: =SUM(N39,P39:U39) -> 3.9
A40: =A39+1 -> 26 | B40: 6871.78 | C40: 192603 | D40: =C40-C39 -> -54 | E40: =C40-152000 -> 40603 | F40: =D40/$D$2 -> -27.224603 | G40: 24 | H40: 0 | I40: =G40+H40 -> 24 | J40: =IF(L40>0,L40,0) -> 0 | K40: =I40+J40 -> 24 | L40: =F40-(I40-AK40) -> -2.224603 | M40: 3.9 | N40: 0 | O40: 0 | P40: 0 | Q40: =1010300/325851/1.9835*1.02 -> 1.5944073 | R40: =((2.2)*1.04)-T40 -> 1.4685861 | S40: 0 | T40: =(0.7433*1.06)*1.04 -> 0.81941392 | U40: =M40-(Q40+R40+S40+T40) -> 0.017592745 | V40: 18.3 | W40: 0 | X40: =M40-N40-P40-O40-Q40-R40-S40-T40-U40+V40+W40 -> 18.3 | Y40: =X40-AO40 -> 18.3 | AC40: 0 | AE40: 0 | AH40: 26.8 | AI40: =AI39-AH40 -> 2858.7 | AK40: =N40+O40+P40+Q40+R40+S40+T40+U40+X40+AE40+AH40 -> 49 | AL40: =IF(L40<0,L40*-1,0) -> 2.224603 | AM40: =AK40+AL40 -> 51.224603 | AN40: =V40 -> 18.3 | AO40: 0 | AV40: 0.01 | AW40: 38 | AX40: 15 | AZ40: =SUM(N40,P40:U40) -> 3.9
A41: =A40+1 -> 27 | B41: 6871.77 | C41: 192576 | D41: =C41-C40 -> -27 | E41: =C41-152000 -> 40576 | F41: =D41/$D$2 -> -13.612301 | G41: 24 | H41: 0 | I41: =G41+H41 -> 24 | J41: =IF(L41>0,L41,0) -> 11.297699 | K41: =I41+J41 -> 35.297699 | L41: =F41-(I41-AK41) -> 11.297699 | M41: 3.81 | N41: 0 | O41: 0 | P41: 0 | Q41: =943900/325851/1.9835*1.02 -> 1.4896179 | R41: =((2.2)*1.04)-T41 -> 1.4685861 | S41: 0 | T41: =(0.7433*1.06)*1.04 -> 0.81941392 | U41: =M41-(Q41+R41+S41+T41) -> 0.032382057 | V41: 18.3 | W41: 0 | X41: =M41-N41-P41-O41-Q41-R41-S41-T41-U41+V41+W41 -> 18.3 | Y41: =X41-AO41 -> 18.3 | AC41: 0 | AE41: 0 | AH41: 26.8 | AI41: =AI40-AH41 -> 2831.9 | AK41: =N41+O41+P41+Q41+R41+S41+T41+U41+X41+AE41+AH41 -> 48.91 | AL41: =IF(L41<0,L41*-1,0) -> 0 | AM41: =AK41+AL41 -> 48.91 | AN41: =V41 -> 18.3 | AO41: 0 | AV41: 0 | AW41: 32 | AX41: 8 | AZ41: =SUM(N41,P41:U41) -> 3.81
A42: =A41+1 -> 28 | B42: 6871.73 | C42: 192467 | D42: =C42-C41 -> -109 | E42: =C42-152000 -> 40467 | F42: =D42/$D$2 -> -54.953365 | G42: 23 | H42: 0 | I42: =G42+H42 -> 23 | J42: =IF(L42>0,L42,0) -> 0 | K42: =I42+J42 -> 23 | L42: =F42-(I42-AK42) -> -29.143365 | M42: 3.71 | N42: 0 | O42: 0 | P42: 0 | Q42: =924300/325851/1.9835*1.02 -> 1.4586862 | R42: =((2.2)*1.04)-T42 -> 1.7190514 | S42: 0 | T42: =(0.5161*1.06)*1.04 -> 0.56894864 | U42: =M42-(Q42+R42+S42+T42) -> -0.036686158 | V42: 18.3 | W42: 0 | X42: =M42-N42-P42-O42-Q42-R42-S42-T42-U42+V42+W42 -> 18.3 | Y42: =X42-AO42 -> 18.3 | AC42: 0 | AE42: 0 | AH42: 26.8 | AI42: =AI41-AH42 -> 2805.1 | AK42: =N42+O42+P42+Q42+R42+S42+T42+U42+X42+AE42+AH42 -> 48.81 | AL42: =IF(L42<0,L42*-1,0) -> 29.143365 | AM42: =AK42+AL42 -> 77.953365 | AN42: =V42 -> 18.3 | AO42: 0 | AV42: 0 | AW42: 30 | AX42: 2 | AZ42: =SUM(N42,P42:U42) -> 3.71
...

Sheet JAN
K1: MCPHEE RESERVOIR INFLOW/OUTFLOW TABULATION
A2: AF/cfs CONVERT FACTOR | D2: 1.9835 | K2: JANUARY "2013"
D4: RESERVOIR | I4: INFLOW | X4: OUTFLOW | AP4: ADJUSTMENTS | AW4: WEATHER
A5: DATE | B5: RESERV | C5: RESERV | D5: AC FT | E5: ACTIVE | F5: CONV TO | G5: DOLORES | H5: LOST | I5: RECORD | J5: CALC | K5: TOTAL | L5: CALC | M5: DOLORES TUNNEL | V5: LONE | W5: U | X5: TOTAL | Y5: TOTAL | Z5: MVI | AA5: MVI | AB5: MVI | AC5: TO EX & | AD5: MVI | AE5: DV CR | AF5: D/S SENIOR | AH5: BELOW | AI5: FISH | AJ5: SPILL | AK5: RECORD | AL5: CALC | AM5: TOTAL | AN5: NAR | AO5: MVI | AP5: MVI | AQ5: MVI | AR5: DIST. | AS5: U/S | AT5: TOTTEN | AU5: UTES | AV5: RAIN | AW5: MAX | AX5: MIN | AZ5: TOTAL
A6: DEC | B6: ELEV | D6: CHANGE | E6: CAP | F6: CFS | G6: RIVER | H6: CAN | I6: INFLOW | J6: INFLOW | K6: INFLOW | L6: INF/OTF | M6: TOT DIV | N6: WET | O6: UTE | P6: QUEST | Q6: MWC | R6: CORTEZ | T6: UTE | U6: F-BAY | V6: PINE | W6: LAT | X6: MVI | Y6: MVI | Z6: CALL | AA6: CALL | AB6: APR- | AC6: U/S EX | AD6: PROJ | AE6: CANAL | AF6: MVIC | AG6: PROJ | AH6: MCP | AI6: LEFT | AK6: OTF | AL6: OTF | AM6: OTF | AN6: FILL | AO6: STOCK | AP6: STORED | AQ6: STORED | AR6: CLASS | AS6: USERS | AT6: (FRESH | AU6: FROM | AW6: TMP | AX6: TMP | AZ6: TUNNEL
N7: LAND | O7: F&R | Q7: NON - | R7: NON - | S7: PROJ | T7: PROJ | U7: BAL | X7: WATER | Y7: IRRIG. | Z7: STOR | AA7: SPILLED | AB7: JUNE | AF7: 1.7 | AG7: 1.3 | AP7: Apr - Jun | AQ7: EVAP | AR7: "B" | AS7: EXCH | AT7: WATER) | AU7: DWCD | AZ7: Misc.
Q8: PROJ | R8: PROJ | X8: USED | Y8: WATER | AA8: OR | AB8: (DIV+
R9: 4.2 | Y9: USED | AA9: USED | AB9: CALL)
C10: AC. Ft. | E10: AC FT | G10: CFS | H10: CFS | I10: CFS | J10: CFS | K10: CFS | L10: CFS | M10: CFS | N10: CFS | O10: CFS | P10: CFS | Q10: CFS | R10: CFS | S10: CFS | T10: CFS | U10: CFS | V10: CFS | W10: CFS | X10: 153400 | Y10: 150400 | AB10: 72000 | AC10: CFS | AD10: CFS | AE10: CFS | AF10: CFS | AG10: CFS | AH10: CFS | AI10: CFS | AJ10: CFS | AK10: CFS | AL10: CFS | AM10: CFS | AN10: CFS | AO10: CFS | AP10: CFS | AQ10: AC.FT. | AR10: CFS | AS10: CFS | AT10: CFS | AU10: CFS | AZ10: Outflow
N11: 1.03 | O11: 1.05 | P11: 1.02 | Q11: 1.02 | R11: 1.04 | T11: 1.04 | X11: CFS | Y11: CFS | Z11: CFS | AA11: CFS | AB11: Ac. Ft. | AZ11: CFS
A12: SEASON BAL
A13: YTD | B13: =DEC!B45 -> 6871.7 | C13: =DEC!C45 -> 192386 | D13: =DEC!D54 -> -2769 | E13: =DEC!E54 -> 40386 | F13: =DEC!F53 -> -1396.0171 | G13: =DEC!G53 -> 1777 | H13: =DEC!H53 -> 0.62 | I13: =DEC!I53 -> 1777 | J13: =DEC!J53 -> 379.04663 | K13: =DEC!K53 -> 2156.0466 | L13: =DEC!L53 -> -101.42164 | M13: =DEC!M53 -> 422.64 | ... Y13: =DEC!Y53 -> 973.42 | AC13: =DEC!AC53 -> 27.7 | AH13: =DEC!AH53 -> 1522.3 | AI13: =DEC!AI53 -> 2724.7 | AK13: =DEC!AK53 -> 3071.5955 | AL13: =DEC!AL53 -> 480.46828 | AM13: =DEC!AM53 -> 3552.0638 | AN13: =DEC!AN53 -> 973.42 | AO13: =DEC!AO53 -> 323.96244 | AV13: =DEC!AV53 -> 1.673 | AZ13: =DEC!AZ53 -> 242.97756
A15: 1 | B15: 6871.67 | C15: 192304 | D15: =C15-C13 -> -82 | E15: =C15-152000 -> 40304 | F15: =D15/$D$2 -> -41.341064 | G15: 23 | H15: 0 | I15: =G15+H15 -> 23 | J15: =IF(L15>0,L15,0) -> 0 | K15: =I15+J15 -> 23 | L15: =F15-(I15-AK15) -> -15.471064 | M15: 3.77 | N15: 0 | O15: 0 | P15: 0 | Q15: =989600/325851/1.9835*1.02 -> 1.5617395 | R15: =((2.2)*1.04)-T15 -> 1.7126574 | S15: 0 | T15: =(0.5219*1.06)*1.04 -> 0.57534256 | U15: =M15-(Q15+R15+S15+T15) -> -0.079739502 | V15: 18.3 | W15: 0 | X15: =M15-N15-P15-O15-Q15-R15-S15-T15-U15+V15+W15 -> 18.3 | Y15: =X15-AO15 -> 18.3 | AC15: 0 | AE15: 0 | AH15: 26.8 | AI15: =AI13-AH15 -> 2697.9 | AK15: =N15+O15+P15+Q15+R15+S15+T15+U15+X15+AE15+AH15 -> 48.87 | AL15: =IF(L15<0,L15*-1,0) -> 15.471064 | AM15: =AK15+AL15 -> 64.341064 | AN15: =X15 -> 18.3 | AO15: 0 | AV15: 0 | AW15: 31 | AX15: -3 | AZ15: =SUM(N15,P15:U15) -> 3.77
A16: =A15+1 -> 2 | B16: 6871.64 | C16: 192223 | D16: =C16-C15 -> -81 | E16: =C16-152000 -> 40223 | F16: =D16/$D$2 -> -40.836904 | G16: 20 | H16: 0 | I16: =G16+H16 -> 20 | J16: =IF(L16>0,L16,0) -> 0 | K16: =I16+J16 -> 20 | L16: =F16-(I16-AK16) -> -11.836904 | M16: 3.9 | N16: 0 | O16: 0 | P16: 0 | Q16: =983400/325851/1.9835*1.02 -> 1.551955 | R16: =((2.2)*1.04)-T16 -> 1.7126574 | S16: 0 | T16: =(0.5219*1.06)*1.04 -> 0.57534256 | U16: =M16-(Q16+R16+S16+T16) -> 0.060045042 | V16: 18.3 | W16: 0 | X16: =M16-N16-P16-O16-Q16-R16-S16-T16-U16+V16+W16 -> 18.3 | Y16: =X16-AO16 -> 18.3 | AC16: 0 | AE16: 0 | AH16: 26.8 | AI16: =AI15-AH16 -> 2671.1 | AK16: =N16+O16+P16+Q16+R16+S16+T16+U16+X16+AE16+AH16 -> 49 | AL16: =IF(L16<0,L16*-1,0) -> 11.836904 | AM16: =AK16+AL16 -> 60.836904 | AN16: =X16 -> 18.3 | AO16: 0 | AV16: 0 | AW16: 32 | AX16: -4 | AZ16: =SUM(N16,P16:U16) -> 3.9
A17: =A16+1 -> 3 | B17: 6871.62 | C17: 192168 | D17: =C17-C16 -> -55 | E17: =C17-152000 -> 40168 | F17: =D17/$D$2 -> -27.728762 | G17: 19 | H17: 0 | I17: =G17+H17 -> 19 | J17: =IF(L17>0,L17,0) -> 2.1612377 | K17: =I17+J17 -> 21.161238 | L17: =F17-(I17-AK17) -> 2.1612377 | M17: 3.79 | N17: 0 | O17: 0 | P17: 0 | Q17: =989400/325851/1.9835*1.02 -> 1.5614239 | R17: =((2.2)*1.04)-T17 -> 1.7126574 | S17: 0 | T17: =(0.5219*1.06)*1.04 -> 0.57534256 | U17: =M17-(Q17+R17+S17+T17) -> -0.059423872 | V17: 18.3 | W17: 0 | X17: =M17-N17-P17-O17-Q17-R17-S17-T17-U17+V17+W17 -> 18.3 | Y17: =X17-AO17 -> 18.3 | AC17: 0 | AE17: 0 | AH17: 26.8 | AI17: =AI16-AH17 -> 2644.3 | AK17: =N17+O17+P17+Q17+R17+S17+T17+U17+X17+AE17+AH17 -> 48.89 | AL17: =IF(L17<0,L17*-1,0) -> 0 | AM17: =AK17+AL17 -> 48.89 | AN17: =X17 -> 18.3 | AO17: 0 | AV17: 0 | AW17: 30 | AX17: 0 | AZ17: =SUM(N17,P17:U17) -> 3.79
