Workbook

Sheet NOV
K1: MC PHEE RESERVOIR IN/OUT FLOW TABULATION
A2: AF/cfs CONVERT FACTOR | D2: 1.9835 | L2: NOVEMBER "97"
A4: DATE | B4: RESERV | C4: RESERV | D4: AC FT | E4: ACTIVE | F4: CONV TO | G4: DOLORES | H4: LOST | I4: RECORDED | J4: CALC | K4: TOTAL | L4: CALC | M4: DOLORES TUNNEL | P4: LONE | Q4: U | R4: TOTAL | S4: MVI | T4: DV CR | U4: BELOW | V4: REMAIN | W4: RECORDED | X4: CALC | Y4: TOTAL | Z4: RAIN | AA4: MAX | AB4: MIN | AC4: DATE
A5: "NOV" | B5: ELEV | C5: AC FT | D5: CHANGE | E5: CAP | F5: CFS | G5: RIVER | H5: CANYON | I5: INFLOW | J5: INFLOW | K5: INFLOW | L5: INF/OTF | M5: TOT DIV | N5: UTE F&R | O5: MVI,CTZ | P5: PINE | Q5: LATERAL | R5: MVI | S5: CALL | T5: CANAL | U5: MC PHEE | V5: RELEASE | W5: OUTFLOW | X5: OUTFLOW | Y5: OUTFLOW | AA5: TMP | AB5: TMP | AC5: "NOV"
A7: SEASON BAL | V7: =V6/D2 -> 0
A8: YTD | B8: 6912.85 | C8: 333510 | V8: 6148 | AD8: 13149 | AE8: 17902
A10: 1 | B10: 6912.85 | C10: 333510 | D10: =C10-C8 -> 0 | E10: =C10-152000 -> 181510 | F10: =D10/$D$2 -> 0 | G10: 166 | H10: 6 | I10: =G10+H10 -> 172 | J10: =IF(L10>0,L10,0) -> 0 | K10: =I10+J10 -> 172 | L10: =F10-(I10-W10) -> -62 | M10: 47 | N10: 0 | O10: =M10-N10 -> 47 | P10: 0 | Q10: 11 | R10: =SUM(O10:Q10) -> 58 | T10: 0 | U10: 52 | V10: =(V7+V8)-U10 -> 6096 | W10: =N10+R10+T10+U10 -> 110 | X10: =IF(L10<0,L10*-1,0) -> 62 | Y10: =W10+X10 -> 172 | Z10: 0 | AA10: 52 | AB10: 34 | AC10: 1 | AD10: 13243 | AF10: 7883
A11: =A10+1 -> 2 | B11: 6912.85 | C11: 333510 | D11: =C11-C10 -> 0 | E11: =C11-152000 -> 181510 | F11: =D11/$D$2 -> 0 | G11: 145 | H11: 4.9 | I11: =G11+H11 -> 149.9 | J11: =IF(L11>0,L11,0) -> 0 | K11: =I11+J11 -> 149.9 | L11: =F11-(I11-W11) -> -37.9 | M11: 49 | N11: 0 | O11: =M11-N11 -> 49 | P11: 0 | Q11: 11 | R11: =SUM(O11:Q11) -> 60 | T11: 0 | U11: 52 | V11: =V10-U11 -> 6044 | W11: =N11+R11+T11+U11 -> 112 | X11: =IF(L11<0,L11*-1,0) -> 37.9 | Y11: =W11+X11 -> 149.9 | Z11: 0 | AA11: 53 | AB11: 23 | AC11: =AC10+1 -> 2 | AD11: 13333 | AE11: 62
A12: =A11+1 -> 3 | B12: 6912.85 | C12: 333510 | D12: =C12-C11 -> 0 | E12: =C12-152000 -> 181510 | F12: =D12/$D$2 -> 0 | G12: 136 | H12: 4.5 | I12: =G12+H12 -> 140.5 | J12: =IF(L12>0,L12,0) -> 0 | K12: =I12+J12 -> 140.5 | L12: =F12-(I12-W12) -> -6.5 | M12: 71 | N12: =(11+11)*1.05 -> 23.1 | O12: =M12-N12 -> 47.9 | P12: 0 | Q12: 11 | R12: =SUM(O12:Q12) -> 58.9 | T12: 0 | U12: 52 | V12: =V11-U12 -> 5992 | W12: =N12+R12+T12+U12 -> 134 | X12: =IF(L12<0,L12*-1,0) -> 6.5 | Y12: =W12+X12 -> 140.5 | Z12: 0 | AA12: 57 | AB12: 24 | AC12: =AC11+1 -> 3 | AD12: 13456 | AE12: 159
A13: =A12+1 -> 4 | B13: 6912.86 | C13: 333550 | D13: =C13-C12 -> 40 | E13: =C13-152000 -> 181550 | F13: =D13/$D$2 -> 20.166373 | G13: 146 | H13: 5.2 | I13: =G13+H13 -> 151.2 | J13: =IF(L13>0,L13,0) -> 16.966373 | K13: =I13+J13 -> 168.16637 | L13: =F13-(I13-W13) -> 16.966373 | M13: 85 | N13: =(19+20)*1.05 -> 40.95 | O13: =M13-N13 -> 44.05 | P13: 0 | Q13: 11 | R13: =SUM(O13:Q13) -> 55.05 | T13: 0 | U13: 52 | V13: =V12-U13 -> 5940 | W13: =N13+R13+T13+U13 -> 148 | X13: =IF(L13<0,L13*-1,0) -> 0 | Y13: =W13+X13 -> 148 | Z13: 0 | AA13: 64 | AB13: 28 | AC13: =AC12+1 -> 4 | AD13: 13563 | AE13: 263
A14: =A13+1 -> 5 | B14: 6912.86 | C14: 333550 | D14: =C14-C13 -> 0 | E14: =C14-152000 -> 181550 | F14: =D14/$D$2 -> 0 | G14: 139 | H14: 5.1 | I14: =G14+H14 -> 144.1 | J14: =IF(L14>0,L14,0) -> 0 | K14: =I14+J14 -> 144.1 | L14: =F14-(I14-W14) -> -1.1 | M14: 80 | N14: =(21+22)*1.05 -> 45.15 | O14: =M14-N14 -> 34.85 | P14: 0 | Q14: 11 | R14: =SUM(O14:Q14) -> 45.85 | T14: 0 | U14: 52 | V14: =V13-U14 -> 5888 | W14: =N14+R14+T14+U14 -> 143 | X14: =IF(L14<0,L14*-1,0) -> 1.1 | Y14: =W14+X14 -> 144.1 | Z14: 0 | AA14: 65 | AB14: 33 | AC14: =AC13+1 -> 5 | AD14: 13678 | AE14: 367
A15: =A14+1 -> 6 | B15: 6912.86 | C15: 333550 | D15: =C15-C14 -> 0 | E15: =C15-152000 -> 181550 | F15: =D15/$D$2 -> 0 | G15: 137 | H15: 4.8 | I15: =G15+H15 -> 141.8 | J15: =IF(L15>0,L15,0) -> 0 | K15: =I15+J15 -> 141.8 | L15: =F15-(I15-W15) -> -12.8 | M15: 66 | N15: =(17+17)*1.05 -> 35.7 | O15: =M15-N15 -> 30.3 | P15: 0 | Q15: 11 | R15: =SUM(O15:Q15) -> 41.3 | T15: 0 | U15: 52 | V15: =V14-U15 -> 5836 | W15: =N15+R15+T15+U15 -> 129 | X15: =IF(L15<0,L15*-1,0) -> 12.8 | Y15: =W15+X15 -> 141.8 | Z15: 0 | AA15: 67 | AB15: 33 | AC15: =AC14+1 -> 6 | AD15: 13812 | AE15: 469
A16: =A15+1 -> 7 | B16: 6912.87 | C16: 333591 | D16: =C16-C15 -> 41 | E16: =C16-152000 -> 181591 | F16: =D16/$D$2 -> 20.670532 | G16: 134 | H16: 4.5 | I16: =G16+H16 -> 138.5 | J16: =IF(L16>0,L16,0) -> 0 | K16: =I16+J16 -> 138.5 | L16: =F16-(I16-W16) -> -7.8294681 | M16: 47 | N16: =(7.8+8)*1.05 -> 16.59 | O16: =M16-N16 -> 30.41 | P16: 0 | Q16: 11 | R16: =SUM(O16:Q16) -> 41.41 | T16: 0 | U16: 52 | V16: =V15-U16 -> 5784 | W16: =N16+R16+T16+U16 -> 110 | X16: =IF(L16<0,L16*-1,0) -> 7.8294681 | Y16: =W16+X16 -> 117.82947 | Z16: 0 | AA16: 62 | AB16: 33 | AC16: =AC15+1 -> 7 | AD16: 13968 | AE16: 587
A17: =A16+1 -> 8 | B17: 6912.88 | C17: 333632 | D17: =C17-C16 -> 41 | E17: =C17-152000 -> 181632 | F17: =D17/$D$2 -> 20.670532 | G17: 132 | H17: 4.4 | I17: =G17+H17 -> 136.4 | J17: =IF(L17>0,L17,0) -> 0 | K17: =I17+J17 -> 136.4 | L17: =F17-(I17-W17) -> -20.729468 | M17: 32 | N17: 0 | O17: =M17-N17 -> 32 | P17: 0 | Q17: 11 | R17: =SUM(O17:Q17) -> 43 | T17: 0 | U17: 52 | V17: =V16-U17 -> 5732 | W17: =N17+R17+T17+U17 -> 95 | X17: =IF(L17<0,L17*-1,0) -> 20.729468 | Y17: =W17+X17 -> 115.72947 | Z17: 0 | AA17: 58 | AB17: 33 | AC17: =AC16+1 -> 8 | AD17: 14117 | AE17: 707
A18: =A17+1 -> 9 | B18: 6912.93 | C18: 333836 | D18: =C18-C17 -> 204 | E18: =C18-152000 -> 181836 | F18: =D18/$D$2 -> 102.8485 | G18: 148 | H18: 5.4 | I18: =G18+H18 -> 153.4 | J18: =IF(L18>0,L18,0) -> 45.4485 | K18: =I18+J18 -> 198.8485 | L18: =F18-(I18-W18) -> 45.4485 | M18: 33 | N18: 0 | O18: =M18-N18 -> 33 | P18: 0 | Q18: 11 | R18: =SUM(O18:Q18) -> 44 | T18: 0 | U18: 52 | V18: =V17-U18 -> 5680 | W18: =N18+R18+T18+U18 -> 96 | X18: =IF(L18<0,L18*-1,0) -> 0 | Y18: =W18+X18 -> 96 | Z18: 0.43 | AA18: 42 | AB18: 30 | AC18: =AC17+1 -> 9 | AD18: 14264 | AE18: 826
A19: =A18+1 -> 10 | B19: 6912.96 | C19: 333958 | D19: =C19-C18 -> 122 | E19: =C19-152000 -> 181958 | F19: =D19/$D$2 -> 61.507436 | G19: 139 | H19: 5.3 | I19: =G19+H19 -> 144.3 | J19: =IF(L19>0,L19,0) -> 3.2074363 | K19: =I19+J19 -> 147.50744 | L19: =F19-(I19-W19) -> 3.2074363 | M19: 23 | N19: =(14+14)*1.05 -> 29.4 | O19: =M19-N19 -> -6.4 | P19: 0 | Q19: 11 | R19: =SUM(O19:Q19) -> 4.6 | T19: 0 | U19: 52 | V19: =V18-U19 -> 5628 | W19: =N19+R19+T19+U19 -> 86 | X19: =IF(L19<0,L19*-1,0) -> 0 | Y19: =W19+X19 -> 86 | Z19: 0 | AA19: 42 | AB19: 25 | AC19: =AC18+1 -> 10 | AD19: 14413 | AE19: 964
A20: =A19+1 -> 11 | B20: 6913 | C20: 334121 | D20: =C20-C19 -> 163 | E20: =C20-152000 -> 182121 | F20: =D20/$D$2 -> 82.177968 | G20: 142 | H20: 5.9 | I20: =G20+H20 -> 147.9 | J20: =IF(L20>0,L20,0) -> 12.277968 | K20: =I20+J20 -> 160.17797 | L20: =F20-(I20-W20) -> 12.277968 | M20: 19 | N20: =(23+23)*1.05 -> 48.3 | O20: =M20-N20 -> -29.3 | P20: 0 | Q20: 11 | R20: =SUM(O20:Q20) -> -18.3 | T20: 0 | U20: 48 | V20: =V19-U20 -> 5580 | W20: =N20+R20+T20+U20 -> 78 | X20: =IF(L20<0,L20*-1,0) -> 0 | Y20: =W20+X20 -> 78 | Z20: 0.48 | AA20: 49 | AB20: 36 | AC20: =AC19+1 -> 11 | AD20: 14571 | AE20: 1065
A21: =A20+1 -> 12 | B21: 6913.06 | C21: 334368 | D21: =C21-C20 -> 247 | E21: =C21-152000 -> 182368 | F21: =D21/$D$2 -> 124.52735 | G21: 149 | H21: 5.8 | I21: =G21+H21 -> 154.8 | J21: =IF(L21>0,L21,0) -> 39.727351 | K21: =I21+J21 -> 194.52735 | L21: =F21-(I21-W21) -> 39.727351 | M21: 19 | N21: =(8.6+8.6)*1.05 -> 18.06 | O21: =M21-N21 -> 0.94 | P21: 0 | Q21: 11 | R21: =SUM(O21:Q21) -> 11.94 | T21: 0 | U21: 40 | V21: =V20-U21 -> 5540 | W21: =N21+R21+T21+U21 -> 70 | X21: =IF(L21<0,L21*-1,0) -> 0 | Y21: =W21+X21 -> 70 | Z21: 0.01 | AA21: 44 | AB21: 27 | AC21: =AC20+1 -> 12 | AD21: 14696 | AE21: 1185
A22: =A21+1 -> 13 | B22: 6913.08 | C22: 334450 | D22: =C22-C21 -> 82 | E22: =C22-152000 -> 182450 | F22: =D22/$D$2 -> 41.341064 | G22: 144 | H22: 5.9 | I22: =G22+H22 -> 149.9 | J22: =IF(L22>0,L22,0) -> 0 | K22: =I22+J22 -> 149.9 | L22: =F22-(I22-W22) -> -38.558936 | M22: 19 | N22: 0 | O22: =M22-N22 -> 19 | P22: 0 | Q22: 11 | R22: =SUM(O22:Q22) -> 30 | T22: 0 | U22: 40 | V22: =V21-U22 -> 5500 | W22: =N22+R22+T22+U22 -> 70 | X22: =IF(L22<0,L22*-1,0) -> 38.558936 | Y22: =W22+X22 -> 108.55894 | Z22: 0 | AA22: 40 | AB22: 28 | AC22: =AC21+1 -> 13 | AD22: 14771 | AE22: 1299
A23: =A22+1 -> 14 | B23: 6913.1 | C23: 334532 | D23: =C23-C22 -> 82 | E23: =C23-152000 -> 182532 | F23: =D23/$D$2 -> 41.341064 | G23: 134 | H23: 5.3 | I23: =G23+H23 -> 139.3 | J23: =IF(L23>0,L23,0) -> 0 | K23: =I23+J23 -> 139.3 | L23: =F23-(I23-W23) -> -45.438936 | M23: 9.32 | N23: 0 | O23: =M23-N23 -> 9.32 | P23: 0 | Q23: 3.2 | R23: =SUM(O23:Q23) -> 12.52 | T23: 0 | U23: 40 | V23: =V22-U23 -> 5460 | W23: =N23+R23+T23+U23 -> 52.52 | X23: =IF(L23<0,L23*-1,0) -> 45.438936 | Y23: =W23+X23 -> 97.958936 | Z23: 0 | AA23: 36 | AB23: 30 | AC23: =AC22+1 -> 14 | AD23: 14842 | AE23: 1407
A24: =A23+1 -> 15 | B24: 6913.11 | C24: 334573 | D24: =C24-C23 -> 41 | E24: =C24-152000 -> 182573 | F24: =D24/$D$2 -> 20.670532 | G24: 102 | H24: 3.7 | I24: =G24 -> 102 | J24: =IF(L24>0,L24,0) -> 0 | K24: =I24+J24 -> 102 | L24: =F24-(I24-W24) -> -36.159468 | M24: 5.17 | N24: 0 | O24: =M24-N24 -> 5.17 | P24: 0 | Q24: 0 | R24: =SUM(O24:Q24) -> 5.17 | T24: 0 | U24: 40 | V24: =V23-U24 -> 5420 | W24: =N24+R24+T24+U24 -> 45.17 | X24: =IF(L24<0,L24*-1,0) -> 36.159468 | Y24: =W24+X24 -> 81.329468 | Z24: 0 | AA24: 40 | AB24: 12 | AC24: =AC23+1 -> 15 | AD24: 14927 | AE24: 1516
A25: =A24+1 -> 16 | B25: 6913.13 | C25: 334655 | D25: =C25-C24 -> 82 | E25: =C25-152000 -> 182655 | F25: =D25/$D$2 -> 41.341064 | G25: 63 | H25: 3.5 | I25: =G25+H25 -> 66.5 | J25: =IF(L25>0,L25,0) -> 19.601064 | K25: =I25+J25 -> 86.101064 | L25: =F25-(I25-W25) -> 19.601064 | M25: 4.76 | N25: 0 | O25: =M25-N25 -> 4.76 | P25: 0 | Q25: 0 | R25: =SUM(O25:Q25) -> 4.76 | T25: 0 | U25: 40 | V25: =V24-U25 -> 5380 | W25: =N25+R25+T25+U25 -> 44.76 | X25: =IF(L25<0,L25*-1,0) -> 0 | Y25: =W25+X25 -> 44.76 | Z25: 0 | AA25: 40 | AB25: 14 | AC25: =AC24+1 -> 16 | AD25: 15009 | AE25: 1615
A26: =A25+1 -> 17 | B26: 6913.14 | C26: 334697 | D26: =C26-C25 -> 42 | E26: =C26-152000 -> 182697 | F26: =D26/$D$2 -> 21.174691 | G26: 95 | H26: 3.8 | I26: =G26+H26 -> 98.8 | J26: =IF(L26>0,L26,0) -> 0 | K26: =I26+J26 -> 98.8 | L26: =F26-(I26-W26) -> -33.425309 | M26: 4.2 | N26: 0 | O26: =M26-N26 -> 4.2 | P26: 0 | Q26: 0 | R26: =SUM(O26:Q26) -> 4.2 | T26: 0 | U26: 40 | V26: =V25-U26 -> 5340 | W26: =N26+R26+T26+U26 -> 44.2 | X26: =IF(L26<0,L26*-1,0) -> 33.425309 | Y26: =W26+X26 -> 77.625309 | Z26: 0 | AA26: 43 | AB26: 16 | AC26: =AC25+1 -> 17 | AD26: 15112 | AE26: 1714
A27: =A26+1 -> 18 | B27: 6913.16 | C27: 334779 | D27: =C27-C26 -> 82 | E27: =C27-152000 -> 182779 | F27: =D27/$D$2 -> 41.341064 | G27: 110 | H27: 4 | I27: =G27+H27 -> 114 | J27: =IF(L27>0,L27,0) -> 0 | K27: =I27+J27 -> 114 | L27: =F27-(I27-W27) -> -29.658936 | M27: 3 | N27: 0 | O27: =M27-N27 -> 3 | P27: 0 | Q27: 0 | R27: =SUM(O27:Q27) -> 3 | T27: 0 | U27: 40 | V27: =V26-U27 -> 5300 | W27: =N27+R27+T27+U27 -> 43 | X27: =IF(L27<0,L27*-1,0) -> 29.658936 | Y27: =W27+X27 -> 72.658936 | Z27: 0 | AA27: 45 | AB27: 16 | AC27: =AC26+1 -> 18 | AD27: 15213 | AE27: 1812
A28: =A27+1 -> 19 | B28: 6913.2 | C28: 334943 | D28: =C28-C27 -> 164 | E28: =C28-152000 -> 182943 | F28: =D28/$D$2 -> 82.682128 | G28: 120 | H28: 4.1 | I28: =G28+H28 -> 124.1 | J28: =IF(L28>0,L28,0) -> 1.2621276 | K28: =I28+J28 -> 125.36213 | L28: =F28-(I28-W28) -> 1.2621276 | M28: 2.68 | N28: 0 | O28: =M28-N28 -> 2.68 | P28: 0 | Q28: 0 | R28: =SUM(O28:Q28) -> 2.68 | T28: 0 | U28: 40 | V28: =V27-U28 -> 5260 | W28: =N28+R28+T28+U28 -> 42.68 | X28: =IF(L28<0,L28*-1,0) -> 0 | Y28: =W28+X28 -> 42.68 | Z28: 0 | AA28: 53 | AB28: 24 | AC28: =AC27+1 -> 19 | AD28: 15295 | AE28: 1909
A29: =A28+1 -> 20 | B29: 6913.26 | C29: 335190 | D29: =C29-C28 -> 247 | E29: =C29-152000 -> 183190 | F29: =D29/$D$2 -> 124.52735 | G29: 115 | H29: 4 | I29: =G29+H29 -> 119 | J29: =IF(L29>0,L29,0) -> 48.197351 | K29: =I29+J29 -> 167.19735 | L29: =F29-(I29-W29) -> 48.197351 | M29: 2.67 | N29: 0 | O29: =M29-N29 -> 2.67 | P29: 0 | Q29: 0 | R29: =SUM(O29:Q29) -> 2.67 | T29: 0 | U29: 40 | V29: =V28-U29 -> 5220 | W29: =N29+R29+T29+U29 -> 42.67 | X29: =IF(L29<0,L29*-1,0) -> 0 | Y29: =W29+X29 -> 42.67 | Z29: 0 | AA29: 59 | AB29: 30 | AC29: =AC28+1 -> 20 | AD29: 15367 | AE29: 2006
A30: =A29+1 -> 21 | B30: 6913.28 | C30: 335272 | D30: =C30-C29 -> 82 | E30: =C30-152000 -> 183272 | F30: =D30/$D$2 -> 41.341064 | G30: 105 | H30: 4 | I30: =G30+H30 -> 109 | J30: =IF(L30>0,L30,0) -> 0 | K30: =I30+J30 -> 109 | L30: =F30-(I30-W30) -> -25.168936 | M30: 2.49 | N30: 0 | O30: =M30-N30 -> 2.49 | P30: 0 | Q30: 0 | R30: =SUM(O30:Q30) -> 2.49 | T30: 0 | U30: 40 | V30: =V29-U30 -> 5180 | W30: =N30+R30+T30+U30 -> 42.49 | X30: =IF(L30<0,L30*-1,0) -> 25.168936 | Y30: =W30+X30 -> 67.658936 | Z30: 0 | AA30: 48 | AB30: 19 | AC30: =AC29+1 -> 21 | AD30: 15445 | AE30: 2106 | AF30: 273.4
A31: =A30+1 -> 22 | B31: 6913.3 | C31: 335354 | D31: =C31-C30 -> 82 | E31: =C31-152000 -> 183354 | F31: =D31/$D$2 -> 41.341064 | G31: 103 | H31: 3.8 | I31: =G31+H31 -> 106.8 | J31: =IF(L31>0,L31,0) -> 0 | K31: =I31+J31 -> 106.8 | L31: =F31-(I31-W31) -> -22.978936 | M31: 2.49 | N31: 0 | O31: =M31-N31 -> 2.49 | P31: 0 | Q31: 0 | R31: =SUM(O31:Q31) -> 2.49 | T31: 0 | U31: 39.99 | V31: =V30-U31 -> 5140.01 | W31: =N31+R31+T31+U31 -> 42.48 | X31: =IF(L31<0,L31*-1,0) -> 22.978936 | Y31: =W31+X31 -> 65.458936 | Z31: 0 | AA31: 51 | AB31: 20 | AC31: =AC30+1 -> 22 | AD31: 15524 | AE31: 2203 | AF31: 249.63
A32: =A31+1 -> 23 | B32: 6913.31 | C32: 335395 | D32: =C32-C31 -> 41 | E32: =C32-152000 -> 183395 | F32: =D32/$D$2 -> 20.670532 | G32: 95 | H32: 3.7 | I32: =G32+H32 -> 98.7 | J32: =IF(L32>0,L32,0) -> 0 | K32: =I32+J32 -> 98.7 | L32: =F32-(I32-W32) -> -35.539468 | M32: 2.49 | N32: 0 | O32: =M32-N32 -> 2.49 | P32: 0 | Q32: 0 | R32: =SUM(O32:Q32) -> 2.49 | T32: 0 | U32: 40 | V32: =V31-U32 -> 5100.01 | W32: =N32+R32+T32+U32 -> 42.49 | X32: =IF(L32<0,L32*-1,0) -> 35.539468 | Y32: =W32+X32 -> 78.029468 | Z32: 0 | AA32: 54 | AB32: 21 | AC32: =AC31+1 -> 23 | AD32: 15607 | AE32: 2299 | AF32: 243.94
A33: =A32+1 -> 24 | B33: 6913.34 | C33: 335518 | D33: =C33-C32 -> 123 | E33: =C33-152000 -> 183518 | F33: =D33/$D$2 -> 62.011596 | G33: 100 | H33: 3.7 | I33: =G33+H33 -> 103.7 | J33: =IF(L33>0,L33,0) -> 0.80159566 | K33: =I33+J33 -> 104.5016 | L33: =F33-(I33-W33) -> 0.80159566 | M33: 2.49 | N33: 0 | O33: =M33-N33 -> 2.49 | P33: 0 | Q33: 0 | R33: =SUM(O33:Q33) -> 2.49 | T33: 0 | U33: 40 | V33: =V32-U33 -> 5060.01 | W33: =N33+R33+T33+U33 -> 42.49 | X33: =IF(L33<0,L33*-1,0) -> 0 | Y33: =W33+X33 -> 42.49 | Z33: 0 | AA33: 59 | AB33: 22 | AC33: =AC32+1 -> 24 | AD33: 15666 | AE33: 2395 | AF33: 243.15
A34: =A33+1 -> 25 | B34: 6913.36 | C34: 335601 | D34: =C34-C33 -> 83 | E34: =C34-152000 -> 183601 | F34: =D34/$D$2 -> 41.845223 | G34: 108 | H34: 3.7 | I34: =G34+H34 -> 111.7 | J34: =IF(L34>0,L34,0) -> 0 | K34: =I34+J34 -> 111.7 | L34: =F34-(I34-W34) -> -26.974777 | M34: 2.88 | N34: 0 | O34: =M34-N34 -> 2.88 | P34: 0 | Q34: 0 | R34: =SUM(O34:Q34) -> 2.88 | T34: 0 | U34: 40 | V34: =V33-U34 -> 5020.01 | W34: =N34+R34+T34+U34 -> 42.88 | X34: =IF(L34<0,L34*-1,0) -> 26.974777 | Y34: =W34+X34 -> 69.854777 | Z34: 0 | AA34: 54 | AB34: 36 | AC34: =AC33+1 -> 25 | AD34: 15726 | AE34: 2491 | AF34: 242.11
A35: =A34+1 -> 26 | B35: 6913.38 | C35: 335683 | D35: =C35-C34 -> 82 | E35: =C35-152000 -> 183683 | F35: =D35/$D$2 -> 41.341064 | G35: 115 | H35: 3.5 | I35: =G35+H35 -> 118.5 | J35: =IF(L35>0,L35,0) -> 0 | K35: =I35+J35 -> 118.5 | L35: =F35-(I35-W35) -> -33.178936 | M35: 2.98 | N35: 0 | O35: =M35-N35 -> 2.98 | P35: 0 | Q35: 0 | R35: =SUM(O35:Q35) -> 2.98 | T35: 0 | U35: 41 | V35: =V34-U35 -> 4979.01 | W35: =N35+R35+T35+U35 -> 43.98 | X35: =IF(L35<0,L35*-1,0) -> 33.178936 | Y35: =W35+X35 -> 77.158936 | Z35: 0 | AA35: 51 | AB35: 38 | AC35: =AC34+1 -> 26 | AD35: 15781 | AE35: 2589 | AF35: 244.72
A36: =A35+1 -> 27 | B36: 6913.45 | C36: 335970 | D36: =C36-C35 -> 287 | E36: =C36-152000 -> 183970 | F36: =D36/$D$2 -> 144.69372 | G36: 122 | H36: 4.1 | I36: =G36+H36 -> 126.1 | J36: =IF(L36>0,L36,0) -> 62.503723 | K36: =I36+J36 -> 188.60372 | L36: =F36-(I36-W36) -> 62.503723 | M36: 2.91 | N36: 0 | O36: =M36-N36 -> 2.91 | P36: 0 | Q36: 0 | R36: =SUM(O36:Q36) -> 2.91 | T36: 0 | U36: 41 | V36: =V35-U36 -> 4938.01 | W36: =N36+R36+T36+U36 -> 43.91 | X36: =IF(L36<0,L36*-1,0) -> 0 | Y36: =W36+X36 -> 43.91 | Z36: 0.15 | AA36: 48 | AB36: 34 | AC36: =AC35+1 -> 27 | AD36: 15841 | AE36: 2686 | AF36: 252.4
A37: =A36+1 -> 28 | B37: 6913.5 | C37: 336176 | D37: =C37-C36 -> 206 | E37: =C37-152000 -> 184176 | F37: =D37/$D$2 -> 103.85682 | G37: 106 | H37: 3.8 | I37: =G37+H37 -> 109.8 | J37: =IF(L37>0,L37,0) -> 37.836819 | K37: =I37+J37 -> 147.63682 | L37: =F37-(I37-W37) -> 37.836819 | M37: 2.78 | N37: 0 | O37: =M37-N37 -> 2.78 | P37: 0 | Q37: 0 | R37: =SUM(O37:Q37) -> 2.78 | T37: 0 | U37: 41 | V37: =V36-U37 -> 4897.01 | W37: =N37+R37+T37+U37 -> 43.78 | X37: =IF(L37<0,L37*-1,0) -> 0 | Y37: =W37+X37 -> 43.78 | Z37: 0.02 | AA37: 40 | AB37: 23 | AC37: =AC36+1 -> 28 | AD37: 804 | AE37: 2779 | AF37: 254.14
A38: =A37+1 -> 29 | B38: 6913.51 | C38: 336217 | D38: =C38-C37 -> 41 | E38: =C38-152000 -> 184217 | F38: =D38/$D$2 -> 20.670532 | G38: 93 | H38: 3.8 | I38: =G38+H38 -> 96.8 | J38: =IF(L38>0,L38,0) -> 0 | K38: =I38+J38 -> 96.8 | L38: =F38-(I38-W38) -> -32.349468 | M38: 2.78 | N38: 0 | O38: =M38-N38 -> 2.78 | P38: 0 | Q38: 0 | R38: =SUM(O38:Q38) -> 2.78 | T38: 0 | U38: 41 | V38: =V37-U38 -> 4856.01 | W38: =N38+R38+T38+U38 -> 43.78 | X38: =IF(L38<0,L38*-1,0) -> 32.349468 | Y38: =W38+X38 -> 76.129468 | Z38: 0 | AA38: 54 | AB38: 18 | AC38: =AC37+1 -> 29 | AD38: 862 | AE38: 2872 | AF38: 256.51
A39: 30 | B39: 6913.55 | C39: 336381 | D39: =C39-C38 -> 164 | E39: =C39-152000 -> 184381 | F39: =D39/$D$2 -> 82.682128 | G39: 98 | H39: 3.8 | I39: =G39+H39 -> 101.8 | J39: =IF(L39>0,L39,0) -> 25.032128 | K39: =I39+J39 -> 126.83213 | L39: =F39-(I39-W39) -> 25.032128 | M39: 3.15 | N39: 0 | O39: =M39-N39 -> 3.15 | P39: 0 | Q39: 0 | R39: =SUM(O39:Q39) -> 3.15 | T39: 0 | U39: 41 | V39: =V38-U39 -> 4815.01 | W39: =N39+R39+T39+U39 -> 44.15 | X39: =IF(L39<0,L39*-1,0) -> 0 | Y39: =W39+X39 -> 44.15 | Z39: 0 | AA39: 51 | AB39: 22 | AC39: 30 | AD39: 927 | AE39: 2965 | AF39: 248.45
A41: MONTH / CFS | F41: =SUM(F10:F39) -> 1447.4414 | G41: =SUM(G10:G39) -> 3641 | H41: =SUM(H10:H39) -> 134 | I41: =SUM(I10:I39) -> 3771.3 | J41: =SUM(J10:J39) -> 312.86244 | K41: =SUM(K10:K39) -> 4084.1624 | L41: =SUM(L10:L39) -> -195.42861 | M41: =SUM(M10:M39) -> 649.24 | ... R41: =SUM(R10:R39) -> 538.19 | T41: =SUM(T10:T39) -> 0 | U41: =SUM(U10:U39) -> 1332.99 | W41: =SUM(W10:W39) -> 2128.43 | X41: =SUM(X10:X39) -> 508.29104 | Y41: =SUM(Y10:Y39) -> 2636.721 | Z41: =SUM(Z10:Z39) -> 1.09 | AA41: =AVERAGE(AA10:AA39) -> 50.7 | AB41: =AVERAGE(AB10:AB39) -> 26.066667
A42: MONTH / AF | D42: =SUM(D10:D39) -> 2871 | F42: =F41*$D$2 -> 2871 | G42: =G41*$D$2 -> 7221.9235 | H42: =H41*$D$2 -> 265.789 | I42: =I41*$D$2 -> 7480.3736 | J42: =J41*$D$2 -> 620.56264 | K42: =K41*$D$2 -> 8100.9362 | L42: =L41*$D$2 -> -387.63265 | M42: =M41*$D$2 -> 1287.7675 | ... R42: =R41*$D$2 -> 1067.4999 | T42: =T41*$D$2 -> 0 | U42: =U41*$D$2 -> 2643.9857 | W42: =W41*$D$2 -> 4221.7409 | X42: =X41*$D$2 -> 1008.1953 | Y42: =Y41*$D$2 -> 5229.9362 | AA42: =MAX(AA10:AA39) -> 67 | AB42: =MAX(AB10:AB39) -> 38 | AC42: HI
A44: SEASON / CFS | AA44: =MIN(AA10:AA39) -> 36 | AB44: =MIN(AB10:AB39) -> 12 | AC44: LO
A45: SEASON / AF
...

Sheet DEC
K1: MC PHEE RESERVOIR IN/OUT FLOW TABULATION
A2: AF/cfs CONVERT FACTOR | D2: 1.9835 | K2: DECEMBER "97"
A4: DATE | B4: RESERV | C4: RESERV | D4: AC FT | E4: ACTIVE | F4: CONV TO | G4: DOLORES | H4: LOST | I4: RECORDED | J4: CALC | K4: TOTAL | L4: CALC | M4: DOLORES TUNNEL | P4: LONE | Q4: U | R4: TOTAL | S4: MVI | T4: DV CR | U4: BELOW | V4: REMAIN | W4: RECORDED | X4: CALC | Y4: TOTAL | Z4: RAIN | AA4: MAX | AB4: MIN | AC4: DATE
A5: "DEC" | B5: ELEV | C5: AC FT | D5: CHANGE | E5: CAP | F5: CFS | G5: RIVER | H5: CANYON | I5: INFLOW | J5: INFLOW | K5: INFLOW | L5: INF/OTF | M5: TOT DIV | N5: UTE F&R | O5: MVI,CTZ | P5: PINE | Q5: LATERAL | R5: MVI | S5: CALL | T5: CANAL | U5: MC PHEE | V5: RELEASE | W5: OUTFLOW | X5: OUTFLOW | Y5: OUTFLOW | AA5: TMP | AB5: TMP | AC5: "DEC"
AD6: 741 | AE6: 742
A7: SEASON BAL
A8: YTD | B8: {=NOV!$B$39:$C$39} -> 6913.55 | C8: 336381 | D8: {=NOV!$D$48:$E$48} -> 2871 | E8: 184381 | F8: {=NOV!$F$47:$Z$47} -> 1447.4414 | G8: 3641 | H8: 134 | I8: 3771.3 | J8: 312.86244 | K8: 4084.1624 | L8: -195.42861 | M8: 649.24 | N8: 0 | O8: 0 | P8: 0 | Q8: 146.2 | R8: 538.19 | S8: 0 | T8: 0 | U8: 1332.99 | V8: 4815.01 | W8: 2128.43 | X8: 508.29104 | Y8: 2636.721 | Z8: 1.09 | AD8: 285 | AE8: 251 | AF8: 1207.63
A10: 1 | B10: 6913.61 | C10: 336628 | D10: =C10-C8 -> 247 | E10: =C10-152000 -> 184628 | F10: =D10/$D$2 -> 124.52735 | G10: 105 | H10: 3.8 | I10: =G10+H10 -> 108.8 | J10: =IF(L10>0,L10,0) -> 60.227351 | K10: =I10+J10 -> 169.02735 | L10: =F10-(I10-W10) -> 60.227351 | M10: 3.5 | N10: 0 | O10: =M10-N10 -> 3.5 | P10: 0 | Q10: 0 | R10: =SUM(O10:Q10) -> 3.5 | T10: 0 | U10: 41 | V10: =V8-U10 -> 4774.01 | W10: =R10+T10+N10+U10 -> 44.5 | X10: =IF(L10<0,L10*-1,0) -> 0 | Y10: =W10+X10 -> 44.5 | Z10: 0 | AA10: 45 | AB10: 33 | AC10: 1 | AD10: 303 | AE10: 273 | AF10: 1256.86
A11: =A10+1 -> 2 | B11: 6913.63 | C11: 336710 | D11: =C11-C10 -> 82 | E11: =C11-152000 -> 184710 | F11: =D11/$D$2 -> 41.341064 | G11: 104 | H11: 3.8 | I11: =G11+H11 -> 107.8 | J11: =IF(L11>0,L11,0) -> 0 | K11: =I11+J11 -> 107.8 | L11: =F11-(I11-W11) -> -22.358936 | M11: 3.1 | N11: 0 | O11: =M11-N11 -> 3.1 | P11: 0 | Q11: 0 | R11: =SUM(O11:Q11) -> 3.1 | T11: 0 | U11: 41 | V11: =V10-U11 -> 4733.01 | W11: =R11+T11+N11+U11 -> 44.1 | X11: =IF(L11<0,L11*-1,0) -> 22.358936 | Y11: =W11+X11 -> 66.458936 | Z11: 0 | AA11: 43 | AB11: 21 | AC11: =AC10+1 -> 2 | AD11: 306 | AE11: 300 | AF11: 1306.42
A12: =A11+1 -> 3 | B12: 6913.65 | C12: 336792 | D12: =C12-C11 -> 82 | E12: =C12-152000 -> 184792 | F12: =D12/$D$2 -> 41.341064 | G12: 103 | H12: 3.7 | I12: =G12+H12 -> 106.7 | J12: =IF(L12>0,L12,0) -> 0 | K12: =I12+J12 -> 106.7 | L12: =F12-(I12-W12) -> -21.278936 | M12: 3.08 | N12: 0 | O12: =M12-N12 -> 3.08 | P12: 0 | Q12: 0 | R12: =SUM(O12:Q12) -> 3.08 | T12: 0 | U12: 41 | V12: =V11-U12 -> 4692.01 | W12: =R12+T12+N12+U12 -> 44.08 | X12: =IF(L12<0,L12*-1,0) -> 21.278936 | Y12: =W12+X12 -> 65.358936 | Z12: 0 | AA12: 34 | AB12: 22 | AC12: =AC11+1 -> 3 | AD12: 316 | AE12: 341 | AF12: 1355.74
A13: =A12+1 -> 4 | B13: 6913.66 | C13: 336833 | D13: =C13-C12 -> 41 | E13: =C13-152000 -> 184833 | F13: =D13/$D$2 -> 20.670532 | G13: 82 | H13: 3.2 | I13: =G13+H13 -> 85.2 | J13: =IF(L13>0,L13,0) -> 0 | K13: =I13+J13 -> 85.2 | L13: =F13-(I13-W13) -> -20.449468 | M13: 3.08 | N13: 0 | O13: =M13-N13 -> 3.08 | P13: 0 | Q13: 0 | R13: =SUM(O13:Q13) -> 3.08 | T13: 0 | U13: 41 | V13: =V12-U13 -> 4651.01 | W13: =R13+T13+N13+U13 -> 44.08 | X13: =IF(L13<0,L13*-1,0) -> 20.449468 | Y13: =W13+X13 -> 64.529468 | Z13: 0 | AA13: 46 | AB13: 12 | AC13: =AC12+1 -> 4 | AD13: 316 | AE13: 395 | AF13: 1405.31
A14: =A13+1 -> 5 | B14: 6913.66 | C14: 336833 | D14: =C14-C13 -> 0 | E14: =C14-152000 -> 184833 | F14: =D14/$D$2 -> 0 | G14: 98 | H14: 3.2 | I14: =G14+H14 -> 101.2 | J14: =IF(L14>0,L14,0) -> 0 | K14: =I14+J14 -> 101.2 | L14: =F14-(I14-W14) -> -57.12 | M14: 3.08 | N14: 0 | O14: =M14-N14 -> 3.08 | P14: 0 | Q14: 0 | R14: =SUM(O14:Q14) -> 3.08 | T14: 0 | U14: 41 | V14: =V13-U14 -> 4610.01 | W14: =R14+T14+N14+U14 -> 44.08 | X14: =IF(L14<0,L14*-1,0) -> 57.12 | Y14: =W14+X14 -> 101.2 | Z14: 0 | AA14: 43 | AB14: 12 | AC14: =AC13+1 -> 5 | AD14: 316 | AE14: 466 | AF14: 1437.16
A15: =A14+1 -> 6 | B15: 6913.68 | C15: 336916 | D15: =C15-C14 -> 83 | E15: =C15-152000 -> 184916 | F15: =D15/$D$2 -> 41.845223 | G15: 95 | H15: 3.2 | I15: =G15 -> 95 | J15: =IF(L15>0,L15,0) -> 0 | K15: =I15+J15 -> 95 | L15: =F15-(I15-W15) -> -9.0747769 | M15: 3.08 | N15: 0 | O15: =M15-N15 -> 3.08 | P15: 0 | Q15: 0 | R15: =SUM(O15:Q15) -> 3.08 | T15: 0 | U15: 41 | V15: =V14-U15 -> 4569.01 | W15: =R15+T15+N15+U15 -> 44.08 | X15: =IF(L15<0,L15*-1,0) -> 9.0747769 | Y15: =W15+X15 -> 53.154777 | Z15: 0.11 | AA15: 48 | AB15: 10 | AC15: =AC14+1 -> 6 | AD15: 325 | AE15: 538 | AF15: 1467.01
A16: =A15+1 -> 7 | B16: 6913.73 | C16: 337121 | D16: =C16-C15 -> 205 | E16: =C16-152000 -> 185121 | F16: =D16/$D$2 -> 103.35266 | G16: 100 | H16: 3.2 | I16: =G16+H16 -> 103.2 | J16: =IF(L16>0,L16,0) -> 44.232659 | K16: =I16+J16 -> 147.43266 | L16: =F16-(I16-W16) -> 44.232659 | M16: 3.08 | N16: 0 | O16: =M16-N16 -> 3.08 | P16: 0 | Q16: 0 | R16: =SUM(O16:Q16) -> 3.08 | T16: 0 | U16: 41 | V16: =V15-U16 -> 4528.01 | W16: =R16+T16+N16+U16 -> 44.08 | X16: =IF(L16<0,L16*-1,0) -> 0 | Y16: =W16+X16 -> 44.08 | Z16: 0.56 | AA16: 37 | AB16: 28 | AC16: =AC15+1 -> 7 | AD16: 342 | AE16: 618 | AF16: 1496.64
A17: =A16+1 -> 8 | B17: 6913.78 | C17: 337327 | D17: =C17-C16 -> 206 | E17: =C17-152000 -> 185327 | F17: =D17/$D$2 -> 103.85682 | G17: 95 | H17: 3.3 | I17: =G17+H17 -> 98.3 | J17: =IF(L17>0,L17,0) -> 49.636819 | K17: =I17+J17 -> 147.93682 | L17: =F17-(I17-W17) -> 49.636819 | M17: 3.08 | N17: 0 | O17: =M17-N17 -> 3.08 | P17: 0 | Q17: 0 | R17: =SUM(O17:Q17) -> 3.08 | T17: 0 | U17: 41 | V17: =V16-U17 -> 4487.01 | W17: =R17+T17+N17+U17 -> 44.08 | X17: =IF(L17<0,L17*-1,0) -> 0 | Y17: =W17+X17 -> 44.08 | Z17: 0.16 | AA17: 35 | AB17: 30 | AC17: =AC16+1 -> 8 | AD17: 367 | AE17: 704 | AF17: 1526.51
A18: =A17+1 -> 9 | B18: 6913.8 | C18: 337409 | D18: =C18-C17 -> 82 | E18: =C18-152000 -> 185409 | F18: =D18/$D$2 -> 41.341064 | G18: 90 | H18: 3.5 | I18: =G18+H18 -> 93.5 | J18: =IF(L18>0,L18,0) -> 0 | K18: =I18+J18 -> 93.5 | L18: =F18-(I18-W18) -> -2.0789362 | M18: 3.08 | N18: 0 | O18: =M18-N18 -> 3.08 | P18: 0 | Q18: 0 | R18: =SUM(O18:Q18) -> 3.08 | T18: 0 | U18: 47 | V18: =V17-U18 -> 4440.01 | W18: =R18+T18+N18+U18 -> 50.08 | X18: =IF(L18<0,L18*-1,0) -> 2.0789362 | Y18: =W18+X18 -> 52.158936 | Z18: 0 | AA18: 37 | AB18: 16 | AC18: =AC17+1 -> 9 | AD18: 390 | AE18: 805 | AF18: 1561.24
A19: =A18+1 -> 10 | B19: 6913.81 | C19: 337450 | D19: =C19-C18 -> 41 | E19: =C19-152000 -> 185450 | F19: =D19/$D$2 -> 20.670532 | G19: 82 | H19: 3.7 | I19: =G19+H19 -> 85.7 | J19: =IF(L19>0,L19,0) -> 0 | K19: =I19+J19 -> 85.7 | L19: =F19-(I19-W19) -> -7.9494681 | M19: 3.08 | N19: 0 | O19: =M19-N19 -> 3.08 | P19: 0 | Q19: 0 | R19: =SUM(O19:Q19) -> 3.08 | T19: 0 | U19: 54 | V19: =V18-U19 -> 4386.01 | W19: =R19+T19+N19+U19 -> 57.08 | X19: =IF(L19<0,L19*-1,0) -> 7.9494681 | Y19: =W19+X19 -> 65.029468 | Z19: 0 | AA19: 25 | AB19: 17 | AC19: =AC18+1 -> 10 | AD19: 437 | AE19: 920 | AF19: 1600.39
A20: =A19+1 -> 11 | B20: 6913.82 | C20: 337491 | D20: =C20-C19 -> 41 | E20: =C20-152000 -> 185491 | F20: =D20/$D$2 -> 20.670532 | G20: 70 | H20: 3.9 | I20: =G20+H20 -> 73.9 | J20: =IF(L20>0,L20,0) -> 3.7705319 | K20: =I20+J20 -> 77.670532 | L20: =F20-(I20-W20) -> 3.7705319 | M20: 3 | N20: 0 | O20: =M20-N20 -> 3 | P20: 0 | Q20: 0 | R20: =SUM(O20:Q20) -> 3 | T20: 0 | U20: 54 | V20: =V19-U20 -> 4332.01 | W20: =R20+T20+N20+U20 -> 57 | X20: =IF(L20<0,L20*-1,0) -> 0 | Y20: =W20+X20 -> 57 | Z20: 0 | AA20: 32 | AB20: 12 | AC20: =AC19+1 -> 11 | AD20: 498 | AE20: 1048 | AF20: 1642
A21: =A20+1 -> 12 | B21: 6913.82 | C21: 337491 | D21: =C21-C20 -> 0 | E21: =C21-152000 -> 185491 | F21: =D21/$D$2 -> 0 | G21: 66 | H21: 4.2 | I21: =G21+H21 -> 70.2 | J21: =IF(L21>0,L21,0) -> 0 | K21: =I21+J21 -> 70.2 | L21: =F21-(I21-W21) -> -13.42 | M21: 2.78 | N21: 0 | O21: =M21-N21 -> 2.78 | P21: 0 | Q21: 0 | R21: =SUM(O21:Q21) -> 2.78 | T21: 0 | U21: 54 | V21: =V20-U21 -> 4278.01 | W21: =R21+T21+N21+U21 -> 56.78 | X21: =IF(L21<0,L21*-1,0) -> 13.42 | Y21: =W21+X21 -> 70.2 | Z21: 0 | AA21: 44 | AB21: 4 | AC21: =AC20+1 -> 12 | AD21: 572 | AE21: 1182 | AF21: 1683.42
A22: =A21+1 -> 13 | B22: 6913.83 | C22: 337532 | D22: =C22-C21 -> 41 | E22: =C22-152000 -> 185532 | F22: =D22/$D$2 -> 20.670532 | G22: 80 | H22: 4.4 | I22: =G22+H22 -> 84.4 | J22: =IF(L22>0,L22,0) -> 0 | K22: =I22+J22 -> 84.4 | L22: =F22-(I22-W22) -> -5.9494681 | M22: 2.78 | N22: 0 | O22: =M22-N22 -> 2.78 | P22: 0 | Q22: 0 | R22: =SUM(O22:Q22) -> 2.78 | T22: 0 | U22: 55 | V22: =V21-U22 -> 4223.01 | W22: =R22+T22+N22+U22 -> 57.78 | X22: =IF(L22<0,L22*-1,0) -> 5.9494681 | Y22: =W22+X22 -> 63.729468 | Z22: 0 | AA22: 47 | AB22: 7 | AC22: =AC21+1 -> 13 | AD22: 716 | AE22: 1339 | AF22: 1725.1
A23: =A22+1 -> 14 | B23: 6913.83 | C23: 337532 | D23: =C23-C22 -> 0 | E23: =C23-152000 -> 185532 | F23: =D23/$D$2 -> 0 | G23: 86 | H23: 4.6 | I23: =G23+H23 -> 90.6 | J23: =IF(L23>0,L23,0) -> 0 | K23: =I23+J23 -> 90.6 | L23: =F23-(I23-W23) -> -29.57 | M23: 3 | N23: 0 | O23: =M23-N23 -> 3 | P23: 0 | Q23: 0 | R23: =SUM(O23:Q23) -> 3 | T23: 0 | U23: 58.03 | V23: =V22-U23 -> 4164.98 | W23: =R23+T23+N23+U23 -> 61.03 | X23: =IF(L23<0,L23*-1,0) -> 29.57 | Y23: =W23+X23 -> 90.6 | Z23: 0 | AA23: 51 | AB23: 9 | AC23: =AC22+1 -> 14 | AD23: 901 | AE23: 1500 | AF23: 1766.22
A24: =A23+1 -> 15 | B24: 6913.84 | C24: 337573 | D24: =C24-C23 -> 41 | E24: =C24-152000 -> 185573 | F24: =D24/$D$2 -> 20.670532 | G24: 86 | H24: 4.9 | I24: =G24+H24 -> 90.9 | J24: =IF(L24>0,L24,0) -> 0 | K24: =I24+J24 -> 90.9 | L24: =F24-(I24-W24) -> -12.839468 | M24: 3.39 | N24: 0 | O24: =M24-N24 -> 3.39 | P24: 0 | Q24: 0 | R24: =SUM(O24:Q24) -> 3.39 | T24: 0 | U24: 54 | V24: =V23-U24 -> 4110.98 | W24: =R24+T24+N24+U24 -> 57.39 | X24: =IF(L24<0,L24*-1,0) -> 12.839468 | Y24: =W24+X24 -> 70.229468 | Z24: 0 | AA24: 49 | AB24: 19 | AC24: =AC23+1 -> 15 | AD24: 1075 | AE24: 1662 | AF24: 1807.54
A25: =A24+1 -> 16 | B25: 6913.85 | C25: 337614 | D25: =C25-C24 -> 41 | E25: =C25-152000 -> 185614 | F25: =D25/$D$2 -> 20.670532 | G25: 82 | H25: 4.6 | I25: =G25+H25 -> 86.6 | J25: =IF(L25>0,L25,0) -> 0 | K25: 78.2 | L25: =F25-(I25-W25) -> -8.5394681 | M25: 3.39 | N25: 0 | O25: =M25-N25 -> 3.39 | P25: 0 | Q25: 0 | R25: =SUM(O25:Q25) -> 3.39 | T25: 0 | U25: 54 | V25: =V24-U25 -> 4056.98 | W25: =R25+T25+N25+U25 -> 57.39 | X25: =IF(L25<0,L25*-1,0) -> 8.5394681 | Y25: =W25+X25 -> 65.929468 | Z25: 0 | AA25: 47 | AB25: 12 | AC25: =AC24+1 -> 16 | AD25: 1313 | AE25: 1828 | AF25: 1858.73
A26: =A25+1 -> 17 | B26: 6913.86 | C26: 337655 | D26: =C26-C25 -> 41 | E26: =C26-152000 -> 185655 | F26: =D26/$D$2 -> 20.670532 | G26: 85 | H26: 4.7 | I26: =G26+H26 -> 89.7 | J26: =IF(L26>0,L26,0) -> 0 | K26: =I26+J26 -> 89.7 | L26: =F26-(I26-W26) -> -11.639468 | M26: 3.39 | N26: 0 | O26: =M26-N26 -> 3.39 | P26: 0 | Q26: 0 | R26: =SUM(O26:Q26) -> 3.39 | T26: 0 | U26: 54 | V26: =V25-U26 -> 4002.98 | W26: =R26+T26+N26+U26 -> 57.39 | X26: =IF(L26<0,L26*-1,0) -> 11.639468 | Y26: =W26+X26 -> 69.029468 | Z26: 0 | AA26: 48 | AB26: 20 | AC26: =AC25+1 -> 17 | AD26: 1559 | AE26: 1968 | AF26: 1921.09
A27: =A26+1 -> 18 | B27: 6913.87 | C27: 337696 | D27: =C27-C26 -> 41 | E27: =C27-152000 -> 185696 | F27: =D27/$D$2 -> 20.670532 | G27: 85 | H27: 4.9 | I27: =G27+H27 -> 89.9 | J27: =IF(L27>0,L27,0) -> 0 | K27: =I27+J27 -> 89.9 | L27: =F27-(I27-W27) -> -11.839468 | M27: 3.39 | N27: 0 | O27: =M27-N27 -> 3.39 | P27: 0 | Q27: 0 | R27: =SUM(O27:Q27) -> 3.39 | T27: 0 | U27: 54 | V27: =V26-U27 -> 3948.98 | W27: =R27+T27+N27+U27 -> 57.39 | X27: =IF(L27<0,L27*-1,0) -> 11.839468 | Y27: =W27+X27 -> 69.229468 | Z27: 0 | AA27: 51 | AB27: 10 | AC27: =AC26+1 -> 18 | AD27: 1867 | AE27: 2133 | AF27: 1990.83
A28: =A27+1 -> 19 | B28: 6913.88 | C28: 337737 | D28: =C28-C27 -> 41 | E28: =C28-152000 -> 185737 | F28: =D28/$D$2 -> 20.670532 | G28: 80 | H28: 4.3 | I28: =G28+H28 -> 84.3 | J28: =IF(L28>0,L28,0) -> 0 | K28: =I28+J28 -> 84.3 | L28: =F28-(I28-W28) -> -6.2394681 | M28: 3.39 | N28: 0 | O28: =M28-N28 -> 3.39 | P28: 0 | Q28: 0 | R28: =SUM(O28:Q28) -> 3.39 | T28: 0 | U28: 54 | V28: =V27-U28 -> 3894.98 | W28: =R28+T28+N28+U28 -> 57.39 | X28: =IF(L28<0,L28*-1,0) -> 6.2394681 | Y28: =W28+X28 -> 63.629468 | Z28: 0 | AA28: 51 | AB28: 21 | AC28: =AC27+1 -> 19 | AD28: 2157 | AE28: 2304 | AF28: 2064.09
A29: =A28+1 -> 20 | B29: 6913.88 | C29: 337737 | D29: =C29-C28 -> 0 | E29: =C29-152000 -> 185737 | F29: =D29/$D$2 -> 0 | G29: 80 | H29: 4.2 | I29: =G29+H29 -> 84.2 | J29: =IF(L29>0,L29,0) -> 0 | K29: =I29+J29 -> 84.2 | L29: =F29-(I29-W29) -> -26.83 | M29: 3.39 | N29: 0 | O29: =M29-N29 -> 3.39 | P29: 0 | Q29: 0 | R29: =SUM(O29:Q29) -> 3.39 | T29: 0 | U29: 53.98 | V29: =V28-U29 -> 3841 | W29: =R29+T29+N29+U29 -> 57.37 | X29: =IF(L29<0,L29*-1,0) -> 26.83 | Y29: =W29+X29 -> 84.2 | Z29: 0 | AA29: 44 | AB29: 21 | AC29: =AC28+1 -> 20 | AD29: 2443 | AE29: 2474 | AF29: 2135.47
A30: =A29+1 -> 21 | B30: 6913.89 | C30: 337779 | D30: =C30-C29 -> 42 | E30: =C30-152000 -> 185779 | F30: =D30/$D$2 -> 21.174691 | G30: 80 | H30: 4.4 | I30: =G30+H30 -> 84.4 | J30: =IF(L30>0,L30,0) -> 0 | K30: =I30+J30 -> 84.4 | L30: =F30-(I30-W30) -> -5.8353088 | M30: 3.39 | N30: 0 | O30: =M30-N30 -> 3.39 | P30: 0 | Q30: 0 | R30: =SUM(O30:Q30) -> 3.39 | T30: 0 | U30: 54 | V30: =V29-U30 -> 3787 | W30: =R30+T30+N30+U30 -> 57.39 | X30: =IF(L30<0,L30*-1,0) -> 5.8353088 | Y30: =W30+X30 -> 63.225309 | Z30: 0 | AA30: 32 | AB30: 19 | AC30: =AC29+1 -> 21 | AD30: 2760 | AE30: 2645 | AF30: 2202.37
A31: =A30+1 -> 22 | B31: 6913.9 | C31: 337820 | D31: =C31-C30 -> 41 | E31: =C31-152000 -> 185820 | F31: =D31/$D$2 -> 20.670532 | G31: 85 | H31: 4.6 | I31: =G31+H31 -> 89.6 | J31: =IF(L31>0,L31,0) -> 0 | K31: =I31+J31 -> 89.6 | L31: =F31-(I31-W31) -> -18.539468 | M31: 3.39 | N31: 0 | O31: =M31-N31 -> 3.39 | P31: 0 | Q31: 0 | R31: =SUM(O31:Q31) -> 3.39 | T31: 0 | U31: 47 | V31: =V30-U31 -> 3740 | W31: =R31+T31+N31+U31 -> 50.39 | X31: =IF(L31<0,L31*-1,0) -> 18.539468 | Y31: =W31+X31 -> 68.929468 | Z31: 0 | AA31: 42 | AB31: 8 | AC31: =AC30+1 -> 22 | AD31: 3077 | AE31: 2820 | AF31: 2257.56
A32: =A31+1 -> 23 | B32: 6913.91 | C32: 337861 | D32: =C32-C31 -> 41 | E32: =C32-152000 -> 185861 | F32: =D32/$D$2 -> 20.670532 | G32: 82 | H32: 4.6 | I32: =G32+H32 -> 86.6 | J32: =IF(L32>0,L32,0) -> 0 | K32: =I32+J32 -> 86.6 | L32: =F32-(I32-W32) -> -20.579468 | M32: 3.39 | N32: 0 | O32: =M32-N32 -> 3.39 | P32: 0 | Q32: 0 | R32: =SUM(O32:Q32) -> 3.39 | T32: 0 | U32: 41.96 | V32: =V31-U32 -> 3698.04 | W32: =R32+T32+N32+U32 -> 45.35 | X32: =IF(L32<0,L32*-1,0) -> 20.579468 | Y32: =W32+X32 -> 65.929468 | Z32: 0 | AA32: 40 | AB32: 8 | AC32: =AC31+1 -> 23 | AD32: 3431 | AE32: 2986 | AF32: 2305.82
A33: =A32+1 -> 24 | B33: 6913.93 | C33: 337943 | D33: =C33-C32 -> 82 | E33: =C33-152000 -> 185943 | F33: =D33/$D$2 -> 41.341064 | G33: 78 | H33: 4.5 | I33: =G33+H33 -> 82.5 | J33: =IF(L33>0,L33,0) -> 3.2310638 | K33: =I33+J33 -> 85.731064 | L33: =F33-(I33-W33) -> 3.2310638 | M33: 3.39 | N33: 0 | O33: =M33-N33 -> 3.39 | P33: 0 | Q33: 0 | R33: =SUM(O33:Q33) -> 3.39 | T33: 0 | U33: 41 | V33: =V32-U33 -> 3657.04 | W33: =R33+T33+N33+U33 -> 44.39 | X33: =IF(L33<0,L33*-1,0) -> 0 | Y33: =W33+X33 -> 44.39 | Z33: 0.04 | AA33: 31 | AB33: 14 | AC33: =AC32+1 -> 24 | AD33: 3778 | AE33: 3159 | AF33: 2351.3
A34: =A33+1 -> 25 | B34: 6913.97 | C34: 338107 | D34: =C34-C33 -> 164 | E34: =C34-152000 -> 186107 | F34: =D34/$D$2 -> 82.682128 | G34: 70 | H34: 4.4 | I34: =G34+H34 -> 74.4 | J34: =IF(L34>0,L34,0) -> 52.672128 | K34: =I34+J34 -> 127.07213 | L34: =F34-(I34-W34) -> 52.672128 | M34: 3.39 | N34: 0 | O34: =M34-N34 -> 3.39 | P34: 0 | Q34: 0 | R34: =SUM(O34:Q34) -> 3.39 | T34: 0 | U34: 41 | V34: =V33-U34 -> 3616.04 | W34: =R34+T34+N34+U34 -> 44.39 | X34: =IF(L34<0,L34*-1,0) -> 0 | Y34: =W34+X34 -> 44.39 | Z34: 0.03 | AA34: 29 | AB34: 8 | AC34: =AC33+1 -> 25 | AD34: 4048 | AE34: 3332 | AF34: 2362.83
A35: =A34+1 -> 26 | B35: 6914.01 | C35: 338272 | D35: =C35-C34 -> 165 | E35: =C35-152000 -> 186272 | F35: =D35/$D$2 -> 83.186287 | G35: 60 | H35: 3.3 | I35: =G35+H35 -> 63.3 | J35: =IF(L35>0,L35,0) -> 64.276287 | K35: =I35+J35 -> 127.57629 | L35: =F35-(I35-W35) -> 64.276287 | M35: 3.39 | N35: 0 | O35: =M35-N35 -> 3.39 | P35: 0 | Q35: 0 | R35: =SUM(O35:Q35) -> 3.39 | T35: 0 | U35: 41 | V35: =V34-U35 -> 3575.04 | W35: =R35+T35+N35+U35 -> 44.39 | X35: =IF(L35<0,L35*-1,0) -> 0 | Y35: =W35+X35 -> 44.39 | Z35: 0 | AA35: 34 | AB35: 2 | AC35: =AC34+1 -> 26 | AD35: 4274 | AE35: 3506 | AF35: 2362.83
A36: =A35+1 -> 27 | B36: 6914.03 | C36: 338355 | D36: =C36-C35 -> 83 | E36: =C36-152000 -> 186355 | F36: =D36/$D$2 -> 41.845223 | G36: 62 | H36: 3.4 | I36: =G36+H36 -> 65.4 | J36: =IF(L36>0,L36,0) -> 22.295223 | K36: =I36+J36 -> 87.695223 | L36: =F36-(I36-W36) -> 22.295223 | M36: 4.85 | N36: 0 | O36: =M36-N36 -> 4.85 | P36: 0 | Q36: 0 | R36: =SUM(O36:Q36) -> 4.85 | T36: 0 | U36: 41 | V36: =V35-U36 -> 3534.04 | W36: =R36+T36+N36+U36 -> 45.85 | X36: =IF(L36<0,L36*-1,0) -> 0 | Y36: =W36+X36 -> 45.85 | Z36: 0 | AA36: 32 | AB36: 2 | AC36: =AC35+1 -> 27 | AD36: 4501 | AE36: 3671 | AF36: 2362.83
A37: =A36+1 -> 28 | B37: 6914.04 | C37: 338396 | D37: =C37-C36 -> 41 | E37: =C37-152000 -> 186396 | F37: =D37/$D$2 -> 20.670532 | G37: 64 | H37: 3.5 | I37: =G37+H37 -> 67.5 | J37: =IF(L37>0,L37,0) -> 0.46053189 | K37: =I37+J37 -> 67.960532 | L37: =F37-(I37-W37) -> 0.46053189 | M37: 6.29 | N37: 0 | O37: =M37-N37 -> 6.29 | P37: 0 | Q37: 0 | R37: =SUM(O37:Q37) -> 6.29 | T37: 0 | U37: 41 | V37: =V36-U37 -> 3493.04 | W37: =R37+T37+N37+U37 -> 47.29 | X37: =IF(L37<0,L37*-1,0) -> 0 | Y37: =W37+X37 -> 47.29 | Z37: 0 | AA37: 38 | AB37: 8 | AC37: =AC36+1 -> 28 | AD37: 4723 | AE37: 3836 | AF37: 2362.83
A38: =A37+1 -> 29 | B38: 6914.06 | C38: 338479 | D38: =C38-C37 -> 83 | E38: =C38-152000 -> 186479 | F38: =D38/$D$2 -> 41.845223 | G38: 70 | H38: 3.8 | I38: =G38+H38 -> 73.8 | J38: =IF(L38>0,L38,0) -> 15.335223 | K38: =I38+J38 -> 89.135223 | L38: =F38-(I38-W38) -> 15.335223 | M38: 6.29 | N38: 0 | O38: =M38-N38 -> 6.29 | P38: 0 | Q38: 0 | R38: =SUM(O38:Q38) -> 6.29 | T38: 0 | U38: 41 | V38: =V37-U38 -> 3452.04 | W38: =R38+T38+N38+U38 -> 47.29 | X38: =IF(L38<0,L38*-1,0) -> 0 | Y38: =W38+X38 -> 47.29 | Z38: 0 | AA38: 48 | AB38: 10 | AC38: =AC37+1 -> 29 | AD38: 4963 | AE38: 4000 | AF38: 2362.83
A39: 30 | B39: 6914.08 | C39: 338562 | D39: =C39-C38 -> 83 | E39: =C39-152000 -> 186562 | F39: =D39/$D$2 -> 41.845223 | G39: 72 | H39: 4.1 | I39: =G39+H39 -> 76.1 | J39: =IF(L39>0,L39,0) -> 13.035223 | K39: =I39+J39 -> 89.135223 | L39: =F39-(I39-W39) -> 13.035223 | M39: 6.29 | N39: 0 | O39: =M39-N39 -> 6.29 | P39: 0 | Q39: 0 | R39: =SUM(O39:Q39) -> 6.29 | T39: 0 | U39: 41 | V39: =V38-U39 -> 3411.04 | W39: =R39+T39+N39+U39 -> 47.29 | X39: =IF(L39<0,L39*-1,0) -> 0 | Y39: =W39+X39 -> 47.29 | Z39: 0 | AA39: 50 | AB39: 12 | AC39: 30 | AD39: 5210 | AE39: 4166 | AF39: 2362.83
A40: 31 | B40: 6914.09 | C40: 338603 | D40: =C40-C39 -> 41 | E40: =C40-152000 -> 186603 | F40: =D40/$D$2 -> 20.670532 | G40: 75 | H40: 4.3 | I40: =G40+H40 -> 79.3 | J40: =IF(L40>0,L40,0) -> 0 | K40: =I40+J40 -> 79.3 | L40: =F40-(I40-W40) -> -11.339468 | M40: 6.29 | N40: 0 | O40: =M40-N40 -> 6.29 | P40: 0 | Q40: 0 | R40: =SUM(O40:Q40) -> 6.29 | T40: 0 | U40: 41 | V40: =V39-U40 -> 3370.04 | W40: =R40+T40+N40+U40 -> 47.29 | X40: =IF(L40<0,L40*-1,0) -> 11.339468 | Y40: =W40+X40 -> 58.629468 | Z40: 0 | AA40: 50 | AB40: 12 | AC40: 31 | AD40: 5455 | AE40: 4334 | AF40: 2403.37
A42: MONTH / CFS | F42: =SUM(F10:F40) -> 1120.242 | G42: =SUM(G10:G40) -> 2552 | H42: =SUM(H10:H40) -> 124.2 | I42: =SUM(I10:I40) -> 2673 | J42: =SUM(J10:J40) -> 329.17304 | K42: =SUM(K10:K40) -> 2993.773 | L42: =SUM(L10:L40) -> 5.7019965 | M42: =SUM(M10:M40) -> 113.49 | ... R42: =SUM(R10:R40) -> 113.49 | T42: =SUM(T10:T40) -> 0 | U42: =SUM(U10:U40) -> 1444.97 | V42: =V40 -> 3370.04 | W42: =SUM(W10:W40) -> 1558.46 | X42: =SUM(X10:X40) -> 323.47104 | Y42: =SUM(Y10:Y40) -> 1881.931 | Z42: =SUM(Z10:Z40) -> 0.9 | AA42: =AVERAGE(AA10:AA40) -> 41.387097 | AB42: =AVERAGE(AB10:AB40) -> 14.16129
A43: MONTH / AF | D43: =SUM(D10:D40) -> 2222 | F43: =F42*$D$2 -> 2222 | G43: =G42*$D$2 -> 5061.892 | H43: =H42*$D$2 -> 246.3507 | I43: =I42*$D$2 -> 5301.8955 | J43: =J42*$D$2 -> 652.91472 | K43: =K42*$D$2 -> 5938.1488 | L43: =L42*$D$2 -> 11.30991 | M43: =M42*$D$2 -> 225.10742 | ... R43: =R42*$D$2 -> 225.10742 | T43: =T42*$D$2 -> 0 | U43: =U42*$D$2 -> 2866.098 | V43: =V42*$D$2 -> 6684.4743 | W43: =W42*$D$2 -> 3091.2054 | X43: =X42*$D$2 -> 641.60482 | Y43: =Y42*$D$2 -> 3732.8102 | AA43: =MAX(AA10:AA40) -> 51 | AB43: =MAX(AB10:AB40) -> 33 | AC43: HI
...

Sheet JAN
K1: MC PHEE RESERVOIR IN/OUT FLOW TABULATION
A2: AF/cfs CONVERT FACTOR | D2: 1.9835 | K2: JANUARY "98"
A4: DATE | B4: RESERV | C4: RESERV | D4: AC FT | E4: ACTIVE | F4: CONV TO | G4: DOLORES | H4: LOST | I4: RECORDED | J4: CALC | K4: TOTAL | L4: CALC | M4: DOLORES TUNNEL | P4: LONE | Q4: U | R4: TOTAL | S4: MVI | T4: DV CR | U4: BELOW | V4: REMAIN | W4: RECORDED | X4: CALC | Y4: TOTAL | Z4: RAIN | AA4: MAX | AB4: MIN | AC4: DATE
A5: "JAN" | B5: ELEV | C5: AC FT | D5: CHANGE | E5: CAP | F5: CFS | G5: RIVER | H5: CANYON | I5: INFLOW | J5: INFLOW | K5: INFLOW | L5: INF/OTF | M5: TOT DIV | N5: UTE F&R | O5: MVI,CTZ | P5: PINE | Q5: LATERAL | R5: MVI | S5: CALL | T5: CANAL | U5: MC PHEE | V5: RELEASE | W5: OUTFLOW | X5: OUTFLOW | Y5: OUTFLOW | AA5: TMP | AB5: TMP | AC5: "JAN"
A7: SEASON BAL
A8: YTD | B8: {=DEC!$B$40:$C$40} -> 6914.09 | C8: 338603 | D8: {=DEC!$D$49:$E$49} -> 5093 | E8: 186603 | F8: {=DEC!$F$48:$Z$48} -> 2567.6834 | G8: 6193 | H8: 258.2 | I8: 6444.3 | J8: 642.03548 | K8: 7077.9355 | L8: -189.72661 | M8: 762.73 | N8: 0 | O8: 113.49 | P8: 0 | Q8: 146.2 | R8: 651.68 | S8: 0 | T8: 0 | U8: 2777.96 | V8: 3370.04 | W8: 3686.89 | X8: 831.76209 | Y8: 4518.6521 | Z8: 1.99
A10: 1 | B10: 6914.1 | C10: 338645 | D10: =C10-C8 -> 42 | E10: =C10-152000 -> 186645 | F10: =D10/$D$2 -> 21.174691 | G10: 80 | H10: 4.5 | I10: =G10+H10 -> 84.5 | J10: =IF(L10>0,L10,0) -> 0 | K10: =I10+J10 -> 84.5 | L10: =F10-(I10-W10) -> -16.035309 | M10: 6.29 | N10: 0 | O10: =M10-N10 -> 6.29 | P10: 0 | Q10: 0 | R10: =SUM(O10:Q10) -> 6.29 | T10: 0 | U10: 41 | V10: =V8-U10 -> 3329.04 | W10: =R10+T10+N10+U10 -> 47.29 | X10: =IF(L10<0,L10*-1,0) -> 16.035309 | Y10: =W10+X10 -> 63.325309 | Z10: 0 | AA10: 53 | AB10: 14 | AC10: 1
A11: =A10+1 -> 2 | B11: 6914.12 | C11: 338728 | D11: =C11-C10 -> 83 | E11: =C11-152000 -> 186728 | F11: =D11/$D$2 -> 41.845223 | G11: 85 | H11: 4.8 | I11: =G11+H11 -> 89.8 | J11: =IF(L11>0,L11,0) -> 0 | K11: =I11+J11 -> 89.8 | L11: =F11-(I11-W11) -> -0.66477691 | M11: 6.29 | N11: 0 | O11: =M11-N11 -> 6.29 | P11: 0 | Q11: 0 | R11: =SUM(O11:Q11) -> 6.29 | T11: 0 | U11: 41 | V11: =V10-U11 -> 3288.04 | W11: =R11+T11+N11+U11 -> 47.29 | X11: =IF(L11<0,L11*-1,0) -> 0.66477691 | Y11: =W11+X11 -> 47.954777 | Z11: 0 | AA11: 47 | AB11: 27 | AC11: =AC10+1 -> 2
A12: =A11+1 -> 3 | B12: 6914.16 | C12: 338893 | D12: =C12-C11 -> 165 | E12: =C12-152000 -> 186893 | F12: =D12/$D$2 -> 83.186287 | G12: 90 | H12: 4.8 | I12: =G12+H12 -> 94.8 | J12: =IF(L12>0,L12,0) -> 36.676287 | K12: =I12+J12 -> 131.47629 | L12: =F12-(I12-W12) -> 36.676287 | M12: 6.29 | N12: 0 | O12: =M12-N12 -> 6.29 | P12: 0 | Q12: 0 | R12: =SUM(O12:Q12) -> 6.29 | T12: 0 | U12: 42 | V12: =V11-U12 -> 3246.04 | W12: =R12+T12+N12+U12 -> 48.29 | X12: =IF(L12<0,L12*-1,0) -> 0 | Y12: =W12+X12 -> 48.29 | Z12: 0.04 | AA12: 40 | AB12: 25 | AC12: =AC11+1 -> 3
A13: =A12+1 -> 4 | B13: 6914.18 | C13: 338976 | D13: =C13-C12 -> 83 | E13: =C13-152000 -> 186976 | F13: =D13/$D$2 -> 41.845223 | G13: 80 | H13: 4.3 | I13: =G13+H13 -> 84.3 | J13: =IF(L13>0,L13,0) -> 4.8352231 | K13: =I13+J13 -> 89.135223 | L13: =F13-(I13-W13) -> 4.8352231 | M13: 6.29 | N13: 0 | O13: =M13-N13 -> 6.29 | P13: 0 | Q13: 0 | R13: =SUM(O13:Q13) -> 6.29 | T13: 0 | U13: 41 | V13: =V12-U13 -> 3205.04 | W13: =R13+T13+N13+U13 -> 47.29 | X13: =IF(L13<0,L13*-1,0) -> 0 | Y13: =W13+X13 -> 47.29 | Z13: 0.17 | AA13: 36 | AB13: 29 | AC13: =AC12+1 -> 4
A14: =A13+1 -> 5 | B14: 6914.24 | C14: 339225 | D14: =C14-C13 -> 249 | E14: =C14-152000 -> 187225 | F14: =D14/$D$2 -> 125.53567 | G14: 68 | H14: 3.9 | I14: =G14+H14 -> 71.9 | J14: =IF(L14>0,L14,0) -> 100.92567 | K14: =I14+J14 -> 172.82567 | L14: =F14-(I14-W14) -> 100.92567 | M14: 6.29 | N14: 0 | O14: =M14-N14 -> 6.29 | P14: 0 | Q14: 0 | R14: =SUM(O14:Q14) -> 6.29 | T14: 0 | U14: 41 | V14: =V13-U14 -> 3164.04 | W14: =R14+T14+N14+U14 -> 47.29 | X14: =IF(L14<0,L14*-1,0) -> 0 | Y14: =W14+X14 -> 47.29 | Z14: 0.25 | AA14: 30 | AB14: 8 | AC14: =AC13+1 -> 5
A15: =A14+1 -> 6 | B15: 6914.28 | C15: 339390 | D15: =C15-C14 -> 165 | E15: =C15-152000 -> 187390 | F15: =D15/$D$2 -> 83.186287 | G15: 60 | H15: 3.5 | I15: =G15+H15 -> 63.5 | J15: =IF(L15>0,L15,0) -> 66.976287 | K15: =I15+J15 -> 130.47629 | L15: =F15-(I15-W15) -> 66.976287 | M15: 6.29 | N15: 0 | O15: =M15-N15 -> 6.29 | P15: 0 | Q15: 0 | R15: =SUM(O15:Q15) -> 6.29 | T15: 0 | U15: 41 | V15: =V14-U15 -> 3123.04 | W15: =R15+T15+N15+U15 -> 47.29 | X15: =IF(L15<0,L15*-1,0) -> 0 | Y15: =W15+X15 -> 47.29 | Z15: 0.19 | AA15: 40 | AB15: 2 | AC15: =AC14+1 -> 6
A16: =A15+1 -> 7 | B16: 6914.31 | C16: 339515 | D16: =C16-C15 -> 125 | E16: =C16-152000 -> 187515 | F16: =D16/$D$2 -> 63.019914 | G16: 64 | H16: 3.6 | I16: =G16+H16 -> 67.6 | J16: =IF(L16>0,L16,0) -> 42.709914 | K16: =I16+J16 -> 110.30991 | L16: =F16-(I16-W16) -> 42.709914 | M16: 6.29 | N16: 0 | O16: =M16-N16 -> 6.29 | P16: 0 | Q16: 0 | R16: =SUM(O16:Q16) -> 6.29 | T16: 0 | U16: 41 | V16: =V15-U16 -> 3082.04 | W16: =R16+T16+N16+U16 -> 47.29 | X16: =IF(L16<0,L16*-1,0) -> 0 | Y16: =W16+X16 -> 47.29 | Z16: 0 | AA16: 38 | AB16: -4 | AC16: =AC15+1 -> 7
A17: =A16+1 -> 8 | B17: 6914.32 | C17: 339556 | D17: =C17-C16 -> 41 | E17: =C17-152000 -> 187556 | F17: =D17/$D$2 -> 20.670532 | G17: 66 | H17: 3.8 | I17: =G17+H17 -> 69.8 | J17: =IF(L17>0,L17,0) -> 0 | K17: =I17+J17 -> 69.8 | L17: =F17-(I17-W17) -> -1.8394681 | M17: 6.29 | N17: 0 | O17: =M17-N17 -> 6.29 | P17: 0 | Q17: 0 | R17: =SUM(O17:Q17) -> 6.29 | T17: 0 | U17: 41 | V17: =V16-U17 -> 3041.04 | W17: =R17+T17+N17+U17 -> 47.29 | X17: =IF(L17<0,L17*-1,0) -> 1.8394681 | Y17: =W17+X17 -> 49.129468 | Z17: 0 | AA17: 38 | AB17: -6 | AC17: =AC16+1 -> 8
A18: =A17+1 -> 9 | B18: 6914.33 | C18: 339597 | D18: =C18-C17 -> 41 | E18: =C18-152000 -> 187597 | F18: =D18/$D$2 -> 20.670532 | G18: 70 | H18: 4.1 | I18: =G18+H18 -> 74.1 | J18: =IF(L18>0,L18,0) -> 0 | K18: =I18+J18 -> 74.1 | L18: =F18-(I18-W18) -> -6.1394681 | M18: 6.29 | N18: 0 | O18: =M18-N18 -> 6.29 | P18: 0 | Q18: 0 | R18: =SUM(O18:Q18) -> 6.29 | T18: 0 | U18: 41 | V18: =V17-U18 -> 3000.04 | W18: =R18+T18+N18+U18 -> 47.29 | X18: =IF(L18<0,L18*-1,0) -> 6.1394681 | Y18: =W18+X18 -> 53.429468 | Z18: 0.08 | AA18: 44 | AB18: 12 | AC18: =AC17+1 -> 9
A19: =A18+1 -> 10 | B19: 6914.36 | C19: 339722 | D19: =C19-C18 -> 125 | E19: =C19-152000 -> 187722 | F19: =D19/$D$2 -> 63.019914 | G19: 78 | H19: 4.4 | I19: =G19+H19 -> 82.4 | J19: =IF(L19>0,L19,0) -> 27.909914 | K19: =I19+J19 -> 110.30991 | L19: =F19-(I19-W19) -> 27.909914 | M19: 6.29 | N19: 0 | O19: =M19-N19 -> 6.29 | P19: 0 | Q19: 0 | R19: =SUM(O19:Q19) -> 6.29 | T19: 0 | U19: 41 | V19: =V18-U19 -> 2959.04 | W19: =R19+T19+N19+U19 -> 47.29 | X19: =IF(L19<0,L19*-1,0) -> 0 | Y19: =W19+X19 -> 47.29 | Z19: 0.05 | AA19: 32 | AB19: 24 | AC19: =AC18+1 -> 10
A20: =A19+1 -> 11 | B20: 6914.41 | C20: 339929 | D20: =C20-C19 -> 207 | E20: =C20-152000 -> 187929 | F20: =D20/$D$2 -> 104.36098 | G20: 76 | H20: 4.3 | I20: =G20+H20 -> 80.3 | J20: =IF(L20>0,L20,0) -> 71.350978 | K20: =I20+J20 -> 151.65098 | L20: =F20-(I20-W20) -> 71.350978 | M20: 6.29 | N20: 0 | O20: =M20-N20 -> 6.29 | P20: 0 | Q20: 0 | R20: =SUM(O20:Q20) -> 6.29 | T20: 0 | U20: 41 | V20: =V19-U20 -> 2918.04 | W20: =R20+T20+N20+U20 -> 47.29 | X20: =IF(L20<0,L20*-1,0) -> 0 | Y20: =W20+X20 -> 47.29 | Z20: 0.03 | AA20: 30 | AB20: 15 | AC20: =AC19+1 -> 11
A21: =A20+1 -> 12 | B21: 6914.42 | C21: 339970 | D21: =C21-C20 -> 41 | E21: =C21-152000 -> 187970 | F21: =D21/$D$2 -> 20.670532 | G21: 74 | H21: 4.3 | I21: =G21+H21 -> 78.3 | J21: =IF(L21>0,L21,0) -> 0 | K21: =I21+J21 -> 78.3 | L21: =F21-(I21-W21) -> -10.339468 | M21: 6.29 | N21: 0 | O21: =M21-N21 -> 6.29 | P21: 0 | Q21: 0 | R21: =SUM(O21:Q21) -> 6.29 | T21: 0 | U21: 41 | V21: =V20-U21 -> 2877.04 | W21: =R21+T21+N21+U21 -> 47.29 | X21: =IF(L21<0,L21*-1,0) -> 10.339468 | Y21: =W21+X21 -> 57.629468 | Z21: 0 | AA21: 36 | AB21: 15 | AC21: =AC20+1 -> 12
A22: 13 | B22: 6914.43 | C22: 340012 | D22: =C22-C21 -> 42 | E22: =C22-152000 -> 188012 | F22: =D22/$D$2 -> 21.174691 | G22: 70 | H22: 4 | I22: =G22+H22 -> 74 | J22: =IF(L22>0,L22,0) -> 0 | K22: =I22+J22 -> 74 | L22: =F22-(I22-W22) -> -5.5353088 | M22: 6.29 | N22: 0 | O22: =M22-N22 -> 6.29 | P22: 0 | Q22: 0 | R22: =SUM(O22:Q22) -> 6.29 | T22: 0 | U22: 41 | V22: =V21-U22 -> 2836.04 | W22: =R22+T22+N22+U22 -> 47.29 | X22: =IF(L22<0,L22*-1,0) -> 5.5353088 | Y22: =W22+X22 -> 52.825309 | Z22: 0.12 | AA22: 34 | AB22: 24 | AC22: =AC21+1 -> 13
A23: =A22+1 -> 14 | B23: 6914.45 | C23: 340094 | D23: =C23-C22 -> 82 | E23: =C23-152000 -> 188094 | F23: =D23/$D$2 -> 41.341064 | G23: 60 | H23: 3.5 | I23: =G23+H23 -> 63.5 | J23: =IF(L23>0,L23,0) -> 25.131064 | K23: =I23+J23 -> 88.631064 | L23: =F23-(I23-W23) -> 25.131064 | M23: 6.29 | N23: 0 | O23: =M23-N23 -> 6.29 | P23: 0 | Q23: 0 | R23: =SUM(O23:Q23) -> 6.29 | T23: 0 | U23: 41 | V23: =V22-U23 -> 2795.04 | W23: =R23+T23+N23+U23 -> 47.29 | X23: =IF(L23<0,L23*-1,0) -> 0 | Y23: =W23+X23 -> 47.29 | Z23: 0 | AA23: 35 | AB23: 10 | AC23: =AC22+1 -> 14
A24: =A23+1 -> 15 | B24: 6914.46 | C24: 340136 | D24: =C24-C23 -> 42 | E24: =C24-152000 -> 188136 | F24: =D24/$D$2 -> 21.174691 | G24: 58 | H24: 3.4 | I24: =G24+H24 -> 61.4 | J24: =IF(L24>0,L24,0) -> 7.0646912 | K24: =I24+J24 -> 68.464691 | L24: =F24-(I24-W24) -> 7.0646912 | M24: 6.29 | N24: 0 | O24: =M24-N24 -> 6.29 | P24: 0 | Q24: 0 | R24: =SUM(O24:Q24) -> 6.29 | T24: 0 | U24: 41 | V24: =V23-U24 -> 2754.04 | W24: =R24+T24+N24+U24 -> 47.29 | X24: =IF(L24<0,L24*-1,0) -> 0 | Y24: =W24+X24 -> 47.29 | Z24: 0 | AA24: 42 | AB24: 9 | AC24: =AC23+1 -> 15
A25: =A24+1 -> 16 | B25: 6914.48 | C25: 340219 | D25: =C25-C24 -> 83 | E25: =C25-152000 -> 188219 | F25: =D25/$D$2 -> 41.845223 | G25: 60 | H25: 3.4 | I25: =G25+H25 -> 63.4 | J25: =IF(L25>0,L25,0) -> 25.735223 | K25: =I25+J25 -> 89.135223 | L25: =F25-(I25-W25) -> 25.735223 | M25: 6.29 | N25: 0 | O25: =M25-N25 -> 6.29 | P25: 0 | Q25: 0 | R25: =SUM(O25:Q25) -> 6.29 | T25: 0 | U25: 41 | V25: =V24-U25 -> 2713.04 | W25: =R25+T25+N25+U25 -> 47.29 | X25: =IF(L25<0,L25*-1,0) -> 0 | Y25: =W25+X25 -> 47.29 | Z25: 0 | AA25: 44 | AB25: 20 | AC25: =AC24+1 -> 16
A26: =A25+1 -> 17 | B26: 6914.51 | C26: 340343 | D26: =C26-C25 -> 124 | E26: =C26-152000 -> 188343 | F26: =D26/$D$2 -> 62.515755 | G26: 60 | H26: 3.6 | I26: =G26+H26 -> 63.6 | J26: =IF(L26>0,L26,0) -> 46.205755 | K26: =I26+J26 -> 109.80575 | L26: =F26-(I26-W26) -> 46.205755 | M26: 6.29 | N26: 0 | O26: =M26-N26 -> 6.29 | P26: 0 | Q26: 0 | R26: =SUM(O26:Q26) -> 6.29 | T26: 0 | U26: 41 | V26: =V25-U26 -> 2672.04 | W26: =R26+T26+N26+U26 -> 47.29 | X26: =IF(L26<0,L26*-1,0) -> 0 | Y26: =W26+X26 -> 47.29 | Z26: 0 | AA26: 43 | AB26: 22 | AC26: =AC25+1 -> 17
A27: =A26+1 -> 18 | B27: 6914.54 | C27: 340467 | D27: =C27-C26 -> 124 | E27: =C27-152000 -> 188467 | F27: =D27/$D$2 -> 62.515755 | G27: 62 | H27: 3.7 | I27: =G27+H27 -> 65.7 | J27: =IF(L27>0,L27,0) -> 44.105755 | K27: =I27+J27 -> 109.80575 | L27: =F27-(I27-W27) -> 44.105755 | M27: 6.29 | N27: 0 | O27: =M27-N27 -> 6.29 | P27: 0 | Q27: 0 | R27: =SUM(O27:Q27) -> 6.29 | T27: 0 | U27: 41 | V27: =V26-U27 -> 2631.04 | W27: =R27+T27+N27+U27 -> 47.29 | X27: =IF(L27<0,L27*-1,0) -> 0 | Y27: =W27+X27 -> 47.29 | Z27: 0 | AA27: 50 | AB27: 24 | AC27: =AC26+1 -> 18
A28: =A27+1 -> 19 | B28: 6914.56 | C28: 340550 | D28: =C28-C27 -> 83 | E28: =C28-152000 -> 188550 | F28: =D28/$D$2 -> 41.845223 | G28: 66 | H28: 3.8 | I28: =G28+H28 -> 69.8 | J28: =IF(L28>0,L28,0) -> 19.335223 | K28: =I28+J28 -> 89.135223 | L28: =F28-(I28-W28) -> 19.335223 | M28: 6.29 | N28: 0 | O28: =M28-N28 -> 6.29 | P28: 0 | Q28: 0 | R28: =SUM(O28:Q28) -> 6.29 | T28: 0 | U28: 41 | V28: =V27-U28 -> 2590.04 | W28: =R28+T28+N28+U28 -> 47.29 | X28: =IF(L28<0,L28*-1,0) -> 0 | Y28: =W28+X28 -> 47.29 | Z28: 0.13 | AA28: 45 | AB28: 28 | AC28: =AC27+1 -> 19
A29: =A28+1 -> 20 | B29: 6914.57 | C29: 340591 | D29: =C29-C28 -> 41 | E29: =C29-152000 -> 188591 | F29: =D29/$D$2 -> 20.670532 | G29: 62 | H29: 3.7 | I29: =G29+H29 -> 65.7 | J29: =IF(L29>0,L29,0) -> 2.2605319 | K29: =I29+J29 -> 67.960532 | L29: =F29-(I29-W29) -> 2.2605319 | M29: 6.29 | N29: 0 | O29: =M29-N29 -> 6.29 | P29: 0 | Q29: 0 | R29: =SUM(O29:Q29) -> 6.29 | T29: 0 | U29: 41 | V29: =V28-U29 -> 2549.04 | W29: =R29+T29+N29+U29 -> 47.29 | X29: =IF(L29<0,L29*-1,0) -> 0 | Y29: =W29+X29 -> 47.29 | Z29: 0 | AA29: 37 | AB29: 13 | AC29: =AC28+1 -> 20
A30: =A29+1 -> 21 | B30: 6914.58 | C30: 340633 | D30: =C30-C29 -> 42 | E30: =C30-152000 -> 188633 | F30: =D30/$D$2 -> 21.174691 | G30: 56 | H30: 3.4 | I30: =G30+H30 -> 59.4 | J30: =IF(L30>0,L30,0) -> 9.0646912 | K30: =I30+J30 -> 68.464691 | L30: =F30-(I30-W30) -> 9.0646912 | M30: 6.29 | N30: 0 | O30: =M30-N30 -> 6.29 | P30: 0 | Q30: 0 | R30: =SUM(O30:Q30) -> 6.29 | T30: 0 | U30: 41 | V30: =V29-U30 -> 2508.04 | W30: =R30+T30+N30+U30 -> 47.29 | X30: =IF(L30<0,L30*-1,0) -> 0 | Y30: =W30+X30 -> 47.29 | Z30: 0 | AA30: 36 | AB30: 10 | AC30: =AC29+1 -> 21
A31: =A30+1 -> 22 | B31: 6914.59 | C31: 340674 | D31: =C31-C30 -> 41 | E31: =C31-152000 -> 188674 | F31: =D31/$D$2 -> 20.670532 | G31: 56 | H31: 3.4 | I31: =G31+H31 -> 59.4 | J31: =IF(L31>0,L31,0) -> 8.5605319 | K31: =I31+J31 -> 67.960532 | L31: =F31-(I31-W31) -> 8.5605319 | M31: 6.29 | N31: 0 | O31: =M31-N31 -> 6.29 | P31: 0 | Q31: 0 | R31: =SUM(O31:Q31) -> 6.29 | T31: 0 | U31: 41 | V31: =V30-U31 -> 2467.04 | W31: =R31+T31+N31+U31 -> 47.29 | X31: =IF(L31<0,L31*-1,0) -> 0 | Y31: =W31+X31 -> 47.29 | Z31: 0 | AA31: 34 | AB31: 5 | AC31: =AC30+1 -> 22
A32: =A31+1 -> 23 | B32: 6914.6 | C32: 340716 | D32: =C32-C31 -> 42 | E32: =C32-152000 -> 188716 | F32: =D32/$D$2 -> 21.174691 | G32: 56 | H32: 3.4 | I32: =G32+H32 -> 59.4 | J32: =IF(L32>0,L32,0) -> 9.0646912 | K32: =I32+J32 -> 68.464691 | L32: =F32-(I32-W32) -> 9.0646912 | M32: 6.29 | N32: 0 | O32: =M32-N32 -> 6.29 | P32: 0 | Q32: 0 | R32: =SUM(O32:Q32) -> 6.29 | T32: 0 | U32: 41 | V32: =V31-U32 -> 2426.04 | W32: =R32+T32+N32+U32 -> 47.29 | X32: =IF(L32<0,L32*-1,0) -> 0 | Y32: =W32+X32 -> 47.29 | Z32: 0 | AA32: 42 | AB32: 12 | AC32: =AC31+1 -> 23
A33: =A32+1 -> 24 | B33: 6914.61 | C33: 340757 | D33: =C33-C32 -> 41 | E33: =C33-152000 -> 188757 | F33: =D33/$D$2 -> 20.670532 | G33: 56 | H33: 3.4 | I33: =G33+H33 -> 59.4 | J33: =IF(L33>0,L33,0) -> 8.5605319 | K33: =I33+J33 -> 67.960532 | L33: =F33-(I33-W33) -> 8.5605319 | M33: 6.29 | N33: 0 | O33: =M33-N33 -> 6.29 | P33: 0 | Q33: 0 | R33: =SUM(O33:Q33) -> 6.29 | T33: 0 | U33: 41 | V33: =V32-U33 -> 2385.04 | W33: =R33+T33+N33+U33 -> 47.29 | X33: =IF(L33<0,L33*-1,0) -> 0 | Y33: =W33+X33 -> 47.29 | Z33: 0 | AA33: 45 | AB33: 19 | AC33: =AC32+1 -> 24
A34: =A33+1 -> 25 | B34: 6914.62 | C34: 340798 | D34: =C34-C33 -> 41 | E34: =C34-152000 -> 188798 | F34: =D34/$D$2 -> 20.670532 | G34: 58 | H34: 3.5 | I34: =G34+H34 -> 61.5 | J34: =IF(L34>0,L34,0) -> 6.4605319 | K34: =I34+J34 -> 67.960532 | L34: =F34-(I34-W34) -> 6.4605319 | M34: 6.29 | N34: 0 | O34: =M34-N34 -> 6.29 | P34: 0 | Q34: 0 | R34: =SUM(O34:Q34) -> 6.29 | T34: 0 | U34: 41 | V34: =V33-U34 -> 2344.04 | W34: =R34+T34+N34+U34 -> 47.29 | X34: =IF(L34<0,L34*-1,0) -> 0 | Y34: =W34+X34 -> 47.29 | Z34: 0 | AA34: 44 | AB34: 18 | AC34: =AC33+1 -> 25
... A38: =A37+1 -> 29 | B38: 6914.66 | C38: 340964 | D38: =C38-C37 -> 41 | E38: =C38-152000 -> 188964 | F38: =D38/$D$2 -> 20.670532 | G38: 64 | H38: 4 | I38: =G38+H38 -> 68 | J38: =IF(L38>0,L38,0) -> 0.96053189 | K38: =I38+J38 -> 68.960532 | L38: =F38-(I38-W38) -> 0.96053189 | M38: 6.29 | N38: 0 | O38: =M38-N38 -> 6.29 | P38: 0 | Q38: 0 | R38: =SUM(O38:Q38) -> 6.29 | T38: 0 | U38: 42 | V38: =V37-U38 -> 2176.04 | W38: =R38+T38+N38+U38 -> 48.29 | X38: =IF(L38<0,L38*-1,0) -> 0 | Y38: =W38+X38 -> 48.29 | Z38: 0 | AA38: 53 | AB38: 21 | AC38: =AC37+1 -> 29
A39: 30 | B39: 6914.67 | C39: 341006 | D39: =C39-C38 -> 42 | E39: =C39-152000 -> 189006 | F39: =D39/$D$2 -> 21.174691 | G39: 64 | H39: 3.9 | I39: =G39+H39 -> 67.9 | J39: =IF(L39>0,L39,0) -> 1.5646912 | K39: =I39+J39 -> 69.464691 | L39: =F39-(I39-W39) -> 1.5646912 | M39: 6.29 | N39: 0 | O39: =M39-N39 -> 6.29 | P39: 0 | Q39: 0 | R39: =SUM(O39:Q39) -> 6.29 | T39: 0 | U39: 42 | V39: =V38-U39 -> 2134.04 | W39: =R39+T39+N39+U39 -> 48.29 | X39: =IF(L39<0,L39*-1,0) -> 0 | Y39: =W39+X39 -> 48.29 | Z39: 0 | AA39: 50 | AB39: 23 | AC39: 30
A40: 31 | B40: 6914.68 | C40: 341047 | D40: =C40-C39 -> 41 | E40: =C40-152000 -> 189047 | F40: =D40/$D$2 -> 20.670532 | G40: 62 | H40: 3.8 | I40: =G40+H40 -> 65.8 | J40: =IF(L40>0,L40,0) -> 3.1605319 | K40: =I40+J40 -> 68.960532 | L40: =F40-(I40-W40) -> 3.1605319 | M40: 6.29 | N40: 0 | O40: =M40-N40 -> 6.29 | P40: 0 | Q40: 0 | R40: =SUM(O40:Q40) -> 6.29 | T40: 0 | U40: 42 | V40: =V39-U40 -> 2092.04 | W40: =R40+T40+N40+U40 -> 48.29 | X40: =IF(L40<0,L40*-1,0) -> 0 | Y40: =W40+X40 -> 48.29 | Z40: 0 | AA40: 50 | AB40: 24 | AC40: 31
A42: MONTH / CFS | F42: =SUM(F10:F40) -> 1232.1654 | G42: =SUM(G10:G40) -> 2047 | H42: =SUM(H10:H40) -> 119.7 | I42: =SUM(I10:I40) -> 2166.7 | J42: =SUM(J10:J40) -> 579.00916 | K42: =SUM(K10:K40) -> 2745.7092 | L42: =SUM(L10:L40) -> 538.45536 | M42: =SUM(M10:M40) -> 194.99 | ... R42: =SUM(R10:R40) -> 194.99 | T42: =SUM(T10:T40) -> 0 | U42: =SUM(U10:U40) -> 1278 | W42: =SUM(W10:W40) -> 1472.99 | X42: =SUM(X10:X40) -> 40.553799 | Y42: =SUM(Y10:Y40) -> 1513.5438 | Z42: =SUM(Z10:Z40) -> 1.06 | AA42: =AVERAGE(AA10:AA40) -> 42 | AB42: =AVERAGE(AB10:AB40) -> 16.387097
A43: MONTH / AF | D43: =SUM(D10:D40) -> 2444 | F43: =F42*$D$2 -> 2444 | G43: =G42*$D$2 -> 4060.2245 | H43: =H42*$D$2 -> 237.42495 | I43: =I42*$D$2 -> 4297.6494 | J43: =J42*$D$2 -> 1148.4647 | K43: =K42*$D$2 -> 5446.1141 | L43: =L42*$D$2 -> 1068.0262 | M43: =M42*$D$2 -> 386.76267 | ... R43: =R42*$D$2 -> 386.76267 | T43: =T42*$D$2 -> 0 | U43: =U42*$D$2 -> 2534.913 | W43: =W42*$D$2 -> 2921.6757 | X43: =X42*$D$2 -> 80.43846 | Y43: =Y42*$D$2 -> 3002.1141 | AA43: =MAX(AA10:AA40) -> 55 | AB43: =MAX(AB10:AB40) -> 29 | AC43: HI
A45: SEASON / CFS | AA45: =MIN(AA10:AA40) -> 30 | AB45: =MIN(AB10:AB40) -> -6 | AC45: LO
A46: SEASON / AF
A48: YTD / CFS | F48: =F8+F42 -> 3799.8488 | G48: =G8+G42 -> 8240 | H48: =H8+H42 -> 377.9 | I48: =I8+I42 -> 8611 | J48: =J8+J42 -> 1221.0446 | K48: =K8+K42 -> 9823.6446 | L48: =L8+L42 -> 348.72875 | M48: =M8+M42 -> 957.72 | ... R48: =R8+R42 -> 846.67 | T48: =T8+T42 -> 0 | U48: =U8+U42 -> 4055.96 | V48: =V40 -> 2092.04 | W48: =W8+W42 -> 5159.88 | X48: =X8+X42 -> 872.31589 | Y48: =Y8+Y42 -> 6032.1959 | Z48: =Z8+Z42 -> 3.05
A49: YTD / AF | D49: =D8+D43 -> 7537 | E49: =E40 -> 189047 | F49: =F48*$D$2 -> 7537 | G49: =G48*$D$2 -> 16344.04 | H49: =H48*$D$2 -> 749.56465 | I49: =I48*$D$2 -> 17079.918 | J49: =J48*$D$2 -> 2421.942 | K49: =K48*$D$2 -> 19485.199 | L49: =L48*$D$2 -> 691.70348 | M49: =M48*$D$2 -> 1899.6376 | ... U49: =U48*$D$2 -> 8044.9967 | V49: =V40*$D$2 -> 4149.5613 | W49: =W48*$D$2 -> 10234.622 | X49: =X48*$D$2 -> 1730.2386 | Y49: =Y48*$D$2 -> 11964.861
...

Sheet FEB
K1: MC PHEE RESERVOIR IN/OUT FLOW TABULATION
A2: AF/cfs CONVERT FACTOR | D2: 1.9835 | K2: FEBRUARY "98"
A4: DATE | B4: RESERV | C4: RESERV | D4: AC FT | E4: ACTIVE | F4: CONV TO | G4: DOLORES | H4: LOST | I4: RECORDED | J4: CALC | K4: TOTAL | L4: CALC | M4: DOLORES TUNNEL | P4: LONE | Q4: U | R4: TOTAL | S4: MVI | T4: DV CR | U4: BELOW | V4: REMAIN | W4: RECORDED | X4: CALC | Y4: TOTAL | Z4: RAIN | AA4: MAX | AB4: MIN | AC4: DATE
A5: FEB | B5: ELEV | C5: AC FT | D5: CHANGE | E5: CAP | F5: CFS | G5: RIVER | H5: CANYON | I5: INFLOW | J5: INFLOW | K5: INFLOW | L5: INF/OTF | M5: TOT DIV | N5: UTE F&R | O5: MVI,CTZ | P5: PINE | Q5: LATERAL | R5: MVI | S5: CALL | T5: CANAL | U5: MC PHEE | V5: RELEASE | W5: OUTFLOW | X5: OUTFLOW | Y5: OUTFLOW | AA5: TMP | AB5: TMP | AC5: FEB
A7: SEASON BAL
