Workbook

Sheet NOV
K1: MC PHEE RESERVOIR IN/OUT FLOW TABULATION
A2: AF/cfs CONVERT FACTOR | D2: 1.9835 | L2: NOVEMBER "2001"
A4: DATE | B4: RESERV | C4: RESERV | D4: AC FT | E4: ACTIVE | F4: CONV TO | G4: DOLORES | H4: LOST | I4: RECORDED | J4: CALC | K4: TOTAL | L4: CALC | M4: DOLORES TUNNEL | Q4: LONE | R4: U | S4: TOTAL | T4: MVI | U4: DV CR | V4: BELOW | W4: REMAIN | X4: RECORDED | Y4: CALC | Z4: TOTAL | AA4: RAIN | AB4: MAX | AC4: MIN | AD4: DATE
A5: "NOV" | B5: ELEV | C5: AC FT | D5: CHANGE | E5: CAP | F5: CFS | G5: RIVER | H5: CANYON | I5: INFLOW | J5: INFLOW | K5: INFLOW | L5: INF/OTF | M5: TOT DIV | N5: WETLAND | O5: UTE F&R | P5: MVI,CTZ | Q5: PINE | R5: LAT | S5: MVI | T5: CALL | U5: CANAL | V5: MC PHEE | W5: RELEASE | X5: OUTFLOW | Y5: OUTFLOW | Z5: OUTFLOW | AB5: TMP | AC5: TMP | AD5: "NOV"
A7: SEASON BAL
A8: YTD | B8: 6876.53 | C8: 205946 | O8: 402.2 | W8: 4802
A10: 1 | B10: 6876.52 | C10: 205917 | D10: =C10-C8 -> -29 | E10: =C10-152000 -> 53917 | F10: =D10/$D$2 -> -14.62062 | G10: 54 | H10: 0 | I10: =G10+H10 -> 54 | J10: =IF(L10>0,L10,0) -> 17.37938 | K10: =I10+J10 -> 71.37938 | L10: =F10-(I10-X10) -> 17.37938 | M10: 35 | N10: 5 | O10: =13.06*1.05 -> 13.713 | P10: =M10-(N10+O10) -> 16.287 | Q10: 0 | R10: 14 | S10: =SUM(P10:R10) -> 30.287 | U10: 0 | V10: 37 | W10: =W8-V10 -> 4765 | X10: =N10+O10+S10+U10+V10 -> 86 | Y10: =IF(L10<0,L10*-1,0) -> 0 | Z10: =X10+Y10 -> 86 | AA10: 0 | AB10: 59 | AC10: 33 | AD10: 1
A11: =A10+1 -> 2 | B11: 6876.48 | C11: 205802 | D11: =C11-C10 -> -115 | E11: =C11-152000 -> 53802 | F11: =D11/$D$2 -> -57.978321 | G11: 49 | H11: 0 | I11: =G11+H11 -> 49 | J11: =IF(L11>0,L11,0) -> 0 | K11: =I11+J11 -> 49 | L11: =F11-(I11-X11) -> -31.978321 | M11: 26 | N11: 0 | O11: =8.43*1.05 -> 8.8515 | P11: =M11-(N11+O11) -> 17.1485 | Q11: 0 | R11: 14 | S11: =SUM(P11:R11) -> 31.1485 | U11: 0 | V11: 35 | W11: =W10-V11 -> 4730 | X11: =N11+O11+S11+U11+V11 -> 75 | Y11: =IF(L11<0,L11*-1,0) -> 31.978321 | Z11: =X11+Y11 -> 106.97832 | AA11: 0 | AB11: 64 | AC11: 33 | AD11: =AD10+1 -> 2
A12: =A11+1 -> 3 | B12: 6876.47 | C12: 205773 | D12: =C12-C11 -> -29 | E12: =C12-152000 -> 53773 | F12: =D12/$D$2 -> -14.62062 | G12: 45 | H12: 0 | I12: =G12+H12 -> 45 | J12: =IF(L12>0,L12,0) -> 12.37938 | K12: =I12+J12 -> 57.37938 | L12: =F12-(I12-X12) -> 12.37938 | M12: 25 | N12: 0 | O12: 0 | P12: =M12-(N12+O12) -> 25 | Q12: 0 | R12: 14 | S12: =SUM(P12:R12) -> 39 | U12: 0 | V12: 33 | W12: =W11-V12 -> 4697 | X12: =N12+O12+S12+U12+V12 -> 72 | Y12: =IF(L12<0,L12*-1,0) -> 0 | Z12: =X12+Y12 -> 72 | AA12: 0 | AB12: 67 | AC12: 35 | AD12: =AD11+1 -> 3
A13: =A12+1 -> 4 | B13: 6876.46 | C13: 205744 | D13: =C13-C12 -> -29 | E13: =C13-152000 -> 53744 | F13: =D13/$D$2 -> -14.62062 | G13: 43 | H13: 0 | I13: =G13+H13 -> 43 | J13: =IF(L13>0,L13,0) -> 14.37938 | K13: =I13+J13 -> 57.37938 | L13: =F13-(I13-X13) -> 14.37938 | M13: 25 | N13: 0 | O13: 0 | P13: =M13-(N13+O13) -> 25 | Q13: 0 | R13: 14 | S13: =SUM(P13:R13) -> 39 | U13: 0 | V13: 33 | W13: =W12-V13 -> 4664 | X13: =N13+O13+S13+U13+V13 -> 72 | Y13: =IF(L13<0,L13*-1,0) -> 0 | Z13: =X13+Y13 -> 72 | AA13: 0 | AB13: 67 | AC13: 39 | AD13: =AD12+1 -> 4
A14: =A13+1 -> 5 | B14: 6876.45 | C14: 205715 | D14: =C14-C13 -> -29 | E14: =C14-152000 -> 53715 | F14: =D14/$D$2 -> -14.62062 | G14: 42 | H14: 0 | I14: =G14+H14 -> 42 | J14: =IF(L14>0,L14,0) -> 15.37938 | K14: =I14+J14 -> 57.37938 | L14: =F14-(I14-X14) -> 15.37938 | M14: 28 | N14: 0 | O14: =7.03*1.05 -> 7.3815 | P14: =M14-(N14+O14) -> 20.6185 | Q14: 0 | R14: 11 | S14: =SUM(P14:R14) -> 31.6185 | U14: 0 | V14: 33 | W14: =W13-V14 -> 4631 | X14: =N14+O14+S14+U14+V14 -> 72 | Y14: =IF(L14<0,L14*-1,0) -> 0 | Z14: =X14+Y14 -> 72 | AA14: 0.02 | AB14: 64 | AC14: 39 | AD14: =AD13+1 -> 5
A15: =A14+1 -> 6 | B15: 6876.44 | C15: 205686 | D15: =C15-C14 -> -29 | E15: =C15-152000 -> 53686 | F15: =D15/$D$2 -> -14.62062 | G15: 43 | H15: 0 | I15: =G15+H15 -> 43 | J15: =IF(L15>0,L15,0) -> 1.0793799 | K15: =I15+J15 -> 44.07938 | L15: =F15-(I15-X15) -> 1.0793799 | M15: 17 | N15: 0 | O15: =3.42*1.05 -> 3.591 | P15: =M15-(N15+O15) -> 13.409 | Q15: 0 | R15: 8.7 | S15: =SUM(P15:R15) -> 22.109 | U15: 0 | V15: 33 | W15: =W14-V15 -> 4598 | X15: =N15+O15+S15+U15+V15 -> 58.7 | Y15: =IF(L15<0,L15*-1,0) -> 0 | Z15: =X15+Y15 -> 58.7 | AA15: 0.01 | AB15: 64 | AC15: 38 | AD15: =AD14+1 -> 6
A16: =A15+1 -> 7 | B16: 6876.43 | C16: 205657 | D16: =C16-C15 -> -29 | E16: =C16-152000 -> 53657 | F16: =D16/$D$2 -> -14.62062 | G16: 45 | H16: 0 | I16: =G16+H16 -> 45 | J16: =IF(L16>0,L16,0) -> 0 | K16: =I16+J16 -> 45 | L16: =F16-(I16-X16) -> -2.3206201 | M16: 17 | N16: 0 | O16: =3.81*1.05 -> 4.0005 | P16: =M16-(N16+O16) -> 12.9995 | Q16: 0 | R16: 7.3 | S16: =SUM(P16:R16) -> 20.2995 | U16: 0 | V16: 33 | W16: =W15-V16 -> 4565 | X16: =N16+O16+S16+U16+V16 -> 57.3 | Y16: =IF(L16<0,L16*-1,0) -> 2.3206201 | Z16: =X16+Y16 -> 59.62062 | AA16: 0 | AB16: 61 | AC16: 37 | AD16: =AD15+1 -> 7
A17: =A16+1 -> 8 | B17: 6876.42 | C17: 205628 | D17: =C17-C16 -> -29 | E17: =C17-152000 -> 53628 | F17: =D17/$D$2 -> -14.62062 | G17: 44 | H17: 0 | I17: =G17+H17 -> 44 | J17: =IF(L17>0,L17,0) -> 0 | K17: =I17+J17 -> 44 | L17: =F17-(I17-X17) -> -1.8206201 | M17: 17 | N17: 0 | O17: =5.97*1.05 -> 6.2685 | P17: =M17-(N17+O17) -> 10.7315 | Q17: 0 | R17: 6.8 | S17: =SUM(P17:R17) -> 17.5315 | U17: 0 | V17: 33 | W17: =W16-V17 -> 4532 | X17: =N17+O17+S17+U17+V17 -> 56.8 | Y17: =IF(L17<0,L17*-1,0) -> 1.8206201 | Z17: =X17+Y17 -> 58.62062 | AA17: 0.03 | AB17: 60 | AC17: 34 | AD17: =AD16+1 -> 8
A18: =A17+1 -> 9 | B18: 6876.41 | C18: 205599 | D18: =C18-C17 -> -29 | E18: =C18-152000 -> 53599 | F18: =D18/$D$2 -> -14.62062 | G18: 47 | H18: 0 | I18: =G18+H18 -> 47 | J18: =IF(L18>0,L18,0) -> 0 | K18: =I18+J18 -> 47 | L18: =F18-(I18-X18) -> -4.8206201 | M18: 16 | N18: 0 | O18: =8.09*1.05 -> 8.4945 | P18: =M18-(N18+O18) -> 7.5055 | Q18: 0 | R18: 6.8 | S18: =SUM(P18:R18) -> 14.3055 | U18: 0 | V18: 34 | W18: =W17-V18 -> 4498 | X18: =N18+O18+S18+U18+V18 -> 56.8 | Y18: =IF(L18<0,L18*-1,0) -> 4.8206201 | Z18: =X18+Y18 -> 61.62062 | AA18: 0 | AB18: 58 | AC18: 31 | AD18: =AD17+1 -> 9
A19: =A18+1 -> 10 | B19: 6876.4 | C19: 205571 | D19: =C19-C18 -> -28 | E19: =C19-152000 -> 53571 | F19: =D19/$D$2 -> -14.116461 | G19: 42 | H19: 0 | I19: =G19+H19 -> 42 | J19: =IF(L19>0,L19,0) -> 0.6835392 | K19: =I19+J19 -> 42.683539 | L19: =F19-(I19-X19) -> 0.6835392 | M19: 16 | N19: 0 | O19: =3.11*1.05 -> 3.2655 | P19: =M19-(N19+O19) -> 12.7345 | Q19: 0 | R19: 6.8 | S19: =SUM(P19:R19) -> 19.5345 | U19: 0 | V19: 34 | W19: =W18-V19 -> 4464 | X19: =N19+O19+S19+U19+V19 -> 56.8 | Y19: =IF(L19<0,L19*-1,0) -> 0 | Z19: =X19+Y19 -> 56.8 | AA19: 0 | AB19: 60 | AC19: 33 | AD19: =AD18+1 -> 10
A20: =A19+1 -> 11 | B20: 6876.38 | C20: 205513 | D20: =C20-C19 -> -58 | E20: =C20-152000 -> 53513 | F20: =D20/$D$2 -> -29.24124 | G20: 40 | H20: 0 | I20: =G20+H20 -> 40 | J20: =IF(L20>0,L20,0) -> 0 | K20: =I20+J20 -> 40 | L20: =F20-(I20-X20) -> -13.44124 | M20: 16 | N20: 0 | O20: 0 | P20: =M20-(N20+O20) -> 16 | Q20: 0 | R20: 6.8 | S20: =SUM(P20:R20) -> 22.8 | U20: 0 | V20: 33 | W20: =W19-V20 -> 4431 | X20: =N20+O20+S20+U20+V20 -> 55.8 | Y20: =IF(L20<0,L20*-1,0) -> 13.44124 | Z20: =X20+Y20 -> 69.24124 | AA20: 0 | AB20: 63 | AC20: 37 | AD20: =AD19+1 -> 11
A21: =A20+1 -> 12 | B21: 6876.36 | C21: 205455 | D21: =C21-C20 -> -58 | E21: =C21-152000 -> 53455 | F21: =D21/$D$2 -> -29.24124 | G21: 41 | H21: 0 | I21: =G21+H21 -> 41 | J21: =IF(L21>0,L21,0) -> 0 | K21: =I21+J21 -> 41 | L21: =F21-(I21-X21) -> -15.54124 | M21: 15 | N21: 0 | O21: 0 | P21: =M21-(N21+O21) -> 15 | Q21: 0 | R21: 5.7 | S21: =SUM(P21:R21) -> 20.7 | U21: 0 | V21: 34 | W21: =W20-V21 -> 4397 | X21: =N21+O21+S21+U21+V21 -> 54.7 | Y21: =IF(L21<0,L21*-1,0) -> 15.54124 | Z21: =X21+Y21 -> 70.24124 | AA21: 0 | AB21: 62 | AC21: 32 | AD21: =AD20+1 -> 12
A22: =A21+1 -> 13 | B22: 6876.34 | C22: 205397 | D22: =C22-C21 -> -58 | E22: =C22-152000 -> 53397 | F22: =D22/$D$2 -> -29.24124 | G22: 40 | H22: 0 | I22: =G22+H22 -> 40 | J22: =IF(L22>0,L22,0) -> 0 | K22: =I22+J22 -> 40 | L22: =F22-(I22-X22) -> -15.34124 | M22: 15 | N22: 0 | O22: 0 | P22: =M22-(N22+O22) -> 15 | Q22: 0 | R22: 4.9 | S22: =SUM(P22:R22) -> 19.9 | U22: 0 | V22: 34 | W22: =W21-V22 -> 4363 | X22: =N22+O22+S22+U22+V22 -> 53.9 | Y22: =IF(L22<0,L22*-1,0) -> 15.34124 | Z22: =X22+Y22 -> 69.24124 | AA22: 0 | AB22: 56 | AC22: 36 | AD22: =AD21+1 -> 13
A23: =A22+1 -> 14 | B23: 6876.33 | C23: 205368 | D23: =C23-C22 -> -29 | E23: =C23-152000 -> 53368 | F23: =D23/$D$2 -> -14.62062 | G23: 40 | H23: 0 | I23: =G23+H23 -> 40 | J23: =IF(L23>0,L23,0) -> 0 | K23: =I23+J23 -> 40 | L23: =F23-(I23-X23) -> -1.7206201 | M23: 14 | N23: 0 | O23: 0 | P23: =M23-(N23+O23) -> 14 | Q23: 0 | R23: 4.9 | S23: =SUM(P23:R23) -> 18.9 | U23: 0 | V23: 34 | W23: =W22-V23 -> 4329 | X23: =N23+O23+S23+U23+V23 -> 52.9 | Y23: =IF(L23<0,L23*-1,0) -> 1.7206201 | Z23: =X23+Y23 -> 54.62062 | AA23: 0 | AB23: 61 | AC23: 32 | AD23: =AD22+1 -> 14
A24: =A23+1 -> 15 | B24: 6876.34 | C24: 205397 | D24: =C24-C23 -> 29 | E24: =C24-152000 -> 53397 | F24: =D24/$D$2 -> 14.62062 | G24: 38 | H24: 0 | I24: =G24+H24 -> 38 | J24: =IF(L24>0,L24,0) -> 19.55062 | K24: =I24+J24 -> 57.55062 | L24: =F24-(I24-X24) -> 19.55062 | M24: 8.13 | N24: 0 | O24: 0 | P24: =M24-(N24+O24) -> 8.13 | Q24: 0 | R24: 1.8 | S24: =SUM(P24:R24) -> 9.93 | U24: 0 | V24: 33 | W24: =W23-V24 -> 4296 | X24: =N24+O24+S24+U24+V24 -> 42.93 | Y24: =IF(L24<0,L24*-1,0) -> 0 | Z24: =X24+Y24 -> 42.93 | AA24: 0 | AB24: 59 | AC24: 32 | AD24: =AD23+1 -> 15
A25: =A24+1 -> 16 | B25: 6876.35 | C25: 205426 | D25: =C25-C24 -> 29 | E25: =C25-152000 -> 53426 | F25: =D25/$D$2 -> 14.62062 | G25: 37 | H25: 0 | I25: =G25+H25 -> 37 | J25: =IF(L25>0,L25,0) -> 13.75062 | K25: =I25+J25 -> 50.75062 | L25: =F25-(I25-X25) -> 13.75062 | M25: 5.13 | N25: 0 | O25: 0 | P25: =M25-(N25+O25) -> 5.13 | Q25: 0 | R25: 0 | S25: =SUM(P25:R25) -> 5.13 | U25: 0 | V25: 31 | W25: =W24-V25 -> 4265 | X25: =N25+O25+S25+U25+V25 -> 36.13 | Y25: =IF(L25<0,L25*-1,0) -> 0 | Z25: =X25+Y25 -> 36.13 | AA25: 0 | AB25: 60 | AC25: 32 | AD25: =AD24+1 -> 16
A26: =A25+1 -> 17 | B26: 6876.37 | C26: 205484 | D26: =C26-C25 -> 58 | E26: =C26-152000 -> 53484 | F26: =D26/$D$2 -> 29.24124 | G26: 39 | H26: 0 | I26: =G26+H26 -> 39 | J26: =IF(L26>0,L26,0) -> 26.37124 | K26: =I26+J26 -> 65.37124 | L26: =F26-(I26-X26) -> 26.37124 | M26: 5.13 | N26: 0 | O26: 0 | P26: =M26-(N26+O26) -> 5.13 | Q26: 0 | R26: 0 | S26: =SUM(P26:R26) -> 5.13 | U26: 0 | V26: 31 | W26: =W25-V26 -> 4234 | X26: =N26+O26+S26+U26+V26 -> 36.13 | Y26: =IF(L26<0,L26*-1,0) -> 0 | Z26: =X26+Y26 -> 36.13 | AA26: 0 | AB26: 59 | AC26: 31 | AD26: =AD25+1 -> 17
A27: =A26+1 -> 18 | B27: 6876.39 | C27: 205542 | D27: =C27-C26 -> 58 | E27: =C27-152000 -> 53542 | F27: =D27/$D$2 -> 29.24124 | G27: 41 | H27: 0 | I27: =G27+H27 -> 41 | J27: =IF(L27>0,L27,0) -> 24.56124 | K27: =I27+J27 -> 65.56124 | L27: =F27-(I27-X27) -> 24.56124 | M27: 5.32 | N27: 0 | O27: 0 | P27: =M27-(N27+O27) -> 5.32 | Q27: 0 | R27: 0 | S27: =SUM(P27:R27) -> 5.32 | U27: 0 | V27: 31 | W27: =W26-V27 -> 4203 | X27: =N27+O27+S27+U27+V27 -> 36.32 | Y27: =IF(L27<0,L27*-1,0) -> 0 | Z27: =X27+Y27 -> 36.32 | AA27: 0 | AB27: 55 | AC27: 29 | AD27: =AD26+1 -> 18
A28: =A27+1 -> 19 | B28: 6876.38 | C28: 205513 | D28: =C28-C27 -> -29 | E28: =C28-152000 -> 53513 | F28: =D28/$D$2 -> -14.62062 | G28: 37 | H28: 0 | I28: =G28+H28 -> 37 | J28: =IF(L28>0,L28,0) -> 0 | K28: =I28+J28 -> 37 | L28: =F28-(I28-X28) -> -15.37062 | M28: 5.25 | N28: 0 | O28: 0 | P28: =M28-(N28+O28) -> 5.25 | Q28: 0 | R28: 0 | S28: =SUM(P28:R28) -> 5.25 | U28: 0 | V28: 31 | W28: =W27-V28 -> 4172 | X28: =N28+O28+S28+U28+V28 -> 36.25 | Y28: =IF(L28<0,L28*-1,0) -> 15.37062 | Z28: =X28+Y28 -> 51.62062 | AA28: 0 | AB28: 56 | AC28: 27 | AD28: =AD27+1 -> 19
A29: =A28+1 -> 20 | B29: 6876.34 | C29: 205397 | D29: =C29-C28 -> -116 | E29: =C29-152000 -> 53397 | F29: =D29/$D$2 -> -58.48248 | G29: 29 | H29: 0 | I29: =G29+H29 -> 29 | J29: =IF(L29>0,L29,0) -> 0 | K29: =I29+J29 -> 29 | L29: =F29-(I29-X29) -> -51.35248 | M29: 5.13 | N29: 0 | O29: 0 | P29: =M29-(N29+O29) -> 5.13 | Q29: 0 | R29: 0 | S29: =SUM(P29:R29) -> 5.13 | U29: 0 | V29: 31 | W29: =W28-V29 -> 4141 | X29: =N29+O29+S29+U29+V29 -> 36.13 | Y29: =IF(L29<0,L29*-1,0) -> 51.35248 | Z29: =X29+Y29 -> 87.48248 | AA29: 0 | AB29: 52 | AC29: 24 | AD29: =AD28+1 -> 20
A30: =A29+1 -> 21 | B30: 6876.33 | C30: 205368 | D30: =C30-C29 -> -29 | E30: =C30-152000 -> 53368 | F30: =D30/$D$2 -> -14.62062 | G30: 26 | H30: 0 | I30: =G30+H30 -> 26 | J30: =IF(L30>0,L30,0) -> 0 | K30: =I30+J30 -> 26 | L30: =F30-(I30-X30) -> -4.4906201 | M30: 5.13 | N30: 0 | O30: 0 | P30: =M30-(N30+O30) -> 5.13 | Q30: 0 | R30: 0 | S30: =SUM(P30:R30) -> 5.13 | U30: 0 | V30: 31 | W30: =W29-V30 -> 4110 | X30: =N30+O30+S30+U30+V30 -> 36.13 | Y30: =IF(L30<0,L30*-1,0) -> 4.4906201 | Z30: =X30+Y30 -> 40.62062 | AA30: 0 | AB30: 54 | AC30: 23 | AD30: =AD29+1 -> 21
A31: =A30+1 -> 22 | B31: 6876.35 | C31: 205426 | D31: =C31-C30 -> 58 | E31: =C31-152000 -> 53426 | F31: =D31/$D$2 -> 29.24124 | G31: 33 | H31: 0 | I31: =G31+H31 -> 33 | J31: =IF(L31>0,L31,0) -> 31.37124 | K31: =I31+J31 -> 64.37124 | L31: =F31-(I31-X31) -> 31.37124 | M31: 5.13 | N31: 0 | O31: 0 | P31: =M31-(N31+O31) -> 5.13 | Q31: 0 | R31: 0 | S31: =SUM(P31:R31) -> 5.13 | U31: 0 | V31: 30 | W31: =W30-V31 -> 4080 | X31: =N31+O31+S31+U31+V31 -> 35.13 | Y31: =IF(L31<0,L31*-1,0) -> 0 | Z31: =X31+Y31 -> 35.13 | AA31: 0.38 | AB31: 45 | AC31: 31 | AD31: =AD30+1 -> 22
... A38: =A37+1 -> 29 | B38: 6876.39 | C38: 205542 | D38: =C38-C37 -> -57 | E38: =C38-152000 -> 53542 | F38: =D38/$D$2 -> -28.737081 | G38: 32 | H38: 0 | I38: =G38+H38 -> 32 | J38: =IF(L38>0,L38,0) -> 0 | K38: =I38+J38 -> 32 | L38: =F38-(I38-X38) -> -24.217081 | M38: 4.52 | N38: 0 | O38: 0 | P38: =M38-(N38+O38) -> 4.52 | Q38: 0 | R38: 0 | S38: =SUM(P38:R38) -> 4.52 | U38: 0 | V38: 32 | W38: =W37-V38 -> 3866 | X38: =N38+O38+S38+U38+V38 -> 36.52 | Y38: =IF(L38<0,L38*-1,0) -> 24.217081 | Z38: =X38+Y38 -> 60.737081 | AA38: 0.04 | AB38: 27 | AC38: 17 | AD38: =AD37+1 -> 29
A39: 30 | B39: 6876.46 | C39: 205744 | D39: =C39-C38 -> 202 | E39: =C39-152000 -> 53744 | F39: =D39/$D$2 -> 101.84018 | G39: 44 | H39: 0 | I39: =G39+H39 -> 44 | J39: =IF(L39>0,L39,0) -> 93.240181 | K39: =I39+J39 -> 137.24018 | L39: =F39-(I39-X39) -> 93.240181 | M39: 4.4 | N39: 0 | O39: 0 | P39: =M39-(N39+O39) -> 4.4 | Q39: 0 | R39: 0 | S39: =SUM(P39:R39) -> 4.4 | U39: 0 | V39: 31 | W39: =W38-V39 -> 3835 | X39: =N39+O39+S39+U39+V39 -> 35.4 | Y39: =IF(L39<0,L39*-1,0) -> 0 | Z39: =X39+Y39 -> 35.4 | AA39: 0.12 | AB39: 31 | AC39: 22 | AD39: 30
A41: MONTH / CFS | F41: =SUM(F10:F39) -> -101.84018 | G41: =SUM(G10:G39) -> 1172 | H41: =SUM(H10:H39) -> 0 | I41: =SUM(I10:I39) -> 1172 | J41: =SUM(J10:J39) -> 465.34532 | K41: =SUM(K10:K39) -> 1637.3453 | L41: =SUM(L10:L39) -> 185.73982 | M41: =SUM(M10:M39) -> 365.08 | ... S41: =SUM(S10:S39) -> 432.014 | U41: =SUM(U10:U39) -> 0 | V41: =SUM(V10:V39) -> 967 | X41: =SUM(X10:X39) -> 1459.58 | Y41: =SUM(Y10:Y39) -> 279.60551 | Z41: =SUM(Z10:Z39) -> 1739.1855 | AA41: =SUM(AA10:AA39) -> 1.92 | AB41: =AVERAGE(AB10:AB39) -> 52.333333 | AC41: =AVERAGE(AC10:AC39) -> 27.933333 | AD41: Avg
A42: MONTH / AF | D42: =SUM(D10:D39) -> -202 | F42: =F41*$D$2 -> -202 | G42: =G41*$D$2 -> 2324.662 | H42: =H41*$D$2 -> 0 | I42: =I41*$D$2 -> 2324.662 | J42: =J41*$D$2 -> 923.01245 | K42: =K41*$D$2 -> 3247.6744 | L42: =L41*$D$2 -> 368.41493 | M42: =M41*$D$2 -> 724.13618 | ... S42: =S41*$D$2 -> 856.89977 | U42: =U41*$D$2 -> 0 | V42: =V41*$D$2 -> 1918.0445 | X42: =X41*$D$2 -> 2895.0769 | Y42: =Y41*$D$2 -> 554.59752 | Z42: =Z41*$D$2 -> 3449.6744 | AB42: =MAX(AB10:AB39) -> 67 | AC42: =MAX(AC10:AC39) -> 39 | AD42: HI
A44: SEASON / CFS | AB44: =MIN(AB10:AB39) -> 27 | AC44: =MIN(AC10:AC39) -> 6 | AD44: LO
A45: SEASON / AF
A47: YTD / CFS | F47: =F8+F41 -> -101.84018 | G47: =G8+G41 -> 1172 | H47: =H8+H41 -> 0 | I47: =I8+I41 -> 1172 | J47: =J8+J41 -> 465.34532 | K47: =K8+K41 -> 1637.3453 | L47: =L8+L41 -> 185.73982 | M47: =M8+M41 -> 365.08 | ... S47: =S8+S41 -> 432.014 | U47: =U8+U41 -> 0 | V47: =V8+V41 -> 967 | W47: =W39 -> 3835 | X47: =X8+X41 -> 1459.58 | Y47: =Y8+Y41 -> 279.60551 | Z47: =Z8+Z41 -> 1739.1855 | AA47: =AA8+AA41 -> 1.92
A48: YTD / AF | D48: =D8+D42 -> -202 | E48: =E39 -> 53744 | F48: =F47*$D$2 -> -202 | G48: =G47*$D$2 -> 2324.662 | H48: =H47*$D$2 -> 0 | I48: =I47*$D$2 -> 2324.662 | J48: =J47*$D$2 -> 923.01245 | K48: =K47*$D$2 -> 3247.6744 | L48: =L47*$D$2 -> 368.41493 | M48: =M47*$D$2 -> 724.13618 | ... Z48: =Z47*$D$2 -> 3449.6744

Sheet DEC
K1: MC PHEE RESERVOIR IN/OUT FLOW TABULATION
A2: AF/cfs CONVERT FACTOR | D2: 1.9835 | K2: DECEMBER "2001"
A4: DATE | B4: RESERV | C4: RESERV | D4: AC FT | E4: ACTIVE | F4: CONV TO | G4: DOLORES | H4: LOST | I4: RECORDED | J4: CALC | K4: TOTAL | L4: CALC | M4: DOLORES TUNNEL | Q4: LONE | R4: U | S4: TOTAL | T4: MVI | U4: DV CR | V4: BELOW | W4: REMAIN | X4: RECORDED | Y4: CALC | Z4: TOTAL | AA4: RAIN | AB4: MAX | AC4: MIN | AD4: DATE
A5: "DEC" | B5: ELEV | C5: AC FT | D5: CHANGE | E5: CAP | F5: CFS | G5: RIVER | H5: CANYON | I5: INFLOW | J5: INFLOW | K5: INFLOW | L5: INF/OTF | M5: TOT DIV | N5: WETLAND | O5: UTE F&R | P5: MVI,CTZ | Q5: PINE | R5: LAT | S5: MVI | T5: CALL | U5: CANAL | V5: MC PHEE | W5: RELEASE | X5: OUTFLOW | Y5: OUTFLOW | Z5: OUTFLOW | AB5: TMP | AC5: TMP | AD5: "DEC"
A7: SEASON BAL
A8: YTD | B8: =NOV!B39 -> 6876.46 | C8: =NOV!C39 -> 205744 | D8: =NOV!$D$48 -> -202 | E8: =NOV!$E$39 -> 53744 | F8: =NOV!F47 -> -101.84018 | G8: =NOV!G47 -> 1172 | H8: =NOV!H47 -> 0 | I8: =NOV!I47 -> 1172 | J8: =NOV!J47 -> 465.34532 | K8: =NOV!K47 -> 1637.3453 | L8: =NOV!L47 -> 185.73982 | M8: =NOV!M47 -> 365.08 | ... AA8: =NOV!AA47 -> 1.92
A10: 1 | B10: 6876.47 | C10: 205773 | D10: =C10-C8 -> 29 | E10: =C10-152000 -> 53773 | F10: =D10/$D$2 -> 14.62062 | G10: 48 | H10: 0 | I10: =G10+H10 -> 48 | J10: =IF(L10>0,L10,0) -> 2.0206201 | K10: =I10+J10 -> 50.02062 | L10: =F10-(I10-X10) -> 2.0206201 | M10: 4.4 | N10: 0 | O10: 0 | P10: =M10-(N10+O10) -> 4.4 | Q10: 0 | R10: 0 | S10: =SUM(P10:R10) -> 4.4 | U10: 0 | V10: 31 | W10: =W8-V10 -> 3804 | X10: =N10+O10+S10+U10+V10 -> 35.4 | Y10: =IF(L10<0,L10*-1,0) -> 0 | Z10: =X10+Y10 -> 35.4 | AA10: 0 | AB10: 38 | AC10: 17 | AD10: 1
A11: =A10+1 -> 2 | B11: 6876.49 | C11: 205830 | D11: =C11-C10 -> 57 | E11: =C11-152000 -> 53830 | F11: =D11/$D$2 -> 28.737081 | G11: 44 | H11: 0 | I11: =G11+H11 -> 44 | J11: =IF(L11>0,L11,0) -> 19.037081 | K11: =I11+J11 -> 63.037081 | L11: =F11-(I11-X11) -> 19.037081 | M11: 4.3 | N11: 0 | O11: 0 | P11: =M11-(N11+O11) -> 4.3 | Q11: 0 | R11: 0 | S11: =SUM(P11:R11) -> 4.3 | U11: 0 | V11: 30 | W11: =W10-V11 -> 3774 | X11: =N11+O11+S11+U11+V11 -> 34.3 | Y11: =IF(L11<0,L11*-1,0) -> 0 | Z11: =X11+Y11 -> 34.3 | AA11: 0 | AB11: 45 | AC11: 33 | AD11: =AD10+1 -> 2
A12: =A11+1 -> 3 | B12: 6876.51 | C12: 205888 | D12: =C12-C11 -> 58 | E12: =C12-152000 -> 53888 | F12: =D12/$D$2 -> 29.24124 | G12: 58 | H12: 0 | I12: =G12+H12 -> 58 | J12: =IF(L12>0,L12,0) -> 5.9912402 | K12: =I12+J12 -> 63.99124 | L12: =F12-(I12-X12) -> 5.9912402 | M12: 3.75 | N12: 0 | O12: 0 | P12: =M12-(N12+O12) -> 3.75 | Q12: 0 | R12: 0 | S12: =SUM(P12:R12) -> 3.75 | U12: 0 | V12: 31 | W12: =W11-V12 -> 3743 | X12: =N12+O12+S12+U12+V12 -> 34.75 | Y12: =IF(L12<0,L12*-1,0) -> 0 | Z12: =X12+Y12 -> 34.75 | AA12: 0 | AB12: 46 | AC12: 33 | AD12: =AD11+1 -> 3
A13: =A12+1 -> 4 | B13: 6876.54 | C13: 205975 | D13: =C13-C12 -> 87 | E13: =C13-152000 -> 53975 | F13: =D13/$D$2 -> 43.86186 | G13: 62 | H13: 0 | I13: =G13+H13 -> 62 | J13: =IF(L13>0,L13,0) -> 15.04186 | K13: =I13+J13 -> 77.04186 | L13: =F13-(I13-X13) -> 15.04186 | M13: 3.18 | N13: 0 | O13: 0 | P13: =M13-(N13+O13) -> 3.18 | Q13: 0 | R13: 0 | S13: =SUM(P13:R13) -> 3.18 | U13: 0 | V13: 30 | W13: =W12-V13 -> 3713 | X13: =N13+O13+S13+U13+V13 -> 33.18 | Y13: =IF(L13<0,L13*-1,0) -> 0 | Z13: =X13+Y13 -> 33.18 | AA13: 0.16 | AB13: 42 | AC13: 25 | AD13: =AD12+1 -> 4
A14: =A13+1 -> 5 | B14: 6876.56 | C14: 206033 | D14: =C14-C13 -> 58 | E14: =C14-152000 -> 54033 | F14: =D14/$D$2 -> 29.24124 | G14: 62 | H14: 0 | I14: =G14+H14 -> 62 | J14: =IF(L14>0,L14,0) -> 0.32124023 | K14: =I14+J14 -> 62.32124 | L14: =F14-(I14-X14) -> 0.32124023 | M14: 3.08 | N14: 0 | O14: 0 | P14: =M14-(N14+O14) -> 3.08 | Q14: 0 | R14: 0 | S14: =SUM(P14:R14) -> 3.08 | U14: 0 | V14: 30 | W14: =W13-V14 -> 3683 | X14: =N14+O14+S14+U14+V14 -> 33.08 | Y14: =IF(L14<0,L14*-1,0) -> 0 | Z14: =X14+Y14 -> 33.08 | AA14: 0 | AB14: 34 | AC14: 13 | AD14: =AD13+1 -> 5
A15: =A14+1 -> 6 | B15: 6876.55 | C15: 206004 | D15: =C15-C14 -> -29 | E15: =C15-152000 -> 54004 | F15: =D15/$D$2 -> -14.62062 | G15: 42 | H15: 0 | I15: =G15+H15 -> 42 | J15: =IF(L15>0,L15,0) -> 0 | K15: =I15+J15 -> 42 | L15: =F15-(I15-X15) -> -22.47062 | M15: 3.15 | N15: 0 | O15: 0 | P15: =M15-(N15+O15) -> 3.15 | Q15: 0 | R15: 0 | S15: =SUM(P15:R15) -> 3.15 | U15: 0 | V15: 31 | W15: =W14-V15 -> 3652 | X15: =N15+O15+S15+U15+V15 -> 34.15 | Y15: =IF(L15<0,L15*-1,0) -> 22.47062 | Z15: =X15+Y15 -> 56.62062 | AA15: 0 | AB15: 41 | AC15: 15 | AD15: =AD14+1 -> 6
A16: =A15+1 -> 7 | B16: 6876.55 | C16: 206004 | D16: =C16-C15 -> 0 | E16: =C16-152000 -> 54004 | F16: =D16/$D$2 -> 0 | G16: 47 | H16: 0 | I16: =G16+H16 -> 47 | J16: =IF(L16>0,L16,0) -> 0 | K16: =I16+J16 -> 47 | L16: =F16-(I16-X16) -> -12.61 | M16: 3.39 | N16: 0 | O16: 0 | P16: =M16-(N16+O16) -> 3.39 | Q16: 0 | R16: 0 | S16: =SUM(P16:R16) -> 3.39 | U16: 0 | V16: 31 | W16: =W15-V16 -> 3621 | X16: =N16+O16+S16+U16+V16 -> 34.39 | Y16: =IF(L16<0,L16*-1,0) -> 12.61 | Z16: =X16+Y16 -> 47 | AA16: 0 | AB16: 37 | AC16: 18 | AD16: =AD15+1 -> 7
A17: =A16+1 -> 8 | B17: 6876.54 | C17: 205975 | D17: =C17-C16 -> -29 | E17: =C17-152000 -> 53975 | F17: =D17/$D$2 -> -14.62062 | G17: 43 | H17: 0 | I17: =G17+H17 -> 43 | J17: =IF(L17>0,L17,0) -> 0 | K17: =I17+J17 -> 43 | L17: =F17-(I17-X17) -> -23.23062 | M17: 3.39 | N17: 0 | O17: 0 | P17: =M17-(N17+O17) -> 3.39 | Q17: 0 | R17: 0 | S17: =SUM(P17:R17) -> 3.39 | U17: 0 | V17: 31 | W17: =W16-V17 -> 3590 | X17: =N17+O17+S17+U17+V17 -> 34.39 | Y17: =IF(L17<0,L17*-1,0) -> 23.23062 | Z17: =X17+Y17 -> 57.62062 | AA17: 0 | AB17: 40 | AC17: 11 | AD17: =AD16+1 -> 8
A18: =A17+1 -> 9 | B18: 6876.53 | C18: 205946 | D18: =C18-C17 -> -29 | E18: =C18-152000 -> 53946 | F18: =D18/$D$2 -> -14.62062 | G18: 42 | H18: 0 | I18: =G18+H18 -> 42 | J18: =IF(L18>0,L18,0) -> 0 | K18: =I18+J18 -> 42 | L18: =F18-(I18-X18) -> -22.23062 | M18: 3.39 | N18: 0 | O18: 0 | P18: =M18-(N18+O18) -> 3.39 | Q18: 0 | R18: 0 | S18: =SUM(P18:R18) -> 3.39 | U18: 0 | V18: 31 | W18: =W17-V18 -> 3559 | X18: =N18+O18+S18+U18+V18 -> 34.39 | Y18: =IF(L18<0,L18*-1,0) -> 22.23062 | Z18: =X18+Y18 -> 56.62062 | AA18: 0 | AB18: 46 | AC18: 14 | AD18: =AD17+1 -> 9
A19: =A18+1 -> 10 | B19: 6876.52 | C19: 205917 | D19: =C19-C18 -> -29 | E19: =C19-152000 -> 53917 | F19: =D19/$D$2 -> -14.62062 | G19: 49 | H19: 0 | I19: =G19+H19 -> 49 | J19: =IF(L19>0,L19,0) -> 0 | K19: =I19+J19 -> 49 | L19: =F19-(I19-X19) -> -28.92062 | M19: 3.7 | N19: 0 | O19: 0 | P19: =M19-(N19+O19) -> 3.7 | Q19: 0 | R19: 0 | S19: =SUM(P19:R19) -> 3.7 | U19: 0 | V19: 31 | W19: =W18-V19 -> 3528 | X19: =N19+O19+S19+U19+V19 -> 34.7 | Y19: =IF(L19<0,L19*-1,0) -> 28.92062 | Z19: =X19+Y19 -> 63.62062 | AA19: 0.16 | AB19: 40 | AC19: 22 | AD19: =AD18+1 -> 10
A20: =A19+1 -> 11 | B20: 6876.54 | C20: 205975 | D20: =C20-C19 -> 58 | E20: =C20-152000 -> 53975 | F20: =D20/$D$2 -> 29.24124 | G20: 54 | H20: 0 | I20: =G20+H20 -> 54 | J20: =IF(L20>0,L20,0) -> 10.20124 | K20: =I20+J20 -> 64.20124 | L20: =F20-(I20-X20) -> 10.20124 | M20: 3.96 | N20: 0 | O20: 0 | P20: =M20-(N20+O20) -> 3.96 | Q20: 0 | R20: 0 | S20: =SUM(P20:R20) -> 3.96 | U20: 0 | V20: 31 | W20: =W19-V20 -> 3497 | X20: =N20+O20+S20+U20+V20 -> 34.96 | Y20: =IF(L20<0,L20*-1,0) -> 0 | Z20: =X20+Y20 -> 34.96 | AA20: 0 | AB20: 35 | AC20: 14 | AD20: =AD19+1 -> 11
A21: =A20+1 -> 12 | B21: 6876.57 | C21: 206062 | D21: =C21-C20 -> 87 | E21: =C21-152000 -> 54062 | F21: =D21/$D$2 -> 43.86186 | G21: 54 | H21: 0 | I21: =G21+H21 -> 54 | J21: =IF(L21>0,L21,0) -> 24.71186 | K21: =I21+J21 -> 78.71186 | L21: =F21-(I21-X21) -> 24.71186 | M21: 3.85 | N21: 0 | O21: 0 | P21: =M21-(N21+O21) -> 3.85 | Q21: 0 | R21: 0 | S21: =SUM(P21:R21) -> 3.85 | U21: 0 | V21: 31 | W21: =W20-V21 -> 3466 | X21: =N21+O21+S21+U21+V21 -> 34.85 | Y21: =IF(L21<0,L21*-1,0) -> 0 | Z21: =X21+Y21 -> 34.85 | AA21: 0 | AB21: 29 | AC21: 9 | AD21: =AD20+1 -> 12
A22: =A21+1 -> 13 | B22: 6876.57 | C22: 206062 | D22: =C22-C21 -> 0 | E22: =C22-152000 -> 54062 | F22: =D22/$D$2 -> 0 | G22: 49 | H22: 0 | I22: =G22+H22 -> 49 | J22: =IF(L22>0,L22,0) -> 0 | K22: =I22+J22 -> 49 | L22: =F22-(I22-X22) -> -13.94 | M22: 4.06 | N22: 0 | O22: 0 | P22: =M22-(N22+O22) -> 4.06 | Q22: 0 | R22: 0 | S22: =SUM(P22:R22) -> 4.06 | U22: 0 | V22: 31 | W22: =W21-V22 -> 3435 | X22: =N22+O22+S22+U22+V22 -> 35.06 | Y22: =IF(L22<0,L22*-1,0) -> 13.94 | Z22: =X22+Y22 -> 49 | AA22: 0 | AB22: 30 | AC22: 6 | AD22: =AD21+1 -> 13
... A38: =A37+1 -> 29 | B38: 6876.61 | C38: 206177 | D38: =C38-C37 -> 58 | E38: =C38-152000 -> 54177 | F38: =D38/$D$2 -> 29.24124 | G38: 48 | H38: 0 | I38: =G38+H38 -> 48 | J38: =IF(L38>0,L38,0) -> 17.37124 | K38: =I38+J38 -> 65.37124 | L38: =F38-(I38-X38) -> 17.37124 | M38: 5.13 | N38: 0 | O38: 0 | P38: =M38-(N38+O38) -> 5.13 | Q38: 0 | R38: 0 | S38: =SUM(P38:R38) -> 5.13 | U38: 0 | V38: 31 | W38: =W37-V38 -> 2939 | X38: =N38+O38+S38+U38+V38 -> 36.13 | Y38: =IF(L38<0,L38*-1,0) -> 0 | Z38: =X38+Y38 -> 36.13 | AA38: 0.34 | AB38: 34 | AC38: 20 | AD38: =AD37+1 -> 29
A39: 30 | B39: 6876.68 | C39: 206379 | D39: =C39-C38 -> 202 | E39: =C39-152000 -> 54379 | F39: =D39/$D$2 -> 101.84018 | G39: 50 | H39: 0 | I39: =G39+H39 -> 50 | J39: =IF(L39>0,L39,0) -> 87.970181 | K39: =I39+J39 -> 137.97018 | L39: =F39-(I39-X39) -> 87.970181 | M39: 5.13 | N39: 0 | O39: 0 | P39: =M39-(N39+O39) -> 5.13 | Q39: 0 | R39: 0 | S39: =SUM(P39:R39) -> 5.13 | U39: 0 | V39: 31 | W39: =W38-V39 -> 2908 | X39: =N39+O39+S39+U39+V39 -> 36.13 | Y39: =IF(L39<0,L39*-1,0) -> 0 | Z39: =X39+Y39 -> 36.13 | AA39: 0.1 | AB39: 34 | AC39: 15 | AD39: 30
A40: 31 | B40: 6876.68 | C40: 206379 | D40: =C40-C39 -> 0 | E40: =C40-152000 -> 54379 | F40: =D40/$D$2 -> 0 | G40: 50 | H40: 0 | I40: =G40+H40 -> 50 | J40: =IF(L40>0,L40,0) -> 0 | K40: =I40+J40 -> 50 | L40: =F40-(I40-X40) -> -13.87 | M40: 5.13 | N40: 0 | O40: 0 | P40: =M40-(N40+O40) -> 5.13 | Q40: 0 | R40: 0 | S40: =SUM(P40:R40) -> 5.13 | U40: 0 | V40: 31 | W40: =W39-V40 -> 2877 | X40: =N40+O40+S40+U40+V40 -> 36.13 | Y40: =IF(L40<0,L40*-1,0) -> 13.87 | Z40: =X40+Y40 -> 50 | AA40: 0 | AB40: 35 | AC40: 15 | AD40: 31
A42: MONTH / CFS | F42: =SUM(F10:F40) -> 320.14116 | G42: =SUM(G10:G40) -> 1521 | H42: =SUM(H10:H40) -> 0 | I42: =SUM(I10:I40) -> 1521 | J42: =SUM(J10:J40) -> 187.02718 | K42: =SUM(K10:K40) -> 1708.0272 | L42: =SUM(L10:L40) -> -106.51884 | M42: =SUM(M10:M40) -> 136.34 | ... S42: =SUM(S10:S40) -> 136.34 | U42: =SUM(U10:U40) -> 0 | V42: =SUM(V10:V40) -> 958 | X42: =SUM(X10:X40) -> 1094.34 | Y42: =SUM(Y10:Y40) -> 293.54602 | Z42: =SUM(Z10:Z40) -> 1387.886 | AA42: =SUM(AA10:AA40) -> 0.85 | AB42: =AVERAGE(AB10:AB40) -> 38.16129 | AC42: =AVERAGE(AC10:AC40) -> 14.709677 | AD42: Avg
A43: MONTH / AF | D43: =SUM(D10:D40) -> 635 | F43: =F42*$D$2 -> 635 | G43: =G42*$D$2 -> 3016.9035 | H43: =H42*$D$2 -> 0 | I43: =I42*$D$2 -> 3016.9035 | J43: =J42*$D$2 -> 370.96842 | K43: =K42*$D$2 -> 3387.8719 | L43: =L42*$D$2 -> -211.28011 | M43: =M42*$D$2 -> 270.43039 | ... S43: =S42*$D$2 -> 270.43039 | U43: =U42*$D$2 -> 0 | V43: =V42*$D$2 -> 1900.193 | X43: =X42*$D$2 -> 2170.6234 | Y43: =Y42*$D$2 -> 582.24853 | Z43: =Z42*$D$2 -> 2752.8719 | AB43: =MAX(AB10:AB40) -> 49 | AC43: =MAX(AC10:AC40) -> 33 | AD43: HI
A45: SEASON / CFS | AB45: =MIN(AB10:AB40) -> 28 | AC45: =MIN(AC10:AC40) -> 2 | AD45: LO
A46: SEASON / AF
A48: YTD / CFS | F48: =F8+F42 -> 218.30098 | G48: =G8+G42 -> 2693 | H48: =H8+H42 -> 0 | I48: =I8+I42 -> 2693 | J48: =J8+J42 -> 652.37251 | K48: =K8+K42 -> 3345.3725 | L48: =L8+L42 -> 79.220983 | M48: =M8+M42 -> 501.42 | ... S48: =S8+S42 -> 568.354 | U48: =U8+U42 -> 0 | V48: =V8+V42 -> 1925 | W48: =W40 -> 2877 | X48: =X8+X42 -> 2553.92 | Y48: =Y8+Y42 -> 573.15153 | Z48: =Z8+Z42 -> 3127.0715 | AA48: =AA8+AA42 -> 2.77
A49: YTD / AF | D49: =D8+D43 -> 433 | E49: =E40 -> 54379 | F49: =F48*$D$2 -> 433 | G49: =G48*$D$2 -> 5341.5655 | H49: =H48*$D$2 -> 0 | I49: =I48*$D$2 -> 5341.5655 | J49: =J48*$D$2 -> 1293.9809 | K49: =K48*$D$2 -> 6635.5464 | L49: =L48*$D$2 -> 157.13482 | M49: =M48*$D$2 -> 994.56657 | ... Z49: =Z48*$D$2 -> 6202.5464

Sheet JAN
K1: MC PHEE RESERVOIR IN/OUT FLOW TABULATION
A2: AF/cfs CONVERT FACTOR | D2: 1.9835 | K2: JANUARY "2002"
A4: DATE | B4: RESERV | C4: RESERV | D4: AC FT | E4: ACTIVE | F4: CONV TO | G4: DOLORES | H4: LOST | I4: RECORDED | J4: CALC | K4: TOTAL | L4: CALC | M4: DOLORES TUNNEL | Q4: LONE | R4: U | S4: TOTAL | T4: MVI | U4: DV CR | V4: BELOW | W4: REMAIN | X4: RECORDED | Y4: CALC | Z4: TOTAL | AA4: RAIN | AB4: MAX | AC4: MIN | AD4: DATE
A5: "JAN" | B5: ELEV | C5: AC FT | D5: CHANGE | E5: CAP | F5: CFS | G5: RIVER | H5: CANYON | I5: INFLOW | J5: INFLOW | K5: INFLOW | L5: INF/OTF | M5: TOT DIV | N5: WETLAND | O5: UTE F&R | P5: MVI,CTZ | Q5: PINE | R5: LAT | S5: MVI | T5: CALL | U5: CANAL | V5: MC PHEE | W5: RELEASE | X5: OUTFLOW | Y5: OUTFLOW | Z5: OUTFLOW | AB5: TMP | AC5: TMP | AD5: "JAN"
A7: SEASON BAL
A8: YTD | B8: =DEC!B40 -> 6876.68 | C8: =DEC!C40 -> 206379 | D8: =DEC!$D$49 -> 433 | E8: =DEC!$E$40 -> 54379 | F8: =DEC!F48 -> 218.30098 | G8: =DEC!G48 -> 2693 | H8: =DEC!H48 -> 0 | I8: =DEC!I48 -> 2693 | J8: =DEC!J48 -> 652.37251 | K8: =DEC!K48 -> 3345.3725 | L8: =DEC!L48 -> 79.220983 | M8: =DEC!M48 -> 501.42 | ... AA8: =DEC!AA48 -> 2.77
A10: 1 | B10: 6876.68 | C10: 206379 | D10: =C10-C8 -> 0 | E10: =C10-152000 -> 54379 | F10: =D10/$D$2 -> 0 | G10: 46 | H10: 0 | I10: =G10+H10 -> 46 | J10: =IF(L10>0,L10,0) -> 0 | K10: =I10+J10 -> 46 | L10: =F10-(I10-X10) -> -9.9 | M10: 5.1 | N10: 0 | O10: 0 | P10: =M10-(N10+O10) -> 5.1 | Q10: 0 | R10: 0 | S10: =SUM(P10:R10) -> 5.1 | U10: 0 | V10: 31 | W10: =W8-V10 -> 2846 | X10: =N10+O10+S10+U10+V10 -> 36.1 | Y10: =IF(L10<0,L10*-1,0) -> 9.9 | Z10: =X10+Y10 -> 46 | AA10: 0 | AB10: 37 | AC10: 8 | AD10: 1
A11: =A10+1 -> 2 | B11: 6876.68 | C11: 206379 | D11: =C11-C10 -> 0 | E11: =C11-152000 -> 54379 | F11: =D11/$D$2 -> 0 | G11: 43 | H11: 0 | I11: =G11+H11 -> 43 | J11: =IF(L11>0,L11,0) -> 0 | K11: =I11+J11 -> 43 | L11: =F11-(I11-X11) -> -6.9 | M11: 5.1 | N11: 0 | O11: 0 | P11: =M11-(N11+O11) -> 5.1 | Q11: 0 | R11: 0 | S11: =SUM(P11:R11) -> 5.1 | U11: 0 | V11: 31 | W11: =W10-V11 -> 2815 | X11: =N11+O11+S11+U11+V11 -> 36.1 | Y11: =IF(L11<0,L11*-1,0) -> 6.9 | Z11: =X11+Y11 -> 43 | AA11: 0 | AB11: 32 | AC11: 4 | AD11: =AD10+1 -> 2
A12: =A11+1 -> 3 | B12: 6876.68 | C12: 206379 | D12: =C12-C11 -> 0 | E12: =C12-152000 -> 54379 | F12: =D12/$D$2 -> 0 | G12: 42 | H12: 0 | I12: =G12+H12 -> 42 | J12: =IF(L12>0,L12,0) -> 0 | K12: =I12+J12 -> 42 | L12: =F12-(I12-X12) -> -5.9 | M12: 5.1 | N12: 0 | O12: 0 | P12: =M12-(N12+O12) -> 5.1 | Q12: 0 | R12: 0 | S12: =SUM(P12:R12) -> 5.1 | U12: 0 | V12: 31 | W12: =W11-V12 -> 2784 | X12: =N12+O12+S12+U12+V12 -> 36.1 | Y12: =IF(L12<0,L12*-1,0) -> 5.9 | Z12: =X12+Y12 -> 42 | AA12: 0 | AB12: 35 | AC12: 8 | AD12: =AD11+1 -> 3
A13: =A12+1 -> 4 | B13: 6876.68 | C13: 206379 | D13: =C13-C12 -> 0 | E13: =C13-152000 -> 54379 | F13: =D13/$D$2 -> 0 | G13: 45 | H13: 0 | I13: =G13+H13 -> 45 | J13: =IF(L13>0,L13,0) -> 0 | K13: =I13+J13 -> 45 | L13: =F13-(I13-X13) -> -8.9 | M13: 5.1 | N13: 0 | O13: 0 | P13: =M13-(N13+O13) -> 5.1 | Q13: 0 | R13: 0 | S13: =SUM(P13:R13) -> 5.1 | U13: 0 | V13: 31 | W13: =W12-V13 -> 2753 | X13: =N13+O13+S13+U13+V13 -> 36.1 | Y13: =IF(L13<0,L13*-1,0) -> 8.9 | Z13: =X13+Y13 -> 45 | AA13: 0 | AB13: 32 | AC13: 21 | AD13: =AD12+1 -> 4
A14: =A13+1 -> 5 | B14: 6876.68 | C14: 206379 | D14: =C14-C13 -> 0 | E14: =C14-152000 -> 54379 | F14: =D14/$D$2 -> 0 | G14: 45 | H14: 0.08 | I14: =G14+H14 -> 45.08 | J14: =IF(L14>0,L14,0) -> 0 | K14: =I14+J14 -> 45.08 | L14: =F14-(I14-X14) -> -8.98 | M14: 5.1 | N14: 0 | O14: 0 | P14: =M14-(N14+O14) -> 5.1 | Q14: 0 | R14: 0 | S14: =SUM(P14:R14) -> 5.1 | U14: 0 | V14: 31 | W14: =W13-V14 -> 2722 | X14: =N14+O14+S14+U14+V14 -> 36.1 | Y14: =IF(L14<0,L14*-1,0) -> 8.98 | Z14: =X14+Y14 -> 45.08 | AA14: 0 | AB14: 36 | AC14: 9 | AD14: =AD13+1 -> 5
A15: =A14+1 -> 6 | B15: 6876.68 | C15: 206379 | D15: =C15-C14 -> 0 | E15: =C15-152000 -> 54379 | F15: =D15/$D$2 -> 0 | G15: 43 | H15: 0.09 | I15: =G15+H15 -> 43.09 | J15: =IF(L15>0,L15,0) -> 0 | K15: =I15+J15 -> 43.09 | L15: =F15-(I15-X15) -> -6.99 | M15: 5.1 | N15: 0 | O15: 0 | P15: =M15-(N15+O15) -> 5.1 | Q15: 0 | R15: 0 | S15: =SUM(P15:R15) -> 5.1 | U15: 0 | V15: 31 | W15: =W14-V15 -> 2691 | X15: =N15+O15+S15+U15+V15 -> 36.1 | Y15: =IF(L15<0,L15*-1,0) -> 6.99 | Z15: =X15+Y15 -> 43.09 | AA15: 0 | AB15: 44 | AC15: 19 | AD15: =AD14+1 -> 6
A16: =A15+1 -> 7 | B16: 6876.68 | C16: 206379 | D16: =C16-C15 -> 0 | E16: =C16-152000 -> 54379 | F16: =D16/$D$2 -> 0 | G16: 43 | H16: 0.22 | I16: =G16+H16 -> 43.22 | J16: =IF(L16>0,L16,0) -> 0 | K16: =I16+J16 -> 43.22 | L16: =F16-(I16-X16) -> -7.32 | M16: 4.9 | N16: 0 | O16: 0 | P16: =M16-(N16+O16) -> 4.9 | Q16: 0 | R16: 0 | S16: =SUM(P16:R16) -> 4.9 | U16: 0 | V16: 31 | W16: =W15-V16 -> 2660 | X16: =N16+O16+S16+U16+V16 -> 35.9 | Y16: =IF(L16<0,L16*-1,0) -> 7.32 | Z16: =X16+Y16 -> 43.22 | AA16: 0 | AB16: 47 | AC16: 22 | AD16: =AD15+1 -> 7
A17: =A16+1 -> 8 | B17: 6876.68 | C17: 206379 | D17: =C17-C16 -> 0 | E17: =C17-152000 -> 54379 | F17: =D17/$D$2 -> 0 | G17: 44 | H17: 0.16 | I17: 36 | J17: =IF(L17>0,L17,0) -> 0 | K17: =I17+J17 -> 36 | L17: =F17-(I17-X17) -> -0.24 | M17: 4.76 | N17: 0 | O17: 0 | P17: =M17-(N17+O17) -> 4.76 | Q17: 0 | R17: 0 | S17: =SUM(P17:R17) -> 4.76 | U17: 0 | V17: 31 | W17: =W16-V17 -> 2629 | X17: =N17+O17+S17+U17+V17 -> 35.76 | Y17: =IF(L17<0,L17*-1,0) -> 0.24 | Z17: =X17+Y17 -> 36 | AA17: 0 | AB17: 52 | AC17: 25 | AD17: =AD16+1 -> 8
A18: =A17+1 -> 9 | B18: 6876.68 | C18: 206379 | D18: =C18-C17 -> 0 | E18: =C18-152000 -> 54379 | F18: =D18/$D$2 -> 0 | G18: 46 | H18: 0.21 | I18: 36 | J18: =IF(L18>0,L18,0) -> 0 | K18: =I18+J18 -> 36 | L18: =F18-(I18-X18) -> -0.24 | M18: 4.76 | N18: 0 | O18: 0 | P18: =M18-(N18+O18) -> 4.76 | Q18: 0 | R18: 0 | S18: =SUM(P18:R18) -> 4.76 | U18: 0 | V18: 31 | W18: =W17-V18 -> 2598 | X18: =N18+O18+S18+U18+V18 -> 35.76 | Y18: =IF(L18<0,L18*-1,0) -> 0.24 | Z18: =X18+Y18 -> 36 | AA18: 0 | AB18: 50 | AC18: 29 | AD18: =AD17+1 -> 9
A19: =A18+1 -> 10 | B19: 6876.69 | C19: 206408 | D19: =C19-C18 -> 29 | E19: =C19-152000 -> 54408 | F19: =D19/$D$2 -> 14.62062 | G19: 48 | H19: 0.23 | I19: 49.6 | J19: =IF(L19>0,L19,0) -> 0 | K19: =I19+J19 -> 49.6 | L19: =F19-(I19-X19) -> -0.33937988 | M19: 4.64 | N19: 0 | O19: 0 | P19: =M19-(N19+O19) -> 4.64 | Q19: 0 | R19: 0 | S19: =SUM(P19:R19) -> 4.64 | U19: 0 | V19: 30 | W19: =W18-V19 -> 2568 | X19: =N19+O19+S19+U19+V19 -> 34.64 | Y19: =IF(L19<0,L19*-1,0) -> 0.33937988 | Z19: =X19+Y19 -> 34.97938 | AA19: 0 | AB19: 43 | AC19: 24 | AD19: =AD18+1 -> 10
A20: =A19+1 -> 11 | B20: 6876.69 | C20: 206408 | D20: =C20-C19 -> 0 | E20: =C20-152000 -> 54408 | F20: =D20/$D$2 -> 0 | G20: 43 | H20: 0.24 | I20: 31.1 | J20: =IF(L20>0,L20,0) -> 3.3 | K20: =I20+J20 -> 34.4 | L20: =F20-(I20-X20) -> 3.3 | M20: 4.4 | N20: 0 | O20: 0 | P20: =M20-(N20+O20) -> 4.4 | Q20: 0 | R20: 0 | S20: =SUM(P20:R20) -> 4.4 | U20: 0 | V20: 30 | W20: =W19-V20 -> 2538 | X20: =N20+O20+S20+U20+V20 -> 34.4 | Y20: =IF(L20<0,L20*-1,0) -> 0 | Z20: =X20+Y20 -> 34.4 | AA20: 0 | AB20: 50 | AC20: 17 | AD20: =AD19+1 -> 11
A21: =A20+1 -> 12 | B21: 6876.69 | C21: 206408 | D21: =C21-C20 -> 0 | E21: =C21-152000 -> 54408 | F21: =D21/$D$2 -> 0 | G21: 43 | H21: 0.27 | I21: 34.1 | J21: =IF(L21>0,L21,0) -> 0.3 | K21: =I21+J21 -> 34.4 | L21: =F21-(I21-X21) -> 0.3 | M21: 4.4 | N21: 0 | O21: 0 | P21: =M21-(N21+O21) -> 4.4 | Q21: 0 | R21: 0 | S21: =SUM(P21:R21) -> 4.4 | U21: 0 | V21: 30 | W21: =W20-V21 -> 2508 | X21: =N21+O21+S21+U21+V21 -> 34.4 | Y21: =IF(L21<0,L21*-1,0) -> 0 | Z21: =X21+Y21 -> 34.4 | AA21: 0 | AB21: 48 | AC21: 23 | AD21: =AD20+1 -> 12
A22: 13 | B22: 6876.69 | C22: 206408 | D22: =C22-C21 -> 0 | E22: =C22-152000 -> 54408 | F22: =D22/$D$2 -> 0 | G22: 43 | H22: 0.32 | I22: 34.1 | J22: =IF(L22>0,L22,0) -> 0.3 | K22: =I22+J22 -> 34.4 | L22: =F22-(I22-X22) -> 0.3 | M22: 4.4 | N22: 0 | O22: 0 | P22: =M22-(N22+O22) -> 4.4 | Q22: 0 | R22: 0 | S22: =SUM(P22:R22) -> 4.4 | U22: 0 | V22: 30 | W22: =W21-V22 -> 2478 | X22: =N22+O22+S22+U22+V22 -> 34.4 | Y22: =IF(L22<0,L22*-1,0) -> 0 | Z22: =X22+Y22 -> 34.4 | AA22: 0 | AB22: 38 | AC22: 18 | AD22: =AD21+1 -> 13
A23: =A22+1 -> 14 | B23: 6876.69 | C23: 206408 | D23: =C23-C22 -> 0 | E23: =C23-152000 -> 54408 | F23: =D23/$D$2 -> 0 | G23: 41 | H23: 0.24 | I23: =G23+H23 -> 41.24 | J23: =IF(L23>0,L23,0) -> 0 | K23: =I23+J23 -> 41.24 | L23: =F23-(I23-X23) -> -6.84 | M23: 4.4 | N23: 0 | O23: 0 | P23: =M23-(N23+O23) -> 4.4 | Q23: 0 | R23: 0 | S23: =SUM(P23:R23) -> 4.4 | U23: 0 | V23: 30 | W23: =W22-V23 -> 2448 | X23: =N23+O23+S23+U23+V23 -> 34.4 | Y23: =IF(L23<0,L23*-1,0) -> 6.84 | Z23: =X23+Y23 -> 41.24 | AA23: 0 | AB23: 41 | AC23: 12 | AD23: =AD22+1 -> 14
A24: =A23+1 -> 15 | B24: 6876.69 | C24: 206408 | D24: =C24-C23 -> 0 | E24: =C24-152000 -> 54408 | F24: =D24/$D$2 -> 0 | G24: 42 | H24: 0.17 | I24: =G24+H24 -> 42.17 | J24: =IF(L24>0,L24,0) -> 0 | K24: =I24+J24 -> 42.17 | L24: =F24-(I24-X24) -> -7.97 | M24: 4.2 | N24: 0 | O24: 0 | P24: =M24-(N24+O24) -> 4.2 | Q24: 0 | R24: 0 | S24: =SUM(P24:R24) -> 4.2 | U24: 0 | V24: 30 | W24: =W23-V24 -> 2418 | X24: =N24+O24+S24+U24+V24 -> 34.2 | Y24: =IF(L24<0,L24*-1,0) -> 7.97 | Z24: =X24+Y24 -> 42.17 | AA24: 0 | AB24: 44 | AC24: 27 | AD24: =AD23+1 -> 15
A25: =A24+1 -> 16 | B25: 6876.7 | C25: 206437 | D25: =C25-C24 -> 29 | E25: =C25-152000 -> 54437 | F25: =D25/$D$2 -> 14.62062 | G25: 46 | H25: 0.21 | I25: =G25+H25 -> 46.21 | J25: =IF(L25>0,L25,0) -> 2.5106201 | K25: =I25+J25 -> 48.72062 | L25: =F25-(I25-X25) -> 2.5106201 | M25: 4.1 | N25: 0 | O25: 0 | P25: =M25-(N25+O25) -> 4.1 | Q25: 0 | R25: 0 | S25: =SUM(P25:R25) -> 4.1 | U25: 0 | V25: 30 | W25: =W24-V25 -> 2388 | X25: =N25+O25+S25+U25+V25 -> 34.1 | Y25: =IF(L25<0,L25*-1,0) -> 0 | Z25: =X25+Y25 -> 34.1 | AA25: 0 | AB25: 39 | AC25: 21 | AD25: =AD24+1 -> 16
A26: =A25+1 -> 17 | B26: 6876.7 | C26: 206437 | D26: =C26-C25 -> 0 | E26: =C26-152000 -> 54437 | F26: =D26/$D$2 -> 0 | G26: 46 | H26: 0.29 | I26: =G26+H26 -> 46.29 | J26: =IF(L26>0,L26,0) -> 0 | K26: =I26+J26 -> 46.29 | L26: =F26-(I26-X26) -> -12.19 | M26: 4.1 | N26: 0 | O26: 0 | P26: =M26-(N26+O26) -> 4.1 | Q26: 0 | R26: 0 | S26: =SUM(P26:R26) -> 4.1 | U26: 0 | V26: 30 | W26: =W25-V26 -> 2358 | X26: =N26+O26+S26+U26+V26 -> 34.1 | Y26: =IF(L26<0,L26*-1,0) -> 12.19 | Z26: =X26+Y26 -> 46.29 | AA26: 0 | AB26: 38 | AC26: 10 | AD26: =AD25+1 -> 17
A27: =A26+1 -> 18 | B27: 6876.71 | C27: 206466 | D27: =C27-C26 -> 29 | E27: =C27-152000 -> 54466 | F27: =D27/$D$2 -> 14.62062 | G27: 42 | H27: 0.38 | I27: =G27+H27 -> 42.38 | J27: =IF(L27>0,L27,0) -> 6.3406201 | K27: =I27+J27 -> 48.72062 | L27: =F27-(I27-X27) -> 6.3406201 | M27: 4.1 | N27: 0 | O27: 0 | P27: =M27-(N27+O27) -> 4.1 | Q27: 0 | R27: 0 | S27: =SUM(P27:R27) -> 4.1 | U27: 0 | V27: 30 | W27: =W26-V27 -> 2328 | X27: =N27+O27+S27+U27+V27 -> 34.1 | Y27: =IF(L27<0,L27*-1,0) -> 0 | Z27: =X27+Y27 -> 34.1 | AA27: 0 | AB27: 30 | AC27: 8 | AD27: =AD26+1 -> 18
A28: =A27+1 -> 19 | B28: 6876.71 | C28: 206466 | D28: =C28-C27 -> 0 | E28: =C28-152000 -> 54466 | F28: =D28/$D$2 -> 0 | G28: 37 | H28: 0.33 | I28: =G28+H28 -> 37.33 | J28: =IF(L28>0,L28,0) -> 0 | K28: =I28+J28 -> 37.33 | L28: =F28-(I28-X28) -> -3.23 | M28: 4.1 | N28: 0 | O28: 0 | P28: =M28-(N28+O28) -> 4.1 | Q28: 0 | R28: 0 | S28: =SUM(P28:R28) -> 4.1 | U28: 0 | V28: 30 | W28: =W27-V28 -> 2298 | X28: =N28+O28+S28+U28+V28 -> 34.1 | Y28: =IF(L28<0,L28*-1,0) -> 3.23 | Z28: =X28+Y28 -> 37.33 | AA28: 0 | AB28: 32 | AC28: 0 | AD28: =AD27+1 -> 19
A29: =A28+1 -> 20 | B29: 6876.71 | C29: 206466 | D29: =C29-C28 -> 0 | E29: =C29-152000 -> 54466 | F29: =D29/$D$2 -> 0 | G29: 40 | H29: 0.3 | I29: =G29+H29 -> 40.3 | J29: =IF(L29>0,L29,0) -> 0 | K29: =I29+J29 -> 40.3 | L29: =F29-(I29-X29) -> -6.2 | M29: 4.1 | N29: 0 | O29: 0 | P29: =M29-(N29+O29) -> 4.1 | Q29: 0 | R29: 0 | S29: =SUM(P29:R29) -> 4.1 | U29: 0 | V29: 30 | W29: =W28-V29 -> 2268 | X29: =N29+O29+S29+U29+V29 -> 34.1 | Y29: =IF(L29<0,L29*-1,0) -> 6.2 | Z29: =X29+Y29 -> 40.3 | AA29: 0 | AB29: 29 | AC29: 12 | AD29: =AD28+1 -> 20
A30: =A29+1 -> 21 | B30: 6876.72 | C30: 206495 | D30: =C30-C29 -> 29 | E30: =C30-152000 -> 54495 | F30: =D30/$D$2 -> 14.62062 | G30: 40 | H30: 0.18 | I30: =G30+H30 -> 40.18 | J30: =IF(L30>0,L30,0) -> 8.5406201 | K30: =I30+J30 -> 48.72062 | L30: =F30-(I30-X30) -> 8.5406201 | M30: 4.1 | N30: 0 | O30: 0 | P30: =M30-(N30+O30) -> 4.1 | Q30: 0 | R30: 0 | S30: =SUM(P30:R30) -> 4.1 | U30: 0 | V30: 30 | W30: =W29-V30 -> 2238 | X30: =N30+O30+S30+U30+V30 -> 34.1 | Y30: =IF(L30<0,L30*-1,0) -> 0 | Z30: =X30+Y30 -> 34.1 | AA30: 0 | AB30: 43 | AC30: 11 | AD30: =AD29+1 -> 21
A31: =A30+1 -> 22 | B31: 6876.72 | C31: 206495 | D31: =C31-C30 -> 0 | E31: =C31-152000 -> 54495 | F31: =D31/$D$2 -> 0 | G31: 41 | H31: 0.06 | I31: =G31+H31 -> 41.06 | J31: =IF(L31>0,L31,0) -> 0 | K31: =I31+J31 -> 41.06 | L31: =F31-(I31-X31) -> -6.76 | M31: 4.3 | N31: 0 | O31: 0 | P31: =M31-(N31+O31) -> 4.3 | Q31: 0 | R31: 0 | S31: =SUM(P31:R31) -> 4.3 | U31: 0 | V31: 30 | W31: =W30-V31 -> 2208 | X31: =N31+O31+S31+U31+V31 -> 34.3 | Y31: =IF(L31<0,L31*-1,0) -> 6.76 | Z31: =X31+Y31 -> 41.06 | AA31: 0 | AB31: 44 | AC31: 21 | AD31: =AD30+1 -> 22
A32: =A31+1 -> 23 | B32: 6876.71 | C32: 206466 | D32: =C32-C31 -> -29 | E32: =C32-152000 -> 54466 | F32: =D32/$D$2 -> -14.62062 | G32: 44 | H32: 0.05 | I32: =G32+H32 -> 44.05 | J32: =IF(L32>0,L32,0) -> 0 | K32: =I32+J32 -> 44.05 | L32: =F32-(I32-X32) -> -24.47062 | M32: 4.2 | N32: 0 | O32: 0 | P32: =M32-(N32+O32) -> 4.2 | Q32: 0 | R32: 0 | S32: =SUM(P32:R32) -> 4.2 | U32: 0 | V32: 30 | W32: =W31-V32 -> 2178 | X32: =N32+O32+S32+U32+V32 -> 34.2 | Y32: =IF(L32<0,L32*-1,0) -> 24.47062 | Z32: =X32+Y32 -> 58.67062 | AA32: 0 | AB32: 29 | AC32: 10 | AD32: =AD31+1 -> 23
A33: =A32+1 -> 24 | B33: 6876.7 | C33: 206437 | D33: =C33-C32 -> -29 | E33: =C33-152000 -> 54437 | F33: =D33/$D$2 -> -14.62062 | G33: 41 | H33: 0.07 | I33: =G33+H33 -> 41.07 | J33: =IF(L33>0,L33,0) -> 0 | K33: =I33+J33 -> 41.07 | L33: =F33-(I33-X33) -> -21.79062 | M33: 3.9 | N33: 0 | O33: 0 | P33: =M33-(N33+O33) -> 3.9 | Q33: 0 | R33: 0 | S33: =SUM(P33:R33) -> 3.9 | U33: 0 | V33: 30 | W33: =W32-V33 -> 2148 | X33: =N33+O33+S33+U33+V33 -> 33.9 | Y33: =IF(L33<0,L33*-1,0) -> 21.79062 | Z33: =X33+Y33 -> 55.69062 | AA33: 0 | AB33: 41 | AC33: 7 | AD33: =AD32+1 -> 24
A34: =A33+1 -> 25 | B34: 6876.69 | C34: 206408 | D34: =C34-C33 -> -29 | E34: =C34-152000 -> 54408 | F34: =D34/$D$2 -> -14.62062 | G34: 40 | H34: 0.07 | I34: =G34+H34 -> 40.07 | J34: =IF(L34>0,L34,0) -> 0 | K34: =I34+J34 -> 40.07 | L34: =F34-(I34-X34) -> -20.59062 | M34: 4.1 | N34: 0 | O34: 0 | P34: =M34-(N34+O34) -> 4.1 | Q34: 0 | R34: 0 | S34: =SUM(P34:R34) -> 4.1 | U34: 0 | V34: 30 | W34: =W33-V34 -> 2118 | X34: =N34+O34+S34+U34+V34 -> 34.1 | Y34: =IF(L34<0,L34*-1,0) -> 20.59062 | Z34: =X34+Y34 -> 54.69062 | AA34: 0 | AB34: 42 | AC34: 12 | AD34: =AD33+1 -> 25
... A38: =A37+1 -> 29 | B38: 6876.68 | C38: 206379 | D38: =C38-C37 -> 58 | E38: =C38-152000 -> 54379 | F38: =D38/$D$2 -> 29.24124 | G38: 44 | H38: 0.22 | I38: =G38+H38 -> 44.22 | J38: =IF(L38>0,L38,0) -> 19.12124 | K38: =I38+J38 -> 63.34124 | L38: =F38-(I38-X38) -> 19.12124 | M38: 4.1 | N38: 0 | O38: 0 | P38: =M38-(N38+O38) -> 4.1 | Q38: 0 | R38: 0 | S38: =SUM(P38:R38) -> 4.1 | U38: 0 | V38: 30 | W38: =W37-V38 -> 1998 | X38: =N38+O38+S38+U38+V38 -> 34.1 | Y38: =IF(L38<0,L38*-1,0) -> 0 | Z38: =X38+Y38 -> 34.1 | AA38: 0 | AB38: 33 | AC38: 25 | AD38: =AD37+1 -> 29
A39: 30 | B39: 6876.69 | C39: 206408 | D39: =C39-C38 -> 29 | E39: =C39-152000 -> 54408 | F39: =D39/$D$2 -> 14.62062 | G39: 43 | H39: 0.22 | I39: =G39+H39 -> 43.22 | J39: =IF(L39>0,L39,0) -> 5.8006201 | K39: =I39+J39 -> 49.02062 | L39: =F39-(I39-X39) -> 5.8006201 | M39: 4.4 | N39: 0 | O39: 0 | P39: =M39-(N39+O39) -> 4.4 | Q39: 0 | R39: 0 | S39: =SUM(P39:R39) -> 4.4 | U39: 0 | V39: 30 | W39: =W38-V39 -> 1968 | X39: =N39+O39+S39+U39+V39 -> 34.4 | Y39: =IF(L39<0,L39*-1,0) -> 0 | Z39: =X39+Y39 -> 34.4 | AA39: 0 | AB39: 27 | AC39: 18 | AD39: 30
A40: 31 | B40: 6876.69 | C40: 206408 | D40: =C40-C39 -> 0 | E40: =C40-152000 -> 54408 | F40: =D40/$D$2 -> 0 | G40: 41 | H40: 0.22 | I40: =G40+H40 -> 41.22 | J40: =IF(L40>0,L40,0) -> 0 | K40: =I40+J40 -> 41.22 | L40: =F40-(I40-X40) -> -8.02 | M40: 4.2 | N40: 0 | O40: 0 | P40: =M40-(N40+O40) -> 4.2 | Q40: 0 | R40: 0 | S40: =SUM(P40:R40) -> 4.2 | U40: 0 | V40: 29 | W40: =W39-V40 -> 1939 | X40: =N40+O40+S40+U40+V40 -> 33.2 | Y40: =IF(L40<0,L40*-1,0) -> 8.02 | Z40: =X40+Y40 -> 41.22 | AA40: 0 | AB40: 27 | AC40: 7 | AD40: 31
AB41: 39
A42: MONTH / CFS | F42: =SUM(F10:F40) -> 14.62062 | G42: =SUM(G10:G40) -> 1331 | H42: =SUM(H10:H40) -> 5.1 | I42: =SUM(I10:I40) -> 1288.57 | J42: =SUM(J10:J40) -> 46.213721 | K42: =SUM(K10:K40) -> 1334.7837 | L42: =SUM(L10:L40) -> -198.68938 | M42: =SUM(M10:M40) -> 137.26 | ... S42: =SUM(S10:S40) -> 137.26 | U42: =SUM(U10:U40) -> 0 | V42: =SUM(V10:V40) -> 938 | X42: =SUM(X10:X40) -> 1075.26 | Y42: =SUM(Y10:Y40) -> 244.9031 | Z42: =SUM(Z10:Z40) -> 1320.1631 | AA42: =SUM(AA10:AA40) -> 0 | AB42: =AVERAGE(AB10:AB40) -> 39.483871 | AC42: =AVERAGE(AC10:AC40) -> 16.16129 | AD42: AVE
A43: MONTH / AF | D43: =SUM(D10:D40) -> 29 | F43: =F42*$D$2 -> 29 | G43: =G42*$D$2 -> 2640.0385 | H43: =H42*$D$2 -> 10.11585 | I43: =I42*$D$2 -> 2555.8786 | J43: =J42*$D$2 -> 91.664915 | K43: =K42*$D$2 -> 2647.5435 | L43: =L42*$D$2 -> -394.10039 | M43: =M42*$D$2 -> 272.25521 | ... S43: =S42*$D$2 -> 272.25521 | U43: =U42*$D$2 -> 0 | V43: =V42*$D$2 -> 1860.523 | X43: =X42*$D$2 -> 2132.7782 | Y43: =Y42*$D$2 -> 485.7653 | Z43: =Z42*$D$2 -> 2618.5435 | AB43: =MAX(AB10:AB40) -> 52 | AC43: =MAX(AC10:AC40) -> 29 | AD43: HI
A45: SEASON / CFS | AB45: =MIN(AB10:AB40) -> 27 | AC45: =MIN(AC10:AC40) -> 0 | AD45: LO
A46: SEASON / AF
A48: YTD / CFS | F48: =F8+F42 -> 232.9216 | G48: =G8+G42 -> 4024 | H48: =H8+H42 -> 5.1 | I48: =I8+I42 -> 3981.57 | J48: =J8+J42 -> 698.58623 | K48: =K8+K42 -> 4680.1562 | L48: =L8+L42 -> -119.4684 | M48: =M8+M42 -> 638.68 | ... S48: =S8+S42 -> 705.614 | U48: =U8+U42 -> 0 | V48: =V8+V42 -> 2863 | W48: =W40 -> 1939 | X48: =X8+X42 -> 3629.18 | Y48: =Y8+Y42 -> 818.05463 | Z48: =Z8+Z42 -> 4447.2346 | AA48: =AA8+AA42 -> 2.77
...

Sheet FEB
K1: MC PHEE RESERVOIR IN/OUT FLOW TABULATION
A2: AF/cfs CONVERT FACTOR | D2: 1.9835 | K2: FEBRUARY "2002"
A4: DATE | B4: RESERV | C4: RESERV | D4: AC FT | E4: ACTIVE | F4: CONV TO | G4: DOLORES | H4: LOST | I4: RECORDED | J4: CALC | K4: TOTAL | L4: CALC | M4: DOLORES TUNNEL | Q4: LONE | R4: U | S4: TOTAL | T4: MVI | U4: DV CR | V4: BELOW | W4: REMAIN | X4: RECORDED | Y4: CALC | Z4: TOTAL | AA4: RAIN | AB4: MAX | AC4: MIN | AD4: DATE
A5: FEB | B5: ELEV | C5: AC FT | D5: CHANGE | E5: CAP | F5: CFS | G5: RIVER | H5: CANYON | I5: INFLOW | J5: INFLOW | K5: INFLOW | L5: INF/OTF | M5: TOT DIV | N5: WETLAND | O5: UTE F&R | P5: MVI,CTZ | Q5: PINE | R5: LAT | S5: MVI | T5: CALL | U5: CANAL | V5: MC PHEE | W5: RELEASE | X5: OUTFLOW | Y5: OUTFLOW | Z5: OUTFLOW | AB5: TMP | AC5: TMP | AD5: FEB
A7: SEASON BAL
A8: YTD | B8: =JAN!B40 -> 6876.69 | C8: =JAN!C40 -> 206408 | D8: =JAN!$D$49 -> 462 | E8: =JAN!$E$40 -> 54408 | F8: =JAN!F48 -> 232.9216 | G8: =JAN!G48 -> 4024 | H8: =JAN!H48 -> 5.1 | I8: =JAN!I48 -> 3981.57 | J8: =JAN!J48 -> 698.58623 | K8: =JAN!K48 -> 4680.1562 | L8: =JAN!L48 -> -119.4684 | M8: =JAN!M48 -> 638.68 | ... AA8: =JAN!AA48 -> 2.77
A10: 1 | B10: 6876.69 | C10: 206408 | D10: =C10-C8 -> 0 | E10: =C10-152000 -> 54408 | F10: =D10/$D$2 -> 0 | G10: 39 | H10: 0.22 | I10: =G10+H10 -> 39.22 | J10: =IF(L10>0,L10,0) -> 0 | K10: =I10+J10 -> 39.22 | L10: =F10-(I10-X10) -> -6.12 | M10: 4.1 | N10: 0 | O10: 0 | P10: =M10-(N10+O10) -> 4.1 | Q10: 0 | R10: 0 | S10: =SUM(P10:R10) -> 4.1 | U10: 0 | V10: 29 | W10: =W8-V10 -> 1910 | X10: =N10+O10+S10+U10+V10 -> 33.1 | Y10: =IF(L10<0,L10*-1,0) -> 6.12 | Z10: =X10+Y10 -> 39.22 | AA10: 0 | AB10: 42 | AC10: 16 | AD10: 1
A11: =A10+1 -> 2 | B11: 6876.68 | C11: 206379 | D11: =C11-C10 -> -29 | E11: =C11-152000 -> 54379 | F11: =D11/$D$2 -> -14.62062 | G11: 42 | H11: 0.2 | I11: =G11+H11 -> 42.2 | J11: =IF(L11>0,L11,0) -> 0 | K11: =I11+J11 -> 42.2 | L11: =F11-(I11-X11) -> -23.72062 | M11: 4.1 | N11: 0 | O11: 0 | P11: =M11-(N11+O11) -> 4.1 | Q11: 0 | R11: 0 | S11: =SUM(P11:R11) -> 4.1 | U11: 0 | V11: 29 | W11: =W10-V11 -> 1881 | X11: =N11+O11+S11+U11+V11 -> 33.1 | Y11: =IF(L11<0,L11*-1,0) -> 23.72062 | Z11: =X11+Y11 -> 56.82062 | AA11: 0 | AB11: 38 | AC11: 6 | AD11: =AD10+1 -> 2
A12: =A11+1 -> 3 | B12: 6876.68 | C12: 206379 | D12: =C12-C11 -> 0 | E12: =C12-152000 -> 54379 | F12: =D12/$D$2 -> 0 | G12: 40 | H12: 0.17 | I12: =G12+H12 -> 40.17 | J12: =IF(L12>0,L12,0) -> 0 | K12: =I12+J12 -> 40.17 | L12: =F12-(I12-X12) -> -7.07 | M12: 4.1 | N12: 0 | O12: 0 | P12: =M12-(N12+O12) -> 4.1 | Q12: 0 | R12: 0 | S12: =SUM(P12:R12) -> 4.1 | U12: 0 | V12: 29 | W12: =W11-V12 -> 1852 | X12: =N12+O12+S12+U12+V12 -> 33.1 | Y12: =IF(L12<0,L12*-1,0) -> 7.07 | Z12: =X12+Y12 -> 40.17 | AA12: 0 | AB12: 40 | AC12: 12 | AD12: =AD11+1 -> 3
A13: =A12+1 -> 4 | B13: 6876.68 | C13: 206379 | D13: =C13-C12 -> 0 | E13: =C13-152000 -> 54379 | F13: =D13/$D$2 -> 0 | G13: 40 | H13: 0.18 | I13: =G13+H13 -> 40.18 | J13: =IF(L13>0,L13,0) -> 0 | K13: =I13+J13 -> 40.18 | L13: =F13-(I13-X13) -> -4.78 | M13: 6.4 | N13: 0 | O13: 0 | P13: =M13-(N13+O13) -> 6.4 | Q13: 0 | R13: 0 | S13: =SUM(P13:R13) -> 6.4 | U13: 0 | V13: 29 | W13: =W12-V13 -> 1823 | X13: =N13+O13+S13+U13+V13 -> 35.4 | Y13: =IF(L13<0,L13*-1,0) -> 4.78 | Z13: =X13+Y13 -> 40.18 | AA13: 0 | AB13: 42 | AC13: 15 | AD13: =AD12+1 -> 4
A14: =A13+1 -> 5 | B14: 6876.68 | C14: 206379 | D14: =C14-C13 -> 0 | E14: =C14-152000 -> 54379 | F14: =D14/$D$2 -> 0 | G14: 41 | H14: 0.22 | I14: =G14+H14 -> 41.22 | J14: =IF(L14>0,L14,0) -> 0 | K14: =I14+J14 -> 41.22 | L14: =F14-(I14-X14) -> -5.22 | M14: 6 | N14: 0 | O14: 0 | P14: =M14-(N14+O14) -> 6 | Q14: 0 | R14: 0 | S14: =SUM(P14:R14) -> 6 | U14: 0 | V14: 30 | W14: =W13-V14 -> 1793 | X14: =N14+O14+S14+U14+V14 -> 36 | Y14: =IF(L14<0,L14*-1,0) -> 5.22 | Z14: =X14+Y14 -> 41.22 | AA14: 0 | AB14: 35 | AC14: 9 | AD14: =AD13+1 -> 5
A15: =A14+1 -> 6 | B15: 6876.67 | C15: 206350 | D15: =C15-C14 -> -29 | E15: =C15-152000 -> 54350 | F15: =D15/$D$2 -> -14.62062 | G15: 38 | H15: 0.22 | I15: =G15+H15 -> 38.22 | J15: =IF(L15>0,L15,0) -> 0 | K15: =I15+J15 -> 38.22 | L15: =F15-(I15-X15) -> -16.54062 | M15: 6.3 | N15: 0 | O15: 0 | P15: =M15-(N15+O15) -> 6.3 | Q15: 0 | R15: 0 | S15: =SUM(P15:R15) -> 6.3 | U15: 0 | V15: 30 | W15: =W14-V15 -> 1763 | X15: =N15+O15+S15+U15+V15 -> 36.3 | Y15: =IF(L15<0,L15*-1,0) -> 16.54062 | Z15: =X15+Y15 -> 52.84062 | AA15: 0 | AB15: 46 | AC15: 9 | AD15: =AD14+1 -> 6
A16: =A15+1 -> 7 | B16: 6876.67 | C16: 206350 | D16: =C16-C15 -> 0 | E16: =C16-152000 -> 54350 | F16: =D16/$D$2 -> 0 | G16: 39 | H16: 0.23 | I16: =G16+H16 -> 39.23 | J16: =IF(L16>0,L16,0) -> 0 | K16: =I16+J16 -> 39.23 | L16: =F16-(I16-X16) -> -4.73 | M16: 5.5 | N16: 0 | O16: 0 | P16: =M16-(N16+O16) -> 5.5 | Q16: 0 | R16: 0 | S16: =SUM(P16:R16) -> 5.5 | U16: 0 | V16: 29 | W16: =W15-V16 -> 1734 | X16: =N16+O16+S16+U16+V16 -> 34.5 | Y16: =IF(L16<0,L16*-1,0) -> 4.73 | Z16: =X16+Y16 -> 39.23 | AA16: 0 | AB16: 46 | AC16: 13 | AD16: =AD15+1 -> 7
A17: =A16+1 -> 8 | B17: 6876.66 | C17: 206321 | D17: =C17-C16 -> -29 | E17: =C17-152000 -> 54321 | F17: =D17/$D$2 -> -14.62062 | G17: 40 | H17: 0.22 | I17: =G17+H17 -> 40.22 | J17: =IF(L17>0,L17,0) -> 0 | K17: =I17+J17 -> 40.22 | L17: =F17-(I17-X17) -> -20.34062 | M17: 5.5 | N17: 0 | O17: 0 | P17: =M17-(N17+O17) -> 5.5 | Q17: 0 | R17: 0 | S17: =SUM(P17:R17) -> 5.5 | U17: 0 | V17: 29 | W17: =W16-V17 -> 1705 | X17: =N17+O17+S17+U17+V17 -> 34.5 | Y17: =IF(L17<0,L17*-1,0) -> 20.34062 | Z17: =X17+Y17 -> 54.84062 | AA17: 0 | AB17: 45 | AC17: 17 | AD17: =AD16+1 -> 8
A18: =A17+1 -> 9 | B18: 6876.66 | C18: 206321 | D18: =C18-C17 -> 0 | E18: =C18-152000 -> 54321 | F18: =D18/$D$2 -> 0 | G18: 40 | H18: 0.12 | I18: =G18+H18 -> 40.12 | J18: =IF(L18>0,L18,0) -> 0 | K18: =I18+J18 -> 40.12 | L18: =F18-(I18-X18) -> -4.62 | M18: 5.5 | N18: 0 | O18: 0 | P18: =M18-(N18+O18) -> 5.5 | Q18: 0 | R18: 0 | S18: =SUM(P18:R18) -> 5.5 | U18: 0 | V18: 30 | W18: =W17-V18 -> 1675 | X18: =N18+O18+S18+U18+V18 -> 35.5 | Y18: =IF(L18<0,L18*-1,0) -> 4.62 | Z18: =X18+Y18 -> 40.12 | AA18: 0 | AB18: 33 | AC18: 10 | AD18: =AD17+1 -> 9
A19: =A18+1 -> 10 | B19: 6876.65 | C19: 206293 | D19: =C19-C18 -> -28 | E19: =C19-152000 -> 54293 | F19: =D19/$D$2 -> -14.116461 | G19: 39 | H19: 0.16 | I19: =G19+H19 -> 39.16 | J19: =IF(L19>0,L19,0) -> 0 | K19: =I19+J19 -> 39.16 | L19: =F19-(I19-X19) -> -17.776461 | M19: 5.5 | N19: 0 | O19: 0 | P19: =M19-(N19+O19) -> 5.5 | Q19: 0 | R19: 0 | S19: =SUM(P19:R19) -> 5.5 | U19: 0 | V19: 30 | W19: =W18-V19 -> 1645 | X19: =N19+O19+S19+U19+V19 -> 35.5 | Y19: =IF(L19<0,L19*-1,0) -> 17.776461 | Z19: =X19+Y19 -> 53.276461 | AA19: 0 | AB19: 42 | AC19: 14 | AD19: =AD18+1 -> 10
A20: =A19+1 -> 11 | B20: 6876.65 | C20: 206293 | D20: =C20-C19 -> 0 | E20: =C20-152000 -> 54293 | F20: =D20/$D$2 -> 0 | G20: 38 | H20: 0.16 | I20: =G20+H20 -> 38.16 | J20: =IF(L20>0,L20,0) -> 0 | K20: =I20+J20 -> 38.16 | L20: =F20-(I20-X20) -> -2.76 | M20: 5.4 | N20: 0 | O20: 0 | P20: =M20-(N20+O20) -> 5.4 | Q20: 0 | R20: 0 | S20: =SUM(P20:R20) -> 5.4 | U20: 0 | V20: 30 | W20: =W19-V20 -> 1615 | X20: =N20+O20+S20+U20+V20 -> 35.4 | Y20: =IF(L20<0,L20*-1,0) -> 2.76 | Z20: =X20+Y20 -> 38.16 | AA20: 0 | AB20: 47 | AC20: 14 | AD20: =AD19+1 -> 11
A21: =A20+1 -> 12 | B21: 6876.64 | C21: 206264 | D21: =C21-C20 -> -29 | E21: =C21-152000 -> 54264 | F21: =D21/$D$2 -> -14.62062 | G21: 39 | H21: 0.11 | I21: =G21+H21 -> 39.11 | J21: =IF(L21>0,L21,0) -> 0 | K21: =I21+J21 -> 39.11 | L21: =F21-(I21-X21) -> -18.23062 | M21: 5.5 | N21: 0 | O21: 0 | P21: =M21-(N21+O21) -> 5.5 | Q21: 0 | R21: 0 | S21: =SUM(P21:R21) -> 5.5 | U21: 0 | V21: 30 | W21: =W20-V21 -> 1585 | X21: =N21+O21+S21+U21+V21 -> 35.5 | Y21: =IF(L21<0,L21*-1,0) -> 18.23062 | Z21: =X21+Y21 -> 53.73062 | AA21: 0 | AB21: 45 | AC21: 20 | AD21: =AD20+1 -> 12
A22: =A21+1 -> 13 | B22: 6876.64 | C22: 206264 | D22: =C22-C21 -> 0 | E22: =C22-152000 -> 54264 | F22: =D22/$D$2 -> 0 | G22: 40 | H22: 0.2 | I22: =G22+H22 -> 40.2 | J22: =IF(L22>0,L22,0) -> 0 | K22: =I22+J22 -> 40.2 | L22: =F22-(I22-X22) -> -4.9 | M22: 5.3 | N22: 0 | O22: 0 | P22: =M22-(N22+O22) -> 5.3 | Q22: 0 | R22: 0 | S22: =SUM(P22:R22) -> 5.3 | U22: 0 | V22: 30 | W22: =W21-V22 -> 1555 | X22: =N22+O22+S22+U22+V22 -> 35.3 | Y22: =IF(L22<0,L22*-1,0) -> 4.9 | Z22: =X22+Y22 -> 40.2 | AA22: 0 | AB22: 46 | AC22: 15 | AD22: =AD21+1 -> 13
... A36: =A35+1 -> 27 | B36: 6876.64 | C36: 206264 | D36: =C36-C35 -> 0 | E36: =C36-152000 -> 54264 | F36: =D36/$D$2 -> 0 | G36: 33 | H36: 0.62 | I36: =G36+H36 -> 33.62 | J36: =IF(L36>0,L36,0) -> 0.28 | K36: =I36+J36 -> 33.9 | L36: =F36-(I36-X36) -> 0.28 | M36: 3.9 | N36: 0 | O36: 0 | P36: =M36-(N36+O36) -> 3.9 | Q36: 0 | R36: 0 | S36: =SUM(P36:R36) -> 3.9 | U36: 0 | V36: 30 | W36: =W35-V36 -> 1135 | X36: =N36+O36+S36+U36+V36 -> 33.9 | Y36: =IF(L36<0,L36*-1,0) -> 0 | Z36: =X36+Y36 -> 33.9 | AA36: 0 | AB36: 43 | AC36: 12 | AD36: =AD35+1 -> 27
A37: 28 | B37: 6876.64 | C37: 206264 | D37: =C37-C36 -> 0 | E37: =C37-152000 -> 54264 | F37: =D37/$D$2 -> 0 | G37: 35 | H37: 0.64 | I37: =G37+H37 -> 35.64 | J37: =IF(L37>0,L37,0) -> 0 | K37: =I37+J37 -> 35.64 | L37: =F37-(I37-X37) -> -1.94 | M37: 3.7 | N37: 0 | O37: 0 | P37: =M37-(N37+O37) -> 3.7 | Q37: 0 | R37: 0 | S37: =SUM(P37:R37) -> 3.7 | U37: 0 | V37: 30 | W37: =W36-V37 -> 1105 | X37: =N37+O37+S37+U37+V37 -> 33.7 | Y37: =IF(L37<0,L37*-1,0) -> 1.94 | Z37: =X37+Y37 -> 35.64 | AA37: 0 | AB37: 19 | AC37: 17 | AD37: 28
A39: MONTH / CFS | F39: =SUM(F10:F37) -> -72.598941 | G39: =SUM(G10:G37) -> 1097 | H39: =SUM(H10:H37) -> 8.88 | I39: =SUM(I10:I37) -> 1105.88 | J39: =SUM(J10:J37) -> 25.657701 | K39: =SUM(K10:K37) -> 1131.5377 | L39: =SUM(L10:L37) -> -202.17894 | M39: =SUM(M10:M37) -> 142.3 | ... S39: =SUM(S10:S37) -> 142.3 | U39: =SUM(U10:U37) -> 0 | V39: =SUM(V10:V37) -> 834 | X39: =SUM(X10:X37) -> 976.3 | Y39: =SUM(Y10:Y37) -> 227.83664 | Z39: =SUM(Z10:Z37) -> 1204.1366 | AA39: =SUM(AA10:AA37) -> 0.12 | AB39: =AVERAGE(AB10:AB37) -> 42.5 | AC39: =AVERAGE(AC10:AC37) -> 16.392857 | AD39: AVE
A40: MONTH / AF | D40: =SUM(D10:D37) -> -144 | F40: =F39*$D$2 -> -144 | G40: =G39*$D$2 -> 2175.8995 | H40: =H39*$D$2 -> 17.61348 | I40: =I39*$D$2 -> 2193.513 | J40: =J39*$D$2 -> 50.89205 | K40: =K39*$D$2 -> 2244.405 | L40: =L39*$D$2 -> -401.02193 | M40: =M39*$D$2 -> 282.25205 | ... S40: =S39*$D$2 -> 282.25205 | U40: =U39*$D$2 -> 0 | V40: =V39*$D$2 -> 1654.239 | X40: =X39*$D$2 -> 1936.4911 | Y40: =Y39*$D$2 -> 451.91398 | Z40: =Z39*$D$2 -> 2388.405 | AB40: =MAX(AB10:AB37) -> 55 | AC40: =MAX(AC10:AC37) -> 28 | AD40: HI
A42: SEASON / CFS | AB42: =MIN(AB10:AB37) -> 19 | AC42: =MIN(AC10:AC37) -> 6 | AD42: LO
A43: SEASON / AF
A45: YTD / CFS | F45: =F8+F39 -> 160.32266 | G45: =G8+G39 -> 5121 | H45: =H8+H39 -> 13.98 | I45: =I8+I39 -> 5087.45 | J45: =J8+J39 -> 724.24393 | K45: =K8+K39 -> 5811.6939 | L45: =L8+L39 -> -321.64734 | M45: =M8+M39 -> 780.98 | ... S45: =S8+S39 -> 847.914 | U45: =U8+U39 -> 0 | V45: =V8+V39 -> 3697 | W45: =W37 -> 1105 | X45: =X8+X39 -> 4605.48 | Y45: =Y8+Y39 -> 1045.8913 | Z45: =Z8+Z39 -> 5651.3713 | AA45: =AA8+AA39 -> 2.89
A46: YTD / AF | D46: =D8+D40 -> 318 | E46: =E37 -> 54264 | F46: =F45*$D$2 -> 318 | G46: =G45*$D$2 -> 10157.504 | H46: =H45*$D$2 -> 27.72933 | I46: =I45*$D$2 -> 10090.957 | J46: =J45*$D$2 -> 1436.5378 | K46: =K45*$D$2 -> 11527.495 | L46: =L45*$D$2 -> -637.98749 | M46: =M45*$D$2 -> 1549.0738 | ... Z46: =Z45*$D$2 -> 11209.495

Sheet MAR
K1: MC PHEE RESERVOIR IN/OUT FLOW TABULATION
A2: AF/cfs CONVERT FACTOR | D2: 1.9835 | K2: MARCH "2002"
A4: DATE | B4: RESERV | C4: RESERV | D4: AC FT | E4: ACTIVE | F4: CONV TO | G4: DOLORES | H4: LOST | I4: RECORDED | J4: CALC | K4: TOTAL | L4: CALC | M4: DOLORES TUNNEL | Q4: LONE | R4: U | S4: TOTAL | T4: MVI | U4: DV CR | V4: BELOW | W4: REMAIN | X4: RECORDED | Y4: CALC | Z4: TOTAL | AA4: RAIN | AB4: MAX | AC4: MIN | AD4: DATE
A5: MAR | B5: ELEV | C5: AC FT | D5: CHANGE | E5: CAP | F5: CFS | G5: RIVER | H5: CANYON | I5: INFLOW | J5: INFLOW | K5: INFLOW | L5: INF/OTF | M5: TOT DIV | N5: WETLAND | O5: UTE F&R | P5: MVI,CTZ | Q5: PINE | R5: LAT | S5: MVI | T5: CALL | U5: CANAL | V5: MC PHEE | W5: RELEASE | X5: OUTFLOW | Y5: OUTFLOW | Z5: OUTFLOW | AB5: TMP | AC5: TMP | AD5: MAR
A7: SEASON BAL
A8: YTD | B8: =FEB!B37 -> 6876.64 | C8: =FEB!C37 -> 206264 | D8: =FEB!$D$46 -> 318 | E8: =FEB!$E$37 -> 54264 | F8: =FEB!F45 -> 160.32266 | G8: =FEB!G45 -> 5121 | H8: =FEB!H45 -> 13.98 | I8: =FEB!I45 -> 5087.45 | J8: =FEB!J45 -> 724.24393 | K8: =FEB!K45 -> 5811.6939 | L8: =FEB!L45 -> -321.64734 | M8: =FEB!M45 -> 780.98 | ... AA8: =FEB!AA45 -> 2.89
A10: 1 | B10: 6876.64 | C10: 206264 | D10: =C10-C8 -> 0 | E10: =C10-152000 -> 54264 | F10: =D10/$D$2 -> 0 | G10: 37 | H10: 0.66 | I10: =G10+H10 -> 37.66 | J10: =IF(L10>0,L10,0) -> 0 | K10: =I10+J10 -> 37.66 | L10: =F10-(I10-X10) -> -3.96 | M10: 3.7 | N10: 0 | O10: 0 | P10: =M10-(N10+O10) -> 3.7 | Q10: 0 | R10: 0 | S10: =SUM(P10:R10) -> 3.7 | U10: 0 | V10: 30 | W10: =W8-V10 -> 1075 | X10: =N10+O10+S10+U10+V10 -> 33.7 | Y10: =IF(L10<0,L10*-1,0) -> 3.96 | Z10: =X10+Y10 -> 37.66 | AA10: 0.01 | AB10: 34 | AC10: 11 | AD10: 1
