Workbook

Sheet NOV
K1: MCPHEE RESERVOIR INFLOW/OUTFLOW TABULATION
A2: AF/cfs CONVERT FACTOR | D2: 1.9835 | L2: NOVEMBER "2003"
D4: RESERVOIR | S4: INFLOW/OUTFLOW (CFS) | AE4: WEATHER | AI4: ADJUSTMENTS
A5: DATE | B5: RESERV | C5: RESERV | D5: AC FT | E5: ACTIVE | F5: CONV TO | G5: DOLORES | H5: LOST | I5: RECORD | J5: CALC | K5: TOTAL | L5: CALC | M5: DOLORES TUNNEL | S5: LONE | T5: U | U5: TOTAL | V5: MVI | W5: MVI | X5: DV CR | Y5: BELOW | Z5: FISH | AA5: RECORD | AB5: CALC | AC5: TOTAL | AD5: RAIN | AE5: MAX | AF5: MIN | AG5: NAR. | AH5: MVI | AI5: MVI | AJ5: MVI | AK5: U/S
A6: NOV | B6: ELEV | C6: AC FT | D6: CHANGE | E6: CAP | F6: CFS | G6: RIVER | H6: CAN | I6: INFLOW | J6: INFLOW | K6: INFLOW | L6: INF/OTF | M6: TOT DIV | N6: WET | O6: UTE | P6: MWC | Q6: CTZ | R6: CTZ & | S6: PINE | T6: LAT | U6: MVI | V6: CALL + | W6: PROJ | X6: CANAL | Y6: MCP | Z6: LEFT | AA6: OTF | AB6: OTF | AC6: OTF | AE6: TMP | AF6: TMP | AG6: CALL | AH6: STOCK | AI6: STORED | AJ6: STORED | AK6: USERS
E7: AC FT | N7: LAND | O7: F&R | R7: UTE | V7: TO EX | AG7: AC.FT. | AH7: CFS | AI7: Apr-Jun | AJ7: EVAP | AK7: EXCH
R8: PROJ | AJ8: AC.FT
A9: SEASON BAL
A10: YTD | B10: 6864.59 | C10: 173943 | Z10: 3219
A12: 1 | B12: 6864.59 | C12: 173943 | D12: =C12-C10 -> 0 | E12: =C12-152000 -> 21943 | F12: =D12/$D$2 -> 0 | G12: 56 | H12: 0 | I12: =G12+H12 -> 56 | J12: =IF(L12>0,L12,0) -> 0 | K12: =I12+J12 -> 56 | L12: =F12-(I12-AA12) -> -28.1 | M12: 5.9 | N12: 0 | O12: 0 | P12: 1.38 | Q12: 2.4 | R12: 0 | S12: 0 | T12: 0 | U12: =M12-N12-O12-P12-Q12-R12+S12+T12 -> 2.12 | X12: 0 | Y12: 22 | Z12: =Z10-Y12 -> 3197 | AA12: =N12+O12+P12+Q12+R12+U12+X12+Y12 -> 27.9 | AB12: =IF(L12<0,L12*-1,0) -> 28.1 | AC12: =AA12+AB12 -> 56 | AD12: 0 | AE12: 54 | AF12: 43 | AG12: 0 | AH12: =M12-P12-Q12+S12+T12 -> 2.12
A13: =A12+1 -> 2 | B13: 6864.62 | C13: 174017 | D13: =C13-C12 -> 74 | E13: =C13-152000 -> 22017 | F13: =D13/$D$2 -> 37.307789 | G13: 61 | H13: 0 | I13: =G13+H13 -> 61 | J13: =IF(L13>0,L13,0) -> 4.2077893 | K13: =I13+J13 -> 65.207789 | L13: =F13-(I13-AA13) -> 4.2077893 | M13: 5.9 | N13: 0 | O13: 0 | P13: 1.38 | Q13: 2.4 | R13: 0 | S13: 0 | T13: 0 | U13: =M13-N13-O13-P13-Q13-R13+S13+T13 -> 2.12 | X13: 0 | Y13: 22 | Z13: =Z12-Y13 -> 3175 | AA13: =N13+O13+P13+Q13+R13+U13+X13+Y13 -> 27.9 | AB13: =IF(L13<0,L13*-1,0) -> 0 | AC13: =AA13+AB13 -> 27.9 | AD13: 0.19 | AE13: 51 | AF13: 42 | AG13: 0 | AH13: =M13-P13-Q13+S13+T13 -> 2.12
A14: =A13+1 -> 3 | B14: 6864.66 | C14: 174115 | D14: =C14-C13 -> 98 | E14: =C14-152000 -> 22115 | F14: =D14/$D$2 -> 49.407613 | G14: 89 | H14: 0 | I14: =G14+H14 -> 89 | J14: =IF(L14>0,L14,0) -> 55.407613 | K14: =I14+J14 -> 144.40761 | L14: =F14-(I14-AA14) -> 55.407613 | M14: 31 | N14: 0 | O14: 0 | P14: 1.38 | Q14: 2.4 | R14: 0 | S14: 25 | T14: 17 | U14: =M14-N14-O14-P14-Q14-R14+S14+T14 -> 69.22 | X14: 0 | Y14: 22 | Z14: =Z13-Y14 -> 3153 | AA14: =N14+O14+P14+Q14+R14+U14+X14+Y14 -> 95 | AB14: =IF(L14<0,L14*-1,0) -> 0 | AC14: =AA14+AB14 -> 95 | AD14: 0.13 | AE14: 47 | AF14: 27 | AG14: 0 | AH14: =M14-P14-Q14+S14+T14 -> 69.22
A15: =A14+1 -> 4 | B15: 6864.63 | C15: 174041 | D15: =C15-C14 -> -74 | E15: =C15-152000 -> 22041 | F15: =D15/$D$2 -> -37.307789 | G15: 73 | H15: 0 | I15: =G15+H15 -> 73 | J15: =IF(L15>0,L15,0) -> 3.6922107 | K15: =I15+J15 -> 76.692211 | L15: =F15-(I15-AA15) -> 3.6922107 | M15: 31 | N15: 0 | O15: 0 | P15: 1.38 | Q15: 2.4 | R15: 0 | S15: 40 | T15: 21 | U15: =M15-N15-O15-P15-Q15-R15+S15+T15 -> 88.22 | X15: 0 | Y15: 22 | Z15: =Z14-Y15 -> 3131 | AA15: =N15+O15+P15+Q15+R15+U15+X15+Y15 -> 114 | AB15: =IF(L15<0,L15*-1,0) -> 0 | AC15: =AA15+AB15 -> 114 | AD15: 0 | AE15: 43 | AF15: 22 | AG15: 0 | AH15: =M15-P15-Q15+S15+T15 -> 88.22
A16: =A15+1 -> 5 | B16: 6864.6 | C16: 173967 | D16: =C16-C15 -> -74 | E16: =C16-152000 -> 21967 | F16: =D16/$D$2 -> -37.307789 | G16: 58 | H16: 0 | I16: =G16+H16 -> 58 | J16: =IF(L16>0,L16,0) -> 10.692211 | K16: =I16+J16 -> 68.692211 | L16: =F16-(I16-AA16) -> 10.692211 | M16: 31 | N16: 0 | O16: 0 | P16: 1.38 | Q16: 2.4 | R16: 0 | S16: 32 | T16: 21 | U16: =M16-N16-O16-P16-Q16-R16+S16+T16 -> 80.22 | X16: 0 | Y16: 22 | Z16: =Z15-Y16 -> 3109 | AA16: =N16+O16+P16+Q16+R16+U16+X16+Y16 -> 106 | AB16: =IF(L16<0,L16*-1,0) -> 0 | AC16: =AA16+AB16 -> 106 | AD16: 0 | AE16: 46 | AF16: 23 | AG16: 0 | AH16: =M16-P16-Q16+S16+T16 -> 80.22
A17: =A16+1 -> 6 | B17: 6864.57 | C17: 173894 | D17: =C17-C16 -> -73 | E17: =C17-152000 -> 21894 | F17: =D17/$D$2 -> -36.80363 | G17: 59 | H17: 0 | I17: =G17+H17 -> 59 | J17: =IF(L17>0,L17,0) -> 0 | K17: =I17+J17 -> 59 | L17: =F17-(I17-AA17) -> -1.8036299 | M17: 28 | N17: 0 | O17: =0.88*1.9835 -> 1.74548 | P17: 1.38 | Q17: 2.4 | R17: 0 | S17: 23 | T17: 21 | U17: =M17-N17-O17-P17-Q17-R17+S17+T17 -> 66.47452 | X17: 0 | Y17: 22 | Z17: =Z16-Y17 -> 3087 | AA17: =N17+O17+P17+Q17+R17+U17+X17+Y17 -> 94 | AB17: =IF(L17<0,L17*-1,0) -> 1.8036299 | AC17: =AA17+AB17 -> 95.80363 | AD17: 0 | AE17: 48 | AF17: 26 | AG17: 0 | AH17: =M17-O17-P17-Q17+S17+T17 -> 66.47452
A18: =A17+1 -> 7 | B18: 6864.55 | C18: 173845 | D18: =C18-C17 -> -49 | E18: =C18-152000 -> 21845 | F18: =D18/$D$2 -> -24.703806 | G18: 63 | H18: 0 | I18: =G18+H18 -> 63 | J18: =IF(L18>0,L18,0) -> 0.2961936 | K18: =I18+J18 -> 63.296194 | L18: =F18-(I18-AA18) -> 0.2961936 | M18: 19 | N18: 0 | O18: =0.37*1.9835 -> 0.733895 | P18: 1.38 | Q18: 2.4 | R18: 0 | S18: 32 | T18: 15 | U18: =M18-N18-O18-P18-Q18-R18+S18+T18 -> 61.486105 | X18: 0 | Y18: 22 | Z18: =Z17-Y18 -> 3065 | AA18: =N18+O18+P18+Q18+R18+U18+X18+Y18 -> 88 | AB18: =IF(L18<0,L18*-1,0) -> 0 | AC18: =AA18+AB18 -> 88 | AD18: 0 | AE18: 52 | AF18: 33 | AG18: 29.33 | AH18: =M18-O18-P18-Q18+S18+T18 -> 61.486105
A19: =A18+1 -> 8 | B19: 6864.55 | C19: 173845 | D19: =C19-C18 -> 0 | E19: =C19-152000 -> 21845 | F19: =D19/$D$2 -> 0 | G19: 61 | H19: 0 | I19: =G19+H19 -> 61 | J19: =IF(L19>0,L19,0) -> 11.8 | K19: =I19+J19 -> 72.8 | L19: =F19-(I19-AA19) -> 11.8 | M19: 4.8 | N19: 0 | O19: =0.82*1.9835 -> 1.62647 | P19: 1.38 | Q19: 2.4 | R19: 0 | S19: 46 | T19: 0 | U19: =M19-N19-O19-P19-Q19-R19+S19+T19 -> 45.39353 | X19: 0 | Y19: 22 | Z19: =Z18-Y19 -> 3043 | AA19: =N19+O19+P19+Q19+R19+U19+X19+Y19 -> 72.8 | AB19: =IF(L19<0,L19*-1,0) -> 0 | AC19: =AA19+AB19 -> 72.8 | AD19: 0 | AE19: 54 | AF19: 31 | AG19: =AG18+(U19*1.9835) -> 119.36807 | AH19: 0
A20: =A19+1 -> 9 | B20: 6864.55 | C20: 173845 | D20: =C20-C19 -> 0 | E20: =C20-152000 -> 21845 | F20: =D20/$D$2 -> 0 | G20: 59 | H20: 0 | I20: =G20+H20 -> 59 | J20: =IF(L20>0,L20,0) -> 13.4 | K20: =I20+J20 -> 72.4 | L20: =F20-(I20-AA20) -> 13.4 | M20: 3.4 | N20: 0 | O20: =0.99*1.9835 -> 1.963665 | P20: 1.38 | Q20: 2.4 | R20: 0 | S20: 47 | T20: 0 | U20: =M20-N20-O20-P20-Q20-R20+S20+T20 -> 44.656335 | X20: 0 | Y20: 22 | Z20: =Z19-Y20 -> 3021 | AA20: =N20+O20+P20+Q20+R20+U20+X20+Y20 -> 72.4 | AB20: =IF(L20<0,L20*-1,0) -> 0 | AC20: =AA20+AB20 -> 72.4 | AD20: 0 | AE20: 54 | AF20: 34 | AG20: =AG19+(U20*1.9835) -> 207.94391 | AH20: 0
A21: =A20+1 -> 10 | B21: 6864.51 | C21: 173746 | D21: =C21-C20 -> -99 | E21: =C21-152000 -> 21746 | F21: =D21/$D$2 -> -49.911772 | G21: 64 | H21: 0 | I21: =G21+H21 -> 64 | J21: =IF(L21>0,L21,0) -> 0 | K21: =I21+J21 -> 64 | L21: =F21-(I21-AA21) -> -6.5117721 | M21: 3.4 | N21: 0 | O21: 0 | P21: 1.38 | Q21: 2.4 | R21: 0 | S21: 83 | T21: 0 | U21: =M21-N21-O21-P21-Q21-R21+S21+T21 -> 82.62 | X21: 0 | Y21: 21 | Z21: =Z20-Y21 -> 3000 | AA21: =N21+O21+P21+Q21+R21+U21+X21+Y21 -> 107.4 | AB21: =IF(L21<0,L21*-1,0) -> 6.5117721 | AC21: =AA21+AB21 -> 113.91177 | AD21: 0.12 | AE21: 45 | AF21: 34 | AG21: =AG20+(U21*1.9835) -> 371.82068 | AH21: 0
A22: =A21+1 -> 11 | B22: 6864.47 | C22: 173648 | D22: =C22-C21 -> -98 | E22: =C22-152000 -> 21648 | F22: =D22/$D$2 -> -49.407613 | G22: 67 | H22: 0 | I22: =G22+H22 -> 67 | J22: =IF(L22>0,L22,0) -> 0 | K22: =I22+J22 -> 67 | L22: =F22-(I22-AA22) -> -3.0076128 | M22: 3.4 | N22: 0 | O22: 0 | P22: 1.38 | Q22: 2.4 | R22: 0 | S22: 88 | T22: 0 | U22: =M22-N22-O22-P22-Q22-R22+S22+T22 -> 87.62 | X22: 0 | Y22: 22 | Z22: =Z21-Y22 -> 2978 | AA22: =N22+O22+P22+Q22+R22+U22+X22+Y22 -> 113.4 | AB22: =IF(L22<0,L22*-1,0) -> 3.0076128 | AC22: =AA22+AB22 -> 116.40761 | AD22: 0 | AE22: 50 | AF22: 33 | AG22: =AG21+(U22*1.9835) -> 545.61495 | AH22: 0
A23: =A22+1 -> 12 | B23: 6864.48 | C23: 173673 | D23: =C23-C22 -> 25 | E23: =C23-152000 -> 21673 | F23: =D23/$D$2 -> 12.603983 | G23: 65 | H23: 0 | I23: =G23+H23 -> 65 | J23: =IF(L23>0,L23,0) -> 37.003983 | K23: =I23+J23 -> 102.00398 | L23: =F23-(I23-AA23) -> 37.003983 | M23: 3.4 | N23: 0 | O23: 0 | P23: 1.38 | Q23: 2.4 | R23: 0 | S23: 64 | T23: 0 | U23: =M23-N23-O23-P23-Q23-R23+S23+T23 -> 63.62 | X23: 0 | Y23: 22 | Z23: =Z22-Y23 -> 2956 | AA23: =N23+O23+P23+Q23+R23+U23+X23+Y23 -> 89.4 | AB23: =IF(L23<0,L23*-1,0) -> 0 | AC23: =AA23+AB23 -> 89.4 | AD23: 0.14 | AE23: 47 | AF23: 32 | AG23: =AG22+(U23*1.9835) -> 671.80522 | AH23: 0
A24: =A23+1 -> 13 | B24: 6864.46 | C24: 173623 | D24: =C24-C23 -> -50 | E24: =C24-152000 -> 21623 | F24: =D24/$D$2 -> -25.207966 | G24: 72 | H24: 0 | I24: =G24+H24 -> 72 | J24: =IF(L24>0,L24,0) -> 0 | K24: =I24+J24 -> 72 | L24: =F24-(I24-AA24) -> -1.8079657 | M24: 3.4 | N24: 0 | O24: 0 | P24: 1.38 | Q24: 2.4 | R24: 0 | S24: 73 | T24: 0 | U24: =M24-N24-O24-P24-Q24-R24+S24+T24 -> 72.62 | X24: 0 | Y24: 19 | Z24: =Z23-Y24 -> 2937 | AA24: =N24+O24+P24+Q24+R24+U24+X24+Y24 -> 95.4 | AB24: =IF(L24<0,L24*-1,0) -> 1.8079657 | AC24: =AA24+AB24 -> 97.207966 | AD24: 0.12 | AE24: 45 | AF24: 38 | AG24: =AG23+(U24*1.9835) -> 815.84699 | AH24: 0
A25: =A24+1 -> 14 | B25: 6864.44 | C25: 173574 | D25: =C25-C24 -> -49 | E25: =C25-152000 -> 21574 | F25: =D25/$D$2 -> -24.703806 | G25: 71 | H25: 0 | I25: =G25+H25 -> 71 | J25: =IF(L25>0,L25,0) -> 1.6961936 | K25: =I25+J25 -> 72.696194 | L25: =F25-(I25-AA25) -> 1.6961936 | M25: 3.4 | N25: 0 | O25: 0 | P25: 1.38 | Q25: 2.4 | R25: 0 | S25: 76 | T25: 0 | U25: =M25-N25-O25-P25-Q25-R25+S25+T25 -> 75.62 | X25: 0 | Y25: 18 | Z25: =Z24-Y25 -> 2919 | AA25: =N25+O25+P25+Q25+R25+U25+X25+Y25 -> 97.4 | AB25: =IF(L25<0,L25*-1,0) -> 0 | AC25: =AA25+AB25 -> 97.4 | AD25: 0 | AE25: 47 | AF25: 34 | AG25: =AG24+(U25*1.9835) -> 965.83926 | AH25: 0
A26: =A25+1 -> 15 | B26: 6864.42 | C26: 173525 | D26: =C26-C25 -> -49 | E26: =C26-152000 -> 21525 | F26: =D26/$D$2 -> -24.703806 | G26: 66 | H26: 0 | I26: =G26+H26 -> 66 | J26: =IF(L26>0,L26,0) -> 6.6961936 | K26: =I26+J26 -> 72.696194 | L26: =F26-(I26-AA26) -> 6.6961936 | M26: 3.4 | N26: 0 | O26: 0 | P26: 1.38 | Q26: 2.4 | R26: 0 | S26: 76 | T26: 0 | U26: =M26-N26-O26-P26-Q26-R26+S26+T26 -> 75.62 | X26: 0 | Y26: 18 | Z26: =Z25-Y26 -> 2901 | AA26: =N26+O26+P26+Q26+R26+U26+X26+Y26 -> 97.4 | AB26: =IF(L26<0,L26*-1,0) -> 0 | AC26: =AA26+AB26 -> 97.4 | AD26: 0 | AE26: 47 | AF26: 31 | AG26: =AG25+(U26*1.9835) -> 1115.8315 | AH26: 0
A27: =A26+1 -> 16 | B27: 6864.4 | C27: 173476 | D27: =C27-C26 -> -49 | E27: =C27-152000 -> 21476 | F27: =D27/$D$2 -> -24.703806 | G27: 61 | H27: 0 | I27: =G27+H27 -> 61 | J27: =IF(L27>0,L27,0) -> 11.696194 | K27: =I27+J27 -> 72.696194 | L27: =F27-(I27-AA27) -> 11.696194 | M27: 3.4 | N27: 0 | O27: 0 | P27: 1.38 | Q27: 2.4 | R27: 0 | S27: 76 | T27: 0 | U27: =M27-N27-O27-P27-Q27-R27+S27+T27 -> 75.62 | X27: 0 | Y27: 18 | Z27: =Z26-Y27 -> 2883 | AA27: =N27+O27+P27+Q27+R27+U27+X27+Y27 -> 97.4 | AB27: =IF(L27<0,L27*-1,0) -> 0 | AC27: =AA27+AB27 -> 97.4 | AD27: 0.13 | AE27: 43 | AF27: 30 | AG27: =AG26+(U27*1.9835) -> 1265.8238 | AH27: 0
A28: =A27+1 -> 17 | B28: 6864.41 | C28: 173501 | D28: =C28-C27 -> 25 | E28: =C28-152000 -> 21501 | F28: =D28/$D$2 -> 12.603983 | G28: 66 | H28: 0 | I28: =G28+H28 -> 66 | J28: =IF(L28>0,L28,0) -> 28.003983 | K28: =I28+J28 -> 94.003983 | L28: =F28-(I28-AA28) -> 28.003983 | M28: 3.4 | N28: 0 | O28: 0 | P28: 1.38 | Q28: 2.4 | R28: 0 | S28: 60 | T28: 0 | U28: =M28-N28-O28-P28-Q28-R28+S28+T28 -> 59.62 | X28: 0 | Y28: 18 | Z28: =Z27-Y28 -> 2865 | AA28: =N28+O28+P28+Q28+R28+U28+X28+Y28 -> 81.4 | AB28: =IF(L28<0,L28*-1,0) -> 0 | AC28: =AA28+AB28 -> 81.4 | AD28: 0.13 | AE28: 36 | AF28: 23 | AG28: =AG27+(U28*1.9835) -> 1384.0801 | AH28: 0
A29: =A28+1 -> 18 | B29: 6864.4 | C29: 173476 | D29: =C29-C28 -> -25 | E29: =C29-152000 -> 21476 | F29: =D29/$D$2 -> -12.603983 | G29: 59 | H29: 0 | I29: =G29+H29 -> 59 | J29: =IF(L29>0,L29,0) -> 0 | K29: =I29+J29 -> 59 | L29: =F29-(I29-AA29) -> -1.6039829 | M29: 3 | N29: 0 | O29: 0 | P29: 1.38 | Q29: 2.4 | R29: 0 | S29: 49 | T29: 0 | U29: =M29-N29-O29-P29-Q29-R29+S29+T29 -> 48.22 | X29: 0 | Y29: 18 | Z29: =Z28-Y29 -> 2847 | AA29: =N29+O29+P29+Q29+R29+U29+X29+Y29 -> 70 | AB29: =IF(L29<0,L29*-1,0) -> 1.6039829 | AC29: =AA29+AB29 -> 71.603983 | AD29: 0 | AE29: 44 | AF29: 21 | AG29: =AG28+(U29*1.9835) -> 1479.7244 | AH29: 0
A30: =A29+1 -> 19 | B30: 6864.38 | C30: 173427 | D30: =C30-C29 -> -49 | E30: =C30-152000 -> 21427 | F30: =D30/$D$2 -> -24.703806 | G30: 57 | H30: 0 | I30: =G30+H30 -> 57 | J30: =IF(L30>0,L30,0) -> 0 | K30: =I30+J30 -> 57 | L30: =F30-(I30-AA30) -> -10.603806 | M30: 3.1 | N30: 0 | O30: 0 | P30: 1.38 | Q30: 2.4 | R30: 0 | S30: 50 | T30: 0 | U30: =M30-N30-O30-P30-Q30-R30+S30+T30 -> 49.32 | X30: 0 | Y30: 18 | Z30: =Z29-Y30 -> 2829 | AA30: =N30+O30+P30+Q30+R30+U30+X30+Y30 -> 71.1 | AB30: =IF(L30<0,L30*-1,0) -> 10.603806 | AC30: =AA30+AB30 -> 81.703806 | AD30: 0 | AE30: 56 | AF30: 24 | AG30: =AG29+(U30*1.9835) -> 1577.5507 | AH30: 0
A31: =A30+1 -> 20 | B31: 6864.36 | C31: 173378 | D31: =C31-C30 -> -49 | E31: =C31-152000 -> 21378 | F31: =D31/$D$2 -> -24.703806 | G31: 62 | H31: 0 | I31: =G31+H31 -> 62 | J31: =IF(L31>0,L31,0) -> 0 | K31: =I31+J31 -> 62 | L31: =F31-(I31-AA31) -> -14.503806 | M31: 3.2 | N31: 0 | O31: 0 | P31: 1.38 | Q31: 2.4 | R31: 0 | S31: 51 | T31: 0 | U31: =M31-N31-O31-P31-Q31-R31+S31+T31 -> 50.42 | X31: 0 | Y31: 18 | Z31: =Z30-Y31 -> 2811 | AA31: =N31+O31+P31+Q31+R31+U31+X31+Y31 -> 72.2 | AB31: =IF(L31<0,L31*-1,0) -> 14.503806 | AC31: =AA31+AB31 -> 86.703806 | AD31: 0 | AE31: 56 | AF31: 28 | AG31: =AG30+(U31*1.9835) -> 1677.5587 | AH31: 0
A32: =A31+1 -> 21 | B32: 6864.34 | C32: 173329 | D32: =C32-C31 -> -49 | E32: =C32-152000 -> 21329 | F32: =D32/$D$2 -> -24.703806 | G32: 66 | H32: 0 | I32: =G32+H32 -> 66 | J32: =IF(L32>0,L32,0) -> 0 | K32: =I32+J32 -> 66 | L32: =F32-(I32-AA32) -> -18.103806 | M32: 3.6 | N32: 0 | O32: 0 | P32: 1.38 | Q32: 2.4 | R32: 0 | S32: 51 | T32: 0 | U32: =M32-N32-O32-P32-Q32-R32+S32+T32 -> 50.82 | X32: 0 | Y32: 18 | Z32: =Z31-Y32 -> 2793 | AA32: =N32+O32+P32+Q32+R32+U32+X32+Y32 -> 72.6 | AB32: =IF(L32<0,L32*-1,0) -> 18.103806 | AC32: =AA32+AB32 -> 90.703806 | AD32: 0 | AE32: 54 | AF32: 33 | AG32: =AG31+(U32*1.9835) -> 1778.3602 | AH32: 0
... A40: =A39+1 -> 29 | B40: 6864.16 | C40: 172887 | D40: =C40-C39 -> -49 | E40: =C40-152000 -> 20887 | F40: =D40/$D$2 -> -24.703806 | G40: 43 | H40: 0 | I40: =G40+H40 -> 43 | J40: =IF(L40>0,L40,0) -> 6.6961936 | K40: =I40+J40 -> 49.696194 | L40: =F40-(I40-AA40) -> 6.6961936 | M40: 4.4 | N40: 0 | O40: 0 | P40: 1.38 | Q40: 2.4 | R40: 0 | S40: 52 | T40: 0 | U40: =M40-N40-O40-P40-Q40-R40+S40+T40 -> 52.62 | X40: 0 | Y40: 18 | Z40: =Z39-Y40 -> 2649 | AA40: =N40+O40+P40+Q40+R40+U40+X40+Y40 -> 74.4 | AB40: =IF(L40<0,L40*-1,0) -> 0 | AC40: =AA40+AB40 -> 74.4 | AD40: 0 | AE40: 52 | AF40: 19 | AG40: =AG39+(U40*1.9835) -> 2617.8964 | AH40: 0
A41: 30 | B41: 6864.15 | C41: 172862 | D41: =C41-C40 -> -25 | E41: =C41-152000 -> 20862 | F41: =D41/$D$2 -> -12.603983 | G41: 45 | H41: 0 | I41: =G41+H41 -> 45 | J41: =IF(L41>0,L41,0) -> 16.796017 | K41: =I41+J41 -> 61.796017 | L41: =F41-(I41-AA41) -> 16.796017 | M41: 4.4 | N41: 0 | O41: 0 | P41: 1.38 | Q41: 2.4 | R41: 0 | S41: 52 | T41: 0 | U41: =M41-N41-O41-P41-Q41-R41+S41+T41 -> 52.62 | X41: 0 | Y41: 18 | Z41: =Z40-Y41 -> 2631 | AA41: =N41+O41+P41+Q41+R41+U41+X41+Y41 -> 74.4 | AB41: =IF(L41<0,L41*-1,0) -> 0 | AC41: =AA41+AB41 -> 74.4 | AD41: 0 | AE41: 55 | AF41: 26 | AG41: =AG40+(U41*1.9835) -> 2722.2682 | AH41: 0
A43: MONTH / CFS | F43: =SUM(F12:F41) -> -544.99622 | G43: =SUM(G12:G41) -> 1861 | H43: =SUM(H12:H41) -> 0 | I43: =SUM(I12:I41) -> 1861 | J43: =SUM(J12:J41) -> 210.97716 | K43: =SUM(K12:K41) -> 2071.9772 | L43: =SUM(L12:L41) -> 29.003781 | M43: =SUM(M12:M41) -> 238 | ... U43: =SUM(U12:U41) -> 1727.5305 | Y43: =SUM(Y12:Y41) -> 588 | AA43: =SUM(AA12:AA41) -> 2435 | AB43: =SUM(AB12:AB41) -> 181.97338 | AC43: =SUM(AC12:AC41) -> 2616.9734 | AD43: =SUM(AD12:AD41) -> 0.98 | AE43: =AVERAGE(AE12:AE41) -> 46.1 | AF43: =AVERAGE(AF12:AF42) -> 26 | AG43: Avg | AH43: =SUM(AH12:AH41) -> 369.86063
A44: MONTH / AF | D44: =SUM(D12:D41) -> -1081 | F44: =F43*$D$2 -> -1081 | G44: =G43*$D$2 -> 3691.2935 | H44: =H43*$D$2 -> 0 | I44: =I43*$D$2 -> 3691.2935 | J44: =J43*$D$2 -> 418.4732 | K44: =K43*$D$2 -> 4109.7667 | L44: =L43*$D$2 -> 57.529 | M44: =M43*$D$2 -> 472.073 | ... U44: =U43*$D$2 -> 3426.5567 | Y44: =Y43*$D$2 -> 1166.298 | AA44: =AA43*$D$2 -> 4829.8225 | AB44: =AB43*$D$2 -> 360.9442 | AC44: =AC43*$D$2 -> 5190.7667 | AE44: =MAX(AE12:AE41) -> 56 | AF44: =MAX(AF12:AF42) -> 43 | AG44: HI | AH44: =AH43*$D$2 -> 733.61855
A46: SEASON / CFS | AE46: =MIN(AE12:AE41) -> 27 | AF46: =MIN(AF12:AF42) -> 5 | AG46: LO
A47: SEASON / AF
A49: YTD / CFS | F49: =F10+F43 -> -544.99622 | G49: =G10+G43 -> 1861 | H49: =H10+H43 -> 0 | I49: =I10+I43 -> 1861 | J49: =J10+J43 -> 210.97716 | K49: =K10+K43 -> 2071.9772 | L49: =L10+L43 -> 29.003781 | M49: =M10+M43 -> 238 | N49: =N10+N43 -> 0 | O49: 0 | P49: =P10+P43 -> 41.4 | Q49: =Q10+Q43 -> 72 | R49: =R10+R43 -> 0 | S49: =S10+S43 -> 1514 | T49: =T10+T43 -> 95 | U49: =U10+U43 -> 1727.5305 | Y49: =Y10+Y43 -> 588 | Z49: =Z41 -> 2631 | AA49: =AA10+AA43 -> 2435 | AB49: =AB10+AB43 -> 181.97338 | AC49: =AC10+AC43 -> 2616.9734 | AD49: =AD10+AD43 -> 0.98 | AH49: =AH10+AH43 -> 369.86063
A50: YTD / AF | D50: =D10+D44 -> -1081 | E50: =E41 -> 20862 | F50: =F49*$D$2 -> -1081 | G50: =G49*$D$2 -> 3691.2935 | H50: =H49*$D$2 -> 0 | I50: =I49*$D$2 -> 3691.2935 | J50: =J49*$D$2 -> 418.4732 | K50: =K49*$D$2 -> 4109.7667 | L50: =L49*$D$2 -> 57.529 | M50: =M49*$D$2 -> 472.073 | ... U50: =U49*$D$2 -> 3426.5567 | Y50: =Y49*$D$2 -> 1166.298 | Z50: =Z49*$D$2 -> 5218.5885 | AA50: =AA49*$D$2 -> 4829.8225 | AB50: =AB49*$D$2 -> 360.9442 | AC50: =AC49*$D$2 -> 5190.7667 | AG50: =AG41 -> 2722.2682 | AH50: =AH49*$D$2 -> 733.61855

Sheet DEC
K1: MCPHEE RESERVOIR INFLOW/OUTFLOW TABULATION
A2: AF/cfs CONVERT FACTOR | D2: 1.9835 | K2: DECEMBER "2003"
D4: RESERVOIR | S4: INFLOW/OUTFLOW (CFS) | AE4: WEATHER | AI4: ADJUSTMENTS
A5: DATE | B5: RESERV | C5: RESERV | D5: AC FT | E5: ACTIVE | F5: CONV TO | G5: DOLORES | H5: LOST | I5: RECORD | J5: CALC | K5: TOTAL | L5: CALC | M5: DOLORES TUNNEL | S5: LONE | T5: U | U5: TOTAL | V5: MVI | W5: MVI | X5: DV CR | Y5: BELOW | Z5: FISH | AA5: RECORD | AB5: CALC | AC5: TOTAL | AD5: RAIN | AE5: MAX | AF5: MIN | AG5: NAR | AH5: MVI | AI5: MVI | AJ5: MVI | AK5: U/S
A6: DEC | B6: ELEV | C6: AC FT | D6: CHANGE | E6: CAP | F6: CFS | G6: RIVER | H6: CAN | I6: INFLOW | J6: INFLOW | K6: INFLOW | L6: INF/OTF | M6: TOT DIV | N6: WET | O6: UTE | P6: MWC | Q6: CTZ | R6: CTZ & | S6: PINE | T6: LAT | U6: MVI | V6: CALL + | W6: PROJ | X6: CANAL | Y6: MCP | Z6: LEFT | AA6: OTF | AB6: OTF | AC6: OTF | AE6: TMP | AF6: TMP | AG6: CALL | AH6: STOCK | AI6: STORED | AJ6: STORED | AK6: USERS
E7: AC FT | N7: LAND | O7: F&R | R7: UTE | V7: TO EX | AG7: AC.FT. | AH7: AC.FT. | AI7: Apr-Jun | AJ7: EVAP | AK7: EXCH
R8: PROJ | AJ8: AC.FT.
A9: SEASON BAL
A10: YTD | B10: =NOV!B41 -> 6864.15 | C10: =NOV!C41 -> 172862 | D10: =NOV!D50 -> -1081 | E10: =NOV!E50 -> 20862 | F10: =NOV!F49 -> -544.99622 | G10: =NOV!G49 -> 1861 | H10: =NOV!H49 -> 0 | I10: =NOV!I49 -> 1861 | J10: =NOV!J49 -> 210.97716 | K10: =NOV!K49 -> 2071.9772 | L10: =NOV!L49 -> 29.003781 | M10: =NOV!M49 -> 238 | ... U10: =NOV!U49 -> 1727.5305 | Y10: =NOV!Y49 -> 588 | Z10: =NOV!Z49 -> 2631 | AA10: =NOV!AA49 -> 2435 | AB10: =NOV!AB49 -> 181.97338 | AC10: =NOV!AC49 -> 2616.9734 | AD10: =NOV!AD49 -> 0.98 | AG10: =NOV!AG50 -> 2722.2682 | AH10: =NOV!AH49 -> 369.86063
A12: 1 | B12: 6864.14 | C12: 172837 | D12: =C12-C10 -> -25 | E12: =C12-152000 -> 20837 | F12: =D12/$D$2 -> -12.603983 | G12: 50 | H12: 0 | I12: =G12+H12 -> 50 | J12: =IF(L12>0,L12,0) -> 10.796017 | K12: =I12+J12 -> 60.796017 | L12: =F12-(I12-AA12) -> 10.796017 | M12: 4.4 | N12: 0 | O12: 0 | P12: 1.4 | Q12: 2.4 | R12: 0 | S12: 51 | T12: 0 | U12: =M12-N12-O12-P12-Q12-R12+S12+T12 -> 51.6 | X12: 0 | Y12: 18 | Z12: =Z10-Y12 -> 2613 | AA12: =N12+O12+P12+Q12+R12+U12+X12+Y12 -> 73.4 | AB12: =IF(L12<0,L12*-1,0) -> 0 | AC12: =AA12+AB12 -> 73.4 | AD12: 0 | AE12: 61 | AF12: 29 | AG12: =AG10+(U12*1.9835) -> 2824.6168 | AH12: 0
A13: =A12+1 -> 2 | B13: 6864.13 | C13: 172813 | D13: =C13-C12 -> -24 | E13: =C13-152000 -> 20813 | F13: =D13/$D$2 -> -12.099824 | G13: 53 | H13: 0 | I13: =G13+H13 -> 53 | J13: =IF(L13>0,L13,0) -> 7.3001765 | K13: =I13+J13 -> 60.300176 | L13: =F13-(I13-AA13) -> 7.3001765 | M13: 4.4 | N13: 0 | O13: 0 | P13: 1.4 | Q13: 2.4 | R13: 0 | S13: 50 | T13: 0 | U13: =M13-N13-O13-P13-Q13-R13+S13+T13 -> 50.6 | X13: 0 | Y13: 18 | Z13: =Z12-Y13 -> 2595 | AA13: =N13+O13+P13+Q13+R13+U13+X13+Y13 -> 72.4 | AB13: =IF(L13<0,L13*-1,0) -> 0 | AC13: =AA13+AB13 -> 72.4 | AD13: 0 | AE13: 53 | AF13: 27 | AG13: =AG12+(U13*1.9835) -> 2924.9819 | AH13: 0
A14: =A13+1 -> 3 | B14: 6864.12 | C14: 172788 | D14: =C14-C13 -> -25 | E14: =C14-152000 -> 20788 | F14: =D14/$D$2 -> -12.603983 | G14: 51 | H14: 0 | I14: =G14+H14 -> 51 | J14: =IF(L14>0,L14,0) -> 13.006017 | K14: =I14+J14 -> 64.006017 | L14: =F14-(I14-AA14) -> 13.006017 | M14: 4.2 | N14: 0 | O14: 4.41 | P14: 1.4 | Q14: 2.4 | R14: 0 | S14: 50 | T14: 0 | U14: =M14-N14-P14-Q14-R14+S14+T14 -> 50.4 | X14: 0 | Y14: 18 | Z14: =Z13-Y14 -> 2577 | AA14: =N14+O14+P14+Q14+R14+U14+X14+Y14 -> 76.61 | AB14: =IF(L14<0,L14*-1,0) -> 0 | AC14: =AA14+AB14 -> 76.61 | AD14: 0 | AE14: 52 | AF14: 24 | AG14: =AG13+(U14*1.9835) -> 3024.9503 | AH14: 0
A15: =A14+1 -> 4 | B15: 6864.11 | C15: 172764 | D15: =C15-C14 -> -24 | E15: =C15-152000 -> 20764 | F15: =D15/$D$2 -> -12.099824 | G15: 48 | H15: 0 | I15: =G15+H15 -> 48 | J15: =IF(L15>0,L15,0) -> 20.300176 | K15: =I15+J15 -> 68.300176 | L15: =F15-(I15-AA15) -> 20.300176 | M15: 4.1 | N15: 0 | O15: 8.3 | P15: 1.4 | Q15: 2.4 | R15: 0 | S15: 50 | T15: 0 | U15: =M15-N15-P15-Q15-R15+S15+T15 -> 50.3 | X15: 0 | Y15: 18 | Z15: =Z14-Y15 -> 2559 | AA15: =N15+O15+P15+Q15+R15+U15+X15+Y15 -> 80.4 | AB15: =IF(L15<0,L15*-1,0) -> 0 | AC15: =AA15+AB15 -> 80.4 | AD15: 0 | AE15: 52 | AF15: 23 | AG15: =AG14+(U15*1.9835) -> 3124.7203 | AH15: 0
A16: =A15+1 -> 5 | B16: 6864.1 | C16: 172739 | D16: =C16-C15 -> -25 | E16: =C16-152000 -> 20739 | F16: =D16/$D$2 -> -12.603983 | G16: 46 | H16: 0 | I16: =G16+H16 -> 46 | J16: =IF(L16>0,L16,0) -> 17.576017 | K16: =I16+J16 -> 63.576017 | L16: =F16-(I16-AA16) -> 17.576017 | M16: 4.1 | N16: 0 | O16: 4.08 | P16: 1.4 | Q16: 2.4 | R16: 0 | S16: 50 | T16: 0 | U16: =M16-N16-P16-Q16-R16+S16+T16 -> 50.3 | X16: 0 | Y16: 18 | Z16: =Z15-Y16 -> 2541 | AA16: =N16+O16+P16+Q16+R16+U16+X16+Y16 -> 76.18 | AB16: =IF(L16<0,L16*-1,0) -> 0 | AC16: =AA16+AB16 -> 76.18 | AD16: 0 | AE16: 48 | AF16: 25 | AG16: =AG15+(U16*1.9835) -> 3224.4904 | AH16: 0
A17: =A16+1 -> 6 | B17: 6864.09 | C17: 172715 | D17: =C17-C16 -> -24 | E17: =C17-152000 -> 20715 | F17: =D17/$D$2 -> -12.099824 | G17: 46 | H17: 0 | I17: =G17+H17 -> 46 | J17: =IF(L17>0,L17,0) -> 14.000176 | K17: =I17+J17 -> 60.000176 | L17: =F17-(I17-AA17) -> 14.000176 | M17: 4.1 | N17: 0 | O17: 0 | P17: 1.4 | Q17: 2.4 | R17: 0 | S17: 50 | T17: 0 | U17: =M17-N17-P17-Q17-R17+S17+T17 -> 50.3 | X17: 0 | Y17: 18 | Z17: =Z16-Y17 -> 2523 | AA17: =N17+O17+P17+Q17+R17+U17+X17+Y17 -> 72.1 | AB17: =IF(L17<0,L17*-1,0) -> 0 | AC17: =AA17+AB17 -> 72.1 | AD17: 0 | AE17: 55 | AF17: 32 | AG17: =AG16+(U17*1.9835) -> 3324.2604 | AH17: 0
A18: =A17+1 -> 7 | B18: 6864.08 | C18: 172690 | D18: =C18-C17 -> -25 | E18: =C18-152000 -> 20690 | F18: =D18/$D$2 -> -12.603983 | G18: 46 | H18: 0 | I18: =G18+H18 -> 46 | J18: =IF(L18>0,L18,0) -> 13.496017 | K18: =I18+J18 -> 59.496017 | L18: =F18-(I18-AA18) -> 13.496017 | M18: 4.1 | N18: 0 | O18: 0 | P18: 1.4 | Q18: 2.4 | R18: 0 | S18: 50 | T18: 0 | U18: =M18-N18-P18-Q18-R18+S18+T18 -> 50.3 | X18: 0 | Y18: 18 | Z18: =Z17-Y18 -> 2505 | AA18: =N18+O18+P18+Q18+R18+U18+X18+Y18 -> 72.1 | AB18: =IF(L18<0,L18*-1,0) -> 0 | AC18: =AA18+AB18 -> 72.1 | AD18: 0 | AE18: 48 | AF18: 33 | AG18: =AG17+(U18*1.9835) -> 3424.0305 | AH18: 0
A19: =A18+1 -> 8 | B19: 6864.06 | C19: 172641 | D19: =C19-C18 -> -49 | E19: =C19-152000 -> 20641 | F19: =D19/$D$2 -> -24.703806 | G19: 45 | H19: 0 | I19: =G19+H19 -> 45 | J19: =IF(L19>0,L19,0) -> 15.086194 | K19: =I19+J19 -> 60.086194 | L19: =F19-(I19-AA19) -> 15.086194 | M19: 4.1 | N19: 0 | O19: 6.69 | P19: 1.4 | Q19: 2.4 | R19: 0 | S19: 56 | T19: 0 | U19: =M19-N19-P19-Q19-R19+S19+T19 -> 56.3 | X19: 0 | Y19: 18 | Z19: =Z18-Y19 -> 2487 | AA19: =N19+O19+P19+Q19+R19+U19+X19+Y19 -> 84.79 | AB19: =IF(L19<0,L19*-1,0) -> 0 | AC19: =AA19+AB19 -> 84.79 | AD19: 0.14 | AE19: 42 | AF19: 24 | AG19: =AG18+(U19*1.9835) -> 3535.7015 | AH19: 0
A20: =A19+1 -> 9 | B20: 6864.03 | C20: 172567 | D20: =C20-C19 -> -74 | E20: =C20-152000 -> 20567 | F20: =D20/$D$2 -> -37.307789 | G20: 43 | H20: 0 | I20: =G20+H20 -> 43 | J20: =IF(L20>0,L20,0) -> 3.7922107 | K20: =I20+J20 -> 46.792211 | L20: =F20-(I20-AA20) -> 3.7922107 | M20: 4.1 | N20: 0 | O20: 0 | P20: 1.4 | Q20: 2.4 | R20: 0 | S20: 61 | T20: 0 | U20: =M20-N20-P20-Q20-R20+S20+T20 -> 61.3 | X20: 0 | Y20: 19 | Z20: =Z19-Y20 -> 2468 | AA20: =N20+O20+P20+Q20+R20+U20+X20+Y20 -> 84.1 | AB20: =IF(L20<0,L20*-1,0) -> 0 | AC20: =AA20+AB20 -> 84.1 | AD20: 0 | AE20: 39 | AF20: 16 | AG20: =AG19+(U20*1.9835) -> 3657.2901 | AH20: 0
A21: =A20+1 -> 10 | B21: 6864 | C21: 172493 | D21: =C21-C20 -> -74 | E21: =C21-152000 -> 20493 | F21: =D21/$D$2 -> -37.307789 | G21: 32 | H21: 0 | I21: =G21+H21 -> 32 | J21: =IF(L21>0,L21,0) -> 12.482211 | K21: =I21+J21 -> 44.482211 | L21: =F21-(I21-AA21) -> 12.482211 | M21: 4.1 | N21: 0 | O21: 1.69 | P21: 1.4 | Q21: 2.4 | R21: 0 | S21: 60 | T21: 0 | U21: =M21-N21-P21-Q21-R21+S21+T21 -> 60.3 | X21: 0 | Y21: 16 | Z21: =Z20-Y21 -> 2452 | AA21: =N21+O21+P21+Q21+R21+U21+X21+Y21 -> 81.79 | AB21: =IF(L21<0,L21*-1,0) -> 0 | AC21: =AA21+AB21 -> 81.79 | AD21: 0 | AE21: 39 | AF21: 14 | AG21: =AG20+(U21*1.9835) -> 3776.8951 | AH21: 0
A22: =A21+1 -> 11 | B22: 6863.97 | C22: 172421 | D22: =C22-C21 -> -72 | E22: =C22-152000 -> 20421 | F22: =D22/$D$2 -> -36.299471 | G22: 31 | H22: 0 | I22: =G22+H22 -> 31 | J22: =IF(L22>0,L22,0) -> 13.425529 | K22: =I22+J22 -> 44.425529 | L22: =F22-(I22-AA22) -> 13.425529 | M22: 4.1 | N22: 0 | O22: 1.625 | P22: 1.4 | Q22: 2.4 | R22: 0 | S22: 59 | T22: 0 | U22: =M22-N22-P22-Q22-R22+S22+T22 -> 59.3 | X22: 0 | Y22: 16 | Z22: =Z21-Y22 -> 2436 | AA22: =N22+O22+P22+Q22+R22+U22+X22+Y22 -> 80.725 | AB22: =IF(L22<0,L22*-1,0) -> 0 | AC22: =AA22+AB22 -> 80.725 | AD22: 0 | AE22: 40 | AF22: 20 | AG22: =AG21+(U22*1.9835) -> 3894.5167 | AH22: 0
A23: =A22+1 -> 12 | B23: 6863.94 | C23: 172348 | D23: =C23-C22 -> -73 | E23: =C23-152000 -> 20348 | F23: =D23/$D$2 -> -36.80363 | G23: 39 | H23: 0 | I23: =G23+H23 -> 39 | J23: =IF(L23>0,L23,0) -> 7.3163701 | K23: =I23+J23 -> 46.31637 | L23: =F23-(I23-AA23) -> 7.3163701 | M23: 4.1 | N23: 0 | O23: 1.02 | P23: 1.4 | Q23: 2.4 | R23: 0 | S23: 59 | T23: 0 | U23: =M23-N23-P23-Q23-R23+S23+T23 -> 59.3 | X23: 0 | Y23: 19 | Z23: =Z22-Y23 -> 2417 | AA23: =N23+O23+P23+Q23+R23+U23+X23+Y23 -> 83.12 | AB23: =IF(L23<0,L23*-1,0) -> 0 | AC23: =AA23+AB23 -> 83.12 | AD23: 0 | AE23: 37 | AF23: 18 | AG23: =AG22+(U23*1.9835) -> 4012.1382 | AH23: 0
A24: =A23+1 -> 13 | B24: 6863.91 | C24: 172276 | D24: =C24-C23 -> -72 | E24: =C24-152000 -> 20276 | F24: =D24/$D$2 -> -36.299471 | G24: 30 | H24: 0 | I24: =G24+H24 -> 30 | J24: =IF(L24>0,L24,0) -> 16.830529 | K24: =I24+J24 -> 46.830529 | L24: =F24-(I24-AA24) -> 16.830529 | M24: 4.1 | N24: 0 | O24: 1.03 | P24: 1.4 | Q24: 2.4 | R24: 0 | S24: 59 | T24: 0 | U24: =M24-N24-P24-Q24-R24+S24+T24 -> 59.3 | X24: 0 | Y24: 19 | Z24: =Z23-Y24 -> 2398 | AA24: =N24+O24+P24+Q24+R24+U24+X24+Y24 -> 83.13 | AB24: =IF(L24<0,L24*-1,0) -> 0 | AC24: =AA24+AB24 -> 83.13 | AD24: 0 | AE24: 41 | AF24: 17 | AG24: =AG23+(U24*1.9835) -> 4129.7598 | AH24: 0
A25: =A24+1 -> 14 | B25: 6863.89 | C25: 172228 | D25: =C25-C24 -> -48 | E25: =C25-152000 -> 20228 | F25: =D25/$D$2 -> -24.199647 | G25: 32 | H25: 0 | I25: =G25+H25 -> 32 | J25: =IF(L25>0,L25,0) -> 27.480353 | K25: =I25+J25 -> 59.480353 | L25: =F25-(I25-AA25) -> 27.480353 | M25: 4.1 | N25: 0 | O25: 1.58 | P25: 1.4 | Q25: 2.4 | R25: 0 | S25: 59 | T25: 0 | U25: =M25-N25-P25-Q25-R25+S25+T25 -> 59.3 | X25: 0 | Y25: 19 | Z25: =Z24-Y25 -> 2379 | AA25: =N25+O25+P25+Q25+R25+U25+X25+Y25 -> 83.68 | AB25: =IF(L25<0,L25*-1,0) -> 0 | AC25: =AA25+AB25 -> 83.68 | AD25: 0 | AE25: 46 | AF25: 23 | AG25: =AG24+(U25*1.9835) -> 4247.3813 | AH25: 0
... A32: =A31+1 -> 21 | B32: 6863.79 | C32: 171986 | D32: =C32-C31 -> -24 | E32: =C32-152000 -> 19986 | F32: =D32/$D$2 -> -12.099824 | G32: 39 | H32: 0 | I32: =G32+H32 -> 39 | J32: =IF(L32>0,L32,0) -> 13.000176 | K32: =I32+J32 -> 52.000176 | L32: =F32-(I32-AA32) -> 13.000176 | M32: 4.1 | N32: 0 | O32: 0 | P32: 1.4 | Q32: 2.4 | R32: 0 | S32: 42 | T32: 0 | U32: =M32-N32-P32-Q32-R32+S32+T32 -> 42.3 | X32: 0 | Y32: 18 | Z32: =Z31-Y32 -> 2253 | AA32: =N32+O32+P32+Q32+R32+U32+X32+Y32 -> 64.1 | AB32: =IF(L32<0,L32*-1,0) -> 0 | AC32: =AA32+AB32 -> 64.1 | AD32: 0.06 | AE32: 46 | AF32: 28 | AG32: =AG31+(U32*1.9835) -> 4850.5637 | AH32: 0
A33: =A32+1 -> 22 | B33: 6863.79 | C33: 171986 | D33: =C33-C32 -> 0 | E33: =C33-152000 -> 19986 | F33: =D33/$D$2 -> 0 | G33: 40 | H33: 0 | I33: =G33+H33 -> 40 | J33: =IF(L33>0,L33,0) -> 22.1 | K33: =I33+J33 -> 62.1 | L33: =F33-(I33-AA33) -> 22.1 | M33: 4.1 | N33: 0 | O33: 0 | P33: 1.4 | Q33: 2.4 | R33: 0 | S33: 40 | T33: 0 | U33: =M33-N33-O33-P33-Q33-R33+S33+T33 -> 40.3 | X33: 0 | Y33: 18 | Z33: =Z32-Y33 -> 2235 | AA33: =N33+O33+P33+Q33+R33+U33+X33+Y33 -> 62.1 | AB33: =IF(L33<0,L33*-1,0) -> 0 | AC33: =AA33+AB33 -> 62.1 | AD33: 0 | AE33: 41 | AF33: 25 | AG33: =AG32+(U33*1.9835) -> 4930.4987 | AH33: 0
A34: =A33+1 -> 23 | B34: 6863.78 | C34: 171962 | D34: =C34-C33 -> -24 | E34: =C34-152000 -> 19962 | F34: =D34/$D$2 -> -12.099824 | G34: 37 | H34: 0 | I34: =G34+H34 -> 37 | J34: =IF(L34>0,L34,0) -> 12.000176 | K34: =I34+J34 -> 49.000176 | L34: =F34-(I34-AA34) -> 12.000176 | M34: 4.1 | N34: 0 | O34: 0 | P34: 1.4 | Q34: 2.4 | R34: 0 | S34: 39 | T34: 0 | U34: =M34-N34-O34-P34-Q34-R34+S34+T34 -> 39.3 | X34: 0 | Y34: 18 | Z34: =Z33-Y34 -> 2217 | AA34: =N34+O34+P34+Q34+R34+U34+X34+Y34 -> 61.1 | AB34: =IF(L34<0,L34*-1,0) -> 0 | AC34: =AA34+AB34 -> 61.1 | AD34: 0 | AE34: 45 | AF34: 18 | AG34: =AG33+(U34*1.9835) -> 5008.4503 | AH34: 0
A35: =A34+1 -> 24 | B35: 6863.78 | C35: 171962 | D35: =C35-C34 -> 0 | E35: =C35-152000 -> 19962 | F35: =D35/$D$2 -> 0 | G35: 34 | H35: 0 | I35: =G35+H35 -> 34 | J35: =IF(L35>0,L35,0) -> 27.1 | K35: =I35+J35 -> 61.1 | L35: =F35-(I35-AA35) -> 27.1 | M35: 4.1 | N35: 0 | O35: 0 | P35: 1.4 | Q35: 2.4 | R35: 0 | S35: 39 | T35: 0 | U35: =M35-N35-O35-P35-Q35-R35+S35+T35 -> 39.3 | X35: 0 | Y35: 18 | Z35: =Z34-Y35 -> 2199 | AA35: =N35+O35+P35+Q35+R35+U35+X35+Y35 -> 61.1 | AB35: =IF(L35<0,L35*-1,0) -> 0 | AC35: =AA35+AB35 -> 61.1 | AD35: 0 | AE35: 44 | AF35: 21 | AG35: =AG34+(U35*1.9835) -> 5086.4018 | AH35: 0
A36: =A35+1 -> 25 | B36: 6863.77 | C36: 171938 | D36: =C36-C35 -> -24 | E36: =C36-152000 -> 19938 | F36: =D36/$D$2 -> -12.099824 | G36: 38 | H36: 0 | I36: =G36+H36 -> 38 | J36: =IF(L36>0,L36,0) -> 12.000176 | K36: =I36+J36 -> 50.000176 | L36: =F36-(I36-AA36) -> 12.000176 | M36: 4.1 | N36: 0 | O36: 0 | P36: 1.4 | Q36: 2.4 | R36: 0 | S36: 39 | T36: 0 | U36: =M36-N36-O36-P36-Q36-R36+S36+T36 -> 39.3 | X36: 0 | Y36: 19 | Z36: =Z35-Y36 -> 2180 | AA36: =N36+O36+P36+Q36+R36+U36+X36+Y36 -> 62.1 | AB36: =IF(L36<0,L36*-1,0) -> 0 | AC36: =AA36+AB36 -> 62.1 | AD36: 0.01 | AE36: 38 | AF36: 31 | AG36: =AG35+(U36*1.9835) -> 5164.3534 | AH36: 0
A37: =A36+1 -> 26 | B37: 6863.77 | C37: 171938 | D37: =C37-C36 -> 0 | E37: =C37-152000 -> 19938 | F37: =D37/$D$2 -> 0 | G37: 38 | H37: 0 | I37: =G37+H37 -> 38 | J37: =IF(L37>0,L37,0) -> 23.1 | K37: =I37+J37 -> 61.1 | L37: =F37-(I37-AA37) -> 23.1 | M37: 4.1 | N37: 0 | O37: 0 | P37: 1.4 | Q37: 2.4 | R37: 0 | S37: 39 | T37: 0 | U37: =M37-N37-O37-P37-Q37-R37+S37+T37 -> 39.3 | X37: 0 | Y37: 18 | Z37: =Z36-Y37 -> 2162 | AA37: =N37+O37+P37+Q37+R37+U37+X37+Y37 -> 61.1 | AB37: =IF(L37<0,L37*-1,0) -> 0 | AC37: =AA37+AB37 -> 61.1 | AD37: 0.27 | AE37: 40 | AF37: 22 | AG37: =AG36+(U37*1.9835) -> 5242.3049 | AH37: 0
A38: =A37+1 -> 27 | B38: 6863.76 | C38: 171913 | D38: =C38-C37 -> -25 | E38: =C38-152000 -> 19913 | F38: =D38/$D$2 -> -12.603983 | G38: 34 | H38: 0 | I38: =G38+H38 -> 34 | J38: =IF(L38>0,L38,0) -> 16.496017 | K38: =I38+J38 -> 50.496017 | L38: =F38-(I38-AA38) -> 16.496017 | M38: 4.1 | N38: 0 | O38: 0 | P38: 1.4 | Q38: 2.4 | R38: 0 | S38: 40 | T38: 0 | U38: =M38-N38-O38-P38-Q38-R38+S38+T38 -> 40.3 | X38: 0 | Y38: 19 | Z38: =Z37-Y38 -> 2143 | AA38: =N38+O38+P38+Q38+R38+U38+X38+Y38 -> 63.1 | AB38: =IF(L38<0,L38*-1,0) -> 0 | AC38: =AA38+AB38 -> 63.1 | AD38: 0.16 | AE38: 24 | AF38: -5 | AG38: =AG37+(U38*1.9835) -> 5322.24 | AH38: 0
A39: =A38+1 -> 28 | B39: 6863.76 | C39: 171913 | D39: =C39-C38 -> 0 | E39: =C39-152000 -> 19913 | F39: =D39/$D$2 -> 0 | G39: 29 | H39: 0 | I39: =G39+H39 -> 29 | J39: =IF(L39>0,L39,0) -> 34.1 | K39: =I39+J39 -> 63.1 | L39: =F39-(I39-AA39) -> 34.1 | M39: 4.1 | N39: 0 | O39: 0 | P39: 1.4 | Q39: 2.4 | R39: 0 | S39: 40 | T39: 0 | U39: =M39-N39-O39-P39-Q39-R39+S39+T39 -> 40.3 | X39: 0 | Y39: 19 | Z39: =Z38-Y39 -> 2124 | AA39: =N39+O39+P39+Q39+R39+U39+X39+Y39 -> 63.1 | AB39: =IF(L39<0,L39*-1,0) -> 0 | AC39: =AA39+AB39 -> 63.1 | AD39: 0 | AE39: 24 | AF39: 0 | AG39: =AG38+(U39*1.9835) -> 5402.175 | AH39: 0
A40: =A39+1 -> 29 | B40: 6863.74 | C40: 171865 | D40: =C40-C39 -> -48 | E40: =C40-152000 -> 19865 | F40: =D40/$D$2 -> -24.199647 | G40: 30 | H40: 0 | I40: =G40+H40 -> 30 | J40: =IF(L40>0,L40,0) -> 14.600353 | K40: =I40+J40 -> 44.600353 | L40: =F40-(I40-AA40) -> 14.600353 | M40: 3.8 | N40: 0 | O40: 0 | P40: 1.4 | Q40: 2.4 | R40: 0 | S40: 47 | T40: 0 | U40: =M40-N40-O40-P40-Q40-R40+S40+T40 -> 47 | X40: 0 | Y40: 18 | Z40: =Z39-Y40 -> 2106 | AA40: =N40+O40+P40+Q40+R40+U40+X40+Y40 -> 68.8 | AB40: =IF(L40<0,L40*-1,0) -> 0 | AC40: =AA40+AB40 -> 68.8 | AD40: 0 | AE40: 28 | AF40: 3 | AG40: =AG39+(U40*1.9835) -> 5495.3995 | AH40: 0
A41: 30 | B41: 6863.72 | C41: 171817 | D41: =C41-C40 -> -48 | E41: =C41-152000 -> 19817 | F41: =D41/$D$2 -> -24.199647 | G41: 34 | H41: 0 | I41: =G41+H41 -> 34 | J41: =IF(L41>0,L41,0) -> 16.600353 | K41: =I41+J41 -> 50.600353 | L41: =F41-(I41-AA41) -> 16.600353 | M41: 3.8 | N41: 0 | O41: 0 | P41: 1.4 | Q41: 2.4 | R41: 0 | S41: 53 | T41: 0 | U41: =M41-N41-O41-P41-Q41-R41+S41+T41 -> 53 | X41: 0 | Y41: 18 | Z41: =Z40-Y41 -> 2088 | AA41: =N41+O41+P41+Q41+R41+U41+X41+Y41 -> 74.8 | AB41: =IF(L41<0,L41*-1,0) -> 0 | AC41: =AA41+AB41 -> 74.8 | AD41: 0 | AE41: 37 | AF41: 23 | AG41: =AG40+(U41*1.9835) -> 5600.525 | AH41: 0
A42: 31 | B42: 6863.7 | C42: 171768 | D42: =C42-C41 -> -49 | E42: =C42-152000 -> 19768 | F42: =D42/$D$2 -> -24.703806 | G42: 37 | H42: 0 | I42: =G42+H42 -> 37 | J42: =IF(L42>0,L42,0) -> 13.996194 | K42: =I42+J42 -> 50.996194 | L42: =F42-(I42-AA42) -> 13.996194 | M42: 3.7 | N42: 0 | O42: 0 | P42: 1.4 | Q42: 2.4 | R42: 0 | S42: 54 | T42: 0 | U42: =M42-N42-O42-P42-Q42-R42+S42+T42 -> 53.9 | X42: 0 | Y42: 18 | Z42: =Z41-Y42 -> 2070 | AA42: =N42+O42+P42+Q42+R42+U42+X42+Y42 -> 75.7 | AB42: =IF(L42<0,L42*-1,0) -> 0 | AC42: =AA42+AB42 -> 75.7 | AD42: 0 | AE42: 43 | AF42: 20 | AG42: =AG41+(U42*1.9835) -> 5707.4357 | AH42: 0
A44: MONTH / CFS | F44: =SUM(F12:F42) -> -551.55029 | G44: =SUM(G12:G42) -> 1190 | H44: =SUM(H12:H42) -> 0 | I44: =SUM(I12:I42) -> 1190 | J44: =SUM(J12:J42) -> 474.10471 | K44: =SUM(K12:K42) -> 1664.1047 | L44: =SUM(L12:L42) -> 474.10471 | M44: =SUM(M12:M42) -> 126.8 | ... U44: =SUM(U12:U42) -> 1505 | Y44: =SUM(Y12:Y42) -> 561 | AA44: =SUM(AA12:AA42) -> 2215.655 | AB44: =SUM(AB12:AB42) -> 0 | AC44: =SUM(AC12:AC42) -> 2215.655 | AD44: =SUM(AD12:AD42) -> 0.65 | AE44: =AVERAGE(AE12:AE42) -> 42.774194 | AF44: =AVERAGE(AF12:AF42) -> 19.16129 | AG44: Avg | AH44: =SUM(AH12:AH42) -> 0
A45: MONTH / AF | D45: =SUM(D12:D42) -> -1094 | F45: =F44*$D$2 -> -1094 | G45: =G44*$D$2 -> 2360.365 | H45: =H44*$D$2 -> 0 | I45: =I44*$D$2 -> 2360.365 | J45: =J44*$D$2 -> 940.38669 | K45: =K44*$D$2 -> 3300.7517 | L45: =L44*$D$2 -> 940.38669 | M45: =M44*$D$2 -> 251.5078 | ... U45: =U44*$D$2 -> 2985.1675 | Y45: =Y44*$D$2 -> 1112.7435 | AA45: =AA44*$D$2 -> 4394.7517 | AB45: =AB44*$D$2 -> 0 | AC45: =AC44*$D$2 -> 4394.7517 | AE45: =MAX(AE12:AE42) -> 61 | AF45: =MAX(AF12:AF42) -> 33 | AG45: HI | AH45: =AH44*$D$2 -> 0
A47: SEASON / CFS | AE47: =MIN(AE12:AE42) -> 24 | AF47: =MIN(AF12:AF42) -> -5 | AG47: LO
A48: SEASON / AF
A50: YTD / CFS | F50: =F10+F44 -> -1096.5465 | G50: =G10+G44 -> 3051 | H50: =H10+H44 -> 0 | I50: =I10+I44 -> 3051 | J50: =J10+J44 -> 685.08187 | K50: =K10+K44 -> 3736.0819 | L50: =L10+L44 -> 503.10849 | M50: =M10+M44 -> 364.8 | N50: =N10+N44 -> 0 | O50: 0 | P50: =P10+P44 -> 84.8 | Q50: =Q10+Q44 -> 146.4 | R50: =R10+R44 -> 0 | S50: =S10+S44 -> 3010 | T50: =T10+T44 -> 95 | U50: =U10+U44 -> 3232.5305 | Y50: =Y10+Y44 -> 1149 | Z50: =Z42 -> 2070 | AA50: =AA10+AA44 -> 4650.655 | AB50: =AB10+AB44 -> 181.97338 | AC50: =AC10+AC44 -> 4832.6284 | AD50: =AD10+AD44 -> 1.63 | AH50: =AH10+AH44 -> 369.86063
A51: YTD / AF | D51: =D10+D45 -> -2175 | E51: =E42 -> 19768 | F51: =F50*$D$2 -> -2175 | G51: =G50*$D$2 -> 6051.6585 | H51: =H50*$D$2 -> 0 | I51: =I50*$D$2 -> 6051.6585 | J51: =J50*$D$2 -> 1358.8599 | K51: =K50*$D$2 -> 7410.5184 | L51: =L50*$D$2 -> 997.91569 | M51: =M50*$D$2 -> 723.5808 | ... U51: =U50*$D$2 -> 6411.7242 | Y51: =Y50*$D$2 -> 2279.0415 | Z51: =Z50*$D$2 -> 4105.845 | AA51: =AA50*$D$2 -> 9224.5742 | AB51: =AB50*$D$2 -> 360.9442 | AC51: =AC50*$D$2 -> 9585.5184 | AG51: =AG42 -> 5707.4357 | AH51: =AH50*$D$2 -> 733.61855

Sheet JAN
K1: MCPHEE RESERVOIR INFLOW/OUTFLOW TABULATION
A2: AF/cfs CONVERT FACTOR | D2: 1.9835 | K2: JANUARY "2004"
D4: RESERVOIR | S4: INFLOW/OUTFLOW (CFS) | AE4: WEATHER | AI4: ADJUSTMENTS
A5: DATE | B5: RESERV | C5: RESERV | D5: AC FT | E5: ACTIVE | F5: CONV TO | G5: DOLORES | H5: LOST | I5: RECORD | J5: CALC | K5: TOTAL | L5: CALC | M5: DOLORES TUNNEL | S5: LONE | T5: U | U5: TOTAL | V5: MVI | W5: MVI | X5: DV CR | Y5: BELOW | Z5: FISH | AA5: RECORD | AB5: CALC | AC5: TOTAL | AD5: RAIN | AE5: MAX | AF5: MIN | AG5: NAR | AH5: MVI | AI5: MVI | AJ5: MVI | AK5: U/S
A6: JAN | B6: ELEV | C6: AC FT | D6: CHANGE | E6: CAP | F6: CFS | G6: RIVER | H6: CAN | I6: INFLOW | J6: INFLOW | K6: INFLOW | L6: INF/OTF | M6: TOT DIV | N6: WET | O6: UTE | P6: MWC | Q6: CTZ | R6: CTZ & | S6: PINE | T6: LAT | U6: MVI | V6: CALL + | W6: PROJ | X6: CANAL | Y6: MCP | Z6: LEFT | AA6: OTF | AB6: OTF | AC6: OTF | AE6: TMP | AF6: TMP | AG6: CALL | AH6: STOCK | AI6: STORED | AJ6: STORED | AK6: USERS
E7: AC FT | N7: LAND | O7: F&R | R7: UTE | V7: TO EX | AG7: AC.FT. | AH7: AC.FT. | AI7: Apr-Jun | AJ7: EVAP | AK7: EXCH
R8: PROJ | AJ8: AC.FT.
A9: SEASON BAL
A10: YTD | B10: =DEC!B42 -> 6863.7 | C10: =DEC!C42 -> 171768 | D10: =DEC!D51 -> -2175 | E10: =DEC!E51 -> 19768 | F10: =DEC!F50 -> -1096.5465 | G10: =DEC!G50 -> 3051 | H10: =DEC!H50 -> 0 | I10: =DEC!I50 -> 3051 | J10: =DEC!J50 -> 685.08187 | K10: =DEC!K50 -> 3736.0819 | L10: =DEC!L50 -> 503.10849 | M10: =DEC!M50 -> 364.8 | ... U10: =DEC!U50 -> 3232.5305 | Y10: =DEC!Y50 -> 1149 | Z10: =DEC!Z50 -> 2070 | AA10: =DEC!AA50 -> 4650.655 | AB10: =DEC!AB50 -> 181.97338 | AC10: =DEC!AC50 -> 4832.6284 | AD10: =DEC!AD50 -> 1.63 | AG10: =DEC!AG51 -> 5707.4357
A12: 1 | B12: 6863.69 | C12: 171744 | D12: =C12-C10 -> -24 | E12: =C12-152000 -> 19744 | F12: =D12/$D$2 -> -12.099824 | G12: 37 | H12: 0 | I12: =G12+H12 -> 37 | J12: =IF(L12>0,L12,0) -> 26.700176 | K12: =I12+J12 -> 63.700176 | L12: =F12-(I12-AA12) -> 26.700176 | M12: 3.8 | N12: 0 | O12: 0 | P12: 1.38 | Q12: 2.4 | R12: 0 | S12: 54 | T12: 0 | U12: =M12-N12-O12-P12-Q12-R12+S12+T12 -> 54.02 | X12: 0 | Y12: 18 | Z12: =Z10-Y12 -> 2052 | AA12: =N12+O12+P12+Q12+R12+U12+X12+Y12 -> 75.8 | AB12: =IF(L12<0,L12*-1,0) -> 0 | AC12: =AA12+AB12 -> 75.8 | AD12: 0.11 | AE12: 41 | AF12: 18 | AG12: =AG10+(U12*1.9835) -> 5814.5843 | AH12: 0
A13: =A12+1 -> 2 | B13: 6863.74 | C13: 171865 | D13: =C13-C12 -> 121 | E13: =C13-152000 -> 19865 | F13: =D13/$D$2 -> 61.003277 | G13: 34 | H13: 0 | I13: =G13+H13 -> 34 | J13: =IF(L13>0,L13,0) -> 102.90328 | K13: =I13+J13 -> 136.90328 | L13: =F13-(I13-AA13) -> 102.90328 | M13: 3.9 | N13: 0 | O13: 0 | P13: 1.38 | Q13: 2.4 | R13: 0 | S13: 54 | T13: 0 | U13: =M13-N13-O13-P13-Q13-R13+S13+T13 -> 54.12 | X13: 0 | Y13: 18 | Z13: =Z12-Y13 -> 2034 | AA13: =N13+O13+P13+Q13+R13+U13+X13+Y13 -> 75.9 | AB13: =IF(L13<0,L13*-1,0) -> 0 | AC13: =AA13+AB13 -> 75.9 | AD13: 0.71 | AE13: 35 | AF13: 30 | AG13: =AG12+(U13*1.9835) -> 5921.9314 | AH13: 0
A14: =A13+1 -> 3 | B14: 6863.77 | C14: 171938 | D14: =C14-C13 -> 73 | E14: =C14-152000 -> 19938 | F14: =D14/$D$2 -> 36.80363 | G14: 30 | H14: 0 | I14: =G14+H14 -> 30 | J14: =IF(L14>0,L14,0) -> 82.50363 | K14: =I14+J14 -> 112.50363 | L14: =F14-(I14-AA14) -> 82.50363 | M14: 3.7 | N14: 0 | O14: 0 | P14: 1.38 | Q14: 2.4 | R14: 0 | S14: 54 | T14: 0 | U14: =M14-N14-O14-P14-Q14-R14+S14+T14 -> 53.92 | X14: 0 | Y14: 18 | Z14: =Z13-Y14 -> 2016 | AA14: =N14+O14+P14+Q14+R14+U14+X14+Y14 -> 75.7 | AB14: =IF(L14<0,L14*-1,0) -> 0 | AC14: =AA14+AB14 -> 75.7 | AD14: 0.48 | AE14: 37 | AF14: 18 | AG14: =AG13+(U14*1.9835) -> 6028.8817 | AH14: 0
A15: =A14+1 -> 4 | B15: 6863.77 | C15: 171938 | D15: =C15-C14 -> 0 | E15: =C15-152000 -> 19938 | F15: =D15/$D$2 -> 0 | G15: 28 | H15: 0 | I15: =G15+H15 -> 28 | J15: =IF(L15>0,L15,0) -> 47.7 | K15: =I15+J15 -> 75.7 | L15: =F15-(I15-AA15) -> 47.7 | M15: 3.7 | N15: 0 | O15: 0 | P15: 1.38 | Q15: 2.4 | R15: 0 | S15: 54 | T15: 0 | U15: =M15-N15-O15-P15-Q15-R15+S15+T15 -> 53.92 | X15: 0 | Y15: 18 | Z15: =Z14-Y15 -> 1998 | AA15: =N15+O15+P15+Q15+R15+U15+X15+Y15 -> 75.7 | AB15: =IF(L15<0,L15*-1,0) -> 0 | AC15: =AA15+AB15 -> 75.7 | AD15: 0 | AE15: 28 | AF15: -1 | AG15: =AG14+(U15*1.9835) -> 6135.832 | AH15: 0
A16: =A15+1 -> 5 | B16: 6863.73 | C16: 171841 | D16: =C16-C15 -> -97 | E16: =C16-152000 -> 19841 | F16: =D16/$D$2 -> -48.903453 | G16: 25 | H16: 0 | I16: =G16+H16 -> 25 | J16: =IF(L16>0,L16,0) -> 4.7965465 | K16: =I16+J16 -> 29.796547 | L16: =F16-(I16-AA16) -> 4.7965465 | M16: 3.7 | N16: 0 | O16: 0 | P16: 1.38 | Q16: 2.4 | R16: 0 | S16: 57 | T16: 0 | U16: =M16-N16-O16-P16-Q16-R16+S16+T16 -> 56.92 | X16: 0 | Y16: 18 | Z16: =Z15-Y16 -> 1980 | AA16: =N16+O16+P16+Q16+R16+U16+X16+Y16 -> 78.7 | AB16: =IF(L16<0,L16*-1,0) -> 0 | AC16: =AA16+AB16 -> 78.7 | AD16: 0 | AE16: 27 | AF16: -5 | AG16: =AG15+(U16*1.9835) -> 6248.7328 | AH16: 0
A17: =A16+1 -> 6 | B17: 6863.69 | C17: 171744 | D17: =C17-C16 -> -97 | E17: =C17-152000 -> 19744 | F17: =D17/$D$2 -> -48.903453 | G17: 25 | H17: 0 | I17: =G17+H17 -> 25 | J17: =IF(L17>0,L17,0) -> 7.8965465 | K17: =I17+J17 -> 32.896547 | L17: =F17-(I17-AA17) -> 7.8965465 | M17: 3.8 | N17: 0 | O17: 0 | P17: 1.38 | Q17: 2.4 | R17: 0 | S17: 60 | T17: 0 | U17: =M17-N17-O17-P17-Q17-R17+S17+T17 -> 60.02 | X17: 0 | Y17: 18 | Z17: =Z16-Y17 -> 1962 | AA17: =N17+O17+P17+Q17+R17+U17+X17+Y17 -> 81.8 | AB17: =IF(L17<0,L17*-1,0) -> 0 | AC17: =AA17+AB17 -> 81.8 | AD17: 0 | AE17: 38 | AF17: 1 | AG17: =AG16+(U17*1.9835) -> 6367.7825 | AH17: 0
A18: =A17+1 -> 7 | B18: 6863.67 | C18: 171696 | D18: =C18-C17 -> -48 | E18: =C18-152000 -> 19696 | F18: =D18/$D$2 -> -24.199647 | G18: 31 | H18: 0 | I18: =G18+H18 -> 31 | J18: =IF(L18>0,L18,0) -> 15.900353 | K18: =I18+J18 -> 46.900353 | L18: =F18-(I18-AA18) -> 15.900353 | M18: 4.1 | N18: 0 | O18: 0 | P18: 1.38 | Q18: 2.4 | R18: 0 | S18: 50 | T18: 0 | U18: =M18-N18-O18-P18-Q18-R18+S18+T18 -> 50.32 | X18: 0 | Y18: 17 | Z18: =Z17-Y18 -> 1945 | AA18: =N18+O18+P18+Q18+R18+U18+X18+Y18 -> 71.1 | AB18: =IF(L18<0,L18*-1,0) -> 0 | AC18: =AA18+AB18 -> 71.1 | AD18: 0 | AE18: 40 | AF18: 22 | AG18: =AG17+(U18*1.9835) -> 6467.5922 | AH18: 0
A19: =A18+1 -> 8 | B19: 6863.66 | C19: 171672 | D19: =C19-C18 -> -24 | E19: =C19-152000 -> 19672 | F19: =D19/$D$2 -> -12.099824 | G19: 34 | H19: 0 | I19: =G19+H19 -> 34 | J19: =IF(L19>0,L19,0) -> 17.000176 | K19: =I19+J19 -> 51.000176 | L19: =F19-(I19-AA19) -> 17.000176 | M19: 4.1 | N19: 0 | O19: 0 | P19: 1.38 | Q19: 2.4 | R19: 0 | S19: 42 | T19: 0 | U19: =M19-N19-O19-P19-Q19-R19+S19+T19 -> 42.32 | X19: 0 | Y19: 17 | Z19: =Z18-Y19 -> 1928 | AA19: =N19+O19+P19+Q19+R19+U19+X19+Y19 -> 63.1 | AB19: =IF(L19<0,L19*-1,0) -> 0 | AC19: =AA19+AB19 -> 63.1 | AD19: 0 | AE19: 42 | AF19: 13 | AG19: =AG18+(U19*1.9835) -> 6551.5339 | AH19: 0
A20: =A19+1 -> 9 | B20: 6863.66 | C20: 171672 | D20: =C20-C19 -> 0 | E20: =C20-152000 -> 19672 | F20: =D20/$D$2 -> 0 | G20: 35 | H20: 0 | I20: =G20+H20 -> 35 | J20: =IF(L20>0,L20,0) -> 31.9 | K20: =I20+J20 -> 66.9 | L20: =F20-(I20-AA20) -> 31.9 | M20: 3.9 | N20: 0 | O20: 0 | P20: 1.38 | Q20: 2.4 | R20: 0 | S20: 45 | T20: 0 | U20: =M20-N20-O20-P20-Q20-R20+S20+T20 -> 45.12 | X20: 0 | Y20: 18 | Z20: =Z19-Y20 -> 1910 | AA20: =N20+O20+P20+Q20+R20+U20+X20+Y20 -> 66.9 | AB20: =IF(L20<0,L20*-1,0) -> 0 | AC20: =AA20+AB20 -> 66.9 | AD20: 0 | AE20: 50 | AF20: 14 | AG20: =AG19+(U20*1.9835) -> 6641.0295 | AH20: 0
A21: =A20+1 -> 10 | B21: 6863.65 | C21: 171647 | D21: =C21-C20 -> -25 | E21: =C21-152000 -> 19647 | F21: =D21/$D$2 -> -12.603983 | G21: 36 | H21: 0 | I21: =G21+H21 -> 36 | J21: =IF(L21>0,L21,0) -> 17.096017 | K21: =I21+J21 -> 53.096017 | L21: =F21-(I21-AA21) -> 17.096017 | M21: 3.7 | N21: 0 | O21: 0 | P21: 1.38 | Q21: 2.4 | R21: 0 | S21: 45 | T21: 0 | U21: =M21-N21-O21-P21-Q21-R21+S21+T21 -> 44.92 | X21: 0 | Y21: 17 | Z21: =Z20-Y21 -> 1893 | AA21: =N21+O21+P21+Q21+R21+U21+X21+Y21 -> 65.7 | AB21: =IF(L21<0,L21*-1,0) -> 0 | AC21: =AA21+AB21 -> 65.7 | AD21: 0 | AE21: 54 | AF21: 18 | AG21: =AG20+(U21*1.9835) -> 6730.1283 | AH21: 0
A22: =A21+1 -> 11 | B22: 6863.65 | C22: 171647 | D22: =C22-C21 -> 0 | E22: =C22-152000 -> 19647 | F22: =D22/$D$2 -> 0 | G22: 37 | H22: 0 | I22: =G22+H22 -> 37 | J22: =IF(L22>0,L22,0) -> 27.9 | K22: =I22+J22 -> 64.9 | L22: =F22-(I22-AA22) -> 27.9 | M22: 3.9 | N22: 0 | O22: 0 | P22: 1.38 | Q22: 2.4 | R22: 0 | S22: 44 | T22: 0 | U22: =M22-N22-O22-P22-Q22-R22+S22+T22 -> 44.12 | X22: 0 | Y22: 17 | Z22: =Z21-Y22 -> 1876 | AA22: =N22+O22+P22+Q22+R22+U22+X22+Y22 -> 64.9 | AB22: =IF(L22<0,L22*-1,0) -> 0 | AC22: =AA22+AB22 -> 64.9 | AD22: 0 | AE22: 51 | AF22: 19 | AG22: =AG21+(U22*1.9835) -> 6817.6403 | AH22: 0
A23: =A22+1 -> 12 | B23: 6863.63 | C23: 171599 | D23: =C23-C22 -> -48 | E23: =C23-152000 -> 19599 | F23: =D23/$D$2 -> -24.199647 | G23: 37 | H23: 0 | I23: =G23+H23 -> 37 | J23: =IF(L23>0,L23,0) -> 12.700353 | K23: =I23+J23 -> 49.700353 | L23: =F23-(I23-AA23) -> 12.700353 | M23: 3.9 | N23: 0 | O23: 0 | P23: 1.38 | Q23: 2.4 | R23: 0 | S23: 53 | T23: 0 | U23: =M23-N23-O23-P23-Q23-R23+S23+T23 -> 53.12 | X23: 0 | Y23: 17 | Z23: =Z22-Y23 -> 1859 | AA23: =N23+O23+P23+Q23+R23+U23+X23+Y23 -> 73.9 | AB23: =IF(L23<0,L23*-1,0) -> 0 | AC23: =AA23+AB23 -> 73.9 | AD23: 0 | AE23: 46 | AF23: 18 | AG23: =AG22+(U23*1.9835) -> 6923.0038 | AH23: 0
A24: 13 | B24: 6863.61 | C24: 171551 | D24: =C24-C23 -> -48 | E24: =C24-152000 -> 19551 | F24: =D24/$D$2 -> -24.199647 | G24: 36 | H24: 0 | I24: =G24+H24 -> 36 | J24: =IF(L24>0,L24,0) -> 17.500353 | K24: =I24+J24 -> 53.500353 | L24: =F24-(I24-AA24) -> 17.500353 | M24: 3.7 | N24: 0 | O24: 0 | P24: 1.38 | Q24: 2.4 | R24: 0 | S24: 57 | T24: 0 | U24: =M24-N24-O24-P24-Q24-R24+S24+T24 -> 56.92 | X24: 0 | Y24: 17 | Z24: =Z23-Y24 -> 1842 | AA24: =N24+O24+P24+Q24+R24+U24+X24+Y24 -> 77.7 | AB24: =IF(L24<0,L24*-1,0) -> 0 | AC24: =AA24+AB24 -> 77.7 | AD24: 0 | AE24: 44 | AF24: 14 | AG24: =AG23+(U24*1.9835) -> 7035.9046 | AH24: 0
A25: =A24+1 -> 14 | B25: 6863.58 | C25: 171478 | D25: =C25-C24 -> -73 | E25: =C25-152000 -> 19478 | F25: =D25/$D$2 -> -36.80363 | G25: 35 | H25: 0 | I25: =G25+H25 -> 35 | J25: =IF(L25>0,L25,0) -> 2.7963701 | K25: =I25+J25 -> 37.79637 | L25: =F25-(I25-AA25) -> 2.7963701 | M25: 3.6 | N25: 0 | O25: 0 | P25: 1.38 | Q25: 2.4 | R25: 0 | S25: 54 | T25: 0 | U25: =M25-N25-O25-P25-Q25-R25+S25+T25 -> 53.82 | X25: 0 | Y25: 17 | Z25: =Z24-Y25 -> 1825 | AA25: =N25+O25+P25+Q25+R25+U25+X25+Y25 -> 74.6 | AB25: =IF(L25<0,L25*-1,0) -> 0 | AC25: =AA25+AB25 -> 74.6 | AD25: 0 | AE25: 50 | AF25: 15 | AG25: =AG24+(U25*1.9835) -> 7142.6566 | AH25: 0
A26: =A25+1 -> 15 | B26: 6863.56 | C26: 171430 | D26: =C26-C25 -> -48 | E26: =C26-152000 -> 19430 | F26: =D26/$D$2 -> -24.199647 | G26: 39 | H26: 0 | I26: =G26+H26 -> 39 | J26: =IF(L26>0,L26,0) -> 12.300353 | K26: =I26+J26 -> 51.300353 | L26: =F26-(I26-AA26) -> 12.300353 | M26: 3.5 | N26: 0 | O26: 0 | P26: 1.38 | Q26: 2.4 | R26: 0 | S26: 55 | T26: 0 | U26: =M26-N26-O26-P26-Q26-R26+S26+T26 -> 54.72 | X26: 0 | Y26: 17 | Z26: =Z25-Y26 -> 1808 | AA26: =N26+O26+P26+Q26+R26+U26+X26+Y26 -> 75.5 | AB26: =IF(L26<0,L26*-1,0) -> 0 | AC26: =AA26+AB26 -> 75.5 | AD26: 0.01 | AE26: 40 | AF26: 26 | AG26: =AG25+(U26*1.9835) -> 7251.1937 | AH26: 0
A27: =A26+1 -> 16 | B27: 6863.55 | C27: 171406 | D27: =C27-C26 -> -24 | E27: =C27-152000 -> 19406 | F27: =D27/$D$2 -> -12.099824 | G27: 39 | H27: 0 | I27: =G27+H27 -> 39 | J27: =IF(L27>0,L27,0) -> 23.600176 | K27: =I27+J27 -> 62.600176 | L27: =F27-(I27-AA27) -> 23.600176 | M27: 3.7 | N27: 0 | O27: 0 | P27: 1.38 | Q27: 2.4 | R27: 0 | S27: 54 | T27: 0 | U27: =M27-N27-O27-P27-Q27-R27+S27+T27 -> 53.92 | X27: 0 | Y27: 17 | Z27: =Z26-Y27 -> 1791 | AA27: =N27+O27+P27+Q27+R27+U27+X27+Y27 -> 74.7 | AB27: =IF(L27<0,L27*-1,0) -> 0 | AC27: =AA27+AB27 -> 74.7 | AD27: 0 | AE27: 38 | AF27: 23 | AG27: =AG26+(U27*1.9835) -> 7358.144 | AH27: 0
A28: =A27+1 -> 17 | B28: 6863.54 | C28: 171382 | D28: =C28-C27 -> -24 | E28: =C28-152000 -> 19382 | F28: =D28/$D$2 -> -12.099824 | G28: 39 | H28: 0 | I28: =G28+H28 -> 39 | J28: =IF(L28>0,L28,0) -> 23.600176 | K28: =I28+J28 -> 62.600176 | L28: =F28-(I28-AA28) -> 23.600176 | M28: 3.7 | N28: 0 | O28: 0 | P28: 1.38 | Q28: 2.4 | R28: 0 | S28: 54 | T28: 0 | U28: =M28-N28-O28-P28-Q28-R28+S28+T28 -> 53.92 | X28: 0 | Y28: 17 | Z28: =Z27-Y28 -> 1774 | AA28: =N28+O28+P28+Q28+R28+U28+X28+Y28 -> 74.7 | AB28: =IF(L28<0,L28*-1,0) -> 0 | AC28: =AA28+AB28 -> 74.7 | AD28: 1 | AE28: 43 | AF28: 19 | AG28: =AG27+(U28*1.9835) -> 7465.0944 | AH28: 0
A29: =A28+1 -> 18 | B29: 6863.52 | C29: 171333 | D29: =C29-C28 -> -49 | E29: =C29-152000 -> 19333 | F29: =D29/$D$2 -> -24.703806 | G29: 38 | H29: 0 | I29: =G29+H29 -> 38 | J29: =IF(L29>0,L29,0) -> 11.896194 | K29: =I29+J29 -> 49.896194 | L29: =F29-(I29-AA29) -> 11.896194 | M29: 3.6 | N29: 0 | O29: 0 | P29: 1.38 | Q29: 2.4 | R29: 0 | S29: 54 | T29: 0 | U29: =M29-N29-O29-P29-Q29-R29+S29+T29 -> 53.82 | X29: 0 | Y29: 17 | Z29: =Z28-Y29 -> 1757 | AA29: =N29+O29+P29+Q29+R29+U29+X29+Y29 -> 74.6 | AB29: =IF(L29<0,L29*-1,0) -> 0 | AC29: =AA29+AB29 -> 74.6 | AD29: 0 | AE29: 41 | AF29: 16 | AG29: =AG28+(U29*1.9835) -> 7571.8463 | AH29: 0
A30: =A29+1 -> 19 | B30: 6863.5 | C30: 171285 | D30: =C30-C29 -> -48 | E30: =C30-152000 -> 19285 | F30: =D30/$D$2 -> -24.199647 | G30: 37 | H30: 0 | I30: =G30+H30 -> 37 | J30: =IF(L30>0,L30,0) -> 13.500353 | K30: =I30+J30 -> 50.500353 | L30: =F30-(I30-AA30) -> 13.500353 | M30: 3.7 | N30: 0 | O30: 0 | P30: 1.38 | Q30: 2.4 | R30: 0 | S30: 54 | T30: 0 | U30: =M30-N30-O30-P30-Q30-R30+S30+T30 -> 53.92 | X30: 0 | Y30: 17 | Z30: =Z29-Y30 -> 1740 | AA30: =N30+O30+P30+Q30+R30+U30+X30+Y30 -> 74.7 | AB30: =IF(L30<0,L30*-1,0) -> 0 | AC30: =AA30+AB30 -> 74.7 | AD30: 0.01 | AE30: 39 | AF30: 15 | AG30: =AG29+(U30*1.9835) -> 7678.7967 | AH30: 0
A31: =A30+1 -> 20 | B31: 6863.48 | C31: 171237 | D31: =C31-C30 -> -48 | E31: =C31-152000 -> 19237 | F31: =D31/$D$2 -> -24.199647 | G31: 39 | H31: 0 | I31: =G31+H31 -> 39 | J31: =IF(L31>0,L31,0) -> 11.500353 | K31: =I31+J31 -> 50.500353 | L31: =F31-(I31-AA31) -> 11.500353 | M31: 3.7 | N31: 0 | O31: 0 | P31: 1.38 | Q31: 2.4 | R31: 0 | S31: 54 | T31: 0 | U31: =M31-N31-O31-P31-Q31-R31+S31+T31 -> 53.92 | X31: 0 | Y31: 17 | Z31: =Z30-Y31 -> 1723 | AA31: =N31+O31+P31+Q31+R31+U31+X31+Y31 -> 74.7 | AB31: =IF(L31<0,L31*-1,0) -> 0 | AC31: =AA31+AB31 -> 74.7 | AD31: 0.05 | AE31: 40 | AF31: 16 | AG31: =AG30+(U31*1.9835) -> 7785.747 | AH31: 0
A32: =A31+1 -> 21 | B32: 6863.47 | C32: 171212 | D32: =C32-C31 -> -25 | E32: =C32-152000 -> 19212 | F32: =D32/$D$2 -> -12.603983 | G32: 39 | H32: 0 | I32: =G32+H32 -> 39 | J32: =IF(L32>0,L32,0) -> 22.996017 | K32: =I32+J32 -> 61.996017 | L32: =F32-(I32-AA32) -> 22.996017 | M32: 3.6 | N32: 0 | O32: 0 | P32: 1.38 | Q32: 2.4 | R32: 0 | S32: 54 | T32: 0 | U32: =M32-N32-O32-P32-Q32-R32+S32+T32 -> 53.82 | X32: 0 | Y32: 17 | Z32: =Z31-Y32 -> 1706 | AA32: =N32+O32+P32+Q32+R32+U32+X32+Y32 -> 74.6 | AB32: =IF(L32<0,L32*-1,0) -> 0 | AC32: =AA32+AB32 -> 74.6 | AD32: 0 | AE32: 39 | AF32: 13 | AG32: =AG31+(U32*1.9835) -> 7892.4989 | AH32: 0
A33: =A32+1 -> 22 | B33: 6863.46 | C33: 171188 | D33: =C33-C32 -> -24 | E33: =C33-152000 -> 19188 | F33: =D33/$D$2 -> -12.099824 | G33: 37 | H33: 0 | I33: =G33+H33 -> 37 | J33: =IF(L33>0,L33,0) -> 25.400176 | K33: =I33+J33 -> 62.400176 | L33: =F33-(I33-AA33) -> 25.400176 | M33: 3.5 | N33: 0 | O33: 0 | P33: 1.38 | Q33: 2.4 | R33: 0 | S33: 54 | T33: 0 | U33: =M33-N33-O33-P33-Q33-R33+S33+T33 -> 53.72 | X33: 0 | Y33: 17 | Z33: =Z32-Y33 -> 1689 | AA33: =N33+O33+P33+Q33+R33+U33+X33+Y33 -> 74.5 | AB33: =IF(L33<0,L33*-1,0) -> 0 | AC33: =AA33+AB33 -> 74.5 | AD33: 0 | AE33: 40 | AF33: 8 | AG33: =AG32+(U33*1.9835) -> 7999.0526 | AH33: 0
A34: =A33+1 -> 23 | B34: 6863.45 | C34: 171164 | D34: =C34-C33 -> -24 | E34: =C34-152000 -> 19164 | F34: =D34/$D$2 -> -12.099824 | G34: 35 | H34: 0 | I34: =G34+H34 -> 35 | J34: =IF(L34>0,L34,0) -> 27.600176 | K34: =I34+J34 -> 62.600176 | L34: =F34-(I34-AA34) -> 27.600176 | M34: 3.7 | N34: 0 | O34: 0 | P34: 1.38 | Q34: 2.4 | R34: 0 | S34: 54 | T34: 0 | U34: =M34-N34-O34-P34-Q34-R34+S34+T34 -> 53.92 | X34: 0 | Y34: 17 | Z34: =Z33-Y34 -> 1672 | AA34: =N34+O34+P34+Q34+R34+U34+X34+Y34 -> 74.7 | AB34: =IF(L34<0,L34*-1,0) -> 0 | AC34: =AA34+AB34 -> 74.7 | AD34: 0 | AE34: 44 | AF34: 11 | AG34: =AG33+(U34*1.9835) -> 8106.0029 | AH34: 0
A35: =A34+1 -> 24 | B35: 6863.43 | C35: 171116 | D35: =C35-C34 -> -48 | E35: =C35-152000 -> 19116 | F35: =D35/$D$2 -> -24.199647 | G35: 36 | H35: 0 | I35: =G35+H35 -> 36 | J35: =IF(L35>0,L35,0) -> 14.500353 | K35: =I35+J35 -> 50.500353 | L35: =F35-(I35-AA35) -> 14.500353 | M35: 3.7 | N35: 0 | O35: 0 | P35: 1.38 | Q35: 2.4 | R35: 0 | S35: 54 | T35: 0 | U35: =M35-N35-O35-P35-Q35-R35+S35+T35 -> 53.92 | X35: 0 | Y35: 17 | Z35: =Z34-Y35 -> 1655 | AA35: =N35+O35+P35+Q35+R35+U35+X35+Y35 -> 74.7 | AB35: =IF(L35<0,L35*-1,0) -> 0 | AC35: =AA35+AB35 -> 74.7 | AD35: 0 | AE35: 42 | AF35: 12 | AG35: =AG34+(U35*1.9835) -> 8212.9532 | AH35: 0
A36: =A35+1 -> 25 | B36: 6863.41 | C36: 171067 | D36: =C36-C35 -> -49 | E36: =C36-152000 -> 19067 | F36: =D36/$D$2 -> -24.703806 | G36: 39 | H36: 0 | I36: =G36+H36 -> 39 | J36: =IF(L36>0,L36,0) -> 10.996194 | K36: =I36+J36 -> 49.996194 | L36: =F36-(I36-AA36) -> 10.996194 | M36: 3.7 | N36: 0 | O36: 0 | P36: 1.38 | Q36: 2.4 | R36: 0 | S36: 54 | T36: 0 | U36: =M36-N36-O36-P36-Q36-R36+S36+T36 -> 53.92 | X36: 0 | Y36: 17 | Z36: =Z35-Y36 -> 1638 | AA36: =N36+O36+P36+Q36+R36+U36+X36+Y36 -> 74.7 | AB36: =IF(L36<0,L36*-1,0) -> 0 | AC36: =AA36+AB36 -> 74.7 | AD36: 0.02 | AE36: 33 | AF36: 10 | AG36: =AG35+(U36*1.9835) -> 8319.9035 | AH36: 0
... A40: =A39+1 -> 29 | B40: 6863.32 | C40: 170850 | D40: =C40-C39 -> -48 | E40: =C40-152000 -> 18850 | F40: =D40/$D$2 -> -24.199647 | G40: 43 | H40: 0 | I40: =G40+H40 -> 43 | J40: =IF(L40>0,L40,0) -> 7.1003529 | K40: =I40+J40 -> 50.100353 | L40: =F40-(I40-AA40) -> 7.1003529 | M40: 4.3 | N40: 0 | O40: 0 | P40: 2.08 | Q40: 2.4 | R40: 0 | S40: 47 | T40: 0 | U40: =M40-N40-O40-P40-Q40-R40+S40+T40 -> 46.82 | X40: 0 | Y40: 23 | Z40: =Z39-Y40 -> 1561 | AA40: =N40+O40+P40+Q40+R40+U40+X40+Y40 -> 74.3 | AB40: =IF(L40<0,L40*-1,0) -> 0 | AC40: =AA40+AB40 -> 74.3 | AD40: 0 | AE40: 43 | AF40: 12 | AG40: =AG39+(U40*1.9835) -> 8726.8781 | AH40: 0
A41: 30 | B41: 6863.31 | C41: 170826 | D41: =C41-C40 -> -24 | E41: =C41-152000 -> 18826 | F41: =D41/$D$2 -> -12.099824 | G41: 43 | H41: 0 | I41: =G41+H41 -> 43 | J41: =IF(L41>0,L41,0) -> 20.000176 | K41: =I41+J41 -> 63.000176 | L41: =F41-(I41-AA41) -> 20.000176 | M41: 4.1 | N41: 0 | O41: 0 | P41: 1.78 | Q41: 2.4 | R41: 0 | S41: 48 | T41: 0 | U41: =M41-N41-O41-P41-Q41-R41+S41+T41 -> 47.92 | X41: 0 | Y41: 23 | Z41: =Z40-Y41 -> 1538 | AA41: =N41+O41+P41+Q41+R41+U41+X41+Y41 -> 75.1 | AB41: =IF(L41<0,L41*-1,0) -> 0 | AC41: =AA41+AB41 -> 75.1 | AD41: 0 | AE41: 45 | AF41: 13 | AG41: =AG40+(U41*1.9835) -> 8821.9274 | AH41: 0
A42: 31 | B42: 6863.3 | C42: 170801 | D42: =C42-C41 -> -25 | E42: =C42-152000 -> 18801 | F42: =D42/$D$2 -> -12.603983 | G42: 43 | H42: 0 | I42: =G42+H42 -> 43 | J42: =IF(L42>0,L42,0) -> 19.496017 | K42: =I42+J42 -> 62.496017 | L42: =F42-(I42-AA42) -> 19.496017 | M42: 4.1 | N42: 0 | O42: 0 | P42: 1.78 | Q42: 2.4 | R42: 0 | S42: 48 | T42: 0 | U42: =M42-N42-O42-P42-Q42-R42+S42+T42 -> 47.92 | X42: 0 | Y42: 23 | Z42: =Z41-Y42 -> 1515 | AA42: =N42+O42+P42+Q42+R42+U42+X42+Y42 -> 75.1 | AB42: =IF(L42<0,L42*-1,0) -> 0 | AC42: =AA42+AB42 -> 75.1 | AD42: 0.28 | AE42: 33 | AF42: 21 | AG42: =AG41+(U42*1.9835) -> 8916.9767 | AH42: 0
A44: MONTH / CFS | F44: =SUM(F12:F42) -> -487.52206 | G44: =SUM(G12:G42) -> 1128 | H44: =SUM(H12:H42) -> 0 | I44: =SUM(I12:I42) -> 1128 | J44: =SUM(J12:J42) -> 691.57724 | K44: =SUM(K12:K42) -> 1819.5772 | L44: =SUM(L12:L42) -> 677.87794 | M44: =SUM(M12:M42) -> 118.4 | ... U44: =SUM(U12:U42) -> 1618.12 | Y44: =SUM(Y12:Y42) -> 555 | AA44: =SUM(AA12:AA42) -> 2293.4 | AB44: =SUM(AB12:AB42) -> 13.699294 | AC44: =SUM(AC12:AC42) -> 2307.0993 | AD44: =SUM(AD12:AD42) -> 2.67 | AE44: =AVERAGE(AE12:AE42) -> 40.096774 | AF44: =AVERAGE(AF12:AF42) -> 13.419355 | AG44: AVE | AH44: =SUM(AH12:AH42) -> 0
A45: MONTH / AF | D45: =SUM(D12:D42) -> -967 | F45: =F44*$D$2 -> -967 | G45: =G44*$D$2 -> 2237.388 | H45: =H44*$D$2 -> 0 | I45: =I44*$D$2 -> 2237.388 | J45: =J44*$D$2 -> 1371.7434 | K45: =K44*$D$2 -> 3609.1314 | L45: =L44*$D$2 -> 1344.5709 | M45: =M44*$D$2 -> 234.8464 | ... U45: =U44*$D$2 -> 3209.541 | Y45: =Y44*$D$2 -> 1100.8425 | AA45: =AA44*$D$2 -> 4548.9589 | AB45: =AB44*$D$2 -> 27.17255 | AC45: =AC44*$D$2 -> 4576.1314 | AE45: =MAX(AE12:AE42) -> 54 | AF45: =MAX(AF12:AF42) -> 30 | AG45: HI | AH45: =AH44*$D$2 -> 0
A47: SEASON / CFS | AE47: =MIN(AE12:AE42) -> 25 | AF47: =MIN(AF12:AF42) -> -5 | AG47: LO
...

Sheet FEB
K1: MCPHEE RESERVOIR INFLOW/OUTFLOW TABULATION
A2: AF/cfs CONVERT FACTOR | D2: 1.9835 | K2: FEBRUARY "2004"
D4: RESERVOIR | S4: INFLOW/OUTFLOW (CFS) | AE4: WEATHER | AI4: ADJUSTMENTS
A5: DATE | B5: RESERV | C5: RESERV | D5: AC FT | E5: ACTIVE | F5: CONV TO | G5: DOLORES | H5: LOST | I5: RECORD | J5: CALC | K5: TOTAL | L5: CALC | M5: DOLORES TUNNEL | S5: LONE | T5: U | U5: TOTAL | V5: MVI | W5: MVI | X5: DV CR | Y5: BELOW | Z5: FISH | AA5: RECORD | AB5: CALC | AC5: TOTAL | AD5: RAIN | AE5: MAX | AF5: MIN | AG5: NAR | AH5: MVI | AI5: MVI | AJ5: MVI | AK5: U/S
A6: FEB | B6: ELEV | C6: AC FT | D6: CHANGE | E6: CAP | F6: CFS | G6: RIVER | H6: CAN | I6: INFLOW | J6: INFLOW | K6: INFLOW | L6: INF/OTF | M6: TOT DIV | N6: WET | O6: UTE | P6: MWC | Q6: CTZ | R6: CTZ & | S6: PINE | T6: LAT | U6: MVI | V6: CALL + | W6: PROJ | X6: CANAL | Y6: MCP | Z6: LEFT | AA6: OTF | AB6: OTF | AC6: OTF | AE6: TMP | AF6: TMP | AG6: CALL | AH6: STOCK | AI6: STORED | AJ6: STORED | AK6: USERS
E7: AC FT | N7: LAND | O7: F&R | R7: UTE | V7: TO EX | AI7: Apr-Jun | AJ7: EVAP | AK7: EXCH
R8: PROJ | AJ8: AC.FT
A9: SEASON BAL
