Workbook

Sheet NOV
K1: MC PHEE RESERVOIR IN/OUT FLOW TABULATION
A2: AF/cfs CONVERT FACTOR | D2: 1.983 | L2: NOVEMBER "94"
A4: DATE | B4: RESERV | C4: RESERV | D4: AC FT | E4: ACTIVE | F4: CONV TO | G4: DOLORES | H4: LOST | I4: RECORDED | J4: CALC | K4: TOTAL | L4: CALC | M4: DOLORES TUNNEL | P4: MVI | Q4: U | R4: TOTAL | S4: MVI | T4: DV CR | U4: BELOW | V4: REMAIN | W4: RECORDED | X4: CALC | Y4: TOTAL | Z4: RAIN | AA4: MAX | AB4: MIN | AC4: DATE
A5: "NOV" | B5: ELEV | C5: AC FT | D5: CHANGE | E5: CAP | F5: CFS | G5: RIVER | H5: CANYON | I5: INFLOW | J5: INFLOW | K5: INFLOW | L5: INF/OTF | M5: TOT DIV | N5: UTE F&R | O5: MVI,CTZ,MWC | P5: DIVER | Q5: LATERAL | R5: MVI | S5: CALL | T5: CANAL | U5: MC PHEE | V5: RELEASE | W5: OUTFLOW | X5: OUTFLOW | Y5: OUTFLOW | AA5: TMP | AB5: TMP | AC5: "NOV"
A7: SEASON BAL
A8: YTD | B8: 6895.3 | C8: 266563 | V8: =(25400+3900+285)/1.9835 -> 14915.553 | AD8: 13149 | AE8: 17902
A10: 1 | B10: 6895.14 | C10: 265995 | D10: =C10-C8 -> -568 | E10: =C10-152000 -> 113995 | F10: =D10/$D$2 -> -286.43469 | G10: 51.29 | H10: 0 | I10: =G10+H10 -> 51.29 | J10: =IF(L10>0,L10,0) -> 0 | K10: =I10+J10 -> 51.29 | L10: =F10-(I10-W10) -> -22.864695 | M10: 22.48 | N10: 11 | O10: =M10-N10 -> 11.48 | P10: 252.19 | R10: =SUM(O10:Q10) -> 263.67 | U10: 40.19 | V10: =V8-U10 -> 14875.363 | W10: =N10+R10+T10+U10 -> 314.86 | X10: =IF(L10<0,L10*-1,0) -> 22.864695 | Y10: =W10+X10 -> 337.72469 | Z10: 0 | AA10: 56 | AB10: 19 | AC10: 1 | AD10: 13243 | AF10: 7883
A11: =A10+1 -> 2 | B11: 6895 | C11: 265496 | D11: =C11-C10 -> -499 | E11: =C11-152000 -> 113496 | F11: =D11/$D$2 -> -251.63893 | G11: 53.62 | H11: 0 | I11: =G11+H11 -> 53.62 | J11: =IF(L11>0,L11,0) -> 9.4010691 | K11: =I11+J11 -> 63.021069 | L11: =F11-(I11-W11) -> 9.4010691 | M11: 22.47 | N11: 11 | O11: =M11-N11 -> 11.47 | P11: 252.62 | R11: =SUM(O11:Q11) -> 264.09 | U11: 39.57 | V11: =V10-U11 -> 14835.793 | W11: =N11+R11+T11+U11 -> 314.66 | X11: =IF(L11<0,L11*-1,0) -> 0 | Y11: =W11+X11 -> 314.66 | Z11: 0.08 | AA11: 50 | AB11: 24 | AC11: =AC10+1 -> 2 | AD11: 13333 | AE11: 62
A12: =A11+1 -> 3 | B12: 6895.02 | C12: 265567 | D12: =C12-C11 -> 71 | E12: =C12-152000 -> 113567 | F12: =D12/$D$2 -> 35.804337 | G12: 61.66 | H12: 0 | I12: =G12+H12 -> 61.66 | J12: =IF(L12>0,L12,0) -> 206.64434 | K12: =I12+J12 -> 268.30434 | L12: =F12-(I12-W12) -> 206.64434 | M12: 16.97 | N12: 10 | O12: =M12-N12 -> 6.97 | P12: 175.55 | R12: =SUM(O12:Q12) -> 182.52 | U12: 39.98 | V12: =V11-U12 -> 14795.813 | W12: =N12+R12+T12+U12 -> 232.5 | X12: =IF(L12<0,L12*-1,0) -> 0 | Y12: =W12+X12 -> 232.5 | Z12: 0 | AA12: 48 | AB12: 22 | AC12: =AC11+1 -> 3 | AD12: 13456 | AE12: 159
A13: =A12+1 -> 4 | B13: 6895.03 | C13: 265602 | D13: =C13-C12 -> 35 | E13: =C13-152000 -> 113602 | F13: =D13/$D$2 -> 17.650025 | G13: 57.02 | H13: 0 | I13: =G13+H13 -> 57.02 | J13: =IF(L13>0,L13,0) -> 7.1200252 | K13: =I13+J13 -> 64.140025 | L13: =F13-(I13-W13) -> 7.1200252 | M13: 6.89 | N13: 10 | O13: =M13-N13 -> -3.11 | R13: =SUM(O13:Q13) -> -3.11 | U13: 39.6 | V13: =V12-U13 -> 14756.213 | W13: =N13+R13+T13+U13 -> 46.49 | X13: =IF(L13<0,L13*-1,0) -> 0 | Y13: =W13+X13 -> 46.49 | Z13: 0.21 | AA13: 50 | AB13: 20 | AC13: =AC12+1 -> 4 | AD13: 13563 | AE13: 263
A14: =A13+1 -> 5 | B14: 6895.04 | C14: 265639 | D14: =C14-C13 -> 37 | E14: =C14-152000 -> 113639 | F14: =D14/$D$2 -> 18.658598 | G14: 48.21 | H14: 0 | I14: =G14+H14 -> 48.21 | J14: =IF(L14>0,L14,0) -> 16.258598 | K14: =I14+J14 -> 64.468598 | L14: =F14-(I14-W14) -> 16.258598 | M14: 6.21 | N14: 10 | O14: =M14-N14 -> -3.79 | R14: =SUM(O14:Q14) -> -3.79 | U14: 39.6 | V14: =V13-U14 -> 14716.613 | W14: =N14+R14+T14+U14 -> 45.81 | X14: =IF(L14<0,L14*-1,0) -> 0 | Y14: =W14+X14 -> 45.81 | Z14: 0 | AA14: 40 | AB14: 10 | AC14: =AC13+1 -> 5 | AD14: 13678 | AE14: 367
A15: =A14+1 -> 6 | B15: 6895.05 | C15: 265673 | D15: =C15-C14 -> 34 | E15: =C15-152000 -> 113673 | F15: =D15/$D$2 -> 17.145739 | G15: 60.63 | H15: 0 | I15: =G15+H15 -> 60.63 | J15: =IF(L15>0,L15,0) -> 2.4057388 | K15: =I15+J15 -> 63.035739 | L15: =F15-(I15-W15) -> 2.4057388 | M15: 6.29 | N15: 10 | O15: =M15-N15 -> -3.71 | R15: =SUM(O15:Q15) -> -3.71 | U15: 39.6 | V15: =V14-U15 -> 14677.013 | W15: =N15+R15+T15+U15 -> 45.89 | X15: =IF(L15<0,L15*-1,0) -> 0 | Y15: =W15+X15 -> 45.89 | Z15: 0 | AA15: 46 | AB15: 9 | AC15: =AC14+1 -> 6 | AD15: 13812 | AE15: 469
A16: =A15+1 -> 7 | B16: 6895.07 | C16: 265745 | D16: =C16-C15 -> 72 | E16: =C16-152000 -> 113745 | F16: =D16/$D$2 -> 36.308623 | G16: 60.25 | H16: 0 | I16: =G16+H16 -> 60.25 | J16: =IF(L16>0,L16,0) -> 22.068623 | K16: =I16+J16 -> 82.318623 | L16: =F16-(I16-W16) -> 22.068623 | M16: 6.44 | N16: 19 | O16: =M16-N16 -> -12.56 | R16: =SUM(O16:Q16) -> -12.56 | U16: 39.57 | V16: =V15-U16 -> 14637.443 | W16: =N16+R16+T16+U16 -> 46.01 | X16: =IF(L16<0,L16*-1,0) -> 0 | Y16: =W16+X16 -> 46.01 | Z16: 0 | AA16: 47 | AB16: 15 | AC16: =AC15+1 -> 7 | AD16: 13968 | AE16: 587
A17: =A16+1 -> 8 | B17: 6895.08 | C17: 265781 | D17: =C17-C16 -> 36 | E17: =C17-152000 -> 113781 | F17: =D17/$D$2 -> 18.154312 | G17: 73 | H17: 0 | I17: =G17+H17 -> 73 | J17: =IF(L17>0,L17,0) -> 0 | K17: =I17+J17 -> 73 | L17: =F17-(I17-W17) -> -9.6056884 | M17: 5.56 | N17: 11 | O17: =M17-N17 -> -5.44 | R17: =SUM(O17:Q17) -> -5.44 | U17: 39.68 | V17: =V16-U17 -> 14597.763 | W17: =N17+R17+T17+U17 -> 45.24 | X17: =IF(L17<0,L17*-1,0) -> 9.6056884 | Y17: =W17+X17 -> 54.845688 | Z17: 0 | AA17: 50 | AB17: 16 | AC17: =AC16+1 -> 8 | AD17: 14117 | AE17: 707
A18: =A17+1 -> 9 | B18: 6895.1 | C18: 265852 | D18: =C18-C17 -> 71 | E18: =C18-152000 -> 113852 | F18: =D18/$D$2 -> 35.804337 | G18: 70.58 | H18: 0 | I18: =G18+H18 -> 70.58 | J18: =IF(L18>0,L18,0) -> 10.174337 | K18: =I18+J18 -> 80.754337 | L18: =F18-(I18-W18) -> 10.174337 | M18: 5.38 | N18: 6 | O18: =M18-N18 -> -0.62 | R18: =SUM(O18:Q18) -> -0.62 | U18: 39.57 | V18: =V17-U18 -> 14558.193 | W18: =N18+R18+T18+U18 -> 44.95 | X18: =IF(L18<0,L18*-1,0) -> 0 | Y18: =W18+X18 -> 44.95 | Z18: 0 | AA18: 52 | AB18: 20 | AC18: =AC17+1 -> 9 | AD18: 14264 | AE18: 826
A19: =A18+1 -> 10 | B19: 6895.12 | C19: 265924 | D19: =C19-C18 -> 72 | E19: =C19-152000 -> 113924 | F19: =D19/$D$2 -> 36.308623 | G19: 60.61 | H19: 0 | I19: =G19+H19 -> 60.61 | J19: =IF(L19>0,L19,0) -> 20.898623 | K19: =I19+J19 -> 81.508623 | L19: =F19-(I19-W19) -> 20.898623 | M19: 5.6 | N19: 6 | O19: =M19-N19 -> -0.4 | R19: =SUM(O19:Q19) -> -0.4 | U19: 39.6 | V19: =V18-U19 -> 14518.593 | W19: =N19+R19+T19+U19 -> 45.2 | X19: =IF(L19<0,L19*-1,0) -> 0 | Y19: =W19+X19 -> 45.2 | Z19: 0 | AA19: 54 | AB19: 21 | AC19: =AC18+1 -> 10 | AD19: 14413 | AE19: 964
A20: =A19+1 -> 11 | B20: 6895.17 | C20: 266101 | D20: =C20-C19 -> 177 | E20: =C20-152000 -> 114101 | F20: =D20/$D$2 -> 89.258699 | G20: 62.74 | H20: 0 | I20: =G20+H20 -> 62.74 | J20: =IF(L20>0,L20,0) -> 72.008699 | K20: =I20+J20 -> 134.7487 | L20: =F20-(I20-W20) -> 72.008699 | M20: 5.89 | N20: 14 | O20: =M20-N20 -> -8.11 | R20: =SUM(O20:Q20) -> -8.11 | U20: 39.6 | V20: =V19-U20 -> 14478.993 | W20: =N20+R20+T20+U20 -> 45.49 | X20: =IF(L20<0,L20*-1,0) -> 0 | Y20: =W20+X20 -> 45.49 | Z20: 0 | AA20: 40 | AB20: 26 | AC20: =AC19+1 -> 11 | AD20: 14571 | AE20: 1065
A21: =A20+1 -> 12 | B21: 6895.25 | C21: 266386 | D21: =C21-C20 -> 285 | E21: =C21-152000 -> 114386 | F21: =D21/$D$2 -> 143.72163 | G21: 89.9 | H21: 0 | I21: =G21+H21 -> 89.9 | J21: =IF(L21>0,L21,0) -> 99.901634 | K21: =I21+J21 -> 189.80163 | L21: =F21-(I21-W21) -> 99.901634 | M21: 5.89 | N21: 5.5 | O21: =M21-N21 -> 0.39 | R21: =SUM(O21:Q21) -> 0.39 | U21: 40.19 | V21: =V20-U21 -> 14438.803 | W21: =N21+R21+T21+U21 -> 46.08 | X21: =IF(L21<0,L21*-1,0) -> 0 | Y21: =W21+X21 -> 46.08 | Z21: 0.83 | AA21: 40 | AB21: 23 | AC21: =AC20+1 -> 12 | AD21: 14696 | AE21: 1185
A22: =A21+1 -> 13 | B22: 6895.32 | C22: 266634 | D22: =C22-C21 -> 248 | E22: =C22-152000 -> 114634 | F22: =D22/$D$2 -> 125.06304 | G22: 95.72 | H22: 0 | I22: =G22+H22 -> 95.72 | J22: =IF(L22>0,L22,0) -> 74.253036 | K22: =I22+J22 -> 169.97304 | L22: =F22-(I22-W22) -> 74.253036 | M22: 5.31 | N22: 0.5 | O22: =M22-N22 -> 4.81 | R22: =SUM(O22:Q22) -> 4.81 | U22: 39.6 | V22: =V21-U22 -> 14399.203 | W22: =N22+R22+T22+U22 -> 44.91 | X22: =IF(L22<0,L22*-1,0) -> 0 | Y22: =W22+X22 -> 44.91 | Z22: 0.21 | AA22: 35 | AB22: 17 | AC22: =AC21+1 -> 13 | AD22: 14771 | AE22: 1299
A23: =A22+1 -> 14 | B23: 6895.29 | C23: 266528 | D23: =C23-C22 -> -106 | E23: =C23-152000 -> 114528 | F23: =D23/$D$2 -> -53.454362 | G23: 76.14 | H23: 0 | I23: =G23+H23 -> 76.14 | J23: =IF(L23>0,L23,0) -> 0 | K23: =I23+J23 -> 76.14 | L23: =F23-(I23-W23) -> -86.914362 | M23: 3.08 | O23: =M23-N23 -> 3.08 | R23: =SUM(O23:Q23) -> 3.08 | U23: 39.6 | V23: =V22-U23 -> 14359.603 | W23: =N23+R23+T23+U23 -> 42.68 | X23: =IF(L23<0,L23*-1,0) -> 86.914362 | Y23: =W23+X23 -> 129.59436 | Z23: 0 | AA23: 49 | AB23: 23 | AC23: =AC22+1 -> 14 | AD23: 14842 | AE23: 1407
A24: =A23+1 -> 15 | B24: 6895.29 | C24: 266528 | D24: =C24-C23 -> 0 | E24: =C24-152000 -> 114528 | F24: =D24/$D$2 -> 0 | G24: 59.43 | H24: FROZE | I24: =G24 -> 59.43 | J24: =IF(L24>0,L24,0) -> 0 | K24: =I24+J24 -> 59.43 | L24: =F24-(I24-W24) -> -15.9 | M24: 3.93 | O24: =M24-N24 -> 3.93 | R24: =SUM(O24:Q24) -> 3.93 | U24: 39.6 | V24: =V23-U24 -> 14320.003 | W24: =N24+R24+T24+U24 -> 43.53 | X24: =IF(L24<0,L24*-1,0) -> 15.9 | Y24: =W24+X24 -> 59.43 | Z24: 0 | AA24: 46 | AB24: 20 | AC24: =AC23+1 -> 15 | AD24: 14927 | AE24: 1516
A25: =A24+1 -> 16 | B25: 6895.31 | C25: 266600 | D25: =C25-C24 -> 72 | E25: =C25-152000 -> 114600 | F25: =D25/$D$2 -> 36.308623 | G25: 81.2 | H25: 0 | I25: =G25+H25 -> 81.2 | J25: =IF(L25>0,L25,0) -> 0 | K25: =I25+J25 -> 81.2 | L25: =F25-(I25-W25) -> -0.011376702 | M25: 5.31 | O25: =M25-N25 -> 5.31 | R25: =SUM(O25:Q25) -> 5.31 | U25: 39.57 | V25: =V24-U25 -> 14280.433 | W25: =N25+R25+T25+U25 -> 44.88 | X25: =IF(L25<0,L25*-1,0) -> 0.011376702 | Y25: =W25+X25 -> 44.891377 | Z25: 0.03 | AA25: 44 | AB25: 18 | AC25: =AC24+1 -> 16 | AD25: 15009 | AE25: 1615
A26: =A25+1 -> 17 | B26: 6895.31 | C26: 266600 | D26: =C26-C25 -> 0 | E26: =C26-152000 -> 114600 | F26: =D26/$D$2 -> 0 | G26: 45.6 | H26: 0 | I26: =G26+H26 -> 45.6 | J26: =IF(L26>0,L26,0) -> 0 | K26: =I26+J26 -> 45.6 | L26: =F26-(I26-W26) -> -0.04 | M26: 5.96 | O26: =M26-N26 -> 5.96 | R26: =SUM(O26:Q26) -> 5.96 | U26: 39.6 | V26: =V25-U26 -> 14240.833 | W26: =N26+R26+T26+U26 -> 45.56 | X26: =IF(L26<0,L26*-1,0) -> 0.04 | Y26: =W26+X26 -> 45.6 | Z26: 0 | AA26: 48 | AB26: 20 | AC26: =AC25+1 -> 17 | AD26: 15112 | AE26: 1714
A27: =A26+1 -> 18 | B27: 6895.34 | C27: 266706 | D27: =C27-C26 -> 106 | E27: =C27-152000 -> 114706 | F27: =D27/$D$2 -> 53.454362 | G27: 98.9 | H27: 0 | I27: =G27+H27 -> 98.9 | J27: =IF(L27>0,L27,0) -> 0.044362078 | K27: =I27+J27 -> 98.944362 | L27: =F27-(I27-W27) -> 0.044362078 | M27: 5.89 | O27: =M27-N27 -> 5.89 | R27: =SUM(O27:Q27) -> 5.89 | U27: 39.6 | V27: =V26-U27 -> 14201.233 | W27: =N27+R27+T27+U27 -> 45.49 | X27: =IF(L27<0,L27*-1,0) -> 0 | Y27: =W27+X27 -> 45.49 | Z27: 0 | AA27: 50 | AB27: 21 | AC27: =AC26+1 -> 18 | AD27: 15213 | AE27: 1812
A28: =A27+1 -> 19 | B28: 6895.35 | C28: 266742 | D28: =C28-C27 -> 36 | E28: =C28-152000 -> 114742 | F28: =D28/$D$2 -> 18.154312 | G28: 63.6 | H28: 0 | I28: =G28+H28 -> 63.6 | J28: =IF(L28>0,L28,0) -> 0.044311649 | K28: =I28+J28 -> 63.644312 | L28: =F28-(I28-W28) -> 0.044311649 | M28: 5.89 | O28: =M28-N28 -> 5.89 | R28: =SUM(O28:Q28) -> 5.89 | U28: 39.6 | V28: =V27-U28 -> 14161.633 | W28: =N28+R28+T28+U28 -> 45.49 | X28: =IF(L28<0,L28*-1,0) -> 0 | Y28: =W28+X28 -> 45.49 | Z28: 0.37 | AA28: 48 | AB28: 18 | AC28: =AC27+1 -> 19 | AD28: 15295 | AE28: 1909
A29: =A28+1 -> 20 | B29: 6895.39 | C29: 266885 | D29: =C29-C28 -> 143 | E29: =C29-152000 -> 114885 | F29: =D29/$D$2 -> 72.11296 | G29: 117.6 | H29: 0 | I29: =G29+H29 -> 117.6 | J29: =IF(L29>0,L29,0) -> 0.0029601614 | K29: =I29+J29 -> 117.60296 | L29: =F29-(I29-W29) -> 0.0029601614 | M29: 5.89 | O29: =M29-N29 -> 5.89 | R29: =SUM(O29:Q29) -> 5.89 | U29: 39.6 | V29: =V28-U29 -> 14122.033 | W29: =N29+R29+T29+U29 -> 45.49 | X29: =IF(L29<0,L29*-1,0) -> 0 | Y29: =W29+X29 -> 45.49 | Z29: 0.03 | AA29: 50 | AB29: 16 | AC29: =AC28+1 -> 20 | AD29: 15367 | AE29: 2006
A30: =A29+1 -> 21 | B30: 6895.4 | C30: 266919 | D30: =C30-C29 -> 34 | E30: =C30-152000 -> 114919 | F30: =D30/$D$2 -> 17.145739 | G30: 62.2 | H30: 0 | I30: =G30+H30 -> 62.2 | J30: =IF(L30>0,L30,0) -> 0 | K30: =I30+J30 -> 62.2 | L30: =F30-(I30-W30) -> -0.03426122 | M30: 5.42 | O30: =M30-N30 -> 5.42 | R30: =SUM(O30:Q30) -> 5.42 | U30: 39.6 | V30: =V29-U30 -> 14082.433 | W30: =N30+R30+T30+U30 -> 45.02 | X30: =IF(L30<0,L30*-1,0) -> 0.03426122 | Y30: =W30+X30 -> 45.054261 | Z30: 0 | AA30: 51 | AB30: 16 | AC30: =AC29+1 -> 21 | AD30: 15445 | AE30: 2106 | AF30: 273.4
A31: =A30+1 -> 22 | B31: 6895.4 | C31: 266919 | D31: =C31-C30 -> 0 | E31: =C31-152000 -> 114919 | F31: =D31/$D$2 -> 0 | G31: 43.4 | H31: 0 | I31: =G31+H31 -> 43.4 | J31: =IF(L31>0,L31,0) -> 0 | K31: =I31+J31 -> 43.4 | L31: =F31-(I31-W31) -> -0.04 | M31: 3.76 | O31: =M31-N31 -> 3.76 | R31: =SUM(O31:Q31) -> 3.76 | U31: 39.6 | V31: =V30-U31 -> 14042.833 | W31: =N31+R31+T31+U31 -> 43.36 | X31: =IF(L31<0,L31*-1,0) -> 0.04 | Y31: =W31+X31 -> 43.4 | Z31: 0 | AA31: 44 | AB31: 38 | AC31: =AC30+1 -> 22 | AD31: 15524 | AE31: 2203 | AF31: 249.63
A32: =A31+1 -> 23 | B32: 6895.4 | C32: 266919 | D32: =C32-C31 -> 0 | E32: =C32-152000 -> 114919 | F32: =D32/$D$2 -> 0 | G32: 45.2 | H32: 0 | I32: 45.1 | J32: =IF(L32>0,L32,0) -> 0.05 | K32: =I32+J32 -> 45.15 | L32: =F32-(I32-W32) -> 0.05 | M32: 5.55 | O32: =M32-N32 -> 5.55 | R32: =SUM(O32:Q32) -> 5.55 | U32: 39.6 | V32: =V31-U32 -> 14003.233 | W32: =N32+R32+T32+U32 -> 45.15 | X32: =IF(L32<0,L32*-1,0) -> 0 | Y32: =W32+X32 -> 45.15 | Z32: 0 | AA32: 52 | AB32: 43 | AC32: =AC31+1 -> 23 | AD32: 15607 | AE32: 2299 | AF32: 243.94
A33: =A32+1 -> 24 | B33: 6895.4 | C33: 266919 | D33: =C33-C32 -> 0 | E33: =C33-152000 -> 114919 | F33: =D33/$D$2 -> 0 | G33: 44.3 | H33: 0 | I33: =G33+H33 -> 44.3 | J33: =IF(L33>0,L33,0) -> 0 | K33: =I33+J33 -> 44.3 | L33: =F33-(I33-W33) -> -0.03 | M33: 4.67 | O33: =M33-N33 -> 4.67 | R33: =SUM(O33:Q33) -> 4.67 | U33: 39.6 | V33: =V32-U33 -> 13963.633 | W33: =N33+R33+T33+U33 -> 44.27 | X33: =IF(L33<0,L33*-1,0) -> 0.03 | Y33: =W33+X33 -> 44.3 | Z33: 0 | AA33: 38 | AB33: 22 | AC33: =AC32+1 -> 24 | AD33: 15666 | AE33: 2395 | AF33: 243.15
A34: =A33+1 -> 25 | B34: 6895.39 | C34: 266885 | D34: =C34-C33 -> -34 | E34: =C34-152000 -> 114885 | F34: =D34/$D$2 -> -17.145739 | G34: 27.6 | H34: 0 | I34: =G34+H34 -> 27.6 | J34: =IF(L34>0,L34,0) -> 0 | K34: =I34+J34 -> 27.6 | L34: =F34-(I34-W34) -> -0.01573878 | M34: 5.13 | O34: =M34-N34 -> 5.13 | R34: =SUM(O34:Q34) -> 5.13 | U34: 39.6 | V34: =V33-U34 -> 13924.033 | W34: =N34+R34+T34+U34 -> 44.73 | X34: =IF(L34<0,L34*-1,0) -> 0.01573878 | Y34: =W34+X34 -> 44.745739 | Z34: 0 | AA34: 33 | AB34: 6 | AC34: =AC33+1 -> 25 | AD34: 15726 | AE34: 2491 | AF34: 242.11
A35: =A34+1 -> 26 | B35: 6895.39 | C35: 266885 | D35: =C35-C34 -> 0 | E35: =C35-152000 -> 114885 | F35: =D35/$D$2 -> 0 | G35: 44.5 | H35: 0 | I35: =G35+H35 -> 44.5 | J35: =IF(L35>0,L35,0) -> 0 | K35: =I35+J35 -> 44.5 | L35: =F35-(I35-W35) -> 0 | M35: 4.9 | O35: =M35-N35 -> 4.9 | R35: =SUM(O35:Q35) -> 4.9 | U35: 39.6 | V35: =V34-U35 -> 13884.433 | W35: =N35+R35+T35+U35 -> 44.5 | X35: =IF(L35<0,L35*-1,0) -> 0 | Y35: =W35+X35 -> 44.5 | Z35: 0.03 | AA35: 40 | AB35: 3 | AC35: =AC34+1 -> 26 | AD35: 15781 | AE35: 2589 | AF35: 244.72
A36: =A35+1 -> 27 | B36: 6895.4 | C36: 266919 | D36: =C36-C35 -> 34 | E36: =C36-152000 -> 114919 | F36: =D36/$D$2 -> 17.145739 | G36: 61.7 | H36: 0 | I36: =G36+H36 -> 61.7 | J36: =IF(L36>0,L36,0) -> 0 | K36: =I36+J36 -> 61.7 | L36: =F36-(I36-W36) -> -0.03426122 | M36: 4.92 | O36: =M36-N36 -> 4.92 | R36: =SUM(O36:Q36) -> 4.92 | U36: 39.6 | V36: =V35-U36 -> 13844.833 | W36: =N36+R36+T36+U36 -> 44.52 | X36: =IF(L36<0,L36*-1,0) -> 0.03426122 | Y36: =W36+X36 -> 44.554261 | Z36: 0 | AA36: 44 | AB36: 7 | AC36: =AC35+1 -> 27 | AD36: 15841 | AE36: 2686 | AF36: 252.4
A37: =A36+1 -> 28 | B37: 6895.39 | C37: 266885 | D37: =C37-C36 -> -34 | E37: =C37-152000 -> 114885 | F37: =D37/$D$2 -> -17.145739 | G37: 27 | H37: 0 | I37: =G37+H37 -> 27 | J37: =IF(L37>0,L37,0) -> 0.04426122 | K37: =I37+J37 -> 27.044261 | L37: =F37-(I37-W37) -> 0.04426122 | M37: 4.59 | O37: =M37-N37 -> 4.59 | R37: =SUM(O37:Q37) -> 4.59 | U37: 39.6 | V37: =V36-U37 -> 13805.233 | W37: =N37+R37+T37+U37 -> 44.19 | X37: =IF(L37<0,L37*-1,0) -> 0 | Y37: =W37+X37 -> 44.19 | Z37: 0 | AA37: 50 | AB37: 12 | AC37: =AC36+1 -> 28 | AD37: 804 | AE37: 2779 | AF37: 254.14
A38: =A37+1 -> 29 | B38: 6895.37 | C38: 266813 | D38: =C38-C37 -> -72 | E38: =C38-152000 -> 114813 | F38: =D38/$D$2 -> -36.308623 | G38: 7.1 | H38: 0 | I38: =G38+H38 -> 7.1 | J38: =IF(L38>0,L38,0) -> 0 | K38: =I38+J38 -> 7.1 | L38: =F38-(I38-W38) -> -0.008623298 | M38: 3.8 | O38: =M38-N38 -> 3.8 | R38: =SUM(O38:Q38) -> 3.8 | U38: 39.6 | V38: =V37-U38 -> 13765.633 | W38: =N38+R38+T38+U38 -> 43.4 | X38: =IF(L38<0,L38*-1,0) -> 0.008623298 | Y38: =W38+X38 -> 43.408623 | Z38: 0 | AA38: 52 | AB38: 17 | AC38: =AC37+1 -> 29 | AD38: 862 | AE38: 2872 | AF38: 256.51
A39: 30 | B39: 6895.37 | C39: 266813 | D39: =C39-C38 -> 0 | E39: =C39-152000 -> 114813 | F39: =D39/$D$2 -> 0 | G39: 44 | H39: 0 | I39: =G39+H39 -> 44 | J39: =IF(L39>0,L39,0) -> 0.03 | K39: =I39+J39 -> 44.03 | L39: =F39-(I39-W39) -> 0.03 | M39: 4.43 | O39: =M39-N39 -> 4.43 | R39: =SUM(O39:Q39) -> 4.43 | U39: 39.6 | V39: =V38-U39 -> 13726.033 | W39: =N39+R39+T39+U39 -> 44.03 | X39: =IF(L39<0,L39*-1,0) -> 0 | Y39: =W39+X39 -> 44.03 | Z39: 0 | AA39: 48 | AB39: 20 | AC39: 30 | AD39: 927 | AE39: 2965 | AF39: 248.45
AA40: 73
A41: MONTH / CFS | F41: =SUM(F10:F39) -> 126.07161 | G41: =SUM(G10:G39) -> 1794.7 | H41: =SUM(H10:H39) -> 0 | I41: =SUM(I10:I39) -> 1794.6 | J41: =SUM(J10:J39) -> 541.35062 | K41: =SUM(K10:K39) -> 2335.9506 | L41: =SUM(L10:L39) -> 405.85161 | M41: =SUM(M10:M39) -> 204.5 | ... R41: =SUM(R10:R39) -> 760.86 | T41: =SUM(T10:T39) -> 0 | U41: =SUM(U10:U39) -> 1189.52 | W41: =SUM(W10:W39) -> 2074.38 | X41: =SUM(X10:X39) -> 135.49901 | Y41: =SUM(Y10:Y39) -> 2209.879 | Z41: =SUM(Z10:Z39) -> 1.79 | AA41: =AVERAGE(AA10:AA39) -> 46.5 | AB41: =AVERAGE(AB10:AB39) -> 18.733333
A42: MONTH / AF | D42: =SUM(D10:D39) -> 250 | F42: =F41*$D$2 -> 250 | G42: =G41*$D$2 -> 3558.8901 | H42: =H41*$D$2 -> 0 | I42: =I41*$D$2 -> 3558.6918 | J42: =J41*$D$2 -> 1073.4983 | K42: =K41*$D$2 -> 4632.1901 | L42: =L41*$D$2 -> 804.80374 | M42: =M41*$D$2 -> 405.5235 | ... R42: =R41*$D$2 -> 1508.7854 | T42: =T41*$D$2 -> 0 | U42: =U41*$D$2 -> 2358.8182 | W42: =W41*$D$2 -> 4113.4955 | X42: =X41*$D$2 -> 268.69453 | Y42: =Y41*$D$2 -> 4382.1901 | AA42: 82 | AB42: 54 | AC42: HI
A44: SEASON / CFS | AA44: 59 | AB44: 32 | AC44: LO
...

Sheet DEC
K1: MC PHEE RESERVOIR IN/OUT FLOW TABULATION
A2: AF/cfs CONVERT FACTOR | D2: 1.983 | K2: DECEMBER "94"
A4: DATE | B4: RESERV | C4: RESERV | D4: AC FT | E4: ACTIVE | F4: CONV TO | G4: DOLORES | H4: LOST | I4: RECORDED | J4: CALC | K4: TOTAL | L4: CALC | M4: DOLORES TUNNEL | P4: LONE | Q4: U | R4: TOTAL | S4: MVI | T4: DV CR | U4: BELOW | V4: REMAIN | W4: RECORDED | X4: CALC | Y4: TOTAL | Z4: RAIN | AA4: MAX | AB4: MIN | AC4: DATE
A5: "DEC" | B5: ELEV | C5: AC FT | D5: CHANGE | E5: CAP | F5: CFS | G5: RIVER | H5: CANYON | I5: INFLOW | J5: INFLOW | K5: INFLOW | L5: INF/OTF | M5: TOT DIV | N5: UTE F&R | O5: MVI,CTZ | P5: PINE | Q5: LATERAL | R5: MVI | S5: CALL | T5: CANAL | U5: MC PHEE | V5: RELEASE | W5: OUTFLOW | X5: OUTFLOW | Y5: OUTFLOW | AA5: TMP | AB5: TMP | AC5: "DEC"
AD6: 741 | AE6: 742
A7: SEASON BAL
A8: YTD | B8: {=NOV!$B$39:$C$39} -> 6895.37 | C8: 266813 | D8: {=NOV!$D$48:$E$48} -> 250 | E8: 114813 | F8: {=NOV!$F$47:$Z$47} -> 126.07161 | G8: 1794.7 | H8: 0 | I8: 1794.6 | J8: 541.35062 | K8: 2335.9506 | L8: 405.85161 | M8: 204.5 | N8: 0 | O8: 0 | P8: 680.36 | Q8: 0 | R8: 760.86 | S8: 0 | T8: 0 | U8: 1189.52 | V8: 13726.033 | W8: 2074.38 | X8: 135.49901 | Y8: 2209.879 | Z8: 1.79 | AD8: 285 | AE8: 251 | AF8: 1207.63
A10: 1 | B10: 6895.42 | C10: 266991 | D10: =C10-C8 -> 178 | E10: =C10-152000 -> 114991 | F10: =D10/$D$2 -> 89.762985 | G10: 130.44299 | H10: 0 | I10: =G10+H10 -> 130.44299 | J10: =IF(L10>0,L10,0) -> 0 | K10: =I10+J10 -> 130.44299 | L10: =F10-(I10-W10) -> 0 | M10: 5.02 | N10: 0 | O10: =M10-N10 -> 5.02 | P10: 0 | Q10: 0 | R10: =SUM(O10:Q10) -> 5.02 | T10: 0 | U10: 35.66 | V10: =V8-U10 -> 13690.373 | W10: =R10+T10+N10+U10 -> 40.68 | X10: =IF(L10<0,L10*-1,0) -> 0 | Y10: =W10+X10 -> 40.68 | Z10: 0 | AA10: 54 | AB10: 36 | AC10: 1 | AD10: 303 | AE10: 273 | AF10: 1256.86
A11: =A10+1 -> 2 | B11: 6895.42 | C11: 266991 | D11: =C11-C10 -> 0 | E11: =C11-152000 -> 114991 | F11: =D11/$D$2 -> 0 | G11: 39.47 | H11: 0 | I11: =G11+H11 -> 39.47 | J11: =IF(L11>0,L11,0) -> 0 | K11: =I11+J11 -> 39.47 | L11: =F11-(I11-W11) -> 0 | M11: 4.76 | N11: 0 | O11: =M11-N11 -> 4.76 | P11: 0 | Q11: 0 | R11: =SUM(O11:Q11) -> 4.76 | T11: 0 | U11: 34.71 | V11: =V10-U11 -> 13655.663 | W11: =R11+T11+N11+U11 -> 39.47 | X11: =IF(L11<0,L11*-1,0) -> 0 | Y11: =W11+X11 -> 39.47 | Z11: 0 | AA11: 61 | AB11: 36 | AC11: =AC10+1 -> 2 | AD11: 306 | AE11: 300 | AF11: 1306.42
A12: =A11+1 -> 3 | B12: 6895.42 | C12: 266991 | D12: =C12-C11 -> 0 | E12: =C12-152000 -> 114991 | F12: =D12/$D$2 -> 0 | G12: 39.6 | H12: 0 | I12: =G12+H12 -> 39.6 | J12: =IF(L12>0,L12,0) -> 0 | K12: =I12+J12 -> 39.6 | L12: =F12-(I12-W12) -> 0 | M12: 4.76 | N12: 0 | O12: =M12-N12 -> 4.76 | P12: 0 | Q12: 0 | R12: =SUM(O12:Q12) -> 4.76 | T12: 0 | U12: 34.84 | V12: =V11-U12 -> 13620.823 | W12: =R12+T12+N12+U12 -> 39.6 | X12: =IF(L12<0,L12*-1,0) -> 0 | Y12: =W12+X12 -> 39.6 | Z12: 0 | AA12: 62 | AB12: 38 | AC12: =AC11+1 -> 3 | AD12: 316 | AE12: 341 | AF12: 1355.74
A13: =A12+1 -> 4 | B13: 6895.44 | C13: 267062 | D13: =C13-C12 -> 71 | E13: =C13-152000 -> 115062 | F13: =D13/$D$2 -> 35.804337 | G13: 75.434337 | H13: 0 | I13: =G13+H13 -> 75.434337 | J13: =IF(L13>0,L13,0) -> 0 | K13: =I13+J13 -> 75.434337 | L13: =F13-(I13-W13) -> 0 | M13: 4.76 | N13: 0 | O13: =M13-N13 -> 4.76 | P13: 0 | Q13: 0 | R13: =SUM(O13:Q13) -> 4.76 | T13: 0 | U13: 34.87 | V13: =V12-U13 -> 13585.953 | W13: =R13+T13+N13+U13 -> 39.63 | X13: =IF(L13<0,L13*-1,0) -> 0 | Y13: =W13+X13 -> 39.63 | Z13: 0 | AA13: 70 | AB13: 39 | AC13: =AC12+1 -> 4 | AD13: 316 | AE13: 395 | AF13: 1405.31
A14: =A13+1 -> 5 | B14: 6895.55 | C14: 267453 | D14: =C14-C13 -> 391 | E14: =C14-152000 -> 115453 | F14: =D14/$D$2 -> 197.176 | G14: 236.836 | H14: 0 | I14: =G14+H14 -> 236.836 | J14: =IF(L14>0,L14,0) -> 0 | K14: =I14+J14 -> 236.836 | L14: =F14-(I14-W14) -> 0 | M14: 4.76 | N14: 0 | O14: =M14-N14 -> 4.76 | P14: 0 | Q14: 0 | R14: =SUM(O14:Q14) -> 4.76 | T14: 0 | U14: 34.9 | V14: =V13-U14 -> 13551.053 | W14: =R14+T14+N14+U14 -> 39.66 | X14: =IF(L14<0,L14*-1,0) -> 0 | Y14: =W14+X14 -> 39.66 | Z14: 1.04 | AA14: 76 | AB14: 43 | AC14: =AC13+1 -> 5 | AD14: 316 | AE14: 466 | AF14: 1437.16
A15: =A14+1 -> 6 | B15: 6895.55 | C15: 267453 | D15: =C15-C14 -> 0 | E15: =C15-152000 -> 115453 | F15: =D15/$D$2 -> 0 | G15: 40.05 | H15: 0 | I15: =G15+H15 -> 40.05 | J15: =IF(L15>0,L15,0) -> 0 | K15: =I15+J15 -> 40.05 | L15: =F15-(I15-W15) -> 0 | M15: 4.76 | N15: 0 | O15: =M15-N15 -> 4.76 | P15: 0 | Q15: 0 | R15: =SUM(O15:Q15) -> 4.76 | T15: 0 | U15: 35.29 | V15: =V14-U15 -> 13515.763 | W15: =R15+T15+N15+U15 -> 40.05 | X15: =IF(L15<0,L15*-1,0) -> 0 | Y15: =W15+X15 -> 40.05 | Z15: 0.04 | AA15: 73 | AB15: 39 | AC15: =AC14+1 -> 6 | AD15: 325 | AE15: 538 | AF15: 1467.01
A16: =A15+1 -> 7 | B16: 6895.6 | C16: 267632 | D16: =C16-C15 -> 179 | E16: =C16-152000 -> 115632 | F16: =D16/$D$2 -> 90.267272 | G16: 129.95727 | H16: 0 | I16: =G16+H16 -> 129.95727 | J16: =IF(L16>0,L16,0) -> 0 | K16: =I16+J16 -> 129.95727 | L16: =F16-(I16-W16) -> 0 | M16: 4.76 | N16: 0 | O16: =M16-N16 -> 4.76 | P16: 0 | Q16: 0 | R16: =SUM(O16:Q16) -> 4.76 | T16: 0 | U16: 34.93 | V16: =V15-U16 -> 13480.833 | W16: =R16+T16+N16+U16 -> 39.69 | X16: =IF(L16<0,L16*-1,0) -> 0 | Y16: =W16+X16 -> 39.69 | Z16: 0.08 | AA16: 74 | AB16: 37 | AC16: =AC15+1 -> 7 | AD16: 342 | AE16: 618 | AF16: 1496.64
A17: =A16+1 -> 8 | B17: 6895.58 | C17: 267561 | D17: =C17-C16 -> -71 | E17: =C17-152000 -> 115561 | F17: =D17/$D$2 -> -35.804337 | G17: 3.8556631 | H17: 0 | I17: =G17+H17 -> 3.8556631 | J17: =IF(L17>0,L17,0) -> 0 | K17: =I17+J17 -> 3.8556631 | L17: =F17-(I17-W17) -> 0 | M17: 4.76 | N17: 0 | O17: =M17-N17 -> 4.76 | P17: 0 | Q17: 0 | R17: =SUM(O17:Q17) -> 4.76 | T17: 0 | U17: 34.9 | V17: =V16-U17 -> 13445.933 | W17: =R17+T17+N17+U17 -> 39.66 | X17: =IF(L17<0,L17*-1,0) -> 0 | Y17: =W17+X17 -> 39.66 | Z17: 0 | AA17: 69 | AB17: 34 | AC17: =AC16+1 -> 8 | AD17: 367 | AE17: 704 | AF17: 1526.51
A18: =A17+1 -> 9 | B18: 6895.57 | C18: 267524 | D18: =C18-C17 -> -37 | E18: =C18-152000 -> 115524 | F18: =D18/$D$2 -> -18.658598 | G18: 21.001402 | H18: 0 | I18: =G18+H18 -> 21.001402 | J18: =IF(L18>0,L18,0) -> 0 | K18: =I18+J18 -> 21.001402 | L18: =F18-(I18-W18) -> 0 | M18: 4.76 | N18: 0 | O18: =M18-N18 -> 4.76 | P18: 0 | Q18: 0 | R18: =SUM(O18:Q18) -> 4.76 | T18: 0 | U18: 34.9 | V18: =V17-U18 -> 13411.033 | W18: =R18+T18+N18+U18 -> 39.66 | X18: =IF(L18<0,L18*-1,0) -> 0 | Y18: =W18+X18 -> 39.66 | Z18: 0 | AA18: 66 | AB18: 44 | AC18: =AC17+1 -> 9 | AD18: 390 | AE18: 805 | AF18: 1561.24
A19: =A18+1 -> 10 | B19: 6895.58 | C19: 267561 | D19: =C19-C18 -> 37 | E19: =C19-152000 -> 115561 | F19: =D19/$D$2 -> 18.658598 | G19: 58.318598 | H19: 0 | I19: =G19+H19 -> 58.318598 | J19: =IF(L19>0,L19,0) -> 0 | K19: =I19+J19 -> 58.318598 | L19: =F19-(I19-W19) -> 0 | M19: 4.76 | N19: 0 | O19: =M19-N19 -> 4.76 | P19: 0 | Q19: 0 | R19: =SUM(O19:Q19) -> 4.76 | T19: 0 | U19: 34.9 | V19: =V18-U19 -> 13376.133 | W19: =R19+T19+N19+U19 -> 39.66 | X19: =IF(L19<0,L19*-1,0) -> 0 | Y19: =W19+X19 -> 39.66 | Z19: 0 | AA19: 66 | AB19: 36 | AC19: =AC18+1 -> 10 | AD19: 437 | AE19: 920 | AF19: 1600.39
A20: =A19+1 -> 11 | B20: 6895.57 | C20: 267524 | D20: =C20-C19 -> -37 | E20: =C20-152000 -> 115524 | F20: =D20/$D$2 -> -18.658598 | G20: 21.001402 | H20: 0 | I20: =G20+H20 -> 21.001402 | J20: =IF(L20>0,L20,0) -> 0 | K20: =I20+J20 -> 21.001402 | L20: =F20-(I20-W20) -> 0 | M20: 4.76 | N20: 0 | O20: =M20-N20 -> 4.76 | P20: 0 | Q20: 0 | R20: =SUM(O20:Q20) -> 4.76 | T20: 0 | U20: 34.9 | V20: =V19-U20 -> 13341.233 | W20: =R20+T20+N20+U20 -> 39.66 | X20: =IF(L20<0,L20*-1,0) -> 0 | Y20: =W20+X20 -> 39.66 | Z20: 0 | AA20: 68 | AB20: 40 | AC20: =AC19+1 -> 11 | AD20: 498 | AE20: 1048 | AF20: 1642
A21: =A20+1 -> 12 | B21: 6895.6 | C21: 267632 | D21: =C21-C20 -> 108 | E21: =C21-152000 -> 115632 | F21: =D21/$D$2 -> 54.462935 | G21: 94.122935 | H21: 0 | I21: =G21+H21 -> 94.122935 | J21: =IF(L21>0,L21,0) -> 0 | K21: =I21+J21 -> 94.122935 | L21: =F21-(I21-W21) -> 0 | M21: 4.76 | N21: 0 | O21: =M21-N21 -> 4.76 | P21: 0 | Q21: 0 | R21: =SUM(O21:Q21) -> 4.76 | T21: 0 | U21: 34.9 | V21: =V20-U21 -> 13306.333 | W21: =R21+T21+N21+U21 -> 39.66 | X21: =IF(L21<0,L21*-1,0) -> 0 | Y21: =W21+X21 -> 39.66 | Z21: 0 | AA21: 68 | AB21: 42 | AC21: =AC20+1 -> 12 | AD21: 572 | AE21: 1182 | AF21: 1683.42
A22: =A21+1 -> 13 | B22: 6895.62 | C22: 267703 | D22: =C22-C21 -> 71 | E22: =C22-152000 -> 115703 | F22: =D22/$D$2 -> 35.804337 | G22: 75.464337 | H22: 0 | I22: =G22+H22 -> 75.464337 | J22: =IF(L22>0,L22,0) -> 0 | K22: =I22+J22 -> 75.464337 | L22: =F22-(I22-W22) -> 0 | M22: 4.76 | N22: 0 | O22: =M22-N22 -> 4.76 | P22: 0 | Q22: 0 | R22: =SUM(O22:Q22) -> 4.76 | T22: 0 | U22: 34.9 | V22: =V21-U22 -> 13271.433 | W22: =R22+T22+N22+U22 -> 39.66 | X22: =IF(L22<0,L22*-1,0) -> 0 | Y22: =W22+X22 -> 39.66 | Z22: 0.07 | AA22: 63 | AB22: 38 | AC22: =AC21+1 -> 13 | AD22: 716 | AE22: 1339 | AF22: 1725.1
... A38: =A37+1 -> 29 | B38: 6895.79 | C38: 268308 | D38: =C38-C37 -> 0 | E38: =C38-152000 -> 116308 | F38: =D38/$D$2 -> 0 | G38: 34.83 | H38: 0 | I38: =G38+H38 -> 34.83 | J38: =IF(L38>0,L38,0) -> 0 | K38: =I38+J38 -> 34.83 | L38: =F38-(I38-W38) -> 0 | M38: 5.13 | N38: 0 | O38: =M38-N38 -> 5.13 | P38: 0 | Q38: 0 | R38: =SUM(O38:Q38) -> 5.13 | T38: 0 | U38: 29.7 | V38: =V37-U38 -> 12788.233 | W38: =R38+T38+N38+U38 -> 34.83 | X38: =IF(L38<0,L38*-1,0) -> 0 | Y38: =W38+X38 -> 34.83 | Z38: 0 | AA38: 78 | AB38: 44 | AC38: =AC37+1 -> 29 | AD38: 4963 | AE38: 4000 | AF38: 2362.83
A39: 30 | B39: 6895.77 | C39: 268237 | D39: =C39-C38 -> -71 | E39: =C39-152000 -> 116237 | F39: =D39/$D$2 -> -35.804337 | G39: 0 | H39: 0 | I39: =G39+H39 -> 0 | J39: =IF(L39>0,L39,0) -> 0 | K39: =I39+J39 -> 0 | L39: =F39-(I39-W39) -> -0.74433686 | M39: 5.36 | N39: 0 | O39: =M39-N39 -> 5.36 | P39: 0 | Q39: 0 | R39: =SUM(O39:Q39) -> 5.36 | T39: 0 | U39: 29.7 | V39: =V38-U39 -> 12758.533 | W39: =R39+T39+N39+U39 -> 35.06 | X39: =IF(L39<0,L39*-1,0) -> 0.74433686 | Y39: =W39+X39 -> 35.804337 | Z39: 0 | AA39: 84 | AB39: 46 | AC39: 30 | AD39: 5210 | AE39: 4166 | AF39: 2362.83
A40: 31 | B40: 6895.8 | C40: 268343 | D40: =C40-C39 -> 106 | E40: =C40-152000 -> 116343 | F40: =D40/$D$2 -> 53.454362 | G40: 88.664362 | H40: 0 | I40: =G40+H40 -> 88.664362 | J40: =IF(L40>0,L40,0) -> 0 | K40: =I40+J40 -> 88.664362 | L40: =F40-(I40-W40) -> 0 | M40: 5.51 | N40: 0 | O40: =M40-N40 -> 5.51 | P40: 0 | Q40: 0 | R40: =SUM(O40:Q40) -> 5.51 | T40: 0 | U40: 29.7 | V40: =V39-U40 -> 12728.833 | W40: =R40+T40+N40+U40 -> 35.21 | X40: =IF(L40<0,L40*-1,0) -> 0 | Y40: =W40+X40 -> 35.21 | Z40: 0 | AA40: 82 | AB40: 46 | AC40: 31 | AD40: 5455 | AE40: 4334 | AF40: 2403.37
AA41: 73
A42: MONTH / CFS | F42: =SUM(F10:F40) -> 771.55825 | G42: =SUM(G10:G40) -> 1921.7169 | H42: =SUM(H10:H40) -> 0 | I42: =SUM(I10:I40) -> 1921.7169 | J42: =SUM(J10:J40) -> 0 | K42: =SUM(K10:K40) -> 1921.7169 | L42: =SUM(L10:L40) -> -2.2486737 | M42: =SUM(M10:M40) -> 150.71 | ... R42: =SUM(R10:R40) -> 150.71 | T42: =SUM(T10:T40) -> 0 | U42: =SUM(U10:U40) -> 997.2 | V42: =V40 -> 12728.833 | W42: =SUM(W10:W40) -> 1147.91 | X42: =SUM(X10:X40) -> 2.2486737 | Y42: =SUM(Y10:Y40) -> 1150.1587 | Z42: =SUM(Z10:Z40) -> 1.23 | AA42: =AVERAGE(AA10:AA40) -> 71.451613 | AB42: =AVERAGE(AB10:AB40) -> 40.16129
A43: MONTH / AF | D43: =SUM(D10:D40) -> 1530 | F43: =F42*$D$2 -> 1530 | G43: =G42*$D$2 -> 3810.7647 | H43: =H42*$D$2 -> 0 | I43: =I42*$D$2 -> 3810.7647 | J43: =J42*$D$2 -> 0 | K43: =K42*$D$2 -> 3810.7647 | L43: =L42*$D$2 -> -4.45912 | M43: =M42*$D$2 -> 298.85793 | ... R43: =R42*$D$2 -> 298.85793 | T43: =T42*$D$2 -> 0 | U43: =U42*$D$2 -> 1977.4476 | V43: =V42*$D$2 -> 25241.276 | W43: =W42*$D$2 -> 2276.3055 | X43: =X42*$D$2 -> 4.45912 | Y43: =Y42*$D$2 -> 2280.7647 | AA43: =MAX(AA10:AA40) -> 84 | AB43: =MAX(AB10:AB40) -> 48 | AC43: HI
A45: SEASON / CFS | AA45: =MIN(AA10:AA40) -> 54 | AB45: =MIN(AB10:AB40) -> 30 | AC45: LO
A46: SEASON / AF
A48: YTD / CFS | F48: =F8+F42 -> 897.62985 | G48: =G8+G42 -> 3716.4169 | H48: =H8+H42 -> 0 | I48: =I8+I42 -> 3716.3169 | J48: =J8+J42 -> 541.35062 | K48: =K8+K42 -> 4257.6675 | L48: =L8+L42 -> 403.60293 | M48: =M8+M42 -> 355.21 | ... R48: =R8+R42 -> 911.57 | T48: =T8+T42 -> 0 | U48: =U8+U42 -> 2186.72 | V48: =V40 -> 12728.833 | W48: =W8+W42 -> 3222.29 | X48: =X8+X42 -> 137.74768 | Y48: =Y8+Y42 -> 3360.0377 | Z48: =Z8+Z42 -> 3.02
A49: YTD / AF | D49: =D8+D43 -> 1780 | E49: =E40 -> 116343 | F49: =F48*$D$2 -> 1780 | G49: =G48*$D$2 -> 7369.6547 | H49: =H48*$D$2 -> 0 | I49: =I48*$D$2 -> 7369.4564 | J49: =J48*$D$2 -> 1073.4983 | K49: =K48*$D$2 -> 8442.9547 | L49: =L48*$D$2 -> 800.34462 | M49: =M48*$D$2 -> 704.38143 | ... U49: =U48*$D$2 -> 4336.2658 | V49: =V40*$D$2 -> 25241.276 | W49: =W48*$D$2 -> 6389.8011 | X49: =X48*$D$2 -> 273.15365 | Y49: =Y48*$D$2 -> 6662.9547
A51: ="JUN /9" -> JUN /9
B52: 6924.15 | C52: 381833 | E52: =C52-152000 -> 229833
A53: ="5/12/94 thru 6/9/94" -> 5/12/94 thru 6/9/94
B54: =B52-B21 -> 28.55 | D54: =C52-C22 -> 114130

Sheet JAN
K1: MC PHEE RESERVOIR IN/OUT FLOW TABULATION
A2: AF/cfs CONVERT FACTOR | D2: 1.983 | K2: JANUARY "95"
A4: DATE | B4: RESERV | C4: RESERV | D4: AC FT | E4: ACTIVE | F4: CONV TO | G4: DOLORES | H4: LOST | I4: RECORDED | J4: CALC | K4: TOTAL | L4: CALC | M4: DOLORES TUNNEL | P4: LONE | Q4: U | R4: TOTAL | S4: MVI | T4: DV CR | U4: BELOW | V4: REMAIN | W4: RECORDED | X4: CALC | Y4: TOTAL | Z4: RAIN | AA4: MAX | AB4: MIN | AC4: DATE
A5: "JAN" | B5: ELEV | C5: AC FT | D5: CHANGE | E5: CAP | F5: CFS | G5: RIVER | H5: CANYON | I5: INFLOW | J5: INFLOW | K5: INFLOW | L5: INF/OTF | M5: TOT DIV | N5: UTE F&R | O5: MVI,CTZ | P5: PINE | Q5: LATERAL | R5: MVI | S5: CALL | T5: CANAL | U5: MC PHEE | V5: RELEASE | W5: OUTFLOW | X5: OUTFLOW | Y5: OUTFLOW | AA5: TMP | AB5: TMP | AC5: "JAN"
AD6: 741 | AE6: 742
A7: SEASON BAL
A8: YTD | B8: {=DEC!$B$40:$C$40} -> 6895.8 | C8: 268343 | D8: {=DEC!$D$49:$E$49} -> 1780 | E8: 116343 | F8: {=DEC!$F$48:$Z$48} -> 897.62985 | G8: 3716.4169 | H8: 0 | I8: 3716.3169 | J8: 541.35062 | K8: 4257.6675 | L8: 403.60293 | M8: 355.21 | N8: 0 | O8: 150.71 | P8: 680.36 | Q8: 0 | R8: 911.57 | S8: 0 | T8: 0 | U8: 2186.72 | V8: 12728.833 | W8: 3222.29 | X8: 137.74768 | Y8: 3360.0377 | Z8: 3.02 | AD8: 285 | AE8: 251 | AF8: 1207.63
A10: 1 | B10: 6895.79 | C10: 268308 | D10: =C10-C8 -> -35 | E10: =C10-152000 -> 116308 | F10: =D10/$D$2 -> -17.650025 | G10: 17.559975 | H10: 0 | I10: =G10+H10 -> 17.559975 | J10: =IF(L10>0,L10,0) -> 0 | K10: =I10+J10 -> 17.559975 | L10: =F10-(I10-W10) -> 0 | M10: 5.51 | N10: 0 | O10: =M10-N10 -> 5.51 | P10: 0 | Q10: 0 | R10: =SUM(O10:Q10) -> 5.51 | T10: 0 | U10: 29.7 | V10: =V8-U10 -> 12699.133 | W10: =R10+T10+N10+U10 -> 35.21 | X10: =IF(L10<0,L10*-1,0) -> 0 | Y10: =W10+X10 -> 35.21 | Z10: 0 | AA10: 54 | AB10: 36 | AC10: 1 | AD10: 303 | AE10: 273 | AF10: 1256.86
A11: =A10+1 -> 2 | B11: 6895.79 | C11: 268308 | D11: =C11-C10 -> 0 | E11: =C11-152000 -> 116308 | F11: =D11/$D$2 -> 0 | G11: 35.21 | H11: 0 | I11: =G11+H11 -> 35.21 | J11: =IF(L11>0,L11,0) -> 0 | K11: =I11+J11 -> 35.21 | L11: =F11-(I11-W11) -> 0 | M11: 5.51 | N11: 0 | O11: =M11-N11 -> 5.51 | P11: 0 | Q11: 0 | R11: =SUM(O11:Q11) -> 5.51 | T11: 0 | U11: 29.7 | V11: =V10-U11 -> 12669.433 | W11: =R11+T11+N11+U11 -> 35.21 | X11: =IF(L11<0,L11*-1,0) -> 0 | Y11: =W11+X11 -> 35.21 | Z11: 0 | AA11: 61 | AB11: 36 | AC11: =AC10+1 -> 2 | AD11: 306 | AE11: 300 | AF11: 1306.42
A12: =A11+1 -> 3 | B12: 6895.8 | C12: 268343 | D12: =C12-C11 -> 35 | E12: =C12-152000 -> 116343 | F12: =D12/$D$2 -> 17.650025 | G12: 51.720025 | H12: 0 | I12: =G12+H12 -> 51.720025 | J12: =IF(L12>0,L12,0) -> 0 | K12: =I12+J12 -> 51.720025 | L12: =F12-(I12-W12) -> 0 | M12: 4.37 | N12: 0 | O12: =M12-N12 -> 4.37 | P12: 0 | Q12: 0 | R12: =SUM(O12:Q12) -> 4.37 | T12: 0 | U12: 29.7 | V12: =V11-U12 -> 12639.733 | W12: =R12+T12+N12+U12 -> 34.07 | X12: =IF(L12<0,L12*-1,0) -> 0 | Y12: =W12+X12 -> 34.07 | Z12: 0 | AA12: 62 | AB12: 38 | AC12: =AC11+1 -> 3 | AD12: 316 | AE12: 341 | AF12: 1355.74
A13: =A12+1 -> 4 | B13: 6895.97 | C13: 268949 | D13: =C13-C12 -> 606 | E13: =C13-152000 -> 116949 | F13: =D13/$D$2 -> 305.59758 | G13: 339.01758 | H13: 0 | I13: =G13+H13 -> 339.01758 | J13: =IF(L13>0,L13,0) -> 0 | K13: =I13+J13 -> 339.01758 | L13: =F13-(I13-W13) -> 0 | M13: 3.72 | N13: 0 | O13: =M13-N13 -> 3.72 | P13: 0 | Q13: 0 | R13: =SUM(O13:Q13) -> 3.72 | T13: 0 | U13: 29.7 | V13: =V12-U13 -> 12610.033 | W13: =R13+T13+N13+U13 -> 33.42 | X13: =IF(L13<0,L13*-1,0) -> 0 | Y13: =W13+X13 -> 33.42 | Z13: 1.2 | AA13: 70 | AB13: 39 | AC13: =AC12+1 -> 4 | AD13: 316 | AE13: 395 | AF13: 1405.31
A14: =A13+1 -> 5 | B14: 6895.97 | C14: 268949 | D14: =C14-C13 -> 0 | E14: =C14-152000 -> 116949 | F14: =D14/$D$2 -> 0 | G14: 33.42 | H14: 0 | I14: =G14+H14 -> 33.42 | J14: =IF(L14>0,L14,0) -> 0 | K14: =I14+J14 -> 33.42 | L14: =F14-(I14-W14) -> 0 | M14: 3.72 | N14: 0 | O14: =M14-N14 -> 3.72 | P14: 0 | Q14: 0 | R14: =SUM(O14:Q14) -> 3.72 | T14: 0 | U14: 29.7 | V14: =V13-U14 -> 12580.333 | W14: =R14+T14+N14+U14 -> 33.42 | X14: =IF(L14<0,L14*-1,0) -> 0 | Y14: =W14+X14 -> 33.42 | Z14: 0.35 | AA14: 76 | AB14: 43 | AC14: =AC13+1 -> 5 | AD14: 316 | AE14: 466 | AF14: 1437.16
A15: =A14+1 -> 6 | B15: 6895.98 | C15: 268984 | D15: =C15-C14 -> 35 | E15: =C15-152000 -> 116984 | F15: =D15/$D$2 -> 17.650025 | G15: 51.070025 | H15: 0 | I15: =G15+H15 -> 51.070025 | J15: =IF(L15>0,L15,0) -> 0 | K15: =I15+J15 -> 51.070025 | L15: =F15-(I15-W15) -> 0 | M15: 3.72 | N15: 0 | O15: =M15-N15 -> 3.72 | P15: 0 | Q15: 0 | R15: =SUM(O15:Q15) -> 3.72 | T15: 0 | U15: 29.7 | V15: =V14-U15 -> 12550.633 | W15: =R15+T15+N15+U15 -> 33.42 | X15: =IF(L15<0,L15*-1,0) -> 0 | Y15: =W15+X15 -> 33.42 | Z15: 0.15 | AA15: 73 | AB15: 39 | AC15: =AC14+1 -> 6 | AD15: 325 | AE15: 538 | AF15: 1467.01
A16: =A15+1 -> 7 | B16: 6895.99 | C16: 269020 | D16: =C16-C15 -> 36 | E16: =C16-152000 -> 117020 | F16: =D16/$D$2 -> 18.154312 | G16: 51.834312 | H16: 0 | I16: =G16+H16 -> 51.834312 | J16: =IF(L16>0,L16,0) -> 0 | K16: =I16+J16 -> 51.834312 | L16: =F16-(I16-W16) -> 0 | M16: 3.98 | N16: 0 | O16: =M16-N16 -> 3.98 | P16: 0 | Q16: 0 | R16: =SUM(O16:Q16) -> 3.98 | T16: 0 | U16: 29.7 | V16: =V15-U16 -> 12520.933 | W16: =R16+T16+N16+U16 -> 33.68 | X16: =IF(L16<0,L16*-1,0) -> 0 | Y16: =W16+X16 -> 33.68 | Z16: 0.11 | AA16: 74 | AB16: 37 | AC16: =AC15+1 -> 7 | AD16: 342 | AE16: 618 | AF16: 1496.64
A17: =A16+1 -> 8 | B17: 6895.99 | C17: 269020 | D17: =C17-C16 -> 0 | E17: =C17-152000 -> 117020 | F17: =D17/$D$2 -> 0 | G17: 34.1 | H17: 0 | I17: =G17+H17 -> 34.1 | J17: =IF(L17>0,L17,0) -> 0 | K17: =I17+J17 -> 34.1 | L17: =F17-(I17-W17) -> 0 | M17: 4.4 | N17: 0 | O17: =M17-N17 -> 4.4 | P17: 0 | Q17: 0 | R17: =SUM(O17:Q17) -> 4.4 | T17: 0 | U17: 29.7 | V17: =V16-U17 -> 12491.233 | W17: =R17+T17+N17+U17 -> 34.1 | X17: =IF(L17<0,L17*-1,0) -> 0 | Y17: =W17+X17 -> 34.1 | Z17: 0.1 | AA17: 69 | AB17: 34 | AC17: =AC16+1 -> 8 | AD17: 367 | AE17: 704 | AF17: 1526.51
A18: =A17+1 -> 9 | B18: 6896 | C18: 269055 | D18: =C18-C17 -> 35 | E18: =C18-152000 -> 117055 | F18: =D18/$D$2 -> 17.650025 | G18: 51.750025 | H18: 0 | I18: =G18+H18 -> 51.750025 | J18: =IF(L18>0,L18,0) -> 0 | K18: =I18+J18 -> 51.750025 | L18: =F18-(I18-W18) -> 0 | M18: 4.4 | N18: 0 | O18: =M18-N18 -> 4.4 | P18: 0 | Q18: 0 | R18: =SUM(O18:Q18) -> 4.4 | T18: 0 | U18: 29.7 | V18: =V17-U18 -> 12461.533 | W18: =R18+T18+N18+U18 -> 34.1 | X18: =IF(L18<0,L18*-1,0) -> 0 | Y18: =W18+X18 -> 34.1 | Z18: 0 | AA18: 66 | AB18: 44 | AC18: =AC17+1 -> 9 | AD18: 390 | AE18: 805 | AF18: 1561.24
A19: =A18+1 -> 10 | B19: 6896.02 | C19: 269127 | D19: =C19-C18 -> 72 | E19: =C19-152000 -> 117127 | F19: =D19/$D$2 -> 36.308623 | G19: 70.408623 | H19: 0 | I19: =G19+H19 -> 70.408623 | J19: =IF(L19>0,L19,0) -> 0 | K19: =I19+J19 -> 70.408623 | L19: =F19-(I19-W19) -> 0 | M19: 4.4 | N19: 0 | O19: =M19-N19 -> 4.4 | P19: 0 | Q19: 0 | R19: =SUM(O19:Q19) -> 4.4 | T19: 0 | U19: 29.7 | V19: =V18-U19 -> 12431.833 | W19: =R19+T19+N19+U19 -> 34.1 | X19: =IF(L19<0,L19*-1,0) -> 0 | Y19: =W19+X19 -> 34.1 | Z19: 0 | AA19: 66 | AB19: 36 | AC19: =AC18+1 -> 10 | AD19: 437 | AE19: 920 | AF19: 1600.39
A20: =A19+1 -> 11 | B20: 6896.09 | C20: 269377 | D20: =C20-C19 -> 250 | E20: =C20-152000 -> 117377 | F20: =D20/$D$2 -> 126.07161 | G20: 159.90161 | H20: 0 | I20: =G20+H20 -> 159.90161 | J20: =IF(L20>0,L20,0) -> 0 | K20: =I20+J20 -> 159.90161 | L20: =F20-(I20-W20) -> 0 | M20: 4.13 | N20: 0 | O20: =M20-N20 -> 4.13 | P20: 0 | Q20: 0 | R20: =SUM(O20:Q20) -> 4.13 | T20: 0 | U20: 29.7 | V20: =V19-U20 -> 12402.133 | W20: =R20+T20+N20+U20 -> 33.83 | X20: =IF(L20<0,L20*-1,0) -> 0 | Y20: =W20+X20 -> 33.83 | Z20: 0.4 | AA20: 68 | AB20: 40 | AC20: =AC19+1 -> 11 | AD20: 498 | AE20: 1048 | AF20: 1642
A21: =A20+1 -> 12 | B21: 6896.09 | C21: 269377 | D21: =C21-C20 -> 0 | E21: =C21-152000 -> 117377 | F21: =D21/$D$2 -> 0 | G21: 33.09 | H21: 0 | I21: =G21+H21 -> 33.09 | J21: =IF(L21>0,L21,0) -> 0 | K21: =I21+J21 -> 33.09 | L21: =F21-(I21-W21) -> 0 | M21: 3.39 | N21: 0 | O21: =M21-N21 -> 3.39 | P21: 0 | Q21: 0 | R21: =SUM(O21:Q21) -> 3.39 | T21: 0 | U21: 29.7 | V21: =V20-U21 -> 12372.433 | W21: =R21+T21+N21+U21 -> 33.09 | X21: =IF(L21<0,L21*-1,0) -> 0 | Y21: =W21+X21 -> 33.09 | Z21: 0 | AA21: 68 | AB21: 42 | AC21: =AC20+1 -> 12 | AD21: 572 | AE21: 1182 | AF21: 1683.42
A22: =A21+1 -> 13 | B22: 6896.09 | C22: 269377 | D22: =C22-C21 -> 0 | E22: =C22-152000 -> 117377 | F22: =D22/$D$2 -> 0 | G22: 33.35 | H22: 0 | I22: =G22+H22 -> 33.35 | J22: =IF(L22>0,L22,0) -> 0 | K22: =I22+J22 -> 33.35 | L22: =F22-(I22-W22) -> 0 | M22: 3.65 | N22: 0 | O22: =M22-N22 -> 3.65 | P22: 0 | Q22: 0 | R22: =SUM(O22:Q22) -> 3.65 | T22: 0 | U22: 29.7 | V22: =V21-U22 -> 12342.733 | W22: =R22+T22+N22+U22 -> 33.35 | X22: =IF(L22<0,L22*-1,0) -> 0 | Y22: =W22+X22 -> 33.35 | Z22: 0 | AA22: 63 | AB22: 38 | AC22: =AC21+1 -> 13 | AD22: 716 | AE22: 1339 | AF22: 1725.1
... A38: =A37+1 -> 29 | B38: 6896.3 | C38: 270131 | D38: =C38-C37 -> 0 | E38: =C38-152000 -> 118131 | F38: =D38/$D$2 -> 0 | G38: 33.76 | H38: 0 | I38: =G38+H38 -> 33.76 | J38: =IF(L38>0,L38,0) -> 0 | K38: =I38+J38 -> 33.76 | L38: =F38-(I38-W38) -> 0 | M38: 4.06 | N38: 0 | O38: =M38-N38 -> 4.06 | P38: 0 | Q38: 0 | R38: =SUM(O38:Q38) -> 4.06 | T38: 0 | U38: 29.7 | V38: =V37-U38 -> 11867.533 | W38: =R38+T38+N38+U38 -> 33.76 | X38: =IF(L38<0,L38*-1,0) -> 0 | Y38: =W38+X38 -> 33.76 | Z38: 0 | AA38: 78 | AB38: 44 | AC38: =AC37+1 -> 29 | AD38: 4963 | AE38: 4000 | AF38: 2362.83
A39: 30 | B39: 6896.32 | C39: 270203 | D39: =C39-C38 -> 72 | E39: =C39-152000 -> 118203 | F39: =D39/$D$2 -> 36.308623 | G39: 69.828623 | H39: 0 | I39: =G39+H39 -> 69.828623 | J39: =IF(L39>0,L39,0) -> 0 | K39: =I39+J39 -> 69.828623 | L39: =F39-(I39-W39) -> 0 | M39: 3.82 | N39: 0 | O39: =M39-N39 -> 3.82 | P39: 0 | Q39: 0 | R39: =SUM(O39:Q39) -> 3.82 | T39: 0 | U39: 29.7 | V39: =V38-U39 -> 11837.833 | W39: =R39+T39+N39+U39 -> 33.52 | X39: =IF(L39<0,L39*-1,0) -> 0 | Y39: =W39+X39 -> 33.52 | Z39: 0 | AA39: 84 | AB39: 46 | AC39: 30 | AD39: 5210 | AE39: 4166 | AF39: 2362.83
A40: 31 | B40: 6896.32 | C40: 270203 | D40: =C40-C39 -> 0 | E40: =C40-152000 -> 118203 | F40: =D40/$D$2 -> 0 | G40: 33.42 | H40: 0 | I40: =G40+H40 -> 33.42 | J40: =IF(L40>0,L40,0) -> 0 | K40: =I40+J40 -> 33.42 | L40: =F40-(I40-W40) -> 0 | M40: 3.72 | N40: 0 | O40: =M40-N40 -> 3.72 | P40: 0 | Q40: 0 | R40: =SUM(O40:Q40) -> 3.72 | T40: 0 | U40: 29.7 | V40: =V39-U40 -> 11808.133 | W40: =R40+T40+N40+U40 -> 33.42 | X40: =IF(L40<0,L40*-1,0) -> 0 | Y40: =W40+X40 -> 33.42 | Z40: 0 | AA40: 82 | AB40: 46 | AC40: 31 | AD40: 5455 | AE40: 4334 | AF40: 2403.37
AA41: 73
A42: MONTH / CFS | F42: =SUM(F10:F40) -> 937.97277 | G42: =SUM(G10:G40) -> 1994.3328 | H42: =SUM(H10:H40) -> 0 | I42: =SUM(I10:I40) -> 1994.3328 | J42: =SUM(J10:J40) -> 0 | K42: =SUM(K10:K40) -> 1994.3328 | L42: =SUM(L10:L40) -> 0 | M42: =SUM(M10:M40) -> 135.66 | ... R42: =SUM(R10:R40) -> 135.66 | T42: =SUM(T10:T40) -> 0 | U42: =SUM(U10:U40) -> 920.7 | W42: =SUM(W10:W40) -> 1056.36 | X42: =SUM(X10:X40) -> 0 | Y42: =SUM(Y10:Y40) -> 1056.36 | Z42: =SUM(Z10:Z40) -> 3.25 | AA42: =AVERAGE(AA10:AA40) -> 71.451613 | AB42: =AVERAGE(AB10:AB40) -> 40.16129
A43: MONTH / AF | D43: =SUM(D10:D40) -> 1860 | F43: =F42*$D$2 -> 1860 | G43: =G42*$D$2 -> 3954.7619 | H43: =H42*$D$2 -> 0 | I43: =I42*$D$2 -> 3954.7619 | J43: =J42*$D$2 -> 0 | K43: =K42*$D$2 -> 3954.7619 | L43: =L42*$D$2 -> 0 | M43: =M42*$D$2 -> 269.01378 | ... R43: =R42*$D$2 -> 269.01378 | T43: =T42*$D$2 -> 0 | U43: =U42*$D$2 -> 1825.7481 | W43: =W42*$D$2 -> 2094.7619 | X43: =X42*$D$2 -> 0 | Y43: =Y42*$D$2 -> 2094.7619 | AA43: =MAX(AA10:AA40) -> 84 | AB43: =MAX(AB10:AB40) -> 48 | AC43: HI
A45: SEASON / CFS | AA45: =MIN(AA10:AA40) -> 54 | AB45: =MIN(AB10:AB40) -> 30 | AC45: LO
A46: SEASON / AF
A48: YTD / CFS | F48: =F8+F42 -> 1835.6026 | G48: =G8+G42 -> 5710.7497 | H48: =H8+H42 -> 0 | I48: =I8+I42 -> 5710.6497 | J48: =J8+J42 -> 541.35062 | K48: =K8+K42 -> 6252.0003 | L48: =L8+L42 -> 403.60293 | M48: =M8+M42 -> 490.87 | ... R48: =R8+R42 -> 1047.23 | T48: =T8+T42 -> 0 | U48: =U8+U42 -> 3107.42 | V48: =V40 -> 11808.133 | W48: =W8+W42 -> 4278.65 | X48: =X8+X42 -> 137.74768 | Y48: =Y8+Y42 -> 4416.3977 | Z48: =Z8+Z42 -> 6.27
A49: YTD / AF | D49: =D8+D43 -> 3640 | E49: =E40 -> 118203 | F49: =F48*$D$2 -> 3640 | G49: =G48*$D$2 -> 11324.417 | H49: =H48*$D$2 -> 0 | I49: =I48*$D$2 -> 11324.218 | J49: =J48*$D$2 -> 1073.4983 | K49: =K48*$D$2 -> 12397.717 | L49: =L48*$D$2 -> 800.34462 | M49: =M48*$D$2 -> 973.39521 | ... U49: =U48*$D$2 -> 6162.0139 | V49: =V40*$D$2 -> 23415.528 | W49: =W48*$D$2 -> 8484.5629 | X49: =X48*$D$2 -> 273.15365 | Y49: =Y48*$D$2 -> 8757.7166
A51: ="JUN /9" -> JUN /9
B52: 6924.15 | C52: 381833 | E52: =C52-152000 -> 229833
A53: ="5/12/94 thru 6/9/94" -> 5/12/94 thru 6/9/94
B54: =B52-B21 -> 28.06 | D54: =C52-C23 -> 112419

Sheet FEB
K1: MC PHEE RESERVOIR IN/OUT FLOW TABULATION
A2: AF/cfs CONVERT FACTOR | D2: 1.983 | K2: FEBRUARY "95"
A4: DATE | B4: RESERV | C4: RESERV | D4: AC FT | E4: ACTIVE | F4: CONV TO | G4: DOLORES | H4: LOST | I4: RECORDED | J4: CALC | K4: TOTAL | L4: CALC | M4: DOLORES TUNNEL | P4: LONE | Q4: U | R4: TOTAL | S4: MVI | T4: DV CR | U4: BELOW | V4: REMAIN | W4: RECORDED | X4: CALC | Y4: TOTAL | Z4: RAIN | AA4: MAX | AB4: MIN | AC4: DATE
A5: FEB | B5: ELEV | C5: AC FT | D5: CHANGE | E5: CAP | F5: CFS | G5: RIVER | H5: CANYON | I5: INFLOW | J5: INFLOW | K5: INFLOW | L5: INF/OTF | M5: TOT DIV | N5: UTE F&R | O5: MVI,CTZ | P5: PINE | Q5: LATERAL | R5: MVI | S5: CALL | T5: CANAL | U5: MC PHEE | V5: RELEASE | W5: OUTFLOW | X5: OUTFLOW | Y5: OUTFLOW | AA5: TMP | AB5: TMP | AC5: FEB
AD6: 741 | AE6: 742
A7: SEASON BAL
A8: YTD | B8: {=JAN!$B$40:$C$40} -> 6896.32 | C8: 270203 | D8: {=JAN!$D$49:$E$49} -> 3640 | E8: 118203 | F8: {=JAN!$F$48:$Z$48} -> 1835.6026 | G8: 5710.7497 | H8: 0 | I8: 5710.6497 | J8: 541.35062 | K8: 6252.0003 | L8: 403.60293 | M8: 490.87 | N8: 0 | O8: 286.37 | P8: 680.36 | Q8: 0 | R8: 1047.23 | S8: 0 | T8: 0 | U8: 3107.42 | V8: 11808.133 | W8: 4278.65 | X8: 137.74768 | Y8: 4416.3977 | Z8: 6.27 | AD8: 285 | AE8: 251 | AF8: 1207.63
A10: 1 | B10: 6896.32 | C10: 270203 | D10: =C10-C8 -> 0 | E10: =C10-152000 -> 118203 | F10: =D10/$D$2 -> 0 | G10: 32.99 | H10: 0 | I10: =G10+H10 -> 32.99 | J10: =IF(L10>0,L10,0) -> 0 | K10: =I10+J10 -> 32.99 | L10: =F10-(I10-W10) -> 0 | M10: 3.29 | N10: 0 | O10: =M10-N10 -> 3.29 | P10: 0 | Q10: 0 | R10: =SUM(O10:Q10) -> 3.29 | T10: 0 | U10: 29.7 | V10: =V8-U10 -> 11778.433 | W10: =R10+T10+N10+U10 -> 32.99 | X10: =IF(L10<0,L10*-1,0) -> 0 | Y10: =W10+X10 -> 32.99 | Z10: 0 | AA10: 54 | AB10: 36 | AC10: 1 | AD10: 303 | AE10: 273 | AF10: 1256.86
A11: =A10+1 -> 2 | B11: 6896.33 | C11: 270239 | D11: =C11-C10 -> 36 | E11: =C11-152000 -> 118239 | F11: =D11/$D$2 -> 18.154312 | G11: 50.934312 | H11: 0 | I11: =G11+H11 -> 50.934312 | J11: =IF(L11>0,L11,0) -> 0 | K11: =I11+J11 -> 50.934312 | L11: =F11-(I11-W11) -> 0 | M11: 3.08 | N11: 0 | O11: =M11-N11 -> 3.08 | P11: 0 | Q11: 0 | R11: =SUM(O11:Q11) -> 3.08 | T11: 0 | U11: 29.7 | V11: =V10-U11 -> 11748.733 | W11: =R11+T11+N11+U11 -> 32.78 | X11: =IF(L11<0,L11*-1,0) -> 0 | Y11: =W11+X11 -> 32.78 | Z11: 0 | AA11: 61 | AB11: 36 | AC11: =AC10+1 -> 2 | AD11: 306 | AE11: 300 | AF11: 1306.42
A12: =A11+1 -> 3 | B12: 6896.35 | C12: 270311 | D12: =C12-C11 -> 72 | E12: =C12-152000 -> 118311 | F12: =D12/$D$2 -> 36.308623 | G12: 69.088623 | H12: 0 | I12: =G12+H12 -> 69.088623 | J12: =IF(L12>0,L12,0) -> 0 | K12: =I12+J12 -> 69.088623 | L12: =F12-(I12-W12) -> 0 | M12: 3.08 | N12: 0 | O12: =M12-N12 -> 3.08 | P12: 0 | Q12: 0 | R12: =SUM(O12:Q12) -> 3.08 | T12: 0 | U12: 29.7 | V12: =V11-U12 -> 11719.033 | W12: =R12+T12+N12+U12 -> 32.78 | X12: =IF(L12<0,L12*-1,0) -> 0 | Y12: =W12+X12 -> 32.78 | Z12: 0 | AA12: 62 | AB12: 38 | AC12: =AC11+1 -> 3 | AD12: 316 | AE12: 341 | AF12: 1355.74
A13: =A12+1 -> 4 | B13: 6896.37 | C13: 270383 | D13: =C13-C12 -> 72 | E13: =C13-152000 -> 118383 | F13: =D13/$D$2 -> 36.308623 | G13: 69.088623 | H13: 0 | I13: =G13+H13 -> 69.088623 | J13: =IF(L13>0,L13,0) -> 0 | K13: =I13+J13 -> 69.088623 | L13: =F13-(I13-W13) -> 0 | M13: 3.08 | N13: 0 | O13: =M13-N13 -> 3.08 | P13: 0 | Q13: 0 | R13: =SUM(O13:Q13) -> 3.08 | T13: 0 | U13: 29.7 | V13: =V12-U13 -> 11689.333 | W13: =R13+T13+N13+U13 -> 32.78 | X13: =IF(L13<0,L13*-1,0) -> 0 | Y13: =W13+X13 -> 32.78 | Z13: 0 | AA13: 70 | AB13: 39 | AC13: =AC12+1 -> 4 | AD13: 316 | AE13: 395 | AF13: 1405.31
A14: =A13+1 -> 5 | B14: 6896.39 | C14: 270455 | D14: =C14-C13 -> 72 | E14: =C14-152000 -> 118455 | F14: =D14/$D$2 -> 36.308623 | G14: 69.088623 | H14: 0 | I14: =G14+H14 -> 69.088623 | J14: =IF(L14>0,L14,0) -> 0 | K14: =I14+J14 -> 69.088623 | L14: =F14-(I14-W14) -> 0 | M14: 3.08 | N14: 0 | O14: =M14-N14 -> 3.08 | P14: 0 | Q14: 0 | R14: =SUM(O14:Q14) -> 3.08 | T14: 0 | U14: 29.7 | V14: =V13-U14 -> 11659.633 | W14: =R14+T14+N14+U14 -> 32.78 | X14: =IF(L14<0,L14*-1,0) -> 0 | Y14: =W14+X14 -> 32.78 | Z14: 0 | AA14: 76 | AB14: 43 | AC14: =AC13+1 -> 5 | AD14: 316 | AE14: 466 | AF14: 1437.16
A15: =A14+1 -> 6 | B15: 6896.42 | C15: 270562 | D15: =C15-C14 -> 107 | E15: =C15-152000 -> 118562 | F15: =D15/$D$2 -> 53.958649 | G15: 86.878649 | H15: 0 | I15: =G15+H15 -> 86.878649 | J15: =IF(L15>0,L15,0) -> 0 | K15: =I15+J15 -> 86.878649 | L15: =F15-(I15-W15) -> 0 | M15: 3.22 | N15: 0 | O15: =M15-N15 -> 3.22 | P15: 0 | Q15: 0 | R15: =SUM(O15:Q15) -> 3.22 | T15: 0 | U15: 29.7 | V15: =V14-U15 -> 11629.933 | W15: =R15+T15+N15+U15 -> 32.92 | X15: =IF(L15<0,L15*-1,0) -> 0 | Y15: =W15+X15 -> 32.92 | Z15: 0 | AA15: 73 | AB15: 39 | AC15: =AC14+1 -> 6 | AD15: 325 | AE15: 538 | AF15: 1467.01
A16: =A15+1 -> 7 | B16: 6896.44 | C16: 270634 | D16: =C16-C15 -> 72 | E16: =C16-152000 -> 118634 | F16: =D16/$D$2 -> 36.308623 | G16: 69.398623 | H16: 0 | I16: =G16+H16 -> 69.398623 | J16: =IF(L16>0,L16,0) -> 0 | K16: =I16+J16 -> 69.398623 | L16: =F16-(I16-W16) -> 0 | M16: 3.39 | N16: 0 | O16: =M16-N16 -> 3.39 | P16: 0 | Q16: 0 | R16: =SUM(O16:Q16) -> 3.39 | T16: 0 | U16: 29.7 | V16: =V15-U16 -> 11600.233 | W16: =R16+T16+N16+U16 -> 33.09 | X16: =IF(L16<0,L16*-1,0) -> 0 | Y16: =W16+X16 -> 33.09 | Z16: 0 | AA16: 74 | AB16: 37 | AC16: =AC15+1 -> 7 | AD16: 342 | AE16: 618 | AF16: 1496.64
A17: =A16+1 -> 8 | B17: 6896.47 | C17: 270742 | D17: =C17-C16 -> 108 | E17: =C17-152000 -> 118742 | F17: =D17/$D$2 -> 54.462935 | G17: 87.642935 | H17: 0 | I17: =G17+H17 -> 87.642935 | J17: =IF(L17>0,L17,0) -> 0 | K17: =I17+J17 -> 87.642935 | L17: =F17-(I17-W17) -> 0 | M17: 3.48 | N17: 0 | O17: =M17-N17 -> 3.48 | P17: 0 | Q17: 0 | R17: =SUM(O17:Q17) -> 3.48 | T17: 0 | U17: 29.7 | V17: =V16-U17 -> 11570.533 | W17: =R17+T17+N17+U17 -> 33.18 | X17: =IF(L17<0,L17*-1,0) -> 0 | Y17: =W17+X17 -> 33.18 | Z17: 0.08 | AA17: 69 | AB17: 34 | AC17: =AC16+1 -> 8 | AD17: 367 | AE17: 704 | AF17: 1526.51
A18: =A17+1 -> 9 | B18: 6896.48 | C18: 270777 | D18: =C18-C17 -> 35 | E18: =C18-152000 -> 118777 | F18: =D18/$D$2 -> 17.650025 | G18: 51.230025 | H18: 0 | I18: =G18+H18 -> 51.230025 | J18: =IF(L18>0,L18,0) -> 0 | K18: =I18+J18 -> 51.230025 | L18: =F18-(I18-W18) -> 0 | M18: 3.88 | N18: 0 | O18: =M18-N18 -> 3.88 | P18: 0 | Q18: 0 | R18: =SUM(O18:Q18) -> 3.88 | T18: 0 | U18: 29.7 | V18: =V17-U18 -> 11540.833 | W18: =R18+T18+N18+U18 -> 33.58 | X18: =IF(L18<0,L18*-1,0) -> 0 | Y18: =W18+X18 -> 33.58 | Z18: 0 | AA18: 66 | AB18: 44 | AC18: =AC17+1 -> 9 | AD18: 390 | AE18: 805 | AF18: 1561.24
A19: =A18+1 -> 10 | B19: 6896.5 | C19: 270849 | D19: =C19-C18 -> 72 | E19: =C19-152000 -> 118849 | F19: =D19/$D$2 -> 36.308623 | G19: 71.058623 | H19: 0 | I19: =G19+H19 -> 71.058623 | J19: =IF(L19>0,L19,0) -> 0 | K19: =I19+J19 -> 71.058623 | L19: =F19-(I19-W19) -> 0 | M19: 5.05 | N19: 0 | O19: =M19-N19 -> 5.05 | P19: 0 | Q19: 0 | R19: =SUM(O19:Q19) -> 5.05 | T19: 0 | U19: 29.7 | V19: =V18-U19 -> 11511.133 | W19: =R19+T19+N19+U19 -> 34.75 | X19: =IF(L19<0,L19*-1,0) -> 0 | Y19: =W19+X19 -> 34.75 | Z19: 0 | AA19: 66 | AB19: 36 | AC19: =AC18+1 -> 10 | AD19: 437 | AE19: 920 | AF19: 1600.39
A20: =A19+1 -> 11 | B20: 6896.54 | C20: 270993 | D20: =C20-C19 -> 144 | E20: =C20-152000 -> 118993 | F20: =D20/$D$2 -> 72.617247 | G20: 107.44725 | H20: 0 | I20: =G20+H20 -> 107.44725 | J20: =IF(L20>0,L20,0) -> 0 | K20: =I20+J20 -> 107.44725 | L20: =F20-(I20-W20) -> 0 | M20: 5.13 | N20: 0 | O20: =M20-N20 -> 5.13 | P20: 0 | Q20: 0 | R20: =SUM(O20:Q20) -> 5.13 | T20: 0 | U20: 29.7 | V20: =V19-U20 -> 11481.433 | W20: =R20+T20+N20+U20 -> 34.83 | X20: =IF(L20<0,L20*-1,0) -> 0 | Y20: =W20+X20 -> 34.83 | Z20: 0 | AA20: 68 | AB20: 40 | AC20: =AC19+1 -> 11 | AD20: 498 | AE20: 1048 | AF20: 1642
A21: =A20+1 -> 12 | B21: 6896.55 | C21: 271028 | D21: =C21-C20 -> 35 | E21: =C21-152000 -> 119028 | F21: =D21/$D$2 -> 17.650025 | G21: 52.130025 | H21: 0 | I21: =G21+H21 -> 52.130025 | J21: =IF(L21>0,L21,0) -> 0 | K21: =I21+J21 -> 52.130025 | L21: =F21-(I21-W21) -> 0 | M21: 4.78 | N21: 0 | O21: =M21-N21 -> 4.78 | P21: 0 | Q21: 0 | R21: =SUM(O21:Q21) -> 4.78 | T21: 0 | U21: 29.7 | V21: =V20-U21 -> 11451.733 | W21: =R21+T21+N21+U21 -> 34.48 | X21: =IF(L21<0,L21*-1,0) -> 0 | Y21: =W21+X21 -> 34.48 | Z21: 0 | AA21: 68 | AB21: 42 | AC21: =AC20+1 -> 12 | AD21: 572 | AE21: 1182 | AF21: 1683.42
A22: =A21+1 -> 13 | B22: 6896.55 | C22: 271028 | D22: =C22-C21 -> 0 | E22: =C22-152000 -> 119028 | F22: =D22/$D$2 -> 0 | G22: 34.13 | H22: 0 | I22: =G22+H22 -> 34.13 | J22: =IF(L22>0,L22,0) -> 0 | K22: =I22+J22 -> 34.13 | L22: =F22-(I22-W22) -> 0 | M22: 4.4 | N22: 0 | O22: =M22-N22 -> 4.4 | P22: 0 | Q22: 0 | R22: =SUM(O22:Q22) -> 4.4 | T22: 0 | U22: 29.73 | V22: =V21-U22 -> 11422.003 | W22: =R22+T22+N22+U22 -> 34.13 | X22: =IF(L22<0,L22*-1,0) -> 0 | Y22: =W22+X22 -> 34.13 | Z22: 0.11 | AA22: 63 | AB22: 38 | AC22: =AC21+1 -> 13 | AD22: 716 | AE22: 1339 | AF22: 1725.1
... A37: =A36+1 -> 28 | B37: 6897.44 | C37: 274235 | D37: =C37-C36 -> 543 | E37: =C37-152000 -> 122235 | F37: =D37/$D$2 -> 273.82753 | G37: 308.76753 | H37: 0 | I37: =G37+H37 -> 308.76753 | J37: =IF(L37>0,L37,0) -> 0 | K37: =I37+J37 -> 308.76753 | L37: =F37-(I37-W37) -> 0 | M37: 5.24 | N37: 0 | O37: =M37-N37 -> 5.24 | P37: 0 | Q37: 0 | R37: =SUM(O37:Q37) -> 5.24 | T37: 0 | U37: 29.7 | V37: =V36-U37 -> 10976.233 | W37: =R37+T37+N37+U37 -> 34.94 | X37: =IF(L37<0,L37*-1,0) -> 0 | Y37: =W37+X37 -> 34.94 | Z37: 0.62 | AA37: 78 | AB37: 45 | AC37: =AC36+1 -> 28 | AD37: 4723 | AE37: 3836 | AF37: 2362.83
AA38: 73
A39: MONTH / CFS | F39: =SUM(F10:F37) -> 2033.2829 | G39: =SUM(G10:G37) -> 2997.2229 | H39: =SUM(H10:H37) -> 0 | I39: =SUM(I10:I37) -> 2997.2229 | J39: =SUM(J10:J37) -> 6.9 | K39: =SUM(K10:K37) -> 3004.1229 | L39: =SUM(L10:L37) -> -0.84 | M39: =SUM(M10:M37) -> 131.2 | ... R39: =SUM(R10:R37) -> 131.2 | T39: =SUM(T10:T37) -> 0 | U39: =SUM(U10:U37) -> 831.9 | W39: =SUM(W10:W37) -> 963.1 | X39: =SUM(X10:X37) -> 7.74 | Y39: =SUM(Y10:Y37) -> 970.84 | Z39: =SUM(Z10:Z37) -> 1.09 | AA39: =AVERAGE(AA10:AA37) -> 70.392857 | AB39: =AVERAGE(AB10:AB37) -> 39.607143
A40: MONTH / AF | D40: =SUM(D10:D37) -> 4032 | F40: =F39*$D$2 -> 4032 | G40: =G39*$D$2 -> 5943.493 | H40: =H39*$D$2 -> 0 | I40: =I39*$D$2 -> 5943.493 | J40: =J39*$D$2 -> 13.6827 | K40: =K39*$D$2 -> 5957.1757 | L40: =L39*$D$2 -> -1.66572 | M40: =M39*$D$2 -> 260.1696 | ... R40: =R39*$D$2 -> 260.1696 | T40: =T39*$D$2 -> 0 | U40: =U39*$D$2 -> 1649.6577 | V40: =V39*$D$2 -> 0 | W40: =W39*$D$2 -> 1909.8273 | X40: =X39*$D$2 -> 15.34842 | Y40: =Y39*$D$2 -> 1925.1757 | AA40: =MAX(AA10:AA37) -> 80 | AB40: =MAX(AB10:AB37) -> 48 | AC40: HI
A42: SEASON / CFS | AA42: =MIN(AA10:AA37) -> 54 | AB42: =MIN(AB10:AB37) -> 30 | AC42: LO
A43: SEASON / AF
A45: YTD / CFS | F45: =F8+F39 -> 3868.8855 | G45: =G8+G39 -> 8707.9726 | H45: =H8+H39 -> 0 | I45: =I8+I39 -> 8707.8726 | J45: =J8+J39 -> 548.25062 | K45: =K8+K39 -> 9256.1232 | L45: =L8+L39 -> 402.76293 | M45: =M8+M39 -> 622.07 | ... R45: =R8+R39 -> 1178.43 | T45: =T8+T39 -> 0 | U45: =U8+U39 -> 3939.32 | V45: =V37 -> 10976.233 | W45: =W8+W39 -> 5241.75 | X45: =X8+X39 -> 145.48768 | Y45: =Y8+Y39 -> 5387.2377 | Z45: =Z8+Z39 -> 7.36
A46: YTD / AF | D46: =D8+D40 -> 7672 | E46: =E37 -> 122235 | F46: =F45*$D$2 -> 7672 | G46: =G45*$D$2 -> 17267.91 | H46: =H45*$D$2 -> 0 | I46: =I45*$D$2 -> 17267.711 | J46: =J45*$D$2 -> 1087.181 | K46: =K45*$D$2 -> 18354.892 | L46: =L45*$D$2 -> 798.6789 | M46: =M45*$D$2 -> 1233.5648 | ... Y46: =Y45*$D$2 -> 10682.892
A48: ="JUN /9" -> JUN /9
B49: 6924.15 | C49: 381833 | E49: =C49-152000 -> 229833
A50: ="5/12/94 thru 6/9/94" -> 5/12/94 thru 6/9/94
B51: =B49-B21 -> 27.6 | D51: =C49-C22 -> 110805

Sheet MAR
K1: MC PHEE RESERVOIR IN/OUT FLOW TABULATION
A2: AF/cfs CONVERT FACTOR | D2: 1.983 | K2: MARCH "95"
A4: DATE | B4: RESERV | C4: RESERV | D4: AC FT | E4: ACTIVE | F4: CONV TO | G4: DOLORES | H4: LOST | I4: RECORDED | J4: CALC | K4: TOTAL | L4: CALC | M4: DOLORES TUNNEL | P4: LONE | Q4: U | R4: TOTAL | S4: MVI | T4: DV CR | U4: BELOW | V4: REMAIN | W4: RECORDED | X4: CALC | Y4: TOTAL | Z4: RAIN | AA4: MAX | AB4: MIN | AC4: DATE
A5: MAR | B5: ELEV | C5: AC FT | D5: CHANGE | E5: CAP | F5: CFS | G5: RIVER | H5: CANYON | I5: INFLOW | J5: INFLOW | K5: INFLOW | L5: INF/OTF | M5: TOT DIV | N5: UTE F&R | O5: MVI,CTZ | P5: PINE | Q5: LATERAL | R5: MVI | S5: CALL | T5: CANAL | U5: MC PHEE | V5: RELEASE | W5: OUTFLOW | X5: OUTFLOW | Y5: OUTFLOW | AA5: TMP | AB5: TMP | AC5: MAR
AD6: 741 | AE6: 742
A7: SEASON BAL
A8: YTD | B8: {=FEB!$B$37:$C$37} -> 6897.44 | C8: 274235 | D8: {=FEB!$D$46:$E$46} -> 7672 | E8: 122235 | F8: {=FEB!$F$45:$Z$45} -> 3868.8855 | G8: 8707.9726 | H8: 0 | I8: 8707.8726 | J8: 548.25062 | K8: 9256.1232 | L8: 402.76293 | M8: 622.07 | N8: 0 | O8: 417.57 | P8: 680.36 | Q8: 0 | R8: 1178.43 | S8: 0 | T8: 0 | U8: 3939.32 | V8: 10976.233 | W8: 5241.75 | X8: 145.48768 | Y8: 5387.2377 | Z8: 7.36 | AD8: 285 | AE8: 251 | AF8: 1207.63
A10: 1 | B10: 6897.63 | C10: 274922 | D10: =C10-C8 -> 687 | E10: =C10-152000 -> 122922 | F10: =D10/$D$2 -> 346.44478 | G10: 120.21 | H10: 10.26 | I10: =G10+H10 -> 130.47 | J10: =IF(L10>0,L10,0) -> 257.87478 | K10: =I10+J10 -> 388.34478 | L10: =F10-(I10-W10) -> 257.87478 | M10: 4.9 | N10: 0 | O10: =M10-N10 -> 4.9 | P10: 0 | Q10: 0 | R10: =SUM(O10:Q10) -> 4.9 | T10: 0 | U10: 37 | V10: =V8-U10 -> 10939.233 | W10: =R10+T10+N10+U10 -> 41.9 | X10: =IF(L10<0,L10*-1,0) -> 0 | Y10: =W10+X10 -> 41.9 | Z10: 1.23 | AA10: 39 | AB10: 36 | AC10: 1 | AD10: 303 | AE10: 273 | AF10: 1256.86
A11: =A10+1 -> 2 | B11: 6897.75 | C11: 275356 | D11: =C11-C10 -> 434 | E11: =C11-152000 -> 123356 | F11: =D11/$D$2 -> 218.86031 | G11: 125.27 | H11: 10.64 | I11: =G11+H11 -> 135.91 | J11: =IF(L11>0,L11,0) -> 126.14031 | K11: =I11+J11 -> 262.05031 | L11: =F11-(I11-W11) -> 126.14031 | M11: 4.01 | N11: 0 | O11: =M11-N11 -> 4.01 | P11: 0 | Q11: 0 | R11: =SUM(O11:Q11) -> 4.01 | T11: 0 | U11: 39.18 | V11: =V10-U11 -> 10900.053 | W11: =R11+T11+N11+U11 -> 43.19 | X11: =IF(L11<0,L11*-1,0) -> 0 | Y11: =W11+X11 -> 43.19 | Z11: 0.32 | AA11: 45 | AB11: 34 | AC11: =AC10+1 -> 2 | AD11: 306 | AE11: 300 | AF11: 1306.42
A12: =A11+1 -> 3 | B12: 6897.88 | C12: 275827 | D12: =C12-C11 -> 471 | E12: =C12-152000 -> 123827 | F12: =D12/$D$2 -> 237.51891 | G12: 113.48 | H12: 10.59 | I12: =G12+H12 -> 124.07 | J12: =IF(L12>0,L12,0) -> 156.10891 | K12: =I12+J12 -> 280.17891 | L12: =F12-(I12-W12) -> 156.10891 | M12: 3.72 | N12: 0 | O12: =M12-N12 -> 3.72 | P12: 0 | Q12: 0 | R12: =SUM(O12:Q12) -> 3.72 | T12: 0 | U12: 38.94 | V12: =V11-U12 -> 10861.113 | W12: =R12+T12+N12+U12 -> 42.66 | X12: =IF(L12<0,L12*-1,0) -> 0 | Y12: =W12+X12 -> 42.66 | Z12: 0 | AA12: 43 | AB12: 35 | AC12: =AC11+1 -> 3 | AD12: 316 | AE12: 341 | AF12: 1355.74
A13: =A12+1 -> 4 | B13: 6897.98 | C13: 276188 | D13: =C13-C12 -> 361 | E13: =C13-152000 -> 124188 | F13: =D13/$D$2 -> 182.0474 | G13: 111.8 | H13: 11.85 | I13: =G13+H13 -> 123.65 | J13: =IF(L13>0,L13,0) -> 101.3574 | K13: =I13+J13 -> 225.0074 | L13: =F13-(I13-W13) -> 101.3574 | M13: 3.72 | N13: 0 | O13: =M13-N13 -> 3.72 | P13: 0 | Q13: 0 | R13: =SUM(O13:Q13) -> 3.72 | T13: 0 | U13: 39.24 | V13: =V12-U13 -> 10821.873 | W13: =R13+T13+N13+U13 -> 42.96 | X13: =IF(L13<0,L13*-1,0) -> 0 | Y13: =W13+X13 -> 42.96 | Z13: 0.28 | AA13: 44 | AB13: 34 | AC13: =AC12+1 -> 4 | AD13: 316 | AE13: 395 | AF13: 1405.31
