Workbook

Sheet NOV
K1: MC PHEE RESERVOIR IN/OUT FLOW TABULATION
A2: AF/cfs CONVERT FACTOR | D2: 1.9835 | L2: NOVEMBER "92"
A4: DATE | B4: RESERV | C4: RESERV | D4: AC FT | E4: ACTIVE | F4: CONV TO | G4: DOLORES | H4: LOST | I4: RECORDED | J4: CALC | K4: TOTAL | L4: CALC | M4: DOLORES | N4: MVI | O4: U | P4: TOTAL | Q4: MVI | R4: DV CR | S4: UTE | T4: BELOW | U4: REMAIN | V4: RECORDED | W4: CALC | X4: TOTAL | Y4: RAIN | Z4: MAX | AA4: MIN | AB4: DATE
A5: "NOV" | B5: ELEV | C5: AC FT | D5: CHANGE | E5: CAP | F5: CFS | G5: RIVER | H5: CANYON | I5: INFLOW | J5: INFLOW | K5: INFLOW | L5: INF/OTF | M5: TUNNEL | N5: DIVER | O5: LATERAL | P5: MVI | Q5: CALL | R5: CANAL | S5: F & R | T5: MC PHEE | U5: RELEASE | V5: OUTFLOW | W5: OUTFLOW | X5: OUTFLOW | Z5: TMP | AA5: TMP | AB5: "NOV"
A7: SEASON BAL
A8: YTD | B8: 6905.41 | C8: 303977 | U8: 15297
A10: 1 | B10: 6905.51 | C10: 304361 | D10: =C10-C8 -> 384 | E10: =C10-152000 -> 152361 | F10: =D10/$D$2 -> 193.59718 | G10: 116.1 | H10: 0 | I10: =G10+H10 -> 116.1 | J10: =IF(L10>0,L10,0) -> 153.39718 | K10: =I10+J10 -> 269.49718 | L10: =F10-(I10-V10) -> 153.39718 | M10: 26.2 | N10: 0 | O10: 10.8 | P10: =SUM(M10:O10) -> 37 | Q10: 0 | R10: 0 | S10: 0 | T10: 38.9 | U10: =U8-T10 -> 15258.1 | V10: =P10+R10+S10+T10 -> 75.9 | W10: =IF(L10<0,L10*-1,0) -> 0 | X10: =V10+W10 -> 75.9 | Y10: 0 | Z10: 58 | AA10: 27 | AB10: 1
A11: =A10+1 -> 2 | B11: 6905.52 | C11: 304401 | D11: =C11-C10 -> 40 | E11: =C11-152000 -> 152401 | F11: =D11/$D$2 -> 20.166373 | G11: 96.1 | H11: 0 | I11: =G11+H11 -> 96.1 | J11: =IF(L11>0,L11,0) -> 0 | K11: =I11+J11 -> 96.1 | L11: =F11-(I11-V11) -> -3.1336274 | M11: 23.4 | N11: 0 | O11: 10.6 | P11: =SUM(M11:O11) -> 34 | Q11: 0 | R11: 0 | S11: 0 | T11: 38.8 | U11: =U10-T11 -> 15219.3 | V11: =P11+R11+S11+T11 -> 72.8 | W11: =IF(L11<0,L11*-1,0) -> 3.1336274 | X11: =V11+W11 -> 75.933627 | Y11: 0 | Z11: 30 | AA11: 26 | AB11: =AB10+1 -> 2
A12: =A11+1 -> 3 | B12: 6905.51 | C12: 304361 | D12: =C12-C11 -> -40 | E12: =C12-152000 -> 152361 | F12: =D12/$D$2 -> -20.166373 | G12: 84.7 | H12: 0 | I12: =G12+H12 -> 84.7 | J12: =IF(L12>0,L12,0) -> 0 | K12: =I12+J12 -> 84.7 | L12: =F12-(I12-V12) -> -35.066373 | M12: 21.3 | N12: 0 | O12: 9.7 | P12: =SUM(M12:O12) -> 31 | Q12: 0 | R12: 0 | S12: 0 | T12: 38.8 | U12: =U11-T12 -> 15180.5 | V12: =P12+R12+S12+T12 -> 69.8 | W12: =IF(L12<0,L12*-1,0) -> 35.066373 | X12: =V12+W12 -> 104.86637 | Y12: 0 | Z12: 46 | AA12: 24 | AB12: =AB11+1 -> 3
A13: =A12+1 -> 4 | B13: 6905.49 | C13: 304286 | D13: =C13-C12 -> -75 | E13: =C13-152000 -> 152286 | F13: =D13/$D$2 -> -37.811949 | G13: 66.6 | H13: 0 | I13: =G13+H13 -> 66.6 | J13: =IF(L13>0,L13,0) -> 0 | K13: =I13+J13 -> 66.6 | L13: =F13-(I13-V13) -> -34.611949 | M13: 20.9 | N13: 0 | O13: 10.1 | P13: =SUM(M13:O13) -> 31 | Q13: 0 | R13: 0 | S13: 0 | T13: 38.8 | U13: =U12-T13 -> 15141.7 | V13: =P13+R13+S13+T13 -> 69.8 | W13: =IF(L13<0,L13*-1,0) -> 34.611949 | X13: =V13+W13 -> 104.41195 | Y13: 0 | Z13: 42 | AA13: 18 | AB13: =AB12+1 -> 4
A14: =A13+1 -> 5 | B14: 6905.46 | C14: 304169 | D14: =C14-C13 -> -117 | E14: =C14-152000 -> 152169 | F14: =D14/$D$2 -> -58.98664 | G14: 69.4 | H14: 0 | I14: =G14+H14 -> 69.4 | J14: =IF(L14>0,L14,0) -> 0 | K14: =I14+J14 -> 69.4 | L14: =F14-(I14-V14) -> -59.58664 | M14: 20.7 | N14: 0 | O14: 9.3 | P14: =SUM(M14:O14) -> 30 | Q14: 0 | R14: 0 | S14: 0 | T14: 38.8 | U14: =U13-T14 -> 15102.9 | V14: =P14+R14+S14+T14 -> 68.8 | W14: =IF(L14<0,L14*-1,0) -> 59.58664 | X14: =V14+W14 -> 128.38664 | Y14: 0 | Z14: 44 | AA14: 19 | AB14: =AB13+1 -> 5
A15: =A14+1 -> 6 | B15: 6905.46 | C15: 304169 | D15: =C15-C14 -> 0 | E15: =C15-152000 -> 152169 | F15: =D15/$D$2 -> 0 | G15: 73.3 | H15: 0 | I15: =G15+H15 -> 73.3 | J15: =IF(L15>0,L15,0) -> 0 | K15: =I15+J15 -> 73.3 | L15: =F15-(I15-V15) -> -4.7 | M15: 20.5 | N15: 0 | O15: 9.5 | P15: =SUM(M15:O15) -> 30 | Q15: 0 | R15: 0 | S15: 0 | T15: 38.6 | U15: =U14-T15 -> 15064.3 | V15: =P15+R15+S15+T15 -> 68.6 | W15: =IF(L15<0,L15*-1,0) -> 4.7 | X15: =V15+W15 -> 73.3 | Y15: 0 | Z15: 47 | AA15: 21 | AB15: =AB14+1 -> 6
A16: =A15+1 -> 7 | B16: 6905.46 | C16: 304169 | D16: =C16-C15 -> 0 | E16: =C16-152000 -> 152169 | F16: =D16/$D$2 -> 0 | G16: 75.9 | H16: 0 | I16: =G16+H16 -> 75.9 | J16: =IF(L16>0,L16,0) -> 0 | K16: =I16+J16 -> 75.9 | L16: =F16-(I16-V16) -> -7.3 | M16: 20.5 | N16: 0 | O16: 9.5 | P16: =SUM(M16:O16) -> 30 | Q16: 0 | R16: 0 | S16: 0 | T16: 38.6 | U16: =U15-T16 -> 15025.7 | V16: =P16+R16+S16+T16 -> 68.6 | W16: =IF(L16<0,L16*-1,0) -> 7.3 | X16: =V16+W16 -> 75.9 | Y16: 0 | Z16: 53 | AA16: 24 | AB16: =AB15+1 -> 7
A17: =A16+1 -> 8 | B17: 6905.44 | C17: 304092 | D17: =C17-C16 -> -77 | E17: =C17-152000 -> 152092 | F17: =D17/$D$2 -> -38.820267 | G17: 79.4 | H17: 0 | I17: =G17+H17 -> 79.4 | J17: =IF(L17>0,L17,0) -> 0 | K17: =I17+J17 -> 79.4 | L17: =F17-(I17-V17) -> -49.720267 | M17: 20.7 | N17: 0 | O17: 9.3 | P17: =SUM(M17:O17) -> 30 | Q17: 0 | R17: 0 | S17: 0 | T17: 38.5 | U17: =U16-T17 -> 14987.2 | V17: =P17+R17+S17+T17 -> 68.5 | W17: =IF(L17<0,L17*-1,0) -> 49.720267 | X17: =V17+W17 -> 118.22027 | Y17: 0 | Z17: 56 | AA17: 33 | AB17: =AB16+1 -> 8
A18: =A17+1 -> 9 | B18: 6905.42 | C18: 304015 | D18: =C18-C17 -> -77 | E18: =C18-152000 -> 152015 | F18: =D18/$D$2 -> -38.820267 | G18: 90 | H18: 0 | I18: =G18+H18 -> 90 | J18: =IF(L18>0,L18,0) -> 0 | K18: =I18+J18 -> 90 | L18: =F18-(I18-V18) -> -56.920267 | M18: 20.7 | N18: 0 | O18: 9.3 | P18: =SUM(M18:O18) -> 30 | Q18: 0 | R18: 0 | S18: 0 | T18: 41.9 | U18: =U17-T18 -> 14945.3 | V18: =P18+R18+S18+T18 -> 71.9 | W18: =IF(L18<0,L18*-1,0) -> 56.920267 | X18: =V18+W18 -> 128.82027 | Y18: 0 | Z18: 50 | AA18: 30 | AB18: =AB17+1 -> 9
A19: =A18+1 -> 10 | B19: 6905.46 | C19: 304169 | D19: =C19-C18 -> 154 | E19: =C19-152000 -> 152169 | F19: =D19/$D$2 -> 77.640534 | G19: 80.4 | H19: 0 | I19: =G19+H19 -> 80.4 | J19: =IF(L19>0,L19,0) -> 66.140534 | K19: =I19+J19 -> 146.54053 | L19: =F19-(I19-V19) -> 66.140534 | M19: 20.9 | N19: 0 | O19: 9.1 | P19: =SUM(M19:O19) -> 30 | Q19: 0 | R19: 0 | S19: 0 | T19: 38.9 | U19: =U18-T19 -> 14906.4 | V19: =P19+R19+S19+T19 -> 68.9 | W19: =IF(L19<0,L19*-1,0) -> 0 | X19: =V19+W19 -> 68.9 | Y19: 0.32 | Z19: 45 | AA19: 20 | AB19: =AB18+1 -> 10
A20: =A19+1 -> 11 | B20: 6905.45 | C20: 304132 | D20: =C20-C19 -> -37 | E20: =C20-152000 -> 152132 | F20: =D20/$D$2 -> -18.653895 | G20: 79.5 | H20: 0 | I20: =G20+H20 -> 79.5 | J20: =IF(L20>0,L20,0) -> 0 | K20: =I20+J20 -> 79.5 | L20: =F20-(I20-V20) -> -29.153895 | M20: 20.7 | N20: 0 | O20: 9.3 | P20: =SUM(M20:O20) -> 30 | Q20: 0 | R20: 0 | S20: 0 | T20: 39 | U20: =U19-T20 -> 14867.4 | V20: =P20+R20+S20+T20 -> 69 | W20: =IF(L20<0,L20*-1,0) -> 29.153895 | X20: =V20+W20 -> 98.153895 | Y20: 0 | Z20: 37 | AA20: 20 | AB20: =AB19+1 -> 11
A21: =A20+1 -> 12 | B21: 6905.44 | C21: 304092 | D21: =C21-C20 -> -40 | E21: =C21-152000 -> 152092 | F21: =D21/$D$2 -> -20.166373 | G21: 66.6 | H21: 0 | I21: =G21+H21 -> 66.6 | J21: =IF(L21>0,L21,0) -> 0 | K21: =I21+J21 -> 66.6 | L21: =F21-(I21-V21) -> -17.766373 | M21: 20.1 | N21: 0 | O21: 9.9 | P21: =SUM(M21:O21) -> 30 | Q21: 0 | R21: 0 | S21: 0 | T21: 39 | U21: =U20-T21 -> 14828.4 | V21: =P21+R21+S21+T21 -> 69 | W21: =IF(L21<0,L21*-1,0) -> 17.766373 | X21: =V21+W21 -> 86.766373 | Y21: 0 | Z21: 44 | AA21: 16 | AB21: =AB20+1 -> 12
A22: =A21+1 -> 13 | B22: 6905.44 | C22: 304092 | D22: =C22-C21 -> 0 | E22: =C22-152000 -> 152092 | F22: =D22/$D$2 -> 0 | G22: 70.4 | H22: 0 | I22: =G22+H22 -> 70.4 | J22: =IF(L22>0,L22,0) -> 2.9 | K22: =I22+J22 -> 73.3 | L22: =F22-(I22-V22) -> 2.9 | M22: 25 | N22: 0 | O22: 9 | P22: =SUM(M22:O22) -> 34 | Q22: 0 | R22: 0 | S22: 0 | T22: 39.3 | U22: =U21-T22 -> 14789.1 | V22: =P22+R22+S22+T22 -> 73.3 | W22: =IF(L22<0,L22*-1,0) -> 0 | X22: =V22+W22 -> 73.3 | Y22: 0 | Z22: 49 | AA22: 16 | AB22: =AB21+1 -> 13
... A38: =A37+1 -> 29 | B38: 6905.36 | C38: 303783 | D38: =C38-C37 -> 0 | E38: =C38-152000 -> 151783 | F38: =D38/$D$2 -> 0 | G38: 99 | H38: 0 | I38: =G38+H38 -> 99 | J38: =IF(L38>0,L38,0) -> 0 | K38: =I38+J38 -> 99 | L38: =F38-(I38-V38) -> -60.3 | M38: 5.7 | N38: 0 | O38: 0 | P38: =SUM(M38:O38) -> 5.7 | Q38: 0 | R38: 0 | S38: 0 | T38: 33 | U38: =U37-T38 -> 14191.7 | V38: =P38+R38+S38+T38 -> 38.7 | W38: =IF(L38<0,L38*-1,0) -> 60.3 | X38: =V38+W38 -> 99 | Y38: 0 | Z38: 34 | AA38: 4 | AB38: =AB37+1 -> 29
A39: 30 | B39: 6905.35 | C39: 303746 | D39: =C39-C38 -> -37 | E39: =C39-152000 -> 151746 | F39: =D39/$D$2 -> -18.653895 | G39: 103.7 | H39: 0 | I39: =G39+H39 -> 103.7 | J39: =IF(L39>0,L39,0) -> 0 | K39: =I39+J39 -> 103.7 | L39: =F39-(I39-V39) -> -85.153895 | M39: 3.8 | N39: 0 | O39: 0 | P39: =SUM(M39:O39) -> 3.8 | Q39: 0 | R39: 0 | S39: 0 | T39: 33.4 | U39: =U38-T39 -> 14158.3 | V39: =P39+R39+S39+T39 -> 37.2 | W39: =IF(L39<0,L39*-1,0) -> 85.153895 | X39: =V39+W39 -> 122.35389 | Y39: 0 | Z39: 36 | AA39: 2 | AB39: 30
Z40: 73
A41: MONTH / CFS | F41: =SUM(F10:F39) -> -116.4608 | G41: =SUM(G10:G39) -> 2415.2 | H41: =SUM(H10:H39) -> 0 | I41: =SUM(I10:I39) -> 2415.2 | J41: =SUM(J10:J39) -> 225.83771 | K41: =SUM(K10:K39) -> 2641.0377 | L41: =SUM(L10:L39) -> -673.9608 | M41: =SUM(M10:M39) -> 540.3 | ... P41: =SUM(P10:P39) -> 719 | R41: =SUM(R10:R39) -> 0 | S41: =SUM(S10:S39) -> 0 | T41: =SUM(T10:T39) -> 1138.7 | V41: =SUM(V10:V39) -> 1857.7 | W41: =SUM(W10:W39) -> 899.79851 | X41: =SUM(X10:X39) -> 2757.4985 | Y41: =SUM(Y10:Y39) -> 0.47 | Z41: =AVERAGE(Z10:Z39) -> 43.066667 | AA41: =AVERAGE(AA10:AA39) -> 17.766667
A42: MONTH / AF | D42: =SUM(D10:D39) -> -231 | F42: =F41*$D$2 -> -231 | G42: =G41*$D$2 -> 4790.5492 | H42: =H41*$D$2 -> 0 | I42: =I41*$D$2 -> 4790.5492 | J42: =J41*$D$2 -> 447.9491 | K42: =K41*$D$2 -> 5238.4983 | L42: =L41*$D$2 -> -1336.8012 | M42: =M41*$D$2 -> 1071.6851 | ... P42: =P41*$D$2 -> 1426.1365 | R42: =R41*$D$2 -> 0 | S42: =S41*$D$2 -> 0 | T42: =T41*$D$2 -> 2258.6114 | V42: =V41*$D$2 -> 3684.7479 | W42: =W41*$D$2 -> 1784.7504 | X42: =X41*$D$2 -> 5469.4983 | Z42: 82 | AA42: 54 | AB42: HI
A44: SEASON / CFS | Z44: 59 | AA44: 32 | AB44: LO
A45: SEASON / AF
A47: YTD / CFS | F47: =F8+F41 -> -116.4608 | G47: =G8+G41 -> 2415.2 | H47: =H8+H41 -> 0 | I47: =I8+I41 -> 2415.2 | J47: =J8+J41 -> 225.83771 | K47: =K8+K41 -> 2641.0377 | L47: =L8+L41 -> -673.9608 | M47: =M8+M41 -> 540.3 | ... P47: =P8+P41 -> 719 | R47: =R8+R41 -> 0 | S47: =S8+S41 -> 0 | T47: =T8+T41 -> 1138.7 | U47: =U39 -> 14158.3 | V47: =V8+V41 -> 1857.7 | W47: =W8+W41 -> 899.79851 | X47: =X8+X41 -> 2757.4985 | Y47: =Y8+Y41 -> 0.47
A48: YTD / AF | D48: =D8+D42 -> -231 | E48: =E39 -> 151746 | F48: =F47*$D$2 -> -231 | G48: =G47*$D$2 -> 4790.5492 | H48: =H47*$D$2 -> 0 | I48: =I47*$D$2 -> 4790.5492 | J48: =J47*$D$2 -> 447.9491 | K48: =K47*$D$2 -> 5238.4983 | L48: =L47*$D$2 -> -1336.8012 | M48: =M47*$D$2 -> 1071.6851 | ... X48: =X47*$D$2 -> 5469.4983

Sheet DEC
K1: MC PHEE RESERVOIR IN/OUT FLOW TABULATION
A2: AF/cfs CONVERT FACTOR | D2: 1.9835 | L2: DECEMBER "92"
A4: DATE | B4: RESERV | C4: RESERV | D4: AC FT | E4: ACTIVE | F4: CONV TO | G4: DOLORES | H4: LOST | I4: RECORDED | J4: CALC | K4: TOTAL | L4: CALC | M4: DOLORES | N4: MVI | O4: U | P4: TOTAL | Q4: MVI | R4: DV CR | S4: UTE | T4: BELOW | U4: REMAIN | V4: RECORDED | W4: CALC | X4: TOTAL | Y4: RAIN | Z4: MAX | AA4: MIN | AB4: DATE
A5: 'DEC'' | B5: ELEV | C5: AC FT | D5: CHANGE | E5: CAP | F5: CFS | G5: RIVER | H5: CANYON | I5: INFLOW | J5: INFLOW | K5: INFLOW | L5: INF/OTF | M5: TUNNEL | N5: DIVER | O5: LATERAL | P5: MVI | Q5: CALL | R5: CANAL | S5: F & R | T5: MC PHEE | U5: RELEASE | V5: OUTFLOW | W5: OUTFLOW | X5: OUTFLOW | Z5: TMP | AA5: TMP | AB5: 'DEC''
A7: SEASON BAL
A8: YTD | B8: =[1]NOV!B39 -> 6905.35 | C8: =[1]NOV!C39 -> 303746 | D8: =[1]NOV!$D$48 -> -231 | E8: =[1]NOV!$E$39 -> 151746 | F8: {=[1]NOV!$F$47:$Y$47} -> -116.4608 | G8: 2415.2 | H8: 0 | I8: 2415.2 | J8: 225.83771 | K8: 2641.0377 | L8: -673.9608 | M8: 540.3 | N8: 0 | O8: 178.7 | P8: 719 | Q8: 0 | R8: 0 | S8: 0 | T8: 1138.7 | U8: 14158.3 | V8: 1857.7 | W8: 899.79851 | X8: 2757.4985 | Y8: 0.47
M9: 4
A10: 1 | B10: 6905.35 | C10: 303746 | D10: =C10-C8 -> 0 | E10: =C10-152000 -> 151746 | F10: =D10/$D$2 -> 0 | G10: 37.9 | H10: 0 | I10: =G10+H10 -> 37.9 | J10: =IF(L10>0,L10,0) -> 0 | K10: =I10+J10 -> 37.9 | L10: =F10-(I10-V10) -> 0 | M10: 3.7 | N10: 0 | O10: 0 | P10: =SUM(M10:O10) -> 3.7 | Q10: 0 | R10: 0 | S10: 0 | T10: 34.2 | U10: =U8-T10 -> 14124.1 | V10: =P10+R10+S10+T10 -> 37.9 | W10: =IF(L10<0,L10*-1,0) -> 0 | X10: =V10+W10 -> 37.9 | Y10: 0 | Z10: 48 | AA10: 7 | AB10: 1
A11: =A10+1 -> 2 | B11: 6905.36 | C11: 303783 | D11: =C11-C10 -> 37 | E11: =C11-152000 -> 151783 | F11: =D11/$D$2 -> 18.653895 | G11: 56.5 | H11: 0 | I11: =G11+H11 -> 56.5 | J11: =IF(L11>0,L11,0) -> 0.053894631 | K11: =I11+J11 -> 56.553895 | L11: =F11-(I11-V11) -> 0.053894631 | M11: 3.7 | N11: 0 | O11: 0 | P11: =SUM(M11:O11) -> 3.7 | Q11: 0 | R11: 0 | S11: 0 | T11: 34.2 | U11: =U10-T11 -> 14089.9 | V11: =P11+R11+S11+T11 -> 37.9 | W11: =IF(L11<0,L11*-1,0) -> 0 | X11: =V11+W11 -> 37.9 | Y11: 0 | Z11: 46 | AA11: 8 | AB11: =AB10+1 -> 2
A12: =A11+1 -> 3 | B12: 6905.36 | C12: 303783 | D12: =C12-C11 -> 0 | E12: =C12-152000 -> 151783 | F12: =D12/$D$2 -> 0 | G12: 38.1 | H12: 0 | I12: =G12+H12 -> 38.1 | J12: =IF(L12>0,L12,0) -> 0 | K12: =I12+J12 -> 38.1 | L12: =F12-(I12-V12) -> 0 | M12: 3.9 | N12: 0 | O12: 0 | P12: =SUM(M12:O12) -> 3.9 | Q12: 0 | R12: 0 | S12: 0 | T12: 34.2 | U12: =U11-T12 -> 14055.7 | V12: =P12+R12+S12+T12 -> 38.1 | W12: =IF(L12<0,L12*-1,0) -> 0 | X12: =V12+W12 -> 38.1 | Y12: 0 | Z12: 43 | AA12: 26 | AB12: =AB11+1 -> 3
A13: =A12+1 -> 4 | B13: 6905.37 | C13: 303823 | D13: =C13-C12 -> 40 | E13: =C13-152000 -> 151823 | F13: =D13/$D$2 -> 20.166373 | G13: 58.4 | H13: 0 | I13: =G13+H13 -> 58.4 | J13: =IF(L13>0,L13,0) -> 0.066372574 | K13: =I13+J13 -> 58.466373 | L13: =F13-(I13-V13) -> 0.066372574 | M13: 4.1 | N13: 0 | O13: 0 | P13: =SUM(M13:O13) -> 4.1 | Q13: 0 | R13: 0 | S13: 0 | T13: 34.2 | U13: =U12-T13 -> 14021.5 | V13: =P13+R13+S13+T13 -> 38.3 | W13: =IF(L13<0,L13*-1,0) -> 0 | X13: =V13+W13 -> 38.3 | Y13: 0.14 | Z13: 39 | AA13: 24 | AB13: =AB12+1 -> 4
A14: =A13+1 -> 5 | B14: 6905.37 | C14: 303823 | D14: =C14-C13 -> 0 | E14: =C14-152000 -> 151823 | F14: =D14/$D$2 -> 0 | G14: 38.2 | H14: 0 | I14: =G14+H14 -> 38.2 | J14: =IF(L14>0,L14,0) -> 0.1 | K14: =I14+J14 -> 38.3 | L14: =F14-(I14-V14) -> 0.1 | M14: 4.1 | N14: 0 | O14: 0 | P14: =SUM(M14:O14) -> 4.1 | Q14: 0 | R14: 0 | S14: 0 | T14: 34.2 | U14: =U13-T14 -> 13987.3 | V14: =P14+R14+S14+T14 -> 38.3 | W14: =IF(L14<0,L14*-1,0) -> 0 | X14: =V14+W14 -> 38.3 | Y14: 0.3 | Z14: 32 | AA14: 19 | AB14: =AB13+1 -> 5
A15: =A14+1 -> 6 | B15: 6905.38 | C15: 303860 | D15: =C15-C14 -> 37 | E15: =C15-152000 -> 151860 | F15: =D15/$D$2 -> 18.653895 | G15: 56.9 | H15: 0 | I15: =G15+H15 -> 56.9 | J15: =IF(L15>0,L15,0) -> 0.053894631 | K15: =I15+J15 -> 56.953895 | L15: =F15-(I15-V15) -> 0.053894631 | M15: 4.1 | N15: 0 | O15: 0 | P15: =SUM(M15:O15) -> 4.1 | Q15: 0 | R15: 0 | S15: 0 | T15: 34.2 | U15: =U14-T15 -> 13953.1 | V15: =P15+R15+S15+T15 -> 38.3 | W15: =IF(L15<0,L15*-1,0) -> 0 | X15: =V15+W15 -> 38.3 | Y15: 0 | Z15: 34 | AA15: 10 | AB15: =AB14+1 -> 6
A16: =A15+1 -> 7 | B16: 6905.38 | C16: 303860 | D16: =C16-C15 -> 0 | E16: =C16-152000 -> 151860 | F16: =D16/$D$2 -> 0 | G16: 38.1 | H16: 0 | I16: =G16+H16 -> 38.1 | J16: =IF(L16>0,L16,0) -> 0.1 | K16: =I16+J16 -> 38.2 | L16: =F16-(I16-V16) -> 0.1 | M16: 4.1 | N16: 0 | O16: 0 | P16: =SUM(M16:O16) -> 4.1 | Q16: 0 | R16: 0 | S16: 0 | T16: 34.1 | U16: =U15-T16 -> 13919 | V16: =P16+R16+S16+T16 -> 38.2 | W16: =IF(L16<0,L16*-1,0) -> 0 | X16: =V16+W16 -> 38.2 | Y16: 0 | Z16: 35 | AA16: 6 | AB16: =AB15+1 -> 7
A17: =A16+1 -> 8 | B17: 6905.39 | C17: 303900 | D17: =C17-C16 -> 40 | E17: =C17-152000 -> 151900 | F17: =D17/$D$2 -> 20.166373 | G17: 58 | H17: 0 | I17: =G17+H17 -> 58 | J17: =IF(L17>0,L17,0) -> 0 | K17: =I17+J17 -> 58 | L17: =F17-(I17-V17) -> -0.033627426 | M17: 4.1 | N17: 0 | O17: 0 | P17: =SUM(M17:O17) -> 4.1 | Q17: 0 | R17: 0 | S17: 0 | T17: 33.7 | U17: =U16-T17 -> 13885.3 | V17: =P17+R17+S17+T17 -> 37.8 | W17: =IF(L17<0,L17*-1,0) -> 0.033627426 | X17: =V17+W17 -> 37.833627 | Y17: 0.03 | Z17: 36 | AA17: 14 | AB17: =AB16+1 -> 8
A18: =A17+1 -> 9 | B18: 6905.39 | C18: 303900 | D18: =C18-C17 -> 0 | E18: =C18-152000 -> 151900 | F18: =D18/$D$2 -> 0 | G18: 43.3 | H18: 0 | I18: =G18+H18 -> 43.3 | J18: =IF(L18>0,L18,0) -> 0.1 | K18: =I18+J18 -> 43.4 | L18: =F18-(I18-V18) -> 0.1 | M18: 4.1 | N18: 0 | O18: 0 | P18: =SUM(M18:O18) -> 4.1 | Q18: 0 | R18: 0 | S18: 0 | T18: 39.3 | U18: =U17-T18 -> 13846 | V18: =P18+R18+S18+T18 -> 43.4 | W18: =IF(L18<0,L18*-1,0) -> 0 | X18: =V18+W18 -> 43.4 | Y18: 0 | Z18: 36 | AA18: 12 | AB18: =AB17+1 -> 9
A19: =A18+1 -> 10 | B19: 6905.4 | C19: 303938 | D19: =C19-C18 -> 38 | E19: =C19-152000 -> 151938 | F19: =D19/$D$2 -> 19.158054 | G19: 56.6 | H19: 0 | I19: =G19+H19 -> 56.6 | J19: =IF(L19>0,L19,0) -> 0.058053945 | K19: =I19+J19 -> 56.658054 | L19: =F19-(I19-V19) -> 0.058053945 | M19: 4.1 | N19: 0 | O19: 0 | P19: =SUM(M19:O19) -> 4.1 | Q19: 0 | R19: 0 | S19: 0 | T19: 33.4 | U19: =U18-T19 -> 13812.6 | V19: =P19+R19+S19+T19 -> 37.5 | W19: =IF(L19<0,L19*-1,0) -> 0 | X19: =V19+W19 -> 37.5 | Y19: 0 | Z19: 37 | AA19: 17 | AB19: =AB18+1 -> 10
A20: =A19+1 -> 11 | B20: 6905.4 | C20: 303938 | D20: =C20-C19 -> 0 | E20: =C20-152000 -> 151938 | F20: =D20/$D$2 -> 0 | G20: 37.5 | H20: 0 | I20: =G20+H20 -> 37.5 | J20: =IF(L20>0,L20,0) -> 0 | K20: =I20+J20 -> 37.5 | L20: =F20-(I20-V20) -> 0 | M20: 4.1 | N20: 0 | O20: 0 | P20: =SUM(M20:O20) -> 4.1 | Q20: 0 | R20: 0 | S20: 0 | T20: 33.4 | U20: =U19-T20 -> 13779.2 | V20: =P20+R20+S20+T20 -> 37.5 | W20: =IF(L20<0,L20*-1,0) -> 0 | X20: =V20+W20 -> 37.5 | Y20: 0 | Z20: 39 | AA20: 14 | AB20: =AB19+1 -> 11
A21: =A20+1 -> 12 | B21: 6905.41 | C21: 303977 | D21: =C21-C20 -> 39 | E21: =C21-152000 -> 151977 | F21: =D21/$D$2 -> 19.662213 | G21: 57.2 | H21: 0 | I21: =G21+H21 -> 57.2 | J21: =IF(L21>0,L21,0) -> 0 | K21: =I21+J21 -> 57.2 | L21: =F21-(I21-V21) -> -0.037786741 | M21: 4.1 | N21: 0 | O21: 0 | P21: =SUM(M21:O21) -> 4.1 | Q21: 0 | R21: 0 | S21: 0 | T21: 33.4 | U21: =U20-T21 -> 13745.8 | V21: =P21+R21+S21+T21 -> 37.5 | W21: =IF(L21<0,L21*-1,0) -> 0.037786741 | X21: =V21+W21 -> 37.537787 | Y21: 0.25 | Z21: 33 | AA21: 12 | AB21: =AB20+1 -> 12
A22: =A21+1 -> 13 | B22: 6905.41 | C22: 303977 | D22: =C22-C21 -> 0 | E22: =C22-152000 -> 151977 | F22: =D22/$D$2 -> 0 | G22: 37.5 | H22: 0 | I22: =G22+H22 -> 37.5 | J22: =IF(L22>0,L22,0) -> 0 | K22: =I22+J22 -> 37.5 | L22: =F22-(I22-V22) -> 0 | M22: 4.1 | N22: 0 | O22: 0 | P22: =SUM(M22:O22) -> 4.1 | Q22: 0 | R22: 0 | S22: 0 | T22: 33.4 | U22: =U21-T22 -> 13712.4 | V22: =P22+R22+S22+T22 -> 37.5 | W22: =IF(L22<0,L22*-1,0) -> 0 | X22: =V22+W22 -> 37.5 | Y22: 0.09 | Z22: 28 | AA22: 7 | AB22: =AB21+1 -> 13
... A38: =A37+1 -> 29 | B38: 6905.54 | C38: 304478 | D38: =C38-C37 -> 77 | E38: =C38-152000 -> 152478 | F38: =D38/$D$2 -> 38.820267 | G38: 75.5 | H38: 0 | I38: =G38+H38 -> 75.5 | J38: =IF(L38>0,L38,0) -> 0 | K38: =I38+J38 -> 75.5 | L38: =F38-(I38-V38) -> -0.079732796 | M38: 4.4 | N38: 0 | O38: 0 | P38: =SUM(M38:O38) -> 4.4 | Q38: 0 | R38: 0 | S38: 0 | T38: 32.2 | U38: =U37-T38 -> 13190.9 | V38: =P38+R38+S38+T38 -> 36.6 | W38: =IF(L38<0,L38*-1,0) -> 0.079732796 | X38: =V38+W38 -> 36.679733 | Y38: 0 | Z38: 40 | AA38: 30 | AB38: =AB37+1 -> 29
A39: 30 | B39: 6905.56 | C39: 304555 | D39: =C39-C38 -> 77 | E39: =C39-152000 -> 152555 | F39: =D39/$D$2 -> 38.820267 | G39: 75.4 | H39: 0 | I39: =G39+H39 -> 75.4 | J39: =IF(L39>0,L39,0) -> 0.020267204 | K39: =I39+J39 -> 75.420267 | L39: =F39-(I39-V39) -> 0.020267204 | M39: 4.4 | N39: 0 | O39: 0 | P39: =SUM(M39:O39) -> 4.4 | Q39: 0 | R39: 0 | S39: 0 | T39: 32.2 | U39: =U38-T39 -> 13158.7 | V39: =P39+R39+S39+T39 -> 36.6 | W39: =IF(L39<0,L39*-1,0) -> 0 | X39: =V39+W39 -> 36.6 | Y39: 0 | Z39: 42 | AA39: 32 | AB39: 30
A40: 31 | B40: 6905.58 | C40: 304632 | D40: =C40-C39 -> 77 | E40: =C40-152000 -> 152632 | F40: =D40/$D$2 -> 38.820267 | G40: 76 | H40: 0 | I40: =G40+H40 -> 76 | J40: =IF(L40>0,L40,0) -> 0.020267204 | K40: =I40+J40 -> 76.020267 | L40: =F40-(I40-V40) -> 0.020267204 | M40: 4.4 | N40: 0 | O40: 0 | P40: =SUM(M40:O40) -> 4.4 | Q40: 0 | R40: 0 | S40: 0 | T40: 32.8 | U40: =U39-T40 -> 13125.9 | V40: =P40+R40+S40+T40 -> 37.2 | W40: =IF(L40<0,L40*-1,0) -> 0 | X40: =V40+W40 -> 37.2 | Y40: 0 | Z40: 47 | AA40: 20 | AB40: 31
Z41: 73
A42: MONTH / CFS | F42: =SUM(F10:F40) -> 446.68515 | G42: =SUM(G10:G40) -> 1610.2 | H42: =SUM(H10:H40) -> 0 | I42: =SUM(I10:I40) -> 1610.2 | J42: =SUM(J10:J40) -> 0.70496597 | K42: =SUM(K10:K40) -> 1610.905 | L42: =SUM(L10:L40) -> 0.28515251 | M42: =SUM(M10:M40) -> 131.4 | ... P42: =SUM(P10:P40) -> 131.4 | R42: =SUM(R10:R40) -> 0 | S42: =SUM(S10:S40) -> 0 | T42: =SUM(T10:T40) -> 1032.4 | U42: =U40 -> 13125.9 | V42: =SUM(V10:V40) -> 1163.8 | W42: =SUM(W10:W40) -> 0.41981346 | X42: =SUM(X10:X40) -> 1164.2198 | Y42: =SUM(Y10:Y40) -> 2.08 | Z42: =AVERAGE(Z10:Z40) -> 34.870968 | AA42: =AVERAGE(AA10:AA40) -> 10.451613
A43: MONTH / AF | D43: =SUM(D10:D40) -> 886 | F43: =F42*$D$2 -> 886 | G43: =G42*$D$2 -> 3193.8317 | H43: =H42*$D$2 -> 0 | I43: =I42*$D$2 -> 3193.8317 | J43: =J42*$D$2 -> 1.3983 | K43: =K42*$D$2 -> 3195.23 | L43: =L42*$D$2 -> 0.5656 | M43: =M42*$D$2 -> 260.6319 | ... P43: =P42*$D$2 -> 260.6319 | R43: =R42*$D$2 -> 0 | S43: =S42*$D$2 -> 0 | T43: =T42*$D$2 -> 2047.7654 | U43: =U42*$D$2 -> 26035.223 | V43: =V42*$D$2 -> 2308.3973 | W43: =W42*$D$2 -> 0.8327 | X43: =X42*$D$2 -> 2309.23 | Z43: =MAX(Z10:Z40) -> 48 | AA43: =MAX(AA10:AA40) -> 32 | AB43: HI
A45: SEASON / CFS | Z45: =MIN(Z10:Z40) -> 20 | AA45: =MIN(AA10:AA40) -> -10 | AB45: LO
A46: SEASON / AF
A48: YTD / CFS | F48: =F8+F42 -> 330.22435 | G48: =G8+G42 -> 4025.4 | H48: =H8+H42 -> 0 | I48: =I8+I42 -> 4025.4 | J48: =J8+J42 -> 226.54268 | K48: =K8+K42 -> 4251.9427 | L48: =L8+L42 -> -673.67565 | M48: =M8+M42 -> 671.7 | ... P48: =P8+P42 -> 850.4 | R48: =R8+R42 -> 0 | S48: =S8+S42 -> 0 | T48: =T8+T42 -> 2171.1 | U48: =U40 -> 13125.9 | V48: =V8+V42 -> 3021.5 | W48: =W8+W42 -> 900.21833 | X48: =X8+X42 -> 3921.7183 | Y48: =Y8+Y42 -> 2.55
A49: YTD / AF | D49: =D8+D43 -> 655 | E49: =E40 -> 152632 | F49: =F48*$D$2 -> 655 | G49: =G48*$D$2 -> 7984.3809 | H49: =H48*$D$2 -> 0 | I49: =I48*$D$2 -> 7984.3809 | J49: =J48*$D$2 -> 449.3474 | K49: =K48*$D$2 -> 8433.7283 | L49: =L48*$D$2 -> -1336.2357 | M49: =M48*$D$2 -> 1332.3169 | ... T49: =T48*$D$2 -> 4306.3768 | U49: =U40*$D$2 -> 26035.223 | V49: =V48*$D$2 -> 5993.1452 | W49: =W48*$D$2 -> 1785.583 | X49: =X48*$D$2 -> 7778.7283

Sheet JAN
K1: MC PHEE RESERVOIR IN/OUT FLOW TABULATION
A2: AF/cfs CONVERT FACTOR | D2: 1.9835 | K2: JANUARY "1993"
A4: DATE | B4: RESERV | C4: RESERV | D4: AC FT | E4: ACTIVE | F4: CONV TO | G4: DOLORES | H4: LOST | I4: RECORDED | J4: CALC | K4: TOTAL | L4: CALC | M4: DOLORES TUNNEL | Q4: LONE | R4: U | S4: TOTAL | T4: MVI | U4: DV CR | V4: BELOW | W4: REMAIN | X4: RECORDED | Y4: CALC | Z4: TOTAL | AA4: RAIN | AB4: MAX | AC4: MIN | AD4: DATE
A5: "JAN" | B5: ELEV | C5: AC FT | D5: CHANGE | E5: CAP | F5: CFS | G5: RIVER | H5: CANYON | I5: INFLOW | J5: INFLOW | K5: INFLOW | L5: INF/OTF | M5: TOT DIV | N5: WETLAND | O5: UTE F&R | P5: MVI,CTZ | Q5: PINE | R5: LAT | S5: MVI | T5: CALL | U5: CANAL | V5: MC PHEE | W5: RELEASE | X5: OUTFLOW | Y5: OUTFLOW | Z5: OUTFLOW | AB5: TMP | AC5: TMP | AD5: "JAN"
A7: SEASON BAL
A8: YTD | B8: =DEC!B40 -> 6905.58 | C8: =DEC!C40 -> 304632 | D8: =DEC!$D$49 -> 655 | E8: =DEC!$E$40 -> 152632 | F8: =DEC!F48 -> 330.22435 | G8: =DEC!G48 -> 4025.4 | H8: =DEC!H48 -> 0 | I8: =DEC!I48 -> 4025.4 | J8: =DEC!J48 -> 226.54268 | K8: =DEC!K48 -> 4251.9427 | L8: =DEC!L48 -> -673.67565 | M8: =DEC!M48 -> 671.7 | N8: =DEC!N48 -> 0 | O8: 0 | P8: 0 | Q8: =DEC!N48 -> 0 | R8: =DEC!O48 -> 178.7 | S8: =DEC!P48 -> 850.4 | T8: 0 | U8: 0 | V8: =DEC!T48 -> 2171.1 | W8: =DEC!U48 -> 13125.9 | X8: =DEC!V48 -> 3021.5 | Y8: =DEC!W48 -> 900.21833 | Z8: =DEC!X48 -> 3921.7183 | AA8: =DEC!Y48 -> 2.55
G9: 54.6
A10: 1 | B10: 6925.59 | C10: 304670 | D10: =C10-C8 -> 38 | E10: =C10-152000 -> 152670 | F10: =D10/$D$2 -> 19.158054 | G10: 54.1 | H10: 0 | I10: =G10+H10 -> 54.1 | J10: =IF(L10>0,L10,0) -> 0 | K10: =I10+J10 -> 54.1 | L10: =F10-(I10-X10) -> -0.041946055 | M10: 4.4 | N10: 0 | O10: 0 | P10: =M10-(N10+O10) -> 4.4 | Q10: 0 | R10: 0 | S10: =SUM(P10:R10) -> 4.4 | U10: 0 | V10: 30.5 | W10: =W8-V10 -> 13095.4 | X10: =N10+O10+S10+U10+V10 -> 34.9 | Y10: =IF(L10<0,L10*-1,0) -> 0.041946055 | Z10: =X10+Y10 -> 34.941946 | AA10: 0 | AB10: 43 | AC10: 20 | AD10: 1
A11: =A10+1 -> 2 | B11: 6905.6 | C11: 304709 | D11: =C11-C10 -> 39 | E11: =C11-152000 -> 152709 | F11: =D11/$D$2 -> 19.662213 | G11: 54.6 | H11: 0 | I11: =G11+H11 -> 54.6 | J11: =IF(L11>0,L11,0) -> 0.062213259 | K11: =I11+J11 -> 54.662213 | L11: =F11-(I11-X11) -> 0.062213259 | M11: 4.5 | N11: 0 | O11: 0 | P11: =M11-(N11+O11) -> 4.5 | Q11: 0 | R11: 0 | S11: =SUM(P11:R11) -> 4.5 | U11: 0 | V11: 30.5 | W11: =W10-V11 -> 13064.9 | X11: =N11+O11+S11+U11+V11 -> 35 | Y11: =IF(L11<0,L11*-1,0) -> 0 | Z11: =X11+Y11 -> 35 | AA11: 0 | AB11: 42 | AC11: 22 | AD11: =AD10+1 -> 2
A12: =A11+1 -> 3 | B12: 6905.61 | C12: 304747 | D12: =C12-C11 -> 38 | E12: =C12-152000 -> 152747 | F12: =D12/$D$2 -> 19.158054 | G12: 54.1 | H12: 0 | I12: =G12+H12 -> 54.1 | J12: =IF(L12>0,L12,0) -> 0 | K12: =I12+J12 -> 54.1 | L12: =F12-(I12-X12) -> -0.041946055 | M12: 4.4 | N12: 0 | O12: 0 | P12: =M12-(N12+O12) -> 4.4 | Q12: 0 | R12: 0 | S12: =SUM(P12:R12) -> 4.4 | U12: 0 | V12: 30.5 | W12: =W11-V12 -> 13034.4 | X12: =N12+O12+S12+U12+V12 -> 34.9 | Y12: =IF(L12<0,L12*-1,0) -> 0.041946055 | Z12: =X12+Y12 -> 34.941946 | AA12: 0 | AB12: 34 | AC12: 32 | AD12: =AD11+1 -> 3
A13: =A12+1 -> 4 | B13: 6905.62 | C13: 304787 | D13: =C13-C12 -> 40 | E13: =C13-152000 -> 152787 | F13: =D13/$D$2 -> 20.166373 | G13: 56 | H13: 0 | I13: =G13+H13 -> 56 | J13: =IF(L13>0,L13,0) -> 0 | K13: =I13+J13 -> 56 | L13: =F13-(I13-X13) -> -0.033627426 | M13: 4.4 | N13: 0 | O13: 0 | P13: =M13-(N13+O13) -> 4.4 | Q13: 0 | R13: 0 | S13: =SUM(P13:R13) -> 4.4 | U13: 0 | V13: 31.4 | W13: =W12-V13 -> 13003 | X13: =N13+O13+S13+U13+V13 -> 35.8 | Y13: =IF(L13<0,L13*-1,0) -> 0.033627426 | Z13: =X13+Y13 -> 35.833627 | AA13: 0 | AB13: 33 | AC13: 15 | AD13: =AD12+1 -> 4
A14: =A13+1 -> 5 | B14: 6905.64 | C14: 304864 | D14: =C14-C13 -> 77 | E14: =C14-152000 -> 152864 | F14: =D14/$D$2 -> 38.820267 | G14: 73.9 | H14: 0 | I14: =G14+H14 -> 73.9 | J14: =IF(L14>0,L14,0) -> 0.020267204 | K14: =I14+J14 -> 73.920267 | L14: =F14-(I14-X14) -> 0.020267204 | M14: 4.4 | N14: 0 | O14: 0 | P14: =M14-(N14+O14) -> 4.4 | Q14: 0 | R14: 0 | S14: =SUM(P14:R14) -> 4.4 | U14: 0 | V14: 30.7 | W14: =W13-V14 -> 12972.3 | X14: =N14+O14+S14+U14+V14 -> 35.1 | Y14: =IF(L14<0,L14*-1,0) -> 0 | Z14: =X14+Y14 -> 35.1 | AA14: 0.07 | AB14: 31 | AC14: 5 | AD14: =AD13+1 -> 5
A15: =A14+1 -> 6 | B15: 6905.66 | C15: 304941 | D15: =C15-C14 -> 77 | E15: =C15-152000 -> 152941 | F15: =D15/$D$2 -> 38.820267 | G15: 73.8 | H15: 0 | I15: =G15+H15 -> 73.8 | J15: =IF(L15>0,L15,0) -> 0.020267204 | K15: =I15+J15 -> 73.820267 | L15: =F15-(I15-X15) -> 0.020267204 | M15: 4.4 | N15: 0 | O15: 0 | P15: =M15-(N15+O15) -> 4.4 | Q15: 0 | R15: 0 | S15: =SUM(P15:R15) -> 4.4 | U15: 0 | V15: 30.6 | W15: =W14-V15 -> 12941.7 | X15: =N15+O15+S15+U15+V15 -> 35 | Y15: =IF(L15<0,L15*-1,0) -> 0 | Z15: =X15+Y15 -> 35 | AA15: 0.35 | AB15: 34 | AC15: 16 | AD15: =AD14+1 -> 6
A16: =A15+1 -> 7 | B16: 6905.72 | C16: 305172 | D16: =C16-C15 -> 231 | E16: =C16-152000 -> 153172 | F16: =D16/$D$2 -> 116.4608 | G16: 151.6 | H16: 0 | I16: =G16+H16 -> 151.6 | J16: =IF(L16>0,L16,0) -> 0 | K16: =I16+J16 -> 151.6 | L16: =F16-(I16-X16) -> -0.039198387 | M16: 4.4 | N16: 0 | O16: 0 | P16: =M16-(N16+O16) -> 4.4 | Q16: 0 | R16: 0 | S16: =SUM(P16:R16) -> 4.4 | U16: 0 | V16: 30.7 | W16: =W15-V16 -> 12911 | X16: =N16+O16+S16+U16+V16 -> 35.1 | Y16: =IF(L16<0,L16*-1,0) -> 0.039198387 | Z16: =X16+Y16 -> 35.139198 | AA16: 0.4 | AB16: 35 | AC16: 25 | AD16: =AD15+1 -> 7
A17: =A16+1 -> 8 | B17: 6905.78 | C17: 305402 | D17: =C17-C16 -> 230 | E17: =C17-152000 -> 153402 | F17: =D17/$D$2 -> 115.95664 | G17: 151.2 | H17: 0 | I17: =G17+H17 -> 151.2 | J17: =IF(L17>0,L17,0) -> 0 | K17: =I17+J17 -> 151.2 | L17: =F17-(I17-X17) -> -0.043357701 | M17: 4.4 | N17: 0 | O17: 0 | P17: =M17-(N17+O17) -> 4.4 | Q17: 0 | R17: 0 | S17: =SUM(P17:R17) -> 4.4 | U17: 0 | V17: 30.8 | W17: =W16-V17 -> 12880.2 | X17: =N17+O17+S17+U17+V17 -> 35.2 | Y17: =IF(L17<0,L17*-1,0) -> 0.043357701 | Z17: =X17+Y17 -> 35.243358 | AA17: 0.45 | AB17: 36 | AC17: 28 | AD17: =AD16+1 -> 8
A18: =A17+1 -> 9 | B18: 6905.84 | C18: 305634 | D18: =C18-C17 -> 232 | E18: =C18-152000 -> 153634 | F18: =D18/$D$2 -> 116.96496 | G18: 151.9 | H18: 0 | I18: =G18+H18 -> 151.9 | J18: =IF(L18>0,L18,0) -> 0 | K18: =I18+J18 -> 151.9 | L18: =F18-(I18-X18) -> -0.035039072 | M18: 4.4 | N18: 0 | O18: 0 | P18: =M18-(N18+O18) -> 4.4 | Q18: 0 | R18: 0 | S18: =SUM(P18:R18) -> 4.4 | U18: 0 | V18: 30.5 | W18: =W17-V18 -> 12849.7 | X18: =N18+O18+S18+U18+V18 -> 34.9 | Y18: =IF(L18<0,L18*-1,0) -> 0.035039072 | Z18: =X18+Y18 -> 34.935039 | AA18: 0.45 | AB18: 38 | AC18: 30 | AD18: =AD17+1 -> 9
A19: =A18+1 -> 10 | B19: 6905.86 | C19: 305711 | D19: =C19-C18 -> 77 | E19: =C19-152000 -> 153711 | F19: =D19/$D$2 -> 38.820267 | G19: 73.8 | H19: 0 | I19: =G19+H19 -> 73.8 | J19: =IF(L19>0,L19,0) -> 0.020267204 | K19: =I19+J19 -> 73.820267 | L19: =F19-(I19-X19) -> 0.020267204 | M19: 4.5 | N19: 0 | O19: 0 | P19: =M19-(N19+O19) -> 4.5 | Q19: 0 | R19: 0 | S19: =SUM(P19:R19) -> 4.5 | U19: 0 | V19: 30.5 | W19: =W18-V19 -> 12819.2 | X19: =N19+O19+S19+U19+V19 -> 35 | Y19: =IF(L19<0,L19*-1,0) -> 0 | Z19: =X19+Y19 -> 35 | AA19: 0.25 | AB19: 40 | AC19: 33 | AD19: =AD18+1 -> 10
A20: =A19+1 -> 11 | B20: 6905.87 | C20: 305750 | D20: =C20-C19 -> 39 | E20: =C20-152000 -> 153750 | F20: =D20/$D$2 -> 19.662213 | G20: 54.7 | H20: 0 | I20: =G20+H20 -> 54.7 | J20: =IF(L20>0,L20,0) -> 0.062213259 | K20: =I20+J20 -> 54.762213 | L20: =F20-(I20-X20) -> 0.062213259 | M20: 4.4 | N20: 0 | O20: 0 | P20: =M20-(N20+O20) -> 4.4 | Q20: 0 | R20: 0 | S20: =SUM(P20:R20) -> 4.4 | U20: 0 | V20: 30.7 | W20: =W19-V20 -> 12788.5 | X20: =N20+O20+S20+U20+V20 -> 35.1 | Y20: =IF(L20<0,L20*-1,0) -> 0 | Z20: =X20+Y20 -> 35.1 | AA20: 0 | AB20: 31 | AC20: 25 | AD20: =AD19+1 -> 11
A21: =A20+1 -> 12 | B21: 6905.89 | C21: 305828 | D21: =C21-C20 -> 78 | E21: =C21-152000 -> 153828 | F21: =D21/$D$2 -> 39.324427 | G21: 73.8 | H21: 0 | I21: =G21+H21 -> 73.8 | J21: =IF(L21>0,L21,0) -> 0.024426519 | K21: =I21+J21 -> 73.824427 | L21: =F21-(I21-X21) -> 0.024426519 | M21: 3.9 | N21: 0 | O21: 0 | P21: =M21-(N21+O21) -> 3.9 | Q21: 0 | R21: 0 | S21: =SUM(P21:R21) -> 3.9 | U21: 0 | V21: 30.6 | W21: =W20-V21 -> 12757.9 | X21: =N21+O21+S21+U21+V21 -> 34.5 | Y21: =IF(L21<0,L21*-1,0) -> 0 | Z21: =X21+Y21 -> 34.5 | AA21: 0.04 | AB21: 33 | AC21: -1 | AD21: =AD20+1 -> 12
A22: 13 | B22: 6905.9 | C22: 305865 | D22: =C22-C21 -> 37 | E22: =C22-152000 -> 153865 | F22: =D22/$D$2 -> 18.653895 | G22: 52.8 | H22: 0 | I22: =G22+H22 -> 52.8 | J22: =IF(L22>0,L22,0) -> 0 | K22: =I22+J22 -> 52.8 | L22: =F22-(I22-X22) -> -0.046105369 | M22: 3.7 | N22: 0 | O22: 0 | P22: =M22-(N22+O22) -> 3.7 | Q22: 0 | R22: 0 | S22: =SUM(P22:R22) -> 3.7 | U22: 0 | V22: 30.4 | W22: =W21-V22 -> 12727.5 | X22: =N22+O22+S22+U22+V22 -> 34.1 | Y22: =IF(L22<0,L22*-1,0) -> 0.046105369 | Z22: =X22+Y22 -> 34.146105 | AA22: 0.09 | AB22: 34 | AC22: 0 | AD22: =AD21+1 -> 13
A23: =A22+1 -> 14 | B23: 6905.91 | C23: 305905 | D23: =C23-C22 -> 40 | E23: =C23-152000 -> 153905 | F23: =D23/$D$2 -> 20.166373 | G23: 54.4 | H23: 0 | I23: =G23+H23 -> 54.4 | J23: =IF(L23>0,L23,0) -> 0 | K23: =I23+J23 -> 54.4 | L23: =F23-(I23-X23) -> -0.033627426 | M23: 3.7 | N23: 0 | O23: 0 | P23: =M23-(N23+O23) -> 3.7 | Q23: 0 | R23: 0 | S23: =SUM(P23:R23) -> 3.7 | U23: 0 | V23: 30.5 | W23: =W22-V23 -> 12697 | X23: =N23+O23+S23+U23+V23 -> 34.2 | Y23: =IF(L23<0,L23*-1,0) -> 0.033627426 | Z23: =X23+Y23 -> 34.233627 | AA23: 0.15 | AB23: 35 | AC23: 28 | AD23: =AD22+1 -> 14
A24: =A23+1 -> 15 | B24: 6905.96 | C24: 306097 | D24: =C24-C23 -> 192 | E24: =C24-152000 -> 154097 | F24: =D24/$D$2 -> 96.798588 | G24: 131.1 | H24: 0 | I24: =G24+H24 -> 131.1 | J24: =IF(L24>0,L24,0) -> 0 | K24: =I24+J24 -> 131.1 | L24: =F24-(I24-X24) -> -0.0014116461 | M24: 3.7 | N24: 0 | O24: 0 | P24: =M24-(N24+O24) -> 3.7 | Q24: 0 | R24: 0 | S24: =SUM(P24:R24) -> 3.7 | U24: 0 | V24: 30.6 | W24: =W23-V24 -> 12666.4 | X24: =N24+O24+S24+U24+V24 -> 34.3 | Y24: =IF(L24<0,L24*-1,0) -> 0.0014116461 | Z24: =X24+Y24 -> 34.301412 | AA24: 0.2 | AB24: 37 | AC24: 30 | AD24: =AD23+1 -> 15
A25: =A24+1 -> 16 | B25: 6906.01 | C25: 306289 | D25: =C25-C24 -> 192 | E25: =C25-152000 -> 154289 | F25: =D25/$D$2 -> 96.798588 | G25: 131 | H25: 0 | I25: =G25+H25 -> 131 | J25: =IF(L25>0,L25,0) -> 0 | K25: =I25+J25 -> 131 | L25: =F25-(I25-X25) -> -0.0014116461 | M25: 3.7 | N25: 0 | O25: 0 | P25: =M25-(N25+O25) -> 3.7 | Q25: 0 | R25: 0 | S25: =SUM(P25:R25) -> 3.7 | U25: 0 | V25: 30.5 | W25: =W24-V25 -> 12635.9 | X25: =N25+O25+S25+U25+V25 -> 34.2 | Y25: =IF(L25<0,L25*-1,0) -> 0.0014116461 | Z25: =X25+Y25 -> 34.201412 | AA25: 0.3 | AB25: 37 | AC25: 33 | AD25: =AD24+1 -> 16
A26: =A25+1 -> 17 | B26: 6906.06 | C26: 306484 | D26: =C26-C25 -> 195 | E26: =C26-152000 -> 154484 | F26: =D26/$D$2 -> 98.311066 | G26: 132.6 | H26: 0 | I26: =G26+H26 -> 132.6 | J26: =IF(L26>0,L26,0) -> 0 | K26: =I26+J26 -> 132.6 | L26: =F26-(I26-X26) -> -0.088933703 | M26: 3.7 | N26: 0 | O26: 0 | P26: =M26-(N26+O26) -> 3.7 | Q26: 0 | R26: 0 | S26: =SUM(P26:R26) -> 3.7 | U26: 0 | V26: 30.5 | W26: =W25-V26 -> 12605.4 | X26: =N26+O26+S26+U26+V26 -> 34.2 | Y26: =IF(L26<0,L26*-1,0) -> 0.088933703 | Z26: =X26+Y26 -> 34.288934 | AA26: 0.1 | AB26: 32 | AC26: 32 | AD26: =AD25+1 -> 17
A27: =A26+1 -> 18 | B27: 6906.09 | C27: 306600 | D27: =C27-C26 -> 116 | E27: =C27-152000 -> 154600 | F27: =D27/$D$2 -> 58.48248 | G27: 110.4 | H27: 0 | I27: =G27+H27 -> 110.4 | J27: =IF(L27>0,L27,0) -> 0 | K27: =I27+J27 -> 110.4 | L27: =F27-(I27-X27) -> -0.017519536 | M27: 21.2 | N27: 0 | O27: 0 | P27: =M27-(N27+O27) -> 21.2 | Q27: 0 | R27: 0 | S27: =SUM(P27:R27) -> 21.2 | U27: 0 | V27: 30.7 | W27: =W26-V27 -> 12574.7 | X27: =N27+O27+S27+U27+V27 -> 51.9 | Y27: =IF(L27<0,L27*-1,0) -> 0.017519536 | Z27: =X27+Y27 -> 51.91752 | AA27: 0.42 | AB27: 40 | AC27: 22 | AD27: =AD26+1 -> 18
A28: =A27+1 -> 19 | B28: 6906.12 | C28: 306718 | D28: =C28-C27 -> 118 | E28: =C28-152000 -> 154718 | F28: =D28/$D$2 -> 59.490799 | G28: 94.6 | H28: 0 | I28: =G28+H28 -> 94.6 | J28: =IF(L28>0,L28,0) -> 0 | K28: =I28+J28 -> 94.6 | L28: =F28-(I28-X28) -> -0.0092009075 | M28: 3.7 | N28: 0 | O28: 0 | P28: =M28-(N28+O28) -> 3.7 | Q28: 0 | R28: 0 | S28: =SUM(P28:R28) -> 3.7 | U28: 0 | V28: 31.4 | W28: =W27-V28 -> 12543.3 | X28: =N28+O28+S28+U28+V28 -> 35.1 | Y28: =IF(L28<0,L28*-1,0) -> 0.0092009075 | Z28: =X28+Y28 -> 35.109201 | AA28: 0.11 | AB28: 36 | AC28: 30 | AD28: =AD27+1 -> 19
A29: =A28+1 -> 20 | B29: 6906.12 | C29: 306718 | D29: =C29-C28 -> 0 | E29: =C29-152000 -> 154718 | F29: =D29/$D$2 -> 0 | G29: 35 | H29: 0 | I29: =G29+H29 -> 35 | J29: =IF(L29>0,L29,0) -> 0 | K29: =I29+J29 -> 35 | L29: =F29-(I29-X29) -> 0 | M29: 3.7 | N29: 0 | O29: 0 | P29: =M29-(N29+O29) -> 3.7 | Q29: 0 | R29: 0 | S29: =SUM(P29:R29) -> 3.7 | U29: 0 | V29: 31.3 | W29: =W28-V29 -> 12512 | X29: =N29+O29+S29+U29+V29 -> 35 | Y29: =IF(L29<0,L29*-1,0) -> 0 | Z29: =X29+Y29 -> 35 | AA29: 0 | AB29: 43 | AC29: 18 | AD29: =AD28+1 -> 20
A30: =A29+1 -> 21 | B30: 6906.14 | C30: 306796 | D30: =C30-C29 -> 78 | E30: =C30-152000 -> 154796 | F30: =D30/$D$2 -> 39.324427 | G30: 74.3 | H30: 0 | I30: =G30+H30 -> 74.3 | J30: =IF(L30>0,L30,0) -> 0 | K30: =I30+J30 -> 74.3 | L30: =F30-(I30-X30) -> -0.075573481 | M30: 3.7 | N30: 0 | O30: 0 | P30: =M30-(N30+O30) -> 3.7 | Q30: 0 | R30: 0 | S30: =SUM(P30:R30) -> 3.7 | U30: 0 | V30: 31.2 | W30: =W29-V30 -> 12480.8 | X30: =N30+O30+S30+U30+V30 -> 34.9 | Y30: =IF(L30<0,L30*-1,0) -> 0.075573481 | Z30: =X30+Y30 -> 34.975573 | AA30: 0 | AB30: 45 | AC30: 15 | AD30: =AD29+1 -> 21
A31: =A30+1 -> 22 | B31: 6906.15 | C31: 306834 | D31: =C31-C30 -> 38 | E31: =C31-152000 -> 154834 | F31: =D31/$D$2 -> 19.158054 | G31: 54 | H31: 0 | I31: =G31+H31 -> 54 | J31: =IF(L31>0,L31,0) -> 0 | K31: =I31+J31 -> 54 | L31: =F31-(I31-X31) -> -0.041946055 | M31: 3.7 | N31: 0 | O31: 0 | P31: =M31-(N31+O31) -> 3.7 | Q31: 0 | R31: 0 | S31: =SUM(P31:R31) -> 3.7 | U31: 0 | V31: 31.1 | W31: =W30-V31 -> 12449.7 | X31: =N31+O31+S31+U31+V31 -> 34.8 | Y31: =IF(L31<0,L31*-1,0) -> 0.041946055 | Z31: =X31+Y31 -> 34.841946 | AA31: 0 | AB31: 47 | AC31: 13 | AD31: =AD30+1 -> 22
A32: =A31+1 -> 23 | B32: 6906.15 | C32: 306834 | D32: =C32-C31 -> 0 | E32: =C32-152000 -> 154834 | F32: =D32/$D$2 -> 0 | G32: 34.7 | H32: 0 | I32: =G32+H32 -> 34.7 | J32: =IF(L32>0,L32,0) -> 0 | K32: =I32+J32 -> 34.7 | L32: =F32-(I32-X32) -> 0 | M32: 3.7 | N32: 0 | O32: 0 | P32: =M32-(N32+O32) -> 3.7 | Q32: 0 | R32: 0 | S32: =SUM(P32:R32) -> 3.7 | U32: 0 | V32: 31 | W32: =W31-V32 -> 12418.7 | X32: =N32+O32+S32+U32+V32 -> 34.7 | Y32: =IF(L32<0,L32*-1,0) -> 0 | Z32: =X32+Y32 -> 34.7 | AA32: 0 | AB32: 34 | AC32: 10 | AD32: =AD31+1 -> 23
A33: =A32+1 -> 24 | B33: 6906.16 | C33: 306874 | D33: =C33-C32 -> 40 | E33: =C33-152000 -> 154874 | F33: =D33/$D$2 -> 20.166373 | G33: 54.6 | H33: 0 | I33: =G33+H33 -> 54.6 | J33: =IF(L33>0,L33,0) -> 0 | K33: =I33+J33 -> 54.6 | L33: =F33-(I33-X33) -> -0.033627426 | M33: 3.7 | N33: 0 | O33: 0 | P33: =M33-(N33+O33) -> 3.7 | Q33: 0 | R33: 0 | S33: =SUM(P33:R33) -> 3.7 | U33: 0 | V33: 30.7 | W33: =W32-V33 -> 12388 | X33: =N33+O33+S33+U33+V33 -> 34.4 | Y33: =IF(L33<0,L33*-1,0) -> 0.033627426 | Z33: =X33+Y33 -> 34.433627 | AA33: 0 | AB33: 37 | AC33: 14 | AD33: =AD32+1 -> 24
A34: =A33+1 -> 25 | B34: 6906.16 | C34: 306874 | D34: =C34-C33 -> 0 | E34: =C34-152000 -> 154874 | F34: =D34/$D$2 -> 0 | G34: 34.4 | H34: 0 | I34: =G34+H34 -> 34.4 | J34: =IF(L34>0,L34,0) -> 0 | K34: =I34+J34 -> 34.4 | L34: =F34-(I34-X34) -> 0 | M34: 3.7 | N34: 0 | O34: 0 | P34: =M34-(N34+O34) -> 3.7 | Q34: 0 | R34: 0 | S34: =SUM(P34:R34) -> 3.7 | U34: 0 | V34: 30.7 | W34: =W33-V34 -> 12357.3 | X34: =N34+O34+S34+U34+V34 -> 34.4 | Y34: =IF(L34<0,L34*-1,0) -> 0 | Z34: =X34+Y34 -> 34.4 | AA34: 0 | AB34: 44 | AC34: 10 | AD34: =AD33+1 -> 25
... A38: =A37+1 -> 29 | B38: 6906.25 | C38: 307223 | D38: =C38-C37 -> 116 | E38: =C38-152000 -> 155223 | F38: =D38/$D$2 -> 58.48248 | G38: 79.1 | H38: 0 | I38: =G38+H38 -> 79.1 | J38: =IF(L38>0,L38,0) -> 14.98248 | K38: =I38+J38 -> 94.08248 | L38: =F38-(I38-X38) -> 14.98248 | M38: 3.7 | N38: 0 | O38: 0 | P38: =M38-(N38+O38) -> 3.7 | Q38: 0 | R38: 0 | S38: =SUM(P38:R38) -> 3.7 | U38: 0 | V38: 31.9 | W38: =W37-V38 -> 12230.1 | X38: =N38+O38+S38+U38+V38 -> 35.6 | Y38: =IF(L38<0,L38*-1,0) -> 0 | Z38: =X38+Y38 -> 35.6 | AA38: 0 | AB38: 43 | AC38: 23 | AD38: =AD37+1 -> 29
A39: 30 | B39: 6906.28 | C39: 307339 | D39: =C39-C38 -> 116 | E39: =C39-152000 -> 155339 | F39: =D39/$D$2 -> 58.48248 | G39: 93.9 | H39: 0 | I39: =G39+H39 -> 93.9 | J39: =IF(L39>0,L39,0) -> 0 | K39: =I39+J39 -> 93.9 | L39: =F39-(I39-X39) -> -0.017519536 | M39: 3.7 | N39: 0 | O39: 0 | P39: =M39-(N39+O39) -> 3.7 | Q39: 0 | R39: 0 | S39: =SUM(P39:R39) -> 3.7 | U39: 0 | V39: 31.7 | W39: =W38-V39 -> 12198.4 | X39: =N39+O39+S39+U39+V39 -> 35.4 | Y39: =IF(L39<0,L39*-1,0) -> 0.017519536 | Z39: =X39+Y39 -> 35.41752 | AA39: 0 | AB39: 44 | AC39: 24 | AD39: 30
A40: 31 | B40: 6906.31 | C40: 307456 | D40: =C40-C39 -> 117 | E40: =C40-152000 -> 155456 | F40: =D40/$D$2 -> 58.98664 | G40: 94.7 | H40: 0 | I40: =G40+H40 -> 94.7 | J40: =IF(L40>0,L40,0) -> 0 | K40: =I40+J40 -> 94.7 | L40: =F40-(I40-X40) -> -0.11336022 | M40: 3.7 | N40: 0 | O40: 0 | P40: =M40-(N40+O40) -> 3.7 | Q40: 0 | R40: 0 | S40: =SUM(P40:R40) -> 3.7 | U40: 0 | V40: 31.9 | W40: =W39-V40 -> 12166.5 | X40: =N40+O40+S40+U40+V40 -> 35.6 | Y40: =IF(L40<0,L40*-1,0) -> 0.11336022 | Z40: =X40+Y40 -> 35.71336 | AA40: 0.5 | AB40: 38 | AC40: 17 | AD40: 31
AB41: 39
A42: MONTH / CFS | F42: =SUM(F10:F40) -> 1423.7459 | G42: =SUM(G10:G40) -> 2509.1 | H42: =SUM(H10:H40) -> 0 | I42: =SUM(I10:I40) -> 2509.1 | J42: =SUM(J10:J40) -> 15.192135 | K42: =SUM(K10:K40) -> 2524.2921 | L42: =SUM(L10:L40) -> 14.345904 | M42: =SUM(M10:M40) -> 140.3 | ... S42: =SUM(S10:S40) -> 140.3 | U42: =SUM(U10:U40) -> 0 | V42: =SUM(V10:V40) -> 959.4 | X42: =SUM(X10:X40) -> 1099.7 | Y42: =SUM(Y10:Y40) -> 0.84623141 | Z42: =SUM(Z10:Z40) -> 1100.5462 | AA42: =SUM(AA10:AA40) -> 3.88 | AB42: =AVERAGE(AB10:AB40) -> 38.451613 | AC42: =AVERAGE(AC10:AC40) -> 20.032258 | AD42: AVE
A43: MONTH / AF | D43: =SUM(D10:D40) -> 2824 | F43: =F42*$D$2 -> 2824 | G43: =G42*$D$2 -> 4976.7999 | H43: =H42*$D$2 -> 0 | I43: =I42*$D$2 -> 4976.7999 | J43: =J42*$D$2 -> 30.1336 | K43: =K42*$D$2 -> 5006.9335 | L43: =L42*$D$2 -> 28.4551 | M43: =M42*$D$2 -> 278.28505 | ... S43: =S42*$D$2 -> 278.28505 | U43: =U42*$D$2 -> 0 | V43: =V42*$D$2 -> 1902.9699 | X43: =X42*$D$2 -> 2181.255 | Y43: =Y42*$D$2 -> 1.6785 | Z43: =Z42*$D$2 -> 2182.9334 | AB43: =MAX(AB10:AB40) -> 47 | AC43: =MAX(AC10:AC40) -> 33 | AD43: HI
A45: SEASON / CFS | AB45: =MIN(AB10:AB40) -> 31 | AC45: =MIN(AC10:AC40) -> -1 | AD45: LO
A46: SEASON / AF
...

Sheet FEB
K1: MC PHEE RESERVOIR IN/OUT FLOW TABULATION
A2: AF/cfs CONVERT FACTOR | D2: 1.9835 | K2: FEBRUARY "1993"
A4: DATE | B4: RESERV | C4: RESERV | D4: AC FT | E4: ACTIVE | F4: CONV TO | G4: DOLORES | H4: LOST | I4: RECORDED | J4: CALC | K4: TOTAL | L4: CALC | M4: DOLORES TUNNEL | Q4: LONE | R4: U | S4: TOTAL | T4: MVI | U4: DV CR | V4: BELOW | W4: REMAIN | X4: RECORDED | Y4: CALC | Z4: TOTAL | AA4: RAIN | AB4: MAX | AC4: MIN | AD4: DATE
A5: FEB | B5: ELEV | C5: AC FT | D5: CHANGE | E5: CAP | F5: CFS | G5: RIVER | H5: CANYON | I5: INFLOW | J5: INFLOW | K5: INFLOW | L5: INF/OTF | M5: TOT DIV | N5: WETLAND | O5: UTE F&R | P5: MVI,CTZ | Q5: PINE | R5: LAT | S5: MVI | T5: CALL | U5: CANAL | V5: MC PHEE | W5: RELEASE | X5: OUTFLOW | Y5: OUTFLOW | Z5: OUTFLOW | AB5: TMP | AC5: TMP | AD5: FEB
A7: SEASON BAL
A8: YTD | B8: =JAN!B40 -> 6906.31 | C8: =JAN!C40 -> 307456 | D8: =JAN!$D$49 -> 3479 | E8: =JAN!$E$40 -> 155456 | F8: =JAN!F48 -> 1753.9703 | G8: =JAN!G48 -> 6534.5 | H8: =JAN!H48 -> 0 | I8: =JAN!I48 -> 6534.5 | J8: =JAN!J48 -> 241.73481 | K8: =JAN!K48 -> 6776.2348 | L8: =JAN!L48 -> -659.32975 | M8: =JAN!M48 -> 812 | ... AA8: =JAN!AA48 -> 6.43
A10: 1 | B10: 6906.31 | C10: 307456 | D10: =C10-C8 -> 0 | E10: =C10-152000 -> 155456 | F10: =D10/$D$2 -> 0 | G10: 39 | H10: 6.2 | I10: =G10+H10 -> 45.2 | J10: =IF(L10>0,L10,0) -> 0 | K10: =I10+J10 -> 45.2 | L10: =F10-(I10-X10) -> 0 | M10: 3.7 | N10: 0 | O10: 0 | P10: =M10-(N10+O10) -> 3.7 | Q10: 0 | R10: 0 | S10: =SUM(P10:R10) -> 3.7 | U10: 0 | V10: 41.5 | W10: =W8-30 -> 12136.5 | X10: =N10+O10+S10+U10+V10 -> 45.2 | Y10: =IF(L10<0,L10*-1,0) -> 0 | Z10: =X10+Y10 -> 45.2 | AA10: 0.2 | AB10: 34 | AC10: 14 | AD10: 1
A11: =A10+1 -> 2 | B11: 6906.31 | C11: 307456 | D11: =C11-C10 -> 0 | E11: =C11-152000 -> 155456 | F11: =D11/$D$2 -> 0 | G11: 47.1 | H11: 6 | I11: =G11+H11 -> 53.1 | J11: =IF(L11>0,L11,0) -> 0 | K11: =I11+J11 -> 53.1 | L11: =F11-(I11-X11) -> 0 | M11: 3.7 | N11: 0 | O11: 0 | P11: =M11-(N11+O11) -> 3.7 | Q11: 0 | R11: 0 | S11: =SUM(P11:R11) -> 3.7 | U11: 0 | V11: 49.4 | W11: =W10-30 -> 12106.5 | X11: =N11+O11+S11+U11+V11 -> 53.1 | Y11: =IF(L11<0,L11*-1,0) -> 0 | Z11: =X11+Y11 -> 53.1 | AA11: 0 | AB11: 40 | AC11: 18 | AD11: =AD10+1 -> 2
A12: =A11+1 -> 3 | B12: 6906.32 | C12: 307494 | D12: =C12-C11 -> 38 | E12: =C12-152000 -> 155494 | F12: =D12/$D$2 -> 19.158054 | G12: 68.6 | H12: 5.8 | I12: =G12+H12 -> 74.4 | J12: =IF(L12>0,L12,0) -> 0.058053945 | K12: =I12+J12 -> 74.458054 | L12: =F12-(I12-X12) -> 0.058053945 | M12: 3.7 | N12: 0 | O12: 0 | P12: =M12-(N12+O12) -> 3.7 | Q12: 0 | R12: 0 | S12: =SUM(P12:R12) -> 3.7 | U12: 0 | V12: 51.6 | W12: =W11-30 -> 12076.5 | X12: =N12+O12+S12+U12+V12 -> 55.3 | Y12: =IF(L12<0,L12*-1,0) -> 0 | Z12: =X12+Y12 -> 55.3 | AA12: 0 | AB12: 44 | AC12: 9 | AD12: =AD11+1 -> 3
A13: =A12+1 -> 4 | B13: 6906.33 | C13: 307534 | D13: =C13-C12 -> 40 | E13: =C13-152000 -> 155534 | F13: =D13/$D$2 -> 20.166373 | G13: 68.7 | H13: 5.5 | I13: =G13+H13 -> 74.2 | J13: =IF(L13>0,L13,0) -> 0 | K13: =I13+J13 -> 74.2 | L13: =F13-(I13-X13) -> -0.13362743 | M13: 3.7 | N13: 0 | O13: 0 | P13: =M13-(N13+O13) -> 3.7 | Q13: 0 | R13: 0 | S13: =SUM(P13:R13) -> 3.7 | U13: 0 | V13: 50.2 | W13: =W12-30 -> 12046.5 | X13: =N13+O13+S13+U13+V13 -> 53.9 | Y13: =IF(L13<0,L13*-1,0) -> 0.13362743 | Z13: =X13+Y13 -> 54.033627 | AA13: 0 | AB13: 43 | AC13: 8 | AD13: =AD12+1 -> 4
A14: =A13+1 -> 5 | B14: 6906.33 | C14: 307534 | D14: =C14-C13 -> 0 | E14: =C14-152000 -> 155534 | F14: =D14/$D$2 -> 0 | G14: 48.6 | H14: 5 | I14: =G14+H14 -> 53.6 | J14: =IF(L14>0,L14,0) -> 0 | K14: =I14+J14 -> 53.6 | L14: =F14-(I14-X14) -> 0 | M14: 3.7 | N14: 0 | O14: 0 | P14: =M14-(N14+O14) -> 3.7 | Q14: 0 | R14: 0 | S14: =SUM(P14:R14) -> 3.7 | U14: 0 | V14: 49.9 | W14: =W13-30 -> 12016.5 | X14: =N14+O14+S14+U14+V14 -> 53.6 | Y14: =IF(L14<0,L14*-1,0) -> 0 | Z14: =X14+Y14 -> 53.6 | AA14: 0 | AB14: 44 | AC14: 10 | AD14: =AD13+1 -> 5
A15: =A14+1 -> 6 | B15: 6906.34 | C15: 307572 | D15: =C15-C14 -> 38 | E15: =C15-152000 -> 155572 | F15: =D15/$D$2 -> 19.158054 | G15: 68.4 | H15: 4.8 | I15: =G15+H15 -> 73.2 | J15: =IF(L15>0,L15,0) -> 0 | K15: =I15+J15 -> 73.2 | L15: =F15-(I15-X15) -> -0.041946055 | M15: 3.7 | N15: 0 | O15: 0 | P15: =M15-(N15+O15) -> 3.7 | Q15: 0 | R15: 0 | S15: =SUM(P15:R15) -> 3.7 | U15: 0 | V15: 50.3 | W15: =W14-30 -> 11986.5 | X15: =N15+O15+S15+U15+V15 -> 54 | Y15: =IF(L15<0,L15*-1,0) -> 0.041946055 | Z15: =X15+Y15 -> 54.041946 | AA15: 0 | AB15: 45 | AC15: 18 | AD15: =AD14+1 -> 6
A16: =A15+1 -> 7 | B16: 3906.34 | C16: 307572 | D16: =C16-C15 -> 0 | E16: =C16-152000 -> 155572 | F16: =D16/$D$2 -> 0 | G16: 48.9 | H16: 4.8 | I16: =G16+H16 -> 53.7 | J16: =IF(L16>0,L16,0) -> 0.1 | K16: =I16+J16 -> 53.8 | L16: =F16-(I16-X16) -> 0.1 | M16: 3.7 | N16: 0 | O16: 0 | P16: =M16-(N16+O16) -> 3.7 | Q16: 0 | R16: 0 | S16: =SUM(P16:R16) -> 3.7 | U16: 0 | V16: 50.1 | W16: =W15-30 -> 11956.5 | X16: =N16+O16+S16+U16+V16 -> 53.8 | Y16: =IF(L16<0,L16*-1,0) -> 0 | Z16: =X16+Y16 -> 53.8 | AA16: 0 | AB16: 42 | AC16: 22 | AD16: =AD15+1 -> 7
A17: =A16+1 -> 8 | B17: 6906.42 | C17: 307883 | D17: =C17-C16 -> 311 | E17: =C17-152000 -> 155883 | F17: =D17/$D$2 -> 156.79355 | G17: 205.8 | H17: 5 | I17: =G17+H17 -> 210.8 | J17: =IF(L17>0,L17,0) -> 0 | K17: =I17+J17 -> 210.8 | L17: =F17-(I17-X17) -> -0.10645324 | M17: 3.7 | N17: 0 | O17: 0 | P17: =M17-(N17+O17) -> 3.7 | Q17: 0 | R17: 0 | S17: =SUM(P17:R17) -> 3.7 | U17: 0 | V17: 50.2 | W17: =W16-30 -> 11926.5 | X17: =N17+O17+S17+U17+V17 -> 53.9 | Y17: =IF(L17<0,L17*-1,0) -> 0.10645324 | Z17: =X17+Y17 -> 54.006453 | AA17: 0.97 | AB17: 42 | AC17: 26 | AD17: =AD16+1 -> 8
A18: =A17+1 -> 9 | B18: 6906.46 | C18: 308039 | D18: =C18-C17 -> 156 | E18: =C18-152000 -> 156039 | F18: =D18/$D$2 -> 78.648853 | G18: 125.3 | H18: 6.4 | I18: =G18+H18 -> 131.7 | J18: =IF(L18>0,L18,0) -> 0 | K18: =I18+J18 -> 131.7 | L18: =F18-(I18-X18) -> -0.051146962 | M18: 3.7 | N18: 0 | O18: 0 | P18: =M18-(N18+O18) -> 3.7 | Q18: 0 | R18: 0 | S18: =SUM(P18:R18) -> 3.7 | U18: 0 | V18: 49.3 | W18: =W17-30 -> 11896.5 | X18: =N18+O18+S18+U18+V18 -> 53 | Y18: =IF(L18<0,L18*-1,0) -> 0.051146962 | Z18: =X18+Y18 -> 53.051147 | AA18: 0.09 | AB18: 40 | AC18: 30 | AD18: =AD17+1 -> 9
A19: =A18+1 -> 10 | B19: 6906.47 | C19: 308079 | D19: =C19-C18 -> 40 | E19: =C19-152000 -> 156079 | F19: =D19/$D$2 -> 20.166373 | G19: 67.7 | H19: 5.9 | I19: =G19+H19 -> 73.6 | J19: =IF(L19>0,L19,0) -> 0 | K19: =I19+J19 -> 73.6 | L19: =F19-(I19-X19) -> -0.033627426 | M19: 3.7 | N19: 0 | O19: 0 | P19: =M19-(N19+O19) -> 3.7 | Q19: 0 | R19: 0 | S19: =SUM(P19:R19) -> 3.7 | U19: 0 | V19: 49.7 | W19: =W18-30 -> 11866.5 | X19: =N19+O19+S19+U19+V19 -> 53.4 | Y19: =IF(L19<0,L19*-1,0) -> 0.033627426 | Z19: =X19+Y19 -> 53.433627 | AA19: 0 | AB19: 45 | AC19: 22 | AD19: =AD18+1 -> 10
A20: =A19+1 -> 11 | B20: 6906.48 | C20: 308117 | D20: =C20-C19 -> 38 | E20: =C20-152000 -> 156117 | F20: =D20/$D$2 -> 19.158054 | G20: 66.6 | H20: 6 | I20: =G20+H20 -> 72.6 | J20: =IF(L20>0,L20,0) -> 0 | K20: =I20+J20 -> 72.6 | L20: =F20-(I20-X20) -> -0.041946055 | M20: 3.7 | N20: 0 | O20: 0 | P20: =M20-(N20+O20) -> 3.7 | Q20: 0 | R20: 0 | S20: =SUM(P20:R20) -> 3.7 | U20: 0 | V20: 49.7 | W20: =W19-30 -> 11836.5 | X20: =N20+O20+S20+U20+V20 -> 53.4 | Y20: =IF(L20<0,L20*-1,0) -> 0.041946055 | Z20: =X20+Y20 -> 53.441946 | AA20: 0 | AB20: 39 | AC20: 23 | AD20: =AD19+1 -> 11
A21: =A20+1 -> 12 | B21: 6906.49 | C21: 308157 | D21: =C21-C20 -> 40 | E21: =C21-152000 -> 156157 | F21: =D21/$D$2 -> 20.166373 | G21: 67.6 | H21: 6.8 | I21: =G21+H21 -> 74.4 | J21: =IF(L21>0,L21,0) -> 0 | K21: =I21+J21 -> 74.4 | L21: =F21-(I21-X21) -> -0.033627426 | M21: 3.7 | N21: 0 | O21: 0 | P21: =M21-(N21+O21) -> 3.7 | Q21: 0 | R21: 0 | S21: =SUM(P21:R21) -> 3.7 | U21: 0 | V21: 50.5 | W21: =W20-30 -> 11806.5 | X21: =N21+O21+S21+U21+V21 -> 54.2 | Y21: =IF(L21<0,L21*-1,0) -> 0.033627426 | Z21: =X21+Y21 -> 54.233627 | AA21: 0 | AB21: 37 | AC21: 24 | AD21: =AD20+1 -> 12
A22: =A21+1 -> 13 | B22: 6906.5 | C22: 308195 | D22: =C22-C21 -> 38 | E22: =C22-152000 -> 156195 | F22: =D22/$D$2 -> 19.158054 | G22: 66.9 | H22: 6.5 | I22: =G22+H22 -> 73.4 | J22: =IF(L22>0,L22,0) -> 0 | K22: =I22+J22 -> 73.4 | L22: =F22-(I22-X22) -> -0.041946055 | M22: 3.7 | N22: 0 | O22: 0 | P22: =M22-(N22+O22) -> 3.7 | Q22: 0 | R22: 0 | S22: =SUM(P22:R22) -> 3.7 | U22: 0 | V22: 50.5 | W22: =W21-30 -> 11776.5 | X22: =N22+O22+S22+U22+V22 -> 54.2 | Y22: =IF(L22<0,L22*-1,0) -> 0.041946055 | Z22: =X22+Y22 -> 54.241946 | AA22: 0 | AB22: 38 | AC22: 19 | AD22: =AD21+1 -> 13
... A36: =A35+1 -> 27 | B36: 6907.01 | C36: 310176 | D36: =C36-C35 -> 76 | E36: =C36-152000 -> 158176 | F36: =D36/$D$2 -> 38.316108 | G36: 83.8 | H36: 8.5 | I36: =G36+H36 -> 92.3 | J36: =IF(L36>0,L36,0) -> 0.01610789 | K36: =I36+J36 -> 92.316108 | L36: =F36-(I36-X36) -> 0.01610789 | M36: 4.1 | N36: 0 | O36: 0 | P36: =M36-(N36+O36) -> 4.1 | Q36: 0 | R36: 0 | S36: =SUM(P36:R36) -> 4.1 | U36: 0 | V36: 49.9 | W36: =W35-30 -> 11356.5 | X36: =N36+O36+S36+U36+V36 -> 54 | Y36: =IF(L36<0,L36*-1,0) -> 0 | Z36: =X36+Y36 -> 54 | AA36: 0 | AB36: 51 | AC36: 25 | AD36: =AD35+1 -> 27
A37: 28 | B37: 6907.04 | C37: 310295 | D37: =C37-C36 -> 119 | E37: =C37-152000 -> 158295 | F37: =D37/$D$2 -> 59.994958 | G37: 107.4 | H37: 6.6 | I37: =G37+H37 -> 114 | J37: =IF(L37>0,L37,0) -> 0 | K37: =I37+J37 -> 114 | L37: =F37-(I37-X37) -> -0.0050415931 | M37: 4.1 | N37: 0 | O37: 0 | P37: =M37-(N37+O37) -> 4.1 | Q37: 0 | R37: 0 | S37: =SUM(P37:R37) -> 4.1 | U37: 0 | V37: 49.9 | W37: =W36-30 -> 11326.5 | X37: =N37+O37+S37+U37+V37 -> 54 | Y37: =IF(L37<0,L37*-1,0) -> 0.0050415931 | Z37: =X37+Y37 -> 54.005042 | AA37: 0 | AB37: 45 | AC37: 29 | AD37: 28
A39: MONTH / CFS | F39: =SUM(F10:F37) -> 1431.3083 | G39: =SUM(G10:G37) -> 2716.8 | H39: =SUM(H10:H37) -> 215.7 | I39: =SUM(I10:I37) -> 2932.5 | J39: =SUM(J10:J37) -> 0.4303756 | K39: =SUM(K10:K37) -> 2932.9304 | L39: =SUM(L10:L37) -> -0.29170658 | M39: =SUM(M10:M37) -> 107.5 | ... S39: =SUM(S10:S37) -> 107.5 | U39: =SUM(U10:U37) -> 0 | V39: =SUM(V10:V37) -> 1393.4 | X39: =SUM(X10:X37) -> 1500.9 | Y39: =SUM(Y10:Y37) -> 0.72208218 | Z39: =SUM(Z10:Z37) -> 1501.6221 | AA39: =SUM(AA10:AA37) -> 4.45 | AB39: =AVERAGE(AB10:AB37) -> 40.071429 | AC39: =AVERAGE(AC10:AC37) -> 21.035714 | AD39: AVE
A40: MONTH / AF | D40: =SUM(D10:D37) -> 2839 | F40: =F39*$D$2 -> 2839 | G40: =G39*$D$2 -> 5388.7728 | H40: =H39*$D$2 -> 427.84095 | I40: =I39*$D$2 -> 5816.6138 | J40: =J39*$D$2 -> 0.85365 | K40: =K39*$D$2 -> 5817.4674 | L40: =L39*$D$2 -> -0.5786 | M40: =M39*$D$2 -> 213.22625 | ... S40: =S39*$D$2 -> 213.22625 | U40: =U39*$D$2 -> 0 | V40: =V39*$D$2 -> 2763.8089 | X40: =X39*$D$2 -> 2977.0352 | Y40: =Y39*$D$2 -> 1.43225 | Z40: =Z39*$D$2 -> 2978.4674 | AB40: =MAX(AB10:AB37) -> 51 | AC40: =MAX(AC10:AC37) -> 32 | AD40: HI
A42: SEASON / CFS | AB42: =MIN(AB10:AB37) -> 32 | AC42: =MIN(AC10:AC37) -> 8 | AD42: LO
A43: SEASON / AF
A45: YTD / CFS | F45: =F8+F39 -> 3185.2785 | G45: =G8+G39 -> 9251.3 | H45: =H8+H39 -> 215.7 | I45: =I8+I39 -> 9467 | J45: =J8+J39 -> 242.16519 | K45: =K8+K39 -> 9709.1652 | L45: =L8+L39 -> -659.62145 | M45: =M8+M39 -> 919.5 | ... S45: =S8+S39 -> 1098.2 | U45: =U8+U39 -> 0 | V45: =V8+V39 -> 4523.9 | W45: =W37 -> 11326.5 | X45: =X8+X39 -> 5622.1 | Y45: =Y8+Y39 -> 901.78664 | Z45: =Z8+Z39 -> 6523.8866 | AA45: =AA8+AA39 -> 10.88
A46: YTD / AF | D46: =D8+D40 -> 6318 | E46: =E37 -> 158295 | F46: =F45*$D$2 -> 6318 | G46: =G45*$D$2 -> 18349.954 | H46: =H45*$D$2 -> 427.84095 | I46: =I45*$D$2 -> 18777.794 | J46: =J45*$D$2 -> 480.33465 | K46: =K45*$D$2 -> 19258.129 | L46: =L45*$D$2 -> -1308.3591 | M46: =M45*$D$2 -> 1823.8283 | ... Z46: =Z45*$D$2 -> 12940.129

Sheet MAR
K1: MC PHEE RESERVOIR IN/OUT FLOW TABULATION
A2: AF/cfs CONVERT FACTOR | D2: 1.9835 | K2: MARCH "1993"
A4: DATE | B4: RESERV | C4: RESERV | D4: AC FT | E4: ACTIVE | F4: CONV TO | G4: DOLORES | H4: LOST | I4: RECORDED | J4: CALC | K4: TOTAL | L4: CALC | M4: DOLORES TUNNEL | Q4: LONE | R4: U | S4: TOTAL | T4: MVI | U4: DV CR | V4: BELOW | W4: REMAIN | X4: RECORDED | Y4: CALC | Z4: TOTAL | AA4: RAIN | AB4: MAX | AC4: MIN | AD4: DATE
A5: MAR | B5: ELEV | C5: AC FT | D5: CHANGE | E5: CAP | F5: CFS | G5: RIVER | H5: CANYON | I5: INFLOW | J5: INFLOW | K5: INFLOW | L5: INF/OTF | M5: TOT DIV | N5: WETLAND | O5: UTE F&R | P5: MVI,CTZ | Q5: PINE | R5: LAT | S5: MVI | T5: CALL | U5: CANAL | V5: MC PHEE | W5: RELEASE | X5: OUTFLOW | Y5: OUTFLOW | Z5: OUTFLOW | AB5: TMP | AC5: TMP | AD5: MAR
A7: SEASON BAL
A8: YTD | B8: =FEB!B37 -> 6907.04 | C8: =FEB!C37 -> 310295 | D8: =FEB!$D$46 -> 6318 | E8: =FEB!$E$37 -> 158295 | F8: =FEB!F45 -> 3185.2785 | G8: =FEB!G45 -> 9251.3 | H8: =FEB!H45 -> 215.7 | I8: =FEB!I45 -> 9467 | J8: =FEB!J45 -> 242.16519 | K8: =FEB!K45 -> 9709.1652 | L8: =FEB!L45 -> -659.62145 | M8: =FEB!M45 -> 919.5 | ... AA8: =FEB!AA45 -> 10.88
A10: 1 | B10: 6907.02 | C10: 310216 | D10: =C10-C8 -> -79 | E10: =C10-152000 -> 158216 | F10: =D10/$D$2 -> -39.828586 | G10: 46.8 | H10: 5.8 | I10: =G10+H10 -> 52.6 | J10: =IF(L10>0,L10,0) -> 0.071414167 | K10: =I10+J10 -> 52.671414 | L10: =F10-(I10-X10) -> 0.071414167 | M10: 4.1 | N10: 0 | O10: 0 | P10: =M10-(N10+O10) -> 4.1 | Q10: 0 | R10: 0 | S10: =SUM(P10:R10) -> 4.1 | U10: 0 | V10: 88.4 | W10: =W8-30 -> 11296.5 | X10: =N10+O10+S10+U10+V10 -> 92.5 | Y10: =IF(L10<0,L10*-1,0) -> 0 | Z10: =X10+Y10 -> 92.5 | AA10: 0 | AB10: 43 | AC10: 28 | AD10: 1
A11: =A10+1 -> 2 | B11: 6906.99 | C11: 310100 | D11: =C11-C10 -> -116 | E11: =C11-152000 -> 158100 | F11: =D11/$D$2 -> -58.48248 | G11: 73.2 | H11: 8.2 | I11: =G11+H11 -> 81.4 | J11: =IF(L11>0,L11,0) -> 0.017519536 | K11: =I11+J11 -> 81.41752 | L11: =F11-(I11-X11) -> 0.017519536 | M11: 4 | N11: 0 | O11: 0 | P11: =M11-(N11+O11) -> 4 | Q11: 0 | R11: 0 | S11: =SUM(P11:R11) -> 4 | U11: 0 | V11: 135.9 | W11: =W10-30 -> 11266.5 | X11: =N11+O11+S11+U11+V11 -> 139.9 | Y11: =IF(L11<0,L11*-1,0) -> 0 | Z11: =X11+Y11 -> 139.9 | AA11: 0 | AB11: 39 | AC11: 21 | AD11: =AD10+1 -> 2
A12: =A11+1 -> 3 | B12: 6906.99 | C12: 310100 | D12: =C12-C11 -> 0 | E12: =C12-152000 -> 158100 | F12: =D12/$D$2 -> 0 | G12: 120.9 | H12: 8.6 | I12: =G12+H12 -> 129.5 | J12: =IF(L12>0,L12,0) -> 0 | K12: =I12+J12 -> 129.5 | L12: =F12-(I12-X12) -> 0 | M12: 4.1 | N12: 0 | O12: 0 | P12: =M12-(N12+O12) -> 4.1 | Q12: 0 | R12: 0 | S12: =SUM(P12:R12) -> 4.1 | U12: 0 | V12: 125.4 | W12: =W11-30 -> 11236.5 | X12: =N12+O12+S12+U12+V12 -> 129.5 | Y12: =IF(L12<0,L12*-1,0) -> 0 | Z12: =X12+Y12 -> 129.5 | AA12: 0 | AB12: 40 | AC12: 14 | AD12: =AD11+1 -> 3
A13: =A12+1 -> 4 | B13: 6906.98 | C13: 310060 | D13: =C13-C12 -> -40 | E13: =C13-152000 -> 158060 | F13: =D13/$D$2 -> -20.166373 | G13: 69.7 | H13: 9.5 | I13: =G13+H13 -> 79.2 | J13: =IF(L13>0,L13,0) -> 0.13362743 | K13: =I13+J13 -> 79.333627 | L13: =F13-(I13-X13) -> 0.13362743 | M13: 4.1 | N13: 0 | O13: 0 | P13: =M13-(N13+O13) -> 4.1 | Q13: 0 | R13: 0 | S13: =SUM(P13:R13) -> 4.1 | U13: 0 | V13: 95.4 | W13: =W12-30 -> 11206.5 | X13: =N13+O13+S13+U13+V13 -> 99.5 | Y13: =IF(L13<0,L13*-1,0) -> 0 | Z13: =X13+Y13 -> 99.5 | AA13: 0 | AB13: 46 | AC13: 14 | AD13: =AD12+1 -> 4
A14: =A13+1 -> 5 | B14: 6906.98 | C14: 310060 | D14: =C14-C13 -> 0 | E14: =C14-152000 -> 158060 | F14: =D14/$D$2 -> 0 | G14: 70.7 | H14: 10.1 | I14: =G14+H14 -> 80.8 | J14: =IF(L14>0,L14,0) -> 0.1 | K14: =I14+J14 -> 80.9 | L14: =F14-(I14-X14) -> 0.1 | M14: 4.1 | N14: 0 | O14: 0 | P14: =M14-(N14+O14) -> 4.1 | Q14: 0 | R14: 0 | S14: =SUM(P14:R14) -> 4.1 | U14: 0 | V14: 76.8 | W14: =W13-30 -> 11176.5 | X14: =N14+O14+S14+U14+V14 -> 80.9 | Y14: =IF(L14<0,L14*-1,0) -> 0 | Z14: =X14+Y14 -> 80.9 | AA14: 0 | AB14: 49 | AC14: 15 | AD14: =AD13+1 -> 5
A15: =A14+1 -> 6 | B15: 6906.97 | C15: 310022 | D15: =C15-C14 -> -38 | E15: =C15-152000 -> 158022 | F15: =D15/$D$2 -> -19.158054 | G15: 50 | H15: 11.8 | I15: =G15+H15 -> 61.8 | J15: =IF(L15>0,L15,0) -> 0.041946055 | K15: =I15+J15 -> 61.841946 | L15: =F15-(I15-X15) -> 0.041946055 | M15: 4.1 | N15: 0 | O15: 0 | P15: =M15-(N15+O15) -> 4.1 | Q15: 0 | R15: 0 | S15: =SUM(P15:R15) -> 4.1 | U15: 0 | V15: 76.9 | W15: =W14-30 -> 11146.5 | X15: =N15+O15+S15+U15+V15 -> 81 | Y15: =IF(L15<0,L15*-1,0) -> 0 | Z15: =X15+Y15 -> 81 | AA15: 0 | AB15: 51 | AC15: 24 | AD15: =AD14+1 -> 6
A16: =A15+1 -> 7 | B16: 6906.97 | C16: 310022 | D16: =C16-C15 -> 0 | E16: =C16-152000 -> 158022 | F16: =D16/$D$2 -> 0 | G16: 67.6 | H16: 14.1 | I16: =G16+H16 -> 81.7 | J16: =IF(L16>0,L16,0) -> 0.1 | K16: =I16+J16 -> 81.8 | L16: =F16-(I16-X16) -> 0.1 | M16: 4.1 | N16: 0 | O16: 0 | P16: =M16-(N16+O16) -> 4.1 | Q16: 0 | R16: 0 | S16: =SUM(P16:R16) -> 4.1 | U16: 0 | V16: 77.7 | W16: =W15-30 -> 11116.5 | X16: =N16+O16+S16+U16+V16 -> 81.8 | Y16: =IF(L16<0,L16*-1,0) -> 0 | Z16: =X16+Y16 -> 81.8 | AA16: 0 | AB16: 52 | AC16: 26 | AD16: =AD15+1 -> 7
A17: =A16+1 -> 8 | B17: 6907 | C17: 310138 | D17: =C17-C16 -> 116 | E17: =C17-152000 -> 158138 | F17: =D17/$D$2 -> 58.48248 | G17: 120.4 | H17: 19 | I17: =G17+H17 -> 139.4 | J17: =IF(L17>0,L17,0) -> 0 | K17: =I17+J17 -> 139.4 | L17: =F17-(I17-X17) -> -0.017519536 | M17: 4.1 | N17: 0 | O17: 0 | P17: =M17-(N17+O17) -> 4.1 | Q17: 0 | R17: 0 | S17: =SUM(P17:R17) -> 4.1 | U17: 0 | V17: 76.8 | W17: =W16-30 -> 11086.5 | X17: =N17+O17+S17+U17+V17 -> 80.9 | Y17: =IF(L17<0,L17*-1,0) -> 0.017519536 | Z17: =X17+Y17 -> 80.91752 | AA17: 0 | AB17: 59 | AC17: 25 | AD17: =AD16+1 -> 8
A18: =A17+1 -> 9 | B18: 6907.06 | C18: 310373 | D18: =C18-C17 -> 235 | E18: =C18-152000 -> 158373 | F18: =D18/$D$2 -> 118.47744 | G18: 159.7 | H18: 21.9 | I18: =G18+H18 -> 181.6 | J18: =IF(L18>0,L18,0) -> 18.577439 | K18: =I18+J18 -> 200.17744 | L18: =F18-(I18-X18) -> 18.577439 | M18: 4.6 | N18: 0 | O18: 0 | P18: =M18-(N18+O18) -> 4.6 | Q18: 0 | R18: 0 | S18: =SUM(P18:R18) -> 4.6 | U18: 0 | V18: 77.1 | W18: =W17-30 -> 11056.5 | X18: =N18+O18+S18+U18+V18 -> 81.7 | Y18: =IF(L18<0,L18*-1,0) -> 0 | Z18: =X18+Y18 -> 81.7 | AA18: 0 | AB18: 54 | AC18: 24 | AD18: =AD17+1 -> 9
A19: =A18+1 -> 10 | B19: 6907.12 | C19: 310609 | D19: =C19-C18 -> 236 | E19: =C19-152000 -> 158609 | F19: =D19/$D$2 -> 118.9816 | G19: 164.3 | H19: 27.8 | I19: =G19+H19 -> 192.1 | J19: =IF(L19>0,L19,0) -> 9.0815982 | K19: =I19+J19 -> 201.1816 | L19: =F19-(I19-X19) -> 9.0815982 | M19: 4.8 | N19: 0 | O19: 0 | P19: =M19-(N19+O19) -> 4.8 | Q19: 0 | R19: 0 | S19: =SUM(P19:R19) -> 4.8 | U19: 0 | V19: 77.4 | W19: =W18-30 -> 11026.5 | X19: =N19+O19+S19+U19+V19 -> 82.2 | Y19: =IF(L19<0,L19*-1,0) -> 0 | Z19: =X19+Y19 -> 82.2 | AA19: 0.02 | AB19: 41 | AC19: 34 | AD19: =AD18+1 -> 10
