Workbook

Sheet NOV
K1: MC PHEE RESERVOIR IN/OUT FLOW TABULATION
A2: AF/cfs CONVERT FACTOR | D2: 1.9835 | L2: NOVEMBER "1991"
A4: DATE | B4: RESERV | C4: RESERV | D4: AC FT | E4: ACTIVE | F4: CONV TO | G4: DOLORES | H4: LOST | I4: RECORDED | J4: CALC | K4: TOTAL | L4: CALC | M4: TUNNEL | Q4: LONE | R4: U | S4: TOTAL | T4: MVI | U4: DV CR | V4: BELOW | W4: REMAIN | X4: RECORDED | Y4: CALC | Z4: TOTAL | AA4: RAIN | AB4: MAX | AC4: MIN | AD4: DATE
A5: "NOV" | B5: ELEV | C5: AC FT | D5: CHANGE | E5: CAP | F5: CFS | G5: RIVER | H5: CANYON | I5: INFLOW | J5: INFLOW | K5: INFLOW | L5: INF/OTF | M5: TOT DIV | N5: WETLAND | O5: UTE F&R | P5: MVI,CTZ | Q5: PINE | R5: LAT | S5: MVI | T5: CALL | U5: CANAL | V5: MC PHEE | W5: RELEASE | X5: OUTFLOW | Y5: OUTFLOW | Z5: OUTFLOW | AB5: TMP | AC5: TMP | AD5: "NOV"
A7: SEASON BAL
A8: YTD | B8: 6903.02 | C8: 294853 | W8: 15240
A10: 1 | B10: 6903 | C10: 294777 | D10: =C10-C8 -> -76 | E10: =C10-152000 -> 142777 | F10: =D10/$D$2 -> -38.316108 | G10: 72 | H10: 0 | I10: =G10+H10 -> 72 | J10: =IF(L10>0,L10,0) -> 0 | K10: =I10+J10 -> 72 | L10: =F10-(I10-X10) -> -19.916108 | M10: 37.3 | N10: 0 | O10: 0 | P10: =M10-(N10+O10) -> 37.3 | Q10: 0 | R10: 18.2 | S10: =SUM(P10:R10) -> 55.5 | U10: 0 | V10: 34.9 | W10: =W8-V10 -> 15205.1 | X10: =N10+O10+S10+U10+V10 -> 90.4 | Y10: =IF(L10<0,L10*-1,0) -> 19.916108 | Z10: =X10+Y10 -> 110.31611 | AA10: 0 | AB10: 38 | AC10: 15 | AD10: 1
A11: =A10+1 -> 2 | B11: 6902.98 | C11: 294702 | D11: =C11-C10 -> -75 | E11: =C11-152000 -> 142702 | F11: =D11/$D$2 -> -37.811949 | G11: 59 | H11: 0 | I11: =G11+H11 -> 59 | J11: =IF(L11>0,L11,0) -> 0 | K11: =I11+J11 -> 59 | L11: =F11-(I11-X11) -> -5.7119486 | M11: 37.3 | N11: 0 | O11: 0 | P11: =M11-(N11+O11) -> 37.3 | Q11: 0 | R11: 18.2 | S11: =SUM(P11:R11) -> 55.5 | U11: 0 | V11: 35.6 | W11: =W10-V11 -> 15169.5 | X11: =N11+O11+S11+U11+V11 -> 91.1 | Y11: =IF(L11<0,L11*-1,0) -> 5.7119486 | Z11: =X11+Y11 -> 96.811949 | AA11: 0.27 | AB11: 37 | AC11: 10 | AD11: =AD10+1 -> 2
A12: =A11+1 -> 3 | B12: 6902.96 | C12: 294626 | D12: =C12-C11 -> -76 | E12: =C12-152000 -> 142626 | F12: =D12/$D$2 -> -38.316108 | G12: 59 | H12: 0 | I12: =G12+H12 -> 59 | J12: =IF(L12>0,L12,0) -> 0 | K12: =I12+J12 -> 59 | L12: =F12-(I12-X12) -> -6.4161079 | M12: 37.3 | N12: 0 | O12: 0 | P12: =M12-(N12+O12) -> 37.3 | Q12: 0 | R12: 17.9 | S12: =SUM(P12:R12) -> 55.2 | U12: 0 | V12: 35.7 | W12: =W11-V12 -> 15133.8 | X12: =N12+O12+S12+U12+V12 -> 90.9 | Y12: =IF(L12<0,L12*-1,0) -> 6.4161079 | Z12: =X12+Y12 -> 97.316108 | AA12: 0 | AB12: 38 | AC12: 11 | AD12: =AD11+1 -> 3
A13: =A12+1 -> 4 | B13: 6902.96 | C13: 294626 | D13: =C13-C12 -> 0 | E13: =C13-152000 -> 142626 | F13: =D13/$D$2 -> 0 | G13: 82.9 | H13: 0 | I13: =G13+H13 -> 82.9 | J13: =IF(L13>0,L13,0) -> 5.8 | K13: =I13+J13 -> 88.7 | L13: =F13-(I13-X13) -> 5.8 | M13: 37.3 | N13: 0 | O13: 0 | P13: =M13-(N13+O13) -> 37.3 | Q13: 0 | R13: 15.7 | S13: =SUM(P13:R13) -> 53 | U13: 0 | V13: 35.7 | W13: =W12-V13 -> 15098.1 | X13: =N13+O13+S13+U13+V13 -> 88.7 | Y13: =IF(L13<0,L13*-1,0) -> 0 | Z13: =X13+Y13 -> 88.7 | AA13: 0 | AB13: 44 | AC13: 6 | AD13: =AD12+1 -> 4
A14: =A13+1 -> 5 | B14: 6902.94 | C14: 294551 | D14: =C14-C13 -> -75 | E14: =C14-152000 -> 142551 | F14: =D14/$D$2 -> -37.811949 | G14: 93.7 | H14: 0 | I14: =G14+H14 -> 93.7 | J14: =IF(L14>0,L14,0) -> 0 | K14: =I14+J14 -> 93.7 | L14: =F14-(I14-X14) -> -49.411949 | M14: 32.2 | N14: 0 | O14: 0 | P14: =M14-(N14+O14) -> 32.2 | Q14: 0 | R14: 14.2 | S14: =SUM(P14:R14) -> 46.4 | U14: 0 | V14: 35.7 | W14: =W13-V14 -> 15062.4 | X14: =N14+O14+S14+U14+V14 -> 82.1 | Y14: =IF(L14<0,L14*-1,0) -> 49.411949 | Z14: =X14+Y14 -> 131.51195 | AA14: 0 | AB14: 52 | AC14: 17 | AD14: =AD13+1 -> 5
A15: =A14+1 -> 6 | B15: 6904.94 | C15: 294551 | D15: =C15-C14 -> 0 | E15: =C15-152000 -> 142551 | F15: =D15/$D$2 -> 0 | G15: 95.7 | H15: 0 | I15: =G15+H15 -> 95.7 | J15: =IF(L15>0,L15,0) -> 0 | K15: =I15+J15 -> 95.7 | L15: =F15-(I15-X15) -> -18.2 | M15: 27.6 | N15: 0 | O15: 0 | P15: =M15-(N15+O15) -> 27.6 | Q15: 0 | R15: 14.2 | S15: =SUM(P15:R15) -> 41.8 | U15: 0 | V15: 35.7 | W15: =W14-V15 -> 15026.7 | X15: =N15+O15+S15+U15+V15 -> 77.5 | Y15: =IF(L15<0,L15*-1,0) -> 18.2 | Z15: =X15+Y15 -> 95.7 | AA15: 0 | AB15: 59 | AC15: 20 | AD15: =AD14+1 -> 6
A16: =A15+1 -> 7 | B16: 6902.93 | C16: 294514 | D16: =C16-C15 -> -37 | E16: =C16-152000 -> 142514 | F16: =D16/$D$2 -> -18.653895 | G16: 91.7 | H16: 0 | I16: =G16+H16 -> 91.7 | J16: =IF(L16>0,L16,0) -> 0 | K16: =I16+J16 -> 91.7 | L16: =F16-(I16-X16) -> -32.853895 | M16: 27.6 | N16: 0 | O16: 0 | P16: =M16-(N16+O16) -> 27.6 | Q16: 0 | R16: 14.2 | S16: =SUM(P16:R16) -> 41.8 | U16: 0 | V16: 35.7 | W16: =W15-V16 -> 14991 | X16: =N16+O16+S16+U16+V16 -> 77.5 | Y16: =IF(L16<0,L16*-1,0) -> 32.853895 | Z16: =X16+Y16 -> 110.35389 | AA16: 0 | AB16: 58 | AC16: 32 | AD16: =AD15+1 -> 7
A17: =A16+1 -> 8 | B17: 6902.93 | C17: 294514 | D17: =C17-C16 -> 0 | E17: =C17-152000 -> 142514 | F17: =D17/$D$2 -> 0 | G17: 86.4 | H17: 0 | I17: =G17+H17 -> 86.4 | J17: =IF(L17>0,L17,0) -> 0 | K17: =I17+J17 -> 86.4 | L17: =F17-(I17-X17) -> -12.5 | M17: 25.9 | N17: 0 | O17: 0 | P17: =M17-(N17+O17) -> 25.9 | Q17: 0 | R17: 12.3 | S17: =SUM(P17:R17) -> 38.2 | U17: 0 | V17: 35.7 | W17: =W16-V17 -> 14955.3 | X17: =N17+O17+S17+U17+V17 -> 73.9 | Y17: =IF(L17<0,L17*-1,0) -> 12.5 | Z17: =X17+Y17 -> 86.4 | AA17: 0 | AB17: 57 | AC17: 30 | AD17: =AD16+1 -> 8
A18: =A17+1 -> 9 | B18: 6902.93 | C18: 294514 | D18: =C18-C17 -> 0 | E18: =C18-152000 -> 142514 | F18: =D18/$D$2 -> 0 | G18: 85.4 | H18: 0 | I18: =G18+H18 -> 85.4 | J18: =IF(L18>0,L18,0) -> 0 | K18: =I18+J18 -> 85.4 | L18: =F18-(I18-X18) -> -14 | M18: 24.8 | N18: 0 | O18: 0 | P18: =M18-(N18+O18) -> 24.8 | Q18: 0 | R18: 10.9 | S18: =SUM(P18:R18) -> 35.7 | U18: 0 | V18: 35.7 | W18: =W17-V18 -> 14919.6 | X18: =N18+O18+S18+U18+V18 -> 71.4 | Y18: =IF(L18<0,L18*-1,0) -> 14 | Z18: =X18+Y18 -> 85.4 | AA18: 0.07 | AB18: 57 | AC18: 31 | AD18: =AD17+1 -> 9
A19: =A18+1 -> 10 | B19: 6902.93 | C19: 294514 | D19: =C19-C18 -> 0 | E19: =C19-152000 -> 142514 | F19: =D19/$D$2 -> 0 | G19: 88.6 | H19: 0 | I19: =G19+H19 -> 88.6 | J19: =IF(L19>0,L19,0) -> 0 | K19: =I19+J19 -> 88.6 | L19: =F19-(I19-X19) -> -17.2 | M19: 24.8 | N19: 0 | O19: 0 | P19: =M19-(N19+O19) -> 24.8 | Q19: 0 | R19: 10.9 | S19: =SUM(P19:R19) -> 35.7 | U19: 0 | V19: 35.7 | W19: =W18-V19 -> 14883.9 | X19: =N19+O19+S19+U19+V19 -> 71.4 | Y19: =IF(L19<0,L19*-1,0) -> 17.2 | Z19: =X19+Y19 -> 88.6 | AA19: 0 | AB19: 58 | AC19: 31 | AD19: =AD18+1 -> 10
A20: =A19+1 -> 11 | B20: 6902.93 | C20: 294514 | D20: =C20-C19 -> 0 | E20: =C20-152000 -> 142514 | F20: =D20/$D$2 -> 0 | G20: 95.4 | H20: 0 | I20: =G20+H20 -> 95.4 | J20: =IF(L20>0,L20,0) -> 0 | K20: =I20+J20 -> 95.4 | L20: =F20-(I20-X20) -> -24.3 | M20: 24.8 | N20: 0 | O20: 0 | P20: =M20-(N20+O20) -> 24.8 | Q20: 0 | R20: 10.6 | S20: =SUM(P20:R20) -> 35.4 | U20: 0 | V20: 35.7 | W20: =W19-V20 -> 14848.2 | X20: =N20+O20+S20+U20+V20 -> 71.1 | Y20: =IF(L20<0,L20*-1,0) -> 24.3 | Z20: =X20+Y20 -> 95.4 | AA20: 0 | AB20: 53 | AC20: 32 | AD20: =AD19+1 -> 11
A21: =A20+1 -> 12 | B21: 6902.93 | C21: 294514 | D21: =C21-C20 -> 0 | E21: =C21-152000 -> 142514 | F21: =D21/$D$2 -> 0 | G21: 91.2 | H21: 0 | I21: =G21+H21 -> 91.2 | J21: =IF(L21>0,L21,0) -> 0 | K21: =I21+J21 -> 91.2 | L21: =F21-(I21-X21) -> -20.2 | M21: 24.8 | N21: 0 | O21: 0 | P21: =M21-(N21+O21) -> 24.8 | Q21: 0 | R21: 10.5 | S21: =SUM(P21:R21) -> 35.3 | U21: 0 | V21: 35.7 | W21: =W20-V21 -> 14812.5 | X21: =N21+O21+S21+U21+V21 -> 71 | Y21: =IF(L21<0,L21*-1,0) -> 20.2 | Z21: =X21+Y21 -> 91.2 | AA21: 0 | AB21: 55 | AC21: 26 | AD21: =AD20+1 -> 12
A22: =A21+1 -> 13 | B22: 6902.93 | C22: 294514 | D22: =C22-C21 -> 0 | E22: =C22-152000 -> 142514 | F22: =D22/$D$2 -> 0 | G22: 76.6 | H22: 0 | I22: =G22+H22 -> 76.6 | J22: =IF(L22>0,L22,0) -> 0 | K22: =I22+J22 -> 76.6 | L22: =F22-(I22-X22) -> -8.5 | M22: 23.2 | N22: 0 | O22: 0 | P22: =M22-(N22+O22) -> 23.2 | Q22: 0 | R22: 8.4 | S22: =SUM(P22:R22) -> 31.6 | U22: 0 | V22: 36.5 | W22: =W21-V22 -> 14776 | X22: =N22+O22+S22+U22+V22 -> 68.1 | Y22: =IF(L22<0,L22*-1,0) -> 8.5 | Z22: =X22+Y22 -> 76.6 | AA22: 0.99 | AB22: 54 | AC22: 24 | AD22: =AD21+1 -> 13
... A38: =A37+1 -> 29 | B38: 6903.39 | C38: 296257 | D38: =C38-C37 -> 39 | E38: =C38-152000 -> 144257 | F38: =D38/$D$2 -> 19.662213 | G38: 102.8 | H38: 1.7 | I38: =G38+H38 -> 104.5 | J38: =IF(L38>0,L38,0) -> 0 | K38: =I38+J38 -> 104.5 | L38: =F38-(I38-X38) -> -45.537787 | M38: 3.6 | N38: 0 | O38: 0 | P38: =M38-(N38+O38) -> 3.6 | Q38: 0 | R38: 0 | S38: =SUM(P38:R38) -> 3.6 | U38: 0 | V38: 35.7 | W38: =W37-V38 -> 14187.4 | X38: =N38+O38+S38+U38+V38 -> 39.3 | Y38: =IF(L38<0,L38*-1,0) -> 45.537787 | Z38: =X38+Y38 -> 84.837787 | AA38: 0.17 | AB38: 31 | AC38: 17 | AD38: =AD37+1 -> 29
A39: 30 | B39: 6903.41 | C39: 296333 | D39: =C39-C38 -> 76 | E39: =C39-152000 -> 144333 | F39: =D39/$D$2 -> 38.316108 | G39: 96.4 | H39: 1.7 | I39: =G39+H39 -> 98.1 | J39: =IF(L39>0,L39,0) -> 0 | K39: =I39+J39 -> 98.1 | L39: =F39-(I39-X39) -> -21.283892 | M39: 2.8 | N39: 0 | O39: 0 | P39: =M39-(N39+O39) -> 2.8 | Q39: 0 | R39: 0 | S39: =SUM(P39:R39) -> 2.8 | U39: 0 | V39: 35.7 | W39: =W38-V39 -> 14151.7 | X39: =N39+O39+S39+U39+V39 -> 38.5 | Y39: =IF(L39<0,L39*-1,0) -> 21.283892 | Z39: =X39+Y39 -> 59.783892 | AA39: 0 | AB39: 31 | AC39: 15 | AD39: 30
A41: MONTH / CFS | F41: =SUM(F10:F39) -> 746.15579 | G41: =SUM(G10:G40) -> 2980.9 | H41: =SUM(H10:H39) -> 25.7 | I41: =SUM(I10:I39) -> 3006.6 | J41: =SUM(J10:J39) -> 408.11109 | K41: =SUM(K10:K39) -> 3414.7111 | L41: =SUM(L10:L39) -> -352.24421 | M41: =SUM(M10:M39) -> 595.8 | N41: =SUM(N10:N39) -> 0 | O41: =SUM(O10:O39) -> 0 | ... S41: =SUM(S10:S39) -> 819.9 | U41: =SUM(U10:U39) -> 0 | V41: =SUM(V10:V39) -> 1088.3 | X41: =SUM(X10:X39) -> 1908.2 | Y41: =SUM(Y10:Y39) -> 760.35531 | Z41: =SUM(Z10:Z39) -> 2668.5553 | AA41: =SUM(AA10:AA39) -> 2.73 | AB41: =AVERAGE(AB10:AB39) -> 45.2 | AC41: =AVERAGE(AC10:AC39) -> 20.2 | AD41: AVE
A42: MONTH / AF | D42: =SUM(D10:D39) -> 1480 | F42: =F41*$D$2 -> 1480 | G42: =G41*$D$2 -> 5912.6151 | H42: =H41*$D$2 -> 50.97595 | I42: =I41*$D$2 -> 5963.5911 | J42: =J41*$D$2 -> 809.48835 | K42: =K41*$D$2 -> 6773.0795 | L42: =L41*$D$2 -> -698.6764 | M42: =M41*$D$2 -> 1181.7693 | ... S42: =S41*$D$2 -> 1626.2716 | U42: =U41*$D$2 -> 0 | V42: =V41*$D$2 -> 2158.6431 | X42: =X41*$D$2 -> 3784.9147 | Y42: =Y41*$D$2 -> 1508.1647 | Z42: =Z41*$D$2 -> 5293.0795 | AB42: =MAX(AB10:AB39) -> 59 | AC42: =MAX(AC10:AC39) -> 32 | AD42: HI
A44: SEASON / CFS | AB44: =MIN(AB10:AB39) -> 31 | AC44: =MIN(AC10:AC39) -> 2 | AD44: LO
A45: SEASON / AF
A47: YTD / CFS | F47: =F8+F41 -> 746.15579 | G47: =G8+G41 -> 2980.9 | H47: =H8+H41 -> 25.7 | I47: =I8+I41 -> 3006.6 | J47: =J8+J41 -> 408.11109 | K47: =K8+K41 -> 3414.7111 | L47: =L8+L41 -> -352.24421 | M47: =M8+M41 -> 595.8 | ... S47: =S8+S41 -> 819.9 | U47: =U8+U41 -> 0 | V47: =V8+V41 -> 1088.3 | W47: =W39 -> 14151.7 | X47: =X8+X41 -> 1908.2 | Y47: =Y8+Y41 -> 760.35531 | Z47: =Z8+Z41 -> 2668.5553 | AA47: =AA8+AA41 -> 2.73
A48: YTD / AF | D48: =D8+D42 -> 1480 | E48: =E39 -> 144333 | F48: =F47*$D$2 -> 1480 | G48: =G47*$D$2 -> 5912.6151 | H48: =H47*$D$2 -> 50.97595 | I48: =I47*$D$2 -> 5963.5911 | J48: =J47*$D$2 -> 809.48835 | K48: =K47*$D$2 -> 6773.0795 | L48: =L47*$D$2 -> -698.6764 | M48: =M47*$D$2 -> 1181.7693 | ... Z48: =Z47*$D$2 -> 5293.0795

Sheet DEC
K1: MC PHEE RESERVOIR IN/OUT FLOW TABULATION
A2: AF/cfs CONVERT FACTOR | D2: 1.9835 | K2: DECEMBER "1991"
A4: DATE | B4: RESERV | C4: RESERV | D4: AC FT | E4: ACTIVE | F4: CONV TO | G4: DOLORES | H4: LOST | I4: RECORDED | J4: CALC | K4: TOTAL | L4: CALC | M4: TUNNEL | Q4: LONE | R4: U | S4: TOTAL | T4: MVI | U4: DV CR | V4: BELOW | W4: REMAIN | X4: RECORDED | Y4: CALC | Z4: TOTAL | AA4: RAIN | AB4: MAX | AC4: MIN | AD4: DATE
A5: "DEC" | B5: ELEV | C5: AC FT | D5: CHANGE | E5: CAP | F5: CFS | G5: RIVER | H5: CANYON | I5: INFLOW | J5: INFLOW | K5: INFLOW | L5: INF/OTF | M5: TOT DIV | N5: WETLAND | O5: UTE F&R | P5: MVI,CTZ | Q5: PINE | R5: LAT | S5: MVI | T5: CALL | U5: CANAL | V5: MC PHEE | W5: RELEASE | X5: OUTFLOW | Y5: OUTFLOW | Z5: OUTFLOW | AB5: TMP | AC5: TMP | AD5: "DEC"
A7: SEASON BAL
A8: YTD | B8: =NOV!B39 -> 6903.41 | C8: =NOV!C39 -> 296333 | D8: =NOV!$D$48 -> 1480 | E8: =NOV!$E$39 -> 144333 | F8: =NOV!F47 -> 746.15579 | G8: =NOV!G47 -> 2980.9 | H8: =NOV!H47 -> 25.7 | I8: =NOV!I47 -> 3006.6 | J8: =NOV!J47 -> 408.11109 | K8: =NOV!K47 -> 3414.7111 | L8: =NOV!L47 -> -352.24421 | M8: =NOV!M47 -> 595.8 | ... AA8: =NOV!AA47 -> 2.73
A10: 1 | B10: 6903.43 | C10: 296409 | D10: =C10-C8 -> 76 | E10: =C10-152000 -> 144409 | F10: =D10/$D$2 -> 38.316108 | G10: 76.8 | H10: 0 | I10: =G10+H10 -> 76.8 | J10: =IF(L10>0,L10,0) -> 0.01610789 | K10: =I10+J10 -> 76.816108 | L10: =F10-(I10-X10) -> 0.01610789 | M10: 2.8 | N10: 0 | O10: 0 | P10: =M10-(N10+O10) -> 2.8 | Q10: 0 | R10: 0 | S10: =SUM(P10:R10) -> 2.8 | U10: 0 | V10: 35.7 | W10: =W8-V10 -> 14116 | X10: =N10+O10+S10+U10+V10 -> 38.5 | Y10: =IF(L10<0,L10*-1,0) -> 0 | Z10: =X10+Y10 -> 38.5 | AA10: 0.1 | AB10: 30 | AC10: 12 | AD10: 1
A11: =A10+1 -> 2 | B11: 6903.43 | C11: 296409 | D11: =C11-C10 -> 0 | E11: =C11-152000 -> 144409 | F11: =D11/$D$2 -> 0 | G11: 37.9 | H11: 0 | I11: =G11+H11 -> 37.9 | J11: =IF(L11>0,L11,0) -> 0 | K11: =I11+J11 -> 37.9 | L11: =F11-(I11-X11) -> 0 | M11: 2.8 | N11: 0 | O11: 0 | P11: =M11-(N11+O11) -> 2.8 | Q11: 0 | R11: 0 | S11: =SUM(P11:R11) -> 2.8 | U11: 0 | V11: 35.1 | W11: =W10-V11 -> 14080.9 | X11: =N11+O11+S11+U11+V11 -> 37.9 | Y11: =IF(L11<0,L11*-1,0) -> 0 | Z11: =X11+Y11 -> 37.9 | AA11: 0 | AB11: 25 | AC11: 11 | AD11: =AD10+1 -> 2
A12: =A11+1 -> 3 | B12: 6903.44 | C12: 296446 | D12: =C12-C11 -> 37 | E12: =C12-152000 -> 144446 | F12: =D12/$D$2 -> 18.653895 | G12: 56.7 | H12: 0 | I12: =G12+H12 -> 56.7 | J12: =IF(L12>0,L12,0) -> 0 | K12: =I12+J12 -> 56.7 | L12: =F12-(I12-X12) -> -0.046105369 | M12: 2.6 | N12: 0 | O12: 0 | P12: =M12-(N12+O12) -> 2.6 | Q12: 0 | R12: 0 | S12: =SUM(P12:R12) -> 2.6 | U12: 0 | V12: 35.4 | W12: =W11-V12 -> 14045.5 | X12: =N12+O12+S12+U12+V12 -> 38 | Y12: =IF(L12<0,L12*-1,0) -> 0.046105369 | Z12: =X12+Y12 -> 38.046105 | AA12: 0 | AB12: 34 | AC12: 7 | AD12: =AD11+1 -> 3
A13: =A12+1 -> 4 | B13: 6903.44 | C13: 296446 | D13: =C13-C12 -> 0 | E13: =C13-152000 -> 144446 | F13: =D13/$D$2 -> 0 | G13: 37.9 | H13: 0 | I13: =G13+H13 -> 37.9 | J13: =IF(L13>0,L13,0) -> 0 | K13: =I13+J13 -> 37.9 | L13: =F13-(I13-X13) -> 0 | M13: 2.2 | N13: 0 | O13: 0 | P13: =M13-(N13+O13) -> 2.2 | Q13: 0 | R13: 0 | S13: =SUM(P13:R13) -> 2.2 | U13: 0 | V13: 35.7 | W13: =W12-V13 -> 14009.8 | X13: =N13+O13+S13+U13+V13 -> 37.9 | Y13: =IF(L13<0,L13*-1,0) -> 0 | Z13: =X13+Y13 -> 37.9 | AA13: 0 | AB13: 36 | AC13: 6 | AD13: =AD12+1 -> 4
A14: =A13+1 -> 5 | B14: 6903.44 | C14: 296446 | D14: =C14-C13 -> 0 | E14: =C14-152000 -> 144446 | F14: =D14/$D$2 -> 0 | G14: 38.8 | H14: 0 | I14: =G14+H14 -> 38.8 | J14: =IF(L14>0,L14,0) -> 0 | K14: =I14+J14 -> 38.8 | L14: =F14-(I14-X14) -> 0 | M14: 2.7 | N14: 0 | O14: 0 | P14: =M14-(N14+O14) -> 2.7 | Q14: 0 | R14: 0 | S14: =SUM(P14:R14) -> 2.7 | U14: 0 | V14: 36.1 | W14: =W13-V14 -> 13973.7 | X14: =N14+O14+S14+U14+V14 -> 38.8 | Y14: =IF(L14<0,L14*-1,0) -> 0 | Z14: =X14+Y14 -> 38.8 | AA14: 0 | AB14: 40 | AC14: 12 | AD14: =AD13+1 -> 5
A15: =A14+1 -> 6 | B15: 6903.46 | C15: 296522 | D15: =C15-C14 -> 76 | E15: =C15-152000 -> 144522 | F15: =D15/$D$2 -> 38.316108 | G15: 77.7 | H15: 0 | I15: =G15+H15 -> 77.7 | J15: =IF(L15>0,L15,0) -> 0 | K15: =I15+J15 -> 77.7 | L15: =F15-(I15-X15) -> -0.08389211 | M15: 2.8 | N15: 0 | O15: 0 | P15: =M15-(N15+O15) -> 2.8 | Q15: 0 | R15: 0 | S15: =SUM(P15:R15) -> 2.8 | U15: 0 | V15: 36.5 | W15: =W14-V15 -> 13937.2 | X15: =N15+O15+S15+U15+V15 -> 39.3 | Y15: =IF(L15<0,L15*-1,0) -> 0.08389211 | Z15: =X15+Y15 -> 39.383892 | AA15: 0 | AB15: 43 | AC15: 16 | AD15: =AD14+1 -> 6
A16: =A15+1 -> 7 | B16: 6903.46 | C16: 296522 | D16: =C16-C15 -> 0 | E16: =C16-152000 -> 144522 | F16: =D16/$D$2 -> 0 | G16: 39 | H16: 0 | I16: =G16+H16 -> 39 | J16: =IF(L16>0,L16,0) -> 0 | K16: =I16+J16 -> 39 | L16: =F16-(I16-X16) -> 0 | M16: 2.5 | N16: 0 | O16: 0 | P16: =M16-(N16+O16) -> 2.5 | Q16: 0 | R16: 0 | S16: =SUM(P16:R16) -> 2.5 | U16: 0 | V16: 36.5 | W16: =W15-V16 -> 13900.7 | X16: =N16+O16+S16+U16+V16 -> 39 | Y16: =IF(L16<0,L16*-1,0) -> 0 | Z16: =X16+Y16 -> 39 | AA16: 0 | AB16: 47 | AC16: 17 | AD16: =AD15+1 -> 7
A17: =A16+1 -> 8 | B17: 6903.48 | C17: 296598 | D17: =C17-C16 -> 76 | E17: =C17-152000 -> 144598 | F17: =D17/$D$2 -> 38.316108 | G17: 77.3 | H17: 0 | I17: =G17+H17 -> 77.3 | J17: =IF(L17>0,L17,0) -> 0.01610789 | K17: =I17+J17 -> 77.316108 | L17: =F17-(I17-X17) -> 0.01610789 | M17: 2.5 | N17: 0 | O17: 0 | P17: =M17-(N17+O17) -> 2.5 | Q17: 0 | R17: 0 | S17: =SUM(P17:R17) -> 2.5 | U17: 0 | V17: 36.5 | W17: =W16-V17 -> 13864.2 | X17: =N17+O17+S17+U17+V17 -> 39 | Y17: =IF(L17<0,L17*-1,0) -> 0 | Z17: =X17+Y17 -> 39 | AA17: 0 | AB17: 49 | AC17: 20 | AD17: =AD16+1 -> 8
A18: =A17+1 -> 9 | B18: 6903.49 | C18: 296637 | D18: =C18-C17 -> 39 | E18: =C18-152000 -> 144637 | F18: =D18/$D$2 -> 19.662213 | G18: 59.4 | H18: 0 | I18: =G18+H18 -> 59.4 | J18: =IF(L18>0,L18,0) -> 0.26221326 | K18: =I18+J18 -> 59.662213 | L18: =F18-(I18-X18) -> 0.26221326 | M18: 3.5 | N18: 0 | O18: 0 | P18: =M18-(N18+O18) -> 3.5 | Q18: 0 | R18: 0 | S18: =SUM(P18:R18) -> 3.5 | U18: 0 | V18: 36.5 | W18: =W17-V18 -> 13827.7 | X18: =N18+O18+S18+U18+V18 -> 40 | Y18: =IF(L18<0,L18*-1,0) -> 0 | Z18: =X18+Y18 -> 40 | AA18: 0 | AB18: 45 | AC18: 22 | AD18: =AD17+1 -> 9
A19: =A18+1 -> 10 | B19: 6903.51 | C19: 296711 | D19: =C19-C18 -> 74 | E19: =C19-152000 -> 144711 | F19: =D19/$D$2 -> 37.307789 | G19: 74.2 | H19: 0 | I19: =G19+H19 -> 74.2 | J19: =IF(L19>0,L19,0) -> 0.0077892614 | K19: =I19+J19 -> 74.207789 | L19: =F19-(I19-X19) -> 0.0077892614 | M19: 3.7 | N19: 0 | O19: 0 | P19: =M19-(N19+O19) -> 3.7 | Q19: 0 | R19: 0 | S19: =SUM(P19:R19) -> 3.7 | U19: 0 | V19: 33.2 | W19: =W18-V19 -> 13794.5 | X19: =N19+O19+S19+U19+V19 -> 36.9 | Y19: =IF(L19<0,L19*-1,0) -> 0 | Z19: =X19+Y19 -> 36.9 | AA19: 0.2 | AB19: 48 | AC19: 20 | AD19: =AD18+1 -> 10
A20: =A19+1 -> 11 | B20: 6903.52 | C20: 296750 | D20: =C20-C19 -> 39 | E20: =C20-152000 -> 144750 | F20: =D20/$D$2 -> 19.662213 | G20: 53.8 | H20: 0 | I20: =G20+H20 -> 53.8 | J20: =IF(L20>0,L20,0) -> 0 | K20: =I20+J20 -> 53.8 | L20: =F20-(I20-X20) -> -0.037786741 | M20: 3.4 | N20: 0 | O20: 0 | P20: =M20-(N20+O20) -> 3.4 | Q20: 0 | R20: 0 | S20: =SUM(P20:R20) -> 3.4 | U20: 0 | V20: 30.7 | W20: =W19-V20 -> 13763.8 | X20: =N20+O20+S20+U20+V20 -> 34.1 | Y20: =IF(L20<0,L20*-1,0) -> 0.037786741 | Z20: =X20+Y20 -> 34.137787 | AA20: 0 | AB20: 38 | AC20: 18 | AD20: =AD19+1 -> 11
A21: =A20+1 -> 12 | B21: 6903.53 | C21: 296787 | D21: =C21-C20 -> 37 | E21: =C21-152000 -> 144787 | F21: =D21/$D$2 -> 18.653895 | G21: 52.5 | H21: 0 | I21: =G21+H21 -> 52.5 | J21: =IF(L21>0,L21,0) -> 0.053894631 | K21: =I21+J21 -> 52.553895 | L21: =F21-(I21-X21) -> 0.053894631 | M21: 3.4 | N21: 0 | O21: 0 | P21: =M21-(N21+O21) -> 3.4 | Q21: 0 | R21: 0 | S21: =SUM(P21:R21) -> 3.4 | U21: 0 | V21: 30.5 | W21: =W20-V21 -> 13733.3 | X21: =N21+O21+S21+U21+V21 -> 33.9 | Y21: =IF(L21<0,L21*-1,0) -> 0 | Z21: =X21+Y21 -> 33.9 | AA21: 0 | AB21: 34 | AC21: 20 | AD21: =AD20+1 -> 12
A22: =A21+1 -> 13 | B22: 6903.53 | C22: 296787 | D22: =C22-C21 -> 0 | E22: =C22-152000 -> 144787 | F22: =D22/$D$2 -> 0 | G22: 33.9 | H22: 0 | I22: =G22+H22 -> 33.9 | J22: =IF(L22>0,L22,0) -> 0 | K22: =I22+J22 -> 33.9 | L22: =F22-(I22-X22) -> 0 | M22: 3.4 | N22: 0 | O22: 0 | P22: =M22-(N22+O22) -> 3.4 | Q22: 0 | R22: 0 | S22: =SUM(P22:R22) -> 3.4 | U22: 0 | V22: 30.5 | W22: =W21-V22 -> 13702.8 | X22: =N22+O22+S22+U22+V22 -> 33.9 | Y22: =IF(L22<0,L22*-1,0) -> 0 | Z22: =X22+Y22 -> 33.9 | AA22: 0 | AB22: 39 | AC22: 16 | AD22: =AD21+1 -> 13
... A38: =A37+1 -> 29 | B38: 6903.69 | C38: 297395 | D38: =C38-C37 -> 37 | E38: =C38-152000 -> 145395 | F38: =D38/$D$2 -> 18.653895 | G38: 51.7 | H38: 0 | I38: =G38+H38 -> 51.7 | J38: =IF(L38>0,L38,0) -> 0 | K38: =I38+J38 -> 51.7 | L38: =F38-(I38-X38) -> -0.046105369 | M38: 3.4 | N38: 0 | O38: 0 | P38: =M38-(N38+O38) -> 3.4 | Q38: 0 | R38: 0 | S38: =SUM(P38:R38) -> 3.4 | U38: 0 | V38: 29.6 | W38: =W37-V38 -> 13220.7 | X38: =N38+O38+S38+U38+V38 -> 33 | Y38: =IF(L38<0,L38*-1,0) -> 0.046105369 | Z38: =X38+Y38 -> 33.046105 | AA38: 0 | AB38: 38 | AC38: 10 | AD38: =AD37+1 -> 29
A39: 30 | B39: 6903.7 | C39: 297434 | D39: =C39-C38 -> 39 | E39: =C39-152000 -> 145434 | F39: =D39/$D$2 -> 19.662213 | G39: 52.6 | H39: 0 | I39: =G39+H39 -> 52.6 | J39: =IF(L39>0,L39,0) -> 0.062213259 | K39: =I39+J39 -> 52.662213 | L39: =F39-(I39-X39) -> 0.062213259 | M39: 3.4 | N39: 0 | O39: 0 | P39: =M39-(N39+O39) -> 3.4 | Q39: 0 | R39: 0 | S39: =SUM(P39:R39) -> 3.4 | U39: 0 | V39: 29.6 | W39: =W38-V39 -> 13191.1 | X39: =N39+O39+S39+U39+V39 -> 33 | Y39: =IF(L39<0,L39*-1,0) -> 0 | Z39: =X39+Y39 -> 33 | AA39: 0.19 | AB39: 34 | AC39: 8 | AD39: 30
A40: 31 | B40: 6903.71 | C40: 297471 | D40: =C40-C39 -> 37 | E40: =C40-152000 -> 145471 | F40: =D40/$D$2 -> 18.653895 | G40: 51.7 | H40: 0 | I40: =G40+H40 -> 51.7 | J40: =IF(L40>0,L40,0) -> 0.053894631 | K40: =I40+J40 -> 51.753895 | L40: =F40-(I40-X40) -> 0.053894631 | M40: 3.4 | N40: 0 | O40: 0 | P40: =M40-(N40+O40) -> 3.4 | Q40: 0 | R40: 0 | S40: =SUM(P40:R40) -> 3.4 | U40: 0 | V40: 29.7 | W40: =W39-V40 -> 13161.4 | X40: =N40+O40+S40+U40+V40 -> 33.1 | Y40: =IF(L40<0,L40*-1,0) -> 0 | Z40: =X40+Y40 -> 33.1 | AA40: 0 | AB40: 31 | AC40: 14 | AD40: 31
A42: MONTH / CFS | F42: =SUM(F10:F40) -> 573.7333 | G42: =SUM(G10:G40) -> 1662.6 | H42: =SUM(H10:H40) -> 0 | I42: =SUM(I10:I40) -> 1662.6 | J42: =SUM(J10:J40) -> 0.74444164 | K42: =SUM(K10:K40) -> 1663.3444 | L42: =SUM(L10:L40) -> 0.43329972 | M42: =SUM(M10:M40) -> 99 | ... S42: =SUM(S10:S40) -> 99 | U42: =SUM(U10:U40) -> 0 | V42: =SUM(V10:V40) -> 990.3 | X42: =SUM(X10:X40) -> 1089.3 | Y42: =SUM(Y10:Y40) -> 0.31114192 | Z42: =SUM(Z10:Z40) -> 1089.6111 | AA42: =SUM(AA10:AA40) -> 1.11 | AB42: =AVERAGE(AB10:AB40) -> 38.806452 | AC42: =AVERAGE(AC10:AC40) -> 15.322581 | AD42: AVE
A43: MONTH / AF | D43: =SUM(D10:D40) -> 1138 | F43: =F42*$D$2 -> 1138 | G43: =G42*$D$2 -> 3297.7671 | H43: =H42*$D$2 -> 0 | I43: =I42*$D$2 -> 3297.7671 | J43: =J42*$D$2 -> 1.4766 | K43: =K42*$D$2 -> 3299.2437 | L43: =L42*$D$2 -> 0.85945 | M43: =M42*$D$2 -> 196.3665 | ... S43: =S42*$D$2 -> 196.3665 | U43: =U42*$D$2 -> 0 | V43: =V42*$D$2 -> 1964.2601 | X43: =X42*$D$2 -> 2160.6265 | Y43: =Y42*$D$2 -> 0.61715 | Z43: =Z42*$D$2 -> 2161.2437 | AB43: =MAX(AB10:AB40) -> 49 | AC43: =MAX(AC10:AC40) -> 30 | AD43: HI
A45: SEASON / CFS | AB45: =MIN(AB10:AB40) -> 25 | AC45: =MIN(AC10:AC40) -> 5 | AD45: LO
A46: SEASON / AF
A48: YTD / CFS | F48: =F8+F42 -> 1319.8891 | G48: =G8+G42 -> 4643.5 | H48: =H8+H42 -> 25.7 | I48: =I8+I42 -> 4669.2 | J48: =J8+J42 -> 408.85553 | K48: =K8+K42 -> 5078.0555 | L48: =L8+L42 -> -351.81092 | M48: =M8+M42 -> 694.8 | ... S48: =S8+S42 -> 918.9 | U48: =U8+U42 -> 0 | V48: =V8+V42 -> 2078.6 | W48: =W40 -> 13161.4 | X48: =X8+X42 -> 2997.5 | Y48: =Y8+Y42 -> 760.66645 | Z48: =Z8+Z42 -> 3758.1664 | AA48: =AA8+AA42 -> 3.84
A49: YTD / AF | D49: =D8+D43 -> 2618 | E49: =E40 -> 145471 | F49: =F48*$D$2 -> 2618 | G49: =G48*$D$2 -> 9210.3823 | H49: =H48*$D$2 -> 50.97595 | I49: =I48*$D$2 -> 9261.3582 | J49: =J48*$D$2 -> 810.96495 | K49: =K48*$D$2 -> 10072.323 | L49: =L48*$D$2 -> -697.81695 | M49: =M48*$D$2 -> 1378.1358 | ... V49: =V48*$D$2 -> 4122.9031 | W49: =W40*$D$2 -> 26105.637 | X49: =X48*$D$2 -> 5945.5413 | Y49: =Y48*$D$2 -> 1508.7819 | Z49: =Z48*$D$2 -> 7454.3232

Sheet JAN
K1: MC PHEE RESERVOIR IN/OUT FLOW TABULATION
A2: AF/cfs CONVERT FACTOR | D2: 1.9835 | K2: JANUARY "1992"
A4: DATE | B4: RESERV | C4: RESERV | D4: AC FT | E4: ACTIVE | F4: CONV TO | G4: DOLORES | H4: LOST | I4: RECORDED | J4: CALC | K4: TOTAL | L4: CALC | M4: TUNNEL | Q4: LONE | R4: U | S4: TOTAL | T4: MVI | U4: DV CR | V4: BELOW | W4: REMAIN | X4: RECORDED | Y4: CALC | Z4: TOTAL | AA4: RAIN | AB4: MAX | AC4: MIN | AD4: DATE
A5: "JAN" | B5: ELEV | C5: AC FT | D5: CHANGE | E5: CAP | F5: CFS | G5: RIVER | H5: CANYON | I5: INFLOW | J5: INFLOW | K5: INFLOW | L5: INF/OTF | M5: TOT DIV | N5: WETLAND | O5: UTE F&R | P5: MVI,CTZ | Q5: PINE | R5: LAT | S5: MVI | T5: CALL | U5: CANAL | V5: MC PHEE | W5: RELEASE | X5: OUTFLOW | Y5: OUTFLOW | Z5: OUTFLOW | AB5: TMP | AC5: TMP | AD5: "JAN"
A7: SEASON BAL
A8: YTD | B8: =DEC!B40 -> 6903.71 | C8: =DEC!C40 -> 297471 | D8: =DEC!$D$49 -> 2618 | E8: =DEC!$E$40 -> 145471 | F8: =DEC!F48 -> 1319.8891 | G8: =DEC!G48 -> 4643.5 | H8: =DEC!H48 -> 25.7 | I8: =DEC!I48 -> 4669.2 | J8: =DEC!J48 -> 408.85553 | K8: =DEC!K48 -> 5078.0555 | L8: =DEC!L48 -> -351.81092 | M8: =DEC!M48 -> 694.8 | ... AA8: =DEC!AA48 -> 3.84
A10: 1 | B10: 6903.71 | C10: 297471 | D10: =C10-C8 -> 0 | E10: =C10-152000 -> 145471 | F10: =D10/$D$2 -> 0 | G10: 32.9 | H10: 0 | I10: =G10+H10 -> 32.9 | J10: =IF(L10>0,L10,0) -> 0.1 | K10: =I10+J10 -> 33 | L10: =F10-(I10-X10) -> 0.1 | M10: 3.4 | N10: 0 | O10: 0 | P10: =M10-(N10+O10) -> 3.4 | Q10: 0 | R10: 0 | S10: =SUM(P10:R10) -> 3.4 | U10: 0 | V10: 29.6 | W10: =W8-V10 -> 13131.8 | X10: =N10+O10+S10+U10+V10 -> 33 | Y10: =IF(L10<0,L10*-1,0) -> 0 | Z10: =X10+Y10 -> 33 | AA10: 0 | AB10: 33 | AC10: 1 | AD10: 1
A11: =A10+1 -> 2 | B11: 6903.72 | C11: 297510 | D11: =C11-C10 -> 39 | E11: =C11-152000 -> 145510 | F11: =D11/$D$2 -> 19.662213 | G11: 52.5 | H11: 0 | I11: =G11+H11 -> 52.5 | J11: =IF(L11>0,L11,0) -> 0 | K11: =I11+J11 -> 52.5 | L11: =F11-(I11-X11) -> -0.037786741 | M11: 3.4 | N11: 0 | O11: 0 | P11: =M11-(N11+O11) -> 3.4 | Q11: 0 | R11: 0 | S11: =SUM(P11:R11) -> 3.4 | U11: 0 | V11: 29.4 | W11: =W10-V11 -> 13102.4 | X11: =N11+O11+S11+U11+V11 -> 32.8 | Y11: =IF(L11<0,L11*-1,0) -> 0.037786741 | Z11: =X11+Y11 -> 32.837787 | AA11: 0 | AB11: 27 | AC11: 4 | AD11: =AD10+1 -> 2
A12: =A11+1 -> 3 | B12: 6903.73 | C12: 297547 | D12: =C12-C11 -> 37 | E12: =C12-152000 -> 145547 | F12: =D12/$D$2 -> 18.653895 | G12: 51.2 | H12: 0 | I12: =G12+H12 -> 51.2 | J12: =IF(L12>0,L12,0) -> 0.053894631 | K12: =I12+J12 -> 51.253895 | L12: =F12-(I12-X12) -> 0.053894631 | M12: 3.4 | N12: 0 | O12: 0 | P12: =M12-(N12+O12) -> 3.4 | Q12: 0 | R12: 0 | S12: =SUM(P12:R12) -> 3.4 | U12: 0 | V12: 29.2 | W12: =W11-V12 -> 13073.2 | X12: =N12+O12+S12+U12+V12 -> 32.6 | Y12: =IF(L12<0,L12*-1,0) -> 0 | Z12: =X12+Y12 -> 32.6 | AA12: 0 | AB12: 29 | AC12: 0 | AD12: =AD11+1 -> 3
A13: =A12+1 -> 4 | B13: 6903.74 | C13: 297585 | D13: =C13-C12 -> 38 | E13: =C13-152000 -> 145585 | F13: =D13/$D$2 -> 19.158054 | G13: 52 | H13: 0 | I13: =G13+H13 -> 52 | J13: =IF(L13>0,L13,0) -> 0 | K13: =I13+J13 -> 52 | L13: =F13-(I13-X13) -> -0.041946055 | M13: 3.4 | N13: 0 | O13: 0 | P13: =M13-(N13+O13) -> 3.4 | Q13: 0 | R13: 0 | S13: =SUM(P13:R13) -> 3.4 | U13: 0 | V13: 29.4 | W13: =W12-V13 -> 13043.8 | X13: =N13+O13+S13+U13+V13 -> 32.8 | Y13: =IF(L13<0,L13*-1,0) -> 0.041946055 | Z13: =X13+Y13 -> 32.841946 | AA13: 0.25 | AB13: 31 | AC13: 6 | AD13: =AD12+1 -> 4
A14: =A13+1 -> 5 | B14: 6903.76 | C14: 297660 | D14: =C14-C13 -> 75 | E14: =C14-152000 -> 145660 | F14: =D14/$D$2 -> 37.811949 | G14: 70.5 | H14: 0 | I14: =G14+H14 -> 70.5 | J14: =IF(L14>0,L14,0) -> 0.011948576 | K14: =I14+J14 -> 70.511949 | L14: =F14-(I14-X14) -> 0.011948576 | M14: 3.4 | N14: 0 | O14: 0 | P14: =M14-(N14+O14) -> 3.4 | Q14: 0 | R14: 0 | S14: =SUM(P14:R14) -> 3.4 | U14: 0 | V14: 29.3 | W14: =W13-V14 -> 13014.5 | X14: =N14+O14+S14+U14+V14 -> 32.7 | Y14: =IF(L14<0,L14*-1,0) -> 0 | Z14: =X14+Y14 -> 32.7 | AA14: 0 | AB14: 36 | AC14: 12 | AD14: =AD13+1 -> 5
A15: =A14+1 -> 6 | B15: 6903.8 | C15: 297812 | D15: =C15-C14 -> 152 | E15: =C15-152000 -> 145812 | F15: =D15/$D$2 -> 76.632216 | G15: 109.3 | H15: 0 | I15: =G15+H15 -> 109.3 | J15: =IF(L15>0,L15,0) -> 0 | K15: =I15+J15 -> 109.3 | L15: =F15-(I15-X15) -> -0.06778422 | M15: 3.4 | N15: 0 | O15: 0 | P15: =M15-(N15+O15) -> 3.4 | Q15: 0 | R15: 0 | S15: =SUM(P15:R15) -> 3.4 | U15: 0 | V15: 29.2 | W15: =W14-V15 -> 12985.3 | X15: =N15+O15+S15+U15+V15 -> 32.6 | Y15: =IF(L15<0,L15*-1,0) -> 0.06778422 | Z15: =X15+Y15 -> 32.667784 | AA15: 0.34 | AB15: 36 | AC15: 22 | AD15: =AD14+1 -> 6
A16: =A15+1 -> 7 | B16: 6903.83 | C16: 297926 | D16: =C16-C15 -> 114 | E16: =C16-152000 -> 145926 | F16: =D16/$D$2 -> 57.474162 | G16: 91.4 | H16: 0 | I16: =G16+H16 -> 91.4 | J16: =IF(L16>0,L16,0) -> 0 | K16: =I16+J16 -> 91.4 | L16: =F16-(I16-X16) -> -0.025838165 | M16: 4.3 | N16: 0 | O16: 0 | P16: =M16-(N16+O16) -> 4.3 | Q16: 0 | R16: 0 | S16: =SUM(P16:R16) -> 4.3 | U16: 0 | V16: 29.6 | W16: =W15-V16 -> 12955.7 | X16: =N16+O16+S16+U16+V16 -> 33.9 | Y16: =IF(L16<0,L16*-1,0) -> 0.025838165 | Z16: =X16+Y16 -> 33.925838 | AA16: 0.5 | AB16: 26 | AC16: 20 | AD16: =AD15+1 -> 7
A17: =A16+1 -> 8 | B17: 6903.85 | C17: 298002 | D17: =C17-C16 -> 76 | E17: =C17-152000 -> 146002 | F17: =D17/$D$2 -> 38.316108 | G17: 72.7 | H17: 0 | I17: =G17+H17 -> 72.7 | J17: =IF(L17>0,L17,0) -> 0.01610789 | K17: =I17+J17 -> 72.716108 | L17: =F17-(I17-X17) -> 0.01610789 | M17: 5.2 | N17: 0 | O17: 0 | P17: =M17-(N17+O17) -> 5.2 | Q17: 0 | R17: 0 | S17: =SUM(P17:R17) -> 5.2 | U17: 0 | V17: 29.2 | W17: =W16-V17 -> 12926.5 | X17: =N17+O17+S17+U17+V17 -> 34.4 | Y17: =IF(L17<0,L17*-1,0) -> 0 | Z17: =X17+Y17 -> 34.4 | AA17: 0 | AB17: 34 | AC17: 10 | AD17: =AD16+1 -> 8
A18: =A17+1 -> 9 | B18: 6903.86 | C18: 298039 | D18: =C18-C17 -> 37 | E18: =C18-152000 -> 146039 | F18: =D18/$D$2 -> 18.653895 | G18: 53.1 | H18: 0 | I18: =G18+H18 -> 53.1 | J18: =IF(L18>0,L18,0) -> 0.053894631 | K18: =I18+J18 -> 53.153895 | L18: =F18-(I18-X18) -> 0.053894631 | M18: 5.1 | N18: 0 | O18: 0 | P18: =M18-(N18+O18) -> 5.1 | Q18: 0 | R18: 0 | S18: =SUM(P18:R18) -> 5.1 | U18: 0 | V18: 29.4 | W18: =W17-V18 -> 12897.1 | X18: =N18+O18+S18+U18+V18 -> 34.5 | Y18: =IF(L18<0,L18*-1,0) -> 0 | Z18: =X18+Y18 -> 34.5 | AA18: 0 | AB18: 34 | AC18: 0 | AD18: =AD17+1 -> 9
A19: =A18+1 -> 10 | B19: 6903.85 | C19: 298002 | D19: =C19-C18 -> -37 | E19: =C19-152000 -> 146002 | F19: =D19/$D$2 -> -18.653895 | G19: 53.8 | H19: 0 | I19: =G19+H19 -> 53.8 | J19: =IF(L19>0,L19,0) -> 0 | K19: =I19+J19 -> 53.8 | L19: =F19-(I19-X19) -> -37.353895 | M19: 5.4 | N19: 0 | O19: 0 | P19: =M19-(N19+O19) -> 5.4 | Q19: 0 | R19: 0 | S19: =SUM(P19:R19) -> 5.4 | U19: 0 | V19: 29.7 | W19: =W18-V19 -> 12867.4 | X19: =N19+O19+S19+U19+V19 -> 35.1 | Y19: =IF(L19<0,L19*-1,0) -> 37.353895 | Z19: =X19+Y19 -> 72.453895 | AA19: 0 | AB19: 36 | AC19: 1 | AD19: =AD18+1 -> 10
A20: =A19+1 -> 11 | B20: 6903.84 | C20: 297936 | D20: =C20-C19 -> -66 | E20: =C20-152000 -> 145936 | F20: =D20/$D$2 -> -33.274515 | G20: 55.4 | H20: 0 | I20: =G20+H20 -> 55.4 | J20: =IF(L20>0,L20,0) -> 0 | K20: =I20+J20 -> 55.4 | L20: =F20-(I20-X20) -> -53.474515 | M20: 5.5 | N20: 0 | O20: 0 | P20: =M20-(N20+O20) -> 5.5 | Q20: 0 | R20: 0 | S20: =SUM(P20:R20) -> 5.5 | U20: 0 | V20: 29.7 | W20: =W19-V20 -> 12837.7 | X20: =N20+O20+S20+U20+V20 -> 35.2 | Y20: =IF(L20<0,L20*-1,0) -> 53.474515 | Z20: =X20+Y20 -> 88.674515 | AA20: 0 | AB20: 34 | AC20: 6 | AD20: =AD19+1 -> 11
A21: =A20+1 -> 12 | B21: 6903.85 | C21: 298002 | D21: =C21-C20 -> 66 | E21: =C21-152000 -> 146002 | F21: =D21/$D$2 -> 33.274515 | G21: 68.5 | H21: 0 | I21: =G21+H21 -> 68.5 | J21: =IF(L21>0,L21,0) -> 0 | K21: =I21+J21 -> 68.5 | L21: =F21-(I21-X21) -> -0.025485253 | M21: 5.5 | N21: 0 | O21: 0 | P21: =M21-(N21+O21) -> 5.5 | Q21: 0 | R21: 0 | S21: =SUM(P21:R21) -> 5.5 | U21: 0 | V21: 29.7 | W21: =W20-V21 -> 12808 | X21: =N21+O21+S21+U21+V21 -> 35.2 | Y21: =IF(L21<0,L21*-1,0) -> 0.025485253 | Z21: =X21+Y21 -> 35.225485 | AA21: 0 | AB21: 36 | AC21: 4 | AD21: =AD20+1 -> 12
A22: 13 | B22: 6903.86 | C22: 298039 | D22: =C22-C21 -> 37 | E22: =C22-152000 -> 146039 | F22: =D22/$D$2 -> 18.653895 | G22: 53.5 | H22: 0 | I22: =G22+H22 -> 53.5 | J22: =IF(L22>0,L22,0) -> 0.053894631 | K22: =I22+J22 -> 53.553895 | L22: =F22-(I22-X22) -> 0.053894631 | M22: 5.2 | N22: 0 | O22: 0 | P22: =M22-(N22+O22) -> 5.2 | Q22: 0 | R22: 0 | S22: =SUM(P22:R22) -> 5.2 | U22: 0 | V22: 29.7 | W22: =W21-V22 -> 12778.3 | X22: =N22+O22+S22+U22+V22 -> 34.9 | Y22: =IF(L22<0,L22*-1,0) -> 0 | Z22: =X22+Y22 -> 34.9 | AA22: 0 | AB22: 32 | AC22: 2 | AD22: =AD21+1 -> 13
A23: =A22+1 -> 14 | B23: 6903.88 | C23: 298115 | D23: =C23-C22 -> 76 | E23: =C23-152000 -> 146115 | F23: =D23/$D$2 -> 38.316108 | G23: 72.9 | H23: 0 | I23: =G23+H23 -> 72.9 | J23: =IF(L23>0,L23,0) -> 0.01610789 | K23: =I23+J23 -> 72.916108 | L23: =F23-(I23-X23) -> 0.01610789 | M23: 4.9 | N23: 0 | O23: 0 | P23: =M23-(N23+O23) -> 4.9 | Q23: 0 | R23: 0 | S23: =SUM(P23:R23) -> 4.9 | U23: 0 | V23: 29.7 | W23: =W22-V23 -> 12748.6 | X23: =N23+O23+S23+U23+V23 -> 34.6 | Y23: =IF(L23<0,L23*-1,0) -> 0 | Z23: =X23+Y23 -> 34.6 | AA23: 0 | AB23: 34 | AC23: 4 | AD23: =AD22+1 -> 14
A24: =A23+1 -> 15 | B24: 6903.89 | C24: 298154 | D24: =C24-C23 -> 39 | E24: =C24-152000 -> 146154 | F24: =D24/$D$2 -> 19.662213 | G24: 53.7 | H24: 0 | I24: =G24+H24 -> 53.7 | J24: =IF(L24>0,L24,0) -> 0 | K24: =I24+J24 -> 53.7 | L24: =F24-(I24-X24) -> -0.037786741 | M24: 4.3 | N24: 0 | O24: 0 | P24: =M24-(N24+O24) -> 4.3 | Q24: 0 | R24: 0 | S24: =SUM(P24:R24) -> 4.3 | U24: 0 | V24: 29.7 | W24: =W23-V24 -> 12718.9 | X24: =N24+O24+S24+U24+V24 -> 34 | Y24: =IF(L24<0,L24*-1,0) -> 0.037786741 | Z24: =X24+Y24 -> 34.037787 | AA24: 0 | AB24: 32 | AC24: 8 | AD24: =AD23+1 -> 15
A25: =A24+1 -> 16 | B25: 6903.89 | C25: 298154 | D25: =C25-C24 -> 0 | E25: =C25-152000 -> 146154 | F25: =D25/$D$2 -> 0 | G25: 33.3 | H25: 0 | I25: =G25+H25 -> 33.3 | J25: =IF(L25>0,L25,0) -> 0 | K25: =I25+J25 -> 33.3 | L25: =F25-(I25-X25) -> 0 | M25: 3.6 | N25: 0 | O25: 0 | P25: =M25-(N25+O25) -> 3.6 | Q25: 0 | R25: 0 | S25: =SUM(P25:R25) -> 3.6 | U25: 0 | V25: 29.7 | W25: =W24-V25 -> 12689.2 | X25: =N25+O25+S25+U25+V25 -> 33.3 | Y25: =IF(L25<0,L25*-1,0) -> 0 | Z25: =X25+Y25 -> 33.3 | AA25: 0 | AB25: 34 | AC25: 4 | AD25: =AD24+1 -> 16
A26: =A25+1 -> 17 | B26: 6903.89 | C26: 298154 | D26: =C26-C25 -> 0 | E26: =C26-152000 -> 146154 | F26: =D26/$D$2 -> 0 | G26: 33.4 | H26: 0 | I26: =G26+H26 -> 33.4 | J26: =IF(L26>0,L26,0) -> 0 | K26: =I26+J26 -> 33.4 | L26: =F26-(I26-X26) -> 0 | M26: 3.7 | N26: 0 | O26: 0 | P26: =M26-(N26+O26) -> 3.7 | Q26: 0 | R26: 0 | S26: =SUM(P26:R26) -> 3.7 | U26: 0 | V26: 29.7 | W26: =W25-V26 -> 12659.5 | X26: =N26+O26+S26+U26+V26 -> 33.4 | Y26: =IF(L26<0,L26*-1,0) -> 0 | Z26: =X26+Y26 -> 33.4 | AA26: 0 | AB26: 36 | AC26: 5 | AD26: =AD25+1 -> 17
A27: =A26+1 -> 18 | B27: 6903.89 | C27: 298154 | D27: =C27-C26 -> 0 | E27: =C27-152000 -> 146154 | F27: =D27/$D$2 -> 0 | G27: 33.4 | H27: 0 | I27: =G27+H27 -> 33.4 | J27: =IF(L27>0,L27,0) -> 0 | K27: =I27+J27 -> 33.4 | L27: =F27-(I27-X27) -> 0 | M27: 3.7 | N27: 0 | O27: 0 | P27: =M27-(N27+O27) -> 3.7 | Q27: 0 | R27: 0 | S27: =SUM(P27:R27) -> 3.7 | U27: 0 | V27: 29.7 | W27: =W26-V27 -> 12629.8 | X27: =N27+O27+S27+U27+V27 -> 33.4 | Y27: =IF(L27<0,L27*-1,0) -> 0 | Z27: =X27+Y27 -> 33.4 | AA27: 0 | AB27: 38 | AC27: 6 | AD27: =AD26+1 -> 18
A28: =A27+1 -> 19 | B28: 6903.89 | C28: 298154 | D28: =C28-C27 -> 0 | E28: =C28-152000 -> 146154 | F28: =D28/$D$2 -> 0 | G28: 33.4 | H28: 0 | I28: =G28+H28 -> 33.4 | J28: =IF(L28>0,L28,0) -> 0 | K28: =I28+J28 -> 33.4 | L28: =F28-(I28-X28) -> 0 | M28: 3.7 | N28: 0 | O28: 0 | P28: =M28-(N28+O28) -> 3.7 | Q28: 0 | R28: 0 | S28: =SUM(P28:R28) -> 3.7 | U28: 0 | V28: 29.7 | W28: =W27-V28 -> 12600.1 | X28: =N28+O28+S28+U28+V28 -> 33.4 | Y28: =IF(L28<0,L28*-1,0) -> 0 | Z28: =X28+Y28 -> 33.4 | AA28: 0 | AB28: 40 | AC28: 7 | AD28: =AD27+1 -> 19
A29: =A28+1 -> 20 | B29: 6903.89 | C29: 298154 | D29: =C29-C28 -> 0 | E29: =C29-152000 -> 146154 | F29: =D29/$D$2 -> 0 | G29: 33.2 | H29: 0 | I29: =G29+H29 -> 33.2 | J29: =IF(L29>0,L29,0) -> 0 | K29: =I29+J29 -> 33.2 | L29: =F29-(I29-X29) -> 0 | M29: 3.5 | N29: 0 | O29: 0 | P29: =M29-(N29+O29) -> 3.5 | Q29: 0 | R29: 0 | S29: =SUM(P29:R29) -> 3.5 | U29: 0 | V29: 29.7 | W29: =W28-V29 -> 12570.4 | X29: =N29+O29+S29+U29+V29 -> 33.2 | Y29: =IF(L29<0,L29*-1,0) -> 0 | Z29: =X29+Y29 -> 33.2 | AA29: 0 | AB29: 38 | AC29: 9 | AD29: =AD28+1 -> 20
A30: =A29+1 -> 21 | B30: 6903.89 | C30: 298154 | D30: =C30-C29 -> 0 | E30: =C30-152000 -> 146154 | F30: =D30/$D$2 -> 0 | G30: 33.2 | H30: 0 | I30: =G30+H30 -> 33.2 | J30: =IF(L30>0,L30,0) -> 0 | K30: =I30+J30 -> 33.2 | L30: =F30-(I30-X30) -> 0 | M30: 3.5 | N30: 0 | O30: 0 | P30: =M30-(N30+O30) -> 3.5 | Q30: 0 | R30: 0 | S30: =SUM(P30:R30) -> 3.5 | U30: 0 | V30: 29.7 | W30: =W29-V30 -> 12540.7 | X30: =N30+O30+S30+U30+V30 -> 33.2 | Y30: =IF(L30<0,L30*-1,0) -> 0 | Z30: =X30+Y30 -> 33.2 | AA30: 0 | AB30: 38 | AC30: 6 | AD30: =AD29+1 -> 21
A31: =A30+1 -> 22 | B31: 6903.89 | C31: 298154 | D31: =C31-C30 -> 0 | E31: =C31-152000 -> 146154 | F31: =D31/$D$2 -> 0 | G31: 33.2 | H31: 0 | I31: =G31+H31 -> 33.2 | J31: =IF(L31>0,L31,0) -> 0 | K31: =I31+J31 -> 33.2 | L31: =F31-(I31-X31) -> 0 | M31: 3.5 | N31: 0 | O31: 0 | P31: =M31-(N31+O31) -> 3.5 | Q31: 0 | R31: 0 | S31: =SUM(P31:R31) -> 3.5 | U31: 0 | V31: 29.7 | W31: =W30-V31 -> 12511 | X31: =N31+O31+S31+U31+V31 -> 33.2 | Y31: =IF(L31<0,L31*-1,0) -> 0 | Z31: =X31+Y31 -> 33.2 | AA31: 0 | AB31: 36 | AC31: 9 | AD31: =AD30+1 -> 22
A32: =A31+1 -> 23 | B32: 6903.89 | C32: 298154 | D32: =C32-C31 -> 0 | E32: =C32-152000 -> 146154 | F32: =D32/$D$2 -> 0 | G32: 33.2 | H32: 0 | I32: =G32+H32 -> 33.2 | J32: =IF(L32>0,L32,0) -> 0 | K32: =I32+J32 -> 33.2 | L32: =F32-(I32-X32) -> 0 | M32: 3.5 | N32: 0 | O32: 0 | P32: =M32-(N32+O32) -> 3.5 | Q32: 0 | R32: 0 | S32: =SUM(P32:R32) -> 3.5 | U32: 0 | V32: 29.7 | W32: =W31-V32 -> 12481.3 | X32: =N32+O32+S32+U32+V32 -> 33.2 | Y32: =IF(L32<0,L32*-1,0) -> 0 | Z32: =X32+Y32 -> 33.2 | AA32: 0 | AB32: 36 | AC32: 12 | AD32: =AD31+1 -> 23
A33: =A32+1 -> 24 | B33: 6903.89 | C33: 298154 | D33: =C33-C32 -> 0 | E33: =C33-152000 -> 146154 | F33: =D33/$D$2 -> 0 | G33: 33.2 | H33: 0 | I33: =G33+H33 -> 33.2 | J33: =IF(L33>0,L33,0) -> 0 | K33: =I33+J33 -> 33.2 | L33: =F33-(I33-X33) -> 0 | M33: 3.5 | N33: 0 | O33: 0 | P33: =M33-(N33+O33) -> 3.5 | Q33: 0 | R33: 0 | S33: =SUM(P33:R33) -> 3.5 | U33: 0 | V33: 29.7 | W33: =W32-V33 -> 12451.6 | X33: =N33+O33+S33+U33+V33 -> 33.2 | Y33: =IF(L33<0,L33*-1,0) -> 0 | Z33: =X33+Y33 -> 33.2 | AA33: 0 | AB33: 44 | AC33: 12 | AD33: =AD32+1 -> 24
A34: =A33+1 -> 25 | B34: 6903.9 | C34: 298191 | D34: =C34-C33 -> 37 | E34: =C34-152000 -> 146191 | F34: =D34/$D$2 -> 18.653895 | G34: 51.9 | H34: 0 | I34: =G34+H34 -> 51.9 | J34: =IF(L34>0,L34,0) -> 0 | K34: =I34+J34 -> 51.9 | L34: =F34-(I34-X34) -> -0.046105369 | M34: 3.5 | N34: 0 | O34: 0 | P34: =M34-(N34+O34) -> 3.5 | Q34: 0 | R34: 0 | S34: =SUM(P34:R34) -> 3.5 | U34: 0 | V34: 29.7 | W34: =W33-V34 -> 12421.9 | X34: =N34+O34+S34+U34+V34 -> 33.2 | Y34: =IF(L34<0,L34*-1,0) -> 0.046105369 | Z34: =X34+Y34 -> 33.246105 | AA34: 0 | AB34: 48 | AC34: 12 | AD34: =AD33+1 -> 25
... A38: =A37+1 -> 29 | B38: 6903.94 | C38: 298343 | D38: =C38-C37 -> 37 | E38: =C38-152000 -> 146343 | F38: =D38/$D$2 -> 18.653895 | G38: 52.1 | H38: 0 | I38: =G38+H38 -> 52.1 | J38: =IF(L38>0,L38,0) -> 0 | K38: =I38+J38 -> 52.1 | L38: =F38-(I38-X38) -> -0.046105369 | M38: 3.7 | N38: 0 | O38: 0 | P38: =M38-(N38+O38) -> 3.7 | Q38: 0 | R38: 0 | S38: =SUM(P38:R38) -> 3.7 | U38: 0 | V38: 29.7 | W38: =W37-V38 -> 12303.1 | X38: =N38+O38+S38+U38+V38 -> 33.4 | Y38: =IF(L38<0,L38*-1,0) -> 0.046105369 | Z38: =X38+Y38 -> 33.446105 | AA38: 0 | AB38: 44 | AC38: 14 | AD38: =AD37+1 -> 29
A39: 30 | B39: 6903.95 | C39: 298382 | D39: =C39-C38 -> 39 | E39: =C39-152000 -> 146382 | F39: =D39/$D$2 -> 19.662213 | G39: 53.3 | H39: 0 | I39: =G39+H39 -> 53.3 | J39: =IF(L39>0,L39,0) -> 0 | K39: =I39+J39 -> 53.3 | L39: =F39-(I39-X39) -> -0.037786741 | M39: 3.9 | N39: 0 | O39: 0 | P39: =M39-(N39+O39) -> 3.9 | Q39: 0 | R39: 0 | S39: =SUM(P39:R39) -> 3.9 | U39: 0 | V39: 29.7 | W39: =W38-V39 -> 12273.4 | X39: =N39+O39+S39+U39+V39 -> 33.6 | Y39: =IF(L39<0,L39*-1,0) -> 0.037786741 | Z39: =X39+Y39 -> 33.637787 | AA39: 0 | AB39: 49 | AC39: 17 | AD39: 30
A40: 31 | B40: 6903.96 | C40: 298419 | D40: =C40-C39 -> 37 | E40: =C40-152000 -> 146419 | F40: =D40/$D$2 -> 18.653895 | G40: 52.5 | H40: 0 | I40: =G40+H40 -> 52.5 | J40: =IF(L40>0,L40,0) -> 0 | K40: =I40+J40 -> 52.5 | L40: =F40-(I40-X40) -> -0.046105369 | M40: 4.1 | N40: 0 | O40: 0 | P40: =M40-(N40+O40) -> 4.1 | Q40: 0 | R40: 0 | S40: =SUM(P40:R40) -> 4.1 | U40: 0 | V40: 29.7 | W40: =W39-V40 -> 12243.7 | X40: =N40+O40+S40+U40+V40 -> 33.8 | Y40: =IF(L40<0,L40*-1,0) -> 0.046105369 | Z40: =X40+Y40 -> 33.846105 | AA40: 0 | AB40: 52 | AC40: 19 | AD40: 31
AB41: 39
A42: MONTH / CFS | F42: =SUM(F10:F40) -> 477.94303 | G42: =SUM(G10:G40) -> 1610.9 | H42: =SUM(H10:H40) -> 0 | I42: =SUM(I10:I40) -> 1610.9 | J42: =SUM(J10:J40) -> 0.42195614 | K42: =SUM(K10:K40) -> 1611.322 | L42: =SUM(L10:L40) -> -90.85697 | M42: =SUM(M10:M40) -> 124.4 | ... S42: =SUM(S10:S40) -> 124.4 | U42: =SUM(U10:U40) -> 0 | V42: =SUM(V10:V40) -> 917.7 | X42: =SUM(X10:X40) -> 1042.1 | Y42: =SUM(Y10:Y40) -> 91.278926 | Z42: =SUM(Z10:Z40) -> 1133.3789 | AA42: =SUM(AA10:AA40) -> 1.09 | AB42: =AVERAGE(AB10:AB40) -> 37.548387 | AC42: =AVERAGE(AC10:AC40) -> 8.9677419 | AD42: AVE
A43: MONTH / AF | D43: =SUM(D10:D40) -> 948 | F43: =F42*$D$2 -> 948 | G43: =G42*$D$2 -> 3195.2202 | H43: =H42*$D$2 -> 0 | I43: =I42*$D$2 -> 3195.2202 | J43: =J42*$D$2 -> 0.83695 | K43: =K42*$D$2 -> 3196.0571 | L43: =L42*$D$2 -> -180.2148 | M43: =M42*$D$2 -> 246.7474 | ... S43: =S42*$D$2 -> 246.7474 | U43: =U42*$D$2 -> 0 | V43: =V42*$D$2 -> 1820.2579 | X43: =X42*$D$2 -> 2067.0053 | Y43: =Y42*$D$2 -> 181.05175 | Z43: =Z42*$D$2 -> 2248.0571 | AB43: =MAX(AB10:AB40) -> 52 | AC43: =MAX(AC10:AC40) -> 22 | AD43: HI
A45: SEASON / CFS | AB45: =MIN(AB10:AB40) -> 26 | AC45: =MIN(AC10:AC40) -> 0 | AD45: LO
A46: SEASON / AF
A48: YTD / CFS | F48: =F8+F42 -> 1797.8321 | G48: =G8+G42 -> 6254.4 | H48: =H8+H42 -> 25.7 | I48: =I8+I42 -> 6280.1 | J48: =J8+J42 -> 409.27749 | K48: =K8+K42 -> 6689.3775 | L48: =L8+L42 -> -442.66789 | M48: =M8+M42 -> 819.2 | ... S48: =S8+S42 -> 1043.3 | U48: =U8+U42 -> 0 | V48: =V8+V42 -> 2996.3 | W48: =W40 -> 12243.7 | X48: =X8+X42 -> 4039.6 | Y48: =Y8+Y42 -> 851.94537 | Z48: =Z8+Z42 -> 4891.5454 | AA48: =AA8+AA42 -> 4.93
...

Sheet FEB
K1: MC PHEE RESERVOIR IN/OUT FLOW TABULATION
A2: AF/cfs CONVERT FACTOR | D2: 1.9835 | K2: FEBRUARY "1992"
A4: DATE | B4: RESERV | C4: RESERV | D4: AC FT | E4: ACTIVE | F4: CONV TO | G4: DOLORES | H4: LOST | I4: RECORDED | J4: CALC | K4: TOTAL | L4: CALC | M4: TUNNEL | Q4: LONE | R4: U | S4: TOTAL | T4: MVI | U4: DV CR | V4: BELOW | W4: REMAIN | X4: RECORDED | Y4: CALC | Z4: TOTAL | AA4: RAIN | AB4: MAX | AC4: MIN | AD4: DATE
A5: FEB | B5: ELEV | C5: AC FT | D5: CHANGE | E5: CAP | F5: CFS | G5: RIVER | H5: CANYON | I5: INFLOW | J5: INFLOW | K5: INFLOW | L5: INF/OTF | M5: TOT DIV | N5: WETLAND | O5: UTE F&R | P5: MVI,CTZ | Q5: PINE | R5: LAT | S5: MVI | T5: CALL | U5: CANAL | V5: MC PHEE | W5: RELEASE | X5: OUTFLOW | Y5: OUTFLOW | Z5: OUTFLOW | AB5: TMP | AC5: TMP | AD5: FEB
A7: SEASON BAL
A8: YTD | B8: =JAN!B40 -> 6903.96 | C8: =JAN!C40 -> 298419 | D8: =JAN!$D$49 -> 3566 | E8: =JAN!$E$40 -> 146419 | F8: =JAN!F48 -> 1797.8321 | G8: =JAN!G48 -> 6254.4 | H8: =JAN!H48 -> 25.7 | I8: =JAN!I48 -> 6280.1 | J8: =JAN!J48 -> 409.27749 | K8: =JAN!K48 -> 6689.3775 | L8: =JAN!L48 -> -442.66789 | M8: =JAN!M48 -> 819.2 | ... AA8: =JAN!AA48 -> 4.93
A10: 1 | B10: 6903.97 | C10: 298454 | D10: =C10-C8 -> 35 | E10: =C10-152000 -> 146454 | F10: =D10/$D$2 -> 17.645576 | G10: 51.7 | H10: 0 | I10: =G10+H10 -> 51.7 | J10: =IF(L10>0,L10,0) -> 0.045576002 | K10: =I10+J10 -> 51.745576 | L10: =F10-(I10-X10) -> 0.045576002 | M10: 4.4 | N10: 0 | O10: 0 | P10: =M10-(N10+O10) -> 4.4 | Q10: 0 | R10: 0 | S10: =SUM(P10:R10) -> 4.4 | U10: 0 | V10: 29.7 | W10: =W8-V10 -> 12214 | X10: =N10+O10+S10+U10+V10 -> 34.1 | Y10: =IF(L10<0,L10*-1,0) -> 0 | Z10: =X10+Y10 -> 34.1 | AA10: 0 | AB10: 53 | AC10: 12 | AD10: 1
A11: =A10+1 -> 2 | B11: 6903.98 | C11: 298495 | D11: =C11-C10 -> 41 | E11: =C11-152000 -> 146495 | F11: =D11/$D$2 -> 20.670532 | G11: 54.8 | H11: 0 | I11: =G11+H11 -> 54.8 | J11: =IF(L11>0,L11,0) -> 0.00053188808 | K11: =I11+J11 -> 54.800532 | L11: =F11-(I11-X11) -> 0.00053188808 | M11: 4.4 | N11: 0 | O11: 0 | P11: =M11-(N11+O11) -> 4.4 | Q11: 0 | R11: 0 | S11: =SUM(P11:R11) -> 4.4 | U11: 0 | V11: 29.73 | W11: =W10-V11 -> 12184.27 | X11: =N11+O11+S11+U11+V11 -> 34.13 | Y11: =IF(L11<0,L11*-1,0) -> 0 | Z11: =X11+Y11 -> 34.13 | AA11: 0 | AB11: 52 | AC11: 18 | AD11: =AD10+1 -> 2
A12: =A11+1 -> 3 | B12: 6903.98 | C12: 298495 | D12: =C12-C11 -> 0 | E12: =C12-152000 -> 146495 | F12: =D12/$D$2 -> 0 | G12: 33.5 | H12: 0 | I12: =G12+H12 -> 33.5 | J12: =IF(L12>0,L12,0) -> 0 | K12: =I12+J12 -> 33.5 | L12: =F12-(I12-X12) -> 0 | M12: 3.8 | N12: 0 | O12: 0 | P12: =M12-(N12+O12) -> 3.8 | Q12: 0 | R12: 0 | S12: =SUM(P12:R12) -> 3.8 | U12: 0 | V12: 29.7 | W12: =W11-V12 -> 12154.57 | X12: =N12+O12+S12+U12+V12 -> 33.5 | Y12: =IF(L12<0,L12*-1,0) -> 0 | Z12: =X12+Y12 -> 33.5 | AA12: 0 | AB12: 44 | AC12: 25 | AD12: =AD11+1 -> 3
A13: =A12+1 -> 4 | B13: 6903.99 | C13: 298534 | D13: =C13-C12 -> 39 | E13: =C13-152000 -> 146534 | F13: =D13/$D$2 -> 19.662213 | G13: 52.9 | H13: 0 | I13: =G13+H13 -> 52.9 | J13: =IF(L13>0,L13,0) -> 0.062213259 | K13: =I13+J13 -> 52.962213 | L13: =F13-(I13-X13) -> 0.062213259 | M13: 3.6 | N13: 0 | O13: 0 | P13: =M13-(N13+O13) -> 3.6 | Q13: 0 | R13: 0 | S13: =SUM(P13:R13) -> 3.6 | U13: 0 | V13: 29.7 | W13: =W12-V13 -> 12124.87 | X13: =N13+O13+S13+U13+V13 -> 33.3 | Y13: =IF(L13<0,L13*-1,0) -> 0 | Z13: =X13+Y13 -> 33.3 | AA13: 0 | AB13: 40 | AC13: 28 | AD13: =AD12+1 -> 4
A14: =A13+1 -> 5 | B14: 6904 | C14: 298571 | D14: =C14-C13 -> 37 | E14: =C14-152000 -> 146571 | F14: =D14/$D$2 -> 18.653895 | G14: 52.4 | H14: 0 | I14: =G14+H14 -> 52.4 | J14: =IF(L14>0,L14,0) -> 0 | K14: =I14+J14 -> 52.4 | L14: =F14-(I14-X14) -> -0.046105369 | M14: 4 | N14: 0 | O14: 0 | P14: =M14-(N14+O14) -> 4 | Q14: 0 | R14: 0 | S14: =SUM(P14:R14) -> 4 | U14: 0 | V14: 29.7 | W14: =W13-V14 -> 12095.17 | X14: =N14+O14+S14+U14+V14 -> 33.7 | Y14: =IF(L14<0,L14*-1,0) -> 0.046105369 | Z14: =X14+Y14 -> 33.746105 | AA14: 0 | AB14: 40 | AC14: 14 | AD14: =AD13+1 -> 5
A15: =A14+1 -> 6 | B15: 6904.01 | C15: 298608 | D15: =C15-C14 -> 37 | E15: =C15-152000 -> 146608 | F15: =D15/$D$2 -> 18.653895 | G15: 51.8 | H15: 0 | I15: =G15+H15 -> 51.8 | J15: =IF(L15>0,L15,0) -> 0.053894631 | K15: =I15+J15 -> 51.853895 | L15: =F15-(I15-X15) -> 0.053894631 | M15: 3.5 | N15: 0 | O15: 0 | P15: =M15-(N15+O15) -> 3.5 | Q15: 0 | R15: 0 | S15: =SUM(P15:R15) -> 3.5 | U15: 0 | V15: 29.7 | W15: =W14-V15 -> 12065.47 | X15: =N15+O15+S15+U15+V15 -> 33.2 | Y15: =IF(L15<0,L15*-1,0) -> 0 | Z15: =X15+Y15 -> 33.2 | AA15: 0 | AB15: 48 | AC15: 14 | AD15: =AD14+1 -> 6
A16: =A15+1 -> 7 | B16: 6904.02 | C16: 298648 | D16: =C16-C15 -> 40 | E16: =C16-152000 -> 146648 | F16: =D16/$D$2 -> 20.166373 | G16: 53.8 | H16: 0 | I16: =G16+H16 -> 53.8 | J16: =IF(L16>0,L16,0) -> 0 | K16: =I16+J16 -> 53.8 | L16: =F16-(I16-X16) -> -0.033627426 | M16: 3.7 | N16: 0 | O16: 0 | P16: =M16-(N16+O16) -> 3.7 | Q16: 0 | R16: 0 | S16: =SUM(P16:R16) -> 3.7 | U16: 0 | V16: 29.9 | W16: =W15-V16 -> 12035.57 | X16: =N16+O16+S16+U16+V16 -> 33.6 | Y16: =IF(L16<0,L16*-1,0) -> 0.033627426 | Z16: =X16+Y16 -> 33.633627 | AA16: 0 | AB16: 42 | AC16: 19 | AD16: =AD15+1 -> 7
A17: =A16+1 -> 8 | B17: 6904.03 | C17: 298685 | D17: =C17-C16 -> 37 | E17: =C17-152000 -> 146685 | F17: =D17/$D$2 -> 18.653895 | G17: 52.3 | H17: 0 | I17: =G17+H17 -> 52.3 | J17: =IF(L17>0,L17,0) -> 0 | K17: =I17+J17 -> 52.3 | L17: =F17-(I17-X17) -> -0.046105369 | M17: 3.7 | N17: 0 | O17: 0 | P17: =M17-(N17+O17) -> 3.7 | Q17: 0 | R17: 0 | S17: =SUM(P17:R17) -> 3.7 | U17: 0 | V17: 29.9 | W17: =W16-V17 -> 12005.67 | X17: =N17+O17+S17+U17+V17 -> 33.6 | Y17: =IF(L17<0,L17*-1,0) -> 0.046105369 | Z17: =X17+Y17 -> 33.646105 | AA17: 0 | AB17: 43 | AC17: 29 | AD17: =AD16+1 -> 8
A18: =A17+1 -> 9 | B18: 6904.04 | C18: 298724 | D18: =C18-C17 -> 39 | E18: =C18-152000 -> 146724 | F18: =D18/$D$2 -> 19.662213 | G18: 53.6 | H18: 0 | I18: =G18+H18 -> 53.6 | J18: =IF(L18>0,L18,0) -> 0.062213259 | K18: =I18+J18 -> 53.662213 | L18: =F18-(I18-X18) -> 0.062213259 | M18: 3.7 | N18: 0 | O18: 0 | P18: =M18-(N18+O18) -> 3.7 | Q18: 0 | R18: 0 | S18: =SUM(P18:R18) -> 3.7 | U18: 0 | V18: 30.3 | W18: =W17-V18 -> 11975.37 | X18: =N18+O18+S18+U18+V18 -> 34 | Y18: =IF(L18<0,L18*-1,0) -> 0 | Z18: =X18+Y18 -> 34 | AA18: 0 | AB18: 41 | AC18: 25 | AD18: =AD17+1 -> 9
A19: =A18+1 -> 10 | B19: 6904.06 | C19: 298801 | D19: =C19-C18 -> 77 | E19: =C19-152000 -> 146801 | F19: =D19/$D$2 -> 38.820267 | G19: 72.8 | H19: 0 | I19: =G19+H19 -> 72.8 | J19: =IF(L19>0,L19,0) -> 0.020267204 | K19: =I19+J19 -> 72.820267 | L19: =F19-(I19-X19) -> 0.020267204 | M19: 3.7 | N19: 0 | O19: 0 | P19: =M19-(N19+O19) -> 3.7 | Q19: 0 | R19: 0 | S19: =SUM(P19:R19) -> 3.7 | U19: 0 | V19: 30.3 | W19: =W18-V19 -> 11945.07 | X19: =N19+O19+S19+U19+V19 -> 34 | Y19: =IF(L19<0,L19*-1,0) -> 0 | Z19: =X19+Y19 -> 34 | AA19: 0.3 | AB19: 40 | AC19: 23 | AD19: =AD18+1 -> 10
A20: =A19+1 -> 11 | B20: 6904.11 | C20: 298991 | D20: =C20-C19 -> 190 | E20: =C20-152000 -> 146991 | F20: =D20/$D$2 -> 95.79027 | G20: 130 | H20: 0 | I20: =G20+H20 -> 130 | J20: =IF(L20>0,L20,0) -> 0 | K20: =I20+J20 -> 130 | L20: =F20-(I20-X20) -> -0.0097302748 | M20: 3.7 | N20: 0 | O20: 0 | P20: =M20-(N20+O20) -> 3.7 | Q20: 0 | R20: 0 | S20: =SUM(P20:R20) -> 3.7 | U20: 0 | V20: 30.5 | W20: =W19-V20 -> 11914.57 | X20: =N20+O20+S20+U20+V20 -> 34.2 | Y20: =IF(L20<0,L20*-1,0) -> 0.0097302748 | Z20: =X20+Y20 -> 34.20973 | AA20: 0.23 | AB20: 42 | AC20: 20 | AD20: =AD19+1 -> 11
A21: =A20+1 -> 12 | B21: 6904.13 | C21: 299068 | D21: =C21-C20 -> 77 | E21: =C21-152000 -> 147068 | F21: =D21/$D$2 -> 38.820267 | G21: 73.5 | H21: 0 | I21: =G21+H21 -> 73.5 | J21: =IF(L21>0,L21,0) -> 0 | K21: =I21+J21 -> 73.5 | L21: =F21-(I21-X21) -> -0.039732796 | M21: 4.14 | N21: 0 | O21: 0 | P21: =M21-(N21+O21) -> 4.14 | Q21: 0 | R21: 0 | S21: =SUM(P21:R21) -> 4.14 | U21: 0 | V21: 30.5 | W21: =W20-V21 -> 11884.07 | X21: =N21+O21+S21+U21+V21 -> 34.64 | Y21: =IF(L21<0,L21*-1,0) -> 0.039732796 | Z21: =X21+Y21 -> 34.679733 | AA21: 0.01 | AB21: 42 | AC21: 29 | AD21: =AD20+1 -> 12
A22: =A21+1 -> 13 | B22: 6904.16 | C22: 299184 | D22: =C22-C21 -> 116 | E22: =C22-152000 -> 147184 | F22: =D22/$D$2 -> 58.48248 | G22: 93.7 | H22: 0 | I22: =G22+H22 -> 93.7 | J22: =IF(L22>0,L22,0) -> 0 | K22: =I22+J22 -> 93.7 | L22: =F22-(I22-X22) -> -0.017519536 | M22: 4.7 | N22: 0 | O22: 0 | P22: =M22-(N22+O22) -> 4.7 | Q22: 0 | R22: 0 | S22: =SUM(P22:R22) -> 4.7 | U22: 0 | V22: 30.5 | W22: =W21-V22 -> 11853.57 | X22: =N22+O22+S22+U22+V22 -> 35.2 | Y22: =IF(L22<0,L22*-1,0) -> 0.017519536 | Z22: =X22+Y22 -> 35.21752 | AA22: 0 | AB22: 40 | AC22: 30 | AD22: =AD21+1 -> 13
... A36: =A35+1 -> 27 | B36: 6904.44 | C36: 300254 | D36: =C36-C35 -> 191 | E36: =C36-152000 -> 148254 | F36: =D36/$D$2 -> 96.294429 | G36: 130.2 | H36: 0 | I36: =G36+H36 -> 130.2 | J36: =IF(L36>0,L36,0) -> 0 | K36: =I36+J36 -> 130.2 | L36: =F36-(I36-X36) -> -0.0055709604 | M36: 3.4 | N36: 0 | O36: 0 | P36: =M36-(N36+O36) -> 3.4 | Q36: 0 | R36: 0 | S36: =SUM(P36:R36) -> 3.4 | U36: 0 | V36: 30.5 | W36: =W35-V36 -> 11426.47 | X36: =N36+O36+S36+U36+V36 -> 33.9 | Y36: =IF(L36<0,L36*-1,0) -> 0.0055709604 | Z36: =X36+Y36 -> 33.905571 | AA36: 0 | AB36: 53 | AC36: 18 | AD36: =AD35+1 -> 27
A37: 28 | B37: 6904.45 | C37: 300293 | D37: =C37-C36 -> 39 | E37: =C37-152000 -> 148293 | F37: =D37/$D$2 -> 19.662213 | G37: 53.7 | H37: 0 | I37: =G37+H37 -> 53.7 | J37: =IF(L37>0,L37,0) -> 0.062213259 | K37: =I37-J37 -> 53.637787 | L37: =F37-(I37-X37) -> 0.062213259 | M37: 3.6 | N37: 0 | O37: 0 | P37: =M37-(N37+O37) -> 3.6 | Q37: 0 | R37: 0 | S37: =SUM(P37:R37) -> 3.6 | U37: 0 | V37: 30.5 | W37: =W36-V37 -> 11395.97 | X37: =N37+O37+S37+U37+V37 -> 34.1 | Y37: =IF(L37<0,L37*-1,0) -> 0 | Z37: =X37+Y37 -> 34.1 | AA37: 0 | AB37: 57 | AC37: 19 | AD37: 28
A38: 29 | B38: 6904.48 | C38: 300407 | D38: =C38-C37 -> 114 | E38: =C38-152000 -> 148407 | F38: =D38/$D$2 -> 57.474162 | G38: 91.7 | H38: 0 | I38: =G38+H38 -> 91.7 | J38: =IF(L38>0,L38,0) -> 0 | K38: =I38+J38 -> 91.7 | L38: =F38-(I38-X38) -> -0.025838165 | M38: 3.7 | N38: 0 | O38: 0 | P38: =M38-(N38+O38) -> 3.7 | Q38: 0 | R38: 0 | S38: =SUM(P38:R38) -> 3.7 | U38: 0 | V38: 30.5 | W38: =W37-V38 -> 11365.47 | X38: =N38+O38+S38+U38+V38 -> 34.2 | Y38: =IF(L38<0,L38*-1,0) -> 0.025838165 | Z38: =X38+Y38 -> 34.225838 | AA38: 0 | AB38: 55 | AC38: 18 | AD38: 29
A40: MONTH / CFS | F40: =SUM(F10:F38) -> 1002.2687 | G40: =SUM(G10:G38) -> 2004.9 | H40: =SUM(H10:H38) -> 0 | I40: =SUM(I10:I38) -> 2004.9 | J40: =SUM(J10:J38) -> 0.6565692 | K40: =SUM(K10:K38) -> 2005.4321 | L40: =SUM(L10:L38) -> 0.33871691 | M40: =SUM(M10:M38) -> 124.74 | ... S40: =SUM(S10:S38) -> 124.74 | U40: =SUM(U10:U38) -> 0 | V40: =SUM(V10:V38) -> 878.23 | X40: =SUM(X10:X38) -> 1002.97 | Y40: =SUM(Y10:Y38) -> 0.31785228 | Z40: =SUM(Z10:Z38) -> 1003.2879 | AA40: =SUM(AA10:AA38) -> 1.64 | AB40: =AVERAGE(AB10:AB38) -> 42.931034 | AC40: =AVERAGE(AC10:AC38) -> 19.172414 | AD40: AVE
A41: MONTH / AF | D41: =SUM(D10:D38) -> 1988 | F41: =F40*$D$2 -> 1988 | G41: =G40*$D$2 -> 3976.7191 | H41: =H40*$D$2 -> 0 | I41: =I40*$D$2 -> 3976.7191 | J41: =J40*$D$2 -> 1.302305 | K41: =K40*$D$2 -> 3977.7747 | L41: =L40*$D$2 -> 0.671845 | M41: =M40*$D$2 -> 247.42179 | ... S41: =S40*$D$2 -> 247.42179 | U41: =U40*$D$2 -> 0 | V41: =V40*$D$2 -> 1741.9692 | X41: =X40*$D$2 -> 1989.391 | Y41: =Y40*$D$2 -> 0.63046 | Z41: =Z40*$D$2 -> 1990.0215 | AB41: =MAX(AB10:AB38) -> 57 | AC41: =MAX(AC10:AC38) -> 30 | AD41: HI
A43: SEASON / CFS | AB43: =MIN(AB10:AB38) -> 31 | AC43: =MIN(AC10:AC38) -> 4 | AD43: LO
A44: SEASON / AF
A46: YTD / CFS | F46: =F8+F40 -> 2800.1008 | G46: =G8+G40 -> 8259.3 | H46: =H8+H40 -> 25.7 | I46: =I8+I40 -> 8285 | J46: =J8+J40 -> 409.93406 | K46: =K8+K40 -> 8694.8096 | L46: =L8+L40 -> -442.32917 | M46: =M8+M40 -> 943.94 | ... S46: =S8+S40 -> 1168.04 | U46: =U8+U40 -> 0 | V46: =V8+V40 -> 3874.53 | W46: =W38 -> 11365.47 | X46: =X8+X40 -> 5042.57 | Y46: =Y8+Y40 -> 852.26323 | Z46: =Z8+Z40 -> 5894.8332 | AA46: =AA8+AA40 -> 6.57
A47: YTD / AF | D47: =D8+D41 -> 5554 | E47: =E38 -> 148407 | F47: =F46*$D$2 -> 5554 | G47: =G46*$D$2 -> 16382.322 | H47: =H46*$D$2 -> 50.97595 | I47: =I46*$D$2 -> 16433.298 | J47: =J46*$D$2 -> 813.1042 | K47: =K46*$D$2 -> 17246.155 | L47: =L46*$D$2 -> -877.35991 | M47: =M46*$D$2 -> 1872.305 | ... Z47: =Z46*$D$2 -> 11692.402

Sheet MAR
K1: MC PHEE RESERVOIR IN/OUT FLOW TABULATION
A2: AF/cfs CONVERT FACTOR | D2: 1.9835 | K2: MARCH "1992"
A4: DATE | B4: RESERV | C4: RESERV | D4: AC FT | E4: ACTIVE | F4: CONV TO | G4: DOLORES | H4: LOST | I4: RECORDED | J4: CALC | K4: TOTAL | L4: CALC | M4: TUNNEL | Q4: LONE | R4: U | S4: TOTAL | T4: MVI | U4: DV CR | V4: BELOW | W4: REMAIN | X4: RECORDED | Y4: CALC | Z4: TOTAL | AA4: RAIN | AB4: MAX | AC4: MIN | AD4: DATE
A5: MAR | B5: ELEV | C5: AC FT | D5: CHANGE | E5: CAP | F5: CFS | G5: RIVER | H5: CANYON | I5: INFLOW | J5: INFLOW | K5: INFLOW | L5: INF/OTF | M5: TOT DIV | N5: WETLAND | O5: UTE F&R | P5: MVI,CTZ | Q5: PINE | R5: LAT | S5: MVI | T5: CALL | U5: CANAL | V5: MC PHEE | W5: RELEASE | X5: OUTFLOW | Y5: OUTFLOW | Z5: OUTFLOW | AB5: TMP | AC5: TMP | AD5: MAR
A7: SEASON BAL
A8: YTD | B8: =FEB!B38 -> 6904.48 | C8: =FEB!C38 -> 300407 | D8: =FEB!$D$47 -> 5554 | E8: =FEB!$E$47 -> 148407 | F8: =FEB!F46 -> 2800.1008 | G8: =FEB!G46 -> 8259.3 | H8: =FEB!H46 -> 25.7 | I8: =FEB!I46 -> 8285 | J8: =FEB!J46 -> 409.93406 | K8: =FEB!K46 -> 8694.8096 | L8: =FEB!L46 -> -442.32917 | M8: =FEB!M46 -> 943.94 | ... AA8: =FEB!AA46 -> 6.57
A10: 1 | B10: 6904.48 | C10: 300407 | D10: =C10-C8 -> 0 | E10: =C10-152000 -> 148407 | F10: =D10/$D$2 -> 0 | G10: 34.2 | H10: 7.7 | I10: =G10+H10 -> 41.9 | J10: =IF(L10>0,L10,0) -> 0 | K10: =I10+J10 -> 41.9 | L10: =F10-(I10-X10) -> -7.7 | M10: 3.7 | N10: 0 | O10: 0 | P10: =M10-(N10+O10) -> 3.7 | Q10: 0 | R10: 0 | S10: =SUM(P10:R10) -> 3.7 | U10: 0 | V10: 30.5 | W10: =W8-V10 -> 11334.97 | X10: =N10+O10+S10+U10+V10 -> 34.2 | Y10: =IF(L10<0,L10*-1,0) -> 7.7 | Z10: =X10+Y10 -> 41.9 | AA10: 0 | AB10: 52 | AC10: 21 | AD10: 1
A11: =A10+1 -> 2 | B11: 6904.51 | C11: 300521 | D11: =C11-C10 -> 114 | E11: =C11-152000 -> 148521 | F11: =D11/$D$2 -> 57.474162 | G11: 92.1 | H11: 4.3 | I11: =G11+H11 -> 96.4 | J11: =IF(L11>0,L11,0) -> 0 | K11: =I11+J11 -> 96.4 | L11: =F11-(I11-X11) -> -4.3258382 | M11: 4.1 | N11: 0 | O11: 0 | P11: =M11-(N11+O11) -> 4.1 | Q11: 0 | R11: 0 | S11: =SUM(P11:R11) -> 4.1 | U11: 0 | V11: 30.5 | W11: =W10-V11 -> 11304.47 | X11: =N11+O11+S11+U11+V11 -> 34.6 | Y11: =IF(L11<0,L11*-1,0) -> 4.3258382 | Z11: =X11+Y11 -> 38.925838 | AA11: 0.24 | AB11: 54 | AC11: 27 | AD11: =AD10+1 -> 2
A12: =A11+1 -> 3 | B12: 6904.56 | C12: 300713 | D12: =C12-C11 -> 192 | E12: =C12-152000 -> 148713 | F12: =D12/$D$2 -> 96.798588 | G12: 131.4 | H12: 4.8 | I12: =G12+H12 -> 136.2 | J12: =IF(L12>0,L12,0) -> 0 | K12: =I12+J12 -> 136.2 | L12: =F12-(I12-X12) -> -4.8014116 | M12: 4.1 | N12: 0 | O12: 0 | P12: =M12-(N12+O12) -> 4.1 | Q12: 0 | R12: 0 | S12: =SUM(P12:R12) -> 4.1 | U12: 0 | V12: 30.5 | W12: =W11-V12 -> 11273.97 | X12: =N12+O12+S12+U12+V12 -> 34.6 | Y12: =IF(L12<0,L12*-1,0) -> 4.8014116 | Z12: =X12+Y12 -> 39.401412 | AA12: 0.16 | AB12: 46 | AC12: 31 | AD12: =AD11+1 -> 3
A13: =A12+1 -> 4 | B13: 6904.61 | C13: 300904 | D13: =C13-C12 -> 191 | E13: =C13-152000 -> 148904 | F13: =D13/$D$2 -> 96.294429 | G13: 131.2 | H13: 5.2 | I13: =G13+H13 -> 136.4 | J13: =IF(L13>0,L13,0) -> 0 | K13: =I13+J13 -> 136.4 | L13: =F13-(I13-X13) -> -5.205571 | M13: 4.4 | N13: 0 | O13: 0 | P13: =M13-(N13+O13) -> 4.4 | Q13: 0 | R13: 0 | S13: =SUM(P13:R13) -> 4.4 | U13: 0 | V13: 30.5 | W13: =W12-V13 -> 11243.47 | X13: =N13+O13+S13+U13+V13 -> 34.9 | Y13: =IF(L13<0,L13*-1,0) -> 5.205571 | Z13: =X13+Y13 -> 40.105571 | AA13: 0.2 | AB13: 41 | AC13: 30 | AD13: =AD12+1 -> 4
A14: =A13+1 -> 5 | B14: 6904.64 | C14: 301020 | D14: =C14-C13 -> 116 | E14: =C14-152000 -> 149020 | F14: =D14/$D$2 -> 58.48248 | G14: 92.7 | H14: 5.5 | I14: =G14+H14 -> 98.2 | J14: =IF(L14>0,L14,0) -> 0 | K14: =I14+J14 -> 98.2 | L14: =F14-(I14-X14) -> -5.5175195 | M14: 3.7 | N14: 0 | O14: 0 | P14: =M14-(N14+O14) -> 3.7 | Q14: 0 | R14: 0 | S14: =SUM(P14:R14) -> 3.7 | U14: 0 | V14: 30.5 | W14: =W13-V14 -> 11212.97 | X14: =N14+O14+S14+U14+V14 -> 34.2 | Y14: =IF(L14<0,L14*-1,0) -> 5.5175195 | Z14: =X14+Y14 -> 39.71752 | AA14: 0 | AB14: 52 | AC14: 30 | AD14: =AD13+1 -> 5
A15: =A14+1 -> 6 | B15: 6904.69 | C15: 301210 | D15: =C15-C14 -> 190 | E15: =C15-152000 -> 149210 | F15: =D15/$D$2 -> 95.79027 | G15: 130 | H15: 10.1 | I15: =G15+H15 -> 140.1 | J15: =IF(L15>0,L15,0) -> 0 | K15: =I15+J15 -> 140.1 | L15: =F15-(I15-X15) -> -10.10973 | M15: 3.7 | N15: 0 | O15: 0 | P15: =M15-(N15+O15) -> 3.7 | Q15: 0 | R15: 0 | S15: =SUM(P15:R15) -> 3.7 | U15: 0 | V15: 30.5 | W15: =W14-V15 -> 11182.47 | X15: =N15+O15+S15+U15+V15 -> 34.2 | Y15: =IF(L15<0,L15*-1,0) -> 10.10973 | Z15: =X15+Y15 -> 44.30973 | AA15: 0 | AB15: 54 | AC15: 24 | AD15: =AD14+1 -> 6
A16: =A15+1 -> 7 | B16: 6904.76 | C16: 301447 | D16: =C16-C15 -> 237 | E16: =C16-152000 -> 149447 | F16: =D16/$D$2 -> 119.48576 | G16: 168.9 | H16: 13 | I16: =G16+H16 -> 181.9 | J16: =IF(L16>0,L16,0) -> 0 | K16: =I16+J16 -> 181.9 | L16: =F16-(I16-X16) -> -28.214243 | M16: 3.7 | N16: 0 | O16: 0 | P16: =M16-(N16+O16) -> 3.7 | Q16: 0 | R16: 0 | S16: =SUM(P16:R16) -> 3.7 | U16: 0 | V16: 30.5 | W16: =W15-V16 -> 11151.97 | X16: =N16+O16+S16+U16+V16 -> 34.2 | Y16: =IF(L16<0,L16*-1,0) -> 28.214243 | Z16: =X16+Y16 -> 62.414243 | AA16: 0 | AB16: 38 | AC16: 29 | AD16: =AD15+1 -> 7
A17: =A16+1 -> 8 | B17: 6904.82 | C17: 301707 | D17: =C17-C16 -> 260 | E17: =C17-152000 -> 149707 | F17: =D17/$D$2 -> 131.08142 | G17: 150.3 | H17: 10.1 | I17: =G17+H17 -> 160.4 | J17: =IF(L17>0,L17,0) -> 4.8814217 | K17: =I17+J17 -> 165.28142 | L17: =F17-(I17-X17) -> 4.8814217 | M17: 3.7 | N17: 0 | O17: 0 | P17: =M17-(N17+O17) -> 3.7 | Q17: 0 | R17: 0 | S17: =SUM(P17:R17) -> 3.7 | U17: 0 | V17: 30.5 | W17: =W16-V17 -> 11121.47 | X17: =N17+O17+S17+U17+V17 -> 34.2 | Y17: =IF(L17<0,L17*-1,0) -> 0 | Z17: =X17+Y17 -> 34.2 | AA17: 0.49 | AB17: 39 | AC17: 33 | AD17: =AD16+1 -> 8
