Workbook

Sheet NOV
K1: MCPHEE RESERVOIR INFLOW/OUTFLOW TABULATION
A2: AF/cfs CONVERT FACTOR | D2: 1.9835 | L2: NOVEMBER "2005"
D4: RESERVOIR | T4: INFLOW/OUTFLOW (CFS) | AH4: WEATHER | AL4: ADJUSTMENTS
A5: DATE | B5: RESERV | C5: RESERV | D5: AC FT | E5: ACTIVE | F5: CONV TO | G5: DOLORES | H5: LOST | I5: RECORD | J5: CALC | K5: TOTAL | L5: CALC | M5: DOLORES TUNNEL | T5: LONE | U5: U | V5: TOTAL | W5: MVI | X5: MVI | Y5: DV CR | Z5: D/S SENIOR | AB5: BELOW | AC5: FISH | AD5: RECORD | AE5: CALC | AF5: TOTAL | AG5: RAIN | AH5: MAX | AI5: MIN | AJ5: NAR. | AK5: MVI | AL5: MVI | AM5: MVI | AN5: U/S | AO5: TOTTEN
A6: NOV | B6: ELEV | C6: AC FT | D6: CHANGE | E6: CAP | F6: CFS | G6: RIVER | H6: CAN | I6: INFLOW | J6: INFLOW | K6: INFLOW | L6: INF/OTF | M6: TOT DIV | N6: WET | O6: UTE | P6: QUEST | Q6: MWC | R6: CTZ | S6: CTZ & | T6: PINE | U6: LAT | V6: MVI | W6: CALL | X6: PROJ & | Y6: CANAL | Z6: MVIC | AA6: PROJ | AB6: MCP | AC6: LEFT | AD6: OTF | AE6: OTF | AF6: OTF | AH6: TMP | AI6: TMP | AJ6: CALL | AK6: STOCK | AL6: STORED | AM6: STORED | AN6: USERS | AO6: (FRESH
E7: AC FT | N7: LAND | O7: F&R | S7: UTE | X7: TO EX & | AJ7: AC.FT. | AK7: CFS | AL7: Apr-Jun | AM7: EVAP | AN7: EXCH | AO7: WATER)
N8: 1.03 | O8: 1.05 | P8: 1.02 | Q8: 1.02 | R8: 1.04 | S8: PROJ | X8: U/S EX | AJ8: TOTAL | AM8: AC.FT
A9: SEASON BAL
A10: YTD | B10: 6904.21 | C10: 299374 | AC10: 5492 | AK10: 0
A12: 1 | B12: 6904.19 | C12: 299298 | D12: =C12-C10 -> -76 | E12: =C12-152000 -> 147298 | F12: =D12/$D$2 -> -38.316108 | G12: 96 | H12: 2.23 | I12: =G12+H12 -> 98.23 | J12: =IF(L12>0,L12,0) -> 0 | K12: =I12+J12 -> 98.23 | L12: =F12-(I12-AD12) -> -34.546108 | M12: 26 | N12: 0 | O12: 0 | Q12: =1.38*1.02 -> 1.4076 | R12: =2.42*1.04 -> 2.5168 | S12: 0 | T12: 32 | U12: 13 | V12: =M12-N12-O12-Q12-R12-S16+T12+U12 -> 67.0756 | Y12: 0 | AB12: 31 | AC12: =AC10-AB12 -> 5461 | AD12: =N12+O12+Q12+R12+S16+V12+Y12+AB12 -> 102 | AE12: =IF(L12<0,L12*-1,0) -> 34.546108 | AF12: =AD12+AE12 -> 136.54611 | AG12: 0 | AH12: 60 | AI12: 30 | AJ12: =(T12-17)*1.98353 -> 29.75295 | AK12: =V12-(T12-17) -> 52.0756
A13: =A12+1 -> 2 | B13: 6904.16 | C13: 299183 | D13: =C13-C12 -> -115 | E13: =C13-152000 -> 147183 | F13: =D13/$D$2 -> -57.978321 | G13: 98 | H13: 1.79 | I13: =G13+H13 -> 99.79 | J13: =IF(L13>0,L13,0) -> 0 | K13: =I13+J13 -> 99.79 | L13: =F13-(I13-AD13) -> -49.768321 | M13: 26 | N13: 0 | O13: 0 | Q13: =1.38*1.02 -> 1.4076 | R13: =2.34*1.04 -> 2.4336 | S13: 0 | T13: 42 | U13: 13 | V13: =M13-N13-O13-Q13-R13-S13+T13+U13 -> 77.1588 | Y13: 0 | AB13: 27 | AC13: =AC12-AB13 -> 5434 | AD13: =N13+O13+Q13+R13+S17+V13+Y13+AB13 -> 108 | AE13: =IF(L13<0,L13*-1,0) -> 49.768321 | AF13: =AD13+AE13 -> 157.76832 | AG13: 0 | AH13: 62 | AI13: 36 | AJ13: =(T13-19)*1.9835+AJ12 -> 75.37345 | AK13: =V13-(T13-19) -> 54.1588
A14: =A13+1 -> 3 | B14: 6904.14 | C14: 299107 | D14: =C14-C13 -> -76 | E14: =C14-152000 -> 147107 | F14: =D14/$D$2 -> -38.316108 | G14: 99 | H14: 1.6 | I14: =G14+H14 -> 100.6 | J14: =IF(L14>0,L14,0) -> 0 | K14: =I14+J14 -> 100.6 | L14: =F14-(I14-AD14) -> -14.916108 | M14: 26 | N14: 0 | O14: 0 | Q14: =1.38*1.02 -> 1.4076 | R14: =2.41*1.04 -> 2.5064 | S14: 0 | T14: 59 | U14: 12 | V14: =M14-N14-O14-Q14-R14-S14+T14+U14 -> 93.086 | Y14: 0 | AB14: 27 | AC14: =AC13-AB14 -> 5407 | AD14: =N14+O14+Q14+R14+S18+V14+Y14+AB14 -> 124 | AE14: =IF(L14<0,L14*-1,0) -> 14.916108 | AF14: =AD14+AE14 -> 138.91611 | AG14: 0 | AH14: 59 | AI14: 39 | AJ14: =(T14-17)*1.9835+AJ13 -> 158.68045 | AK14: =V14-(T14-17) -> 51.086
A15: =A14+1 -> 4 | B15: 6904.13 | C15: 299068 | D15: =C15-C14 -> -39 | E15: =C15-152000 -> 147068 | F15: =D15/$D$2 -> -19.662213 | G15: 98 | H15: 1.9 | I15: =G15+H15 -> 99.9 | J15: =IF(L15>0,L15,0) -> 12.437787 | K15: =I15+J15 -> 112.33779 | L15: =F15-(I15-AD15) -> 12.437787 | M15: 26 | N15: 0 | O15: 0 | Q15: =1.38*1.02 -> 1.4076 | R15: =2.37*1.04 -> 2.4648 | S15: 0 | T15: 69 | U15: 11 | V15: =M15-N15-O15-Q15-R15-S15+T15+U15 -> 102.1276 | Y15: 0 | AB15: 26 | AC15: =AC14-AB15 -> 5381 | AD15: =N15+O15+Q15+R15+S19+V15+Y15+AB15 -> 132 | AE15: =IF(L15<0,L15*-1,0) -> 0 | AF15: =AD15+AE15 -> 132 | AG15: 0 | AH15: 56 | AI15: 31 | AJ15: =(T15-16)*1.9835+AJ14 -> 263.80595 | AK15: =V15-(T15-16) -> 49.1276
A16: =A15+1 -> 5 | B16: 6904.11 | C16: 298992 | D16: =C16-C15 -> -76 | E16: =C16-152000 -> 146992 | F16: =D16/$D$2 -> -38.316108 | G16: 89 | H16: 1.83 | I16: =G16+H16 -> 90.83 | J16: =IF(L16>0,L16,0) -> 0.85389211 | K16: =I16+J16 -> 91.683892 | L16: =F16-(I16-AD16) -> 0.85389211 | M16: 25 | N16: 0 | O16: 0 | Q16: =1.38*1.02 -> 1.4076 | R16: =2.23*1.04 -> 2.3192 | S16: 0 | T16: 68 | U16: 11 | V16: =M16-N16-O16-Q16-R16-S16+T16+U16 -> 100.2732 | Y16: 0 | AB16: 26 | AC16: =AC15-AB16 -> 5355 | AD16: =N16+O16+Q16+R16+S20+V16+Y16+AB16 -> 130 | AE16: =IF(L16<0,L16*-1,0) -> 0 | AF16: =AD16+AE16 -> 130 | AG16: 0 | AH16: 51 | AI16: 29 | AJ16: =(T16-15)*1.9835+AJ15 -> 368.93145 | AK16: =V16-(T16-15) -> 47.2732
A17: =A16+1 -> 6 | B17: 6904.09 | C17: 298915 | D17: =C17-C16 -> -77 | E17: =C17-152000 -> 146915 | F17: =D17/$D$2 -> -38.820267 | G17: 83 | H17: 1.6 | I17: =G17+H17 -> 84.6 | J17: =IF(L17>0,L17,0) -> 6.5797328 | K17: =I17+J17 -> 91.179733 | L17: =F17-(I17-AD17) -> 6.5797328 | M17: 25 | N17: 0 | O17: 0 | Q17: =1.38*1.02 -> 1.4076 | R17: =2.42*1.04 -> 2.5168 | S17: 0 | T17: 68 | U17: 11 | V17: =M17-N17-O17-Q17-R17-S17+T17+U17 -> 100.0756 | Y17: 0 | AB17: 26 | AC17: =AC16-AB17 -> 5329 | AD17: =N17+O17+Q17+R17+S21+V17+Y17+AB17 -> 130 | AE17: =IF(L17<0,L17*-1,0) -> 0 | AF17: =AD17+AE17 -> 130 | AG17: 0 | AH17: 59 | AI17: 32 | AJ17: =(T17-14)*1.9835+AJ16 -> 476.04045 | AK17: =V17-(T17-14) -> 46.0756
A18: =A17+1 -> 7 | B18: 6904.07 | C18: 298839 | D18: =C18-C17 -> -76 | E18: =C18-152000 -> 146839 | F18: =D18/$D$2 -> -38.316108 | G18: 81 | H18: 1.32 | I18: =G18+H18 -> 82.32 | J18: =IF(L18>0,L18,0) -> 0.36389211 | K18: =I18+J18 -> 82.683892 | L18: =F18-(I18-AD18) -> 0.36389211 | M18: 25 | N18: 0 | O18: 0 | Q18: =1.38*1.02 -> 1.4076 | R18: =2.75*1.04 -> 2.86 | S18: 0 | T18: 60 | U18: 11 | V18: =M18-N18-O18-Q18-R18-S18+T18+U18 -> 91.7324 | Y18: 0 | AB18: 25 | AC18: =AC17-AB18 -> 5304 | AD18: =N18+O18+Q18+R18+S22+V18+Y18+AB18 -> 121 | AE18: =IF(L18<0,L18*-1,0) -> 0 | AF18: =AD18+AE18 -> 121 | AG18: 0 | AH18: 60 | AI18: 42 | AJ18: =(T18-12)*1.9835+AJ17 -> 571.24845 | AK18: =V18-(T18-12) -> 43.7324
A19: =A18+1 -> 8 | B19: 6904.04 | C19: 298724 | D19: =C19-C18 -> -115 | E19: =C19-152000 -> 146724 | F19: =D19/$D$2 -> -57.978321 | G19: 84 | H19: 1.743 | I19: =G19+H19 -> 85.743 | J19: =IF(L19>0,L19,0) -> 0 | K19: =I19+J19 -> 85.743 | L19: =F19-(I19-AD19) -> -28.721321 | M19: 25 | N19: 0 | O19: 0 | Q19: =1.38*1.02 -> 1.4076 | R19: =2.25*1.04 -> 2.34 | S19: 0 | T19: 54 | U19: 11 | V19: =M19-N19-O19-Q19-R19-S19+T19+U19 -> 86.2524 | Y19: 0 | AB19: 25 | AC19: =AC18-AB19 -> 5279 | AD19: =N19+O19+Q19+R19+S23+V19+Y19+AB19 -> 115 | AE19: =IF(L19<0,L19*-1,0) -> 28.721321 | AF19: =AD19+AE19 -> 143.72132 | AG19: 0 | AH19: 59 | AI19: 41 | AJ19: =(T19-11)*1.9835+AJ18 -> 656.53895 | AK19: =V19-(T19-11) -> 43.2524
A20: =A19+1 -> 9 | B20: 6904.02 | C20: 298648 | D20: =C20-C19 -> -76 | E20: =C20-152000 -> 146648 | F20: =D20/$D$2 -> -38.316108 | G20: 82 | H20: 1.8 | I20: =G20+H20 -> 83.8 | J20: =IF(L20>0,L20,0) -> 0 | K20: =I20+J20 -> 83.8 | L20: =F20-(I20-AD20) -> -6.1161079 | M20: 25 | N20: 0 | O20: 0 | Q20: =1.38*1.02 -> 1.4076 | R20: =2.25*1.04 -> 2.34 | S20: 0 | T20: 55 | U20: 11 | V20: =M20-N20-O20-Q20-R20-S20+T20+U20 -> 87.2524 | Y20: 0 | AB20: 25 | AC20: =AC19-AB20 -> 5254 | AD20: =N20+O20+Q20+R20+S24+V20+Y20+AB20 -> 116 | AE20: =IF(L20<0,L20*-1,0) -> 6.1161079 | AF20: =AD20+AE20 -> 122.11611 | AG20: 0 | AH20: 66 | AI20: 40 | AJ20: =(T20-10)*1.9835+AJ19 -> 745.79645 | AK20: =V20-(T20-10) -> 42.2524
A21: =A20+1 -> 10 | B21: 6904.01 | C21: 298609 | D21: =C21-C20 -> -39 | E21: =C21-152000 -> 146609 | F21: =D21/$D$2 -> -19.662213 | G21: 80 | H21: 1.8 | I21: =G21+H21 -> 81.8 | J21: =IF(L21>0,L21,0) -> 6.5377867 | K21: =I21+J21 -> 88.337787 | L21: =F21-(I21-AD21) -> 6.5377867 | M21: 24 | N21: 0 | O21: 0 | Q21: =1.38*1.02 -> 1.4076 | R21: =2.12*1.04 -> 2.2048 | S21: 0 | T21: 48 | U21: 11 | V21: =M21-N21-O21-Q21-R21-S21+T21+U21 -> 79.3876 | Y21: 0 | AB21: 25 | AC21: =AC20-AB21 -> 5229 | AD21: =N21+O21+Q21+R21+S25+V21+Y21+AB21 -> 108 | AE21: =IF(L21<0,L21*-1,0) -> 0 | AF21: =AD21+AE21 -> 108 | AG21: 0 | AH21: 69 | AI21: 43 | AJ21: =(T21-13)*1.9835+AJ20 -> 815.21895 | AK21: =V21-(T21-13) -> 44.3876
A22: =A21+1 -> 11 | B22: 6904 | C22: 298571 | D22: =C22-C21 -> -38 | E22: =C22-152000 -> 146571 | F22: =D22/$D$2 -> -19.158054 | G22: 81 | H22: 1.9 | I22: =G22+H22 -> 82.9 | J22: =IF(L22>0,L22,0) -> 2.9419461 | K22: =I22+J22 -> 85.841946 | L22: =F22-(I22-AD22) -> 2.9419461 | M22: 24 | N22: 0 | O22: 0 | Q22: =1.38*1.02 -> 1.4076 | R22: =2*1.04 -> 2.08 | S22: 0 | T22: 45 | U22: 11 | V22: =M22-N22-O22-Q22-R22-S22+T22+U22 -> 76.5124 | Y22: 0 | AB22: 25 | AC22: =AC21-AB22 -> 5204 | AD22: =N22+O22+Q22+R22+S26+V22+Y22+AB22 -> 105 | AE22: =IF(L22<0,L22*-1,0) -> 0 | AF22: =AD22+AE22 -> 105 | AG22: 0 | AH22: 58 | AI22: 35 | AJ22: =(T22-13)*1.9835+AJ21 -> 878.69095 | AK22: =V22-(T22-13) -> 44.5124
A23: =A22+1 -> 12 | B23: 6903.99 | C23: 298533 | D23: =C23-C22 -> -38 | E23: =C23-152000 -> 146533 | F23: =D23/$D$2 -> -19.158054 | G23: 98 | H23: 2.6 | I23: =G23+H23 -> 100.6 | J23: =IF(L23>0,L23,0) -> 0 | K23: =I23+J23 -> 100.6 | L23: =F23-(I23-AD23) -> -14.798054 | M23: 24 | N23: 0 | O23: 0 | Q23: =1.38*1.02 -> 1.4076 | R23: =2.17*1.04 -> 2.2568 | S23: 0 | T23: 44.96 | U23: 11 | V23: =M23-N23-O23-Q23-R23-S23+T23+U23 -> 76.2956 | Y23: 0 | AB23: 25 | AC23: =AC22-AB23 -> 5179 | AD23: =N23+O23+Q23+R23+S27+V23+Y23+AB23 -> 104.96 | AE23: =IF(L23<0,L23*-1,0) -> 14.798054 | AF23: =AD23+AE23 -> 119.75805 | AG23: 0.01 | AH23: 52 | AI23: 33 | AJ23: =(T23-13)*1.9835+AJ22 -> 942.08361 | AK23: =V23-(T23-13) -> 44.3356
A24: =A23+1 -> 13 | B24: 6903.97 | C24: 298457 | D24: =C24-C23 -> -76 | E24: =C24-152000 -> 146457 | F24: =D24/$D$2 -> -38.316108 | G24: 91 | H24: 2.6 | I24: =G24+H24 -> 93.6 | J24: =IF(L24>0,L24,0) -> 0 | K24: =I24+J24 -> 93.6 | L24: =F24-(I24-AD24) -> -26.916108 | M24: 24 | N24: 0 | O24: 0 | Q24: =1.38*1.02 -> 1.4076 | R24: =2.33*1.04 -> 2.4232 | S24: 0 | T24: 45 | U24: 11 | V24: =M24-N24-O24-Q24-R24-S24+T24+U24 -> 76.1692 | Y24: 0 | AB24: 25 | AC24: =AC23-AB24 -> 5154 | AD24: =N24+O24+Q24+R24+S28+V24+Y24+AB24 -> 105 | AE24: =IF(L24<0,L24*-1,0) -> 26.916108 | AF24: =AD24+AE24 -> 131.91611 | AG24: 0 | AH24: 53 | AI24: 32 | AJ24: =(T24-13)*1.9835+AJ23 -> 1005.5556 | AK24: =V24-(T24-13) -> 44.1692
A25: =A24+1 -> 14 | B25: 6903.95 | C25: 298381 | D25: =C25-C24 -> -76 | E25: =C25-152000 -> 146381 | F25: =D25/$D$2 -> -38.316108 | G25: 82 | H25: 2.1 | I25: =G25+H25 -> 84.1 | J25: =IF(L25>0,L25,0) -> 0 | K25: =I25+J25 -> 84.1 | L25: =F25-(I25-AD25) -> -27.946108 | M25: 11 | N25: 0 | O25: 0 | Q25: =1.38*1.02 -> 1.4076 | R25: =1.94*1.04 -> 2.0176 | S25: 0 | T25: 55 | U25: 3.47 | V25: =M25-N25-O25-Q25-R25-S25+T25+U25 -> 66.0448 | Y25: 0 | AB25: 25 | AC25: =AC24-AB25 -> 5129 | AD25: =N25+O25+Q25+R25+S29+V25+Y25+AB25 -> 94.47 | AE25: =IF(L25<0,L25*-1,0) -> 27.946108 | AF25: =AD25+AE25 -> 122.41611 | AG25: 0 | AH25: 55 | AI25: 28 | AJ25: =(T25-5)*1.9835+AJ24 -> 1104.7306 | AK25: =V25-(T25-5) -> 16.0448
A26: =A25+1 -> 15 | B26: 6903.93 | C26: 298306 | D26: =C26-C25 -> -75 | E26: =C26-152000 -> 146306 | F26: =D26/$D$2 -> -37.811949 | G26: 83 | H26: 2.1 | I26: =G26+H26 -> 85.1 | J26: =IF(L26>0,L26,0) -> 0 | K26: =I26+J26 -> 85.1 | L26: =F26-(I26-AD26) -> -13.811949 | M26: 5.1 | N26: 0 | O26: 0 | Q26: =1.38*1.02 -> 1.4076 | R26: =2.16*1.04 -> 2.2464 | S26: 0 | T26: 80 | U26: 0 | V26: =M26-N26-O26-Q26-R26-S26+T26+U26 -> 81.446 | Y26: 0 | AB26: 24 | AC26: =AC25-AB26 -> 5105 | AD26: =N26+O26+Q26+R26+S30+V26+Y26+AB26 -> 109.1 | AE26: =IF(L26<0,L26*-1,0) -> 13.811949 | AF26: =AD26+AE26 -> 122.91195 | AG26: 0 | AH26: 37 | AI26: 21 | AJ26: =V26*1.9835+AJ25 -> 1266.2788
A27: =A26+1 -> 16 | B27: 6903.91 | C27: 298230 | D27: =C27-C26 -> -76 | E27: =C27-152000 -> 146230 | F27: =D27/$D$2 -> -38.316108 | G27: 55 | H27: 1.7 | I27: =G27+H27 -> 56.7 | J27: =IF(L27>0,L27,0) -> 13.683892 | K27: =I27+J27 -> 70.383892 | L27: =F27-(I27-AD27) -> 13.683892 | M27: 4.7 | N27: 0 | O27: 0 | Q27: =1.38*1.02 -> 1.4076 | R27: =2.22*1.04 -> 2.3088 | S27: 0 | T27: 80 | U27: 0 | V27: =M27-N27-O27-Q27-R27-S27+T27+U27 -> 80.9836 | Y27: 0 | AB27: 24 | AC27: =AC26-AB27 -> 5081 | AD27: =N27+O27+Q27+R27+S31+V27+Y27+AB27 -> 108.7 | AE27: =IF(L27<0,L27*-1,0) -> 0 | AF27: =AD27+AE27 -> 108.7 | AG27: 0 | AH27: 47 | AI27: 18 | AJ27: =V27*1.9835+AJ26 -> 1426.9097
A28: =A27+1 -> 17 | B28: 6903.89 | C28: 298154 | D28: =C28-C27 -> -76 | E28: =C28-152000 -> 146154 | F28: =D28/$D$2 -> -38.316108 | G28: 66 | H28: 1.2 | I28: =G28+H28 -> 67.2 | J28: =IF(L28>0,L28,0) -> 0 | K28: =I28+J28 -> 67.2 | L28: =F28-(I28-AD28) -> -9.9161079 | M28: 4.6 | N28: 0 | O28: 0 | Q28: =1.38*1.02 -> 1.4076 | R28: =2.05*1.04 -> 2.132 | S28: 0 | T28: 67 | U28: 0 | V28: =M28-N28-O28-Q28-R28-S28+T28+U28 -> 68.0604 | Y28: 0 | AB28: 24 | AC28: =AC27-AB28 -> 5057 | AD28: =N28+O28+Q28+R28+S32+V28+Y28+AB28 -> 95.6 | AE28: =IF(L28<0,L28*-1,0) -> 9.9161079 | AF28: =AD28+AE28 -> 105.51611 | AG28: 0 | AH28: 51 | AI28: 24 | AJ28: =V28*1.9835+AJ27 -> 1561.9075
A29: =A28+1 -> 18 | B29: 6903.86 | C29: 298040 | D29: =C29-C28 -> -114 | E29: =C29-152000 -> 146040 | F29: =D29/$D$2 -> -57.474162 | G29: 66 | H29: 0.85 | I29: =G29+H29 -> 66.85 | J29: =IF(L29>0,L29,0) -> 0 | K29: =I29+J29 -> 66.85 | L29: =F29-(I29-AD29) -> -36.024162 | M29: 4.3 | N29: 0 | O29: 0 | Q29: =1.38*1.02 -> 1.4076 | R29: =2.21*1.04 -> 2.2984 | S29: 0 | T29: 60 | U29: 0 | V29: =M29-N29-O29-Q29-R29-S29+T29+U29 -> 60.594 | Y29: 0 | AB29: 24 | AC29: =AC28-AB29 -> 5033 | AD29: =N29+O29+Q29+R29+S33+V29+Y29+AB29 -> 88.3 | AE29: =IF(L29<0,L29*-1,0) -> 36.024162 | AF29: =AD29+AE29 -> 124.32416 | AG29: 0 | AH29: 49 | AI29: 25 | AJ29: =V29*1.9835+AJ28 -> 1682.0957
A30: =A29+1 -> 19 | B30: 6903.84 | C30: 297964 | D30: =C30-C29 -> -76 | E30: =C30-152000 -> 145964 | F30: =D30/$D$2 -> -38.316108 | G30: 58 | H30: 1 | I30: =G30+H30 -> 59 | J30: =IF(L30>0,L30,0) -> 0 | K30: =I30+J30 -> 59 | L30: =F30-(I30-AD30) -> -9.3161079 | M30: 4 | N30: 0 | O30: 0 | Q30: =1.38*1.02 -> 1.4076 | R30: =2.34*1.04 -> 2.4336 | S30: 0 | T30: 60 | U30: 0 | V30: =M30-N30-O30-Q30-R30-S30+T30+U30 -> 60.1588 | Y30: 0 | AB30: 24 | AC30: =AC29-AB30 -> 5009 | AD30: =N30+O30+Q30+R30+S34+V30+Y30+AB30 -> 88 | AE30: =IF(L30<0,L30*-1,0) -> 9.3161079 | AF30: =AD30+AE30 -> 97.316108 | AG30: 0 | AH30: 49 | AI30: 25 | AJ30: =V30*1.9835+AJ29 -> 1801.4207
A31: =A30+1 -> 20 | B31: 6903.81 | C31: 297850 | D31: =C31-C30 -> -114 | E31: =C31-152000 -> 145850 | F31: =D31/$D$2 -> -57.474162 | G31: 61 | H31: 1.2 | I31: =G31+H31 -> 62.2 | J31: =IF(L31>0,L31,0) -> 0 | K31: =I31+J31 -> 62.2 | L31: =F31-(I31-AD31) -> -31.674162 | M31: 4 | N31: 0 | O31: 0 | Q31: =1.38*1.02 -> 1.4076 | R31: =2.15*1.04 -> 2.236 | S31: 0 | T31: 60 | U31: 0 | V31: =M31-N31-O31-Q31-R31-S31+T31+U31 -> 60.3564 | Y31: 0 | AB31: 24 | AC31: =AC30-AB31 -> 4985 | AD31: =N31+O31+Q31+R31+S35+V31+Y31+AB31 -> 88 | AE31: =IF(L31<0,L31*-1,0) -> 31.674162 | AF31: =AD31+AE31 -> 119.67416 | AG31: 0 | AH31: 53 | AI31: 26 | AJ31: =V31*1.9835+AJ30 -> 1921.1376
A32: =A31+1 -> 21 | B32: 6903.79 | C32: 297774 | D32: =C32-C31 -> -76 | E32: =C32-152000 -> 145774 | F32: =D32/$D$2 -> -38.316108 | G32: 57 | H32: 1.1 | I32: =G32+H32 -> 58.1 | J32: =IF(L32>0,L32,0) -> 0 | K32: =I32+J32 -> 58.1 | L32: =F32-(I32-AD32) -> -8.4161079 | M32: 4 | N32: 0 | O32: 0 | Q32: =1.38*1.02 -> 1.4076 | R32: =2.14*1.04 -> 2.2256 | S32: 0 | T32: 60 | U32: 0 | V32: =M32-N32-O32-Q32-R32-S32+T32+U32 -> 60.3668 | Y32: 0 | AB32: 24 | AC32: =AC31-AB32 -> 4961 | AD32: =N32+O32+Q32+R32+S36+V32+Y32+AB32 -> 88 | AE32: =IF(L32<0,L32*-1,0) -> 8.4161079 | AF32: =AD32+AE32 -> 96.416108 | AG32: 0 | AH32: 57 | AI32: 25 | AJ32: =V32*1.9835+AJ31 -> 2040.8752
A33: =A32+1 -> 22 | B33: 6903.76 | C33: 297661 | D33: =C33-C32 -> -113 | E33: =C33-152000 -> 145661 | F33: =D33/$D$2 -> -56.970003 | G33: 60 | H33: 1.1 | I33: =G33+H33 -> 61.1 | J33: =IF(L33>0,L33,0) -> 0 | K33: =I33+J33 -> 61.1 | L33: =F33-(I33-AD33) -> -30.070003 | M33: 4 | N33: 0 | O33: 0 | Q33: =1.38*1.02 -> 1.4076 | R33: =2.14*1.04 -> 2.2256 | S33: 0 | T33: 60 | U33: 0 | V33: =M33-N33-O33-Q33-R33-S33+T33+U33 -> 60.3668 | Y33: 0 | AB33: 24 | AC33: =AC32-AB33 -> 4937 | AD33: =N33+O33+Q33+R33+S37+V33+Y33+AB33 -> 88 | AE33: =IF(L33<0,L33*-1,0) -> 30.070003 | AF33: =AD33+AE33 -> 118.07 | AG33: 0 | AH33: 58 | AI33: 27 | AJ33: =V33*1.9835+AJ32 -> 2160.6127
A34: =A33+1 -> 23 | B34: 6903.73 | C34: 297547 | D34: =C34-C33 -> -114 | E34: =C34-152000 -> 145547 | F34: =D34/$D$2 -> -57.474162 | G34: 55 | H34: 1.1 | I34: =G34+H34 -> 56.1 | J34: =IF(L34>0,L34,0) -> 0 | K34: =I34+J34 -> 56.1 | L34: =F34-(I34-AD34) -> -26.574162 | M34: 4 | N34: 0 | O34: 0 | Q34: =1.38*1.02 -> 1.4076 | R34: =2.11*1.04 -> 2.1944 | S34: 0 | T34: 60 | U34: 0 | V34: =M34-N34-O34-Q34-R34-S34+T34+U34 -> 60.398 | Y34: 0 | AB34: 23 | AC34: =AC33-AB34 -> 4914 | AD34: =N34+O34+Q34+R34+S38+V34+Y34+AB34 -> 87 | AE34: =IF(L34<0,L34*-1,0) -> 26.574162 | AF34: =AD34+AE34 -> 113.57416 | AG34: 0 | AH34: 53 | AI34: 27 | AJ34: =V34*1.9835+AJ33 -> 2280.4122
A35: =A34+1 -> 24 | B35: 6903.7 | C35: 297433 | D35: =C35-C34 -> -114 | E35: =C35-152000 -> 145433 | F35: =D35/$D$2 -> -57.474162 | G35: 59 | H35: 0.94 | I35: =G35+H35 -> 59.94 | J35: =IF(L35>0,L35,0) -> 0 | K35: =I35+J35 -> 59.94 | L35: =F35-(I35-AD35) -> -30.414162 | M35: 4 | N35: 0 | O35: 0 | Q35: =1.38*1.02 -> 1.4076 | R35: =2.18*1.04 -> 2.2672 | S35: 0 | T35: 60 | U35: 0 | V35: =M35-N35-O35-Q35-R35-S35+T35+U35 -> 60.3252 | Y35: 0 | AB35: 23 | AC35: =AC34-AB35 -> 4891 | AD35: =N35+O35+Q35+R35+S39+V35+Y35+AB35 -> 87 | AE35: =IF(L35<0,L35*-1,0) -> 30.414162 | AF35: =AD35+AE35 -> 117.41416 | AG35: 0 | AH35: 53 | AI35: 24 | AJ35: =V35*1.9835+AJ34 -> 2400.0672
A36: =A35+1 -> 25 | B36: 6903.67 | C36: 297319 | D36: =C36-C35 -> -114 | E36: =C36-152000 -> 145319 | F36: =D36/$D$2 -> -57.474162 | G36: 58 | H36: 0.73 | I36: =G36+H36 -> 58.73 | J36: =IF(L36>0,L36,0) -> 0 | K36: =I36+J36 -> 58.73 | L36: =F36-(I36-AD36) -> -28.204162 | M36: 4 | N36: 0 | O36: 0 | Q36: =1.38*1.02 -> 1.4076 | R36: =2.18*1.04 -> 2.2672 | S36: 0 | T36: 61 | U36: 0 | V36: =M36-N36-O36-Q36-R36-S36+T36+U36 -> 61.3252 | Y36: 0 | AB36: 23 | AC36: =AC35-AB36 -> 4868 | AD36: =N36+O36+Q36+R36+S40+V36+Y36+AB36 -> 88 | AE36: =IF(L36<0,L36*-1,0) -> 28.204162 | AF36: =AD36+AE36 -> 116.20416 | AG36: 0 | AH36: 53 | AI36: 24 | AJ36: =V36*1.9835+AJ35 -> 2521.7057
A37: =A36+1 -> 26 | B37: 6903.64 | C37: 297205 | D37: =C37-C36 -> -114 | E37: =C37-152000 -> 145205 | F37: =D37/$D$2 -> -57.474162 | G37: 57 | H37: 0.89 | I37: =G37+H37 -> 57.89 | J37: =IF(L37>0,L37,0) -> 0 | K37: =I37+J37 -> 57.89 | L37: =F37-(I37-AD37) -> -27.364162 | M37: 4 | N37: 0 | O37: 0 | Q37: =1.38*1.02 -> 1.4076 | R37: =2.1*1.04 -> 2.184 | S37: 0 | T37: 61 | U37: 0 | V37: =M37-N37-O37-Q37-R37-S37+T37+U37 -> 61.4084 | Y37: 0 | AB37: 23 | AC37: =AC36-AB37 -> 4845 | AD37: =N37+O37+Q37+R37+S41+V37+Y37+AB37 -> 88 | AE37: =IF(L37<0,L37*-1,0) -> 27.364162 | AF37: =AD37+AE37 -> 115.36416 | AG37: 0 | AH37: 46 | AI37: 24 | AJ37: =V37*1.9835+AJ36 -> 2643.5093
A38: =A37+1 -> 27 | B38: 6903.61 | C38: 297092 | D38: =C38-C37 -> -113 | E38: =C38-152000 -> 145092 | F38: =D38/$D$2 -> -56.970003 | G38: 54 | H38: 1.1 | I38: =G38+H38 -> 55.1 | J38: =IF(L38>0,L38,0) -> 0 | K38: =I38+J38 -> 55.1 | L38: =F38-(I38-AD38) -> -25.070003 | M38: 4 | N38: 0 | O38: 0 | Q38: =1.38*1.02 -> 1.4076 | R38: =2.16*1.04 -> 2.2464 | S38: 0 | T38: 61 | U38: 0 | V38: =M38-N38-O38-Q38-R38-S38+T38+U38 -> 61.346 | Y38: 0 | AB38: 22 | AC38: =AC37-AB38 -> 4823 | AD38: =N38+O38+Q38+R38+S42+V38+Y38+AB38 -> 87 | AE38: =IF(L38<0,L38*-1,0) -> 25.070003 | AF38: =AD38+AE38 -> 112.07 | AG38: 0 | AH38: 31 | AI38: 14 | AJ38: =V38*1.9835+AJ37 -> 2765.1891
A39: =A38+1 -> 28 | B39: 6903.58 | C39: 296978 | D39: =C39-C38 -> -114 | E39: =C39-152000 -> 144978 | F39: =D39/$D$2 -> -57.474162 | G39: 47 | H39: 0.97 | I39: =G39+H39 -> 47.97 | J39: =IF(L39>0,L39,0) -> 0 | K39: =I39+J39 -> 47.97 | L39: =F39-(I39-AD39) -> -18.444162 | M39: 4 | N39: 0 | O39: 0 | Q39: =1.38*1.02 -> 1.4076 | R39: =2.21*1.04 -> 2.2984 | S39: 0 | T39: 61 | U39: 0 | V39: =M39-N39-O39-Q39-R39-S39+T39+U39 -> 61.294 | Y39: 0 | AB39: 22 | AC39: =AC38-AB39 -> 4801 | AD39: =N39+O39+Q39+R39+S43+V39+Y39+AB39 -> 87 | AE39: =IF(L39<0,L39*-1,0) -> 18.444162 | AF39: =AD39+AE39 -> 105.44416 | AG39: 0 | AH39: 25 | AI39: 12 | AJ39: =V39*1.9835+AJ38 -> 2886.7657
A40: =A39+1 -> 29 | B40: 6903.55 | C40: 296864 | D40: =C40-C39 -> -114 | E40: =C40-152000 -> 144864 | F40: =D40/$D$2 -> -57.474162 | G40: 46 | H40: 0.68 | I40: =G40+H40 -> 46.68 | J40: =IF(L40>0,L40,0) -> 0 | K40: =I40+J40 -> 46.68 | L40: =F40-(I40-AD40) -> -21.654162 | M40: 4.5 | N40: 0 | O40: 0 | Q40: =1.38*1.02 -> 1.4076 | R40: =2.1*1.04 -> 2.184 | S40: 0 | T40: 57 | U40: 0 | V40: =M40-N40-O40-Q40-R40-S40+T40+U40 -> 57.9084 | Y40: 0 | AB40: 21 | AC40: =AC39-AB40 -> 4780 | AD40: =N40+O40+Q40+R40+S44+V40+Y40+AB40 -> 82.5 | AE40: =IF(L40<0,L40*-1,0) -> 21.654162 | AF40: =AD40+AE40 -> 104.15416 | AG40: 0 | AH40: 40 | AI40: 17 | AJ40: =V40*1.9835+AJ39 -> 3001.627
A41: 30 | B41: 6903.53 | C41: 296788 | D41: =C41-C40 -> -76 | E41: =C41-152000 -> 144788 | F41: =D41/$D$2 -> -38.316108 | G41: 51 | H41: 0.87 | I41: =G41+H41 -> 51.87 | J41: =IF(L41>0,L41,0) -> 0 | K41: =I41+J41 -> 51.87 | L41: =F41-(I41-AD41) -> -14.236108 | M41: 5 | N41: 0 | O41: 0 | Q41: =1.38*1.02 -> 1.4076 | R41: =2.21*1.04 -> 2.2984 | S41: 0 | T41: 48.95 | U41: 0 | V41: =M41-N41-O41-Q41-R41-S41+T41+U41 -> 50.244 | Y41: 0 | AB41: 22 | AC41: =AC40-AB41 -> 4758 | AD41: =N41+O41+Q41+R41+S45+V41+Y41+AB41 -> 75.95 | AE41: =IF(L41<0,L41*-1,0) -> 14.236108 | AF41: =AD41+AE41 -> 90.186108 | AG41: 0 | AH41: 42 | AI41: 26 | AJ41: =V41*1.9835+AJ40 -> 3101.286
A43: MONTH / CFS | F43: =SUM(F12:F41) -> -1303.756 | G43: =SUM(G12:G41) -> 2175 | H43: =SUM(H12:H41) -> 44.343 | I43: =SUM(I12:I41) -> 2219.343 | J43: =SUM(J12:J41) -> 43.398929 | K43: =SUM(K12:K41) -> 2262.7419 | L43: =SUM(L12:L41) -> -491.51899 | M43: =SUM(M12:M41) -> 404.2 | ... O43: =SUM(O12:O41) -> 0 | Q43: =SUM(Q12:Q41) -> 42.228 | R43: =SUM(R12:R41) -> 69.3264 | S43: =SUM(S13:S41) -> 0 | T43: =SUM(T12:T41) -> 1741.91 | U43: =SUM(U12:U41) -> 151.47 | V43: =SUM(V12:V41) -> 2186.0256 | AB43: =SUM(AB12:AB41) -> 734 | AD43: =SUM(AD12:AD41) -> 3031.58 | AE43: =SUM(AE12:AE41) -> 534.91792 | AF43: =SUM(AF12:AF41) -> 3566.4979 | AG43: =SUM(AG12:AG41) -> 0.01 | AH43: =AVERAGE(AH12:AH41) -> 52.1 | AI43: =AVERAGE(AI12:AI42) -> 28.333333 | AJ43: Avg | AK43: =SUM(AK12:AK41) -> 622.4836
...

Sheet DEC
K1: MCPHEE RESERVOIR INFLOW/OUTFLOW TABULATION
A2: AF/cfs CONVERT FACTOR | D2: 1.9835 | K2: DECEMBER "2005"
D4: RESERVOIR | T4: INFLOW/OUTFLOW (CFS) | AH4: WEATHER | AL4: ADJUSTMENTS
A5: DATE | B5: RESERV | C5: RESERV | D5: AC FT | E5: ACTIVE | F5: CONV TO | G5: DOLORES | H5: LOST | I5: RECORD | J5: CALC | K5: TOTAL | L5: CALC | M5: DOLORES TUNNEL | T5: LONE | U5: U | V5: TOTAL | W5: MVI | X5: MVI | Y5: DV CR | Z5: D/S SENIOR | AB5: BELOW | AC5: FISH | AD5: RECORD | AE5: CALC | AF5: TOTAL | AG5: RAIN | AH5: MAX | AI5: MIN | AJ5: NAR | AK5: MVI | AL5: MVI | AM5: MVI | AN5: U/S | AO5: TOTTEN
A6: DEC | B6: ELEV | C6: AC FT | D6: CHANGE | E6: CAP | F6: CFS | G6: RIVER | H6: CAN | I6: INFLOW | J6: INFLOW | K6: INFLOW | L6: INF/OTF | M6: TOT DIV | N6: WET | O6: UTE | P6: QUEST | Q6: MWC | R6: CTZ | S6: CTZ & | T6: PINE | U6: LAT | V6: MVI | W6: CALL | X6: PROJ & | Y6: CANAL | AB6: MCP | AC6: LEFT | AD6: OTF | AE6: OTF | AF6: OTF | AH6: TMP | AI6: TMP | AJ6: CALL | AK6: STOCK | AL6: STORED | AM6: STORED | AN6: USERS | AO6: (FRESH
E7: AC FT | N7: LAND | O7: F&R | S7: UTE | X7: TO EX & | AJ7: AC.FT. | AK7: AC.FT. | AL7: Apr-Jun | AM7: EVAP | AN7: EXCH | AO7: WATER)
N8: 1.03 | O8: 1.05 | P8: 1.02 | Q8: 1.02 | R8: 1.04 | S8: PROJ | X8: U/S EX | AM8: AC.FT.
A9: SEASON BAL
A10: YTD | B10: =NOV!B41 -> 6903.53 | C10: =NOV!C41 -> 296788 | D10: =NOV!D50 -> -2586 | E10: =NOV!E50 -> 144788 | F10: =NOV!F49 -> -1303.756 | G10: =NOV!G49 -> 2175 | H10: =NOV!H49 -> 44.343 | I10: =NOV!I49 -> 2219.343 | J10: =NOV!J49 -> 43.398929 | K10: =NOV!K49 -> 2262.7419 | L10: =NOV!L49 -> -491.51899 | M10: =NOV!M49 -> 404.2 | ... O10: =NOV!O49 -> 0 | Q10: =NOV!Q49 -> 42.228 | R10: =NOV!R49 -> 69.3264 | S10: =NOV!S49 -> 0 | T10: =NOV!T49 -> 1741.91 | U10: =NOV!U49 -> 151.47 | V10: =NOV!V49 -> 2186.0256 | AB10: =NOV!AB49 -> 734 | AC10: =NOV!AC49 -> 4758 | AD10: =NOV!AD49 -> 3031.58 | AE10: =NOV!AE49 -> 534.91792 | AF10: =NOV!AF49 -> 3566.4979 | AG10: =NOV!AG49 -> 0.01 | AJ10: =NOV!AJ50 -> 3101.286 | AK10: =NOV!AK49 -> 622.4836
A12: 1 | B12: 6903.51 | C12: 296712 | D12: =C12-C10 -> -76 | E12: =C12-152000 -> 144712 | F12: =D12/$D$2 -> -38.316108 | G12: 52 | H12: 0.93 | I12: =G12+H12 -> 52.93 | J12: =IF(L12>0,L12,0) -> 0 | K12: =I12+J12 -> 52.93 | L12: =F12-(I12-AD12) -> -14.166108 | M12: 5.1 | N12: 0 | O12: 0 | Q12: =1.51*1.02 -> 1.5402 | R12: =2.15*1.04 -> 2.236 | S12: 0 | T12: 48.98 | U12: 0 | V12: =M12-N12-O12-Q12-R12-S12+T12+U12 -> 50.3038 | Y12: 0 | AB12: 23 | AC12: =AC10-AB12 -> 4735 | AD12: =N12+O12+Q12+R12+S12+V12+Y12+AB12 -> 77.08 | AE12: =IF(L12<0,L12*-1,0) -> 14.166108 | AF12: =AD12+AE12 -> 91.246108 | AG12: 0 | AH12: 48 | AI12: 25 | AJ12: =AJ10+(V12*1.9835) -> 3201.0636 | AK12: 0
A13: =A12+1 -> 2 | B13: 6903.49 | C13: 296636 | D13: =C13-C12 -> -76 | E13: =C13-152000 -> 144636 | F13: =D13/$D$2 -> -38.316108 | G13: 52 | H13: 1.2 | I13: =G13+H13 -> 53.2 | J13: =IF(L13>0,L13,0) -> 0 | K13: =I13+J13 -> 53.2 | L13: =F13-(I13-AD13) -> -13.606108 | M13: 4.9 | N13: 0 | O13: 0 | Q13: =1.51*1.02 -> 1.5402 | R13: =2.11*1.04 -> 2.1944 | S13: 0 | T13: 49.01 | U13: 0 | V13: =M13-N13-O13-Q13-R13-S13+T13+U13 -> 50.1754 | Y13: 0 | AB13: 24 | AC13: =AC12-AB13 -> 4711 | AD13: =N13+O13+Q13+R13+S13+V13+Y13+AB13 -> 77.91 | AE13: =IF(L13<0,L13*-1,0) -> 13.606108 | AF13: =AD13+AE13 -> 91.516108 | AG13: 0 | AH13: 48 | AI13: 30 | AJ13: =AJ12+(V13*1.9835) -> 3300.5865 | AK13: 0
A14: =A13+1 -> 3 | B14: 6903.46 | C14: 296523 | D14: =C14-C13 -> -113 | E14: =C14-152000 -> 144523 | F14: =D14/$D$2 -> -56.970003 | G14: 53 | H14: 1.5 | I14: =G14+H14 -> 54.5 | J14: =IF(L14>0,L14,0) -> 0 | K14: =I14+J14 -> 54.5 | L14: =F14-(I14-AD14) -> -33.570003 | M14: 4.9 | N14: 0 | O14: 0 | Q14: =1.51*1.02 -> 1.5402 | R14: =2.41*1.04 -> 2.5064 | S14: 0 | T14: 49 | U14: 0 | V14: =M14-N14-Q14-R14-S14+T14+U14 -> 49.8534 | Y14: 0 | AB14: 24 | AC14: =AC13-AB14 -> 4687 | AD14: =N14+O14+Q14+R14+S14+V14+Y14+AB14 -> 77.9 | AE14: =IF(L14<0,L14*-1,0) -> 33.570003 | AF14: =AD14+AE14 -> 111.47 | AG14: 0.12 | AH14: 42 | AI14: 20 | AJ14: =AJ13+(V14*1.9835) -> 3399.4707 | AK14: 0
A15: =A14+1 -> 4 | B15: 6903.43 | C15: 296409 | D15: =C15-C14 -> -114 | E15: =C15-152000 -> 144409 | F15: =D15/$D$2 -> -57.474162 | G15: 50 | H15: 1.2 | I15: =G15+H15 -> 51.2 | J15: =IF(L15>0,L15,0) -> 0 | K15: =I15+J15 -> 51.2 | L15: =F15-(I15-AD15) -> -30.774162 | M15: 4.9 | N15: 0 | O15: 0 | Q15: =1.51*1.02 -> 1.5402 | R15: =2.22*1.04 -> 2.3088 | S15: 0 | T15: 49 | U15: 0 | V15: =M15-N15-Q15-R15-S15+T15+U15 -> 50.051 | Y15: 0 | AB15: 24 | AC15: =AC14-AB15 -> 4663 | AD15: =N15+O15+Q15+R15+S15+V15+Y15+AB15 -> 77.9 | AE15: =IF(L15<0,L15*-1,0) -> 30.774162 | AF15: =AD15+AE15 -> 108.67416 | AG15: 0 | AH15: 27 | AI15: 9 | AJ15: =AJ14+(V15*1.9835) -> 3498.7469 | AK15: 0
A16: =A15+1 -> 5 | B16: 6903.4 | C16: 296295 | D16: =C16-C15 -> -114 | E16: =C16-152000 -> 144295 | F16: =D16/$D$2 -> -57.474162 | G16: 43 | H16: 0.89 | I16: =G16+H16 -> 43.89 | J16: =IF(L16>0,L16,0) -> 0 | K16: =I16+J16 -> 43.89 | L16: =F16-(I16-AD16) -> -23.464162 | M16: 4.9 | N16: 0 | O16: 0 | Q16: =1.51*1.02 -> 1.5402 | R16: =2.16*1.04 -> 2.2464 | S16: 0 | T16: 49 | U16: 0 | V16: =M16-N16-Q16-R16-S16+T16+U16 -> 50.1134 | Y16: 0 | AB16: 24 | AC16: =AC15-AB16 -> 4639 | AD16: =N16+O16+Q16+R16+S16+V16+Y16+AB16 -> 77.9 | AE16: =IF(L16<0,L16*-1,0) -> 23.464162 | AF16: =AD16+AE16 -> 101.36416 | AG16: 0 | AH16: 30 | AI16: 5 | AJ16: =AJ15+(V16*1.9835) -> 3598.1468 | AK16: 0
A17: =A16+1 -> 6 | B17: 6903.37 | C17: 296181 | D17: =C17-C16 -> -114 | E17: =C17-152000 -> 144181 | F17: =D17/$D$2 -> -57.474162 | G17: 42 | H17: 0.53 | I17: =G17+H17 -> 42.53 | J17: =IF(L17>0,L17,0) -> 0 | K17: =I17+J17 -> 42.53 | L17: =F17-(I17-AD17) -> -22.104162 | M17: 4.9 | N17: 0 | O17: 0 | Q17: =1.51*1.02 -> 1.5402 | R17: =3.13*1.04 -> 3.2552 | S17: 0 | T17: 49 | U17: 0 | V17: =M17-N17-Q17-R17-S17+T17+U17 -> 49.1046 | Y17: 0 | AB17: 24 | AC17: =AC16-AB17 -> 4615 | AD17: =N17+O17+Q17+R17+S17+V17+Y17+AB17 -> 77.9 | AE17: =IF(L17<0,L17*-1,0) -> 22.104162 | AF17: =AD17+AE17 -> 100.00416 | AG17: 0 | AH17: 33 | AI17: 11 | AJ17: =AJ16+(V17*1.9835) -> 3695.5458 | AK17: 0
A18: =A17+1 -> 7 | B18: 6903.33 | C18: 296029 | D18: =C18-C17 -> -152 | E18: =C18-152000 -> 144029 | F18: =D18/$D$2 -> -76.632216 | G18: 44 | H18: 0.38 | I18: =G18+H18 -> 44.38 | J18: =IF(L18>0,L18,0) -> 0 | K18: =I18+J18 -> 44.38 | L18: =F18-(I18-AD18) -> -24.112216 | M18: 4.9 | N18: 0 | O18: 0 | Q18: =1.51*1.02 -> 1.5402 | R18: =2.44*1.04 -> 2.5376 | S18: 0 | T18: 69 | U18: 0 | V18: =M18-N18-Q18-R18-S18+T18+U18 -> 69.8222 | Y18: 0 | AB18: 23 | AC18: =AC17-AB18 -> 4592 | AD18: =N18+O18+Q18+R18+S18+V18+Y18+AB18 -> 96.9 | AE18: =IF(L18<0,L18*-1,0) -> 24.112216 | AF18: =AD18+AE18 -> 121.01222 | AG18: 0 | AH18: 25 | AI18: 6 | AJ18: =AJ17+(V18*1.9835) -> 3834.0381 | AK18: 0
A19: =A18+1 -> 8 | B19: 6903.28 | C19: 295840 | D19: =C19-C18 -> -189 | E19: =C19-152000 -> 143840 | F19: =D19/$D$2 -> -95.28611 | G19: 39 | H19: 0.15 | I19: =G19+H19 -> 39.15 | J19: =IF(L19>0,L19,0) -> 0 | K19: =I19+J19 -> 39.15 | L19: =F19-(I19-AD19) -> -9.5361104 | M19: 4.9 | N19: 0 | O19: 0 | Q19: =1.51*1.02 -> 1.5402 | R19: =2.15*1.04 -> 2.236 | S19: 0 | T19: 97 | U19: 0 | V19: =M19-N19-Q19-R19-S19+T19+U19 -> 98.1238 | Y19: 0 | AB19: 23 | AC19: =AC18-AB19 -> 4569 | AD19: =N19+O19+Q19+R19+S19+V19+Y19+AB19 -> 124.9 | AE19: =IF(L19<0,L19*-1,0) -> 9.5361104 | AF19: =AD19+AE19 -> 134.43611 | AG19: 0 | AH19: 30 | AI19: 0 | AJ19: =AJ18+(V19*1.9835) -> 4028.6667 | AK19: 0
A20: =A19+1 -> 9 | B20: 6903.23 | C20: 295650 | D20: =C20-C19 -> -190 | E20: =C20-152000 -> 143650 | F20: =D20/$D$2 -> -95.79027 | G20: 41 | H20: 0.08 | I20: =G20+H20 -> 41.08 | J20: =IF(L20>0,L20,0) -> 0 | K20: =I20+J20 -> 41.08 | L20: =F20-(I20-AD20) -> -11.97027 | M20: 4.9 | N20: 0 | O20: 0 | Q20: =1.51*1.02 -> 1.5402 | R20: =2.29*1.04 -> 2.3816 | S20: 0 | T20: 97 | U20: 0 | V20: =M20-N20-Q20-R20-S20+T20+U20 -> 97.9782 | Y20: 0 | AB20: 23 | AC20: =AC19-AB20 -> 4546 | AD20: =N20+O20+Q20+R20+S20+V20+Y20+AB20 -> 124.9 | AE20: =IF(L20<0,L20*-1,0) -> 11.97027 | AF20: =AD20+AE20 -> 136.87027 | AG20: 0 | AH20: 40 | AI20: 12 | AJ20: =AJ19+(V20*1.9835) -> 4223.0064 | AK20: 0
A21: =A20+1 -> 10 | B21: 6903.18 | C21: 295460 | D21: =C21-C20 -> -190 | E21: =C21-152000 -> 143460 | F21: =D21/$D$2 -> -95.79027 | G21: 40 | H21: 0.06 | I21: =G21+H21 -> 40.06 | J21: =IF(L21>0,L21,0) -> 0 | K21: =I21+J21 -> 40.06 | L21: =F21-(I21-AD21) -> -10.95027 | M21: 4.9 | N21: 0 | O21: 0 | Q21: =1.51*1.02 -> 1.5402 | R21: =2.1*1.04 -> 2.184 | S21: 0 | T21: 97 | U21: 0 | V21: =M21-N21-Q21-R21-S21+T21+U21 -> 98.1758 | Y21: 0 | AB21: 23 | AC21: =AC20-AB21 -> 4523 | AD21: =N21+O21+Q21+R21+S21+V21+Y21+AB21 -> 124.9 | AE21: =IF(L21<0,L21*-1,0) -> 10.95027 | AF21: =AD21+AE21 -> 135.85027 | AG21: 0 | AH21: 43 | AI21: 15 | AJ21: =AJ20+(V21*1.9835) -> 4417.7381 | AK21: 0
A22: =A21+1 -> 11 | B22: 6903.13 | C22: 295271 | D22: =C22-C21 -> -189 | E22: =C22-152000 -> 143271 | F22: =D22/$D$2 -> -95.28611 | G22: 40 | H22: 0.13 | I22: =G22+H22 -> 40.13 | J22: =IF(L22>0,L22,0) -> 0 | K22: =I22+J22 -> 40.13 | L22: =F22-(I22-AD22) -> -10.51611 | M22: 4.9 | N22: 0 | O22: 0 | Q22: =1.51*1.02 -> 1.5402 | R22: =2.2*1.04 -> 2.288 | S22: 0 | T22: 97 | U22: 0 | V22: =M22-N22-Q22-R22-S22+T22+U22 -> 98.0718 | Y22: 0 | AB22: 23 | AC22: =AC21-AB22 -> 4500 | AD22: =N22+O22+Q22+R22+S22+V22+Y22+AB22 -> 124.9 | AE22: =IF(L22<0,L22*-1,0) -> 10.51611 | AF22: =AD22+AE22 -> 135.41611 | AG22: 0 | AH22: 46 | AI22: 17 | AJ22: =AJ21+(V22*1.9835) -> 4612.2635 | AK22: 0
A23: =A22+1 -> 12 | B23: 6903.08 | C23: 295081 | D23: =C23-C22 -> -190 | E23: =C23-152000 -> 143081 | F23: =D23/$D$2 -> -95.79027 | G23: 42 | H23: 0.15 | I23: =G23+H23 -> 42.15 | J23: =IF(L23>0,L23,0) -> 0 | K23: =I23+J23 -> 42.15 | L23: =F23-(I23-AD23) -> -13.04027 | M23: 4.9 | N23: 0 | O23: 0 | Q23: =1.51*1.02 -> 1.5402 | R23: =2.38*1.04 -> 2.4752 | S23: 0 | T23: 97 | U23: 0 | V23: =M23-N23-Q23-R23-S23+T23+U23 -> 97.8846 | Y23: 0 | AB23: 23 | AC23: =AC22-AB23 -> 4477 | AD23: =N23+O23+Q23+R23+S23+V23+Y23+AB23 -> 124.9 | AE23: =IF(L23<0,L23*-1,0) -> 13.04027 | AF23: =AD23+AE23 -> 137.94027 | AG23: 0 | AH23: 43 | AI23: 21 | AJ23: =AJ22+(V23*1.9835) -> 4806.4177 | AK23: 0
A24: =A23+1 -> 13 | B24: 6903.02 | C24: 294853 | D24: =C24-C23 -> -228 | E24: =C24-152000 -> 142853 | F24: =D24/$D$2 -> -114.94832 | G24: 43 | H24: 0.17 | I24: =G24+H24 -> 43.17 | J24: =IF(L24>0,L24,0) -> 0 | K24: =I24+J24 -> 43.17 | L24: =F24-(I24-AD24) -> -34.218324 | M24: 4.9 | N24: 0 | O24: 0 | Q24: =1.51*1.02 -> 1.5402 | R24: =2.12*1.04 -> 2.2048 | S24: 0 | T24: 96 | U24: 0 | V24: =M24-N24-Q24-R24-S24+T24+U24 -> 97.155 | Y24: 0 | AB24: 23 | AC24: =AC23-AB24 -> 4454 | AD24: =N24+O24+Q24+R24+S24+V24+Y24+AB24 -> 123.9 | AE24: =IF(L24<0,L24*-1,0) -> 34.218324 | AF24: =AD24+AE24 -> 158.11832 | AG24: 0.02 | AH24: 40 | AI24: 20 | AJ24: =AJ23+(V24*1.9835) -> 4999.1246 | AK24: 0
A25: =A24+1 -> 14 | B25: 6902.96 | C25: 294627 | D25: =C25-C24 -> -226 | E25: =C25-152000 -> 142627 | F25: =D25/$D$2 -> -113.94001 | G25: 40 | H25: 0.18 | I25: =G25+H25 -> 40.18 | J25: =IF(L25>0,L25,0) -> 0 | K25: =I25+J25 -> 40.18 | L25: =F25-(I25-AD25) -> -30.220005 | M25: 4.9 | N25: 0 | O25: 0 | Q25: =1.51*1.02 -> 1.5402 | R25: =2.16*1.04 -> 2.2464 | S25: 0 | T25: 96 | U25: 0 | V25: =M25-N25-Q25-R25-S25+T25+U25 -> 97.1134 | Y25: 0 | AB25: 23 | AC25: =AC24-AB25 -> 4431 | AD25: =N25+O25+Q25+R25+S25+V25+Y25+AB25 -> 123.9 | AE25: =IF(L25<0,L25*-1,0) -> 30.220005 | AF25: =AD25+AE25 -> 154.12001 | AG25: 0 | AH25: 32 | AI25: 14 | AJ25: =AJ24+(V25*1.9835) -> 5191.749 | AK25: 0
A26: =A25+1 -> 15 | B26: 6902.91 | C26: 294439 | D26: =C26-C25 -> -188 | E26: =C26-152000 -> 142439 | F26: =D26/$D$2 -> -94.781951 | G26: 34 | H26: 0.18 | I26: =G26+H26 -> 34.18 | J26: =IF(L26>0,L26,0) -> 0 | K26: =I26+J26 -> 34.18 | L26: =F26-(I26-AD26) -> -5.0619511 | M26: 4.9 | N26: 0 | O26: 0 | Q26: =1.51*1.02 -> 1.5402 | R26: =2.35*1.04 -> 2.444 | S26: 0 | T26: 96 | U26: 0 | V26: =M26-N26-Q26-R26-S26+T26+U26 -> 96.9158 | Y26: 0 | AB26: 23 | AC26: =AC25-AB26 -> 4408 | AD26: =N26+O26+Q26+R26+S26+V26+Y26+AB26 -> 123.9 | AE26: =IF(L26<0,L26*-1,0) -> 5.0619511 | AF26: =AD26+AE26 -> 128.96195 | AG26: 0 | AH26: 33 | AI26: 3 | AJ26: =AJ25+(V26*1.9835) -> 5383.9815 | AK26: 0
A27: =A26+1 -> 16 | B27: 6902.86 | C27: 294251 | D27: =C27-C26 -> -188 | E27: =C27-152000 -> 142251 | F27: =D27/$D$2 -> -94.781951 | G27: 28 | H27: 0.16 | I27: =G27+H27 -> 28.16 | J27: =IF(L27>0,L27,0) -> 0.9580489 | K27: =I27+J27 -> 29.118049 | L27: =F27-(I27-AD27) -> 0.9580489 | M27: 4.9 | N27: 0 | O27: 0 | Q27: =1.51*1.02 -> 1.5402 | R27: =2.18*1.04 -> 2.2672 | S27: 0 | T27: 96 | U27: 0 | V27: =M27-N27-Q27-R27-S27+T27+U27 -> 97.0926 | Y27: 0 | AB27: 23 | AC27: =AC26-AB27 -> 4385 | AD27: =N27+O27+Q27+R27+S27+V27+Y27+AB27 -> 123.9 | AE27: =IF(L27<0,L27*-1,0) -> 0 | AF27: =AD27+AE27 -> 123.9 | AG27: 0 | AH27: 32 | AI27: 1 | AJ27: =AJ26+(V27*1.9835) -> 5576.5647 | AK27: 0
A28: =A27+1 -> 17 | B28: 6902.82 | C28: 294100 | D28: =C28-C27 -> -151 | E28: =C28-152000 -> 142100 | F28: =D28/$D$2 -> -76.128056 | G28: 27 | H28: 0.11 | I28: =G28+H28 -> 27.11 | J28: =IF(L28>0,L28,0) -> 20.661944 | K28: =I28+J28 -> 47.771944 | L28: =F28-(I28-AD28) -> 20.661944 | M28: 4.9 | N28: 0 | O28: 0 | Q28: =1.51*1.02 -> 1.5402 | R28: =1.97*1.04 -> 2.0488 | S28: 0 | T28: 96 | U28: 0 | V28: =M28-N28-Q28-R28-S28+T28+U28 -> 97.311 | Y28: 0 | AB28: 23 | AC28: =AC27-AB28 -> 4362 | AD28: =N28+O28+Q28+R28+S28+V28+Y28+AB28 -> 123.9 | AE28: =IF(L28<0,L28*-1,0) -> 0 | AF28: =AD28+AE28 -> 123.9 | AG28: 0 | AH28: 35 | AI28: 11 | AJ28: =AJ27+(V28*1.9835) -> 5769.5811 | AK28: 0
A29: =A28+1 -> 18 | B29: 6902.78 | C29: 293950 | D29: =C29-C28 -> -150 | E29: =C29-152000 -> 141950 | F29: =D29/$D$2 -> -75.623897 | G29: 29 | H29: 0.08 | I29: =G29+H29 -> 29.08 | J29: =IF(L29>0,L29,0) -> 19.196103 | K29: =I29+J29 -> 48.276103 | L29: =F29-(I29-AD29) -> 19.196103 | M29: 4.9 | N29: 0 | O29: 0 | Q29: =1.51*1.02 -> 1.5402 | R29: =2.49*1.04 -> 2.5896 | S29: 0 | T29: 96 | U29: 0 | V29: =M29-N29-Q29-R29-S29+T29+U29 -> 96.7702 | Y29: 0 | AB29: 23 | AC29: =AC28-AB29 -> 4339 | AD29: =N29+O29+Q29+R29+S29+V29+Y29+AB29 -> 123.9 | AE29: =IF(L29<0,L29*-1,0) -> 0 | AF29: =AD29+AE29 -> 123.9 | AG29: 0.06 | AH29: 41 | AI29: 20 | AJ29: =AJ28+(V29*1.9835) -> 5961.5247 | AK29: 0
A30: =A29+1 -> 19 | B30: 6902.74 | C30: 293799 | D30: =C30-C29 -> -151 | E30: =C30-152000 -> 141799 | F30: =D30/$D$2 -> -76.128056 | G30: 40 | H30: 0.1 | I30: =G30+H30 -> 40.1 | J30: =IF(L30>0,L30,0) -> 0 | K30: =I30+J30 -> 40.1 | L30: =F30-(I30-AD30) -> -35.328056 | M30: 4.9 | N30: 0 | O30: 0 | Q30: =1.51*1.02 -> 1.5402 | R30: =2.2*1.04 -> 2.288 | S30: 0 | T30: 53 | U30: 0 | V30: =M30-N30-Q30-R30-S30+T30+U30 -> 54.0718 | Y30: 0 | AB30: 23 | AC30: =AC29-AB30 -> 4316 | AD30: =N30+O30+Q30+R30+S30+V30+Y30+AB30 -> 80.9 | AE30: =IF(L30<0,L30*-1,0) -> 35.328056 | AF30: =AD30+AE30 -> 116.22806 | AG30: 0 | AH30: 44 | AI30: 27 | AJ30: =AJ29+(V30*1.9835) -> 6068.7762 | AK30: 0
A31: =A30+1 -> 20 | B31: 6902.74 | C31: 293799 | D31: =C31-C30 -> 0 | E31: =C31-152000 -> 141799 | F31: =D31/$D$2 -> 0 | G31: 45 | H31: 0.14 | I31: =G31+H31 -> 45.14 | J31: =IF(L31>0,L31,0) -> 8.8 | K31: =I31+J31 -> 53.94 | L31: =F31-(I31-AD31) -> 8.8 | M31: 4.9 | N31: 0 | O31: 0 | Q31: =1.51*1.02 -> 1.5402 | R31: =2.22*1.04 -> 2.3088 | S31: 0 | T31: 26.04 | U31: 0 | V31: =M31-N31-Q31-R31-S31+T31+U31 -> 27.091 | Y31: 0 | AB31: 23 | AC31: =AC30-AB31 -> 4293 | AD31: =N31+O31+Q31+R31+S31+V31+Y31+AB31 -> 53.94 | AE31: =IF(L31<0,L31*-1,0) -> 0 | AF31: =AD31+AE31 -> 53.94 | AG31: 0.11 | AH31: 41 | AI31: 25 | AJ31: =AJ30+(V31*1.9835) -> 6122.5112 | AK31: 0
A32: =A31+1 -> 21 | B32: 6902.73 | C32: 293761 | D32: =C32-C31 -> -38 | E32: =C32-152000 -> 141761 | F32: =D32/$D$2 -> -19.158054 | G32: 43 | H32: 0.17 | I32: =G32+H32 -> 43.17 | J32: =IF(L32>0,L32,0) -> 0 | K32: =I32+J32 -> 43.17 | L32: =F32-(I32-AD32) -> -9.3280539 | M32: 5 | N32: 0 | O32: 0 | Q32: =1.51*1.02 -> 1.5402 | R32: =3.39*1.04 -> 3.5256 | S32: 0 | T32: 25 | U32: 0 | V32: =M32-N32-Q32-R32-S32+T32+U32 -> 24.9342 | Y32: 0 | AB32: 23 | AC32: =AC31-AB32 -> 4270 | AD32: =N32+O32+Q32+R32+S32+V32+Y32+AB32 -> 53 | AE32: =IF(L32<0,L32*-1,0) -> 9.3280539 | AF32: =AD32+AE32 -> 62.328054 | AG32: 0 | AH32: 54 | AI32: 26 | AJ32: =AJ31+(V32*1.9835) -> 6171.9681 | AK32: 0
A33: =A32+1 -> 22 | B33: 6902.72 | C33: 293724 | D33: =C33-C32 -> -37 | E33: =C33-152000 -> 141724 | F33: =D33/$D$2 -> -18.653895 | G33: 42 | H33: 0.27 | I33: =G33+H33 -> 42.27 | J33: =IF(L33>0,L33,0) -> 0 | K33: =I33+J33 -> 42.27 | L33: =F33-(I33-AD33) -> -7.7238946 | M33: 5.2 | N33: 0 | O33: 0 | Q33: =1.51*1.02 -> 1.5402 | R33: =2.6*1.04 -> 2.704 | S33: 0 | T33: 25 | U33: 0 | V33: =M33-N33-O33-Q33-R33-S33+T33+U33 -> 25.9558 | Y33: 0 | AB33: 23 | AC33: =AC32-AB33 -> 4247 | AD33: =N33+O33+Q33+R33+S33+V33+Y33+AB33 -> 53.2 | AE33: =IF(L33<0,L33*-1,0) -> 7.7238946 | AF33: =AD33+AE33 -> 60.923895 | AG33: 0 | AH33: 56 | AI33: 29 | AJ33: =AJ32+(V33*1.9835) -> 6223.4515 | AK33: 0
A34: =A33+1 -> 23 | B34: 6902.71 | C34: 293686 | D34: =C34-C33 -> -38 | E34: =C34-152000 -> 141686 | F34: =D34/$D$2 -> -19.158054 | G34: 43 | H34: 0.44 | I34: =G34+H34 -> 43.44 | J34: =IF(L34>0,L34,0) -> 0 | K34: =I34+J34 -> 43.44 | L34: =F34-(I34-AD34) -> -9.5980539 | M34: 5 | N34: 0 | O34: 0 | Q34: =1.51*1.02 -> 1.5402 | R34: =3.38*1.04 -> 3.5152 | S34: 0 | T34: 25 | U34: 0 | V34: =M34-N34-O34-Q34-R34-S34+T34+U34 -> 24.9446 | Y34: 0 | AB34: 23 | AC34: =AC33-AB34 -> 4224 | AD34: =N34+O34+Q34+R34+S34+V34+Y34+AB34 -> 53 | AE34: =IF(L34<0,L34*-1,0) -> 9.5980539 | AF34: =AD34+AE34 -> 62.598054 | AG34: 0 | AH34: 53 | AI34: 30 | AJ34: =AJ33+(V34*1.9835) -> 6272.9291 | AK34: 0
A35: =A34+1 -> 24 | B35: 6902.7 | C35: 293649 | D35: =C35-C34 -> -37 | E35: =C35-152000 -> 141649 | F35: =D35/$D$2 -> -18.653895 | G35: 41 | H35: 0.65 | I35: =G35+H35 -> 41.65 | J35: =IF(L35>0,L35,0) -> 0 | K35: =I35+J35 -> 41.65 | L35: =F35-(I35-AD35) -> -7.4038946 | M35: 4.9 | N35: 0 | O35: 0 | Q35: =1.51*1.02 -> 1.5402 | R35: =2.74*1.04 -> 2.8496 | S35: 0 | T35: 25 | U35: 0 | V35: =M35-N35-O35-Q35-R35-S35+T35+U35 -> 25.5102 | Y35: 0 | AB35: 23 | AC35: =AC34-AB35 -> 4201 | AD35: =N35+O35+Q35+R35+S35+V35+Y35+AB35 -> 52.9 | AE35: =IF(L35<0,L35*-1,0) -> 7.4038946 | AF35: =AD35+AE35 -> 60.303895 | AG35: 0 | AH35: 53 | AI35: 30 | AJ35: =AJ34+(V35*1.9835) -> 6323.5286 | AK35: 0
A36: =A35+1 -> 25 | B36: 6902.69 | C36: 293611 | D36: =C36-C35 -> -38 | E36: =C36-152000 -> 141611 | F36: =D36/$D$2 -> -19.158054 | G36: 40 | H36: 1 | I36: =G36+H36 -> 41 | J36: =IF(L36>0,L36,0) -> 0 | K36: =I36+J36 -> 41 | L36: =F36-(I36-AD36) -> -7.0580539 | M36: 5.1 | N36: 0 | O36: 0 | Q36: =1.51*1.02 -> 1.5402 | R36: =2.55*1.04 -> 2.652 | S36: 0 | T36: 25 | U36: 0 | V36: =M36-N36-O36-Q36-R36-S36+T36+U36 -> 25.9078 | Y36: 0 | AB36: 23 | AC36: =AC35-AB36 -> 4178 | AD36: =N36+O36+Q36+R36+S36+V36+Y36+AB36 -> 53.1 | AE36: =IF(L36<0,L36*-1,0) -> 7.0580539 | AF36: =AD36+AE36 -> 60.158054 | AG36: 0 | AH36: 54 | AI36: 27 | AJ36: =AJ35+(V36*1.9835) -> 6374.9167 | AK36: 0
A37: =A36+1 -> 26 | B37: 6902.68 | C37: 293573 | D37: =C37-C36 -> -38 | E37: =C37-152000 -> 141573 | F37: =D37/$D$2 -> -19.158054 | G37: 39 | H37: 1.8 | I37: =G37+H37 -> 40.8 | J37: =IF(L37>0,L37,0) -> 0 | K37: =I37+J37 -> 40.8 | L37: =F37-(I37-AD37) -> -7.7580539 | M37: 5.2 | N37: 0 | O37: 0 | Q37: =1.51*1.02 -> 1.5402 | R37: =2.13*1.04 -> 2.2152 | S37: 0 | T37: 25 | U37: 0 | V37: =M37-N37-O37-Q37-R37-S37+T37+U37 -> 26.4446 | Y37: 0 | AB37: 22 | AC37: =AC36-AB37 -> 4156 | AD37: =N37+O37+Q37+R37+S37+V37+Y37+AB37 -> 52.2 | AE37: =IF(L37<0,L37*-1,0) -> 7.7580539 | AF37: =AD37+AE37 -> 59.958054 | AG37: 0.01 | AH37: 54 | AI37: 26 | AJ37: =AJ36+(V37*1.9835) -> 6427.3696 | AK37: 0
A38: =A37+1 -> 27 | B38: 6902.67 | C38: 293536 | D38: =C38-C37 -> -37 | E38: =C38-152000 -> 141536 | F38: =D38/$D$2 -> -18.653895 | G38: 39 | H38: 2.1 | I38: =G38+H38 -> 41.1 | J38: =IF(L38>0,L38,0) -> 0 | K38: =I38+J38 -> 41.1 | L38: =F38-(I38-AD38) -> -7.5538946 | M38: 5.2 | N38: 0 | O38: 0 | Q38: =1.51*1.02 -> 1.5402 | R38: =2.34*1.04 -> 2.4336 | S38: 0 | T38: 25 | U38: 0 | V38: =M38-N38-O38-Q38-R38-S38+T38+U38 -> 26.2262 | Y38: 0 | AB38: 22 | AC38: =AC37-AB38 -> 4134 | AD38: =N38+O38+Q38+R38+S38+V38+Y38+AB38 -> 52.2 | AE38: =IF(L38<0,L38*-1,0) -> 7.5538946 | AF38: =AD38+AE38 -> 59.753895 | AG38: 0 | AH38: 44 | AI38: 24 | AJ38: =AJ37+(V38*1.9835) -> 6479.3892 | AK38: 0
A39: =A38+1 -> 28 | B39: 6902.66 | C39: 293498 | D39: =C39-C38 -> -38 | E39: =C39-152000 -> 141498 | F39: =D39/$D$2 -> -19.158054 | G39: 39 | H39: 2.1 | I39: =G39+H39 -> 41.1 | J39: =IF(L39>0,L39,0) -> 0 | K39: =I39+J39 -> 41.1 | L39: =F39-(I39-AD39) -> -8.1580539 | M39: 5.1 | N39: 0 | O39: 0 | Q39: =1.51*1.02 -> 1.5402 | R39: =2.27*1.04 -> 2.3608 | S39: 0 | T39: 25 | U39: 0 | V39: =M39-N39-O39-Q39-R39-S39+T39+U39 -> 26.199 | Y39: 0 | AB39: 22 | AC39: =AC38-AB39 -> 4112 | AD39: =N39+O39+Q39+R39+S39+V39+Y39+AB39 -> 52.1 | AE39: =IF(L39<0,L39*-1,0) -> 8.1580539 | AF39: =AD39+AE39 -> 60.258054 | AG39: 0.01 | AH39: 51 | AI39: 25 | AJ39: =AJ38+(V39*1.9835) -> 6531.3549 | AK39: 0
A40: =A39+1 -> 29 | B40: 6902.65 | C40: 293460 | D40: =C40-C39 -> -38 | E40: =C40-152000 -> 141460 | F40: =D40/$D$2 -> -19.158054 | G40: 42 | H40: 2 | I40: =G40+H40 -> 44 | J40: =IF(L40>0,L40,0) -> 0 | K40: =I40+J40 -> 44 | L40: =F40-(I40-AD40) -> -11.458054 | M40: 4.7 | N40: 0 | O40: 0 | Q40: =1.51*1.02 -> 1.5402 | R40: =2.29*1.04 -> 2.3816 | S40: 0 | T40: 25 | U40: 0 | V40: =M40-N40-O40-Q40-R40-S40+T40+U40 -> 25.7782 | Y40: 0 | AB40: 22 | AC40: =AC39-AB40 -> 4090 | AD40: =N40+O40+Q40+R40+S40+V40+Y40+AB40 -> 51.7 | AE40: =IF(L40<0,L40*-1,0) -> 11.458054 | AF40: =AD40+AE40 -> 63.158054 | AG40: 0 | AH40: 43 | AI40: 23 | AJ40: =AJ39+(V40*1.9835) -> 6582.486 | AK40: 0
A41: 30 | B41: 6902.64 | C41: 293423 | D41: =C41-C40 -> -37 | E41: =C41-152000 -> 141423 | F41: =D41/$D$2 -> -18.653895 | G41: 42 | H41: 1.9 | I41: =G41+H41 -> 43.9 | J41: =IF(L41>0,L41,0) -> 0 | K41: =I41+J41 -> 43.9 | L41: =F41-(I41-AD41) -> -10.953895 | M41: 4.6 | N41: 0 | O41: 0 | Q41: =1.51*1.02 -> 1.5402 | R41: =2.18*1.04 -> 2.2672 | S41: 0 | T41: 25 | U41: 0 | V41: =M41-N41-O41-Q41-R41-S41+T41+U41 -> 25.7926 | Y41: 0 | AB41: 22 | AC41: =AC40-AB41 -> 4068 | AD41: =N41+O41+Q41+R41+S41+V41+Y41+AB41 -> 51.6 | AE41: =IF(L41<0,L41*-1,0) -> 10.953895 | AF41: =AD41+AE41 -> 62.553895 | AG41: 0 | AH41: 44 | AI41: 18 | AJ41: =AJ40+(V41*1.9835) -> 6633.6456 | AK41: 0
A42: 31 | B42: 6902.64 | C42: 293423 | D42: =C42-C41 -> 0 | E42: =C42-152000 -> 141423 | F42: =D42/$D$2 -> 0 | G42: 42 | H42: 1.9 | I42: =G42+H42 -> 43.9 | J42: =IF(L42>0,L42,0) -> 8 | K42: =I42+J42 -> 51.9 | L42: =F42-(I42-AD42) -> 8 | M42: 4.9 | N42: 0 | O42: 0 | Q42: =1.51*1.02 -> 1.5402 | R42: =3.2*1.04 -> 3.328 | S42: 0 | T42: 25 | U42: 0 | V42: =M42-N42-O42-Q42-R42-S42+T42+U42 -> 25.0318 | Y42: 0 | AB42: 22 | AC42: =AC41-AB42 -> 4046 | AD42: =N42+O42+Q42+R42+S42+V42+Y42+AB42 -> 51.9 | AE42: =IF(L42<0,L42*-1,0) -> 0 | AF42: =AD42+AE42 -> 51.9 | AG42: 0.06 | AH42: 49 | AI42: 30 | AJ42: =AJ41+(V42*1.9835) -> 6683.2962 | AK42: 0
...

Sheet JAN
K1: MCPHEE RESERVOIR INFLOW/OUTFLOW TABULATION
A2: AF/cfs CONVERT FACTOR | D2: 1.9835 | K2: JANUARY "2006"
D4: RESERVOIR | T4: INFLOW/OUTFLOW (CFS) | AH4: WEATHER | AL4: ADJUSTMENTS
A5: DATE | B5: RESERV | C5: RESERV | D5: AC FT | E5: ACTIVE | F5: CONV TO | G5: DOLORES | H5: LOST | I5: RECORD | J5: CALC | K5: TOTAL | L5: CALC | M5: DOLORES TUNNEL | T5: LONE | U5: U | V5: TOTAL | W5: MVI | X5: MVI | Y5: DV CR | Z5: D/S SENIOR | AB5: BELOW | AC5: FISH | AD5: RECORD | AE5: CALC | AF5: TOTAL | AG5: RAIN | AH5: MAX | AI5: MIN | AJ5: NAR | AK5: MVI | AL5: MVI | AM5: MVI | AN5: U/S | AO5: TOTTEN
A6: JAN | B6: ELEV | C6: AC FT | D6: CHANGE | E6: CAP | F6: CFS | G6: RIVER | H6: CAN | I6: INFLOW | J6: INFLOW | K6: INFLOW | L6: INF/OTF | M6: TOT DIV | N6: WET | O6: UTE | P6: QUEST | Q6: MWC | R6: CTZ | S6: CTZ & | T6: PINE | U6: LAT | V6: MVI | W6: CALL | X6: PROJ & | Y6: CANAL | AB6: MCP | AC6: LEFT | AD6: OTF | AE6: OTF | AF6: OTF | AH6: TMP | AI6: TMP | AJ6: CALL | AK6: STOCK | AL6: STORED | AM6: STORED | AN6: USERS | AO6: (FRESH
E7: AC FT | N7: LAND | O7: F&R | S7: UTE | X7: TO EX & | AJ7: AC.FT. | AK7: AC.FT. | AL7: Apr-Jun | AM7: EVAP | AN7: EXCH | AO7: WATER)
N8: 1.03 | O8: 1.05 | P8: 1.02 | Q8: 1.02 | R8: 1.04 | S8: PROJ | X8: U/S EX | AM8: AC.FT.
A9: SEASON BAL
A10: YTD | B10: =DEC!B42 -> 6902.64 | C10: =DEC!C42 -> 293423 | D10: =DEC!D51 -> -5951 | E10: =DEC!E51 -> 141423 | F10: =DEC!F50 -> -3000.2521 | G10: =DEC!G50 -> 3451 | H10: =DEC!H50 -> 66.993 | I10: =DEC!I50 -> 3517.993 | J10: =DEC!J50 -> 101.01502 | K10: =DEC!K50 -> 3619.008 | L10: =DEC!L50 -> -843.53508 | M10: =DEC!M50 -> 557.3 | ... O10: =DEC!O50 -> 0 | Q10: =DEC!Q50 -> 89.9742 | R10: =DEC!R50 -> 146.8064 | S10: =DEC!S50 -> 0 | T10: =DEC!T50 -> 3519.94 | U10: =DEC!U50 -> 151.47 | V10: =DEC!V50 -> 3991.9294 | AB10: =DEC!AB50 -> 1446 | AC10: =DEC!AC50 -> 4046 | AD10: =DEC!AD50 -> 5674.71 | AE10: =DEC!AE50 -> 944.5501 | AF10: =DEC!AF50 -> 6619.2601 | AG10: =DEC!AG50 -> 0.4 | AJ10: =DEC!AJ51 -> 6683.2962
A12: 1 | B12: 6902.64 | C12: 293423 | D12: =C12-C10 -> 0 | E12: =C12-152000 -> 141423 | F12: =D12/$D$2 -> 0 | G12: 44 | H12: 2 | I12: =G12+H12 -> 46 | J12: =IF(L12>0,L12,0) -> 5.7 | K12: =I12+J12 -> 51.7 | L12: =F12-(I12-AD12) -> 5.7 | M12: 4.7 | N12: 0 | O12: 0 | Q12: =1.4*1.02 -> 1.428 | R12: =3.08*1.04 -> 3.2032 | S12: 0 | T12: 25 | U12: 0 | V12: =M12-N12-O12-Q12-R12-S12+T12+U12 -> 25.0688 | Y12: 0 | AB12: 22 | AC12: =AC10-AB12 -> 4024 | AD12: =N12+O12+Q12+R12+S12+V12+Y12+AB12 -> 51.7 | AE12: =IF(L12<0,L12*-1,0) -> 0 | AF12: =AD12+AE12 -> 51.7 | AG12: 0.11 | AH12: 41 | AI12: 25 | AJ12: =AJ10+(V12*1.9835) -> 6733.0202 | AK12: 0
A13: =A12+1 -> 2 | B13: 6902.63 | C13: 293385 | D13: =C13-C12 -> -38 | E13: =C13-152000 -> 141385 | F13: =D13/$D$2 -> -19.158054 | G13: 42 | H13: 2 | I13: =G13+H13 -> 44 | J13: =IF(L13>0,L13,0) -> 0 | K13: =I13+J13 -> 44 | L13: =F13-(I13-AD13) -> -11.558054 | M13: 4.6 | N13: 0 | O13: 0 | Q13: =1.4*1.02 -> 1.428 | R13: =2.55*1.04 -> 2.652 | S13: 0 | T13: 25 | U13: 0 | V13: =M13-N13-O13-Q13-R13-S13+T13+U13 -> 25.52 | Y13: 0 | AB13: 22 | AC13: =AC12-AB13 -> 4002 | AD13: =N13+O13+Q13+R13+S13+V13+Y13+AB13 -> 51.6 | AE13: =IF(L13<0,L13*-1,0) -> 11.558054 | AF13: =AD13+AE13 -> 63.158054 | AG13: 0 | AH13: 49 | AI13: 26 | AJ13: =AJ12+(V13*1.9835) -> 6783.6391 | AK13: 0
A14: =A13+1 -> 3 | B14: 6902.63 | C14: 293385 | D14: =C14-C13 -> 0 | E14: =C14-152000 -> 141385 | F14: =D14/$D$2 -> 0 | G14: 40 | H14: 2 | I14: =G14+H14 -> 42 | J14: =IF(L14>0,L14,0) -> 9.6 | K14: =I14+J14 -> 51.6 | L14: =F14-(I14-AD14) -> 9.6 | M14: 4.6 | N14: 0 | O14: 0 | Q14: =1.4*1.02 -> 1.428 | R14: =2.22*1.04 -> 2.3088 | S14: 0 | T14: 25 | U14: 0 | V14: =M14-N14-O14-Q14-R14-S14+T14+U14 -> 25.8632 | Y14: 0 | AB14: 22 | AC14: =AC13-AB14 -> 3980 | AD14: =N14+O14+Q14+R14+S14+V14+Y14+AB14 -> 51.6 | AE14: =IF(L14<0,L14*-1,0) -> 0 | AF14: =AD14+AE14 -> 51.6 | AG14: 0.01 | AH14: 45 | AI14: 27 | AJ14: =AJ13+(V14*1.9835) -> 6834.9387 | AK14: 0
A15: =A14+1 -> 4 | B15: 6902.63 | C15: 293385 | D15: =C15-C14 -> 0 | E15: =C15-152000 -> 141385 | F15: =D15/$D$2 -> 0 | G15: 40 | H15: 1.9 | I15: =G15+H15 -> 41.9 | J15: =IF(L15>0,L15,0) -> 9.7 | K15: =I15+J15 -> 51.6 | L15: =F15-(I15-AD15) -> 9.7 | M15: 4.6 | N15: 0 | O15: 0 | Q15: =1.4*1.02 -> 1.428 | R15: =2.28*1.04 -> 2.3712 | S15: 0 | T15: 25 | U15: 0 | V15: =M15-N15-O15-Q15-R15-S15+T15+U15 -> 25.8008 | Y15: 0 | AB15: 22 | AC15: =AC14-AB15 -> 3958 | AD15: =N15+O15+Q15+R15+S15+V15+Y15+AB15 -> 51.6 | AE15: =IF(L15<0,L15*-1,0) -> 0 | AF15: =AD15+AE15 -> 51.6 | AG15: 0 | AH15: 45 | AI15: 26 | AJ15: =AJ14+(V15*1.9835) -> 6886.1146 | AK15: 0
A16: =A15+1 -> 5 | B16: 6902.64 | C16: 293423 | D16: =C16-C15 -> 38 | E16: =C16-152000 -> 141423 | F16: =D16/$D$2 -> 19.158054 | G16: 38 | H16: 1.8 | I16: =G16+H16 -> 39.8 | J16: =IF(L16>0,L16,0) -> 31.058054 | K16: =I16+J16 -> 70.858054 | L16: =F16-(I16-AD16) -> 31.058054 | M16: 4.7 | N16: 0 | O16: 0 | Q16: =1.4*1.02 -> 1.428 | R16: =2.2*1.04 -> 2.288 | S16: 0 | T16: 25 | U16: 0 | V16: =M16-N16-O16-Q16-R16-S16+T16+U16 -> 25.984 | Y16: 0 | AB16: 22 | AC16: =AC15-AB16 -> 3936 | AD16: =N16+O16+Q16+R16+S16+V16+Y16+AB16 -> 51.7 | AE16: =IF(L16<0,L16*-1,0) -> 0 | AF16: =AD16+AE16 -> 51.7 | AG16: 0 | AH16: 50 | AI16: 31 | AJ16: =AJ15+(V16*1.9835) -> 6937.6539 | AK16: 0
A17: =A16+1 -> 6 | B17: 6902.64 | C17: 293423 | D17: =C17-C16 -> 0 | E17: =C17-152000 -> 141423 | F17: =D17/$D$2 -> 0 | G17: 37 | H17: 1.7 | I17: =G17+H17 -> 38.7 | J17: =IF(L17>0,L17,0) -> 13.2 | K17: =I17+J17 -> 51.9 | L17: =F17-(I17-AD17) -> 13.2 | M17: 4.9 | N17: 0 | O17: 0 | Q17: =1.4*1.02 -> 1.428 | R17: =2.67*1.04 -> 2.7768 | S17: 0 | T17: 25 | U17: 0 | V17: =M17-N17-O17-Q17-R17-S17+T17+U17 -> 25.6952 | Y17: 0 | AB17: 22 | AC17: =AC16-AB17 -> 3914 | AD17: =N17+O17+Q17+R17+S17+V17+Y17+AB17 -> 51.9 | AE17: =IF(L17<0,L17*-1,0) -> 0 | AF17: =AD17+AE17 -> 51.9 | AG17: 0 | AH17: 54 | AI17: 26 | AJ17: =AJ16+(V17*1.9835) -> 6988.6203 | AK17: 0
A18: =A17+1 -> 7 | B18: 6902.65 | C18: 293460 | D18: =C18-C17 -> 37 | E18: =C18-152000 -> 141460 | F18: =D18/$D$2 -> 18.653895 | G18: 38 | H18: 1.8 | I18: =G18+H18 -> 39.8 | J18: =IF(L18>0,L18,0) -> 30.753895 | K18: =I18+J18 -> 70.553895 | L18: =F18-(I18-AD18) -> 30.753895 | M18: 4.9 | N18: 0 | O18: 0 | Q18: =1.4*1.02 -> 1.428 | R18: =2.29*1.04 -> 2.3816 | S18: 0 | T18: 25 | U18: 0 | V18: =M18-N18-O18-Q18-R18-S18+T18+U18 -> 26.0904 | Y18: 0 | AB18: 22 | AC18: =AC17-AB18 -> 3892 | AD18: =N18+O18+Q18+R18+S18+V18+Y18+AB18 -> 51.9 | AE18: =IF(L18<0,L18*-1,0) -> 0 | AF18: =AD18+AE18 -> 51.9 | AG18: 0 | AH18: 54 | AI18: 27 | AJ18: =AJ17+(V18*1.9835) -> 7040.3706 | AK18: 0
A19: =A18+1 -> 8 | B19: 6902.64 | C19: 293423 | D19: =C19-C18 -> -37 | E19: =C19-152000 -> 141423 | F19: =D19/$D$2 -> -18.653895 | G19: 38 | H19: 1.7 | I19: =G19+H19 -> 39.7 | J19: =IF(L19>0,L19,0) -> 0 | K19: =I19+J19 -> 39.7 | L19: =F19-(I19-AD19) -> -6.7538946 | M19: 4.6 | N19: 0 | O19: 0 | Q19: =1.4*1.02 -> 1.428 | R19: =2.11*1.04 -> 2.1944 | S19: 0 | T19: 25 | U19: 0 | V19: =M19-N19-O19-Q19-R19-S19+T19+U19 -> 25.9776 | Y19: 0 | AB19: 22 | AC19: =AC18-AB19 -> 3870 | AD19: =N19+O19+Q19+R19+S19+V19+Y19+AB19 -> 51.6 | AE19: =IF(L19<0,L19*-1,0) -> 6.7538946 | AF19: =AD19+AE19 -> 58.353895 | AG19: 0 | AH19: 45 | AI19: 21 | AJ19: =AJ18+(V19*1.9835) -> 7091.8972 | AK19: 0
A20: =A19+1 -> 9 | B20: 6902.63 | C20: 293385 | D20: =C20-C19 -> -38 | E20: =C20-152000 -> 141385 | F20: =D20/$D$2 -> -19.158054 | G20: 38 | H20: 1.6 | I20: =G20+H20 -> 39.6 | J20: =IF(L20>0,L20,0) -> 0 | K20: =I20+J20 -> 39.6 | L20: =F20-(I20-AD20) -> -7.0580539 | M20: 4.7 | N20: 0 | O20: 0 | Q20: =1.4*1.02 -> 1.428 | R20: =2.27*1.04 -> 2.3608 | S20: 0 | T20: 25 | U20: 0 | V20: =M20-N20-O20-Q20-R20-S20+T20+U20 -> 25.9112 | Y20: 0 | AB20: 22 | AC20: =AC19-AB20 -> 3848 | AD20: =N20+O20+Q20+R20+S20+V20+Y20+AB20 -> 51.7 | AE20: =IF(L20<0,L20*-1,0) -> 7.0580539 | AF20: =AD20+AE20 -> 58.758054 | AG20: 0 | AH20: 40 | AI20: 18 | AJ20: =AJ19+(V20*1.9835) -> 7143.2921 | AK20: 0
A21: =A20+1 -> 10 | B21: 6903.63 | C21: 293385 | D21: =C21-C20 -> 0 | E21: =C21-152000 -> 141385 | F21: =D21/$D$2 -> 0 | G21: 30 | H21: 1.6 | I21: =G21+H21 -> 31.6 | J21: =IF(L21>0,L21,0) -> 20.2 | K21: =I21+J21 -> 51.8 | L21: =F21-(I21-AD21) -> 20.2 | M21: 4.8 | N21: 0 | O21: 0 | Q21: =1.4*1.02 -> 1.428 | R21: =2.15*1.04 -> 2.236 | S21: 0 | T21: 25 | U21: 0 | V21: =M21-N21-O21-Q21-R21-S21+T21+U21 -> 26.136 | Y21: 0 | AB21: 22 | AC21: =AC20-AB21 -> 3826 | AD21: =N21+O21+Q21+R21+S21+V21+Y21+AB21 -> 51.8 | AE21: =IF(L21<0,L21*-1,0) -> 0 | AF21: =AD21+AE21 -> 51.8 | AG21: 0 | AH21: 46 | AI21: 15 | AJ21: =AJ20+(V21*1.9835) -> 7195.1328 | AK21: 0
A22: =A21+1 -> 11 | B22: 6902.62 | C22: 293347 | D22: =C22-C21 -> -38 | E22: =C22-152000 -> 141347 | F22: =D22/$D$2 -> -19.158054 | G22: 28 | H22: 1.5 | I22: =G22+H22 -> 29.5 | J22: =IF(L22>0,L22,0) -> 2.9419461 | K22: =I22+J22 -> 32.441946 | L22: =F22-(I22-AD22) -> 2.9419461 | M22: 4.6 | N22: 0 | O22: 0 | Q22: =1.4*1.02 -> 1.428 | R22: =2.24*1.04 -> 2.3296 | S22: 0 | T22: 25 | U22: 0 | V22: =M22-N22-O22-Q22-R22-S22+T22+U22 -> 25.8424 | Y22: 0 | AB22: 22 | AC22: =AC21-AB22 -> 3804 | AD22: =N22+O22+Q22+R22+S22+V22+Y22+AB22 -> 51.6 | AE22: =IF(L22<0,L22*-1,0) -> 0 | AF22: =AD22+AE22 -> 51.6 | AG22: 0 | AH22: 49 | AI22: 21 | AJ22: =AJ21+(V22*1.9835) -> 7246.3912 | AK22: 0
A23: =A22+1 -> 12 | B23: 6902.61 | C23: 293310 | D23: =C23-C22 -> -37 | E23: =C23-152000 -> 141310 | F23: =D23/$D$2 -> -18.653895 | G23: 34 | H23: 1.4 | I23: =G23+H23 -> 35.4 | J23: =IF(L23>0,L23,0) -> 0 | K23: =I23+J23 -> 35.4 | L23: =F23-(I23-AD23) -> -2.4538946 | M23: 4.6 | N23: 0 | O23: 0 | Q23: =1.4*1.02 -> 1.428 | R23: =2.53*1.04 -> 2.6312 | S23: 0 | T23: 25 | U23: 0 | V23: =M23-N23-O23-Q23-R23-S23+T23+U23 -> 25.5408 | Y23: 0 | AB23: 22 | AC23: =AC22-AB23 -> 3782 | AD23: =N23+O23+Q23+R23+S23+V23+Y23+AB23 -> 51.6 | AE23: =IF(L23<0,L23*-1,0) -> 2.4538946 | AF23: =AD23+AE23 -> 54.053895 | AG23: 0 | AH23: 39 | AI23: 23 | AJ23: =AJ22+(V23*1.9835) -> 7297.0514 | AK23: 0
A24: 13 | B24: 6902.6 | C24: 293272 | D24: =C24-C23 -> -38 | E24: =C24-152000 -> 141272 | F24: =D24/$D$2 -> -19.158054 | G24: 34 | H24: 1.4 | I24: =G24+H24 -> 35.4 | J24: =IF(L24>0,L24,0) -> 0 | K24: =I24+J24 -> 35.4 | L24: =F24-(I24-AD24) -> -2.7580539 | M24: 4.8 | N24: 0 | O24: 0 | Q24: =1.4*1.02 -> 1.428 | R24: =2.33*1.04 -> 2.4232 | S24: 0 | T24: 25 | U24: 0 | V24: =M24-N24-O24-Q24-R24-S24+T24+U24 -> 25.9488 | Y24: 0 | AB24: 22 | AC24: =AC23-AB24 -> 3760 | AD24: =N24+O24+Q24+R24+S24+V24+Y24+AB24 -> 51.8 | AE24: =IF(L24<0,L24*-1,0) -> 2.7580539 | AF24: =AD24+AE24 -> 54.558054 | AG24: 0 | AH24: 46 | AI24: 17 | AJ24: =AJ23+(V24*1.9835) -> 7348.5208 | AK24: 0
A25: =A24+1 -> 14 | B25: 6902.59 | C25: 293235 | D25: =C25-C24 -> -37 | E25: =C25-152000 -> 141235 | F25: =D25/$D$2 -> -18.653895 | G25: 32 | H25: 1.6 | I25: =G25+H25 -> 33.6 | J25: =IF(L25>0,L25,0) -> 0 | K25: =I25+J25 -> 33.6 | L25: =F25-(I25-AD25) -> -0.55389463 | M25: 4.7 | N25: 0 | O25: 0 | Q25: =1.4*1.02 -> 1.428 | R25: =2.58*1.04 -> 2.6832 | S25: 0 | T25: 25 | U25: 0 | V25: =M25-N25-O25-Q25-R25-S25+T25+U25 -> 25.5888 | Y25: 0 | AB25: 22 | AC25: =AC24-AB25 -> 3738 | AD25: =N25+O25+Q25+R25+S25+V25+Y25+AB25 -> 51.7 | AE25: =IF(L25<0,L25*-1,0) -> 0.55389463 | AF25: =AD25+AE25 -> 52.253895 | AG25: 0 | AH25: 54 | AI25: 25 | AJ25: =AJ24+(V25*1.9835) -> 7399.2762 | AK25: 0
A26: =A25+1 -> 15 | B26: 6902.59 | C26: 293235 | D26: =C26-C25 -> 0 | E26: =C26-152000 -> 141235 | F26: =D26/$D$2 -> 0 | G26: 38 | H26: 1.6 | I26: =G26+H26 -> 39.6 | J26: =IF(L26>0,L26,0) -> 12 | K26: =I26+J26 -> 51.6 | L26: =F26-(I26-AD26) -> 12 | M26: 4.6 | N26: 0 | O26: 0 | Q26: =1.4*1.02 -> 1.428 | R26: =2.22*1.04 -> 2.3088 | S26: 0 | T26: 25 | U26: 0 | V26: =M26-N26-O26-Q26-R26-S26+T26+U26 -> 25.8632 | Y26: 0 | AB26: 22 | AC26: =AC25-AB26 -> 3716 | AD26: =N26+O26+Q26+R26+S26+V26+Y26+AB26 -> 51.6 | AE26: =IF(L26<0,L26*-1,0) -> 0 | AF26: =AD26+AE26 -> 51.6 | AG26: 0.01 | AH26: 43 | AI26: 21 | AJ26: =AJ25+(V26*1.9835) -> 7450.5759 | AK26: 0
A27: =A26+1 -> 16 | B27: 6902.58 | C27: 293197 | D27: =C27-C26 -> -38 | E27: =C27-152000 -> 141197 | F27: =D27/$D$2 -> -19.158054 | G27: 36 | H27: 1.6 | I27: =G27+H27 -> 37.6 | J27: =IF(L27>0,L27,0) -> 0 | K27: =I27+J27 -> 37.6 | L27: =F27-(I27-AD27) -> -5.1580539 | M27: 4.6 | N27: 0 | O27: 0 | Q27: =1.4*1.02 -> 1.428 | R27: =2.16*1.04 -> 2.2464 | S27: 0 | T27: 25 | U27: 0 | V27: =M27-N27-O27-Q27-R27-S27+T27+U27 -> 25.9256 | Y27: 0 | AB27: 22 | AC27: =AC26-AB27 -> 3694 | AD27: =N27+O27+Q27+R27+S27+V27+Y27+AB27 -> 51.6 | AE27: =IF(L27<0,L27*-1,0) -> 5.1580539 | AF27: =AD27+AE27 -> 56.758054 | AG27: 0 | AH27: 32 | AI27: 16 | AJ27: =AJ26+(V27*1.9835) -> 7501.9993 | AK27: 0
A28: =A27+1 -> 17 | B28: 6902.57 | C28: 293159 | D28: =C28-C27 -> -38 | E28: =C28-152000 -> 141159 | F28: =D28/$D$2 -> -19.158054 | G28: 32 | H28: 1.7 | I28: =G28+H28 -> 33.7 | J28: =IF(L28>0,L28,0) -> 0 | K28: =I28+J28 -> 33.7 | L28: =F28-(I28-AD28) -> -1.2580539 | M28: 4.6 | N28: 0 | O28: 0 | Q28: =1.4*1.02 -> 1.428 | R28: =2.54*1.04 -> 2.6416 | S28: 0 | T28: 25 | U28: 0 | V28: =M28-N28-O28-Q28-R28-S28+T28+U28 -> 25.5304 | Y28: 0 | AB28: 22 | AC28: =AC27-AB28 -> 3672 | AD28: =N28+O28+Q28+R28+S28+V28+Y28+AB28 -> 51.6 | AE28: =IF(L28<0,L28*-1,0) -> 1.2580539 | AF28: =AD28+AE28 -> 52.858054 | AG28: 0 | AH28: 43 | AI28: 14 | AJ28: =AJ27+(V28*1.9835) -> 7552.6389 | AK28: 0
A29: =A28+1 -> 18 | B29: 6902.57 | C29: 293159 | D29: =C29-C28 -> 0 | E29: =C29-152000 -> 141159 | F29: =D29/$D$2 -> 0 | G29: 32 | H29: 1.7 | I29: =G29+H29 -> 33.7 | J29: =IF(L29>0,L29,0) -> 17.9 | K29: =I29+J29 -> 51.6 | L29: =F29-(I29-AD29) -> 17.9 | M29: 4.6 | N29: 0 | O29: 0 | Q29: =1.4*1.02 -> 1.428 | R29: =2.41*1.04 -> 2.5064 | S29: 0 | T29: 25 | U29: 0 | V29: =M29-N29-O29-Q29-R29-S29+T29+U29 -> 25.6656 | Y29: 0 | AB29: 22 | AC29: =AC28-AB29 -> 3650 | AD29: =N29+O29+Q29+R29+S29+V29+Y29+AB29 -> 51.6 | AE29: =IF(L29<0,L29*-1,0) -> 0 | AF29: =AD29+AE29 -> 51.6 | AG29: 0 | AH29: 46 | AI29: 22 | AJ29: =AJ28+(V29*1.9835) -> 7603.5466 | AK29: 0
