Workbook

Sheet NOV
K1: MCPHEE RESERVOIR INFLOW/OUTFLOW TABULATION
A2: AF/cfs CONVERT FACTOR | D2: 1.9835 | L2: NOVEMBER "2013"
D4: RESERVOIR | I4: INFLOW | X4: OUTFLOW | AP4: ADJUSTMENTS | AW4: WEATHER
A5: DATE | B5: RESERV | C5: RESERV | D5: AC FT | E5: ACTIVE | F5: CONV TO | G5: DOLORES | H5: LOST | I5: RECORD | J5: CALC | K5: TOTAL | L5: CALC | M5: DOLORES TUNNEL | V5: LONE | W5: U | X5: TOTAL | Y5: TOTAL | Z5: MVI | AA5: MVI | AB5: MVI | AC5: TO EX & | AD5: MVI | AE5: DV CR | AF5: D/S SENIOR | AH5: BELOW | AI5: FISH | AJ5: SPILL | AK5: RECORD | AL5: CALC | AM5: TOTAL | AN5: NAR | AO5: MVI | AP5: MVI | AQ5: MVI | AR5: DIST. | AS5: U/S | AT5: TOTTEN | AU5: UTES | AV5: RAIN | AW5: MAX | AX5: MIN | AZ5: TOTAL | BA5: GRNDHOG | BB5: GRNDHOG
A6: NOV | B6: ELEV | D6: CHANGE | E6: CAP | F6: CFS | G6: RIVER | H6: CAN | I6: INFLOW | J6: INFLOW | K6: INFLOW | L6: INF/OTF | M6: TOT DIV | N6: WET | O6: UTE | P6: QUEST | Q6: MWC | R6: CORTEZ | T6: UTE | U6: F-BAY | V6: PINE | W6: LAT | X6: MVI | Y6: MVI | Z6: CALL | AA6: CALL | AB6: APR- | AC6: U/S EX | AD6: PROJ | AE6: CANAL | AF6: MVIC | AG6: PROJ | AH6: MCP | AI6: LEFT | AK6: OTF | AL6: OTF | AM6: OTF | AN6: FILL | AO6: STOCK | AP6: STORED | AQ6: STORED | AR6: CLASS | AS6: USERS | AT6: (FRESH | AU6: FROM | AW6: TMP | AX6: TMP | AZ6: TUNNEL | BA6: DISCHARGE | BB6: CAPACITY
N7: LAND | O7: F&R | Q7: NON - | R7: NON - | S7: PROJ | T7: PROJ | U7: BAL | X7: WATER | Y7: IRRIG. | Z7: STOR | AA7: SPILLED | AB7: JUNE | AF7: 1.7 | AG7: 1.3 | AI7: 12682.175 | AP7: Apr - Jun | AQ7: EVAP | AR7: "B" | AS7: EXCH | AT7: WATER) | AU7: DWCD | AZ7: Misc.
Q8: PROJ | R8: PROJ | X8: USED | Y8: WATER | AA8: OR | AB8: (DIV+
R9: 4.2 | Y9: USED | AA9: USED | AB9: CALL) | BB9: FP = 5394
C10: AC. Ft. | E10: AC FT | G10: CFS | H10: CFS | I10: CFS | J10: CFS | K10: CFS | L10: CFS | M10: CFS | N10: CFS | O10: CFS | P10: CFS | Q10: CFS | R10: CFS | S10: CFS | T10: CFS | U10: CFS | V10: CFS | W10: CFS | X10: 153400 | Y10: 150400 | AB10: 72000 | AC10: CFS | AD10: CFS | AE10: CFS | AF10: CFS | AG10: CFS | AH10: CFS | AI10: CFS | AJ10: CFS | AK10: CFS | AL10: CFS | AM10: CFS | AN10: CFS | AO10: CFS | AP10: CFS | AQ10: AC.FT. | AR10: CFS | AS10: CFS | AT10: CFS | AU10: CFS | AZ10: Outflow | BA10: CFS | BB10: AC FT
N11: 1.03 | O11: 1.05 | P11: 1.02 | Q11: 1.02 | R11: 1.04 | T11: 1.04 | X11: CFS | Y11: CFS | Z11: CFS | AA11: CFS | AB11: Ac. Ft. | AZ11: CFS
A12: SEASON BAL
A13: YTD | B13: 6864.5 | C13: 173722 | AI13: 2999.8368
A15: 1 | B15: 6864.59 | C15: 173943 | D15: =C15-C13 -> 221 | E15: =C15-152000 -> 21943 | F15: =D15/$D$2 -> 111.41921 | G15: 141 | H15: 0.43 | I15: =G15+H15 -> 141.43 | J15: =IF(L15>0,L15,0) -> 0 | K15: =I15+J15 -> 141.43 | L15: =F15-(I15-AK15) -> -11.010792 | M15: 1.7 | N15: 0 | O15: =8.38*1.05 -> 8.799 | P15: 0 | Q15: =949500/325851/1.9835*1.02 -> 1.4984556 | R15: =((1208448/646272)*1.04)-T15 -> 1.4749376 | S15: 0 | T15: =(0.4261*1.06)*1.04 -> 0.46973264 | U15: =M15-(Q15+R15+S15+T15) -> -1.7431258 | V15: 0 | W15: 0 | X15: =M15-N15-O15-P15-Q15-R15-S15-T15-U15+V15+W15-AU15+AR15 -> -8.799 | Y15: =X15-AO15 -> -8.799 | AC15: 100 | AE15: 0 | AH15: 17.3 | AI15: =AI13-AH15 -> 2982.5368 | AK15: =N15+O15+P15+Q15+R15+S15+T15+U15+X15+AE15+AH15 -> 19 | AL15: =IF(L15<0,L15*-1,0) -> 11.010792 | AM15: =AK15+AL15 -> 30.010792 | AN15: =V15 -> 0 | AV15: 0 | AW15: 53 | AX15: 28 | AZ15: =SUM(N15,P15:U15) -> 1.7 | BA15: 0 | BB15: 6444
A16: =A15+1 -> 2 | B16: 6864.69 | C16: 174188 | D16: =C16-C15 -> 245 | E16: =C16-152000 -> 22188 | F16: =D16/$D$2 -> 123.51903 | G16: 138 | H16: 0.256 | I16: =G16+H16 -> 138.256 | J16: =IF(L16>0,L16,0) -> 4.533032 | K16: =I16+J16 -> 142.78903 | L16: =F16-(I16-AK16) -> 4.533032 | M16: 1.37 | N16: 0 | O16: =1.42*1.05 -> 1.491 | P16: 0 | Q16: =1060700/325851/1.9835*1.02 -> 1.6739461 | R16: =((1140614/646272)*1.04)-T16 -> 1.3657771 | S16: 0 | T16: =(0.4261*1.06)*1.04 -> 0.46973264 | U16: =M16-(Q16+R16+S16+T16) -> -2.1394559 | V16: 0 | W16: 0 | X16: =M16-N16-O16-P16-Q16-R16-S16-T16-U16+V16+W16-AU16+AR16 -> -1.491 | Y16: =X16-AO16 -> -1.491 | AC16: 100 | AE16: 0 | AH16: 17.9 | AI16: =AI15-AH16 -> 2964.6368 | AK16: =N16+O16+P16+Q16+R16+S16+T16+U16+X16+AE16+AH16 -> 19.27 | AL16: =IF(L16<0,L16*-1,0) -> 0 | AM16: =AK16+AL16 -> 19.27 | AV16: 0 | AW16: 62 | AX16: 28 | AZ16: =SUM(N16,P16:U16) -> 1.37 | BA16: 0 | BB16: 6450
A17: =A16+1 -> 3 | B17: 6864.78 | C17: 174410 | D17: =C17-C16 -> 222 | E17: =C17-152000 -> 22410 | F17: =D17/$D$2 -> 111.92337 | G17: 142 | H17: 0.219 | I17: =G17+H17 -> 142.219 | J17: =IF(L17>0,L17,0) -> 0 | K17: =I17+J17 -> 142.219 | L17: =F17-(I17-AK17) -> -10.135632 | M17: 1.66 | N17: 0 | O17: =0*1.05 -> 0 | P17: 0 | Q17: =1149000/325851/1.9835*1.02 -> 1.813297 | R17: =((1204506/646272)*1.04)-T17 -> 1.468594 | S17: 0 | T17: =(0.4261*1.06)*1.04 -> 0.46973264 | U17: =M17-(Q17+R17+S17+T17) -> -2.0916236 | V17: 0 | W17: 0 | X17: =M17-N17-O17-P17-Q17-R17-S17-T17-U17+V17+W17-AU17+AR17 -> 0 | Y17: =X17-AO17 -> 0 | AC17: 100 | AE17: 0 | AH17: 18.5 | AI17: =AI16-AH17 -> 2946.1368 | AK17: =N17+O17+P17+Q17+R17+S17+T17+U17+X17+AE17+AH17 -> 20.16 | AL17: =IF(L17<0,L17*-1,0) -> 10.135632 | AM17: =AK17+AL17 -> 30.295632 | AV17: 0 | AW17: 61 | AX17: 34 | AZ17: =SUM(N17,P17:U17) -> 1.66 | BA17: 0 | BB17: 6463
A18: =A17+1 -> 4 | B18: 6864.87 | C18: 174631 | D18: =C18-C17 -> 221 | E18: =C18-152000 -> 22631 | F18: =D18/$D$2 -> 111.41921 | G18: 135 | H18: 0.187 | I18: =G18+H18 -> 135.187 | J18: =IF(L18>0,L18,0) -> 0 | K18: =I18+J18 -> 135.187 | L18: =F18-(I18-AK18) -> -3.5777915 | M18: 1.69 | N18: 0 | O18: =0*1.05 -> 0 | P18: 0 | Q18: =957900/325851/1.9835*1.02 -> 1.5117121 | R18: =((1047304/646272)*1.04)-T18 -> 1.2156199 | S18: 0 | T18: =(0.4261*1.06)*1.04 -> 0.46973264 | U18: =M18-(Q18+R18+S18+T18) -> -1.5070646 | V18: 0 | W18: 0 | X18: =M18-N18-O18-P18-Q18-R18-S18-T18-U18+V18+W18-AU18+AR18 -> 0 | Y18: =X18-AO18 -> 0 | AC18: 100 | AE18: 0 | AH18: 18.5 | AI18: =AI17-AH18 -> 2927.6368 | AK18: =N18+O18+P18+Q18+R18+S18+T18+U18+X18+AE18+AH18 -> 20.19 | AL18: =IF(L18<0,L18*-1,0) -> 3.5777915 | AM18: =AK18+AL18 -> 23.767792 | AV18: 0 | AW18: 53 | AX18: 28 | AZ18: =SUM(N18,P18:U18) -> 1.69 | BA18: 0 | BB18: 6474
A19: =A18+1 -> 5 | B19: 6864.97 | C19: 174876 | D19: =C19-C18 -> 245 | E19: =C19-152000 -> 22876 | F19: =D19/$D$2 -> 123.51903 | G19: 137 | H19: 0.149 | I19: =G19+H19 -> 137.149 | J19: =IF(L19>0,L19,0) -> 6.350032 | K19: =I19+J19 -> 143.49903 | L19: =F19-(I19-AK19) -> 6.350032 | M19: 1.88 | N19: 0 | O19: =0*1.05 -> 0 | P19: 0 | Q19: =932600/325851/1.9835*1.02 -> 1.4717848 | R19: =((1130240/646272)*1.04)-T19 -> 1.349083 | S19: 0 | T19: =(0.4261*1.06)*1.04 -> 0.46973264 | U19: =M19-(Q19+R19+S19+T19) -> -1.4106004 | V19: 0 | W19: 0 | X19: =M19-N19-O19-P19-Q19-R19-S19-T19-U19+V19+W19-AU19+AR19 -> 0 | Y19: =X19-AO19 -> 0 | AC19: 100 | AE19: 0 | AH19: 18.1 | AI19: =AI18-AH19 -> 2909.5368 | AK19: =N19+O19+P19+Q19+R19+S19+T19+U19+X19+AE19+AH19 -> 19.98 | AL19: =IF(L19<0,L19*-1,0) -> 0 | AM19: =AK19+AL19 -> 19.98 | AV19: 0 | AW19: 42 | AX19: 19 | AZ19: =SUM(N19,P19:U19) -> 1.88 | BA19: 0 | BB19: 6490
A20: =A19+1 -> 6 | B20: 6865 | C20: 174950 | D20: =C20-C19 -> 74 | E20: =C20-152000 -> 22950 | F20: =D20/$D$2 -> 37.307789 | G20: 104 | H20: 0.105 | I20: =G20+H20 -> 104.105 | J20: =IF(L20>0,L20,0) -> 0 | K20: =I20+J20 -> 104.105 | L20: =F20-(I20-AK20) -> -46.697211 | M20: 2.2 | N20: 0 | O20: =0*1.05 -> 0 | P20: 0 | Q20: =1249900/325851/1.9835*1.02 -> 1.9725325 | R20: =((1243288/646272)*1.04)-T20 -> 1.5310031 | S20: 0 | T20: =(0.4261*1.06)*1.04 -> 0.46973264 | U20: =M20-(Q20+R20+S20+T20) -> -1.7732683 | V20: 0 | W20: 0 | X20: =M20-N20-O20-P20-Q20-R20-S20-T20-U20+V20+W20-AU20+AR20 -> 0 | Y20: =X20-AO20 -> 0 | AC20: 100 | AE20: 0 | AH20: 17.9 | AI20: =AI19-AH20 -> 2891.6368 | AK20: =N20+O20+P20+Q20+R20+S20+T20+U20+X20+AE20+AH20 -> 20.1 | AL20: =IF(L20<0,L20*-1,0) -> 46.697211 | AM20: =AK20+AL20 -> 66.797211 | AV20: 0 | AW20: 52 | AX20: 17 | AZ20: =SUM(N20,P20:U20) -> 2.2 | BA20: 0 | BB20: 6493
A21: =A20+1 -> 7 | B21: 6865.08 | C21: 175150 | D21: =C21-C20 -> 200 | E21: =C21-152000 -> 23150 | F21: =D21/$D$2 -> 100.83186 | G21: 110 | H21: 0.09 | I21: =G21+H21 -> 110.09 | J21: =IF(L21>0,L21,0) -> 11.861863 | K21: =I21+J21 -> 121.95186 | L21: =F21-(I21-AK21) -> 11.861863 | M21: 3.22 | N21: 0 | O21: =0.214*1.05 -> 0.2247 | P21: 0 | Q21: =968200/325851/1.9835*1.02 -> 1.527967 | R21: =((1139168/646272)*1.04)-T21 -> 1.3634502 | S21: 0 | T21: =(0.4261*1.06)*1.04 -> 0.46973264 | U21: =M21-(Q21+R21+S21+T21) -> -0.14114985 | V21: 0 | W21: 0 | X21: =M21-N21-O21-P21-Q21-R21-S21-T21-U21+V21+W21-AU21+AR21 -> -0.2247 | Y21: =X21-AO21 -> -0.2247 | AC21: 100 | AE21: 0 | AH21: 17.9 | AI21: =AI20-AH21 -> 2873.7368 | AK21: =N21+O21+P21+Q21+R21+S21+T21+U21+X21+AE21+AH21 -> 21.12 | AL21: =IF(L21<0,L21*-1,0) -> 0 | AM21: =AK21+AL21 -> 21.12 | AV21: 0 | AW21: 59 | AX21: 25 | AZ21: =SUM(N21,P21:U21) -> 3.22 | BA21: 0 | BB21: 6484
A22: =A21+1 -> 8 | B22: 6865.15 | C22: 175324 | D22: =C22-C21 -> 174 | E22: =C22-152000 -> 23324 | F22: =D22/$D$2 -> 87.723721 | G22: 125 | H22: 0.09 | I22: =G22+H22 -> 125.09 | J22: =IF(L22>0,L22,0) -> 0 | K22: =I22+J22 -> 125.09 | L22: =F22-(I22-AK22) -> -16.246279 | M22: 3.22 | N22: 0 | O22: =0*1.05 -> 0 | P22: 0 | Q22: =951200/325851/1.9835*1.02 -> 1.5011385 | R22: =((1028896/646272)*1.04)-T22 -> 1.2186282 | S22: 0 | T22: =(0.3965*1.06)*1.04 -> 0.4371016 | U22: =M22-(Q22+R22+S22+T22) -> 0.063131698 | V22: 0 | W22: 0 | X22: =M22-N22-O22-P22-Q22-R22-S22-T22-U22+V22+W22-AU22+AR22 -> 0 | Y22: =X22-AO22 -> 0 | AC22: 100 | AE22: 0 | AH22: 17.9 | AI22: =AI21-AH22 -> 2855.8368 | AK22: =N22+O22+P22+Q22+R22+S22+T22+U22+X22+AE22+AH22 -> 21.12 | AL22: =IF(L22<0,L22*-1,0) -> 16.246279 | AM22: =AK22+AL22 -> 37.366279 | AV22: 0 | AW22: 61 | AX22: 27 | AZ22: =SUM(N22,P22:U22) -> 3.22 | BA22: 0 | BB22: 6473
A23: =A22+1 -> 9 | B23: 6865.22 | C23: 175499 | D23: =C23-C22 -> 175 | E23: =C23-152000 -> 23499 | F23: =D23/$D$2 -> 88.22788 | G23: 116 | H23: 0.09 | I23: =G23+H23 -> 116.09 | J23: =IF(L23>0,L23,0) -> 0 | K23: =I23+J23 -> 116.09 | L23: =F23-(I23-AK23) -> -6.74212 | M23: 3.22 | N23: 0 | O23: =0*1.05 -> 0 | P23: 0 | Q23: =1023300/325851/1.9835*1.02 -> 1.6149232 | R23: =((1131480/646272)*1.04)-T23 -> 1.3837095 | S23: 0 | T23: =(0.3965*1.06)*1.04 -> 0.4371016 | U23: =M23-(Q23+R23+S23+T23) -> -0.21573429 | V23: 0 | W23: 0 | X23: =M23-N23-O23-P23-Q23-R23-S23-T23-U23+V23+W23-AU23+AR23 -> 0 | Y23: =X23-AO23 -> 0 | AC23: 100 | AE23: 0 | AH23: 17.9 | AI23: =AI22-AH23 -> 2837.9368 | AK23: =N23+O23+P23+Q23+R23+S23+T23+U23+X23+AE23+AH23 -> 21.12 | AL23: =IF(L23<0,L23*-1,0) -> 6.74212 | AM23: =AK23+AL23 -> 27.86212 | AV23: 0 | AW23: 64 | AX23: 30 | AZ23: =SUM(N23,P23:U23) -> 3.22 | BA23: 0 | BB23: 6482
A24: =A23+1 -> 10 | B24: 6865.3 | C24: 175699 | D24: =C24-C23 -> 200 | E24: =C24-152000 -> 23699 | F24: =D24/$D$2 -> 100.83186 | G24: 112 | H24: 0.082 | I24: =G24+H24 -> 112.082 | J24: =IF(L24>0,L24,0) -> 9.8698629 | K24: =I24+J24 -> 121.95186 | L24: =F24-(I24-AK24) -> 9.8698629 | M24: 3.22 | N24: 0 | O24: =0*1.05 -> 0 | P24: 0 | Q24: =1280500/325851/1.9835*1.02 -> 2.020824 | R24: =((1133064/646272)*1.04)-T24 -> 1.3862585 | S24: 0 | T24: =(0.3965*1.06)*1.04 -> 0.4371016 | U24: =M24-(Q24+R24+S24+T24) -> -0.62418407 | V24: 0 | W24: 0 | X24: =M24-N24-O24-P24-Q24-R24-S24-T24-U24+V24+W24-AU24+AR24 -> 0 | Y24: =X24-AO24 -> 0 | AC24: 100 | AE24: 0 | AH24: 17.9 | AI24: =AI23-AH24 -> 2820.0368 | AK24: =N24+O24+P24+Q24+R24+S24+T24+U24+X24+AE24+AH24 -> 21.12 | AL24: =IF(L24<0,L24*-1,0) -> 0 | AM24: =AK24+AL24 -> 21.12 | AV24: 0 | AW24: 65 | AX24: 31 | AZ24: =SUM(N24,P24:U24) -> 3.22 | BA24: 0 | BB24: 6517
A25: =A24+1 -> 11 | B25: 6865.35 | C25: 175823 | D25: =C25-C24 -> 124 | E25: =C25-152000 -> 23823 | F25: =D25/$D$2 -> 62.515755 | G25: 109 | H25: 0.08 | I25: =G25+H25 -> 109.08 | J25: =IF(L25>0,L25,0) -> 0 | K25: =I25+J25 -> 109.08 | L25: =F25-(I25-AK25) -> -25.444245 | M25: 3.22 | N25: 0 | O25: =3.19*1.05 -> 3.3495 | P25: 0 | Q25: =1005500/325851/1.9835*1.02 -> 1.5868321 | R25: =((1144736/646272)*1.04)-T25 -> 1.4050414 | S25: 0 | T25: =(0.3965*1.06)*1.04 -> 0.4371016 | U25: =M25-(Q25+R25+S25+T25) -> -0.20897512 | V25: 0 | W25: 0 | X25: =M25-N25-O25-P25-Q25-R25-S25-T25-U25+V25+W25-AU25+AR25 -> -3.3495 | Y25: =X25-AO25 -> -3.3495 | AC25: 100 | AE25: 0 | AH25: 17.9 | AI25: =AI24-AH25 -> 2802.1368 | AK25: =N25+O25+P25+Q25+R25+S25+T25+U25+X25+AE25+AH25 -> 21.12 | AL25: =IF(L25<0,L25*-1,0) -> 25.444245 | AM25: =AK25+AL25 -> 46.564245 | AV25: 0 | AW25: 66 | AX25: 30 | AZ25: =SUM(N25,P25:U25) -> 3.22 | BA25: 0 | BB25: 6524
A26: =A25+1 -> 12 | B26: 6865.43 | C26: 176023 | D26: =C26-C25 -> 200 | E26: =C26-152000 -> 24023 | F26: =D26/$D$2 -> 100.83186 | G26: 107 | H26: 0.071 | I26: =G26+H26 -> 107.071 | J26: =IF(L26>0,L26,0) -> 14.260863 | K26: =I26+J26 -> 121.33186 | L26: =F26-(I26-AK26) -> 14.260863 | M26: 2.6 | N26: 0 | O26: =1.12*1.05 -> 1.176 | P26: 0 | Q26: =1077600/325851/1.9835*1.02 -> 1.7006169 | R26: =((1123496/646272)*1.04)-T26 -> 1.3708614 | S26: 0 | T26: =(0.3965*1.06)*1.04 -> 0.4371016 | U26: =M26-(Q26+R26+S26+T26) -> -0.90857987 | V26: 0 | W26: 0 | X26: =M26-N26-O26-P26-Q26-R26-S26-T26-U26+V26+W26-AU26+AR26 -> -1.176 | Y26: =X26-AO26 -> -1.176 | AC26: 100 | AE26: 0 | AH26: 17.9 | AI26: =AI25-AH26 -> 2784.2368 | AK26: =N26+O26+P26+Q26+R26+S26+T26+U26+X26+AE26+AH26 -> 20.5 | AL26: =IF(L26<0,L26*-1,0) -> 0 | AM26: =AK26+AL26 -> 20.5 | AV26: 0 | AW26: 67 | AX26: 32 | AZ26: =SUM(N26,P26:U26) -> 2.6 | BA26: 0 | BB26: 6534
A27: =A26+1 -> 13 | B27: 6865.48 | C27: 176148 | D27: =C27-C26 -> 125 | E27: =C27-152000 -> 24148 | F27: =D27/$D$2 -> 63.019914 | G27: 105 | H27: 0.07 | I27: =G27+H27 -> 105.07 | J27: =IF(L27>0,L27,0) -> 0 | K27: =I27+J27 -> 105.07 | L27: =F27-(I27-AK27) -> -20.680086 | M27: 3.47 | N27: 0 | O27: =0*1.05 -> 0 | P27: 0 | Q27: =1039000/325851/1.9835*1.02 -> 1.6397002 | R27: =((1128440/646272)*1.04)-T27 -> 1.3788174 | S27: 0 | T27: =(0.3965*1.06)*1.04 -> 0.4371016 | U27: =M27-(Q27+R27+S27+T27) -> 0.014380781 | V27: 0 | W27: 0 | X27: =M27-N27-O27-P27-Q27-R27-S27-T27-U27+V27+W27-AU27+AR27 -> 0 | Y27: =X27-AO27 -> 0 | AC27: 100 | AE27: 0 | AH27: 17.9 | AI27: =AI26-AH27 -> 2766.3368 | AK27: =N27+O27+P27+Q27+R27+S27+T27+U27+X27+AE27+AH27 -> 21.37 | AL27: =IF(L27<0,L27*-1,0) -> 20.680086 | AM27: =AK27+AL27 -> 42.050086 | AV27: 0 | AW27: 60 | AX27: 29 | AZ27: =SUM(N27,P27:U27) -> 3.47 | BA27: 0 | BB27: 6535
A28: =A27+1 -> 14 | B28: 6865.55 | C28: 176322 | D28: =C28-C27 -> 174 | E28: =C28-152000 -> 24322 | F28: =D28/$D$2 -> 87.723721 | G28: 106 | H28: 0.077 | I28: =G28+H28 -> 106.077 | J28: =IF(L28>0,L28,0) -> 2.8467207 | K28: =I28+J28 -> 108.92372 | L28: =F28-(I28-AK28) -> 2.8467207 | M28: 3.3 | N28: 0 | O28: =0*1.05 -> 0 | P28: 0 | Q28: =988500/325851/1.9835*1.02 -> 1.5600035 | R28: =((1132088/646272)*1.04)-T28 -> 1.3846879 | S28: 0 | T28: =(0.3965*1.06)*1.04 -> 0.4371016 | U28: =M28-(Q28+R28+S28+T28) -> -0.081792998 | V28: 0 | W28: 0 | X28: =M28-N28-O28-P28-Q28-R28-S28-T28-U28+V28+W28-AU28+AR28 -> 0 | Y28: =X28-AO28 -> 0 | AC28: 100 | AE28: 0 | AH28: 17.9 | AI28: =AI27-AH28 -> 2748.4368 | AK28: =N28+O28+P28+Q28+R28+S28+T28+U28+X28+AE28+AH28 -> 21.2 | AL28: =IF(L28<0,L28*-1,0) -> 0 | AM28: =AK28+AL28 -> 21.2 | AV28: 0 | AW28: 59 | AX28: 30 | AZ28: =SUM(N28,P28:U28) -> 3.3 | BA28: 0 | BB28: 6521
A29: =A28+1 -> 15 | B29: 6865.65 | C29: 176572 | D29: =C29-C28 -> 250 | E29: =C29-152000 -> 24572 | F29: =D29/$D$2 -> 126.03983 | G29: 101 | H29: 0.094 | I29: =G29+H29 -> 101.094 | J29: =IF(L29>0,L29,0) -> 45.545829 | K29: =I29+J29 -> 146.63983 | L29: =F29-(I29-AK29) -> 45.545829 | M29: 2.6 | N29: 0 | O29: =0*1.05 -> 0 | P29: 0 | Q29: =874300/325851/1.9835*1.02 -> 1.3797785 | R29: =((1172248/646272)*1.04)-T29 -> 1.3800838 | S29: 0 | T29: =(0.4593*1.06)*1.04 -> 0.50633232 | U29: =M29-(Q29+R29+S29+T29) -> -0.66619467 | V29: 0 | W29: 0 | X29: =M29-N29-O29-P29-Q29-R29-S29-T29-U29+V29+W29-AU29+AR29 -> 0 | Y29: =X29-AO29 -> 0 | AC29: 100 | AE29: 0 | AH29: 18 | AI29: =AI28-AH29 -> 2730.4368 | AK29: =N29+O29+P29+Q29+R29+S29+T29+U29+X29+AE29+AH29 -> 20.6 | AL29: =IF(L29<0,L29*-1,0) -> 0 | AM29: =AK29+AL29 -> 20.6 | AV29: 0.28 | AW29: 56 | AX29: 30 | AZ29: =SUM(N29,P29:U29) -> 2.6 | BA29: 0 | BB29: 6532
A30: =A29+1 -> 16 | B30: 6865.74 | C30: 176797 | D30: =C30-C29 -> 225 | E30: =C30-152000 -> 24797 | F30: =D30/$D$2 -> 113.43585 | G30: 116 | H30: 0.15 | I30: =G30+H30 -> 116.15 | J30: =IF(L30>0,L30,0) -> 18.625846 | K30: =I30+J30 -> 134.77585 | L30: =F30-(I30-AK30) -> 18.625846 | M30: 3.44 | N30: 0 | O30: =0*1.05 -> 0 | P30: 0 | Q30: =986000/325851/1.9835*1.02 -> 1.5560582 | R30: =((1139148/646272)*1.04)-T30 -> 1.3268183 | S30: 0 | T30: =(0.4593*1.06)*1.04 -> 0.50633232 | U30: =M30-(Q30+R30+S30+T30) -> 0.050791222 | V30: 0 | W30: 0 | X30: =M30-N30-O30-P30-Q30-R30-S30-T30-U30+V30+W30-AU30+AR30 -> 2.220446e-16 | Y30: =X30-AO30 -> 2.220446e-16 | AC30: 100 | AE30: 0 | AH30: 17.9 | AI30: =AI29-AH30 -> 2712.5368 | AK30: =N30+O30+P30+Q30+R30+S30+T30+U30+X30+AE30+AH30 -> 21.34 | AL30: =IF(L30<0,L30*-1,0) -> 0 | AM30: =AK30+AL30 -> 21.34 | AV30: 0.02 | AW30: 47 | AX30: 32 | AZ30: =SUM(N30,P30:U30) -> 3.44 | BA30: 0 | BB30: 6550
A31: =A30+1 -> 17 | B31: 6865.79 | C31: 176921 | D31: =C31-C30 -> 124 | E31: =C31-152000 -> 24921 | F31: =D31/$D$2 -> 62.515755 | G31: 113 | H31: 0.183 | I31: =G31+H31 -> 113.183 | J31: =IF(L31>0,L31,0) -> 0 | K31: =I31+J31 -> 113.183 | L31: =F31-(I31-AK31) -> -29.777245 | M31: 2.99 | N31: 0 | O31: =0*1.05 -> 0 | P31: 0 | Q31: =1182500/325851/1.9835*1.02 -> 1.8661651 | R31: =((1137364/646272)*1.04)-T31 -> 1.3239474 | S31: 0 | T31: =(0.4593*1.06)*1.04 -> 0.50633232 | U31: =M31-(Q31+R31+S31+T31) -> -0.70644484 | V31: 0 | W31: 0 | X31: =M31-N31-O31-P31-Q31-R31-S31-T31-U31+V31+W31-AU31+AR31 -> 0 | Y31: =X31-AO31 -> 0 | AC31: 100 | AE31: 0 | AH31: 17.9 | AI31: =AI30-AH31 -> 2694.6368 | AK31: =N31+O31+P31+Q31+R31+S31+T31+U31+X31+AE31+AH31 -> 20.89 | AL31: =IF(L31<0,L31*-1,0) -> 29.777245 | AM31: =AK31+AL31 -> 50.667245 | AV31: 0 | AW31: 52 | AX31: 29 | AZ31: =SUM(N31,P31:U31) -> 2.99 | BA31: 0 | BB31: 6558
A32: =A31+1 -> 18 | B32: 6865.84 | C32: 177046 | D32: =C32-C31 -> 125 | E32: =C32-152000 -> 25046 | F32: =D32/$D$2 -> 63.019914 | G32: 95 | H32: 0.165 | I32: =G32+H32 -> 95.165 | J32: =IF(L32>0,L32,0) -> 0 | K32: =I32+J32 -> 95.165 | L32: =F32-(I32-AK32) -> -11.125086 | M32: 3.12 | N32: 0 | O32: =0*1.05 -> 0 | P32: 0 | Q32: =915900/325851/1.9835*1.02 -> 1.4454297 | R32: =((1107952/646272)*1.04)-T32 -> 1.2766168 | S32: 0 | T32: =(0.4593*1.06)*1.04 -> 0.50633232 | U32: =M32-(Q32+R32+S32+T32) -> -0.10837878 | V32: 0 | W32: 0 | X32: =M32-N32-O32-P32-Q32-R32-S32-T32-U32+V32+W32-AU32+AR32 -> 4.4408921e-16 | Y32: =X32-AO32 -> 4.4408921e-16 | AC32: 14.14 | AE32: 0 | AH32: 17.9 | AI32: =AI31-AH32 -> 2676.7368 | AK32: =N32+O32+P32+Q32+R32+S32+T32+U32+X32+AE32+AH32 -> 21.02 | AL32: =IF(L32<0,L32*-1,0) -> 11.125086 | AM32: =AK32+AL32 -> 32.145086 | AV32: 0 | AW32: 57 | AX32: 27 | AZ32: =SUM(N32,P32:U32) -> 3.12 | BA32: 0 | BB32: 6556
A33: =A32+1 -> 19 | B33: 6865.91 | C33: 177221 | D33: =C33-C32 -> 175 | E33: =C33-152000 -> 25221 | F33: =D33/$D$2 -> 88.22788 | G33: 94 | H33: 0.14 | I33: =G33+H33 -> 94.14 | J33: =IF(L33>0,L33,0) -> 15.53788 | K33: =I33+J33 -> 109.67788 | L33: =F33-(I33-AK33) -> 15.53788 | M33: 3.55 | N33: 0 | O33: =0*1.05 -> 0 | P33: 0 | Q33: =984800/325851/1.9835*1.02 -> 1.5541644 | R33: =((1404584/646272)*1.04)-T33 -> 1.7539658 | S33: 0 | T33: =(0.4593*1.06)*1.04 -> 0.50633232 | U33: =M33-(Q33+R33+S33+T33) -> -0.26446245 | V33: 0 | W33: 0 | X33: =M33-N33-O33-P33-Q33-R33-S33-T33-U33+V33+W33-AU33+AR33 -> 0 | Y33: =X33-AO33 -> 0 | AE33: 0 | AH33: 17.9 | AI33: =AI32-AH33 -> 2658.8368 | AK33: =N33+O33+P33+Q33+R33+S33+T33+U33+X33+AE33+AH33 -> 21.45 | AL33: =IF(L33<0,L33*-1,0) -> 0 | AM33: =AK33+AL33 -> 21.45 | AV33: 0 | AW33: 56 | AX33: 31 | AZ33: =SUM(N33,P33:U33) -> 3.55 | BA33: 0 | BB33: 6559
A34: =A33+1 -> 20 | B34: 6865.99 | C34: 177420 | D34: =C34-C33 -> 199 | E34: =C34-152000 -> 25420 | F34: =D34/$D$2 -> 100.3277 | G34: 118 | H34: 0.139 | I34: =G34+H34 -> 118.139 | J34: =IF(L34>0,L34,0) -> 3.7387036 | K34: =I34+J34 -> 121.8777 | L34: =F34-(I34-AK34) -> 3.7387036 | M34: 3.55 | N34: 0 | O34: =0*1.05 -> 0 | P34: 0 | Q34: =953300/325851/1.9835*1.02 -> 1.5044526 | R34: =((1454640/646272)*1.04)-T34 -> 1.8345174 | S34: 0 | T34: =(0.4593*1.06)*1.04 -> 0.50633232 | U34: =M34-(Q34+R34+S34+T34) -> -0.29530225 | V34: 0 | W34: 0 | X34: =M34-N34-O34-P34-Q34-R34-S34-T34-U34+V34+W34-AU34+AR34 -> 0 | Y34: =X34-AO34 -> 0 | AE34: 0 | AH34: 18 | AI34: =AI33-AH34 -> 2640.8368 | AK34: =N34+O34+P34+Q34+R34+S34+T34+U34+X34+AE34+AH34 -> 21.55 | AL34: =IF(L34<0,L34*-1,0) -> 0 | AM34: =AK34+AL34 -> 21.55 | AV34: 0.14 | AW34: 56 | AX34: 29 | AZ34: =SUM(N34,P34:U34) -> 3.55 | BA34: 0 | BB34: 6571
A35: =A34+1 -> 21 | B35: 6866.12 | C35: 177749 | D35: =C35-C34 -> 329 | E35: =C35-152000 -> 25749 | F35: =D35/$D$2 -> 165.86841 | G35: 112 | H35: 0.194 | I35: =G35+H35 -> 112.194 | J35: =IF(L35>0,L35,0) -> 74.914414 | K35: =I35+J35 -> 187.10841 | L35: =F35-(I35-AK35) -> 74.914414 | M35: 3.04 | N35: 0 | O35: =0*1.05 -> 0 | P35: 0 | Q35: =839300/325851/1.9835*1.02 -> 1.3245432 | R35: =((1442328/646272)*1.04)-T35 -> 1.8147045 | S35: 0 | T35: =(0.4593*1.06)*1.04 -> 0.50633232 | U35: =M35-(Q35+R35+S35+T35) -> -0.60558005 | V35: 0 | W35: 0 | X35: =M35-N35-O35-P35-Q35-R35-S35-T35-U35+V35+W35-AU35+AR35 -> 0 | Y35: =X35-AO35 -> 0 | AE35: 0 | AH35: 18.2 | AI35: =AI34-AH35 -> 2622.6368 | AK35: =N35+O35+P35+Q35+R35+S35+T35+U35+X35+AE35+AH35 -> 21.24 | AL35: =IF(L35<0,L35*-1,0) -> 0 | AM35: =AK35+AL35 -> 21.24 | AV35: 0.38 | AW35: 51 | AX35: 32 | AZ35: =SUM(N35,P35:U35) -> 3.04 | BA35: 0 | BB35: 6585
A36: =A35+1 -> 22 | B36: 6866.26 | C36: 178104 | D36: =C36-C35 -> 355 | E36: =C36-152000 -> 26104 | F36: =D36/$D$2 -> 178.97656 | G36: 116 | H36: 0.48 | I36: =G36+H36 -> 116.48 | J36: =IF(L36>0,L36,0) -> 84.106557 | K36: =I36+J36 -> 200.58656 | L36: =F36-(I36-AK36) -> 84.106557 | M36: 3.11 | N36: 0 | O36: =0*1.05 -> 0 | P36: 0 | Q36: =829900/325851/1.9835*1.02 -> 1.3097086 | R36: =((1448008/646272)*1.04)-T36 -> 1.8701457 | S36: 0 | T36: =(0.4173*1.06)*1.04 -> 0.46003152 | U36: =M36-(Q36+R36+S36+T36) -> -0.52988585 | V36: 0 | W36: 0 | X36: =M36-N36-O36-P36-Q36-R36-S36-T36-U36+V36+W36-AU36+AR36 -> 0 | Y36: =X36-AO36 -> 0 | AE36: 0 | AH36: 18.5 | AI36: =AI35-AH36 -> 2604.1368 | AK36: =N36+O36+P36+Q36+R36+S36+T36+U36+X36+AE36+AH36 -> 21.61 | AL36: =IF(L36<0,L36*-1,0) -> 0 | AM36: =AK36+AL36 -> 21.61 | AV36: 0.53 | AW36: 45 | AX36: 33 | AZ36: =SUM(N36,P36:U36) -> 3.11 | BA36: 0 | BB36: 6607
A37: =A36+1 -> 23 | B37: 6866.37 | C37: 178383 | D37: =C37-C36 -> 279 | E37: =C37-152000 -> 26383 | F37: =D37/$D$2 -> 140.66045 | G37: 120 | H37: 0.912 | I37: =G37+H37 -> 120.912 | J37: =IF(L37>0,L37,0) -> 41.788449 | K37: =I37+J37 -> 162.70045 | L37: =F37-(I37-AK37) -> 41.788449 | M37: 3.54 | N37: 0 | O37: =0*1.05 -> 0 | P37: 0 | Q37: =936200/325851/1.9835*1.02 -> 1.4774662 | R37: =((1430416/646272)*1.04)-T37 -> 1.8418362 | S37: 0 | T37: =(0.4173*1.06)*1.04 -> 0.46003152 | U37: =M37-(Q37+R37+S37+T37) -> -0.23933387 | V37: 0 | W37: 0 | X37: =M37-N37-O37-P37-Q37-R37-S37-T37-U37+V37+W37-AU37+AR37 -> 0 | Y37: =X37-AO37 -> 0 | AE37: 0 | AH37: 18.5 | AI37: =AI36-AH37 -> 2585.6368 | AK37: =N37+O37+P37+Q37+R37+S37+T37+U37+X37+AE37+AH37 -> 22.04 | AL37: =IF(L37<0,L37*-1,0) -> 0 | AM37: =AK37+AL37 -> 22.04 | AV37: 0.21 | AW37: 46 | AX37: 30 | AZ37: =SUM(N37,P37:U37) -> 3.54 | BA37: 0 | BB37: 6618
A38: =A37+1 -> 24 | B38: 6866.46 | C38: 178611 | D38: =C38-C37 -> 228 | E38: =C38-152000 -> 26611 | F38: =D38/$D$2 -> 114.94832 | G38: 117 | H38: 0.899 | I38: =G38+H38 -> 117.899 | J38: =IF(L38>0,L38,0) -> 18.449324 | K38: =I38+J38 -> 136.34832 | L38: =F38-(I38-AK38) -> 18.449324 | M38: 2.9 | N38: 0 | O38: =0*1.05 -> 0 | P38: 0 | Q38: =972000/325851/1.9835*1.02 -> 1.533964 | R38: =((1411800/646272)*1.04)-T38 -> 1.8118788 | S38: 0 | T38: =(0.4173*1.06)*1.04 -> 0.46003152 | U38: =M38-(Q38+R38+S38+T38) -> -0.9058743 | V38: 0 | W38: 0 | X38: =M38-N38-O38-P38-Q38-R38-S38-T38-U38+V38+W38-AU38+AR38 -> 0 | Y38: =X38-AO38 -> 0 | AE38: 0 | AH38: 18.5 | AI38: =AI37-AH38 -> 2567.1368 | AK38: =N38+O38+P38+Q38+R38+S38+T38+U38+X38+AE38+AH38 -> 21.4 | AL38: =IF(L38<0,L38*-1,0) -> 0 | AM38: =AK38+AL38 -> 21.4 | AV38: 0.02 | AW38: 36 | AX38: 26 | AZ38: =SUM(N38,P38:U38) -> 2.9 | BA38: 0 | BB38: 6632
A39: =A38+1 -> 25 | B39: 6866.5 | C39: 178712 | D39: =C39-C38 -> 101 | E39: =C39-152000 -> 26712 | F39: =D39/$D$2 -> 50.920091 | G39: 107 | H39: 0.681 | I39: =G39+H39 -> 107.681 | J39: =IF(L39>0,L39,0) -> 0 | K39: =I39+J39 -> 107.681 | L39: =F39-(I39-AK39) -> -34.780909 | M39: 3.68 | N39: 0 | O39: =0*1.05 -> 0 | P39: 0 | Q39: =1084800/325851/1.9835*1.02 -> 1.7119796 | R39: =((1459016/646272)*1.04)-T39 -> 1.8878601 | S39: 0 | T39: =(0.4173*1.06)*1.04 -> 0.46003152 | U39: =M39-(Q39+R39+S39+T39) -> -0.37987126 | V39: 0 | W39: 0 | X39: =M39-N39-O39-P39-Q39-R39-S39-T39-U39+V39+W39-AU39+AR39 -> 0 | Y39: =X39-AO39 -> 0 | AE39: 0 | AH39: 18.3 | AI39: =AI38-AH39 -> 2548.8368 | AK39: =N39+O39+P39+Q39+R39+S39+T39+U39+X39+AE39+AH39 -> 21.98 | AL39: =IF(L39<0,L39*-1,0) -> 34.780909 | AM39: =AK39+AL39 -> 56.760909 | AV39: 0.07 | AW39: 48 | AX39: 22 | AZ39: =SUM(N39,P39:U39) -> 3.68 | BA39: 0 | BB39: 6651
A40: =A39+1 -> 26 | B40: 6866.54 | C40: 178813 | D40: =C40-C39 -> 101 | E40: =C40-152000 -> 26813 | F40: =D40/$D$2 -> 50.920091 | G40: 92 | H40: 0.448 | I40: =G40+H40 -> 92.448 | J40: =IF(L40>0,L40,0) -> 0 | K40: =I40+J40 -> 92.448 | L40: =F40-(I40-AK40) -> -19.757909 | M40: 3.67 | N40: 0 | O40: =0*1.05 -> 0 | P40: 0 | Q40: =936200/325851/1.9835*1.04 -> 1.5064361 | R40: =((1415072/646272)*1.04)-T40 -> 1.8171442 | S40: 0 | T40: =(0.4173*1.06)*1.04 -> 0.46003152 | U40: =M40-(Q40+R40+S40+T40) -> -0.11361177 | V40: 0 | W40: 0 | X40: =M40-N40-O40-P40-Q40-R40-S40-T40-U40+V40+W40-AU40+AR40 -> 4.4408921e-16 | Y40: =X40-AO40 -> 4.4408921e-16 | AE40: 0 | AH40: 18.1 | AI40: =AI39-AH40 -> 2530.7368 | AK40: =N40+O40+P40+Q40+R40+S40+T40+U40+X40+AE40+AH40 -> 21.77 | AL40: =IF(L40<0,L40*-1,0) -> 19.757909 | AM40: =AK40+AL40 -> 41.527909 | AV40: 0.01 | AW40: 45 | AX40: 22 | AZ40: =SUM(N40,P40:U40) -> 3.67 | BA40: 0 | BB40: 6659
A41: =A40+1 -> 27 | B41: 6866.62 | C41: 179016 | D41: =C41-C40 -> 203 | E41: =C41-152000 -> 27016 | F41: =D41/$D$2 -> 102.34434 | G41: 85 | H41: 0.359 | I41: =G41+H41 -> 85.359 | J41: =IF(L41>0,L41,0) -> 38.105341 | K41: =I41+J41 -> 123.46434 | L41: =F41-(I41-AK41) -> 38.105341 | M41: 3.12 | N41: 0 | O41: =0*1.05 -> 0 | P41: 0 | Q41: =923700/325851/1.9835*1.02 -> 1.4577393 | R41: =((1434584/646272)*1.04)-T41 -> 1.8485434 | S41: 0 | T41: =(0.4173*1.06)*1.04 -> 0.46003152 | U41: =M41-(Q41+R41+S41+T41) -> -0.64631423 | V41: 0 | W41: 0 | X41: =M41-N41-O41-P41-Q41-R41-S41-T41-U41+V41+W41-AU41+AR41 -> 0 | Y41: =X41-AO41 -> 0 | AE41: 0 | AH41: 18 | AI41: =AI40-AH41 -> 2512.7368 | AK41: =N41+O41+P41+Q41+R41+S41+T41+U41+X41+AE41+AH41 -> 21.12 | AL41: =IF(L41<0,L41*-1,0) -> 0 | AM41: =AK41+AL41 -> 21.12 | AV41: 0 | AW41: 48 | AX41: 24 | AZ41: =SUM(N41,P41:U41) -> 3.12 | BA41: 0 | BB41: 6671
A42: =A41+1 -> 28 | B42: 6866.64 | C42: 179067 | D42: =C42-C41 -> 51 | E42: =C42-152000 -> 27067 | F42: =D42/$D$2 -> 25.712125 | G42: 92 | H42: 0.268 | I42: =G42+H42 -> 92.268 | J42: =IF(L42>0,L42,0) -> 0 | K42: =I42+J42 -> 92.268 | L42: =F42-(I42-AK42) -> -44.955875 | M42: 3.6 | N42: 0 | O42: =0*1.05 -> 0 | P42: 0 | Q42: =946000/325851/1.9835*1.02 -> 1.4929321 | R42: =((1436776/646272)*1.04)-T42 -> 1.8520709 | S42: 0 | T42: =(0.4173*1.06)*1.04 -> 0.46003152 | U42: =M42-(Q42+R42+S42+T42) -> -0.20503446 | V42: 0 | W42: 0 | X42: =M42-N42-O42-P42-Q42-R42-S42-T42-U42+V42+W42-AU42+AR42 -> 0 | Y42: =X42-AO42 -> 0 | AE42: 0 | AH42: 18 | AI42: =AI41-AH42 -> 2494.7368 | AK42: =N42+O42+P42+Q42+R42+S42+T42+U42+X42+AE42+AH42 -> 21.6 | AL42: =IF(L42<0,L42*-1,0) -> 44.955875 | AM42: =AK42+AL42 -> 66.555875 | AV42: 0 | AW42: 51 | AX42: 24 | AZ42: =SUM(N42,P42:U42) -> 3.6 | BA42: 0 | BB42: 6680
...

Sheet DEC
K1: MCPHEE RESERVOIR INFLOW/OUTFLOW TABULATION
A2: AF/cfs CONVERT FACTOR | D2: 1.9835 | K2: DECEMBER "2013"
D4: RESERVOIR | I4: INFLOW | X4: OUTFLOW | AP4: ADJUSTMENTS | AW4: WEATHER
A5: DATE | B5: RESERV | C5: RESERV | D5: AC FT | E5: ACTIVE | F5: CONV TO | G5: DOLORES | H5: LOST | I5: RECORD | J5: CALC | K5: TOTAL | L5: CALC | M5: DOLORES TUNNEL | V5: LONE | W5: U | X5: TOTAL | Y5: TOTAL | Z5: MVI | AA5: MVI | AB5: MVI | AC5: TO EX & | AD5: MVI | AE5: DV CR | AF5: D/S SENIOR | AH5: BELOW | AI5: FISH | AJ5: SPILL | AK5: RECORD | AL5: CALC | AM5: TOTAL | AN5: NAR | AO5: MVI | AP5: MVI | AQ5: MVI | AR5: DIST. | AS5: U/S | AT5: TOTTEN | AU5: UTES | AV5: RAIN | AW5: MAX | AX5: MIN | AZ5: TOTAL | BA5: GRNDHOG | BB5: GRNDHOG
A6: DEC | B6: ELEV | D6: CHANGE | E6: CAP | F6: CFS | G6: RIVER | H6: CAN | I6: INFLOW | J6: INFLOW | K6: INFLOW | L6: INF/OTF | M6: TOT DIV | N6: WET | O6: UTE | P6: QUEST | Q6: MWC | R6: CORTEZ | T6: UTE | U6: F-BAY | V6: PINE | W6: LAT | X6: MVI | Y6: MVI | Z6: CALL | AA6: CALL | AB6: APR- | AC6: U/S EX | AD6: PROJ | AE6: CANAL | AF6: MVIC | AG6: PROJ | AH6: MCP | AI6: LEFT | AK6: OTF | AL6: OTF | AM6: OTF | AN6: FILLL | AO6: STOCK | AP6: STORED | AQ6: STORED | AR6: CLASS | AS6: USERS | AT6: (FRESH | AU6: FROM | AW6: TMP | AX6: TMP | AZ6: TUNNEL | BA6: DISCHARGE | BB6: CAPACITY
N7: LAND | O7: F&R | Q7: NON - | R7: NON - | S7: PROJ | T7: PROJ | U7: BAL | X7: WATER | Y7: IRRIG. | Z7: STOR | AA7: SPILLED | AB7: JUNE | AF7: 1.7 | AG7: 1.3 | AI7: 12682.175 | AP7: Apr - Jun | AQ7: EVAP | AR7: "B" | AS7: EXCH | AT7: WATER) | AU7: DWCD | AZ7: Misc.
Q8: PROJ | R8: PROJ | X8: USED | Y8: WATER | AA8: OR | AB8: (DIV+
R9: 4.2 | Y9: USED | AA9: USED | AB9: CALL) | BB9: FP = 5394
C10: AC. Ft. | E10: AC FT | G10: CFS | H10: CFS | I10: CFS | J10: CFS | K10: CFS | L10: CFS | M10: CFS | N10: CFS | O10: CFS | P10: CFS | Q10: CFS | R10: CFS | S10: CFS | T10: CFS | U10: CFS | V10: CFS | W10: CFS | X10: 153400 | Y10: 150400 | AB10: 72000 | AC10: CFS | AD10: CFS | AE10: CFS | AF10: CFS | AG10: CFS | AH10: CFS | AI10: CFS | AJ10: CFS | AK10: CFS | AL10: CFS | AM10: CFS | AN10: CFS | AO10: CFS | AP10: CFS | AQ10: AC.FT. | AR10: CFS | AS10: CFS | AT10: CFS | AU10: CFS | AZ10: Outflow | BA10: CFS | BB10: AC FT
N11: 1.03 | O11: 1.05 | P11: 1.02 | Q11: 1.02 | R11: 1.04 | T11: 1.04 | X11: CFS | Y11: CFS | Z11: CFS | AA11: CFS | AB11: Ac. Ft. | AZ11: CFS
A12: SEASON BAL
A13: YTD | B13: =NOV!B44 -> 6866.78 | C13: =NOV!C44 -> 179421 | D13: =NOV!D53 -> 5699 | E13: =NOV!E53 -> 27421 | F13: =NOV!F52 -> 2873.2039 | G13: =NOV!G52 -> 3357 | H13: =NOV!H52 -> 8.109 | I13: =NOV!I52 -> 3364.489 | J13: =NOV!J52 -> 419.37611 | K13: =NOV!K52 -> 3783.8651 | L13: =NOV!L52 -> 138.44493 | M13: =NOV!M52 -> 88.63 | ... Y13: =NOV!Y52 -> -15.0402 | AC13: =NOV!AC52 -> 1714.14 | AH13: =NOV!AH52 -> 541.1 | AI13: =NOV!AI52 -> 2458.7368 | AK13: =NOV!AK52 -> 629.73 | AL13: =NOV!AL52 -> 280.93118 | AM13: =NOV!AM52 -> 910.66118 | AN13: =NOV!AN52 -> 0 | AO13: =NOV!AO52 -> 0 | AV13: =NOV!AV52 -> 1.66 | AZ13: =NOV!AZ52 -> 88.63 | BA13: =NOV!BA52 -> 0
A15: 1 | B15: 6866.82 | C15: 179523 | D15: =C15-C13 -> 102 | E15: =C15-152000 -> 27523 | F15: =D15/$D$2 -> 51.42425 | G15: 90 | H15: 0.147 | I15: =G15+H15 -> 90.147 | J15: =IF(L15>0,L15,0) -> 0 | K15: =I15+J15 -> 90.147 | L15: =F15-(I15-AK15) -> -17.22275 | M15: 3.5 | N15: 0 | O15: =0*1.05 -> 0 | P15: 0 | Q15: =1072500/325851/1.9835*1.02 -> 1.6925683 | R15: =((1417512/646272)*1.04)-T15 -> 1.7003579 | S15: 0 | T15: =(0.5268*1.06)*1.04 -> 0.58074432 | U15: =M15-(Q15+R15+S15+T15) -> -0.47367053 | V15: 0 | W15: 0 | X15: =M15-N15-P15-O15-Q15-R15-S15-T15-U15+V15+W15 -> 0 | Y15: =X15-AO15 -> 0 | AE15: 0 | AH15: 18 | AI15: =AI13-AH15 -> 2440.7368 | AK15: =N15+O15+P15+Q15+R15+S15+T15+U15+X15+AE15+AH15 -> 21.5 | AL15: =IF(L15<0,L15*-1,0) -> 17.22275 | AM15: =AK15+AL15 -> 38.72275 | AV15: 0.01 | AW15: 35 | AX15: 18 | AZ15: =SUM(N15,P15:U15) -> 3.5 | BA15: 0 | BB15: 6689
A16: =A15+1 -> 2 | B16: 6866.84 | C16: 179573 | D16: =C16-C15 -> 50 | E16: =C16-152000 -> 27573 | F16: =D16/$D$2 -> 25.207966 | G16: 88 | H16: 0.148 | I16: =G16+H16 -> 88.148 | J16: =IF(L16>0,L16,0) -> 0 | K16: =I16+J16 -> 88.148 | L16: =F16-(I16-AK16) -> -41.580034 | M16: 3.46 | N16: 0 | O16: =0*1.05 -> 0 | P16: 0 | Q16: =1081700/325851/1.9835*1.02 -> 1.7070873 | R16: =((1419464/646272)*1.04)-T16 -> 1.7034991 | S16: 0 | T16: =(0.5268*1.06)*1.04 -> 0.58074432 | U16: =M16-(Q16+R16+S16+T16) -> -0.53133074 | V16: 0 | W16: 0 | X16: =M16-N16-P16-O16-Q16-R16-S16-T16-U16+V16+W16 -> 0 | Y16: =X16-AO16 -> 0 | AE16: 0 | AH16: 17.9 | AI16: =AI15-AH16 -> 2422.8368 | AK16: =N16+O16+P16+Q16+R16+S16+T16+U16+X16+AE16+AH16 -> 21.36 | AL16: =IF(L16<0,L16*-1,0) -> 41.580034 | AM16: =AK16+AL16 -> 62.940034 | AV16: 0 | AW16: 38 | AX16: 22 | AZ16: =SUM(N16,P16:U16) -> 3.46 | BA16: 0 | BB16: 6693
A17: =A16+1 -> 3 | B17: 6866.94 | C17: 179827 | D17: =C17-C16 -> 254 | E17: =C17-152000 -> 27827 | F17: =D17/$D$2 -> 128.05647 | G17: 85 | H17: 0.18 | I17: =G17+H17 -> 85.18 | J17: =IF(L17>0,L17,0) -> 64.186466 | K17: =I17+J17 -> 149.36647 | L17: =F17-(I17-AK17) -> 64.186466 | M17: 3.41 | N17: 0 | O17: =0*1.05 -> 0 | P17: 0 | Q17: =794100/325851/1.9835*1.02 -> 1.2532107 | R17: =((1408368/646272)*1.04)-T17 -> 1.6856431 | S17: 0 | T17: =(0.5268*1.06)*1.04 -> 0.58074432 | U17: =M17-(Q17+R17+S17+T17) -> -0.10959813 | V17: 0 | W17: 0 | X17: =M17-N17-P17-O17-Q17-R17-S17-T17-U17+V17+W17 -> 0 | Y17: =X17-AO17 -> 0 | AE17: 0 | AH17: 17.9 | AI17: =AI16-AH17 -> 2404.9368 | AK17: =N17+O17+P17+Q17+R17+S17+T17+U17+X17+AE17+AH17 -> 21.31 | AL17: =IF(L17<0,L17*-1,0) -> 0 | AM17: =AK17+AL17 -> 21.31 | AV17: 0.1 | AW17: 52 | AX17: 27 | AZ17: =SUM(N17,P17:U17) -> 3.41 | BA17: 0 | BB17: 6696
A18: =A17+1 -> 4 | B18: 6867.01 | C18: 180004 | D18: =C18-C17 -> 177 | E18: =C18-152000 -> 28004 | F18: =D18/$D$2 -> 89.236199 | G18: 75 | H18: 0.196 | I18: =G18+H18 -> 75.196 | J18: =IF(L18>0,L18,0) -> 35.350199 | K18: =I18+J18 -> 110.5462 | L18: =F18-(I18-AK18) -> 35.350199 | M18: 3.41 | N18: 0 | O18: =0*1.05 -> 0 | P18: 0 | Q18: =1062700/325851/1.9835*1.02 -> 1.6771024 | R18: =((1481824/646272)*1.04)-T18 -> 1.8038506 | S18: 0 | T18: =(0.5268*1.06)*1.04 -> 0.58074432 | U18: =M18-(Q18+R18+S18+T18) -> -0.6516974 | V18: 0 | W18: 0 | X18: =M18-N18-P18-O18-Q18-R18-S18-T18-U18+V18+W18 -> 0 | Y18: =X18-AO18 -> 0 | AE18: 0 | AH18: 17.9 | AI18: =AI17-AH18 -> 2387.0368 | AK18: =N18+O18+P18+Q18+R18+S18+T18+U18+X18+AE18+AH18 -> 21.31 | AL18: =IF(L18<0,L18*-1,0) -> 0 | AM18: =AK18+AL18 -> 21.31 | AV18: 0.1 | AW18: 46 | AX18: 3 | AZ18: =SUM(N18,P18:U18) -> 3.41 | BA18: 0 | BB18: 6719
A19: =A18+1 -> 5 | B19: 6867.02 | C19: 180030 | D19: =C19-C18 -> 26 | E19: =C19-152000 -> 28030 | F19: =D19/$D$2 -> 13.108142 | G19: 67 | H19: 0.414 | I19: =G19+H19 -> 67.414 | J19: =IF(L19>0,L19,0) -> 0 | K19: =I19+J19 -> 67.414 | L19: =F19-(I19-AK19) -> -32.985858 | M19: 3.42 | N19: 0 | O19: =0*1.05 -> 0 | P19: 0 | Q19: =1133900/325851/1.9835*1.02 -> 1.7894669 | R19: =((1430536/646272)*1.04)-T19 -> 1.8965981 | S19: 0 | T19: =(0.3678*1.06)*1.04 -> 0.40546272 | U19: =M19-(Q19+R19+S19+T19) -> -0.67152768 | V19: 0 | W19: 0 | X19: =M19-N19-P19-O19-Q19-R19-S19-T19-U19+V19+W19 -> 0 | Y19: =X19-AO19 -> 0 | AE19: 0 | AH19: 17.9 | AI19: =AI18-AH19 -> 2369.1368 | AK19: =N19+O19+P19+Q19+R19+S19+T19+U19+X19+AE19+AH19 -> 21.32 | AL19: =IF(L19<0,L19*-1,0) -> 32.985858 | AM19: =AK19+AL19 -> 54.305858 | AV19: 0 | AW19: 30 | AX19: 0 | AZ19: =SUM(N19,P19:U19) -> 3.42 | BA19: 0 | BB19: 6731
A20: =A19+1 -> 6 | B20: 6867.03 | C20: 180056 | D20: =C20-C19 -> 26 | E20: =C20-152000 -> 28056 | F20: =D20/$D$2 -> 13.108142 | G20: 64 | H20: 0 | I20: =G20+H20 -> 64 | J20: =IF(L20>0,L20,0) -> 0 | K20: =I20+J20 -> 64 | L20: =F20-(I20-AK20) -> -29.421858 | M20: 3.57 | N20: 0 | O20: =0*1.05 -> 0 | P20: 0 | Q20: =1022600/325851/1.9835*1.02 -> 1.6138185 | R20: =((1423752/646272)*1.04)-T20 -> 1.8856811 | S20: 0 | T20: =(0.3678*1.06)*1.04 -> 0.40546272 | U20: =M20-(Q20+R20+S20+T20) -> -0.33496232 | V20: 0 | W20: 0 | X20: =M20-N20-P20-O20-Q20-R20-S20-T20-U20+V20+W20 -> 0 | Y20: =X20-AO20 -> 0 | AE20: 0 | AH20: 17.9 | AI20: =AI19-AH20 -> 2351.2368 | AK20: =N20+O20+P20+Q20+R20+S20+T20+U20+X20+AE20+AH20 -> 21.47 | AL20: =IF(L20<0,L20*-1,0) -> 29.421858 | AM20: =AK20+AL20 -> 50.891858 | AV20: 0 | AW20: 30 | AX20: 1 | AZ20: =SUM(N20,P20:U20) -> 3.57 | BA20: 0 | BB20: 6740
A21: =A20+1 -> 7 | B21: 6867.08 | C21: 180184 | D21: =C21-C20 -> 128 | E21: =C21-152000 -> 28184 | F21: =D21/$D$2 -> 64.532392 | G21: 61 | H21: 0 | I21: =G21+H21 -> 61 | J21: =IF(L21>0,L21,0) -> 24.592392 | K21: =I21+J21 -> 85.592392 | L21: =F21-(I21-AK21) -> 24.592392 | M21: 3.16 | N21: 0 | O21: =0*1.05 -> 0 | P21: 0 | Q21: =983100/325851/1.9835*1.02 -> 1.5514815 | R21: =((1456511/646272)*1.04)-T21 -> 1.9383978 | S21: 0 | T21: =(0.3678*1.06)*1.04 -> 0.40546272 | U21: =M21-(Q21+R21+S21+T21) -> -0.73534205 | V21: 0 | W21: 0 | X21: =M21-N21-P21-O21-Q21-R21-S21-T21-U21+V21+W21 -> 0 | Y21: =X21-AO21 -> 0 | AE21: 0 | AH21: 17.9 | AI21: =AI20-AH21 -> 2333.3368 | AK21: =N21+O21+P21+Q21+R21+S21+T21+U21+X21+AE21+AH21 -> 21.06 | AL21: =IF(L21<0,L21*-1,0) -> 0 | AM21: =AK21+AL21 -> 21.06 | AV21: 0.07 | AW21: 31 | AX21: 1 | AZ21: =SUM(N21,P21:U21) -> 3.16 | BA21: 0 | BB21: 6750
A22: =A21+1 -> 8 | B22: 6867.12 | C22: 180287 | D22: =C22-C21 -> 103 | E22: =C22-152000 -> 28287 | F22: =D22/$D$2 -> 51.928409 | G22: 60 | H22: 0 | I22: =G22+H22 -> 60 | J22: =IF(L22>0,L22,0) -> 12.688409 | K22: =I22+J22 -> 72.688409 | L22: =F22-(I22-AK22) -> 12.688409 | M22: 2.86 | N22: 0 | O22: =0*1.05 -> 0 | P22: 0 | Q22: =1177900/325851/1.9835*1.02 -> 1.8589056 | R22: =((1412545/646272)*1.04)-T22 -> 1.8676464 | S22: 0 | T22: =(0.3678*1.06)*1.04 -> 0.40546272 | U22: =M22-(Q22+R22+S22+T22) -> -1.2720147 | V22: 0 | W22: 0 | X22: =M22-N22-P22-O22-Q22-R22-S22-T22-U22+V22+W22 -> 0 | Y22: =X22-AO22 -> 0 | AE22: 0 | AH22: 17.9 | AI22: =AI21-AH22 -> 2315.4368 | AK22: =N22+O22+P22+Q22+R22+S22+T22+U22+X22+AE22+AH22 -> 20.76 | AL22: =IF(L22<0,L22*-1,0) -> 0 | AM22: =AK22+AL22 -> 20.76 | AV22: 0.07 | AW22: 29 | AX22: -2 | AZ22: =SUM(N22,P22:U22) -> 2.86 | BA22: 0 | BB22: 6762
A23: =A22+1 -> 9 | B23: 6867.14 | C23: 180339 | D23: =C23-C22 -> 52 | E23: =C23-152000 -> 28339 | F23: =D23/$D$2 -> 26.216284 | G23: 62 | H23: 0 | I23: =G23+H23 -> 62 | J23: =IF(L23>0,L23,0) -> 0 | K23: =I23+J23 -> 62 | L23: =F23-(I23-AK23) -> -14.613716 | M23: 3.27 | N23: 0 | O23: =0*1.05 -> 0 | P23: 0 | Q23: =856700/325851/1.9835*1.02 -> 1.3520031 | R23: =((1385640/646272)*1.04)-T23 -> 1.8243501 | S23: 0 | T23: =(0.3678*1.06)*1.04 -> 0.40546272 | U23: =M23-(Q23+R23+S23+T23) -> -0.3118159 | V23: 0 | W23: 0 | X23: =M23-N23-P23-O23-Q23-R23-S23-T23-U23+V23+W23 -> 0 | Y23: =X23-AO23 -> 0 | AE23: 0 | AH23: 17.9 | AI23: =AI22-AH23 -> 2297.5368 | AK23: =N23+O23+P23+Q23+R23+S23+T23+U23+X23+AE23+AH23 -> 21.17 | AL23: =IF(L23<0,L23*-1,0) -> 14.613716 | AM23: =AK23+AL23 -> 35.783716 | AV23: 0 | AW23: 21 | AX23: -5 | AZ23: =SUM(N23,P23:U23) -> 3.27 | BA23: 0 | BB23: 6767
A24: =A23+1 -> 10 | B24: 6867.16 | C24: 180390 | D24: =C24-C23 -> 51 | E24: =C24-152000 -> 28390 | F24: =D24/$D$2 -> 25.712125 | G24: 60 | H24: 0 | I24: =G24+H24 -> 60 | J24: =IF(L24>0,L24,0) -> 0 | K24: =I24+J24 -> 60 | L24: =F24-(I24-AK24) -> -12.627875 | M24: 3.76 | N24: 0 | O24: =0*1.05 -> 0 | P24: 0 | Q24: =1217400/325851/1.9835*1.02 -> 1.9212426 | R24: =((1464000/646272)*1.04)-T24 -> 1.9504493 | S24: 0 | T24: =(0.3678*1.06)*1.04 -> 0.40546272 | U24: =M24-(Q24+R24+S24+T24) -> -0.51715466 | V24: 0 | W24: 0 | X24: =M24-N24-P24-O24-Q24-R24-S24-T24-U24+V24+W24 -> 0 | Y24: =X24-AO24 -> 0 | AE24: 0 | AH24: 17.9 | AI24: =AI23-AH24 -> 2279.6368 | AK24: =N24+O24+P24+Q24+R24+S24+T24+U24+X24+AE24+AH24 -> 21.66 | AL24: =IF(L24<0,L24*-1,0) -> 12.627875 | AM24: =AK24+AL24 -> 34.287875 | AV24: 0 | AW24: 32 | AX24: -2 | AZ24: =SUM(N24,P24:U24) -> 3.76 | BA24: 0 | BB24: 6775
A25: =A24+1 -> 11 | B25: 6867.16 | C25: 180390 | D25: =C25-C24 -> 0 | E25: =C25-152000 -> 28390 | F25: =D25/$D$2 -> 0 | G25: 61 | H25: 0 | I25: =G25+H25 -> 61 | J25: =IF(L25>0,L25,0) -> 0 | K25: =I25+J25 -> 61 | L25: =F25-(I25-AK25) -> -39.5 | M25: 3.6 | N25: 0 | O25: =0*1.05 -> 0 | P25: 0 | Q25: =1199900/325851/1.9835*1.02 -> 1.8936249 | R25: =((1432726/646272)*1.04)-T25 -> 1.9001223 | S25: 0 | T25: =(0.3678*1.06)*1.04 -> 0.40546272 | U25: =M25-(Q25+R25+S25+T25) -> -0.59920995 | V25: 0 | W25: 0 | X25: =M25-N25-P25-O25-Q25-R25-S25-T25-U25+V25+W25 -> 0 | Y25: =X25-AO25 -> 0 | AE25: 0 | AH25: 17.9 | AI25: =AI24-AH25 -> 2261.7368 | AK25: =N25+O25+P25+Q25+R25+S25+T25+U25+X25+AE25+AH25 -> 21.5 | AL25: =IF(L25<0,L25*-1,0) -> 39.5 | AM25: =AK25+AL25 -> 61 | AV25: 0 | AW25: 41 | AX25: 5 | AZ25: =SUM(N25,P25:U25) -> 3.6 | BA25: 0 | BB25: 6783
A26: =A25+1 -> 12 | B26: 6867.19 | C26: 180467 | D26: =C26-C25 -> 77 | E26: =C26-152000 -> 28467 | F26: =D26/$D$2 -> 38.820267 | G26: 56 | H26: 0 | I26: =G26+H26 -> 56 | J26: =IF(L26>0,L26,0) -> 4.4202672 | K26: =I26+J26 -> 60.420267 | L26: =F26-(I26-AK26) -> 4.4202672 | M26: 3.7 | N26: 0 | O26: =0*1.05 -> 0 | P26: 0 | Q26: =1169400/325851/1.9835*1.02 -> 1.8454913 | R26: =((1405746/646272)*1.04)-T26 -> 1.8567053 | S26: 0 | T26: =(0.3678*1.06)*1.04 -> 0.40546272 | U26: =M26-(Q26+R26+S26+T26) -> -0.40765929 | V26: 0 | W26: 0 | X26: =M26-N26-P26-O26-Q26-R26-S26-T26-U26+V26+W26 -> 0 | Y26: =X26-AO26 -> 0 | AE26: 0 | AH26: 17.9 | AI26: =AI25-AH26 -> 2243.8368 | AK26: =N26+O26+P26+Q26+R26+S26+T26+U26+X26+AE26+AH26 -> 21.6 | AL26: =IF(L26<0,L26*-1,0) -> 0 | AM26: =AK26+AL26 -> 21.6 | AV26: 0 | AW26: 47 | AX26: 13 | AZ26: =SUM(N26,P26:U26) -> 3.7 | BA26: 0 | BB26: 6794
A27: =A26+1 -> 13 | B27: 6867.23 | C27: 180570 | D27: =C27-C26 -> 103 | E27: =C27-152000 -> 28570 | F27: =D27/$D$2 -> 51.928409 | G27: 57 | H27: 0 | I27: =G27+H27 -> 57 | J27: =IF(L27>0,L27,0) -> 15.918409 | K27: =I27+J27 -> 72.918409 | L27: =F27-(I27-AK27) -> 15.918409 | M27: 3.09 | N27: 0 | O27: =0*1.05 -> 0 | P27: 0 | Q27: =998300/325851/1.9835*1.02 -> 1.5754694 | R27: =((1478096/646272)*1.04)-T27 -> 1.912501 | S27: 0 | T27: =(0.4228*1.06)*1.04 -> 0.46609472 | U27: =M27-(Q27+R27+S27+T27) -> -0.86406519 | V27: 0 | W27: 0 | X27: =M27-N27-P27-O27-Q27-R27-S27-T27-U27+V27+W27 -> 0 | Y27: =X27-AO27 -> 0 | AE27: 0 | AH27: 17.9 | AI27: =AI26-AH27 -> 2225.9368 | AK27: =N27+O27+P27+Q27+R27+S27+T27+U27+X27+AE27+AH27 -> 20.99 | AL27: =IF(L27<0,L27*-1,0) -> 0 | AM27: =AK27+AL27 -> 20.99 | AV27: 0 | AW27: 41 | AX27: 16 | AZ27: =SUM(N27,P27:U27) -> 3.09 | BA27: 0 | BB27: 6823
A28: =A27+1 -> 14 | B28: 6867.28 | C28: 180699 | D28: =C28-C27 -> 129 | E28: =C28-152000 -> 28699 | F28: =D28/$D$2 -> 65.036552 | G28: 56 | H28: 0 | I28: =G28+H28 -> 56 | J28: =IF(L28>0,L28,0) -> 30.156552 | K28: =I28+J28 -> 86.156552 | L28: =F28-(I28-AK28) -> 30.156552 | M28: 3.22 | N28: 0 | O28: =0*1.05 -> 0 | P28: 0 | Q28: =1078400/325851/1.9835*1.02 -> 1.7018794 | R28: =((1431480/646272)*1.04)-T28 -> 1.8374852 | S28: 0 | T28: =(0.4228*1.06)*1.04 -> 0.46609472 | U28: =M28-(Q28+R28+S28+T28) -> -0.78545934 | V28: 0 | W28: 0 | X28: =M28-N28-P28-O28-Q28-R28-S28-T28-U28+V28+W28 -> 0 | Y28: =X28-AO28 -> 0 | AE28: 0 | AH28: 17.9 | AI28: =AI27-AH28 -> 2208.0368 | AK28: =N28+O28+P28+Q28+R28+S28+T28+U28+X28+AE28+AH28 -> 21.12 | AL28: =IF(L28<0,L28*-1,0) -> 0 | AM28: =AK28+AL28 -> 21.12 | AV28: 0 | AW28: 47 | AX28: 16 | AZ28: =SUM(N28,P28:U28) -> 3.22 | BA28: 0 | BB28: 6829
A29: =A28+1 -> 15 | B29: 6867.35 | C29: 180879 | D29: =C29-C28 -> 180 | E29: =C29-152000 -> 28879 | F29: =D29/$D$2 -> 90.748677 | G29: 55 | H29: 0 | I29: =G29+H29 -> 55 | J29: =IF(L29>0,L29,0) -> 56.868677 | K29: =I29+J29 -> 111.86868 | L29: =F29-(I29-AK29) -> 56.868677 | M29: 3.22 | N29: 0 | O29: =0*1.05 -> 0 | P29: 0 | Q29: =1143600/325851/1.9835*1.02 -> 1.804775 | R29: =((1414768/646272)*1.04)-T29 -> 1.8105918 | S29: 0 | T29: =(0.4228*1.06)*1.04 -> 0.46609472 | U29: =M29-(Q29+R29+S29+T29) -> -0.86146143 | V29: 0 | W29: 0 | X29: =M29-N29-P29-O29-Q29-R29-S29-T29-U29+V29+W29 -> 0 | Y29: =X29-AO29 -> 0 | AE29: 0 | AH29: 17.9 | AI29: =AI28-AH29 -> 2190.1368 | AK29: =N29+O29+P29+Q29+R29+S29+T29+U29+X29+AE29+AH29 -> 21.12 | AL29: =IF(L29<0,L29*-1,0) -> 0 | AM29: =AK29+AL29 -> 21.12 | AV29: 0 | AW29: 52 | AX29: 14 | AZ29: =SUM(N29,P29:U29) -> 3.22 | BA29: 0 | BB29: 6837
A30: =A29+1 -> 16 | B30: 6867.37 | C30: 180930 | D30: =C30-C29 -> 51 | E30: =C30-152000 -> 28930 | F30: =D30/$D$2 -> 25.712125 | G30: 56 | H30: 0 | I30: =G30+H30 -> 56 | J30: =IF(L30>0,L30,0) -> 0 | K30: =I30+J30 -> 56 | L30: =F30-(I30-AK30) -> -8.667875 | M30: 3.72 | N30: 0 | O30: =0*1.05 -> 0 | P30: 0 | Q30: =1105800/325851/1.9835*1.02 -> 1.7451208 | R30: =((1396752/646272)*1.04)-T30 -> 1.7815999 | S30: 0 | T30: =(0.4228*1.06)*1.04 -> 0.46609472 | U30: =M30-(Q30+R30+S30+T30) -> -0.27281539 | V30: 0 | W30: 0 | X30: =M30-N30-P30-O30-Q30-R30-S30-T30-U30+V30+W30 -> 0 | Y30: =X30-AO30 -> 0 | AE30: 0 | AH30: 17.9 | AI30: =AI29-AH30 -> 2172.2368 | AK30: =N30+O30+P30+Q30+R30+S30+T30+U30+X30+AE30+AH30 -> 21.62 | AL30: =IF(L30<0,L30*-1,0) -> 8.667875 | AM30: =AK30+AL30 -> 30.287875 | AV30: 0 | AW30: 55 | AX30: 18 | AZ30: =SUM(N30,P30:U30) -> 3.72 | BA30: 0 | BB30: 6842
A31: =A30+1 -> 17 | B31: 6867.42 | C31: 181059 | D31: =C31-C30 -> 129 | E31: =C31-152000 -> 29059 | F31: =D31/$D$2 -> 65.036552 | G31: 56 | H31: 0 | I31: =G31+H31 -> 56 | J31: =IF(L31>0,L31,0) -> 30.046552 | K31: =I31+J31 -> 86.046552 | L31: =F31-(I31-AK31) -> 30.046552 | M31: 3.11 | N31: 0 | O31: =0*1.05 -> 0 | P31: 0 | Q31: =1169700/325851/1.9835*1.02 -> 1.8459647 | R31: =((1410728/646272)*1.04)-T31 -> 1.8040905 | S31: 0 | T31: =(0.4228*1.06)*1.04 -> 0.46609472 | U31: =M31-(Q31+R31+S31+T31) -> -1.0061499 | V31: 0 | W31: 0 | X31: =M31-N31-P31-O31-Q31-R31-S31-T31-U31+V31+W31 -> 0 | Y31: =X31-AO31 -> 0 | AE31: 0 | AH31: 17.9 | AI31: =AI30-AH31 -> 2154.3368 | AK31: =N31+O31+P31+Q31+R31+S31+T31+U31+X31+AE31+AH31 -> 21.01 | AL31: =IF(L31<0,L31*-1,0) -> 0 | AM31: =AK31+AL31 -> 21.01 | AV31: 0 | AW31: 51 | AX31: 20 | AZ31: =SUM(N31,P31:U31) -> 3.11 | BA31: 0 | BB31: 6851
A32: =A31+1 -> 18 | B32: 6867.47 | C32: 181187 | D32: =C32-C31 -> 128 | E32: =C32-152000 -> 29187 | F32: =D32/$D$2 -> 64.532392 | G32: 57 | H32: 0 | I32: =G32+H32 -> 57 | J32: =IF(L32>0,L32,0) -> 28.892392 | K32: =I32+J32 -> 85.892392 | L32: =F32-(I32-AK32) -> 28.892392 | M32: 3.46 | N32: 0 | O32: =0*1.05 -> 0 | P32: 0 | Q32: =848600/325851/1.9835*1.02 -> 1.33922 | R32: =((1463800/646272)*1.04)-T32 -> 1.8894955 | S32: 0 | T32: =(0.4228*1.06)*1.04 -> 0.46609472 | U32: =M32-(Q32+R32+S32+T32) -> -0.23481025 | V32: 0 | W32: 0 | X32: =M32-N32-P32-O32-Q32-R32-S32-T32-U32+V32+W32 -> 0 | Y32: =X32-AO32 -> 0 | AE32: 0 | AH32: 17.9 | AI32: =AI31-AH32 -> 2136.4368 | AK32: =N32+O32+P32+Q32+R32+S32+T32+U32+X32+AE32+AH32 -> 21.36 | AL32: =IF(L32<0,L32*-1,0) -> 0 | AM32: =AK32+AL32 -> 21.36 | AV32: 0 | AW32: 53 | AX32: 24 | AZ32: =SUM(N32,P32:U32) -> 3.46 | BA32: 0 | BB32: 6859
A33: =A32+1 -> 19 | B33: 6867.54 | C33: 181367 | D33: =C33-C32 -> 180 | E33: =C33-152000 -> 29367 | F33: =D33/$D$2 -> 90.748677 | G33: 57 | H33: 0 | I33: =G33+H33 -> 57 | J33: =IF(L33>0,L33,0) -> 54.538677 | K33: =I33+J33 -> 111.53868 | L33: =F33-(I33-AK33) -> 54.538677 | M33: 2.99 | N33: 0 | O33: =0*1.05 -> 0 | P33: 0 | Q33: =981700/325851/1.9835*1.02 -> 1.5492721 | R33: =((1430688/646272)*1.04)-T33 -> 1.8362107 | S33: 0 | T33: =(0.4228*1.06)*1.04 -> 0.46609472 | U33: =M33-(Q33+R33+S33+T33) -> -0.86157751 | V33: 0 | W33: 0 | X33: =M33-N33-P33-O33-Q33-R33-S33-T33-U33+V33+W33 -> 0 | Y33: =X33-AO33 -> 0 | AE33: 0 | AH33: 17.8 | AI33: =AI32-AH33 -> 2118.6368 | AK33: =N33+O33+P33+Q33+R33+S33+T33+U33+X33+AE33+AH33 -> 20.79 | AL33: =IF(L33<0,L33*-1,0) -> 0 | AM33: =AK33+AL33 -> 20.79 | AV33: 0 | AW33: 51 | AX33: 28 | AZ33: =SUM(N33,P33:U33) -> 2.99 | BA33: 0 | BB33: 6854
A34: =A33+1 -> 20 | B34: 6867.62 | C34: 181573 | D34: =C34-C33 -> 206 | E34: =C34-152000 -> 29573 | F34: =D34/$D$2 -> 103.85682 | G34: 57 | H34: 0 | I34: =G34+H34 -> 57 | J34: =IF(L34>0,L34,0) -> 68.256819 | K34: =I34+J34 -> 125.25682 | L34: =F34-(I34-AK34) -> 68.256819 | M34: 3.5 | N34: 0 | O34: =0*1.05 -> 0 | P34: 0 | Q34: =907800/325851/1.9835*1.02 -> 1.4326466 | R34: =((1452048/646272)*1.04)-T34 -> 1.8930728 | S34: 0 | T34: =(0.4024*1.06)*1.04 -> 0.44360576 | U34: =M34-(Q34+R34+S34+T34) -> -0.2693252 | V34: 0 | W34: 0 | X34: =M34-N34-P34-O34-Q34-R34-S34-T34-U34+V34+W34 -> 0 | Y34: =X34-AO34 -> 0 | AE34: 0 | AH34: 17.9 | AI34: =AI33-AH34 -> 2100.7368 | AK34: =N34+O34+P34+Q34+R34+S34+T34+U34+X34+AE34+AH34 -> 21.4 | AL34: =IF(L34<0,L34*-1,0) -> 0 | AM34: =AK34+AL34 -> 21.4 | AV34: 0.03 | AW34: 40 | AX34: 21 | AZ34: =SUM(N34,P34:U34) -> 3.5 | BA34: 0 | BB34: 6872
A35: =A34+1 -> 21 | B35: 6867.64 | C35: 181624 | D35: =C35-C34 -> 51 | E35: =C35-152000 -> 29624 | F35: =D35/$D$2 -> 25.712125 | G35: 57 | H35: 0 | I35: =G35+H35 -> 57 | J35: =IF(L35>0,L35,0) -> 0 | K35: =I35+J35 -> 57 | L35: =F35-(I35-AK35) -> -10.437875 | M35: 2.95 | N35: 0 | O35: =0*1.05 -> 0 | P35: 0 | Q35: =1157400/325851/1.9835*1.02 -> 1.8265535 | R35: =((1406128/646272)*1.04)-T35 -> 1.819177 | S35: 0 | T35: =(0.4024*1.06)*1.04 -> 0.44360576 | U35: =M35-(Q35+R35+S35+T35) -> -1.1393362 | V35: 0 | W35: 0 | X35: =M35-N35-P35-O35-Q35-R35-S35-T35-U35+V35+W35 -> 0 | Y35: =X35-AO35 -> 0 | AE35: 0 | AH35: 17.9 | AI35: =AI34-AH35 -> 2082.8368 | AK35: =N35+O35+P35+Q35+R35+S35+T35+U35+X35+AE35+AH35 -> 20.85 | AL35: =IF(L35<0,L35*-1,0) -> 10.437875 | AM35: =AK35+AL35 -> 31.287875 | AV35: 0.03 | AW35: 33 | AX35: 13 | AZ35: =SUM(N35,P35:U35) -> 2.95 | BA35: 0 | BB35: 6863
A36: =A35+1 -> 22 | B36: 6867.69 | C36: 181753 | D36: =C36-C35 -> 129 | E36: =C36-152000 -> 29753 | F36: =D36/$D$2 -> 65.036552 | G36: 56 | H36: 0 | I36: =G36+H36 -> 56 | J36: =IF(L36>0,L36,0) -> 30.396552 | K36: =I36+J36 -> 86.396552 | L36: =F36-(I36-AK36) -> 30.396552 | M36: 3.46 | N36: 0 | O36: =0*1.05 -> 0 | P36: 0 | Q36: =1065800/325851/1.9835*1.02 -> 1.6819947 | R36: =((1434720/646272)*1.04)-T36 -> 1.8651881 | S36: 0 | T36: =(0.4024*1.06)*1.04 -> 0.44360576 | U36: =M36-(Q36+R36+S36+T36) -> -0.53078853 | V36: 0 | W36: 0 | X36: =M36-N36-P36-O36-Q36-R36-S36-T36-U36+V36+W36 -> 0 | Y36: =X36-AO36 -> 0 | AE36: 0 | AH36: 17.9 | AI36: =AI35-AH36 -> 2064.9368 | AK36: =N36+O36+P36+Q36+R36+S36+T36+U36+X36+AE36+AH36 -> 21.36 | AL36: =IF(L36<0,L36*-1,0) -> 0 | AM36: =AK36+AL36 -> 21.36 | AV36: 0 | AW36: 34 | AX36: 8 | AZ36: =SUM(N36,P36:U36) -> 3.46 | BA36: 0 | BB36: 6851
A37: =A36+1 -> 23 | B37: 6867.73 | C37: 181856 | D37: =C37-C36 -> 103 | E37: =C37-152000 -> 29856 | F37: =D37/$D$2 -> 51.928409 | G37: 56 | H37: 0 | I37: =G37+H37 -> 56 | J37: =IF(L37>0,L37,0) -> 17.078409 | K37: =I37+J37 -> 73.078409 | L37: =F37-(I37-AK37) -> 17.078409 | M37: 3.25 | N37: 0 | O37: =0*1.05 -> 0 | P37: 0 | Q37: =1053300/325851/1.9835*1.02 -> 1.6622678 | R37: =((1426656/646272)*1.04)-T37 -> 1.8522112 | S37: 0 | T37: =(0.4024*1.06)*1.04 -> 0.44360576 | U37: =M37-(Q37+R37+S37+T37) -> -0.7080848 | V37: 0 | W37: 0 | X37: =M37-N37-P37-O37-Q37-R37-S37-T37-U37+V37+W37 -> 0 | Y37: =X37-AO37 -> 0 | AE37: 0 | AH37: 17.9 | AI37: =AI36-AH37 -> 2047.0368 | AK37: =N37+O37+P37+Q37+R37+S37+T37+U37+X37+AE37+AH37 -> 21.15 | AL37: =IF(L37<0,L37*-1,0) -> 0 | AM37: =AK37+AL37 -> 21.15 | AV37: 0 | AW37: 41 | AX37: 17 | AZ37: =SUM(N37,P37:U37) -> 3.25 | BA37: 0 | BB37: 6862
A38: =A37+1 -> 24 | B38: 6867.77 | C38: 181959 | D38: =C38-C37 -> 103 | E38: =C38-152000 -> 29959 | F38: =D38/$D$2 -> 51.928409 | G38: 56 | H38: 0 | I38: =G38+H38 -> 56 | J38: =IF(L38>0,L38,0) -> 17.048409 | K38: =I38+J38 -> 73.048409 | L38: =F38-(I38-AK38) -> 17.048409 | M38: 3.22 | N38: 0 | O38: =0*1.05 -> 0 | P38: 0 | Q38: =910100/325851/1.9835*1.02 -> 1.4362764 | R38: =((1535616/646272)*1.04)-T38 -> 2.0275529 | S38: 0 | T38: =(0.4024*1.06)*1.04 -> 0.44360576 | U38: =M38-(Q38+R38+S38+T38) -> -0.68743504 | V38: 0 | W38: 0 | X38: =M38-N38-P38-O38-Q38-R38-S38-T38-U38+V38+W38 -> 0 | Y38: =X38-AO38 -> 0 | AE38: 0 | AH38: 17.9 | AI38: =AI37-AH38 -> 2029.1368 | AK38: =N38+O38+P38+Q38+R38+S38+T38+U38+X38+AE38+AH38 -> 21.12 | AL38: =IF(L38<0,L38*-1,0) -> 0 | AM38: =AK38+AL38 -> 21.12 | AV38: 0 | AW38: 46 | AX38: 18 | AZ38: =SUM(N38,P38:U38) -> 3.22 | BA38: 0 | BB38: 6857
A39: =A38+1 -> 25 | B39: 6867.81 | C39: 182061 | D39: =C39-C38 -> 102 | E39: =C39-152000 -> 30061 | F39: =D39/$D$2 -> 51.42425 | G39: 56 | H39: 0 | I39: =G39+H39 -> 56 | J39: =IF(L39>0,L39,0) -> 16.69425 | K39: =I39+J39 -> 72.69425 | L39: =F39-(I39-AK39) -> 16.69425 | M39: 3.37 | N39: 0 | O39: =0*1.05 -> 0 | P39: 0 | Q39: =996600/325851/1.9835*1.02 -> 1.5727866 | R39: =((1381264/646272)*1.04)-T39 -> 1.7791651 | S39: 0 | T39: =(0.4024*1.06)*1.04 -> 0.44360576 | U39: =M39-(Q39+R39+S39+T39) -> -0.42555741 | V39: 0 | W39: 0 | X39: =M39-N39-P39-O39-Q39-R39-S39-T39-U39+V39+W39 -> 0 | Y39: =X39-AO39 -> 0 | AE39: 0 | AH39: 17.9 | AI39: =AI38-AH39 -> 2011.2368 | AK39: =N39+O39+P39+Q39+R39+S39+T39+U39+X39+AE39+AH39 -> 21.27 | AL39: =IF(L39<0,L39*-1,0) -> 0 | AM39: =AK39+AL39 -> 21.27 | AV39: 0 | AW39: 48 | AX39: 17 | AZ39: =SUM(N39,P39:U39) -> 3.37 | BA39: 0 | BB39: 6848
A40: =A39+1 -> 26 | B40: 6867.84 | C40: 182139 | D40: =C40-C39 -> 78 | E40: =C40-152000 -> 30139 | F40: =D40/$D$2 -> 39.324427 | G40: 55 | H40: 0 | I40: =G40+H40 -> 55 | J40: =IF(L40>0,L40,0) -> 5.0644265 | K40: =I40+J40 -> 60.064427 | L40: =F40-(I40-AK40) -> 5.0644265 | M40: 2.84 | N40: 0 | O40: =0*1.05 -> 0 | P40: 0 | Q40: =929500/325851/1.9835*1.02 -> 1.4668926 | R40: =((1503696/646272)*1.04)-T40 -> 1.9761863 | S40: 0 | T40: =(0.4024*1.06)*1.04 -> 0.44360576 | U40: =M40-(Q40+R40+S40+T40) -> -1.0466846 | V40: 0 | W40: 0 | X40: =M40-N40-P40-O40-Q40-R40-S40-T40-U40+V40+W40 -> 0 | Y40: =X40-AO40 -> 0 | AE40: 0 | AH40: 17.9 | AI40: =AI39-AH40 -> 1993.3368 | AK40: =N40+O40+P40+Q40+R40+S40+T40+U40+X40+AE40+AH40 -> 20.74 | AL40: =IF(L40<0,L40*-1,0) -> 0 | AM40: =AK40+AL40 -> 20.74 | AV40: 0 | AW40: 50 | AX40: 16 | AZ40: =SUM(N40,P40:U40) -> 2.84 | BA40: 0 | BB40: 6843
A41: =A40+1 -> 27 | B41: 6867.88 | C41: 182241 | D41: =C41-C40 -> 102 | E41: =C41-152000 -> 30241 | F41: =D41/$D$2 -> 51.42425 | G41: 56 | H41: 0 | I41: =G41+H41 -> 56 | J41: =IF(L41>0,L41,0) -> 16.22425 | K41: =I41+J41 -> 72.22425 | L41: =F41-(I41-AK41) -> 16.22425 | M41: 2.9 | N41: 0 | O41: =0*1.05 -> 0 | P41: 0 | Q41: =935400/325851/1.9835*1.02 -> 1.4762036 | R41: =((1193232/646272)*1.04)-T41 -> 1.467208 | S41: 0 | T41: =(0.4109*1.06)*1.04 -> 0.45297616 | U41: =M41-(Q41+R41+S41+T41) -> -0.49638784 | V41: 0 | W41: 0 | X41: =M41-N41-P41-O41-Q41-R41-S41-T41-U41+V41+W41 -> 0 | Y41: =X41-AO41 -> 0 | AE41: 0 | AH41: 17.9 | AI41: =AI40-AH41 -> 1975.4368 | AK41: =N41+O41+P41+Q41+R41+S41+T41+U41+X41+AE41+AH41 -> 20.8 | AL41: =IF(L41<0,L41*-1,0) -> 0 | AM41: =AK41+AL41 -> 20.8 | AV41: 0 | AW41: 48 | AX41: 18 | AZ41: =SUM(N41,P41:U41) -> 2.9 | BA41: 0 | BB41: 6843
A42: =A41+1 -> 28 | B42: 6867.9 | C42: 182293 | D42: =C42-C41 -> 52 | E42: =C42-152000 -> 30293 | F42: =D42/$D$2 -> 26.216284 | G42: 57 | H42: 0 | I42: =G42+H42 -> 57 | J42: =IF(L42>0,L42,0) -> 0 | K42: =I42+J42 -> 57 | L42: =F42-(I42-AK42) -> -9.9837157 | M42: 2.9 | N42: 0 | O42: =0*1.05 -> 0 | P42: 0 | Q42: =1033600/325851/1.9835*1.02 -> 1.6311782 | R42: =((1323168/646272)*1.04)-T42 -> 1.6763049 | S42: 0 | T42: =(0.4109*1.06)*1.04 -> 0.45297616 | U42: =M42-(Q42+R42+S42+T42) -> -0.86045925 | V42: 0 | W42: 0 | X42: =M42-N42-P42-O42-Q42-R42-S42-T42-U42+V42+W42 -> 0 | Y42: =X42-AO42 -> 0 | AE42: 0 | AH42: 17.9 | AI42: =AI41-AH42 -> 1957.5368 | AK42: =N42+O42+P42+Q42+R42+S42+T42+U42+X42+AE42+AH42 -> 20.8 | AL42: =IF(L42<0,L42*-1,0) -> 9.9837157 | AM42: =AK42+AL42 -> 30.783716 | AV42: 0 | AW42: 46 | AX42: 22 | AZ42: =SUM(N42,P42:U42) -> 2.9 | BA42: 0 | BB42: 6843
...

Sheet JAN
K1: MCPHEE RESERVOIR INFLOW/OUTFLOW TABULATION
A2: AF/cfs CONVERT FACTOR | D2: 1.9835 | K2: JANUARY "2014"
D4: RESERVOIR | I4: INFLOW | X4: OUTFLOW | AP4: ADJUSTMENTS | AW4: WEATHER
A5: DATE | B5: RESERV | C5: RESERV | D5: AC FT | E5: ACTIVE | F5: CONV TO | G5: DOLORES | H5: LOST | I5: RECORD | J5: CALC | K5: TOTAL | L5: CALC | M5: DOLORES TUNNEL | V5: LONE | W5: U | X5: TOTAL | Y5: TOTAL | Z5: MVI | AA5: MVI | AB5: MVI | AC5: TO EX & | AD5: MVI | AE5: DV CR | AF5: D/S SENIOR | AH5: BELOW | AI5: FISH | AJ5: SPILL | AK5: RECORD | AL5: CALC | AM5: TOTAL | AN5: NAR | AO5: MVI | AP5: MVI | AQ5: MVI | AR5: DIST. | AS5: U/S | AT5: TOTTEN | AU5: UTES | AV5: RAIN | AW5: MAX | AX5: MIN | AZ5: TOTAL | BA5: GRNDHOG | BB5: GRNDHOG
A6: DEC | B6: ELEV | D6: CHANGE | E6: CAP | F6: CFS | G6: RIVER | H6: CAN | I6: INFLOW | J6: INFLOW | K6: INFLOW | L6: INF/OTF | M6: TOT DIV | N6: WET | O6: UTE | P6: QUEST | Q6: MWC | R6: CORTEZ | T6: UTE | U6: F-BAY | V6: PINE | W6: LAT | X6: MVI | Y6: MVI | Z6: CALL | AA6: CALL | AB6: APR- | AC6: U/S EX | AD6: PROJ | AE6: CANAL | AF6: MVIC | AG6: PROJ | AH6: MCP | AI6: LEFT | AK6: OTF | AL6: OTF | AM6: OTF | AN6: FILL | AO6: STOCK | AP6: STORED | AQ6: STORED | AR6: CLASS | AS6: USERS | AT6: (FRESH | AU6: FROM | AW6: TMP | AX6: TMP | AZ6: TUNNEL | BA6: DISCHARGE | BB6: CAPACITY
N7: LAND | O7: F&R | Q7: NON - | R7: NON - | S7: PROJ | T7: PROJ | U7: BAL | X7: WATER | Y7: IRRIG. | Z7: STOR | AA7: SPILLED | AB7: JUNE | AF7: 1.7 | AG7: 1.3 | AI7: 12682.175 | AP7: Apr - Jun | AQ7: EVAP | AR7: "B" | AS7: EXCH | AT7: WATER) | AU7: DWCD | AZ7: Misc.
Q8: PROJ | R8: PROJ | X8: USED | Y8: WATER | AA8: OR | AB8: (DIV+
R9: 4.2 | Y9: USED | AA9: USED | AB9: CALL) | BB9: FP = 5394
C10: AC. Ft. | E10: AC FT | G10: CFS | H10: CFS | I10: CFS | J10: CFS | K10: CFS | L10: CFS | M10: CFS | N10: CFS | O10: CFS | P10: CFS | Q10: CFS | R10: CFS | S10: CFS | T10: CFS | U10: CFS | V10: CFS | W10: CFS | X10: 153400 | Y10: 150400 | AB10: 72000 | AC10: CFS | AD10: CFS | AE10: CFS | AF10: CFS | AG10: CFS | AH10: CFS | AI10: CFS | AJ10: CFS | AK10: CFS | AL10: CFS | AM10: CFS | AN10: CFS | AO10: CFS | AP10: CFS | AQ10: AC.FT. | AR10: CFS | AS10: CFS | AT10: CFS | AU10: CFS | AZ10: Outflow | BA10: CFS | BB10: AC FT
N11: 1.03 | O11: 1.05 | P11: 1.02 | Q11: 1.02 | R11: 1.04 | T11: 1.04 | X11: CFS | Y11: CFS | Z11: CFS | AA11: CFS | AB11: Ac. Ft. | AZ11: CFS
A12: SEASON BAL
A13: YTD | B13: =DEC!B45 -> 6868 | C13: =DEC!C45 -> 182550 | D13: =DEC!D54 -> 8828 | E13: =DEC!E54 -> 30550 | F13: =DEC!F53 -> 4450.7184 | G13: =DEC!G53 -> 5254 | H13: =DEC!H53 -> 9.194 | I13: =DEC!I53 -> 5262.574 | J13: =DEC!J53 -> 980.25504 | K13: =DEC!K53 -> 6242.829 | L13: =DEC!L53 -> 473.79443 | M13: =DEC!M53 -> 189.65 | ... Y13: =DEC!Y53 -> -15.0402 | AC13: =DEC!AC53 -> 1714.14 | AH13: =DEC!AH53 -> 1096 | AI13: =DEC!AI53 -> 1903.8368 | AK13: =DEC!AK53 -> 1285.65 | AL13: =DEC!AL53 -> 506.46061 | AM13: =DEC!AM53 -> 1792.1106 | AN13: =DEC!AN53 -> 0 | AO13: =DEC!AO53 -> 0 | AV13: =DEC!AV53 -> 2.07 | AZ13: =DEC!AZ53 -> 189.65 | BA13: =DEC!BA53 -> 0
A15: 1 | B15: 6868.05 | C15: 182680 | D15: =C15-C13 -> 130 | E15: =C15-152000 -> 30680 | F15: =D15/$D$2 -> 65.540711 | G15: 56 | H15: 0 | I15: =G15+H15 -> 56 | J15: =IF(L15>0,L15,0) -> 30.460711 | K15: =I15+J15 -> 86.460711 | L15: =F15-(I15-AK15) -> 30.460711 | M15: 3.02 | N15: 0 | O15: 0 | P15: 0 | Q15: =990100/325851/1.9835*1.02 -> 1.5625286 | R15: =((1260864/646272)*1.04)-T15 -> 1.5787994 | S15: 0 | T15: =(0.4084*1.06)*1.04 -> 0.45022016 | U15: =M15-(Q15+R15+S15+T15) -> -0.57154819 | V15: 0 | W15: 0 | X15: =M15-N15-P15-O15-Q15-R15-S15-T15-U15+V15+W15 -> 0 | Y15: =X15-AO15 -> 0 | AE15: 0 | AH15: 17.9 | AI15: =AI13-AH15 -> 1885.9368 | AK15: =N15+O15+P15+Q15+R15+S15+T15+U15+X15+AE15+AH15 -> 20.92 | AL15: =IF(L15<0,L15*-1,0) -> 0 | AM15: =AK15+AL15 -> 20.92 | AV15: 0 | AW15: 50 | AX15: 23 | AZ15: =SUM(N15,P15:U15) -> 3.02 | BA15: 0 | BB15: 6846
