Workbook

Sheet NOV
K1: MCPHEE RESERVOIR INFLOW/OUTFLOW TABULATION
A2: AF/cfs CONVERT FACTOR | D2: 1.9835 | L2: NOVEMBER "2009"
D4: RESERVOIR | W4: INFLOW/OUTFLOW (CFS) | AO4: ADJUSTMENTS | AV4: WEATHER
A5: DATE | B5: RESERV | C5: RESERV | D5: AC FT | E5: ACTIVE | F5: CONV TO | G5: DOLORES | H5: LOST | I5: RECORD | J5: CALC | K5: TOTAL | L5: CALC | M5: DOLORES TUNNEL | U5: LONE | V5: U | W5: TOTAL | X5: TOTAL | Y5: MVI | Z5: MVI | AA5: MVI | AB5: TO EX & | AC5: MVI | AD5: DV CR | AE5: D/S SENIOR | AG5: BELOW | AH5: FISH | AI5: SPILL | AJ5: RECORD | AK5: CALC | AL5: TOTAL | AM5: NAR | AN5: MVI | AO5: MVI | AP5: MVI | AQ5: DIST. | AR5: U/S | AS5: TOTTEN | AT5: UTES | AU5: RAIN | AV5: MAX | AW5: MIN | AY5: TOTAL
A6: NOV | B6: ELEV | D6: CHANGE | E6: CAP | F6: CFS | G6: RIVER | H6: CAN | I6: INFLOW | J6: INFLOW | K6: INFLOW | L6: INF/OTF | M6: TOT DIV | N6: WET | O6: UTE | P6: QUEST | Q6: MWC | R6: CTZ | S6: CTZ & | T6: F-BAY | U6: PINE | V6: LAT | W6: MVI | X6: MVI | Y6: CALL | Z6: CALL | AA6: APR- | AB6: U/S EX | AC6: PROJ | AD6: CANAL | AE6: MVIC | AF6: PROJ | AG6: MCP | AH6: LEFT | AJ6: OTF | AK6: OTF | AL6: OTF | AM6: FILL | AN6: STOCK | AO6: STORED | AP6: STORED | AQ6: CLASS | AR6: USERS | AS6: (FRESH | AT6: FROM | AV6: TMP | AW6: TMP | AY6: TUNNEL
N7: LAND | O7: F&R | S7: UTE | T7: SPILL | W7: WATER | X7: IRRIG. | Y7: STOR | Z7: SPILLED | AA7: JUNE | AE7: 1.7 | AF7: 1.3 | AH7: 31798 | AO7: Apr - Jun | AP7: EVAP | AQ7: "B" | AR7: EXCH | AS7: WATER) | AT7: DWCD | AY7: Misc.
W8: USED | X8: WATER | Z8: OR | AA8: (DIV+
X9: USED | Z9: USED | AA9: CALL)
C10: AC. Ft. | E10: AC FT | G10: CFS | H10: CFS | I10: CFS | J10: CFS | K10: CFS | L10: CFS | M10: CFS | N10: CFS | O10: CFS | P10: CFS | Q10: CFS | R10: CFS | S10: PROJ | T10: CFS | U10: CFS | V10: CFS | W10: 153400 | X10: 150400 | AA10: 72000 | AB10: CFS | AC10: CFS | AD10: CFS | AE10: CFS | AF10: CFS | AG10: CFS | AH10: CFS | AI10: CFS | AJ10: CFS | AK10: CFS | AL10: CFS | AM10: AC FT | AN10: CFS | AO10: CFS | AP10: AC.FT. | AQ10: CFS | AR10: CFS | AS10: CFS | AT10: CFS | AY10: Outflow
N11: 1.03 | O11: 1.05 | P11: 1.02 | Q11: 1.02 | R11: 1.04 | S11: CFS | W11: CFS | X11: CFS | Y11: CFS | Z11: CFS | AA11: Ac. Ft. | AY11: CFS
A12: SEASON BAL
A13: YTD | B13: 6893.25 | C13: 259343 | AH13: 4595 | AN13: 0
A15: 1 | B15: 6893.22 | C15: 259239 | D15: =C15-C13 -> -104 | E15: =C15-152000 -> 107239 | F15: =D15/$D$2 -> -52.432569 | G15: 55 | H15: 0 | I15: =G15+H15 -> 55 | J15: =IF(L15>0,L15,0) -> 0 | K15: =I15+J15 -> 55 | L15: =F15-(I15-AJ15) -> -17.232569 | M15: 5.2 | N15: 0 | O15: 0 | P15: 0 | Q15: =1.842*1.02 -> 1.87884 | R15: 2.55 | T15: =M15-(Q15+R15+S15) -> 0.77116 | U15: 46 | V15: 11 | W15: =M15-N15-P15-O15-Q15-R15-S15-T15+U15+V15 -> 57 | X15: =W15-AN15 -> 46 | AD15: 0 | AG15: 28 | AH15: =AH13-AG15 -> 4567 | AJ15: =N15+O15+P15+Q15+R15+S15+T15+W15+AD15+AG15 -> 90.2 | AK15: =IF(L15<0,L15*-1,0) -> 17.232569 | AL15: =AJ15+AK15 -> 107.43257 | AM15: =U15*1.9835 -> 91.241 | AN15: =V15 -> 11 | AT15: 0 | AU15: 0 | AV15: 61 | AW15: 28 | AY15: =SUM(N15,P15:T15) -> 5.2
A16: =A15+1 -> 2 | B16: 6893.19 | C16: 259134 | D16: =C16-C15 -> -105 | E16: =C16-152000 -> 107134 | F16: =D16/$D$2 -> -52.936728 | G16: 57 | H16: 0 | I16: =G16+H16 -> 57 | J16: =IF(L16>0,L16,0) -> 0 | K16: =I16+J16 -> 57 | L16: =F16-(I16-AJ16) -> -27.236728 | M16: 4.7 | N16: 0 | O16: 0 | P16: 0 | Q16: =1.842*1.02 -> 1.87884 | R16: 2.06 | T16: =M16-(Q16+R16+S16) -> 0.76116 | U16: 38 | V16: 12 | W16: =M16-N16-P16-O16-Q16-R16-S16-T16+U16+V16 -> 50 | X16: =W16-AN16 -> 38 | AD16: 0 | AG16: 28 | AH16: =AH15-AG16 -> 4539 | AJ16: =N16+O16+P16+Q16+R16+S16+T16+W16+AD16+AG16 -> 82.7 | AK16: =IF(L16<0,L16*-1,0) -> 27.236728 | AL16: =AJ16+AK16 -> 109.93673 | AM16: =AM15+(U16*1.9835) -> 166.614 | AN16: =V16 -> 12 | AT16: 0 | AU16: 0 | AV16: 64 | AW16: 34 | AY16: =SUM(N16,P16:T16) -> 4.7
A17: =A16+1 -> 3 | B17: 6893.15 | C17: 258994 | D17: =C17-C16 -> -140 | E17: =C17-152000 -> 106994 | F17: =D17/$D$2 -> -70.582304 | G17: 52 | H17: 0 | I17: =G17+H17 -> 52 | J17: =IF(L17>0,L17,0) -> 0 | K17: =I17+J17 -> 52 | L17: =F17-(I17-AJ17) -> -43.382304 | M17: 4.2 | N17: 0 | O17: 0 | P17: 0 | Q17: =1.842*1.02 -> 1.87884 | R17: 2.2 | T17: =M17-(Q17+R17+S17) -> 0.12116 | U17: 36 | V17: 12 | W17: =M17-N17-P17-O17-Q17-R17-S17-T17+U17+V17 -> 48 | X17: =W17-AN17 -> 36 | AD17: 0 | AG17: 27 | AH17: =AH16-AG17 -> 4512 | AJ17: =N17+O17+P17+Q17+R17+S17+T17+W17+AD17+AG17 -> 79.2 | AK17: =IF(L17<0,L17*-1,0) -> 43.382304 | AL17: =AJ17+AK17 -> 122.5823 | AM17: =AM16+(U17*1.9835) -> 238.02 | AN17: =V17 -> 12 | AT17: 0 | AU17: 0 | AV17: 64 | AW17: 32 | AY17: =SUM(N17,P17:T17) -> 4.2
A18: =A17+1 -> 4 | B18: 6893.11 | C18: 258854 | D18: =C18-C17 -> -140 | E18: =C18-152000 -> 106854 | F18: =D18/$D$2 -> -70.582304 | G18: 50 | H18: 0 | I18: =G18+H18 -> 50 | J18: =IF(L18>0,L18,0) -> 0 | K18: =I18+J18 -> 50 | L18: =F18-(I18-AJ18) -> -43.782304 | M18: 3.3 | N18: 0 | O18: 0 | P18: 0 | Q18: =1.842*1.02 -> 1.87884 | R18: 3.09 | T18: =M18-(Q18+R18+S18) -> -1.66884 | U18: 40 | V18: 5.5 | W18: =M18-N18-P18-O18-Q18-R18-S18-T18+U18+V18 -> 45.5 | X18: =W18-AN18 -> 40 | AD18: 0 | AG18: 28 | AH18: =AH17-AG18 -> 4484 | AJ18: =N18+O18+P18+Q18+R18+S18+T18+W18+AD18+AG18 -> 76.8 | AK18: =IF(L18<0,L18*-1,0) -> 43.782304 | AL18: =AJ18+AK18 -> 120.5823 | AM18: =AM17+(U18*1.9835) -> 317.36 | AN18: =V18 -> 5.5 | AT18: =6.16*1.05 -> 6.468 | AU18: 0 | AV18: 69 | AW18: 34 | AY18: =SUM(N18,P18:T18) -> 3.3
A19: =A18+1 -> 5 | B19: 6893.07 | C19: 258714 | D19: =C19-C18 -> -140 | E19: =C19-152000 -> 106714 | F19: =D19/$D$2 -> -70.582304 | G19: 50 | H19: 0 | I19: =G19+H19 -> 50 | J19: =IF(L19>0,L19,0) -> 0 | K19: =I19+J19 -> 50 | L19: =F19-(I19-AJ19) -> -48.782304 | M19: 2.8 | N19: 0 | O19: 0 | P19: 0 | Q19: =1.842*1.02 -> 1.87884 | R19: 3.52 | T19: =M19-(Q19+R19+S19) -> -2.59884 | U19: 41 | V19: 0 | W19: =M19-N19-P19-O19-Q19-R19-S19-T19+U19+V19 -> 41 | X19: =W19-AN19 -> 41 | AD19: 0 | AG19: 28 | AH19: =AH18-AG19 -> 4456 | AJ19: =N19+O19+P19+Q19+R19+S19+T19+W19+AD19+AG19 -> 71.8 | AK19: =IF(L19<0,L19*-1,0) -> 48.782304 | AL19: =AJ19+AK19 -> 120.5823 | AM19: =AM18+(U19*1.9835) -> 398.6835 | AN19: =V19 -> 0 | AT19: =4.87*1.05 -> 5.1135 | AU19: 0 | AV19: 67 | AW19: 37 | AY19: =SUM(N19,P19:T19) -> 2.8
A20: =A19+1 -> 6 | B20: 6893.04 | C20: 258609 | D20: =C20-C19 -> -105 | E20: =C20-152000 -> 106609 | F20: =D20/$D$2 -> -52.936728 | G20: 49 | H20: 0 | I20: =G20+H20 -> 49 | J20: =IF(L20>0,L20,0) -> 0 | K20: =I20+J20 -> 49 | L20: =F20-(I20-AJ20) -> -29.936728 | M20: 3 | N20: 0 | O20: 0 | P20: 0 | Q20: =1.842*1.02 -> 1.87884 | R20: 3.37 | T20: =M20-(Q20+R20+S20) -> -2.24884 | U20: 40 | V20: 0 | W20: =M20-N20-P20-O20-Q20-R20-S20-T20+U20+V20 -> 40 | X20: =W20-AN20 -> 40 | AD20: 0 | AG20: 29 | AH20: =AH19-AG20 -> 4427 | AJ20: =N20+O20+P20+Q20+R20+S20+T20+W20+AD20+AG20 -> 72 | AK20: =IF(L20<0,L20*-1,0) -> 29.936728 | AL20: =AJ20+AK20 -> 101.93673 | AM20: =AM19+(U20*1.9835) -> 478.0235 | AT20: =2.44*1.05 -> 2.562 | AU20: 0 | AV20: 65 | AW20: 38 | AY20: =SUM(N20,P20:T20) -> 3
A21: =A20+1 -> 7 | B21: 6893 | C21: 258469 | D21: =C21-C20 -> -140 | E21: =C21-152000 -> 106469 | F21: =D21/$D$2 -> -70.582304 | G21: 50 | H21: 0 | I21: =G21+H21 -> 50 | J21: =IF(L21>0,L21,0) -> 0 | K21: =I21+J21 -> 50 | L21: =F21-(I21-AJ21) -> -48.682304 | M21: 2.9 | N21: 0 | O21: 0 | P21: 0 | Q21: =1.842*1.02 -> 1.87884 | R21: 2.17 | T21: =M21-(Q21+R21+S21) -> -1.14884 | U21: 40 | V21: 0 | W21: =M21-N21-P21-O21-Q21-R21-S21-T21+U21+V21 -> 40 | X21: =W21-AN21 -> 40 | AD21: 0 | AG21: 29 | AH21: =AH20-AG21 -> 4398 | AJ21: =N21+O21+P21+Q21+R21+S21+T21+W21+AD21+AG21 -> 71.9 | AK21: =IF(L21<0,L21*-1,0) -> 48.682304 | AL21: =AJ21+AK21 -> 120.5823 | AM21: =AM20+(U21*1.9835) -> 557.3635 | AT21: =0.34*1.05 -> 0.357 | AU21: 0 | AV21: 66 | AW21: 38 | AY21: =SUM(N21,P21:T21) -> 2.9
A22: =A21+1 -> 8 | B22: 6892.96 | C22: 258330 | D22: =C22-C21 -> -139 | E22: =C22-152000 -> 106330 | F22: =D22/$D$2 -> -70.078145 | G22: 50 | H22: 0 | I22: =G22+H22 -> 50 | J22: =IF(L22>0,L22,0) -> 0 | K22: =I22+J22 -> 50 | L22: =F22-(I22-AJ22) -> -48.078145 | M22: 3 | N22: 0 | O22: 0 | P22: 0 | Q22: =1.842*1.02 -> 1.87884 | R22: 2.17 | T22: =M22-(Q22+R22+S22) -> -1.04884 | U22: 40 | V22: 0 | W22: =M22-N22-P22-O22-Q22-R22-S22-T22+U22+V22 -> 40 | X22: =W22-AN22 -> 40 | AD22: 0 | AG22: 29 | AH22: =AH21-AG22 -> 4369 | AJ22: =N22+O22+P22+Q22+R22+S22+T22+W22+AD22+AG22 -> 72 | AK22: =IF(L22<0,L22*-1,0) -> 48.078145 | AL22: =AJ22+AK22 -> 120.07814 | AM22: =AM21+(U22*1.9835) -> 636.7035 | AT22: 0 | AU22: 0 | AV22: 59 | AW22: 33 | AY22: =SUM(N22,P22:T22) -> 3
A23: =A22+1 -> 9 | B23: 6892.93 | C23: 258226 | D23: =C23-C22 -> -104 | E23: =C23-152000 -> 106226 | F23: =D23/$D$2 -> -52.432569 | G23: 48 | H23: 0 | I23: =G23+H23 -> 48 | J23: =IF(L23>0,L23,0) -> 0 | K23: =I23+J23 -> 48 | L23: =F23-(I23-AJ23) -> -24.432569 | M23: 4 | N23: 0 | O23: 0 | P23: 0 | Q23: =1.842*1.02 -> 1.87884 | R23: 1.73 | T23: 0 | U23: 44 | V23: 0 | W23: =M23-N23-P23-O23-Q23-R23-S23-T23+U23+V23 -> 44.39116 | X23: =W23-AN23 -> 44.39116 | AD23: 0 | AG23: 28 | AH23: =AH22-AG23 -> 4341 | AJ23: =N23+O23+P23+Q23+R23+S23+T23+W23+AD23+AG23 -> 76 | AK23: =IF(L23<0,L23*-1,0) -> 24.432569 | AL23: =AJ23+AK23 -> 100.43257 | AM23: =AM22+(U23*1.9835) -> 723.9775 | AT23: =6.45*1.05 -> 6.7725 | AU23: 0 | AV23: 61 | AW23: 33 | AY23: =SUM(N23,P23:T23) -> 3.60884
A24: =A23+1 -> 10 | B24: 6892.9 | C24: 258122 | D24: =C24-C23 -> -104 | E24: =C24-152000 -> 106122 | F24: =D24/$D$2 -> -52.432569 | G24: 47 | H24: 0 | I24: =G24+H24 -> 47 | J24: =IF(L24>0,L24,0) -> 0 | K24: =I24+J24 -> 47 | L24: =F24-(I24-AJ24) -> -21.932569 | M24: 3.5 | N24: 0 | O24: 0 | P24: 0 | Q24: =1.842*1.02 -> 1.87884 | R24: 2.43 | T24: 0 | U24: 46 | V24: 0 | W24: =M24-N24-P24-O24-Q24-R24-S24-T24+U24+V24 -> 45.19116 | X24: =W24-AN24 -> 45.19116 | AD24: 0 | AG24: 28 | AH24: =AH23-AG24 -> 4313 | AJ24: =N24+O24+P24+Q24+R24+S24+T24+W24+AD24+AG24 -> 77.5 | AK24: =IF(L24<0,L24*-1,0) -> 21.932569 | AL24: =AJ24+AK24 -> 99.432569 | AM24: =AM23+(U24*1.9835) -> 815.2185 | AT24: =11.4*1.05 -> 11.97 | AU24: 0 | AV24: 63 | AW24: 34 | AY24: =SUM(N24,P24:T24) -> 4.30884
A25: =A24+1 -> 11 | B25: 6892.87 | C25: 258018 | D25: =C25-C24 -> -104 | E25: =C25-152000 -> 106018 | F25: =D25/$D$2 -> -52.432569 | G25: 46 | H25: 0 | I25: =G25+H25 -> 46 | J25: =IF(L25>0,L25,0) -> 0 | K25: =I25+J25 -> 46 | L25: =F25-(I25-AJ25) -> -21.932569 | M25: 3.5 | N25: 0 | O25: 0 | P25: 0 | Q25: =1.842*1.02 -> 1.87884 | R25: 2.4 | T25: =M25-(Q25+R25+S25) -> -0.77884 | U25: 45 | V25: 0 | W25: =M25-N25-P25-O25-Q25-R25-S25-T25+U25+V25 -> 45 | X25: =W25-AN25 -> 45 | AD25: 0 | AG25: 28 | AH25: =AH24-AG25 -> 4285 | AJ25: =N25+O25+P25+Q25+R25+S25+T25+W25+AD25+AG25 -> 76.5 | AK25: =IF(L25<0,L25*-1,0) -> 21.932569 | AL25: =AJ25+AK25 -> 98.432569 | AM25: =AM24+(U25*1.9835) -> 904.476 | AT25: =16.8*1.05 -> 17.64 | AU25: 0 | AV25: 61 | AW25: 39 | AY25: =SUM(N25,P25:T25) -> 3.5
A26: =A25+1 -> 12 | B26: 6892.84 | C26: 257914 | D26: =C26-C25 -> -104 | E26: =C26-152000 -> 105914 | F26: =D26/$D$2 -> -52.432569 | G26: 47 | H26: 0 | I26: =G26+H26 -> 47 | J26: =IF(L26>0,L26,0) -> 0 | K26: =I26+J26 -> 47 | L26: =F26-(I26-AJ26) -> -22.732569 | M26: 3.7 | N26: 0 | O26: 0 | P26: 0 | Q26: =1.842*1.02 -> 1.87884 | R26: 2.13 | T26: =M26-(Q26+R26+S26) -> -0.30884 | U26: 45 | V26: 0 | W26: =M26-N26-P26-O26-Q26-R26-S26-T26+U26+V26 -> 45 | X26: =W26-AN26 -> 45 | AD26: 0 | AG26: 28 | AH26: =AH25-AG26 -> 4257 | AJ26: =N26+O26+P26+Q26+R26+S26+T26+W26+AD26+AG26 -> 76.7 | AK26: =IF(L26<0,L26*-1,0) -> 22.732569 | AL26: =AJ26+AK26 -> 99.432569 | AM26: =AM25+(U26*1.9835) -> 993.7335 | AT26: =7.18*1.05 -> 7.539 | AU26: 0 | AV26: 56 | AW26: 47 | AY26: =SUM(N26,P26:T26) -> 3.7
A27: =A26+1 -> 13 | B27: 6892.83 | C27: 257880 | D27: =C27-C26 -> -34 | E27: =C27-152000 -> 105880 | F27: =D27/$D$2 -> -17.141417 | G27: 56 | H27: 0 | I27: =G27+H27 -> 56 | J27: =IF(L27>0,L27,0) -> 2.9585833 | K27: =I27+J27 -> 58.958583 | L27: =F27-(I27-AJ27) -> 2.9585833 | M27: 3.1 | N27: 0 | O27: 0 | P27: 0 | Q27: =1.842*1.02 -> 1.87884 | R27: 2.06 | T27: =M27-(Q27+R27+S27) -> -0.83884 | U27: 45 | V27: 0 | W27: =M27-N27-P27-O27-Q27-R27-S27-T27+U27+V27 -> 45 | X27: =W27-AN27 -> 45 | AD27: 0 | AG27: 28 | AH27: =AH26-AG27 -> 4229 | AJ27: =N27+O27+P27+Q27+R27+S27+T27+W27+AD27+AG27 -> 76.1 | AK27: =IF(L27<0,L27*-1,0) -> 0 | AL27: =AJ27+AK27 -> 76.1 | AM27: =AM26+(U27*1.9835) -> 1082.991 | AT27: 0 | AU27: 0.21 | AV27: 49 | AW27: 35 | AY27: =SUM(N27,P27:T27) -> 3.1
A28: =A27+1 -> 14 | B28: 6892.82 | C28: 257845 | D28: =C28-C27 -> -35 | E28: =C28-152000 -> 105845 | F28: =D28/$D$2 -> -17.645576 | G28: 67 | H28: 0 | I28: =G28+H28 -> 67 | J28: =IF(L28>0,L28,0) -> 0 | K28: =I28+J28 -> 67 | L28: =F28-(I28-AJ28) -> -7.945576 | M28: 2.7 | N28: 0 | O28: 0 | P28: 0 | Q28: =1.842*1.02 -> 1.87884 | R28: 2.23 | T28: =M28-(Q28+R28+S28) -> -1.40884 | U28: 45 | V28: 0 | W28: =M28-N28-P28-O28-Q28-R28-S28-T28+U28+V28 -> 45 | X28: =W28-AN28 -> 45 | AD28: 0 | AG28: 29 | AH28: =AH27-AG28 -> 4200 | AJ28: =N28+O28+P28+Q28+R28+S28+T28+W28+AD28+AG28 -> 76.7 | AK28: =IF(L28<0,L28*-1,0) -> 7.945576 | AL28: =AJ28+AK28 -> 84.645576 | AM28: =AM27+(U28*1.9835) -> 1172.2485 | AT28: 0 | AU28: 0.05 | AV28: 38 | AW28: 25 | AY28: =SUM(N28,P28:T28) -> 2.7
A29: =A28+1 -> 15 | B29: 6892.81 | C29: 257810 | D29: =C29-C28 -> -35 | E29: =C29-152000 -> 105810 | F29: =D29/$D$2 -> -17.645576 | G29: 57 | H29: 0 | I29: =G29+H29 -> 57 | J29: =IF(L29>0,L29,0) -> 2.954424 | K29: =I29+J29 -> 59.954424 | L29: =F29-(I29-AJ29) -> 2.954424 | M29: 3.6 | N29: 0 | O29: 0 | P29: 0 | Q29: =1.842*1.02 -> 1.87884 | R29: 2.13 | T29: =M29-(Q29+R29+S29) -> -0.40884 | U29: 45 | V29: 0 | W29: =M29-N29-P29-O29-Q29-R29-S29-T29+U29+V29 -> 45 | X29: =W29-AN29 -> 45 | AD29: 0 | AG29: 29 | AH29: =AH28-AG29 -> 4171 | AJ29: =N29+O29+P29+Q29+R29+S29+T29+W29+AD29+AG29 -> 77.6 | AK29: =IF(L29<0,L29*-1,0) -> 0 | AL29: =AJ29+AK29 -> 77.6 | AM29: =AM28+(U29*1.9835) -> 1261.506 | AT29: 0 | AU29: 0.03 | AV29: 33 | AW29: 14 | AY29: =SUM(N29,P29:T29) -> 3.6
A30: =A29+1 -> 16 | B30: 6892.79 | C30: 257741 | D30: =C30-C29 -> -69 | E30: =C30-152000 -> 105741 | F30: =D30/$D$2 -> -34.786993 | G30: 51 | H30: 0 | I30: =G30+H30 -> 51 | J30: =IF(L30>0,L30,0) -> 0 | K30: =I30+J30 -> 51 | L30: =F30-(I30-AJ30) -> -9.1869927 | M30: 3.6 | N30: 0 | O30: 0 | P30: 0 | Q30: =1.842*1.02 -> 1.87884 | R30: 2.3 | T30: =M30-(Q30+R30+S30) -> -0.57884 | U30: 45 | V30: 0 | W30: =M30-N30-P30-O30-Q30-R30-S30-T30+U30+V30 -> 45 | X30: =W30-AN30 -> 45 | AD30: 0 | AG30: 28 | AH30: =AH29-AG30 -> 4143 | AJ30: =N30+O30+P30+Q30+R30+S30+T30+W30+AD30+AG30 -> 76.6 | AK30: =IF(L30<0,L30*-1,0) -> 9.1869927 | AL30: =AJ30+AK30 -> 85.786993 | AM30: =AM29+(U30*1.9835) -> 1350.7635 | AU30: 0.05 | AV30: 39 | AW30: 13 | AY30: =SUM(N30,P30:T30) -> 3.6
A31: =A30+1 -> 17 | B31: 6892.78 | C31: 257706 | D31: =C31-C30 -> -35 | E31: =C31-152000 -> 105706 | F31: =D31/$D$2 -> -17.645576 | G31: 46 | H31: 0 | I31: =G31+H31 -> 46 | J31: =IF(L31>0,L31,0) -> 12.354424 | K31: =I31+J31 -> 58.354424 | L31: =F31-(I31-AJ31) -> 12.354424 | M31: 3 | N31: 0 | O31: 0 | P31: 0 | Q31: =1.842*1.02 -> 1.87884 | R31: 2.2 | T31: =M31-(Q31+R31+S31) -> -1.07884 | U31: 45 | V31: 0 | W31: =M31-N31-P31-O31-Q31-R31-S31-T31+U31+V31 -> 45 | X31: =W31-AN31 -> 45 | AD31: 0 | AG31: 28 | AH31: =AH30-AG31 -> 4115 | AJ31: =N31+O31+P31+Q31+R31+S31+T31+W31+AD31+AG31 -> 76 | AK31: =IF(L31<0,L31*-1,0) -> 0 | AL31: =AJ31+AK31 -> 76 | AM31: =AM30+(U31*1.9835) -> 1440.021 | AU31: 0 | AV31: 46 | AW31: 20 | AY31: =SUM(N31,P31:T31) -> 3
A32: =A31+1 -> 18 | B32: 6892.76 | C32: 257637 | D32: =C32-C31 -> -69 | E32: =C32-152000 -> 105637 | F32: =D32/$D$2 -> -34.786993 | G32: 42 | H32: 0 | I32: =G32+H32 -> 42 | J32: =IF(L32>0,L32,0) -> 3.8130073 | K32: =I32+J32 -> 45.813007 | L32: =F32-(I32-AJ32) -> 3.8130073 | M32: 2.6 | N32: 0 | O32: 0 | P32: 0 | Q32: =1.842*1.02 -> 1.87884 | R32: 2.03 | T32: =M32-(Q32+R32+S32) -> -1.30884 | U32: 45 | V32: 0 | W32: =M32-N32-P32-O32-Q32-R32-S32-T32+U32+V32 -> 45 | X32: =W32-AN32 -> 45 | AD32: 0 | AG32: 33 | AH32: =AH31-AG32 -> 4082 | AJ32: =N32+O32+P32+Q32+R32+S32+T32+W32+AD32+AG32 -> 80.6 | AK32: =IF(L32<0,L32*-1,0) -> 0 | AL32: =AJ32+AK32 -> 80.6 | AM32: =AM31+(U32*1.9835) -> 1529.2785 | AU32: 0 | AV32: 50 | AW32: 25 | AY32: =SUM(N32,P32:T32) -> 2.6
A33: =A32+1 -> 19 | B33: 6892.74 | C33: 257568 | D33: =C33-C32 -> -69 | E33: =C33-152000 -> 105568 | F33: =D33/$D$2 -> -34.786993 | G33: 38 | H33: 0 | I33: =G33+H33 -> 38 | J33: =IF(L33>0,L33,0) -> 4.1130073 | K33: =I33+J33 -> 42.113007 | L33: =F33-(I33-AJ33) -> 4.1130073 | M33: 3.9 | N33: 0 | O33: 0 | P33: 0 | Q33: =1.842*1.02 -> 1.87884 | R33: 1.88 | T33: =M33-(Q33+R33+S33) -> 0.14116 | U33: 45 | V33: 0 | W33: =M33-N33-P33-O33-Q33-R33-S33-T33+U33+V33 -> 45 | X33: =W33-AN33 -> 45 | AD33: 0 | AG33: 28 | AH33: =AH32-AG33 -> 4054 | AJ33: =N33+O33+P33+Q33+R33+S33+T33+W33+AD33+AG33 -> 76.9 | AK33: =IF(L33<0,L33*-1,0) -> 0 | AL33: =AJ33+AK33 -> 76.9 | AM33: =AM32+(U33*1.9835) -> 1618.536 | AU33: 0 | AV33: 52 | AW33: 25 | AY33: =SUM(N33,P33:T33) -> 3.9
A34: =A33+1 -> 20 | B34: 6892.72 | C34: 257498 | D34: =C34-C33 -> -70 | E34: =C34-152000 -> 105498 | F34: =D34/$D$2 -> -35.291152 | G34: 34 | H34: 0 | I34: =G34+H34 -> 34 | J34: =IF(L34>0,L34,0) -> 8.908848 | K34: =I34+J34 -> 42.908848 | L34: =F34-(I34-AJ34) -> 8.908848 | M34: 5.2 | N34: 0 | O34: 0 | P34: 0 | Q34: =1.842*1.02 -> 1.87884 | R34: 2.24 | T34: =M34-(Q34+R34+S34) -> 1.08116 | U34: 45 | V34: 0 | W34: =M34-N34-P34-O34-Q34-R34-S34-T34+U34+V34 -> 45 | X34: =W34-AN34 -> 45 | AD34: 0 | AG34: 28 | AH34: =AH33-AG34 -> 4026 | AJ34: =N34+O34+P34+Q34+R34+S34+T34+W34+AD34+AG34 -> 78.2 | AK34: =IF(L34<0,L34*-1,0) -> 0 | AL34: =AJ34+AK34 -> 78.2 | AM34: =AM33+(U34*1.9835) -> 1707.7935 | AU34: 0 | AV34: 52 | AW34: 25 | AY34: =SUM(N34,P34:T34) -> 5.2
A35: =A34+1 -> 21 | B35: 6892.7 | C35: 257429 | D35: =C35-C34 -> -69 | E35: =C35-152000 -> 105429 | F35: =D35/$D$2 -> -34.786993 | G35: 32 | H35: 0 | I35: =G35+H35 -> 32 | J35: =IF(L35>0,L35,0) -> 10.513007 | K35: =I35+J35 -> 42.513007 | L35: =F35-(I35-AJ35) -> 10.513007 | M35: 4.3 | N35: 0 | O35: 0 | P35: 0 | Q35: =1.842*1.02 -> 1.87884 | R35: 2.2 | T35: =M35-(Q35+R35+S35) -> 0.22116 | U35: 45 | V35: 0 | W35: =M35-N35-P35-O35-Q35-R35-S35-T35+U35+V35 -> 45 | X35: =W35-AN35 -> 45 | AD35: 0 | AG35: 28 | AH35: =AH34-AG35 -> 3998 | AJ35: =N35+O35+P35+Q35+R35+S35+T35+W35+AD35+AG35 -> 77.3 | AK35: =IF(L35<0,L35*-1,0) -> 0 | AL35: =AJ35+AK35 -> 77.3 | AM35: =AM34+(U35*1.9835) -> 1797.051 | AU35: 0 | AV35: 52 | AW35: 28 | AY35: =SUM(N35,P35:T35) -> 4.3
A36: =A35+1 -> 22 | B36: 6892.68 | C36: 257360 | D36: =C36-C35 -> -69 | E36: =C36-152000 -> 105360 | F36: =D36/$D$2 -> -34.786993 | G36: 29 | H36: 0 | I36: =G36+H36 -> 29 | J36: =IF(L36>0,L36,0) -> 12.713007 | K36: =I36+J36 -> 41.713007 | L36: =F36-(I36-AJ36) -> 12.713007 | M36: 3.5 | N36: 0 | O36: 0 | P36: 0 | Q36: =1.842*1.02 -> 1.87884 | R36: 2.21 | T36: =M36-(Q36+R36+S36) -> -0.58884 | U36: 45 | V36: 0 | W36: =M36-N36-P36-O36-Q36-R36-S36-T36+U36+V36 -> 45 | X36: =W36-AN36 -> 45 | AD36: 0 | AG36: 28 | AH36: =AH35-AG36 -> 3970 | AJ36: =N36+O36+P36+Q36+R36+S36+T36+W36+AD36+AG36 -> 76.5 | AK36: =IF(L36<0,L36*-1,0) -> 0 | AL36: =AJ36+AK36 -> 76.5 | AM36: =AM35+(U36*1.9835) -> 1886.3085 | AU36: 0 | AV36: 48 | AW36: 24 | AY36: =SUM(N36,P36:T36) -> 3.5
A37: =A36+1 -> 23 | B37: 6892.64 | C37: 257221 | D37: =C37-C36 -> -139 | E37: =C37-152000 -> 105221 | F37: =D37/$D$2 -> -70.078145 | G37: 28 | H37: 0 | I37: =G37+H37 -> 28 | J37: =IF(L37>0,L37,0) -> 0 | K37: =I37+J37 -> 28 | L37: =F37-(I37-AJ37) -> -11.778145 | M37: 3.3 | N37: 0 | O37: 0 | P37: 0 | Q37: =1.842*1.02 -> 1.87884 | R37: 2.27 | T37: =M37-(Q37+R37+S37) -> -0.84884 | U37: 55 | V37: 0 | W37: =M37-N37-P37-O37-Q37-R37-S37-T37+U37+V37 -> 55 | X37: =W37-AN37 -> 55 | AD37: 0 | AG37: 28 | AH37: =AH36-AG37 -> 3942 | AJ37: =N37+O37+P37+Q37+R37+S37+T37+W37+AD37+AG37 -> 86.3 | AK37: =IF(L37<0,L37*-1,0) -> 11.778145 | AL37: =AJ37+AK37 -> 98.078145 | AM37: =AM36+(U37*1.9835) -> 1995.401 | AU37: 0 | AV37: 38 | AW37: 22 | AY37: =SUM(N37,P37:T37) -> 3.3
A38: =A37+1 -> 24 | B38: 6892.6 | C38: 257083 | D38: =C38-C37 -> -138 | E38: =C38-152000 -> 105083 | F38: =D38/$D$2 -> -69.573985 | G38: 27 | H38: 0 | I38: =G38+H38 -> 27 | J38: =IF(L38>0,L38,0) -> 0 | K38: =I38+J38 -> 27 | L38: =F38-(I38-AJ38) -> -4.1739854 | M38: 3.4 | N38: 0 | O38: 0 | P38: 0 | Q38: =1.842*1.02 -> 1.87884 | R38: 2.17 | T38: =M38-(Q38+R38+S38) -> -0.64884 | U38: 61 | V38: 0 | W38: =M38-N38-P38-O38-Q38-R38-S38-T38+U38+V38 -> 61 | X38: =W38-AN38 -> 61 | AD38: 0 | AG38: 28 | AH38: =AH37-AG38 -> 3914 | AJ38: =N38+O38+P38+Q38+R38+S38+T38+W38+AD38+AG38 -> 92.4 | AK38: =IF(L38<0,L38*-1,0) -> 4.1739854 | AL38: =AJ38+AK38 -> 96.573985 | AM38: =AM37+(U38*1.9835) -> 2116.3945 | AU38: 0 | AV38: 44 | AW38: 18 | AY38: =SUM(N38,P38:T38) -> 3.4
A39: =A38+1 -> 25 | B39: 6892.56 | C39: 256944 | D39: =C39-C38 -> -139 | E39: =C39-152000 -> 104944 | F39: =D39/$D$2 -> -70.078145 | G39: 24 | H39: 0 | I39: =G39+H39 -> 24 | J39: =IF(L39>0,L39,0) -> 0 | K39: =I39+J39 -> 24 | L39: =F39-(I39-AJ39) -> -1.5781447 | M39: 3.5 | N39: 0 | O39: 0 | P39: 0 | Q39: =1.842*1.02 -> 1.87884 | R39: 2.21 | T39: =M39-(Q39+R39+S39) -> -0.58884 | U39: 61 | V39: 0 | W39: =M39-N39-P39-O39-Q39-R39-S39-T39+U39+V39 -> 61 | X39: =W39-AN39 -> 61 | AD39: 0 | AG39: 28 | AH39: =AH38-AG39 -> 3886 | AJ39: =N39+O39+P39+Q39+R39+S39+T39+W39+AD39+AG39 -> 92.5 | AK39: =IF(L39<0,L39*-1,0) -> 1.5781447 | AL39: =AJ39+AK39 -> 94.078145 | AM39: =AM38+(U39*1.9835) -> 2237.388 | AU39: 0 | AV39: 49 | AW39: 19 | AY39: =SUM(N39,P39:T39) -> 3.5
A40: =A39+1 -> 26 | B40: 6892.52 | C40: 256805 | D40: =C40-C39 -> -139 | E40: =C40-152000 -> 104805 | F40: =D40/$D$2 -> -70.078145 | G40: 23 | H40: 0 | I40: =G40+H40 -> 23 | J40: =IF(L40>0,L40,0) -> 0 | K40: =I40+J40 -> 23 | L40: =F40-(I40-AJ40) -> -0.87814469 | M40: 4.2 | N40: 0 | O40: 0 | P40: 0 | Q40: =1.842*1.02 -> 1.87884 | R40: 2.05 | T40: =M40-(Q40+R40+S40) -> 0.27116 | U40: 60 | V40: 0 | W40: =M40-N40-P40-O40-Q40-R40-S40-T40+U40+V40 -> 60 | X40: =W40-AN40 -> 60 | AD40: 0 | AG40: 28 | AH40: =AH39-AG40 -> 3858 | AJ40: =N40+O40+P40+Q40+R40+S40+T40+W40+AD40+AG40 -> 92.2 | AK40: =IF(L40<0,L40*-1,0) -> 0.87814469 | AL40: =AJ40+AK40 -> 93.078145 | AM40: =AM39+(U40*1.9835) -> 2356.398 | AU40: 0 | AV40: 55 | AW40: 25 | AY40: =SUM(N40,P40:T40) -> 4.2
A41: =A40+1 -> 27 | B41: 6892.48 | C41: 256667 | D41: =C41-C40 -> -138 | E41: =C41-152000 -> 104667 | F41: =D41/$D$2 -> -69.573985 | G41: 23 | H41: 0 | I41: =G41+H41 -> 23 | J41: =IF(L41>0,L41,0) -> 0 | K41: =I41+J41 -> 23 | L41: =F41-(I41-AJ41) -> -0.97398538 | M41: 3.6 | N41: 0 | O41: 0 | P41: 0 | Q41: =1.842*1.02 -> 1.87884 | R41: 1.88 | T41: =M41-(Q41+R41+S41) -> -0.15884 | U41: 60 | V41: 0 | W41: =M41-N41-P41-O41-Q41-R41-S41-T41+U41+V41 -> 60 | X41: =W41-AN41 -> 60 | AD41: 0 | AG41: 28 | AH41: =AH40-AG41 -> 3830 | AJ41: =N41+O41+P41+Q41+R41+S41+T41+W41+AD41+AG41 -> 91.6 | AK41: =IF(L41<0,L41*-1,0) -> 0.97398538 | AL41: =AJ41+AK41 -> 92.573985 | AM41: =AM40+(U41*1.9835) -> 2475.408 | AU41: 0 | AV41: 54 | AW41: 26 | AY41: =SUM(N41,P41:T41) -> 3.6
... A43: =A42+1 -> 29 | B43: 6892.4 | C43: 256389 | D43: =C43-C42 -> -139 | E43: =C43-152000 -> 104389 | F43: =D43/$D$2 -> -70.078145 | G43: 24 | H43: 0 | I43: =G43+H43 -> 24 | J43: =IF(L43>0,L43,0) -> 0 | K43: =I43+J43 -> 24 | L43: =F43-(I43-AJ43) -> -3.6781447 | M43: 2.4 | N43: 0 | O43: 0 | P43: 0 | Q43: =1.842*1.02 -> 1.87884 | R43: 2.24 | T43: =M43-(Q43+R43+S43) -> -1.71884 | U43: 60 | V43: 0 | W43: =M43-N43-P43-O43-Q43-R43-S43-T43+U43+V43 -> 60 | X43: =W43-AN43 -> 60 | AD43: 0 | AG43: 28 | AH43: =AH42-AG43 -> 3774 | AJ43: =N43+O43+P43+Q43+R43+S43+T43+W43+AD43+AG43 -> 90.4 | AK43: =IF(L43<0,L43*-1,0) -> 3.6781447 | AL43: =AJ43+AK43 -> 94.078145 | AM43: =AM42+(U43*1.9835) -> 2713.428 | AU43: 0.1 | AV43: 45 | AW43: 24 | AY43: =SUM(N43,P43:T43) -> 2.4
...

Sheet DEC
K1: MCPHEE RESERVOIR INFLOW/OUTFLOW TABULATION
A2: AF/cfs CONVERT FACTOR | D2: 1.9835 | K2: DECEMBER "2009"
D4: RESERVOIR | W4: INFLOW/OUTFLOW (CFS) | AO4: ADJUSTMENTS | AV4: WEATHER
A5: DATE | B5: RESERV | C5: RESERV | D5: AC FT | E5: ACTIVE | F5: CONV TO | G5: DOLORES | H5: LOST | I5: RECORD | J5: CALC | K5: TOTAL | L5: CALC | M5: DOLORES TUNNEL | U5: LONE | V5: U | W5: TOTAL | X5: TOTAL | Y5: MVI | Z5: MVI | AA5: MVI | AB5: TO EX & | AC5: MVI | AD5: DV CR | AE5: D/S SENIOR | AG5: BELOW | AH5: FISH | AI5: SPILL | AJ5: RECORD | AK5: CALC | AL5: TOTAL | AM5: NAR | AN5: MVI | AO5: MVI | AP5: MVI | AQ5: DIST. | AR5: U/S | AS5: TOTTEN | AT5: UTES | AU5: RAIN | AV5: MAX | AW5: MIN | AY5: TOTAL
A6: DEC | B6: ELEV | D6: CHANGE | E6: CAP | F6: CFS | G6: RIVER | H6: CAN | I6: INFLOW | J6: INFLOW | K6: INFLOW | L6: INF/OTF | M6: TOT DIV | N6: WET | O6: UTE | P6: QUEST | Q6: MWC | R6: CTZ | S6: CTZ & | T6: F-BAY | U6: PINE | V6: LAT | W6: MVI | X6: MVI | Y6: CALL | Z6: CALL | AA6: APR- | AB6: U/S EX | AC6: PROJ | AD6: CANAL | AE6: MVIC | AF6: PROJ | AG6: MCP | AH6: LEFT | AJ6: OTF | AK6: OTF | AL6: OTF | AM6: FILLL | AN6: STOCK | AO6: STORED | AP6: STORED | AQ6: CLASS | AR6: USERS | AS6: (FRESH | AT6: FROM | AV6: TMP | AW6: TMP | AY6: TUNNEL
N7: LAND | O7: F&R | S7: UTE | T7: SPILL | W7: WATER | X7: IRRIG. | Y7: STOR | Z7: SPILLED | AA7: JUNE | AE7: 1.7 | AF7: 1.3 | AO7: Apr - Jun | AP7: EVAP | AQ7: "B" | AR7: EXCH | AS7: WATER) | AT7: DWCD | AY7: Misc.
W8: USED | X8: WATER | Z8: OR | AA8: (DIV+
X9: USED | Z9: USED | AA9: CALL)
C10: AC. Ft. | E10: AC FT | G10: CFS | H10: CFS | I10: CFS | J10: CFS | K10: CFS | L10: CFS | M10: CFS | N10: CFS | O10: CFS | P10: CFS | Q10: CFS | R10: CFS | S10: PROJ | T10: CFS | U10: CFS | V10: CFS | W10: 153400 | X10: 150400 | AA10: 72000 | AB10: CFS | AC10: CFS | AD10: CFS | AE10: CFS | AF10: CFS | AG10: CFS | AH10: CFS | AI10: CFS | AJ10: CFS | AK10: CFS | AL10: CFS | AM10: AC FT | AN10: CFS | AO10: CFS | AP10: AC.FT. | AQ10: CFS | AR10: CFS | AS10: CFS | AT10: CFS | AY10: Outflow
N11: 1.03 | O11: 1.05 | P11: 1.02 | Q11: 1.02 | R11: 1.04 | S11: CFS | W11: CFS | X11: CFS | Y11: CFS | Z11: CFS | AA11: Ac. Ft. | AY11: CFS
A12: SEASON BAL
A13: YTD | B13: =NOV!B44 -> 6892.38 | C13: =NOV!C44 -> 256320 | D13: =NOV!D53 -> -3023 | E13: =NOV!E53 -> 104320 | F13: =NOV!F52 -> -1524.0736 | G13: =NOV!G52 -> 1249 | H13: =NOV!H52 -> 0 | I13: =NOV!I52 -> 1249 | J13: =NOV!J52 -> 63.941316 | K13: =NOV!K52 -> 1312.9413 | L13: =NOV!L52 -> -376.67361 | M13: =NOV!M52 -> 105.9 | ... O13: =NOV!O52 -> 0 | Q13: =NOV!Q52 -> 56.3652 | R13: =NOV!R52 -> 67.99 | S13: =NOV!S52 -> 0 | T13: =NOV!T52 -> -18.80868 | U13: =NOV!U52 -> 1401 | V13: =NOV!V52 -> 40.5 | W13: =NOV!W52 -> 1441.0823 | X13: =NOV!X52 -> 1400.5823 | AG13: =NOV!AG52 -> 849 | AH13: =NOV!AH52 -> 3746 | AJ13: =NOV!AJ52 -> 2396.4 | AK13: =NOV!AK52 -> 440.61492 | AL13: =NOV!AL52 -> 2837.0149 | AM13: =NOV!AM53 -> 2778.8835 | AN13: =NOV!AN52 -> 40.5 | AU13: =NOV!AU52 -> 0.46 | AY13: =NOV!AY52 -> 106.31768
A15: 1 | B15: 6892.36 | C15: 256251 | D15: =C15-C13 -> -69 | E15: =C15-152000 -> 104251 | F15: =D15/$D$2 -> -34.786993 | G15: 24 | H15: 0 | I15: =G15+H15 -> 24 | J15: =IF(L15>0,L15,0) -> 0 | K15: =I15+J15 -> 24 | L15: =F15-(I15-AJ15) -> -8.3869927 | M15: 4.4 | N15: 0 | O15: 0 | P15: 0 | Q15: =1.6*1.02 -> 1.632 | R15: 2.25 | S15: 0 | T15: =M15-(Q15+R15+S15) -> 0.518 | U15: 18 | V15: 0 | W15: =M15-N15-O15-P15-Q15-R15-S15-T15+U15+V15 -> 18 | X15: =W15-AN15 -> 18 | AD15: 0 | AG15: 28 | AH15: =AH13-AG15 -> 3718 | AJ15: =N15+O15+P15+Q15+R15+S15+T15+W15+AD15+AG15 -> 50.4 | AK15: =IF(L15<0,L15*-1,0) -> 8.3869927 | AL15: =AJ15+AK15 -> 58.786993 | AM15: =AM13+(W15*1.9835) -> 2814.5865 | AN15: 0 | AU15: 0 | AV15: 47 | AW15: 23 | AY15: =SUM(N15,P15:T15) -> 4.4
A16: =A15+1 -> 2 | B16: 6892.34 | C16: 256181 | D16: =C16-C15 -> -70 | E16: =C16-152000 -> 104181 | F16: =D16/$D$2 -> -35.291152 | G16: 24 | H16: 0 | I16: =G16+H16 -> 24 | J16: =IF(L16>0,L16,0) -> 0 | K16: =I16+J16 -> 24 | L16: =F16-(I16-AJ16) -> -8.791152 | M16: 3.5 | N16: 0 | O16: 0 | P16: 0 | Q16: =1.6*1.02 -> 1.632 | R16: 2.15 | S16: 0 | T16: =M16-(Q16+R16+S16) -> -0.282 | U16: 19 | V16: 0 | W16: =M16-N16-O16-P16-Q16-R16-S16-T16+U16+V16 -> 19 | X16: =W16-AN16 -> 19 | AD16: 0 | AG16: 28 | AH16: =AH15-AG16 -> 3690 | AJ16: =N16+O16+P16+Q16+R16+S16+T16+W16+AD16+AG16 -> 50.5 | AK16: =IF(L16<0,L16*-1,0) -> 8.791152 | AL16: =AJ16+AK16 -> 59.291152 | AM16: =AM15+(W16*1.9835) -> 2852.273 | AN16: 0 | AU16: 0 | AV16: 41 | AW16: 21 | AY16: =SUM(N16,P16:T16) -> 3.5
A17: =A16+1 -> 3 | B17: 6892.32 | C17: 256112 | D17: =C17-C16 -> -69 | E17: =C17-152000 -> 104112 | F17: =D17/$D$2 -> -34.786993 | G17: 24 | H17: 0 | I17: =G17+H17 -> 24 | J17: =IF(L17>0,L17,0) -> 0 | K17: =I17+J17 -> 24 | L17: =F17-(I17-AJ17) -> -8.2869927 | M17: 3.5 | N17: 0 | O17: 0 | P17: 0 | Q17: =1.6*1.02 -> 1.632 | R17: 2.11 | S17: 0 | T17: =M17-(Q17+R17+S17) -> -0.242 | U17: 19 | V17: 0 | W17: =M17-N17-O17-P17-Q17-R17-S17-T17+U17+V17 -> 19 | X17: =W17-AN17 -> 19 | AD17: 0 | AG17: 28 | AH17: =AH16-AG17 -> 3662 | AJ17: =N17+O17+P17+Q17+R17+S17+T17+W17+AD17+AG17 -> 50.5 | AK17: =IF(L17<0,L17*-1,0) -> 8.2869927 | AL17: =AJ17+AK17 -> 58.786993 | AM17: =AM16+(W17*1.9835) -> 2889.9595 | AN17: 0 | AU17: 0 | AV17: 27 | AW17: 8 | AY17: =SUM(N17,P17:T17) -> 3.5
A18: =A17+1 -> 4 | B18: 6892.3 | C18: 256043 | D18: =C18-C17 -> -69 | E18: =C18-152000 -> 104043 | F18: =D18/$D$2 -> -34.786993 | G18: 24 | H18: 0 | I18: =G18+H18 -> 24 | J18: =IF(L18>0,L18,0) -> 0 | K18: =I18+J18 -> 24 | L18: =F18-(I18-AJ18) -> -8.1869927 | M18: 3.6 | N18: 0 | O18: 0 | P18: 0 | Q18: =1.6*1.02 -> 1.632 | R18: 2.38 | S18: 0 | T18: =M18-(Q18+R18+S18) -> -0.412 | U18: 19 | V18: 0 | W18: =M18-N18-O18-P18-Q18-R18-S18-T18+U18+V18 -> 19 | X18: =W18-AN18 -> 19 | AD18: 0 | AG18: 28 | AH18: =AH17-AG18 -> 3634 | AJ18: =N18+O18+P18+Q18+R18+S18+T18+W18+AD18+AG18 -> 50.6 | AK18: =IF(L18<0,L18*-1,0) -> 8.1869927 | AL18: =AJ18+AK18 -> 58.786993 | AM18: =AM17+(W18*1.9835) -> 2927.646 | AN18: 0 | AU18: 0 | AV18: 33 | AW18: 6 | AY18: =SUM(N18,P18:T18) -> 3.6
A19: =A18+1 -> 5 | B19: 6892.28 | C19: 255973 | D19: =C19-C18 -> -70 | E19: =C19-152000 -> 103973 | F19: =D19/$D$2 -> -35.291152 | G19: 24 | H19: 0 | I19: =G19+H19 -> 24 | J19: =IF(L19>0,L19,0) -> 0 | K19: =I19+J19 -> 24 | L19: =F19-(I19-AJ19) -> -8.691152 | M19: 3.6 | N19: 0 | O19: 0 | P19: 0 | Q19: =1.6*1.02 -> 1.632 | R19: 2.04 | S19: 0 | T19: =M19-(Q19+R19+S19) -> -0.072 | U19: 19 | V19: 0 | W19: =M19-N19-O19-P19-Q19-R19-S19-T19+U19+V19 -> 19 | X19: =W19-AN19 -> 19 | AD19: 0 | AG19: 28 | AH19: =AH18-AG19 -> 3606 | AJ19: =N19+O19+P19+Q19+R19+S19+T19+W19+AD19+AG19 -> 50.6 | AK19: =IF(L19<0,L19*-1,0) -> 8.691152 | AL19: =AJ19+AK19 -> 59.291152 | AM19: =AM18+(W19*1.9835) -> 2965.3325 | AN19: 0 | AU19: 0 | AV19: 35 | AW19: 14 | AY19: =SUM(N19,P19:T19) -> 3.6
A20: =A19+1 -> 6 | B20: 6892.26 | C20: 255904 | D20: =C20-C19 -> -69 | E20: =C20-152000 -> 103904 | F20: =D20/$D$2 -> -34.786993 | G20: 24 | H20: 0 | I20: =G20+H20 -> 24 | J20: =IF(L20>0,L20,0) -> 0 | K20: =I20+J20 -> 24 | L20: =F20-(I20-AJ20) -> -8.3869927 | M20: 3.4 | N20: 0 | O20: 0 | P20: 0 | Q20: =1.6*1.02 -> 1.632 | R20: 2.07 | S20: 0 | T20: =M20-(Q20+R20+S20) -> -0.302 | U20: 19 | V20: 0 | W20: =M20-N20-O20-P20-Q20-R20-S20-T20+U20+V20 -> 19 | X20: =W20-AN20 -> 19 | AD20: 0 | AG20: 28 | AH20: =AH19-AG20 -> 3578 | AJ20: =N20+O20+P20+Q20+R20+S20+T20+W20+AD20+AG20 -> 50.4 | AK20: =IF(L20<0,L20*-1,0) -> 8.3869927 | AL20: =AJ20+AK20 -> 58.786993 | AM20: =AM19+(W20*1.9835) -> 3003.019 | AN20: 0 | AU20: 0 | AV20: 33 | AW20: 22 | AY20: =SUM(N20,P20:T20) -> 3.4
A21: =A20+1 -> 7 | B21: 6892.21 | C21: 255731 | D21: =C21-C20 -> -173 | E21: =C21-152000 -> 103731 | F21: =D21/$D$2 -> -87.219561 | G21: 24 | H21: 0 | I21: =G21+H21 -> 24 | J21: =IF(L21>0,L21,0) -> 0.48043862 | K21: =I21+J21 -> 24.480439 | L21: =F21-(I21-AJ21) -> 0.48043862 | M21: 3.7 | N21: 0 | O21: 0 | P21: 0 | Q21: =1.6*1.02 -> 1.632 | R21: 2.15 | S21: 0 | T21: =M21-(Q21+R21+S21) -> -0.082 | U21: 79 | V21: 0 | W21: =M21-N21-O21-P21-Q21-R21-S21-T21+U21+V21 -> 79 | X21: =W21-AN21 -> 79 | AD21: 0 | AG21: 29 | AH21: =AH20-AG21 -> 3549 | AJ21: =N21+O21+P21+Q21+R21+S21+T21+W21+AD21+AG21 -> 111.7 | AK21: =IF(L21<0,L21*-1,0) -> 0 | AL21: =AJ21+AK21 -> 111.7 | AM21: =AM20+(W21*1.9835) -> 3159.7155 | AN21: 0 | AU21: 0.52 | AV21: 32 | AW21: 26 | AY21: =SUM(N21,P21:T21) -> 3.7
A22: =A21+1 -> 8 | B22: 6892.16 | C22: 255557 | D22: =C22-C21 -> -174 | E22: =C22-152000 -> 103557 | F22: =D22/$D$2 -> -87.723721 | G22: 24 | H22: 0 | I22: =G22+H22 -> 24 | J22: =IF(L22>0,L22,0) -> 66.476279 | K22: =I22+J22 -> 90.476279 | L22: =F22-(I22-AJ22) -> 66.476279 | M22: 3.2 | N22: 0 | O22: 0 | P22: 0 | Q22: =1.6*1.02 -> 1.632 | R22: 2.33 | S22: 0 | T22: =M22-(Q22+R22+S22) -> -0.762 | U22: 145 | V22: 0 | W22: =M22-N22-O22-P22-Q22-R22-S22-T22+U22+V22 -> 145 | X22: =W22-AN22 -> 145 | AD22: 0 | AG22: 30 | AH22: =AH21-AG22 -> 3519 | AJ22: =N22+O22+P22+Q22+R22+S22+T22+W22+AD22+AG22 -> 178.2 | AK22: =IF(L22<0,L22*-1,0) -> 0 | AL22: =AJ22+AK22 -> 178.2 | AM22: =AM21+(W22*1.9835) -> 3447.323 | AN22: 0 | AU22: 0.32 | AV22: 33 | AW22: 4 | AY22: =SUM(N22,P22:T22) -> 3.2
A23: =A22+1 -> 9 | B23: 6892.08 | C23: 255280 | D23: =C23-C22 -> -277 | E23: =C23-152000 -> 103280 | F23: =D23/$D$2 -> -139.65213 | G23: 24 | H23: 0 | I23: =G23+H23 -> 24 | J23: =IF(L23>0,L23,0) -> 14.74787 | K23: =I23+J23 -> 38.74787 | L23: =F23-(I23-AJ23) -> 14.74787 | M23: 3.4 | N23: 0 | O23: 0 | P23: 0 | Q23: =1.6*1.02 -> 1.632 | R23: 2.27 | S23: 0 | T23: =M23-(Q23+R23+S23) -> -0.502 | U23: 145 | V23: 0 | W23: =M23-N23-O23-P23-Q23-R23-S23-T23+U23+V23 -> 145 | X23: =W23-AN23 -> 145 | AD23: 0 | AG23: 30 | AH23: =AH22-AG23 -> 3489 | AJ23: =N23+O23+P23+Q23+R23+S23+T23+W23+AD23+AG23 -> 178.4 | AK23: =IF(L23<0,L23*-1,0) -> 0 | AL23: =AJ23+AK23 -> 178.4 | AM23: =AM22+(W23*1.9835) -> 3734.9305 | AN23: 0 | AU23: 0 | AV23: 25 | AW23: -6 | AY23: =SUM(N23,P23:T23) -> 3.4
A24: =A23+1 -> 10 | B24: 6892 | C24: 255003 | D24: =C24-C23 -> -277 | E24: =C24-152000 -> 103003 | F24: =D24/$D$2 -> -139.65213 | G24: 24 | H24: 0 | I24: =G24+H24 -> 24 | J24: =IF(L24>0,L24,0) -> 14.84787 | K24: =I24+J24 -> 38.84787 | L24: =F24-(I24-AJ24) -> 14.84787 | M24: 3.5 | N24: 0 | O24: 0 | P24: 0 | Q24: =1.6*1.02 -> 1.632 | R24: 2.43 | S24: 0 | T24: =M24-(Q24+R24+S24) -> -0.562 | U24: 145 | V24: 0 | W24: =M24-N24-O24-P24-Q24-R24-S24-T24+U24+V24 -> 145 | X24: =W24-AN24 -> 145 | AD24: 0 | AG24: 30 | AH24: =AH23-AG24 -> 3459 | AJ24: =N24+O24+P24+Q24+R24+S24+T24+W24+AD24+AG24 -> 178.5 | AK24: =IF(L24<0,L24*-1,0) -> 0 | AL24: =AJ24+AK24 -> 178.5 | AM24: =AM23+(W24*1.9835) -> 4022.538 | AN24: 0 | AU24: 0 | AV24: 23 | AW24: -11 | AY24: =SUM(N24,P24:T24) -> 3.5
A25: =A24+1 -> 11 | B25: 6891.92 | C25: 254728 | D25: =C25-C24 -> -275 | E25: =C25-152000 -> 102728 | F25: =D25/$D$2 -> -138.64381 | G25: 24 | H25: 0 | I25: =G25+H25 -> 24 | J25: =IF(L25>0,L25,0) -> 15.856189 | K25: =I25+J25 -> 39.856189 | L25: =F25-(I25-AJ25) -> 15.856189 | M25: 3.5 | N25: 0 | O25: 0 | P25: 0 | Q25: =1.6*1.02 -> 1.632 | R25: 2.27 | S25: 0 | T25: =M25-(Q25+R25+S25) -> -0.402 | U25: 145 | V25: 0 | W25: =M25-N25-O25-P25-Q25-R25-S25-T25+U25+V25 -> 145 | X25: =W25-AN25 -> 145 | AD25: 0 | AG25: 30 | AH25: =AH24-AG25 -> 3429 | AJ25: =N25+O25+P25+Q25+R25+S25+T25+W25+AD25+AG25 -> 178.5 | AK25: =IF(L25<0,L25*-1,0) -> 0 | AL25: =AJ25+AK25 -> 178.5 | AM25: =AM24+(W25*1.9835) -> 4310.1455 | AN25: 0 | AU25: 0 | AV25: 30 | AW25: -10 | AY25: =SUM(N25,P25:T25) -> 3.5
A26: =A25+1 -> 12 | B26: 6891.84 | C26: 254453 | D26: =C26-C25 -> -275 | E26: =C26-152000 -> 102453 | F26: =D26/$D$2 -> -138.64381 | G26: 24 | H26: 0 | I26: =G26+H26 -> 24 | J26: =IF(L26>0,L26,0) -> 14.856189 | K26: =I26+J26 -> 38.856189 | L26: =F26-(I26-AJ26) -> 14.856189 | M26: 3.5 | N26: 0 | O26: 0 | P26: 0 | Q26: =1.6*1.02 -> 1.632 | R26: 2.19 | S26: 0 | T26: =M26-(Q26+R26+S26) -> -0.322 | U26: 144 | V26: 0 | W26: =M26-N26-O26-P26-Q26-R26-S26-T26+U26+V26 -> 144 | X26: =W26-AN26 -> 144 | AD26: 0 | AG26: 30 | AH26: =AH25-AG26 -> 3399 | AJ26: =N26+O26+P26+Q26+R26+S26+T26+W26+AD26+AG26 -> 177.5 | AK26: =IF(L26<0,L26*-1,0) -> 0 | AL26: =AJ26+AK26 -> 177.5 | AM26: =AM25+(W26*1.9835) -> 4595.7695 | AN26: 0 | AU26: 0.01 | AV26: 33 | AW26: 22 | AY26: =SUM(N26,P26:T26) -> 3.5
A27: =A26+1 -> 13 | B27: 6891.76 | C27: 254179 | D27: =C27-C26 -> -274 | E27: =C27-152000 -> 102179 | F27: =D27/$D$2 -> -138.13965 | G27: 24 | H27: 0 | I27: =G27+H27 -> 24 | J27: =IF(L27>0,L27,0) -> 15.360348 | K27: =I27+J27 -> 39.360348 | L27: =F27-(I27-AJ27) -> 15.360348 | M27: 3.5 | N27: 0 | O27: 0 | P27: 0 | Q27: =1.6*1.02 -> 1.632 | R27: 2.45 | S27: 0 | T27: =M27-(Q27+R27+S27) -> -0.582 | U27: 144 | V27: 0 | W27: =M27-N27-O27-P27-Q27-R27-S27-T27+U27+V27 -> 144 | X27: =W27-AN27 -> 144 | AD27: 0 | AG27: 30 | AH27: =AH26-AG27 -> 3369 | AJ27: =N27+O27+P27+Q27+R27+S27+T27+W27+AD27+AG27 -> 177.5 | AK27: =IF(L27<0,L27*-1,0) -> 0 | AL27: =AJ27+AK27 -> 177.5 | AM27: =AM26+(W27*1.9835) -> 4881.3935 | AN27: 0 | AU27: 0.03 | AV27: 36 | AW27: 21 | AY27: =SUM(N27,P27:T27) -> 3.5
... A43: =A42+1 -> 29 | B43: 6891.48 | C43: 253217 | D43: =C43-C42 -> 34 | E43: =C43-152000 -> 101217 | F43: =D43/$D$2 -> 17.141417 | G43: 30 | H43: 0 | I43: =G43+H43 -> 30 | J43: =IF(L43>0,L43,0) -> 22.341417 | K43: =I43+J43 -> 52.341417 | L43: =F43-(I43-AJ43) -> 22.341417 | M43: 5.2 | N43: 0 | O43: 0 | P43: 0 | Q43: =1.6*1.02 -> 1.632 | R43: 2.18 | S43: 0 | T43: =M43-(Q43+R43+S43) -> 1.388 | U43: 0 | V43: 0 | W43: =M43-N43-O43-P43-Q43-R43-S43-T43+U43+V43 -> 0 | X43: =W43-AN43 -> 0 | AD43: 0 | AG43: 30 | AH43: =AH42-AG43 -> 2889 | AJ43: =N43+O43+P43+Q43+R43+S43+T43+W43+AD43+AG43 -> 35.2 | AK43: =IF(L43<0,L43*-1,0) -> 0 | AL43: =AJ43+AK43 -> 35.2 | AM43: =AM42+(W43*1.9835) -> 5922.731 | AN43: 0 | AU43: 0 | AV43: 32 | AW43: 16 | AY43: =SUM(N43,P43:T43) -> 5.2
A44: 30 | B44: 6891.5 | C44: 253286 | D44: =C44-C43 -> 69 | E44: =C44-152000 -> 101286 | F44: =D44/$D$2 -> 34.786993 | G44: 30 | H44: 0 | I44: =G44+H44 -> 30 | J44: =IF(L44>0,L44,0) -> 40.686993 | K44: =I44+J44 -> 70.686993 | L44: =F44-(I44-AJ44) -> 40.686993 | M44: 5.9 | N44: 0 | O44: 0 | P44: 0 | Q44: =1.6*1.02 -> 1.632 | R44: 2.21 | S44: 0 | T44: =M44-(Q44+R44+S44) -> 2.058 | U44: 0 | V44: 0 | W44: =M44-N44-O44-P44-Q44-R44-S44-T44+U44+V44 -> 0 | X44: =W44-AN44 -> 0 | AD44: 0 | AG44: 30 | AH44: =AH43-AG44 -> 2859 | AJ44: =N44+O44+P44+Q44+R44+S44+T44+W44+AD44+AG44 -> 35.9 | AK44: =IF(L44<0,L44*-1,0) -> 0 | AL44: =AJ44+AK44 -> 35.9 | AM44: =AM43+(W44*1.9835) -> 5922.731 | AN44: 0 | AU44: 0.25 | AV44: 27 | AW44: 21 | AY44: =SUM(N44,P44:T44) -> 5.9
A45: 31 | B45: 6891.52 | C45: 253355 | D45: =C45-C44 -> 69 | E45: =C45-152000 -> 101355 | F45: =D45/$D$2 -> 34.786993 | G45: 30 | H45: 0 | I45: =G45+H45 -> 30 | J45: =IF(L45>0,L45,0) -> 39.786993 | K45: =I45+J45 -> 69.786993 | L45: =F45-(I45-AJ45) -> 39.786993 | M45: 5 | N45: 0 | O45: 0 | P45: 0 | Q45: =1.6*1.02 -> 1.632 | R45: 2.46 | S45: 0 | T45: =M45-(Q45+R45+S45) -> 0.908 | U45: 0 | V45: 0 | W45: =M45-N45-O45-P45-Q45-R45-S45-T45+U45+V45 -> 0 | X45: =W45-AN45 -> 0 | AD45: 0 | AG45: 30 | AH45: =AH44-AG45 -> 2829 | AJ45: =N45+O45+P45+Q45+R45+S45+T45+W45+AD45+AG45 -> 35 | AK45: =IF(L45<0,L45*-1,0) -> 0 | AL45: =AJ45+AK45 -> 35 | AM45: =AM44+(W45*1.9835) -> 5922.731 | AN45: 0 | AU45: 0 | AV45: 31 | AW45: 3 | AY45: =SUM(N45,P45:T45) -> 5
W46: =M46-N46-O46-Q46-R46-S46+U46+V46 -> 0 | X46: =N46-O46-P46-R46-S46-T46+V46+W46 -> 0 | AJ46: =N46+O46+Q46+R46+S46+W46+AD46+AG46 -> 0
A47: MONTH / CFS | F47: =SUM(F15:F45) -> -1494.8324 | G47: =SUM(G15:G45) -> 792 | H47: =SUM(H15:H45) -> 0 | I47: =SUM(I15:I45) -> 792 | J47: =SUM(J15:J45) -> 395.93932 | K47: =SUM(K15:K45) -> 1187.9393 | L47: =SUM(L15:L45) -> 334.56763 | M47: =SUM(M15:M46) -> 119.4 | N47: =SUM(N15:N45) -> 0 | O47: =SUM(O15:O45) -> 0 | Q47: =SUM(Q15:Q45) -> 50.592 | R47: =SUM(R15:R45) -> 69.92 | S47: =SUM(S15:S45) -> 0 | T47: =SUM(T15:T45) -> -1.112 | U47: =SUM(U15:U45) -> 1585 | V47: =SUM(V15:V45) -> 0 | W47: =SUM(W15:W45) -> 1585 | X47: =SUM(X15:X45) -> 1585 | AG47: =SUM(AG15:AG46) -> 917 | AI47: =SUM(AI16:AI45) -> 0 | AJ47: =SUM(AJ15:AJ46) -> 2621.4 | AK47: =SUM(AK15:AK45) -> 61.371691 | AL47: =SUM(AL15:AL45) -> 2682.7717 | AN47: =SUM(AN15:AN45) -> 0 | AU47: =SUM(AU15:AU45) -> 1.24 | AV47: =AVERAGE(AV15:AV45) -> 33.612903 | AW47: =AVERAGE(AW15:AW45) -> 8.5483871 | AX47: Avg | AY47: =SUM(AY15:AY45) -> 119.4
A48: MONTH / AF | D48: =SUM(D15:D45) -> -2965 | F48: =F47*$D$2 -> -2965 | G48: =G47*$D$2 -> 1570.932 | H48: =H47*$D$2 -> 0 | I48: =I47*$D$2 -> 1570.932 | J48: =J47*$D$2 -> 785.34565 | K48: =K47*$D$2 -> 2356.2776 | L48: =L47*$D$2 -> 663.6149 | M48: =M47*$D$2 -> 236.8299 | ... O48: =O47*$D$2 -> 0 | Q48: =Q47*$D$2 -> 100.34923 | R48: =R47*$D$2 -> 138.68632 | S48: =S47*$D$2 -> 0 | T48: =T47*$D$2 -> -2.205652 | U48: =U47*$D$2 -> 3143.8475 | V48: =V47*$D$2 -> 0 | W48: =W47*$D$2 -> 3143.8475 | X48: =X47*$D$2 -> 3143.8475 | AG48: =AG47*$D$2 -> 1818.8695 | AI48: =AI47*$D$2 -> 0 | AJ48: =AJ47*$D$2 -> 5199.5469 | AK48: =AK47*$D$2 -> 121.73075 | AL48: =AL47*$D$2 -> 5321.2776 | AN48: =AN47*$D$2 -> 0 | AV48: =MAX(AV15:AV45) -> 47 | AW48: =MAX(AW15:AW45) -> 26 | AX48: HI | AY48: =AY47*$D$2 -> 236.8299
A50: SEASON / CFS | AV50: =MIN(AV15:AV45) -> 23 | AW50: =MIN(AW15:AW45) -> -11 | AX50: LO
A51: SEASON / AF
A53: YTD / CFS | F53: =F13+F47 -> -3018.906 | G53: =G13+G47 -> 2041 | H53: =H13+H47 -> 0 | I53: =I13+I47 -> 2041 | J53: =J13+J47 -> 459.88064 | K53: =K13+K47 -> 2500.8806 | L53: =L13+L47 -> -42.105974 | M53: =M13+M47 -> 225.3 | N53: =N13+N47 -> 0 | O53: 0 | Q53: =Q13+Q47 -> 106.9572 | R53: =R13+R47 -> 137.91 | S53: =S13+S47 -> 0 | T53: =T13+T47 -> -19.92068 | U53: =U13+U47 -> 2986 | V53: =V13+V47 -> 40.5 | W53: =W13+W47 -> 3026.0823 | X53: =X13+X47 -> 2985.5823 | AG53: =AG13+AG47 -> 1766 | AH53: =AH45 -> 2829 | AI53: =AI14+AI47 -> 0 | AJ53: =AJ13+AJ47 -> 5017.8 | AK53: =AK13+AK47 -> 501.98661 | AL53: =AL13+AL47 -> 5519.7866 | AN53: =AN13+AN47 -> 40.5 | AU53: =AU13+AU47 -> 1.7 | AY53: =AY13+AY47 -> 225.71768
A54: YTD / AF | D54: =D13+D48 -> -5988 | E54: =E45 -> 101355 | F54: =F53*$D$2 -> -5988 | G54: =G53*$D$2 -> 4048.3235 | H54: =H53*$D$2 -> 0 | I54: =I53*$D$2 -> 4048.3235 | J54: =J53*$D$2 -> 912.17325 | K54: =K53*$D$2 -> 4960.4968 | L54: =L53*$D$2 -> -83.5172 | M54: =M53*$D$2 -> 446.88255 | ... O54: =O53*$D$2 -> 0 | Q54: =Q53*$D$2 -> 212.14961 | R54: =R53*$D$2 -> 273.54449 | S54: =S53*$D$2 -> 0 | T54: =T53*$D$2 -> -39.512669 | U54: =U53*$D$2 -> 5922.731 | V54: =V53*$D$2 -> 80.33175 | W54: =W53*$D$2 -> 6002.2343 | X54: =X53*$D$2 -> 5921.9025 | AG54: =AG53*$D$2 -> 3502.861 | AH54: =AH53*$D$2 -> 5611.3215 | AI54: =AI53*$D$2 -> 0 | AJ54: =AJ53*$D$2 -> 9952.8063 | AK54: =AK53*$D$2 -> 995.69045 | AL54: =AL53*$D$2 -> 10948.497 | AM54: =AM45 -> 5922.731 | AN54: =AN53*$D$2 -> 80.33175 | AY54: =AY53*$D$2 -> 447.71102

Sheet JAN
K1: MCPHEE RESERVOIR INFLOW/OUTFLOW TABULATION
A2: AF/cfs CONVERT FACTOR | D2: 1.9835 | K2: JANUARY "2010"
D4: RESERVOIR | W4: INFLOW/OUTFLOW (CFS) | AO4: ADJUSTMENTS | AV4: WEATHER
A5: DATE | B5: RESERV | C5: RESERV | D5: AC FT | E5: ACTIVE | F5: CONV TO | G5: DOLORES | H5: LOST | I5: RECORD | J5: CALC | K5: TOTAL | L5: CALC | M5: DOLORES TUNNEL | U5: LONE | V5: U | W5: TOTAL | X5: TOTAL | Y5: MVI | Z5: MVI | AA5: MVI | AB5: TO EX & | AC5: MVI | AD5: DV CR | AE5: D/S SENIOR | AG5: BELOW | AH5: FISH | AI5: SPILL | AJ5: RECORD | AK5: CALC | AL5: TOTAL | AM5: NAR | AN5: MVI | AO5: MVI | AP5: MVI | AQ5: DIST. | AR5: U/S | AS5: TOTTEN | AT5: UTES | AU5: RAIN | AV5: MAX | AW5: MIN | AY5: TOTAL
A6: DEC | B6: ELEV | D6: CHANGE | E6: CAP | F6: CFS | G6: RIVER | H6: CAN | I6: INFLOW | J6: INFLOW | K6: INFLOW | L6: INF/OTF | M6: TOT DIV | N6: WET | O6: UTE | P6: QUEST | Q6: MWC | R6: CTZ | S6: CTZ & | T6: F-BAY | U6: PINE | V6: LAT | W6: MVI | X6: MVI | Y6: CALL | Z6: CALL | AA6: APR- | AB6: U/S EX | AC6: PROJ | AD6: CANAL | AE6: MVIC | AF6: PROJ | AG6: MCP | AH6: LEFT | AJ6: OTF | AK6: OTF | AL6: OTF | AM6: FILL | AN6: STOCK | AO6: STORED | AP6: STORED | AQ6: CLASS | AR6: USERS | AS6: (FRESH | AT6: FROM | AV6: TMP | AW6: TMP | AY6: TUNNEL
N7: LAND | O7: F&R | S7: UTE | T7: SPILL | W7: WATER | X7: IRRIG. | Y7: STOR | Z7: SPILLED | AA7: JUNE | AE7: 1.7 | AF7: 1.3 | AO7: Apr - Jun | AP7: EVAP | AQ7: "B" | AR7: EXCH | AS7: WATER) | AT7: DWCD | AY7: Misc.
W8: USED | X8: WATER | Z8: OR | AA8: (DIV+
X9: USED | Z9: USED | AA9: CALL)
C10: AC. Ft. | E10: AC FT | G10: CFS | H10: CFS | I10: CFS | J10: CFS | K10: CFS | L10: CFS | M10: CFS | N10: CFS | O10: CFS | P10: CFS | Q10: CFS | R10: CFS | S10: PROJ | T10: CFS | U10: CFS | V10: CFS | W10: 153400 | X10: 150400 | AA10: 72000 | AB10: CFS | AC10: CFS | AD10: CFS | AE10: CFS | AF10: CFS | AG10: CFS | AH10: CFS | AI10: CFS | AJ10: CFS | AK10: CFS | AL10: CFS | AM10: AC FT | AN10: CFS | AO10: CFS | AP10: AC.FT. | AQ10: CFS | AR10: CFS | AS10: CFS | AT10: CFS | AY10: Outflow
N11: 1.03 | O11: 1.05 | P11: 1.02 | Q11: 1.02 | R11: 1.04 | S11: CFS | W11: CFS | X11: CFS | Y11: CFS | Z11: CFS | AA11: Ac. Ft. | AY11: CFS
A12: SEASON BAL
A13: YTD | B13: =DEC!B45 -> 6891.52 | C13: =DEC!C45 -> 253355 | D13: =DEC!D54 -> -5988 | E13: =DEC!E54 -> 101355 | F13: =DEC!F53 -> -3018.906 | G13: =DEC!G53 -> 2041 | H13: =DEC!H53 -> 0 | I13: =DEC!I53 -> 2041 | J13: =DEC!J53 -> 459.88064 | K13: =DEC!K53 -> 2500.8806 | L13: =DEC!L53 -> -42.105974 | M13: =DEC!M53 -> 225.3 | ... X13: =DEC!X53 -> 2985.5823 | AG13: =DEC!AG53 -> 1766 | AH13: =DEC!AH53 -> 2829 | AJ13: =DEC!AJ53 -> 5017.8 | AK13: =DEC!AK53 -> 501.98661 | AL13: =DEC!AL53 -> 5519.7866 | AM13: =DEC!AM54 -> 5922.731 | AN13: =DEC!AN53 -> 40.5 | AU13: =DEC!AU53 -> 1.7 | AY13: =DEC!AY53 -> 225.71768
A15: 1 | B15: 6891.52 | C15: 253355 | D15: =C15-C13 -> 0 | E15: =C15-152000 -> 101355 | F15: =D15/$D$2 -> 0 | G15: 30 | H15: 0 | I15: =G15+H15 -> 30 | J15: =IF(L15>0,L15,0) -> 2.3 | K15: =I15+J15 -> 32.3 | L15: =F15-(I15-AJ15) -> 2.3 | M15: 2.3 | N15: 0 | O15: 0 | P15: 0 | Q15: =1.477*1.02 -> 1.50654 | R15: 2.47 | S15: 0 | T15: =M15-(Q15+R15+S15) -> -1.67654 | U15: 0 | V15: 0 | W15: =M15-N15-O15-P15-Q15-R15-S15-T15+U15+V15 -> 0 | X15: =W15-AN15 -> 0 | AD15: 0 | AG15: 30 | AH15: =AH13-AG15 -> 2799 | AJ15: =N15+O15+P15+Q15+R15+S15+T15+W15+AD15+AG15 -> 32.3 | AK15: =IF(L15<0,L15*-1,0) -> 0 | AL15: =AJ15+AK15 -> 32.3 | AM15: =AM13+(W15*1.9835) -> 5922.731 | AN15: 0 | AU15: 0 | AV15: 26 | AW15: -5 | AY15: =SUM(N15,P15:T15) -> 2.3
A16: =A15+1 -> 2 | B16: 6891.53 | C16: 253389 | D16: =C16-C15 -> 34 | E16: =C16-152000 -> 101389 | F16: =D16/$D$2 -> 17.141417 | G16: 30 | H16: 0 | I16: =G16+H16 -> 30 | J16: =IF(L16>0,L16,0) -> 19.741417 | K16: =I16+J16 -> 49.741417 | L16: =F16-(I16-AJ16) -> 19.741417 | M16: 2.6 | N16: 0 | O16: 0 | P16: 0 | Q16: =1.477*1.02 -> 1.50654 | R16: 2.33 | S16: 0 | T16: =M16-(Q16+R16+S16) -> -1.23654 | U16: 0 | V16: 0 | W16: =M16-N16-O16-P16-Q16-R16-S16-T16+U16+V16 -> 0 | X16: =W16-AN16 -> 0 | AD16: 0 | AG16: 30 | AH16: =AH15-AG16 -> 2769 | AJ16: =N16+O16+P16+Q16+R16+S16+T16+W16+AD16+AG16 -> 32.6 | AK16: =IF(L16<0,L16*-1,0) -> 0 | AL16: =AJ16+AK16 -> 32.6 | AM16: =AM15+(W16*1.9835) -> 5922.731 | AN16: 0 | AU16: 0 | AV16: 33 | AW16: -3 | AY16: =SUM(N16,P16:T16) -> 2.6
A17: =A16+1 -> 3 | B17: 6891.53 | C17: 253389 | D17: =C17-C16 -> 0 | E17: =C17-152000 -> 101389 | F17: =D17/$D$2 -> 0 | G17: 30 | H17: 0.25 | I17: =G17+H17 -> 30.25 | J17: =IF(L17>0,L17,0) -> 2.35 | K17: =I17+J17 -> 32.6 | L17: =F17-(I17-AJ17) -> 2.35 | M17: 2.6 | N17: 0 | O17: 0 | P17: 0 | Q17: =1.477*1.02 -> 1.50654 | R17: 2.52 | S17: 0 | T17: =M17-(Q17+R17+S17) -> -1.42654 | U17: 0 | V17: 0 | W17: =M17-N17-O17-P17-Q17-R17-S17-T17+U17+V17 -> 0 | X17: =W17-AN17 -> 0 | AD17: 0 | AG17: 30 | AH17: =AH16-AG17 -> 2739 | AJ17: =N17+O17+P17+Q17+R17+S17+T17+W17+AD17+AG17 -> 32.6 | AK17: =IF(L17<0,L17*-1,0) -> 0 | AL17: =AJ17+AK17 -> 32.6 | AM17: =AM16+(W17*1.9835) -> 5922.731 | AN17: 0 | AU17: 0 | AV17: 30 | AW17: -4 | AY17: =SUM(N17,P17:T17) -> 2.6
A18: =A17+1 -> 4 | B18: 6891.53 | C18: 253389 | D18: =C18-C17 -> 0 | E18: =C18-152000 -> 101389 | F18: =D18/$D$2 -> 0 | G18: 30 | H18: 0.5 | I18: =G18+H18 -> 30.5 | J18: =IF(L18>0,L18,0) -> 2 | K18: =I18+J18 -> 32.5 | L18: =F18-(I18-AJ18) -> 2 | M18: 2.5 | N18: 0 | O18: 0 | P18: 0 | Q18: =1.477*1.02 -> 1.50654 | R18: 2.52 | S18: 0 | T18: =M18-(Q18+R18+S18) -> -1.52654 | U18: 0 | V18: 0 | W18: =M18-N18-O18-P18-Q18-R18-S18-T18+U18+V18 -> 0 | X18: =W18-AN18 -> 0 | AD18: 0 | AG18: 30 | AH18: =AH17-AG18 -> 2709 | AJ18: =N18+O18+P18+Q18+R18+S18+T18+W18+AD18+AG18 -> 32.5 | AK18: =IF(L18<0,L18*-1,0) -> 0 | AL18: =AJ18+AK18 -> 32.5 | AM18: =AM17+(W18*1.9835) -> 5922.731 | AN18: 0 | AU18: 0 | AV18: 34 | AW18: 6 | AY18: =SUM(N18,P18:T18) -> 2.5
A19: =A18+1 -> 5 | B19: 6891.54 | C19: 253423 | D19: =C19-C18 -> 34 | E19: =C19-152000 -> 101423 | F19: =D19/$D$2 -> 17.141417 | G19: 31 | H19: 0.5 | I19: =G19+H19 -> 31.5 | J19: =IF(L19>0,L19,0) -> 17.941417 | K19: =I19+J19 -> 49.441417 | L19: =F19-(I19-AJ19) -> 17.941417 | M19: 2.3 | N19: 0 | O19: 0 | P19: 0 | Q19: =1.477*1.02 -> 1.50654 | R19: 2.47 | S19: 0 | T19: =M19-(Q19+R19+S19) -> -1.67654 | U19: 0 | V19: 0 | W19: =M19-N19-O19-P19-Q19-R19-S19-T19+U19+V19 -> 0 | X19: =W19-AN19 -> 0 | AD19: 0 | AG19: 30 | AH19: =AH18-AG19 -> 2679 | AJ19: =N19+O19+P19+Q19+R19+S19+T19+W19+AD19+AG19 -> 32.3 | AK19: =IF(L19<0,L19*-1,0) -> 0 | AL19: =AJ19+AK19 -> 32.3 | AM19: =AM18+(W19*1.9835) -> 5922.731 | AN19: 0 | AU19: 0 | AV19: 38 | AW19: 9 | AY19: =SUM(N19,P19:T19) -> 2.3
A20: =A19+1 -> 6 | B20: 6891.54 | C20: 253423 | D20: =C20-C19 -> 0 | E20: =C20-152000 -> 101423 | F20: =D20/$D$2 -> 0 | G20: 31 | H20: 0.5 | I20: =G20+H20 -> 31.5 | J20: =IF(L20>0,L20,0) -> 0.8 | K20: =I20+J20 -> 32.3 | L20: =F20-(I20-AJ20) -> 0.8 | M20: 2.3 | N20: 0 | O20: 0 | P20: 0 | Q20: =1.477*1.02 -> 1.50654 | R20: 3.52 | S20: 0 | T20: =M20-(Q20+R20+S20) -> -2.72654 | U20: 0 | V20: 0 | W20: =M20-N20-O20-P20-Q20-R20-S20-T20+U20+V20 -> 0 | X20: =W20-AN20 -> 0 | AD20: 0 | AG20: 30 | AH20: =AH19-AG20 -> 2649 | AJ20: =N20+O20+P20+Q20+R20+S20+T20+W20+AD20+AG20 -> 32.3 | AK20: =IF(L20<0,L20*-1,0) -> 0 | AL20: =AJ20+AK20 -> 32.3 | AM20: =AM19+(W20*1.9835) -> 5922.731 | AN20: 0 | AU20: 0 | AV20: 36 | AW20: 10 | AY20: =SUM(N20,P20:T20) -> 2.3
A21: =A20+1 -> 7 | B21: 6891.54 | C21: 253423 | D21: =C21-C20 -> 0 | E21: =C21-152000 -> 101423 | F21: =D21/$D$2 -> 0 | G21: 31 | H21: 0.5 | I21: =G21+H21 -> 31.5 | J21: =IF(L21>0,L21,0) -> 1.3 | K21: =I21+J21 -> 32.8 | L21: =F21-(I21-AJ21) -> 1.3 | M21: 2.8 | N21: 0 | O21: 0 | P21: 0 | Q21: =1.477*1.02 -> 1.50654 | R21: 2.52 | S21: 0 | T21: =M21-(Q21+R21+S21) -> -1.22654 | U21: 0 | V21: 0 | W21: =M21-N21-O21-P21-Q21-R21-S21-T21+U21+V21 -> 0 | X21: =W21-AN21 -> 0 | AD21: 0 | AG21: 30 | AH21: =AH20-AG21 -> 2619 | AJ21: =N21+O21+P21+Q21+R21+S21+T21+W21+AD21+AG21 -> 32.8 | AK21: =IF(L21<0,L21*-1,0) -> 0 | AL21: =AJ21+AK21 -> 32.8 | AM21: =AM20+(W21*1.9835) -> 5922.731 | AN21: 0 | AU21: 0 | AV21: 36 | AW21: 9 | AY21: =SUM(N21,P21:T21) -> 2.8
A22: =A21+1 -> 8 | B22: 6891.55 | C22: 253458 | D22: =C22-C21 -> 35 | E22: =C22-152000 -> 101458 | F22: =D22/$D$2 -> 17.645576 | G22: 31 | H22: 0.5 | I22: =G22+H22 -> 31.5 | J22: =IF(L22>0,L22,0) -> 19.045576 | K22: =I22+J22 -> 50.545576 | L22: =F22-(I22-AJ22) -> 19.045576 | M22: 2.9 | N22: 0 | O22: 0 | P22: 0 | Q22: =1.477*1.02 -> 1.50654 | R22: 2.5 | S22: 0 | T22: =M22-(Q22+R22+S22) -> -1.10654 | U22: 0 | V22: 0 | W22: =M22-N22-O22-P22-Q22-R22-S22-T22+U22+V22 -> 0 | X22: =W22-AN22 -> 0 | AD22: 0 | AG22: 30 | AH22: =AH21-AG22 -> 2589 | AJ22: =N22+O22+P22+Q22+R22+S22+T22+W22+AD22+AG22 -> 32.9 | AK22: =IF(L22<0,L22*-1,0) -> 0 | AL22: =AJ22+AK22 -> 32.9 | AM22: =AM21+(W22*1.9835) -> 5922.731 | AN22: 0 | AU22: 0 | AV22: 30 | AW22: 4 | AY22: =SUM(N22,P22:T22) -> 2.9
A23: =A22+1 -> 9 | B23: 6891.55 | C23: 253458 | D23: =C23-C22 -> 0 | E23: =C23-152000 -> 101458 | F23: =D23/$D$2 -> 0 | G23: 31 | H23: 0.52 | I23: =G23+H23 -> 31.52 | J23: =IF(L23>0,L23,0) -> 1.08 | K23: =I23+J23 -> 32.6 | L23: =F23-(I23-AJ23) -> 1.08 | M23: 2.6 | N23: 0 | O23: 0 | P23: 0 | Q23: =1.477*1.02 -> 1.50654 | R23: 2.56 | S23: 0 | T23: =M23-(Q23+R23+S23) -> -1.46654 | U23: 0 | V23: 0 | W23: =M23-N23-O23-P23-Q23-R23-S23-T23+U23+V23 -> 0 | X23: =W23-AN23 -> 0 | AD23: 0 | AG23: 30 | AH23: =AH22-AG23 -> 2559 | AJ23: =N23+O23+P23+Q23+R23+S23+T23+W23+AD23+AG23 -> 32.6 | AK23: =IF(L23<0,L23*-1,0) -> 0 | AL23: =AJ23+AK23 -> 32.6 | AM23: =AM22+(W23*1.9835) -> 5922.731 | AN23: 0 | AU23: 0 | AV23: 32 | AW23: 4 | AY23: =SUM(N23,P23:T23) -> 2.6
A24: =A23+1 -> 10 | B24: 6891.55 | C24: 253458 | D24: =C24-C23 -> 0 | E24: =C24-152000 -> 101458 | F24: =D24/$D$2 -> 0 | G24: 31 | H24: 0.58 | I24: =G24+H24 -> 31.58 | J24: =IF(L24>0,L24,0) -> 1.02 | K24: =I24+J24 -> 32.6 | L24: =F24-(I24-AJ24) -> 1.02 | M24: 2.6 | N24: 0 | O24: 0 | P24: 0 | Q24: =1.477*1.02 -> 1.50654 | R24: 2.51 | S24: 0 | T24: =M24-(Q24+R24+S24) -> -1.41654 | U24: 0 | V24: 0 | W24: =M24-N24-O24-P24-Q24-R24-S24-T24+U24+V24 -> 0 | X24: =W24-AN24 -> 0 | AD24: 0 | AG24: 30 | AH24: =AH23-AG24 -> 2529 | AJ24: =N24+O24+P24+Q24+R24+S24+T24+W24+AD24+AG24 -> 32.6 | AK24: =IF(L24<0,L24*-1,0) -> 0 | AL24: =AJ24+AK24 -> 32.6 | AM24: =AM23+(W24*1.9835) -> 5922.731 | AN24: 0 | AU24: 0 | AV24: 38 | AW24: 7 | AY24: =SUM(N24,P24:T24) -> 2.6
A25: =A24+1 -> 11 | B25: 6891.55 | C25: 253458 | D25: =C25-C24 -> 0 | E25: =C25-152000 -> 101458 | F25: =D25/$D$2 -> 0 | G25: 31 | H25: 0.59 | I25: =G25+H25 -> 31.59 | J25: =IF(L25>0,L25,0) -> 1.31 | K25: =I25+J25 -> 32.9 | L25: =F25-(I25-AJ25) -> 1.31 | M25: 2.9 | N25: 0 | O25: 0 | P25: 0 | Q25: =1.477*1.02 -> 1.50654 | R25: 2.27 | S25: 0 | T25: =M25-(Q25+R25+S25) -> -0.87654 | U25: 0 | V25: 0 | W25: =M25-N25-O25-P25-Q25-R25-S25-T25+U25+V25 -> 0 | X25: =W25-AN25 -> 0 | AD25: 0 | AG25: 30 | AH25: =AH24-AG25 -> 2499 | AJ25: =N25+O25+P25+Q25+R25+S25+T25+W25+AD25+AG25 -> 32.9 | AK25: =IF(L25<0,L25*-1,0) -> 0 | AL25: =AJ25+AK25 -> 32.9 | AM25: =AM24+(W25*1.9835) -> 5922.731 | AN25: 0 | AU25: 0 | AV25: 45 | AW25: 15 | AY25: =SUM(N25,P25:T25) -> 2.9
A26: =A25+1 -> 12 | B26: 6891.55 | C26: 253458 | D26: =C26-C25 -> 0 | E26: =C26-152000 -> 101458 | F26: =D26/$D$2 -> 0 | G26: 31 | H26: 0.61 | I26: =G26+H26 -> 31.61 | J26: =IF(L26>0,L26,0) -> 1.29 | K26: =I26+J26 -> 32.9 | L26: =F26-(I26-AJ26) -> 1.29 | M26: 2.9 | N26: 0 | O26: 0 | P26: 0 | Q26: =1.477*1.02 -> 1.50654 | R26: 2.49 | S26: 0 | T26: =M26-(Q26+R26+S26) -> -1.09654 | U26: 0 | V26: 0 | W26: =M26-N26-O26-P26-Q26-R26-S26-T26+U26+V26 -> 0 | X26: =W26-AN26 -> 0 | AD26: 0 | AG26: 30 | AH26: =AH25-AG26 -> 2469 | AJ26: =N26+O26+P26+Q26+R26+S26+T26+W26+AD26+AG26 -> 32.9 | AK26: =IF(L26<0,L26*-1,0) -> 0 | AL26: =AJ26+AK26 -> 32.9 | AM26: =AM25+(W26*1.9835) -> 5922.731 | AN26: 0 | AU26: 0 | AV26: 50 | AW26: 17 | AY26: =SUM(N26,P26:T26) -> 2.9
A27: =A26+1 -> 13 | B27: 6891.55 | C27: 253458 | D27: =C27-C26 -> 0 | E27: =C27-152000 -> 101458 | F27: =D27/$D$2 -> 0 | G27: 31 | H27: 0.66 | I27: =G27+H27 -> 31.66 | J27: =IF(L27>0,L27,0) -> 4.74 | K27: =I27+J27 -> 36.4 | L27: =F27-(I27-AJ27) -> 4.74 | M27: 6.4 | N27: 0 | O27: 0 | P27: 0 | Q27: =1.477*1.02 -> 1.50654 | R27: 2.48 | S27: 0 | T27: =M27-(Q27+R27+S27) -> 2.41346 | U27: 0 | V27: 0 | W27: =M27-N27-O27-P27-Q27-R27-S27-T27+U27+V27 -> 0 | X27: =W27-AN27 -> 0 | AD27: 0 | AG27: 30 | AH27: =AH26-AG27 -> 2439 | AJ27: =N27+O27+P27+Q27+R27+S27+T27+W27+AD27+AG27 -> 36.4 | AK27: =IF(L27<0,L27*-1,0) -> 0 | AL27: =AJ27+AK27 -> 36.4 | AM27: =AM26+(W27*1.9835) -> 5922.731 | AN27: 0 | AU27: 0 | AV27: 49 | AW27: 19 | AY27: =SUM(N27,P27:T27) -> 6.4
... A43: =A42+1 -> 29 | B43: 6891.74 | C43: 254110 | D43: =C43-C42 -> -103 | E43: =C43-152000 -> 102110 | F43: =D43/$D$2 -> -51.928409 | G43: 31 | H43: 0.81 | I43: =G43+H43 -> 31.81 | J43: =IF(L43>0,L43,0) -> 0 | K43: =I43+J43 -> 31.81 | L43: =F43-(I43-AJ43) -> -14.138409 | M43: 4.6 | N43: 0 | O43: 0 | P43: 0 | Q43: =1.477*1.02 -> 1.50654 | R43: 2.28 | S43: 0 | T43: =M43-(Q43+R43+S43) -> 0.81346 | U43: 35 | V43: 0 | W43: =M43-N43-O43-P43-Q43-R43-S43-T43+U43+V43 -> 35 | X43: =W43-AN43 -> 35 | AD43: 0 | AG43: 30 | AH43: =AH42-AG43 -> 1959 | AJ43: =N43+O43+P43+Q43+R43+S43+T43+W43+AD43+AG43 -> 69.6 | AK43: =IF(L43<0,L43*-1,0) -> 14.138409 | AL43: =AJ43+AK43 -> 83.738409 | AM43: =AM42+(W43*1.9835) -> 6187.7266 | AN43: 0 | AU43: 0 | AV43: 32 | AW43: 24 | AY43: =SUM(N43,P43:T43) -> 4.6
A44: 30 | B44: 6891.71 | C44: 254007 | D44: =C44-C43 -> -103 | E44: =C44-152000 -> 102007 | F44: =D44/$D$2 -> -51.928409 | G44: 31 | H44: 0.95 | I44: =G44+H44 -> 31.95 | J44: =IF(L44>0,L44,0) -> 0 | K44: =I44+J44 -> 31.95 | L44: =F44-(I44-AJ44) -> -14.278409 | M44: 4.6 | N44: 0 | O44: 0 | P44: 0 | Q44: =1.477*1.02 -> 1.50654 | R44: 2.29 | S44: 0 | T44: =M44-(Q44+R44+S44) -> 0.80346 | U44: 35 | V44: 0 | W44: =M44-N44-O44-P44-Q44-R44-S44-T44+U44+V44 -> 35 | X44: =W44-AN44 -> 35 | AD44: 0 | AG44: 30 | AH44: =AH43-AG44 -> 1929 | AJ44: =N44+O44+P44+Q44+R44+S44+T44+W44+AD44+AG44 -> 69.6 | AK44: =IF(L44<0,L44*-1,0) -> 14.278409 | AL44: =AJ44+AK44 -> 83.878409 | AM44: =AM43+(W44*1.9835) -> 6257.1491 | AN44: 0 | AU44: 0 | AV44: 36 | AW44: 12 | AY44: =SUM(N44,P44:T44) -> 4.6
A45: 31 | B45: 6891.68 | C45: 253904 | D45: =C45-C44 -> -103 | E45: =C45-152000 -> 101904 | F45: =D45/$D$2 -> -51.928409 | G45: 31 | H45: 1 | I45: =G45+H45 -> 32 | J45: =IF(L45>0,L45,0) -> 0 | K45: =I45+J45 -> 32 | L45: =F45-(I45-AJ45) -> -14.328409 | M45: 4.6 | N45: 0 | O45: 0 | P45: 0 | Q45: =1.477*1.02 -> 1.50654 | R45: 2.18 | S45: 0 | T45: =M45-(Q45+R45+S45) -> 0.91346 | U45: 35 | V45: 0 | W45: =M45-N45-O45-P45-Q45-R45-S45-T45+U45+V45 -> 35 | X45: =W45-AN45 -> 35 | AD45: 0 | AG45: 30 | AH45: =AH44-AG45 -> 1899 | AJ45: =N45+O45+P45+Q45+R45+S45+T45+W45+AD45+AG45 -> 69.6 | AK45: =IF(L45<0,L45*-1,0) -> 14.328409 | AL45: =AJ45+AK45 -> 83.928409 | AM45: =AM44+(W45*1.9835) -> 6326.5716 | AN45: 0 | AU45: 0 | AV45: 39 | AW45: 16 | AY45: =SUM(N45,P45:T45) -> 4.6
W46: =M46-N46-O46-Q46-R46-S46+U46+V46 -> 0 | X46: =N46-O46-P46-R46-S46-T46+V46+W46 -> 0 | AJ46: =N46+O46+Q46+R46+S46+W46+AD46+AG46 -> 0
A47: MONTH / CFS | F47: =SUM(F15:F45) -> 276.78346 | G47: =SUM(G15:G45) -> 957 | H47: =SUM(H15:H45) -> 21.79 | I47: =SUM(I15:I45) -> 978.79 | J47: =SUM(J15:J45) -> 615.6625 | K47: =SUM(K15:K45) -> 1594.4525 | L47: =SUM(L15:L45) -> 543.19346 | M47: =SUM(M15:M46) -> 111.6 | N47: =SUM(N15:N45) -> 0 | O47: =SUM(O15:O45) -> 0 | Q47: =SUM(Q15:Q45) -> 46.70274 | R47: =SUM(R15:R45) -> 76.7 | S47: =SUM(S15:S45) -> 0.43 | T47: =SUM(T15:T45) -> -12.23274 | U47: =SUM(U15:U45) -> 203.6 | V47: =SUM(V15:V45) -> 0 | W47: =SUM(W15:W45) -> 203.6 | X47: =SUM(X15:X45) -> 203.6 | AG47: =SUM(AG15:AG46) -> 930 | AI47: =SUM(AI16:AI45) -> 0 | AJ47: =SUM(AJ15:AJ46) -> 1245.2 | AK47: =SUM(AK15:AK45) -> 72.46904 | AL47: =SUM(AL15:AL45) -> 1317.669 | AN47: =SUM(AN15:AN45) -> 0 | AU47: =SUM(AU15:AU45) -> 2.55 | AV47: =AVERAGE(AV15:AV45) -> 36.193548 | AW47: =AVERAGE(AW15:AW45) -> 10.483871 | AX47: Avg | AY47: =SUM(AY15:AY45) -> 111.6
A48: MONTH / AF | D48: =SUM(D15:D45) -> 549 | F48: =F47*$D$2 -> 549 | G48: =G47*$D$2 -> 1898.2095 | H48: =H47*$D$2 -> 43.220465 | I48: =I47*$D$2 -> 1941.43 | J48: =J47*$D$2 -> 1221.1666 | K48: =K47*$D$2 -> 3162.5965 | L48: =L47*$D$2 -> 1077.4242 | M48: =M47*$D$2 -> 221.3586 | ... O48: =O47*$D$2 -> 0 | Q48: =Q47*$D$2 -> 92.634885 | R48: =R47*$D$2 -> 152.13445 | S48: =S47*$D$2 -> 0.852905 | T48: =T47*$D$2 -> -24.26364 | U48: =U47*$D$2 -> 403.8406 | V48: =V47*$D$2 -> 0 | W48: =W47*$D$2 -> 403.8406 | X48: =X47*$D$2 -> 403.8406 | AG48: =AG47*$D$2 -> 1844.655 | AI48: =AI47*$D$2 -> 0 | AJ48: =AJ47*$D$2 -> 2469.8542 | AK48: =AK47*$D$2 -> 143.74234 | AL48: =AL47*$D$2 -> 2613.5965 | AN48: =AN47*$D$2 -> 0 | AV48: =MAX(AV15:AV45) -> 50 | AW48: =MAX(AW15:AW45) -> 29 | AX48: HI | AY48: =AY47*$D$2 -> 221.3586
A50: SEASON / CFS | AV50: =MIN(AV15:AV45) -> 26 | AW50: =MIN(AW15:AW45) -> -8 | AX50: LO
A51: SEASON / AF
