Workbook

Sheet NOV
K1: MCPHEE RESERVOIR INFLOW/OUTFLOW TABULATION
A2: AF/cfs CONVERT FACTOR | D2: 1.9835 | L2: NOVEMBER "2007"
D4: RESERVOIR | U4: INFLOW/OUTFLOW (CFS) | AK4: WEATHER | AO4: ADJUSTMENTS
A5: DATE | B5: RESERV | C5: RESERV | D5: AC FT | E5: ACTIVE | F5: CONV TO | G5: DOLORES | H5: LOST | I5: RECORD | J5: CALC | K5: TOTAL | L5: CALC | M5: DOLORES TUNNEL | U5: LONE | V5: U | W5: TOTAL | X5: MVI | Y5: TO EX & | Z5: MVI | AA5: DV CR | AB5: D/S SENIOR | AD5: BELOW | AE5: FISH | AF5: SPILL | AG5: RECORD | AH5: CALC | AI5: TOTAL | AJ5: RAIN | AK5: MAX | AL5: MIN | AM5: NAR. | AN5: MVI | AO5: MVI | AP5: MVI | AQ5: U/S | AR5: TOTTEN | AS5: UTES
A6: NOV | B6: ELEV | C6: AC FT | D6: CHANGE | E6: CAP | F6: CFS | G6: RIVER | H6: CAN | I6: INFLOW | J6: INFLOW | K6: INFLOW | L6: INF/OTF | M6: TOT DIV | N6: WET | O6: UTE | P6: QUEST | Q6: MWC | R6: CTZ | S6: CTZ & | T6: F-BAY | U6: PINE | V6: LAT | W6: MVI | X6: CALL | Y6: U/S EX | Z6: PROJ | AA6: CANAL | AB6: MVIC | AC6: PROJ | AD6: MCP | AE6: LEFT | AG6: OTF | AH6: OTF | AI6: OTF | AK6: TMP | AL6: TMP | AM6: CALL | AN6: STOCK | AO6: STORED | AP6: STORED | AQ6: USERS | AR6: (FRESH | AS6: FROM
E7: AC FT | N7: LAND | O7: F&R | S7: UTE | T7: SPILL | AM7: AC.FT. | AN7: CFS | AO7: Apr-Jun | AP7: EVAP | AQ7: EXCH | AR7: WATER) | AS7: MVIC
N8: 1.03 | O8: 1.05 | P8: 1.02 | Q8: 1.02 | R8: 1.04 | S8: PROJ | AM8: TOTAL | AP8: AC.FT
A9: SEASON BAL
A10: YTD | B10: 6901.16 | C10: 287879 | AE10: 4939 | AN10: 321
A12: 1 | B12: 6901.14 | C12: 287804 | D12: =C12-C10 -> -75 | E12: =C12-152000 -> 135804 | F12: =D12/$D$2 -> -37.811949 | G12: 102 | H12: 2 | I12: =G12+H12 -> 104 | J12: =IF(L12>0,L12,0) -> 0 | K12: =I12+J12 -> 104 | L12: =F12-(I12-AG12) -> -35.811949 | M12: 40 | N12: 0 | O12: 0 | P12: 0 | Q12: =1.56*1.02 -> 1.5912 | R12: 2.49 | S12: 0 | T12: 0 | U12: 22 | V12: 11 | W12: =M12-N12-P12-O12-Q12-R12-S12-T12+U12+V12 -> 68.9188 | AA12: 0 | AD12: 33 | AE12: =AE10-AD12 -> 4906 | AG12: =N12+O12+P12+Q12+R12+S12+T12+W12+AA12+AD12 -> 106 | AH12: =IF(L12<0,L12*-1,0) -> 35.811949 | AI12: =AG12+AH12 -> 141.81195 | AJ12: 0 | AK12: 60 | AL12: 28 | AN12: =W12 -> 68.9188
A13: =A12+1 -> 2 | B13: 6901.12 | C13: 287730 | D13: =C13-C12 -> -74 | E13: =C13-152000 -> 135730 | F13: =D13/$D$2 -> -37.307789 | G13: 96 | H13: 1.6 | I13: =G13+H13 -> 97.6 | J13: =IF(L13>0,L13,0) -> 0 | K13: =I13+J13 -> 97.6 | L13: =F13-(I13-AG13) -> -12.907789 | M13: 46 | N13: 0 | O13: 0 | P13: 0 | Q13: =1.56*1.02 -> 1.5912 | R13: 2.3 | S13: 0 | T13: 0 | U13: 29 | V13: 16 | W13: =M13-N13-P13-O13-Q13-R13-S13-T13+U13+V13 -> 87.1088 | AA13: 0 | AD13: 31 | AE13: =AE12-AD13 -> 4875 | AG13: =N13+O13+P13+Q13+R13+S13+T13+W13+AA13+AD13 -> 122 | AH13: =IF(L13<0,L13*-1,0) -> 12.907789 | AI13: =AG13+AH13 -> 134.90779 | AJ13: 0 | AK13: 61 | AL13: 25 | AN13: =W13 -> 87.1088
A14: =A13+1 -> 3 | B14: 6901.1 | C14: 287655 | D14: =C14-C13 -> -75 | E14: =C14-152000 -> 135655 | F14: =D14/$D$2 -> -37.811949 | G14: 89 | H14: 1.4 | I14: =G14+H14 -> 90.4 | J14: =IF(L14>0,L14,0) -> 0 | K14: =I14+J14 -> 90.4 | L14: =F14-(I14-AG14) -> -0.25194858 | M14: 48 | N14: 0 | O14: 0 | P14: 0 | Q14: =1.56*1.02 -> 1.5912 | R14: 2.48 | S14: 0 | T14: 0 | U14: 32.96 | V14: 16 | W14: =M14-N14-P14-O14-Q14-R14-S14-T14+U14+V14 -> 92.8888 | AA14: 0 | AD14: 31 | AE14: =AE13-AD14 -> 4844 | AG14: =N14+O14+P14+Q14+R14+S14+T14+W14+AA14+AD14 -> 127.96 | AH14: =IF(L14<0,L14*-1,0) -> 0.25194858 | AI14: =AG14+AH14 -> 128.21195 | AJ14: 0 | AK14: 62 | AL14: 27 | AN14: =W14 -> 92.8888
A15: =A14+1 -> 4 | B15: 6901.07 | C15: 287543 | D15: =C15-C14 -> -112 | E15: =C15-152000 -> 135543 | F15: =D15/$D$2 -> -56.465843 | G15: 80 | H15: 1 | I15: =G15+H15 -> 81 | J15: =IF(L15>0,L15,0) -> 0 | K15: =I15+J15 -> 81 | L15: =F15-(I15-AG15) -> -9.4658432 | M15: 48 | N15: 0 | O15: 0 | P15: 0 | Q15: =1.56*1.02 -> 1.5912 | R15: 2.43 | S15: 0 | T15: 0 | U15: 32 | V15: 17 | W15: =M15-N15-P15-O15-Q15-R15-S15-T15+U15+V15 -> 92.9788 | AA15: 0 | AD15: 31 | AE15: =AE14-AD15 -> 4813 | AG15: =N15+O15+P15+Q15+R15+S15+T15+W15+AA15+AD15 -> 128 | AH15: =IF(L15<0,L15*-1,0) -> 9.4658432 | AI15: =AG15+AH15 -> 137.46584 | AJ15: 0 | AK15: 64 | AL15: 27 | AN15: =W15 -> 92.9788
A16: =A15+1 -> 5 | B16: 6901.04 | C16: 287431 | D16: =C16-C15 -> -112 | E16: =C16-152000 -> 135431 | F16: =D16/$D$2 -> -56.465843 | G16: 80 | H16: 0.79 | I16: =G16+H16 -> 80.79 | J16: =IF(L16>0,L16,0) -> 0 | K16: =I16+J16 -> 80.79 | L16: =F16-(I16-AG16) -> -34.255843 | M16: 21 | N16: 0 | O16: 0 | P16: 0 | Q16: =1.56*1.02 -> 1.5912 | R16: 2.94 | S16: 0 | T16: 0 | U16: 32 | V16: 19 | W16: =M16-N16-P16-O16-Q16-R16-S16-T16+U16+V16 -> 67.4688 | AA16: 0 | AD16: 31 | AE16: =AE15-AD16 -> 4782 | AG16: =N16+O16+P16+Q16+R16+S16+T16+W16+AA16+AD16 -> 103 | AH16: =IF(L16<0,L16*-1,0) -> 34.255843 | AI16: =AG16+AH16 -> 137.25584 | AJ16: 0 | AK16: 65 | AL16: 23 | AN16: =W16 -> 67.4688
A17: =A16+1 -> 6 | B17: 6901.02 | C17: 287357 | D17: =C17-C16 -> -74 | E17: =C17-152000 -> 135357 | F17: =D17/$D$2 -> -37.307789 | G17: 79 | H17: 0.58 | I17: =G17+H17 -> 79.58 | J17: =IF(L17>0,L17,0) -> 0 | K17: =I17+J17 -> 79.58 | L17: =F17-(I17-AG17) -> -16.687789 | M17: 7.4 | N17: 0 | O17: 0 | P17: 0 | Q17: =1.56*1.02 -> 1.5912 | R17: 3.01 | S17: 0 | T17: 0 | U17: 56 | V17: 5.8 | W17: =M17-N17-P17-O17-Q17-R17-S17-T17+U17+V17 -> 64.5988 | AA17: 0 | AD17: 31 | AE17: =AE16-AD17 -> 4751 | AG17: =N17+O17+P17+Q17+R17+S17+T17+W17+AA17+AD17 -> 100.2 | AH17: =IF(L17<0,L17*-1,0) -> 16.687789 | AI17: =AG17+AH17 -> 116.88779 | AJ17: 0 | AK17: 65 | AL17: 28 | AM17: =44.3*1.9835 -> 87.86905 | AN17: =W17-AM17/1.9835 -> 20.2988
A18: =A17+1 -> 7 | B18: 6900.99 | C18: 287245 | D18: =C18-C17 -> -112 | E18: =C18-152000 -> 135245 | F18: =D18/$D$2 -> -56.465843 | G18: 80 | H18: 0.46 | I18: =G18+H18 -> 80.46 | J18: =IF(L18>0,L18,0) -> 0 | K18: =I18+J18 -> 80.46 | L18: =F18-(I18-AG18) -> -19.325843 | M18: 6.6 | N18: 0 | O18: 0 | P18: 0 | Q18: =1.56*1.02 -> 1.5912 | R18: 2.47 | S18: 0 | T18: =M18-(Q18+R18+S18) -> 2.5388 | U18: 80 | V18: 0 | W18: =M18-N18-P18-O18-Q18-R18-S18-T18+U18+V18 -> 80 | AA18: 0 | AD18: 31 | AE18: =AE17-AD18 -> 4720 | AG18: =N18+O18+P18+Q18+R18+S18+T18+W18+AA18+AD18 -> 117.6 | AH18: =IF(L18<0,L18*-1,0) -> 19.325843 | AI18: =AG18+AH18 -> 136.92584 | AJ18: 0 | AK18: 68 | AL18: 26 | AM18: =AM17+W18*1.9835 -> 246.54905
A19: =A18+1 -> 8 | B19: 6900.96 | C19: 287134 | D19: =C19-C18 -> -111 | E19: =C19-152000 -> 135134 | F19: =D19/$D$2 -> -55.961684 | G19: 78 | H19: 0.67 | I19: =G19+H19 -> 78.67 | J19: =IF(L19>0,L19,0) -> 0 | K19: =I19+J19 -> 78.67 | L19: =F19-(I19-AG19) -> -17.431684 | M19: 6.2 | N19: 0 | O19: 0 | P19: 0 | Q19: =1.56*1.02 -> 1.5912 | R19: 2.36 | S19: 0 | T19: =M19-(Q19+R19+S19) -> 2.2488 | U19: 80 | V19: 0 | W19: =M19-N19-P19-O19-Q19-R19-S19-T19+U19+V19 -> 80 | AA19: 0 | AD19: 31 | AE19: =AE18-AD19 -> 4689 | AG19: =N19+O19+P19+Q19+R19+S19+T19+W19+AA19+AD19 -> 117.2 | AH19: =IF(L19<0,L19*-1,0) -> 17.431684 | AI19: =AG19+AH19 -> 134.63168 | AJ19: 0 | AK19: 69 | AL19: 24 | AM19: =AM18+W19*1.9835 -> 405.22905
A20: =A19+1 -> 9 | B20: 6900.93 | C20: 287023 | D20: =C20-C19 -> -111 | E20: =C20-152000 -> 135023 | F20: =D20/$D$2 -> -55.961684 | G20: 75 | H20: 0.74 | I20: =G20+H20 -> 75.74 | J20: =IF(L20>0,L20,0) -> 0 | K20: =I20+J20 -> 75.74 | L20: =F20-(I20-AG20) -> -15.401684 | M20: 5.3 | N20: 0 | O20: 0 | P20: 0 | Q20: =1.56*1.02 -> 1.5912 | R20: 2.45 | S20: 0 | T20: =M20-(Q20+R20+S20) -> 1.2588 | U20: 80 | V20: 0 | W20: =M20-N20-P20-O20-Q20-R20-S20-T20+U20+V20 -> 80 | AA20: 0 | AD20: 31 | AE20: =AE19-AD20 -> 4658 | AG20: =N20+O20+P20+Q20+R20+S20+T20+W20+AA20+AD20 -> 116.3 | AH20: =IF(L20<0,L20*-1,0) -> 15.401684 | AI20: =AG20+AH20 -> 131.70168 | AJ20: 0 | AK20: 64 | AL20: 27 | AM20: =AM19+W20*1.9835 -> 563.90905
A21: =A20+1 -> 10 | B21: 6900.91 | C21: 286949 | D21: =C21-C20 -> -74 | E21: =C21-152000 -> 134949 | F21: =D21/$D$2 -> -37.307789 | G21: 75 | H21: 0.74 | I21: =G21+H21 -> 75.74 | J21: =IF(L21>0,L21,0) -> 2.8522107 | K21: =I21+J21 -> 78.592211 | L21: =F21-(I21-AG21) -> 2.8522107 | M21: 4.9 | N21: 0 | O21: 0 | P21: 0 | Q21: =1.56*1.02 -> 1.5912 | R21: 2.56 | S21: 0 | T21: =M21-(Q21+R21+S21) -> 0.7488 | U21: 80 | V21: 0 | W21: =M21-N21-P21-O21-Q21-R21-S21-T21+U21+V21 -> 80 | AA21: 0 | AD21: 31 | AE21: =AE20-AD21 -> 4627 | AG21: =N21+O21+P21+Q21+R21+S21+T21+W21+AA21+AD21 -> 115.9 | AH21: =IF(L21<0,L21*-1,0) -> 0 | AI21: =AG21+AH21 -> 115.9 | AJ21: 0 | AK21: 66 | AL21: 29 | AM21: =AM20+W21*1.9835 -> 722.58905
A22: =A21+1 -> 11 | B22: 6900.89 | C22: 286875 | D22: =C22-C21 -> -74 | E22: =C22-152000 -> 134875 | F22: =D22/$D$2 -> -37.307789 | G22: 74 | H22: 0.73 | I22: =G22+H22 -> 74.73 | J22: =IF(L22>0,L22,0) -> 3.6622107 | K22: =I22+J22 -> 78.392211 | L22: =F22-(I22-AG22) -> 3.6622107 | M22: 4.7 | N22: 0 | O22: 0 | P22: 0 | Q22: =1.56*1.02 -> 1.5912 | R22: 2.53 | S22: 0 | T22: =M22-(Q22+R22+S22) -> 0.5788 | U22: 80 | V22: 0 | W22: =M22-N22-P22-O22-Q22-R22-S22-T22+U22+V22 -> 80 | AA22: 0 | AD22: 31 | AE22: =AE21-AD22 -> 4596 | AG22: =N22+O22+P22+Q22+R22+S22+T22+W22+AA22+AD22 -> 115.7 | AH22: =IF(L22<0,L22*-1,0) -> 0 | AI22: =AG22+AH22 -> 115.7 | AJ22: 0 | AK22: 64 | AL22: 26 | AM22: =AM21+W22*1.9835 -> 881.26905
A23: =A22+1 -> 12 | B23: 6900.86 | C23: 286764 | D23: =C23-C22 -> -111 | E23: =C23-152000 -> 134764 | F23: =D23/$D$2 -> -55.961684 | G23: 72 | H23: 0.79 | I23: =G23+H23 -> 72.79 | J23: =IF(L23>0,L23,0) -> 0 | K23: =I23+J23 -> 72.79 | L23: =F23-(I23-AG23) -> -20.651684 | M23: 5.1 | N23: 0 | O23: 0 | P23: 0 | Q23: =1.56*1.02 -> 1.5912 | R23: 2.46 | S23: 0 | T23: =M23-(Q23+R23+S23) -> 1.0488 | U23: 72 | V23: 0 | W23: =M23-N23-P23-O23-Q23-R23-S23-T23+U23+V23 -> 72 | AA23: 0 | AD23: 31 | AE23: =AE22-AD23 -> 4565 | AG23: =N23+O23+P23+Q23+R23+S23+T23+W23+AA23+AD23 -> 108.1 | AH23: =IF(L23<0,L23*-1,0) -> 20.651684 | AI23: =AG23+AH23 -> 128.75168 | AJ23: 0 | AK23: 62 | AL23: 28 | AM23: =AM22+W23*1.9835 -> 1024.0811
A24: =A23+1 -> 13 | B24: 6900.84 | C24: 286690 | D24: =C24-C23 -> -74 | E24: =C24-152000 -> 134690 | F24: =D24/$D$2 -> -37.307789 | G24: 68 | H24: 0.73 | I24: =G24+H24 -> 68.73 | J24: =IF(L24>0,L24,0) -> 2.7622107 | K24: =I24+J24 -> 71.492211 | L24: =F24-(I24-AG24) -> 2.7622107 | M24: 8.8 | N24: 0 | O24: 0 | P24: 0 | Q24: =1.56*1.02 -> 1.5912 | R24: 2.42 | S24: 0 | T24: =M24-(Q24+R24+S24) -> 4.7888 | U24: 69 | V24: 0 | W24: =M24-N24-P24-O24-Q24-R24-S24-T24+U24+V24 -> 69 | AA24: 0 | AD24: 31 | AE24: =AE23-AD24 -> 4534 | AG24: =N24+O24+P24+Q24+R24+S24+T24+W24+AA24+AD24 -> 108.8 | AH24: =IF(L24<0,L24*-1,0) -> 0 | AI24: =AG24+AH24 -> 108.8 | AJ24: 0 | AK24: 63 | AL24: 25 | AM24: =AM23+W24*1.9835 -> 1160.9425
A25: =A24+1 -> 14 | B25: 6900.82 | C25: 286616 | D25: =C25-C24 -> -74 | E25: =C25-152000 -> 134616 | F25: =D25/$D$2 -> -37.307789 | G25: 61 | H25: 0.62 | I25: =G25+H25 -> 61.62 | J25: =IF(L25>0,L25,0) -> 0.47221074 | K25: =I25+J25 -> 62.092211 | L25: =F25-(I25-AG25) -> 0.47221074 | M25: 4.4 | N25: 0 | O25: 0 | P25: 0 | Q25: =1.56*1.02 -> 1.5912 | R25: 2.33 | S25: 0 | T25: =M25-(Q25+R25+S25) -> 0.4788 | U25: 64 | V25: 0 | W25: =M25-N25-P25-O25-Q25-R25-S25-T25+U25+V25 -> 64 | AA25: 0 | AD25: 31 | AE25: =AE24-AD25 -> 4503 | AG25: =N25+O25+P25+Q25+R25+S25+T25+W25+AA25+AD25 -> 99.4 | AH25: =IF(L25<0,L25*-1,0) -> 0 | AI25: =AG25+AH25 -> 99.4 | AJ25: 0 | AK25: 64 | AL25: 27 | AM25: =AM24+W25*1.9835 -> 1287.8865
A26: =A25+1 -> 15 | B26: 6900.8 | C26: 286541 | D26: =C26-C25 -> -75 | E26: =C26-152000 -> 134541 | F26: =D26/$D$2 -> -37.811949 | G26: 59 | H26: 0.67 | I26: =G26+H26 -> 59.67 | J26: =IF(L26>0,L26,0) -> 0 | K26: =I26+J26 -> 59.67 | L26: =F26-(I26-AG26) -> -1.7819486 | M26: 3.7 | N26: 0 | O26: 0 | P26: 0 | Q26: =1.56*1.02 -> 1.5912 | R26: 2.33 | S26: 0 | T26: =M26-(Q26+R26+S26) -> -0.2212 | U26: 61 | V26: 0 | W26: =M26-N26-P26-O26-Q26-R26-S26-T26+U26+V26 -> 61 | AA26: 0 | AD26: 31 | AE26: =AE25-AD26 -> 4472 | AG26: =N26+O26+P26+Q26+R26+S26+T26+W26+AA26+AD26 -> 95.7 | AH26: =IF(L26<0,L26*-1,0) -> 1.7819486 | AI26: =AG26+AH26 -> 97.481949 | AJ26: 0 | AK26: 62 | AL26: 25 | AM26: =AM25+W26*1.9835 -> 1408.88
A27: =A26+1 -> 16 | B27: 6900.78 | C27: 286467 | D27: =C27-C26 -> -74 | E27: =C27-152000 -> 134467 | F27: =D27/$D$2 -> -37.307789 | G27: 58 | H27: 0.48 | I27: =G27+H27 -> 58.48 | J27: =IF(L27>0,L27,0) -> 0 | K27: =I27+J27 -> 58.48 | L27: =F27-(I27-AG27) -> -0.38778926 | M27: 3.4 | N27: 0 | O27: 0 | P27: 0 | Q27: =1.56*1.02 -> 1.5912 | R27: 2.53 | S27: 0 | T27: =M27-(Q27+R27+S27) -> -0.7212 | U27: 61 | V27: 0 | W27: =M27-N27-P27-O27-Q27-R27-S27-T27+U27+V27 -> 61 | AA27: 0 | AD27: 31 | AE27: =AE26-AD27 -> 4441 | AG27: =N27+O27+P27+Q27+R27+S27+T27+W27+AA27+AD27 -> 95.4 | AH27: =IF(L27<0,L27*-1,0) -> 0.38778926 | AI27: =AG27+AH27 -> 95.787789 | AJ27: 0 | AK27: 63 | AL27: 26 | AM27: =AM26+W27*1.9835 -> 1529.8736
A28: =A27+1 -> 17 | B28: 6900.76 | C28: 286393 | D28: =C28-C27 -> -74 | E28: =C28-152000 -> 134393 | F28: =D28/$D$2 -> -37.307789 | G28: 57 | H28: 0.37 | I28: =G28+H28 -> 57.37 | J28: =IF(L28>0,L28,0) -> 0.62221074 | K28: =I28+J28 -> 57.992211 | L28: =F28-(I28-AG28) -> 0.62221074 | M28: 3.3 | N28: 0 | O28: 0 | P28: 0 | Q28: =1.56*1.02 -> 1.5912 | R28: 3.05 | S28: 0 | T28: =M28-(Q28+R28+S28) -> -1.3412 | U28: 61 | V28: 0 | W28: =M28-N28-P28-O28-Q28-R28-S28-T28+U28+V28 -> 61 | AA28: 0 | AD28: 31 | AE28: =AE27-AD28 -> 4410 | AG28: =N28+O28+P28+Q28+R28+S28+T28+W28+AA28+AD28 -> 95.3 | AH28: =IF(L28<0,L28*-1,0) -> 0 | AI28: =AG28+AH28 -> 95.3 | AJ28: 0 | AK28: 63 | AL28: 30 | AM28: =AM27+W28*1.9835 -> 1650.8671
A29: =A28+1 -> 18 | B29: 6900.74 | C29: 286319 | D29: =C29-C28 -> -74 | E29: =C29-152000 -> 134319 | F29: =D29/$D$2 -> -37.307789 | G29: 56 | H29: 0.25 | I29: =G29+H29 -> 56.25 | J29: =IF(L29>0,L29,0) -> 1.5422107 | K29: =I29+J29 -> 57.792211 | L29: =F29-(I29-AG29) -> 1.5422107 | M29: 3.1 | N29: 0 | O29: 0 | P29: 0 | Q29: =1.56*1.02 -> 1.5912 | R29: 2.743 | S29: 0 | T29: =M29-(Q29+R29+S29) -> -1.2342 | U29: 61 | V29: 0 | W29: =M29-N29-P29-O29-Q29-R29-S29-T29+U29+V29 -> 61 | AA29: 0 | AD29: 31 | AE29: =AE28-AD29 -> 4379 | AG29: =N29+O29+P29+Q29+R29+S29+T29+W29+AA29+AD29 -> 95.1 | AH29: =IF(L29<0,L29*-1,0) -> 0 | AI29: =AG29+AH29 -> 95.1 | AJ29: 0 | AK29: 62 | AL29: 28 | AM29: =AM28+W29*1.9835 -> 1771.8606
... A40: =A39+1 -> 29 | B40: 6900.4 | C40: 285061 | D40: =C40-C39 -> -148 | E40: =C40-152000 -> 133061 | F40: =D40/$D$2 -> -74.615579 | G40: 49 | H40: 0.27 | I40: =G40+H40 -> 49.27 | J40: =IF(L40>0,L40,0) -> 0 | K40: =I40+J40 -> 49.27 | L40: =F40-(I40-AG40) -> -30.385579 | M40: 3.5 | N40: 0 | O40: 0 | P40: 0 | Q40: =1.56*1.02 -> 1.5912 | R40: 2.29 | S40: 0 | T40: =M40-(Q40+R40+S40) -> -0.3812 | U40: 60 | V40: 0 | W40: =M40-N40-P40-O40-Q40-R40-S40-T40+U40+V40 -> 60 | AA40: 0 | AD40: 30 | AE40: =AE39-AD40 -> 4040 | AG40: =N40+O40+P40+Q40+R40+S40+T40+W40+AA40+AD40 -> 93.5 | AH40: =IF(L40<0,L40*-1,0) -> 30.385579 | AI40: =AG40+AH40 -> 123.88558 | AJ40: 0 | AK40: 44 | AL40: 12 | AM40: =AM39+W40*1.9835 -> 3094.8551
A41: 30 | B41: 6900.47 | C41: 285320 | D41: =C41-C40 -> 259 | E41: =C41-152000 -> 133320 | F41: =D41/$D$2 -> 130.57726 | G41: 55 | H41: 0.99 | I41: =G41+H41 -> 55.99 | J41: =IF(L41>0,L41,0) -> 168.98726 | K41: =I41+J41 -> 224.97726 | L41: =F41-(I41-AG41) -> 168.98726 | M41: 3.4 | N41: 0 | O41: 0 | P41: 0 | Q41: =1.56*1.02 -> 1.5912 | R41: 2.29 | S41: 0 | T41: =M41-(Q41+R41+S41) -> -0.4812 | U41: 60 | V41: 0 | W41: =M41-N41-P41-O41-Q41-R41-S41-T41+U41+V41 -> 60 | AA41: 0 | AD41: 31 | AE41: =AE40-AD41 -> 4009 | AG41: =N41+O41+P41+Q41+R41+S41+T41+W41+AA41+AD41 -> 94.4 | AH41: =IF(L41<0,L41*-1,0) -> 0 | AI41: =AG41+AH41 -> 94.4 | AJ41: 1 | AK41: 44 | AL41: 30 | AM41: =AM40+W41*1.9835 -> 3213.865
A43: MONTH / CFS | F43: =SUM(F12:F41) -> -1290.1437 | G43: =SUM(G12:G41) -> 1950 | H43: =SUM(H12:H41) -> 18.44 | I43: =SUM(I12:I41) -> 1968.44 | J43: =SUM(J12:J41) -> 184.71326 | K43: =SUM(K12:K41) -> 2153.1533 | L43: =SUM(L12:L41) -> -155.32369 | M43: =SUM(M12:M41) -> 308.5 | ... O43: =SUM(O12:O41) -> 0 | Q43: =SUM(Q12:Q41) -> 47.736 | R43: =SUM(R12:R41) -> 75.553 | S43: =SUM(S13:S41) -> 0 | T43: =SUM(T13:T41) -> 0.0082 | U43: =SUM(U12:U41) -> 1779.96 | V43: =SUM(V12:V41) -> 84.8 | W43: =SUM(W12:W41)-AN43 -> 1620.3 | AD43: =SUM(AD12:AD41) -> 930 | AF43: =SUM(AF12:AF41) -> 0 | AG43: =SUM(AG12:AG41) -> 3103.26 | AH43: =SUM(AH12:AH41) -> 340.03695 | AI43: =SUM(AI12:AI41) -> 3443.2969 | AJ43: =SUM(AJ12:AJ41) -> 1.24 | AK43: =AVERAGE(AK12:AK41) -> 56.1 | AL43: =AVERAGE(AL12:AL42) -> 23.133333 | AM43: Avg | AN43: =SUM(AN12:AN41) -> 429.6628
A44: MONTH / AF | D44: =SUM(D12:D41) -> -2559 | F44: =F43*$D$2 -> -2559 | G44: =G43*$D$2 -> 3867.825 | H44: =H43*$D$2 -> 36.57574 | I44: =I43*$D$2 -> 3904.4007 | J44: =J43*$D$2 -> 366.37876 | K44: =K43*$D$2 -> 4270.7795 | L44: =L43*$D$2 -> -308.08453 | M44: =M43*$D$2 -> 611.90975 | ... O44: =O43*$D$2 -> 0 | Q44: =Q43*$D$2 -> 94.684356 | R44: =R43*$D$2 -> 149.85938 | S44: =S43*$D$2 -> 0 | T44: =T43*$D$2 -> 0.0162647 | U44: =U43*$D$2 -> 3530.5507 | V44: =V43*$D$2 -> 168.2008 | W44: =W43*$D$2 -> 3213.865 | AD44: =AD43*$D$2 -> 1844.655 | AF44: =AF43*$D$2 -> 0 | AG44: =AG43*$D$2 -> 6155.3162 | AH44: =AH43*$D$2 -> 674.46329 | AI44: =AI43*$D$2 -> 6829.7795 | AK44: =MAX(AK12:AK41) -> 69 | AL44: =MAX(AL12:AL42) -> 30 | AM44: HI | AN44: =AN43*$D$2 -> 852.23616
A46: SEASON / CFS | AK46: =MIN(AK12:AK41) -> 36 | AL46: =MIN(AL12:AL42) -> 10 | AM46: LO
A47: SEASON / AF
A49: YTD / CFS | F49: =F10+F43 -> -1290.1437 | G49: =G10+G43 -> 1950 | H49: =H10+H43 -> 18.44 | I49: =I10+I43 -> 1968.44 | J49: =J10+J43 -> 184.71326 | K49: =K10+K43 -> 2153.1533 | L49: =L10+L43 -> -155.32369 | M49: =M10+M43 -> 308.5 | N49: =N10+N43 -> 0 | O49: 0 | Q49: =Q10+Q43 -> 47.736 | R49: =R10+R43 -> 75.553 | S49: =S10+S43 -> 0 | T49: =T10+T43 -> 0.0082 | U49: =U10+U43 -> 1779.96 | V49: =V10+V43 -> 84.8 | W49: =W10+W43 -> 1620.3 | AD49: =AD10+AD43 -> 930 | AE49: =AE41 -> 4009 | AF49: =AF10+AF43 -> 0 | AG49: =AG10+AG43 -> 3103.26 | AH49: =AH10+AH43 -> 340.03695 | AI49: =AI10+AI43 -> 3443.2969 | AJ49: =AJ10+AJ43 -> 1.24 | AN49: =AN10+AN43 -> 750.6628
A50: YTD / AF | D50: =D10+D44 -> -2559 | E50: =E41 -> 133320 | F50: =F49*$D$2 -> -2559 | G50: =G49*$D$2 -> 3867.825 | H50: =H49*$D$2 -> 36.57574 | I50: =I49*$D$2 -> 3904.4007 | J50: =J49*$D$2 -> 366.37876 | K50: =K49*$D$2 -> 4270.7795 | L50: =L49*$D$2 -> -308.08453 | M50: =M49*$D$2 -> 611.90975 | ... O50: =O49*$D$2 -> 0 | Q50: =Q49*$D$2 -> 94.684356 | R50: =R49*$D$2 -> 149.85938 | S50: =S49*$D$2 -> 0 | T50: =T49*$D$2 -> 0.0162647 | U50: =U49*$D$2 -> 3530.5507 | V50: =V49*$D$2 -> 168.2008 | W50: =W49*$D$2 -> 3213.865 | AD50: =AD49*$D$2 -> 1844.655 | AE50: =AE49*$D$2 -> 7951.8515 | AF50: =AF49*$D$2 -> 0 | AG50: =AG49*$D$2 -> 6155.3162 | AH50: =AH49*$D$2 -> 674.46329 | AI50: =AI49*$D$2 -> 6829.7795 | AM50: =AM41 -> 3213.865 | AN50: =AN49*$D$2 -> 1488.9397

Sheet DEC
K1: MCPHEE RESERVOIR INFLOW/OUTFLOW TABULATION
A2: AF/cfs CONVERT FACTOR | D2: 1.9835 | K2: DECEMBER "2007"
D4: RESERVOIR | U4: INFLOW/OUTFLOW (CFS) | AK4: WEATHER | AO4: ADJUSTMENTS
A5: DATE | B5: RESERV | C5: RESERV | D5: AC FT | E5: ACTIVE | F5: CONV TO | G5: DOLORES | H5: LOST | I5: RECORD | J5: CALC | K5: TOTAL | L5: CALC | M5: DOLORES TUNNEL | U5: LONE | V5: U | W5: TOTAL | X5: MVI | Y5: TO EX & | Z5: MVI | AA5: DV CR | AB5: D/S SENIOR | AD5: BELOW | AE5: FISH | AF5: SPILL | AG5: RECORD | AH5: CALC | AI5: TOTAL | AJ5: RAIN | AK5: MAX | AL5: MIN | AM5: NAR | AN5: MVI | AO5: MVI | AP5: MVI | AQ5: U/S | AR5: TOTTEN | AS5: UTES
A6: DEC | B6: ELEV | C6: AC FT | D6: CHANGE | E6: CAP | F6: CFS | G6: RIVER | H6: CAN | I6: INFLOW | J6: INFLOW | K6: INFLOW | L6: INF/OTF | M6: TOT DIV | N6: WET | O6: UTE | P6: QUEST | Q6: MWC | R6: CTZ | S6: CTZ & | T6: F-BAY | U6: PINE | V6: LAT | W6: MVI | X6: CALL | Y6: U/S EX | Z6: PROJ | AA6: CANAL | AD6: MCP | AE6: LEFT | AG6: OTF | AH6: OTF | AI6: OTF | AK6: TMP | AL6: TMP | AM6: CALL | AN6: STOCK | AO6: STORED | AP6: STORED | AQ6: USERS | AR6: (FRESH | AS6: FROM
E7: AC FT | N7: LAND | O7: F&R | S7: UTE | T7: SPILL | AM7: AC.FT. | AN7: CFS | AO7: Apr-Jun | AP7: EVAP | AQ7: EXCH | AR7: WATER) | AS7: MVIC
N8: 1.03 | O8: 1.05 | P8: 1.02 | Q8: 1.02 | R8: 1.04 | S8: PROJ | AP8: AC.FT.
A9: SEASON BAL
A10: YTD | B10: =NOV!B41 -> 6900.47 | C10: =NOV!C41 -> 285320 | D10: =NOV!D50 -> -2559 | E10: =NOV!E50 -> 133320 | F10: =NOV!F49 -> -1290.1437 | G10: =NOV!G49 -> 1950 | H10: =NOV!H49 -> 18.44 | I10: =NOV!I49 -> 1968.44 | J10: =NOV!J49 -> 184.71326 | K10: =NOV!K49 -> 2153.1533 | L10: =NOV!L49 -> -155.32369 | M10: =NOV!M49 -> 308.5 | ... O10: =NOV!O49 -> 0 | Q10: =NOV!Q49 -> 47.736 | R10: =NOV!R49 -> 75.553 | S10: =NOV!S49 -> 0 | T10: =NOV!T49 -> 0.0082 | U10: =NOV!U49 -> 1779.96 | V10: =NOV!V49 -> 84.8 | W10: =NOV!W49 -> 1620.3 | AD10: =NOV!AD49 -> 930 | AE10: =NOV!AE49 -> 4009 | AF10: =NOV!AF49 -> 0 | AG10: =NOV!AG49 -> 3103.26 | AH10: =NOV!AH49 -> 340.03695 | AI10: =NOV!AI49 -> 3443.2969 | AJ10: =NOV!AJ49 -> 1.24 | AM10: =NOV!AM50 -> 3213.865 | AN10: =NOV!AN49 -> 750.6628
A12: 1 | B12: 6900.7 | C12: 286171 | D12: =C12-C10 -> 851 | E12: =C12-152000 -> 134171 | F12: =D12/$D$2 -> 429.03958 | G12: 251 | H12: 12 | I12: =G12+H12 -> 263 | J12: =IF(L12>0,L12,0) -> 261.13958 | K12: =I12+J12 -> 524.13958 | L12: =F12-(I12-AG12) -> 261.13958 | M12: 3.1 | N12: 0 | O12: 0 | P12: 0 | Q12: =1.38*1.02 -> 1.4076 | R12: 2.28 | S12: 0 | T12: =M12-(Q12+R12+S12) -> -0.5876 | U12: 60 | V12: 0 | W12: =M12-N12-O12-P12-Q12-R12-S12-T12+U12+V12 -> 60 | AA12: 0 | AD12: 32 | AE12: =AE10-AD12 -> 3977 | AG12: =N12+O12+P12+Q12+R12+S12+T12+W12+AA12+AD12 -> 95.1 | AH12: =IF(L12<0,L12*-1,0) -> 0 | AI12: =AG12+AH12 -> 95.1 | AJ12: 0.84 | AK12: 44 | AL12: 33 | AM12: =AM10+(W12*1.9835) -> 3332.8751 | AN12: 0
A13: =A12+1 -> 2 | B13: 6900.77 | C13: 286430 | D13: =C13-C12 -> 259 | E13: =C13-152000 -> 134430 | F13: =D13/$D$2 -> 130.57726 | G13: 168 | H13: 6.2 | I13: =G13+H13 -> 174.2 | J13: =IF(L13>0,L13,0) -> 51.677262 | K13: =I13+J13 -> 225.87726 | L13: =F13-(I13-AG13) -> 51.677262 | M13: 3.3 | N13: 0 | O13: 0 | P13: 0 | Q13: =1.38*1.02 -> 1.4076 | R13: 2.3 | S13: 0 | T13: =M13-(Q13+R13+S13) -> -0.4076 | U13: 61 | V13: 0 | W13: =M13-N13-O13-P13-Q13-R13-S13-T13+U13+V13 -> 61 | AA13: 0 | AD13: 31 | AE13: =AE12-AD13 -> 3946 | AG13: =N13+O13+P13+Q13+R13+S13+T13+W13+AA13+AD13 -> 95.3 | AH13: =IF(L13<0,L13*-1,0) -> 0 | AI13: =AG13+AH13 -> 95.3 | AJ13: 0 | AK13: 38 | AL13: 25 | AM13: =AM12+(W13*1.9835) -> 3453.8686 | AN13: 0
A14: =A13+1 -> 3 | B14: 6900.75 | C14: 286356 | D14: =C14-C13 -> -74 | E14: =C14-152000 -> 134356 | F14: =D14/$D$2 -> -37.307789 | G14: 110 | H14: 2.8 | I14: =G14+H14 -> 112.8 | J14: =IF(L14>0,L14,0) -> 0 | K14: =I14+J14 -> 112.8 | L14: =F14-(I14-AG14) -> -55.507789 | M14: 3.6 | N14: 0 | O14: 0 | P14: 0 | Q14: =1.38*1.02 -> 1.4076 | R14: 2.26 | S14: 0 | T14: =M14-(Q14+R14+S14) -> -0.0676 | U14: 60 | V14: 0 | W14: =M14-N14-O14-P14-Q14-R14-S14-T14+U14+V14 -> 60 | AA14: 0 | AD14: 31 | AE14: =AE13-AD14 -> 3915 | AG14: =N14+O14+P14+Q14+R14+S14+T14+W14+AA14+AD14 -> 94.6 | AH14: =IF(L14<0,L14*-1,0) -> 55.507789 | AI14: =AG14+AH14 -> 150.10779 | AJ14: 0 | AK14: 46 | AL14: 21 | AM14: =AM13+(W14*1.9835) -> 3572.8785 | AN14: 0
A15: =A14+1 -> 4 | B15: 6900.73 | C15: 286282 | D15: =C15-C14 -> -74 | E15: =C15-152000 -> 134282 | F15: =D15/$D$2 -> -37.307789 | G15: 90 | H15: 1.9 | I15: =G15+H15 -> 91.9 | J15: =IF(L15>0,L15,0) -> 0 | K15: =I15+J15 -> 91.9 | L15: =F15-(I15-AG15) -> -35.107789 | M15: 3.1 | N15: 0 | O15: 0 | P15: 0 | Q15: =1.38*1.02 -> 1.4076 | R15: 2.26 | S15: 0 | T15: =M15-(Q15+R15+S15) -> -0.5676 | U15: 60 | V15: 0 | W15: =M15-N15-O15-P15-Q15-R15-S15-T15+U15+V15 -> 60 | AA15: 0 | AD15: 31 | AE15: =AE14-AD15 -> 3884 | AG15: =N15+O15+P15+Q15+R15+S15+T15+W15+AA15+AD15 -> 94.1 | AH15: =IF(L15<0,L15*-1,0) -> 35.107789 | AI15: =AG15+AH15 -> 129.20779 | AJ15: 0 | AK15: 49 | AL15: 26 | AM15: =AM14+(W15*1.9835) -> 3691.8886 | AN15: 0
A16: =A15+1 -> 5 | B16: 6900.71 | C16: 286208 | D16: =C16-C15 -> -74 | E16: =C16-152000 -> 134208 | F16: =D16/$D$2 -> -37.307789 | G16: 84 | H16: 1.7 | I16: =G16+H16 -> 85.7 | J16: =IF(L16>0,L16,0) -> 0 | K16: =I16+J16 -> 85.7 | L16: =F16-(I16-AG16) -> -28.207789 | M16: 3.8 | N16: 0 | O16: 0 | P16: 0 | Q16: =1.38*1.02 -> 1.4076 | R16: 2.22 | S16: 0 | T16: =M16-(Q16+R16+S16) -> 0.1724 | U16: 60 | V16: 0 | W16: =M16-N16-O16-P16-Q16-R16-S16-T16+U16+V16 -> 60 | AA16: 0 | AD16: 31 | AE16: =AE15-AD16 -> 3853 | AG16: =N16+O16+P16+Q16+R16+S16+T16+W16+AA16+AD16 -> 94.8 | AH16: =IF(L16<0,L16*-1,0) -> 28.207789 | AI16: =AG16+AH16 -> 123.00779 | AJ16: 0 | AK16: 44 | AL16: 27 | AM16: =AM15+(W16*1.9835) -> 3810.8985 | AN16: 0
A17: =A16+1 -> 6 | B17: 6900.69 | C17: 286134 | D17: =C17-C16 -> -74 | E17: =C17-152000 -> 134134 | F17: =D17/$D$2 -> -37.307789 | G17: 79 | H17: 1.6 | I17: =G17+H17 -> 80.6 | J17: =IF(L17>0,L17,0) -> 0 | K17: =I17+J17 -> 80.6 | L17: =F17-(I17-AG17) -> -22.907789 | M17: 4 | N17: 0 | O17: 0 | P17: 0 | Q17: =1.38*1.02 -> 1.4076 | R17: 2.25 | S17: 0 | T17: =M17-(Q17+R17+S17) -> 0.3424 | U17: 60 | V17: 0 | W17: =M17-N17-O17-P17-Q17-R17-S17-T17+U17+V17 -> 60 | AA17: 0 | AD17: 31 | AE17: =AE16-AD17 -> 3822 | AG17: =N17+O17+P17+Q17+R17+S17+T17+W17+AA17+AD17 -> 95 | AH17: =IF(L17<0,L17*-1,0) -> 22.907789 | AI17: =AG17+AH17 -> 117.90779 | AJ17: 0.2 | AK17: 46 | AL17: 30 | AM17: =AM16+(W17*1.9835) -> 3929.9086 | AN17: 0
A18: =A17+1 -> 7 | B18: 6900.81 | C18: 286579 | D18: =C18-C17 -> 445 | E18: =C18-152000 -> 134579 | F18: =D18/$D$2 -> 224.35089 | G18: 98 | H18: 6.2 | I18: =G18+H18 -> 104.2 | J18: =IF(L18>0,L18,0) -> 215.85089 | K18: =I18+J18 -> 320.05089 | L18: =F18-(I18-AG18) -> 215.85089 | M18: 3.7 | N18: 0 | O18: 0 | P18: 0 | Q18: =1.38*1.02 -> 1.4076 | R18: 2.29 | S18: 0 | T18: =M18-(Q18+R18+S18) -> 0.0024 | U18: 60 | V18: 0 | W18: =M18-N18-O18-P18-Q18-R18-S18-T18+U18+V18 -> 60 | AA18: 0 | AD18: 32 | AE18: =AE17-AD18 -> 3790 | AG18: =N18+O18+P18+Q18+R18+S18+T18+W18+AA18+AD18 -> 95.7 | AH18: =IF(L18<0,L18*-1,0) -> 0 | AI18: =AG18+AH18 -> 95.7 | AJ18: 0.93 | AK18: 44 | AL18: 33 | AM18: =AM17+(W18*1.9835) -> 4048.9185 | AN18: 0
A19: =A18+1 -> 8 | B19: 6900.9 | C19: 286912 | D19: =C19-C18 -> 333 | E19: =C19-152000 -> 134912 | F19: =D19/$D$2 -> 167.88505 | G19: 150 | H19: 15 | I19: =G19+H19 -> 165 | J19: =IF(L19>0,L19,0) -> 97.485052 | K19: =I19+J19 -> 262.48505 | L19: =F19-(I19-AG19) -> 97.485052 | M19: 3.6 | N19: 0 | O19: 0 | P19: 0 | Q19: =1.38*1.02 -> 1.4076 | R19: 2.32 | S19: 0 | T19: =M19-(Q19+R19+S19) -> -0.1276 | U19: 60 | V19: 0 | W19: =M19-N19-O19-P19-Q19-R19-S19-T19+U19+V19 -> 60 | AA19: 0 | AD19: 31 | AE19: =AE18-AD19 -> 3759 | AG19: =N19+O19+P19+Q19+R19+S19+T19+W19+AA19+AD19 -> 94.6 | AH19: =IF(L19<0,L19*-1,0) -> 0 | AI19: =AG19+AH19 -> 94.6 | AJ19: 0.37 | AK19: 38 | AL19: 26 | AM19: =AM18+(W19*1.9835) -> 4167.9285 | AN19: 0
A20: =A19+1 -> 9 | B20: 6900.96 | C20: 287134 | D20: =C20-C19 -> 222 | E20: =C20-152000 -> 135134 | F20: =D20/$D$2 -> 111.92337 | G20: 113 | H20: 7.4 | I20: =G20+H20 -> 120.4 | J20: =IF(L20>0,L20,0) -> 86.923368 | K20: =I20+J20 -> 207.32337 | L20: =F20-(I20-AG20) -> 86.923368 | M20: 3.4 | N20: 0 | O20: 0 | P20: 0 | Q20: =1.38*1.02 -> 1.4076 | R20: 2.29 | S20: 0 | T20: =M20-(Q20+R20+S20) -> -0.2976 | U20: 61 | V20: 0 | W20: =M20-N20-O20-P20-Q20-R20-S20-T20+U20+V20 -> 61 | AA20: 0 | AD20: 31 | AE20: =AE19-AD20 -> 3728 | AG20: =N20+O20+P20+Q20+R20+S20+T20+W20+AA20+AD20 -> 95.4 | AH20: =IF(L20<0,L20*-1,0) -> 0 | AI20: =AG20+AH20 -> 95.4 | AJ20: 0 | AK20: 34 | AL20: 19 | AM20: =AM19+(W20*1.9835) -> 4288.9221 | AN20: 0
A21: =A20+1 -> 10 | B21: 6900.92 | C21: 286986 | D21: =C21-C20 -> -148 | E21: =C21-152000 -> 134986 | F21: =D21/$D$2 -> -74.615579 | G21: 98 | H21: 5.4 | I21: =G21+H21 -> 103.4 | J21: =IF(L21>0,L21,0) -> 0 | K21: =I21+J21 -> 103.4 | L21: =F21-(I21-AG21) -> -65.415579 | M21: 3.6 | N21: 0 | O21: 0 | P21: 0 | Q21: =1.38*1.02 -> 1.4076 | R21: 2.26 | S21: 0 | T21: =M21-(Q21+R21+S21) -> -0.0676 | U21: 78 | V21: 0 | W21: =M21-N21-O21-P21-Q21-R21-S21-T21+U21+V21 -> 78 | AA21: 0 | AD21: 31 | AE21: =AE20-AD21 -> 3697 | AG21: =N21+O21+P21+Q21+R21+S21+T21+W21+AA21+AD21 -> 112.6 | AH21: =IF(L21<0,L21*-1,0) -> 65.415579 | AI21: =AG21+AH21 -> 178.01558 | AJ21: 0.16 | AK21: 39 | AL21: 25 | AM21: =AM20+(W21*1.9835) -> 4443.635 | AN21: 0
A22: =A21+1 -> 11 | B22: 6900.97 | C22: 287171 | D22: =C22-C21 -> 185 | E22: =C22-152000 -> 135171 | F22: =D22/$D$2 -> 93.269473 | G22: 90 | H22: 4.1 | I22: =G22+H22 -> 94.1 | J22: =IF(L22>0,L22,0) -> 124.76947 | K22: =I22+J22 -> 218.86947 | L22: =F22-(I22-AG22) -> 124.76947 | M22: 3.6 | N22: 0 | O22: 0 | P22: 0 | Q22: =1.38*1.02 -> 1.4076 | R22: 2.32 | S22: 0 | T22: =M22-(Q22+R22+S22) -> -0.1276 | U22: 91 | V22: 0 | W22: =M22-N22-O22-P22-Q22-R22-S22-T22+U22+V22 -> 91 | AA22: 0 | AD22: 31 | AE22: =AE21-AD22 -> 3666 | AG22: =N22+O22+P22+Q22+R22+S22+T22+W22+AA22+AD22 -> 125.6 | AH22: =IF(L22<0,L22*-1,0) -> 0 | AI22: =AG22+AH22 -> 125.6 | AJ22: 0.12 | AK22: 34 | AL22: 22 | AM22: =AM21+(W22*1.9835) -> 4624.1335 | AN22: 0
A23: =A22+1 -> 12 | B23: 6900.99 | C23: 287245 | D23: =C23-C22 -> 74 | E23: =C23-152000 -> 135245 | F23: =D23/$D$2 -> 37.307789 | G23: 72 | H23: 2.9 | I23: =G23+H23 -> 74.9 | J23: =IF(L23>0,L23,0) -> 86.907789 | K23: =I23+J23 -> 161.80779 | L23: =F23-(I23-AG23) -> 86.907789 | M23: 3.5 | N23: 0 | O23: 0 | P23: 0 | Q23: =1.38*1.02 -> 1.4076 | R23: 2.45 | S23: 0 | T23: =M23-(Q23+R23+S23) -> -0.3576 | U23: 90 | V23: 0 | W23: =M23-N23-O23-P23-Q23-R23-S23-T23+U23+V23 -> 90 | AA23: 0 | AD23: 31 | AE23: =AE22-AD23 -> 3635 | AG23: =N23+O23+P23+Q23+R23+S23+T23+W23+AA23+AD23 -> 124.5 | AH23: =IF(L23<0,L23*-1,0) -> 0 | AI23: =AG23+AH23 -> 124.5 | AJ23: 0 | AK23: 33 | AL23: 12 | AM23: =AM22+(W23*1.9835) -> 4802.6485 | AN23: 0
A24: =A23+1 -> 13 | B24: 6900.96 | C24: 287134 | D24: =C24-C23 -> -111 | E24: =C24-152000 -> 135134 | F24: =D24/$D$2 -> -55.961684 | G24: 70 | H24: 2.3 | I24: =G24+H24 -> 72.3 | J24: =IF(L24>0,L24,0) -> 0 | K24: =I24+J24 -> 72.3 | L24: =F24-(I24-AG24) -> -3.5616839 | M24: 3.7 | N24: 0 | O24: 0 | P24: 0 | Q24: =1.38*1.02 -> 1.4076 | R24: 2.55 | S24: 0 | T24: =M24-(Q24+R24+S24) -> -0.2576 | U24: 90 | V24: 0 | W24: =M24-N24-O24-P24-Q24-R24-S24-T24+U24+V24 -> 90 | AA24: 0 | AD24: 31 | AE24: =AE23-AD24 -> 3604 | AG24: =N24+O24+P24+Q24+R24+S24+T24+W24+AA24+AD24 -> 124.7 | AH24: =IF(L24<0,L24*-1,0) -> 3.5616839 | AI24: =AG24+AH24 -> 128.26168 | AJ24: 0 | AK24: 32 | AL24: 12 | AM24: =AM23+(W24*1.9835) -> 4981.1636 | AN24: 0
... A40: =A39+1 -> 29 | B40: 6900.7 | C40: 286171 | D40: =C40-C39 -> -37 | E40: =C40-152000 -> 134171 | F40: =D40/$D$2 -> -18.653895 | G40: 71 | H40: 2.4 | I40: =G40+H40 -> 73.4 | J40: =IF(L40>0,L40,0) -> 0 | K40: =I40+J40 -> 73.4 | L40: =F40-(I40-AG40) -> -20.653895 | M40: 3.4 | N40: 0 | O40: 0 | P40: 0 | Q40: =1.38*1.02 -> 1.4076 | R40: 2.52 | S40: 0 | T40: =M40-(Q40+R40+S40) -> -0.5276 | U40: 37 | V40: 0 | W40: =M40-N40-O40-P40-Q40-R40-S40-T40+U40+V40 -> 37 | AA40: 0 | AD40: 31 | AE40: =AE39-AD40 -> 3109 | AG40: =N40+O40+P40+Q40+R40+S40+T40+W40+AA40+AD40 -> 71.4 | AH40: =IF(L40<0,L40*-1,0) -> 20.653895 | AI40: =AG40+AH40 -> 92.053895 | AJ40: 0 | AK40: 28 | AL40: 0 | AM40: =AM39+(W40*1.9835) -> 6548.1286 | AN40: 0
A41: 30 | B41: 6900.69 | C41: 286134 | D41: =C41-C40 -> -37 | E41: =C41-152000 -> 134134 | F41: =D41/$D$2 -> -18.653895 | G41: 71 | H41: 2.2 | I41: =G41+H41 -> 73.2 | J41: =IF(L41>0,L41,0) -> 0 | K41: =I41+J41 -> 73.2 | L41: =F41-(I41-AG41) -> -20.453895 | M41: 3.4 | N41: 0 | O41: 0 | P41: 0 | Q41: =1.38*1.02 -> 1.4076 | R41: 2.52 | S41: 0 | T41: =M41-(Q41+R41+S41) -> -0.5276 | U41: 37 | V41: 0 | W41: =M41-N41-O41-P41-Q41-R41-S41-T41+U41+V41 -> 37 | AA41: 0 | AD41: 31 | AE41: =AE40-AD41 -> 3078 | AG41: =N41+O41+P41+Q41+R41+S41+T41+W41+AA41+AD41 -> 71.4 | AH41: =IF(L41<0,L41*-1,0) -> 20.453895 | AI41: =AG41+AH41 -> 91.853895 | AJ41: 0 | AK41: 31 | AL41: 7 | AM41: =AM40+(W41*1.9835) -> 6621.518 | AN41: 0
A42: 31 | B42: 6900.68 | C42: 286097 | D42: =C42-C41 -> -37 | E42: =C42-152000 -> 134097 | F42: =D42/$D$2 -> -18.653895 | G42: 71 | H42: 2.2 | I42: =G42+H42 -> 73.2 | J42: =IF(L42>0,L42,0) -> 0 | K42: =I42+J42 -> 73.2 | L42: =F42-(I42-AG42) -> -20.453895 | M42: 3.4 | N42: 0 | O42: 0 | P42: 0 | Q42: =1.38*1.02 -> 1.4076 | R42: 2.4 | S42: 0 | T42: =M42-(Q42+R42+S42) -> -0.4076 | U42: 37 | V42: 0 | W42: =M42-N42-O42-P42-Q42-R42-S42-T42+U42+V42 -> 37 | AA42: 0 | AD42: 31 | AE42: =AE41-AD42 -> 3047 | AG42: =N42+O42+P42+Q42+R42+S42+T42+W42+AA42+AD42 -> 71.4 | AH42: =IF(L42<0,L42*-1,0) -> 20.453895 | AI42: =AG42+AH42 -> 91.853895 | AJ42: 0 | AK42: 29 | AL42: 8 | AM42: =AM41+(W42*1.9835) -> 6694.9075 | AN42: 0
W43: =M43-N43-O43-Q43-R43-S43+U43+V43 -> 0 | AG43: =N43+O43+Q43+R43+S43+W43+AA43+AD43 -> 0
A44: MONTH / CFS | F44: =SUM(F12:F42) -> 391.73179 | G44: =SUM(G12:G42) -> 2771 | H44: =SUM(H12:H42) -> 100.01 | I44: =SUM(I12:I42) -> 2871.01 | J44: =SUM(J12:J42) -> 995.20731 | K44: =SUM(K12:K42) -> 3866.2173 | L44: =SUM(L12:L42) -> 343.52179 | M44: =SUM(M12:M43) -> 105.8 | N44: =SUM(N12:N42) -> 0 | O44: =SUM(O12:O42) -> 0 | Q44: =SUM(Q12:Q42) -> 43.6356 | R44: =SUM(R12:R42) -> 75.84 | S44: =SUM(S12:S42) -> 0 | T44: =SUM(T12:T42) -> -13.6756 | U44: =SUM(U12:U42) -> 1755 | V44: =SUM(V12:V42) -> 0 | W44: =SUM(W12:W43) -> 1755 | AD44: =SUM(AD12:AD43) -> 962 | AF44: =SUM(AF13:AF42) -> 0 | AG44: =SUM(AG12:AG43) -> 2822.8 | AH44: =SUM(AH12:AH42) -> 651.68552 | AI44: =SUM(AI12:AI42) -> 3474.4855 | AJ44: =SUM(AJ12:AJ42) -> 2.81 | AK44: =AVERAGE(AK12:AK42) -> 35.580645 | AL44: =AVERAGE(AL12:AL42) -> 15.16129 | AM44: Avg | AN44: =SUM(AN12:AN42) -> 0
A45: MONTH / AF | D45: =SUM(D12:D42) -> 777 | F45: =F44*$D$2 -> 777 | G45: =G44*$D$2 -> 5496.2785 | H45: =H44*$D$2 -> 198.36983 | I45: =I44*$D$2 -> 5694.6483 | J45: =J44*$D$2 -> 1973.9937 | K45: =K44*$D$2 -> 7668.642 | L45: =L44*$D$2 -> 681.37546 | M45: =M44*$D$2 -> 209.8543 | ... O45: =O44*$D$2 -> 0 | Q45: =Q44*$D$2 -> 86.551213 | R45: =R44*$D$2 -> 150.42864 | S45: =S44*$D$2 -> 0 | T45: =T44*$D$2 -> -27.125553 | U45: =U44*$D$2 -> 3481.0425 | V45: =V44*$D$2 -> 0 | W45: =W44*$D$2 -> 3481.0425 | AD45: =AD44*$D$2 -> 1908.127 | AF45: =AF44*$D$2 -> 0 | AG45: =AG44*$D$2 -> 5599.0238 | AH45: =AH44*$D$2 -> 1292.6182 | AI45: =AI44*$D$2 -> 6891.642 | AK45: =MAX(AK12:AK42) -> 49 | AL45: =MAX(AL12:AL42) -> 33 | AM45: HI | AN45: =AN44*$D$2 -> 0
A47: SEASON / CFS | AK47: =MIN(AK12:AK42) -> 21 | AL47: =MIN(AL12:AL42) -> -2 | AM47: LO
A48: SEASON / AF
A50: YTD / CFS | F50: =F10+F44 -> -898.4119 | G50: =G10+G44 -> 4721 | H50: =H10+H44 -> 118.45 | I50: =I10+I44 -> 4839.45 | J50: =J10+J44 -> 1179.9206 | K50: =K10+K44 -> 6019.3706 | L50: =L10+L44 -> 188.1981 | M50: =M10+M44 -> 414.3 | N50: =N10+N44 -> 0 | O50: 0 | Q50: =Q10+Q44 -> 91.3716 | R50: =R10+R44 -> 151.393 | S50: =S10+S44 -> 0 | T50: =T10+T44 -> -13.6674 | U50: =U10+U44 -> 3534.96 | V50: =V10+V44 -> 84.8 | W50: =W10+W44 -> 3375.3 | AD50: =AD10+AD44 -> 1892 | AE50: =AE42 -> 3047 | AF50: =AF11+AF44 -> 0 | AG50: =AG10+AG44 -> 5926.06 | AH50: =AH10+AH44 -> 991.72247 | AI50: =AI10+AI44 -> 6917.7825 | AJ50: =AJ10+AJ44 -> 4.05 | AN50: =AN10+AN44 -> 750.6628
A51: YTD / AF | D51: =D10+D45 -> -1782 | E51: =E42 -> 134097 | F51: =F50*$D$2 -> -1782 | G51: =G50*$D$2 -> 9364.1035 | H51: =H50*$D$2 -> 234.94557 | I51: =I50*$D$2 -> 9599.0491 | J51: =J50*$D$2 -> 2340.3725 | K51: =K50*$D$2 -> 11939.422 | L51: =L50*$D$2 -> 373.29093 | M51: =M50*$D$2 -> 821.76405 | ... O51: =O50*$D$2 -> 0 | Q51: =Q50*$D$2 -> 181.23557 | R51: =R50*$D$2 -> 300.28802 | S51: =S50*$D$2 -> 0 | T51: =T50*$D$2 -> -27.109288 | U51: =U50*$D$2 -> 7011.5932 | V51: =V50*$D$2 -> 168.2008 | W51: =W50*$D$2 -> 6694.9075 | AD51: =AD50*$D$2 -> 3752.782 | AE51: =AE50*$D$2 -> 6043.7245 | AF51: =AF50*$D$2 -> 0 | AG51: =AG50*$D$2 -> 11754.34 | AH51: =AH50*$D$2 -> 1967.0815 | AI51: =AI50*$D$2 -> 13721.422 | AM51: =AM42 -> 6694.9075 | AN51: =AN50*$D$2 -> 1488.9397

Sheet JAN
K1: MCPHEE RESERVOIR INFLOW/OUTFLOW TABULATION
A2: AF/cfs CONVERT FACTOR | D2: 1.9835 | K2: JANUARY "2008"
D4: RESERVOIR | U4: INFLOW/OUTFLOW (CFS) | AK4: WEATHER | AO4: ADJUSTMENTS
A5: DATE | B5: RESERV | C5: RESERV | D5: AC FT | E5: ACTIVE | F5: CONV TO | G5: DOLORES | H5: LOST | I5: RECORD | J5: CALC | K5: TOTAL | L5: CALC | M5: DOLORES TUNNEL | U5: LONE | V5: U | W5: TOTAL | X5: MVI | Y5: TO EX & | Z5: MVI | AA5: DV CR | AB5: D/S SENIOR | AD5: BELOW | AE5: FISH | AF5: SPILL | AG5: RECORD | AH5: CALC | AI5: TOTAL | AJ5: RAIN | AK5: MAX | AL5: MIN | AM5: NAR | AN5: MVI | AO5: MVI | AP5: MVI | AQ5: U/S | AR5: TOTTEN | AS5: UTES
A6: JAN | B6: ELEV | C6: AC FT | D6: CHANGE | E6: CAP | F6: CFS | G6: RIVER | H6: CAN | I6: INFLOW | J6: INFLOW | K6: INFLOW | L6: INF/OTF | M6: TOT DIV | N6: WET | O6: UTE | P6: QUEST | Q6: MWC | R6: CTZ | S6: CTZ & | T6: F-BAY | U6: PINE | V6: LAT | W6: MVI | X6: CALL | Y6: U/S EX | Z6: PROJ | AA6: CANAL | AD6: MCP | AE6: LEFT | AG6: OTF | AH6: OTF | AI6: OTF | AK6: TMP | AL6: TMP | AM6: CALL | AN6: STOCK | AO6: STORED | AP6: STORED | AQ6: USERS | AR6: (FRESH | AS6: FROM
E7: AC FT | N7: LAND | O7: F&R | S7: UTE | T7: SPILL | AM7: AC.FT. | AN7: CFS | AO7: Apr-Jun | AP7: EVAP | AQ7: EXCH | AR7: WATER) | AS7: MVIC
N8: 1.03 | O8: 1.05 | P8: 1.02 | Q8: 1.02 | R8: 1.04 | S8: PROJ | AP8: AC.FT.
A9: SEASON BAL
A10: YTD | B10: =DEC!B42 -> 6900.68 | C10: =DEC!C42 -> 286097 | D10: =DEC!D51 -> -1782 | E10: =DEC!E51 -> 134097 | F10: =DEC!F50 -> -898.4119 | G10: =DEC!G50 -> 4721 | H10: =DEC!H50 -> 118.45 | I10: =DEC!I50 -> 4839.45 | J10: =DEC!J50 -> 1179.9206 | K10: =DEC!K50 -> 6019.3706 | L10: =DEC!L50 -> 188.1981 | M10: =DEC!M50 -> 414.3 | ... O10: =DEC!O50 -> 0 | Q10: =DEC!Q50 -> 91.3716 | R10: =DEC!R50 -> 151.393 | S10: =DEC!S50 -> 0 | T10: =DEC!T50 -> -13.6674 | U10: =DEC!U50 -> 3534.96 | V10: =DEC!V50 -> 84.8 | W10: =DEC!W50 -> 3375.3 | AD10: =DEC!AD50 -> 1892 | AE10: =DEC!AE50 -> 3047 | AF10: =DEC!AF50 -> 0 | AG10: =DEC!AG50 -> 5926.06 | AH10: =DEC!AH50 -> 991.72247 | AI10: =DEC!AI50 -> 6917.7825 | AJ10: =DEC!AJ50 -> 4.05 | AM10: =DEC!AM51 -> 6694.9075
A12: 1 | B12: 6900.67 | C12: 286060 | D12: =C12-C10 -> -37 | E12: =C12-152000 -> 134060 | F12: =D12/$D$2 -> -18.653895 | G12: 71 | H12: 2.2 | I12: =G12+H12 -> 73.2 | J12: =IF(L12>0,L12,0) -> 0 | K12: =I12+J12 -> 73.2 | L12: =F12-(I12-AG12) -> -20.453895 | M12: 3.4 | N12: 0 | O12: 0 | P12: 0 | Q12: =1.51*1.02 -> 1.5402 | R12: 2.42 | S12: 0 | T12: =M12-(Q12+R12+S12) -> -0.5602 | U12: 37 | V12: 0 | W12: =M12-N12-O12-P12-Q12-R12-S12-T12+U12+V12 -> 37 | AA12: 0 | AD12: 31 | AE12: =AE10-AD12 -> 3016 | AG12: =N12+O12+P12+Q12+R12+S12+T12+W12+AA12+AD12 -> 71.4 | AH12: =IF(L12<0,L12*-1,0) -> 20.453895 | AI12: =AG12+AH12 -> 91.853895 | AJ12: 0 | AK12: 30 | AL12: 0 | AM12: =AM10+(W12*1.9835) -> 6768.2971
A13: =A12+1 -> 2 | B13: 6900.66 | C13: 286023 | D13: =C13-C12 -> -37 | E13: =C13-152000 -> 134023 | F13: =D13/$D$2 -> -18.653895 | G13: 71 | H13: 2 | I13: =G13+H13 -> 73 | J13: =IF(L13>0,L13,0) -> 0 | K13: =I13+J13 -> 73 | L13: =F13-(I13-AG13) -> -20.153895 | M13: 3.5 | N13: 0 | O13: 0 | P13: 0 | Q13: =1.51*1.02 -> 1.5402 | R13: 2.59 | S13: 0 | T13: =M13-(Q13+R13+S13) -> -0.6302 | U13: 37 | V13: 0 | W13: =M13-N13-O13-P13-Q13-R13-S13-T13+U13+V13 -> 37 | AA13: 0 | AD13: 31 | AE13: =AE12-AD13 -> 2985 | AG13: =N13+O13+P13+Q13+R13+S13+T13+W13+AA13+AD13 -> 71.5 | AH13: =IF(L13<0,L13*-1,0) -> 20.153895 | AI13: =AG13+AH13 -> 91.653895 | AJ13: 0 | AK13: 40 | AL13: 8 | AM13: =AM12+(W13*1.9835) -> 6841.6866
A14: =A13+1 -> 3 | B14: 6900.64 | C14: 285949 | D14: =C14-C13 -> -74 | E14: =C14-152000 -> 133949 | F14: =D14/$D$2 -> -37.307789 | G14: 71 | H14: 1.7 | I14: =G14+H14 -> 72.7 | J14: =IF(L14>0,L14,0) -> 0 | K14: =I14+J14 -> 72.7 | L14: =F14-(I14-AG14) -> -38.607789 | M14: 3.4 | N14: 0 | O14: 0 | P14: 0 | Q14: =1.51*1.02 -> 1.5402 | R14: 2.61 | S14: 0 | T14: =M14-(Q14+R14+S14) -> -0.7502 | U14: 37 | V14: 0 | W14: =M14-N14-O14-P14-Q14-R14-S14-T14+U14+V14 -> 37 | AA14: 0 | AD14: 31 | AE14: =AE13-AD14 -> 2954 | AG14: =N14+O14+P14+Q14+R14+S14+T14+W14+AA14+AD14 -> 71.4 | AH14: =IF(L14<0,L14*-1,0) -> 38.607789 | AI14: =AG14+AH14 -> 110.00779 | AJ14: 0 | AK14: 47 | AL14: 17 | AM14: =AM13+(W14*1.9835) -> 6915.076
A15: =A14+1 -> 4 | B15: 6900.62 | C15: 285875 | D15: =C15-C14 -> -74 | E15: =C15-152000 -> 133875 | F15: =D15/$D$2 -> -37.307789 | G15: 71 | H15: 1.7 | I15: =G15+H15 -> 72.7 | J15: =IF(L15>0,L15,0) -> 0 | K15: =I15+J15 -> 72.7 | L15: =F15-(I15-AG15) -> -37.607789 | M15: 3.4 | N15: 0 | O15: 0 | P15: 0 | Q15: =1.51*1.02 -> 1.5402 | R15: 2.74 | S15: 0 | T15: =M15-(Q15+R15+S15) -> -0.8802 | U15: 38 | V15: 0 | W15: =M15-N15-O15-P15-Q15-R15-S15-T15+U15+V15 -> 38 | AA15: 0 | AD15: 31 | AE15: =AE14-AD15 -> 2923 | AG15: =N15+O15+P15+Q15+R15+S15+T15+W15+AA15+AD15 -> 72.4 | AH15: =IF(L15<0,L15*-1,0) -> 37.607789 | AI15: =AG15+AH15 -> 110.00779 | AJ15: 0 | AK15: 45 | AL15: 30 | AM15: =AM14+(W15*1.9835) -> 6990.4491
A16: =A15+1 -> 5 | B16: 6900.72 | C16: 286245 | D16: =C16-C15 -> 370 | E16: =C16-152000 -> 134245 | F16: =D16/$D$2 -> 186.53895 | G16: 71 | H16: 1.7 | I16: =G16+H16 -> 72.7 | J16: =IF(L16>0,L16,0) -> 187.33895 | K16: =I16+J16 -> 260.03895 | L16: =F16-(I16-AG16) -> 187.33895 | M16: 3.5 | N16: 0 | O16: 0 | P16: 0 | Q16: =1.51*1.02 -> 1.5402 | R16: 3.2 | S16: 0 | T16: =M16-(Q16+R16+S16) -> -1.2402 | U16: 38 | V16: 0 | W16: =M16-N16-O16-P16-Q16-R16-S16-T16+U16+V16 -> 38 | AA16: 0 | AD16: 32 | AE16: =AE15-AD16 -> 2891 | AG16: =N16+O16+P16+Q16+R16+S16+T16+W16+AA16+AD16 -> 73.5 | AH16: =IF(L16<0,L16*-1,0) -> 0 | AI16: =AG16+AH16 -> 73.5 | AJ16: 0.93 | AK16: 38 | AL16: 31 | AM16: =AM15+(W16*1.9835) -> 7065.822
A17: =A16+1 -> 6 | B17: 6900.78 | C17: 286467 | D17: =C17-C16 -> 222 | E17: =C17-152000 -> 134467 | F17: =D17/$D$2 -> 111.92337 | G17: 71 | H17: 2.6 | I17: =G17+H17 -> 73.6 | J17: =IF(L17>0,L17,0) -> 109.72337 | K17: =I17+J17 -> 183.32337 | L17: =F17-(I17-AG17) -> 109.72337 | M17: 3.4 | N17: 0 | O17: 0 | P17: 0 | Q17: =1.51*1.02 -> 1.5402 | R17: 3.32 | S17: 0 | T17: =M17-(Q17+R17+S17) -> -1.4602 | U17: 38 | V17: 0 | W17: =M17-N17-O17-P17-Q17-R17-S17-T17+U17+V17 -> 38 | AA17: 0 | AD17: 30 | AE17: =AE16-AD17 -> 2861 | AG17: =N17+O17+P17+Q17+R17+S17+T17+W17+AA17+AD17 -> 71.4 | AH17: =IF(L17<0,L17*-1,0) -> 0 | AI17: =AG17+AH17 -> 71.4 | AJ17: 0.6 | AK17: 37 | AL17: 30 | AM17: =AM16+(W17*1.9835) -> 7141.1951
A18: =A17+1 -> 7 | B18: 6900.78 | C18: 286467 | D18: =C18-C17 -> 0 | E18: =C18-152000 -> 134467 | F18: =D18/$D$2 -> 0 | G18: 71 | H18: 2.2 | I18: =G18+H18 -> 73.2 | J18: =IF(L18>0,L18,0) -> 0 | K18: =I18+J18 -> 73.2 | L18: =F18-(I18-AG18) -> -1.6 | M18: 3.6 | N18: 0 | O18: 0 | P18: 0 | Q18: =1.51*1.02 -> 1.5402 | R18: 3.08 | S18: 0 | T18: =M18-(Q18+R18+S18) -> -1.0202 | U18: 38 | V18: 0 | W18: =M18-N18-O18-P18-Q18-R18-S18-T18+U18+V18 -> 38 | AA18: 0 | AD18: 30 | AE18: =AE17-AD18 -> 2831 | AG18: =N18+O18+P18+Q18+R18+S18+T18+W18+AA18+AD18 -> 71.6 | AH18: =IF(L18<0,L18*-1,0) -> 1.6 | AI18: =AG18+AH18 -> 73.2 | AJ18: 0.12 | AK18: 31 | AL18: 19 | AM18: =AM17+(W18*1.9835) -> 7216.568
A19: =A18+1 -> 8 | B19: 6900.78 | C19: 286467 | D19: =C19-C18 -> 0 | E19: =C19-152000 -> 134467 | F19: =D19/$D$2 -> 0 | G19: 71 | H19: 2.1 | I19: =G19+H19 -> 73.1 | J19: =IF(L19>0,L19,0) -> 0 | K19: =I19+J19 -> 73.1 | L19: =F19-(I19-AG19) -> -0.4 | M19: 3.7 | N19: 0 | O19: 0 | P19: 0 | Q19: =1.51*1.02 -> 1.5402 | R19: 3.22 | S19: 0 | T19: =M19-(Q19+R19+S19) -> -1.0602 | U19: 38 | V19: 0 | W19: =M19-N19-O19-P19-Q19-R19-S19-T19+U19+V19 -> 38 | AA19: 0 | AD19: 31 | AE19: =AE18-AD19 -> 2800 | AG19: =N19+O19+P19+Q19+R19+S19+T19+W19+AA19+AD19 -> 72.7 | AH19: =IF(L19<0,L19*-1,0) -> 0.4 | AI19: =AG19+AH19 -> 73.1 | AJ19: 0 | AK19: 28 | AL19: 0 | AM19: =AM18+(W19*1.9835) -> 7291.9411
A20: =A19+1 -> 9 | B20: 6900.78 | C20: 286467 | D20: =C20-C19 -> 0 | E20: =C20-152000 -> 134467 | F20: =D20/$D$2 -> 0 | G20: 71 | H20: 2 | I20: =G20+H20 -> 73 | J20: =IF(L20>0,L20,0) -> 0 | K20: =I20+J20 -> 73 | L20: =F20-(I20-AG20) -> -1.6 | M20: 3.4 | N20: 0 | O20: 0 | P20: 0 | Q20: =1.51*1.02 -> 1.5402 | R20: 3.21 | S20: 0 | T20: =M20-(Q20+R20+S20) -> -1.3502 | U20: 37 | V20: 0 | W20: =M20-N20-O20-P20-Q20-R20-S20-T20+U20+V20 -> 37 | AA20: 0 | AD20: 31 | AE20: =AE19-AD20 -> 2769 | AG20: =N20+O20+P20+Q20+R20+S20+T20+W20+AA20+AD20 -> 71.4 | AH20: =IF(L20<0,L20*-1,0) -> 1.6 | AI20: =AG20+AH20 -> 73 | AJ20: 0 | AK20: 28 | AL20: 13 | AM20: =AM19+(W20*1.9835) -> 7365.3305
A21: =A20+1 -> 10 | B21: 6900.78 | C21: 286467 | D21: =C21-C20 -> 0 | E21: =C21-152000 -> 134467 | F21: =D21/$D$2 -> 0 | G21: 71 | H21: 2.5 | I21: =G21+H21 -> 73.5 | J21: =IF(L21>0,L21,0) -> 0 | K21: =I21+J21 -> 73.5 | L21: =F21-(I21-AG21) -> -1 | M21: 3.5 | N21: 0 | O21: 0 | P21: 0 | Q21: =1.51*1.02 -> 1.5402 | R21: 2.95 | S21: 0 | T21: =M21-(Q21+R21+S21) -> -0.9902 | U21: 38 | V21: 0 | W21: =M21-N21-O21-P21-Q21-R21-S21-T21+U21+V21 -> 38 | AA21: 0 | AD21: 31 | AE21: =AE20-AD21 -> 2738 | AG21: =N21+O21+P21+Q21+R21+S21+T21+W21+AA21+AD21 -> 72.5 | AH21: =IF(L21<0,L21*-1,0) -> 1 | AI21: =AG21+AH21 -> 73.5 | AJ21: 0 | AK21: 23 | AL21: 0 | AM21: =AM20+(W21*1.9835) -> 7440.7036
A22: =A21+1 -> 11 | B22: 6900.78 | C22: 286467 | D22: =C22-C21 -> 0 | E22: =C22-152000 -> 134467 | F22: =D22/$D$2 -> 0 | G22: 71 | H22: 2.7 | I22: =G22+H22 -> 73.7 | J22: =IF(L22>0,L22,0) -> 0 | K22: =I22+J22 -> 73.7 | L22: =F22-(I22-AG22) -> -1 | M22: 3.7 | N22: 0 | O22: 0 | P22: 0 | Q22: =1.51*1.02 -> 1.5402 | R22: 2.76 | S22: 0 | T22: =M22-(Q22+R22+S22) -> -0.6002 | U22: 38 | V22: 0 | W22: =M22-N22-O22-P22-Q22-R22-S22-T22+U22+V22 -> 38 | AA22: 0 | AD22: 31 | AE22: =AE21-AD22 -> 2707 | AG22: =N22+O22+P22+Q22+R22+S22+T22+W22+AA22+AD22 -> 72.7 | AH22: =IF(L22<0,L22*-1,0) -> 1 | AI22: =AG22+AH22 -> 73.7 | AJ22: 0 | AK22: 30 | AL22: -2 | AM22: =AM21+(W22*1.9835) -> 7516.0765
A23: =A22+1 -> 12 | B23: 6900.78 | C23: 286467 | D23: =C23-C22 -> 0 | E23: =C23-152000 -> 134467 | F23: =D23/$D$2 -> 0 | G23: 71 | H23: 2.1 | I23: =G23+H23 -> 73.1 | J23: =IF(L23>0,L23,0) -> 0 | K23: =I23+J23 -> 73.1 | L23: =F23-(I23-AG23) -> -0.4 | M23: 3.7 | N23: 0 | O23: 0 | P23: 0 | Q23: =1.51*1.02 -> 1.5402 | R23: 2.75 | S23: 0 | T23: =M23-(Q23+R23+S23) -> -0.5902 | U23: 38 | V23: 0 | W23: =M23-N23-O23-P23-Q23-R23-S23-T23+U23+V23 -> 38 | AA23: 0 | AD23: 31 | AE23: =AE22-AD23 -> 2676 | AG23: =N23+O23+P23+Q23+R23+S23+T23+W23+AA23+AD23 -> 72.7 | AH23: =IF(L23<0,L23*-1,0) -> 0.4 | AI23: =AG23+AH23 -> 73.1 | AJ23: 0 | AK23: 31 | AL23: 2 | AM23: =AM22+(W23*1.9835) -> 7591.4496
A24: 13 | B24: 6900.78 | C24: 286467 | D24: =C24-C23 -> 0 | E24: =C24-152000 -> 134467 | F24: =D24/$D$2 -> 0 | G24: 71 | H24: 2.1 | I24: =G24+H24 -> 73.1 | J24: =IF(L24>0,L24,0) -> 0 | K24: =I24+J24 -> 73.1 | L24: =F24-(I24-AG24) -> -1.5 | M24: 3.6 | N24: 0 | O24: 0 | P24: 0 | Q24: =1.51*1.02 -> 1.5402 | R24: 2.74 | S24: 0 | T24: =M24-(Q24+R24+S24) -> -0.6802 | U24: 37 | V24: 0 | W24: =M24-N24-O24-P24-Q24-R24-S24-T24+U24+V24 -> 37 | AA24: 0 | AD24: 31 | AE24: =AE23-AD24 -> 2645 | AG24: =N24+O24+P24+Q24+R24+S24+T24+W24+AA24+AD24 -> 71.6 | AH24: =IF(L24<0,L24*-1,0) -> 1.5 | AI24: =AG24+AH24 -> 73.1 | AJ24: 0 | AK24: 32 | AL24: -1 | AM24: =AM23+(W24*1.9835) -> 7664.839
A25: =A24+1 -> 14 | B25: 6900.77 | C25: 286430 | D25: =C25-C24 -> -37 | E25: =C25-152000 -> 134430 | F25: =D25/$D$2 -> -18.653895 | G25: 70 | H25: 2 | I25: =G25+H25 -> 72 | J25: =IF(L25>0,L25,0) -> 0 | K25: =I25+J25 -> 72 | L25: =F25-(I25-AG25) -> -16.253895 | M25: 3.4 | N25: 0 | O25: 0 | P25: 0 | Q25: =1.51*1.02 -> 1.5402 | R25: 3.8 | S25: 0 | T25: =M25-(Q25+R25+S25) -> -1.9402 | U25: 40 | V25: 0 | W25: =M25-N25-O25-P25-Q25-R25-S25-T25+U25+V25 -> 40 | AA25: 0 | AD25: 31 | AE25: =AE24-AD25 -> 2614 | AG25: =N25+O25+P25+Q25+R25+S25+T25+W25+AA25+AD25 -> 74.4 | AH25: =IF(L25<0,L25*-1,0) -> 16.253895 | AI25: =AG25+AH25 -> 90.653895 | AJ25: 0 | AK25: 33 | AL25: 0 | AM25: =AM24+(W25*1.9835) -> 7744.179
A26: =A25+1 -> 15 | B26: 6900.77 | C26: 286430 | D26: =C26-C25 -> 0 | E26: =C26-152000 -> 134430 | F26: =D26/$D$2 -> 0 | G26: 70 | H26: 1.8 | I26: =G26+H26 -> 71.8 | J26: =IF(L26>0,L26,0) -> 11.6 | K26: =I26+J26 -> 83.4 | L26: =F26-(I26-AG26) -> 11.6 | M26: 3.4 | N26: 0 | O26: 0 | P26: 0 | Q26: =1.51*1.02 -> 1.5402 | R26: 4.01 | S26: 0 | T26: =M26-(Q26+R26+S26) -> -2.1502 | U26: 49 | V26: 0 | W26: =M26-N26-O26-P26-Q26-R26-S26-T26+U26+V26 -> 49 | AA26: 0 | AD26: 31 | AE26: =AE25-AD26 -> 2583 | AG26: =N26+O26+P26+Q26+R26+S26+T26+W26+AA26+AD26 -> 83.4 | AH26: =IF(L26<0,L26*-1,0) -> 0 | AI26: =AG26+AH26 -> 83.4 | AJ26: 0 | AK26: 30 | AL26: -2 | AM26: =AM25+(W26*1.9835) -> 7841.3705
A27: =A26+1 -> 16 | B27: 6900.76 | C27: 286393 | D27: =C27-C26 -> -37 | E27: =C27-152000 -> 134393 | F27: =D27/$D$2 -> -18.653895 | G27: 70 | H27: 1.7 | I27: =G27+H27 -> 71.7 | J27: =IF(L27>0,L27,0) -> 0 | K27: =I27+J27 -> 71.7 | L27: =F27-(I27-AG27) -> -6.0538946 | M27: 3.3 | N27: 0 | O27: 0 | P27: 0 | Q27: =1.51*1.02 -> 1.5402 | R27: 3.84 | S27: 0 | T27: =M27-(Q27+R27+S27) -> -2.0802 | U27: 50 | V27: 0 | W27: =M27-N27-O27-P27-Q27-R27-S27-T27+U27+V27 -> 50 | AA27: 0 | AD27: 31 | AE27: =AE26-AD27 -> 2552 | AG27: =N27+O27+P27+Q27+R27+S27+T27+W27+AA27+AD27 -> 84.3 | AH27: =IF(L27<0,L27*-1,0) -> 6.0538946 | AI27: =AG27+AH27 -> 90.353895 | AJ27: 0 | AK27: 17 | AL27: -5 | AM27: =AM26+(W27*1.9835) -> 7940.5455
A28: =A27+1 -> 17 | B28: 6900.74 | C28: 286319 | D28: =C28-C27 -> -74 | E28: =C28-152000 -> 134319 | F28: =D28/$D$2 -> -37.307789 | G28: 70 | H28: 1.5 | I28: =G28+H28 -> 71.5 | J28: =IF(L28>0,L28,0) -> 0 | K28: =I28+J28 -> 71.5 | L28: =F28-(I28-AG28) -> -24.307789 | M28: 3.5 | N28: 0 | O28: 0 | P28: 0 | Q28: =1.51*1.02 -> 1.5402 | R28: 3.99 | S28: 0 | T28: =M28-(Q28+R28+S28) -> -2.0302 | U28: 50 | V28: 0 | W28: =M28-N28-O28-P28-Q28-R28-S28-T28+U28+V28 -> 50 | AA28: 0 | AD28: 31 | AE28: =AE27-AD28 -> 2521 | AG28: =N28+O28+P28+Q28+R28+S28+T28+W28+AA28+AD28 -> 84.5 | AH28: =IF(L28<0,L28*-1,0) -> 24.307789 | AI28: =AG28+AH28 -> 108.80779 | AJ28: 0 | AK28: 18 | AL28: -10 | AM28: =AM27+(W28*1.9835) -> 8039.7206
A29: =A28+1 -> 18 | B29: 6900.73 | C29: 286282 | D29: =C29-C28 -> -37 | E29: =C29-152000 -> 134282 | F29: =D29/$D$2 -> -18.653895 | G29: 70 | H29: 1.2 | I29: =G29+H29 -> 71.2 | J29: =IF(L29>0,L29,0) -> 0 | K29: =I29+J29 -> 71.2 | L29: =F29-(I29-AG29) -> -5.1538946 | M29: 3.7 | N29: 0 | O29: 0 | P29: 0 | Q29: =1.51*1.02 -> 1.5402 | R29: 2.79 | S29: 0 | T29: =M29-(Q29+R29+S29) -> -0.6302 | U29: 50 | V29: 0 | W29: =M29-N29-O29-P29-Q29-R29-S29-T29+U29+V29 -> 50 | AA29: 0 | AD29: 31 | AE29: =AE28-AD29 -> 2490 | AG29: =N29+O29+P29+Q29+R29+S29+T29+W29+AA29+AD29 -> 84.7 | AH29: =IF(L29<0,L29*-1,0) -> 5.1538946 | AI29: =AG29+AH29 -> 89.853895 | AJ29: 0 | AK29: 24 | AL29: -4 | AM29: =AM28+(W29*1.9835) -> 8138.8956
A30: =A29+1 -> 19 | B30: 6900.72 | C30: 286245 | D30: =C30-C29 -> -37 | E30: =C30-152000 -> 134245 | F30: =D30/$D$2 -> -18.653895 | G30: 70 | H30: 1.2 | I30: =G30+H30 -> 71.2 | J30: =IF(L30>0,L30,0) -> 0 | K30: =I30+J30 -> 71.2 | L30: =F30-(I30-AG30) -> -5.1538946 | M30: 3.7 | N30: 0 | O30: 0 | P30: 0 | Q30: =1.51*1.02 -> 1.5402 | R30: 3.13 | S30: 0.16 | T30: =M30-(Q30+R30+S30) -> -1.1302 | U30: 50 | V30: 0 | W30: =M30-N30-O30-P30-Q30-R30-S30-T30+U30+V30 -> 50 | AA30: 0 | AD30: 31 | AE30: =AE29-AD30 -> 2459 | AG30: =N30+O30+P30+Q30+R30+S30+T30+W30+AA30+AD30 -> 84.7 | AH30: =IF(L30<0,L30*-1,0) -> 5.1538946 | AI30: =AG30+AH30 -> 89.853895 | AJ30: 0 | AK30: 30 | AL30: 1 | AM30: =AM29+(W30*1.9835) -> 8238.0706
A31: =A30+1 -> 20 | B31: 6900.71 | C31: 286208 | D31: =C31-C30 -> -37 | E31: =C31-152000 -> 134208 | F31: =D31/$D$2 -> -18.653895 | G31: 70 | H31: 1.2 | I31: =G31+H31 -> 71.2 | J31: =IF(L31>0,L31,0) -> 0 | K31: =I31+J31 -> 71.2 | L31: =F31-(I31-AG31) -> -5.1538946 | M31: 3.7 | N31: 0 | O31: 0 | P31: 0 | Q31: =1.51*1.02 -> 1.5402 | R31: 3.55 | S31: 0 | T31: =M31-(Q31+R31+S31) -> -1.3902 | U31: 50 | V31: 0 | W31: =M31-N31-O31-P31-Q31-R31-S31-T31+U31+V31 -> 50 | AA31: 0 | AD31: 31 | AE31: =AE30-AD31 -> 2428 | AG31: =N31+O31+P31+Q31+R31+S31+T31+W31+AA31+AD31 -> 84.7 | AH31: =IF(L31<0,L31*-1,0) -> 5.1538946 | AI31: =AG31+AH31 -> 89.853895 | AJ31: 0 | AK31: 37 | AL31: 6 | AM31: =AM30+(W31*1.9835) -> 8337.2455
A32: =A31+1 -> 21 | B32: 6900.7 | C32: 286171 | D32: =C32-C31 -> -37 | E32: =C32-152000 -> 134171 | F32: =D32/$D$2 -> -18.653895 | G32: 69 | H32: 1.2 | I32: =G32+H32 -> 70.2 | J32: =IF(L32>0,L32,0) -> 0 | K32: =I32+J32 -> 70.2 | L32: =F32-(I32-AG32) -> -1.2538946 | M32: 3.6 | N32: 0 | O32: 0 | P32: 0 | Q32: =1.51*1.02 -> 1.5402 | R32: 4.02 | S32: 0 | T32: =M32-(Q32+R32+S32) -> -1.9602 | U32: 53 | V32: 0 | W32: =M32-N32-O32-P32-Q32-R32-S32-T32+U32+V32 -> 53 | AA32: 0 | AD32: 31 | AE32: =AE31-AD32 -> 2397 | AG32: =N32+O32+P32+Q32+R32+S32+T32+W32+AA32+AD32 -> 87.6 | AH32: =IF(L32<0,L32*-1,0) -> 1.2538946 | AI32: =AG32+AH32 -> 88.853895 | AJ32: 0 | AK32: 35 | AL32: 4 | AM32: =AM31+(W32*1.9835) -> 8442.371
A33: =A32+1 -> 22 | B33: 6900.69 | C33: 286134 | D33: =C33-C32 -> -37 | E33: =C33-152000 -> 134134 | F33: =D33/$D$2 -> -18.653895 | G33: 69 | H33: 1.2 | I33: =G33+H33 -> 70.2 | J33: =IF(L33>0,L33,0) -> 6.3461054 | K33: =I33+J33 -> 76.546105 | L33: =F33-(I33-AG33) -> 6.3461054 | M33: 4.2 | N33: 0 | O33: 0 | P33: 0 | Q33: =1.51*1.02 -> 1.5402 | R33: 4.2 | S33: 1.97 | T33: =M33-(Q33+R33+S33) -> -3.5102 | U33: 60 | V33: 0 | W33: =M33-N33-O33-P33-Q33-R33-S33-T33+U33+V33 -> 60 | AA33: 0 | AD33: 31 | AE33: =AE32-AD33 -> 2366 | AG33: =N33+O33+P33+Q33+R33+S33+T33+W33+AA33+AD33 -> 95.2 | AH33: =IF(L33<0,L33*-1,0) -> 0 | AI33: =AG33+AH33 -> 95.2 | AJ33: 0 | AK33: 38 | AL33: 10 | AM33: =AM32+(W33*1.9835) -> 8561.381
A34: =A33+1 -> 23 | B34: 6900.68 | C34: 286097 | D34: =C34-C33 -> -37 | E34: =C34-152000 -> 134097 | F34: =D34/$D$2 -> -18.653895 | G34: 69 | H34: 1.2 | I34: =G34+H34 -> 70.2 | J34: =IF(L34>0,L34,0) -> 6.4461054 | K34: =I34+J34 -> 76.646105 | L34: =F34-(I34-AG34) -> 6.4461054 | M34: 4.3 | N34: 0 | O34: 0 | P34: 0 | Q34: =1.51*1.02 -> 1.5402 | R34: 3.61 | S34: 0 | T34: =M34-(Q34+R34+S34) -> -0.8502 | U34: 60 | V34: 0 | W34: =M34-N34-O34-P34-Q34-R34-S34-T34+U34+V34 -> 60 | AA34: 0 | AD34: 31 | AE34: =AE33-AD34 -> 2335 | AG34: =N34+O34+P34+Q34+R34+S34+T34+W34+AA34+AD34 -> 95.3 | AH34: =IF(L34<0,L34*-1,0) -> 0 | AI34: =AG34+AH34 -> 95.3 | AJ34: 0 | AK34: 43 | AL34: 11 | AM34: =AM33+(W34*1.9835) -> 8680.3911
A35: =A34+1 -> 24 | B35: 6900.68 | C35: 286097 | D35: =C35-C34 -> 0 | E35: =C35-152000 -> 134097 | F35: =D35/$D$2 -> 0 | G35: 64 | H35: 1 | I35: =G35+H35 -> 65 | J35: =IF(L35>0,L35,0) -> 30.7 | K35: =I35+J35 -> 95.7 | L35: =F35-(I35-AG35) -> 30.7 | M35: 4.7 | N35: 0 | O35: 0 | P35: 0 | Q35: =1.51*1.02 -> 1.5402 | R35: 3.05 | S35: 0 | T35: =M35-(Q35+R35+S35) -> 0.1098 | U35: 60 | V35: 0 | W35: =M35-N35-O35-P35-Q35-R35-S35-T35+U35+V35 -> 60 | AA35: 0 | AD35: 31 | AE35: =AE34-AD35 -> 2304 | AG35: =N35+O35+P35+Q35+R35+S35+T35+W35+AA35+AD35 -> 95.7 | AH35: =IF(L35<0,L35*-1,0) -> 0 | AI35: =AG35+AH35 -> 95.7 | AJ35: 0.01 | AK35: 35 | AL35: 23 | AM35: =AM34+(W35*1.9835) -> 8799.4011
A36: =A35+1 -> 25 | B36: 6900.67 | C36: 286060 | D36: =C36-C35 -> -37 | E36: =C36-152000 -> 134060 | F36: =D36/$D$2 -> -18.653895 | G36: 66 | H36: 0.96 | I36: =G36+H36 -> 66.96 | J36: =IF(L36>0,L36,0) -> 9.2861054 | K36: =I36+J36 -> 76.246105 | L36: =F36-(I36-AG36) -> 9.2861054 | M36: 4.9 | N36: 0 | O36: 0 | P36: 0 | Q36: =1.51*1.02 -> 1.5402 | R36: 3.34 | S36: 0 | T36: =M36-(Q36+R36+S36) -> 0.0198 | U36: 59 | V36: 0 | W36: =M36-N36-O36-P36-Q36-R36-S36-T36+U36+V36 -> 59 | AA36: 0 | AD36: 31 | AE36: =AE35-AD36 -> 2273 | AG36: =N36+O36+P36+Q36+R36+S36+T36+W36+AA36+AD36 -> 94.9 | AH36: =IF(L36<0,L36*-1,0) -> 0 | AI36: =AG36+AH36 -> 94.9 | AJ36: 0 | AK36: 38 | AL36: 11 | AM36: =AM35+(W36*1.9835) -> 8916.4276
... A40: =A39+1 -> 29 | B40: 6900.71 | C40: 286208 | D40: =C40-C39 -> -74 | E40: =C40-152000 -> 134208 | F40: =D40/$D$2 -> -37.307789 | G40: 69 | H40: 0.9 | I40: =G40+H40 -> 69.9 | J40: =IF(L40>0,L40,0) -> 0 | K40: =I40+J40 -> 69.9 | L40: =F40-(I40-AG40) -> -11.707789 | M40: 4.5 | N40: 0 | O40: 0 | P40: 0 | Q40: =1.51*1.02 -> 1.5402 | R40: 4.09 | S40: 0 | T40: =M40-(Q40+R40+S40) -> -1.1302 | U40: 60 | V40: 0 | W40: =M40-N40-O40-P40-Q40-R40-S40-T40+U40+V40 -> 60 | AA40: 0 | AD40: 31 | AE40: =AE39-AD40 -> 2148 | AG40: =N40+O40+P40+Q40+R40+S40+T40+W40+AA40+AD40 -> 95.5 | AH40: =IF(L40<0,L40*-1,0) -> 11.707789 | AI40: =AG40+AH40 -> 107.20779 | AJ40: 0 | AK40: 25 | AL40: -2 | AM40: =AM39+(W40*1.9835) -> 9378.583
A41: 30 | B41: 6900.69 | C41: 286134 | D41: =C41-C40 -> -74 | E41: =C41-152000 -> 134134 | F41: =D41/$D$2 -> -37.307789 | G41: 69 | H41: 0.9 | I41: =G41+H41 -> 69.9 | J41: =IF(L41>0,L41,0) -> 0 | K41: =I41+J41 -> 69.9 | L41: =F41-(I41-AG41) -> -5.6077893 | M41: 4.6 | N41: 0 | O41: 0 | P41: 0 | Q41: =1.51*1.02 -> 1.5402 | R41: 3.83 | S41: 0 | T41: =M41-(Q41+R41+S41) -> -0.7702 | U41: 66 | V41: 0 | W41: =M41-N41-O41-P41-Q41-R41-S41-T41+U41+V41 -> 66 | AA41: 0 | AD41: 31 | AE41: =AE40-AD41 -> 2117 | AG41: =N41+O41+P41+Q41+R41+S41+T41+W41+AA41+AD41 -> 101.6 | AH41: =IF(L41<0,L41*-1,0) -> 5.6077893 | AI41: =AG41+AH41 -> 107.20779 | AJ41: 0 | AK41: 23 | AL41: 9 | AM41: =AM40+(W41*1.9835) -> 9509.494
A42: 31 | B42: 6900.67 | C42: 286060 | D42: =C42-C41 -> -74 | E42: =C42-152000 -> 134060 | F42: =D42/$D$2 -> -37.307789 | G42: 69 | H42: 0.84 | I42: =G42+H42 -> 69.84 | J42: =IF(L42>0,L42,0) -> 0 | K42: =I42+J42 -> 69.84 | L42: =F42-(I42-AG42) -> -1.5477893 | M42: 4.6 | N42: 0 | O42: 0 | P42: 0 | Q42: =1.51*1.02 -> 1.5402 | R42: 3.32 | S42: 0 | T42: =M42-(Q42+R42+S42) -> -0.2602 | U42: 70 | V42: 0 | W42: =M42-N42-O42-P42-Q42-R42-S42-T42+U42+V42 -> 70 | AA42: 0 | AD42: 31 | AE42: =AE41-AD42 -> 2086 | AG42: =N42+O42+P42+Q42+R42+S42+T42+W42+AA42+AD42 -> 105.6 | AH42: =IF(L42<0,L42*-1,0) -> 1.5477893 | AI42: =AG42+AH42 -> 107.14779 | AJ42: 0 | AK42: 24 | AL42: -8 | AM42: =AM41+(W42*1.9835) -> 9648.3391
A44: MONTH / CFS | F44: =SUM(F12:F42) -> -18.653895 | G44: =SUM(G12:G42) -> 2162 | H44: =SUM(H12:H42) -> 49.13 | I44: =SUM(I12:I42) -> 2211.13 | J44: =SUM(J12:J42) -> 546.234 | K44: =SUM(K12:K42) -> 2757.364 | L44: =SUM(L12:L42) -> 339.71611 | M44: =SUM(M12:M42) -> 119.5 | ... O44: =SUM(O12:O42) -> 0 | Q44: =SUM(Q12:Q42) -> 47.7462 | R44: =SUM(R12:R42) -> 102.47 | S44: =SUM(S12:S42) -> 2.34 | T44: =SUM(T12:T42) -> -33.0562 | U44: =SUM(U12:U42) -> 1489 | V44: =SUM(V12:V42) -> 0 | W44: =SUM(W12:W42) -> 1489 | AD44: =SUM(AD12:AD42) -> 961 | AF44: =SUM(AF12:AF42) -> 0 | AG44: =SUM(AG12:AG42) -> 2569.5 | AH44: =SUM(AH12:AH42) -> 206.51789 | AI44: =SUM(AI12:AI42) -> 2776.0179 | AJ44: =SUM(AJ12:AJ42) -> 3.36 | AK44: =AVERAGE(AK12:AK42) -> 32.451613 | AL44: =AVERAGE(AL12:AL42) -> 7.5483871 | AM44: AVE | AN44: =SUM(AN12:AN42) -> 0
A45: MONTH / AF | D45: =SUM(D12:D42) -> -37 | F45: =F44*$D$2 -> -37 | G45: =G44*$D$2 -> 4288.327 | H45: =H44*$D$2 -> 97.449355 | I45: =I44*$D$2 -> 4385.7764 | J45: =J44*$D$2 -> 1083.4551 | K45: =K44*$D$2 -> 5469.2315 | L45: =L44*$D$2 -> 673.8269 | M45: =M44*$D$2 -> 237.02825 | ... O45: =O44*$D$2 -> 0 | Q45: =Q44*$D$2 -> 94.704588 | R45: =R44*$D$2 -> 203.24925 | S45: =S44*$D$2 -> 4.64139 | T45: =T44*$D$2 -> -65.566973 | U45: =U44*$D$2 -> 2953.4315 | V45: =V44*$D$2 -> 0 | W45: =W44*$D$2 -> 2953.4315 | AD45: =AD44*$D$2 -> 1906.1435 | AF45: =AF44*$D$2 -> 0 | AG45: =AG44*$D$2 -> 5096.6033 | AH45: =AH44*$D$2 -> 409.62824 | AI45: =AI44*$D$2 -> 5506.2315 | AK45: =MAX(AK12:AK42) -> 47 | AL45: =MAX(AL12:AL42) -> 31 | AM45: HI | AN45: =AN44*$D$2 -> 0
A47: SEASON / CFS | AK47: =MIN(AK12:AK42) -> 17 | AL47: =MIN(AL12:AL42) -> -10 | AM47: LO
...

Sheet FEB
K1: MCPHEE RESERVOIR INFLOW/OUTFLOW TABULATION
A2: AF/cfs CONVERT FACTOR | D2: 1.9835 | K2: FEBRUARY "2008"
D4: RESERVOIR | U4: INFLOW/OUTFLOW (CFS) | AK4: WEATHER | AO4: ADJUSTMENTS
A5: DATE | B5: RESERV | C5: RESERV | D5: AC FT | E5: ACTIVE | F5: CONV TO | G5: DOLORES | H5: LOST | I5: RECORD | J5: CALC | K5: TOTAL | L5: CALC | M5: DOLORES TUNNEL | U5: LONE | V5: U | W5: TOTAL | X5: MVI | Y5: TO EX & | Z5: MVI | AA5: DV CR | AB5: D/S SENIOR | AD5: BELOW | AE5: FISH | AF5: SPILL | AG5: RECORD | AH5: CALC | AI5: TOTAL | AJ5: RAIN | AK5: MAX | AL5: MIN | AM5: NAR | AN5: MVI | AO5: MVI | AP5: MVI | AQ5: U/S | AR5: TOTTEN | AS5: UTES
