Workbook

Sheet NOV
K1: MC PHEE RESERVOIR IN/OUT FLOW TABULATION
A2: AF/cfs CONVERT FACTOR | D2: 1.9835 | L2: NOVEMBER "1990"
A4: DATE | B4: RESERV | C4: RESERV | D4: AC FT | E4: ACTIVE | F4: CONV TO | G4: DOLORES | H4: LOST | I4: RECORDED | J4: CALC | K4: TOTAL | L4: CALC | M4: TUNNEL | Q4: LONE | R4: U | S4: TOTAL | T4: MVI | U4: DV CR | V4: BELOW | W4: REMAIN | X4: RECORDED | Y4: CALC | Z4: TOTAL | AA4: RAIN | AB4: MAX | AC4: MIN | AD4: DATE
A5: "NOV" | B5: ELEV | C5: AC FT | D5: CHANGE | E5: CAP | F5: CFS | G5: RIVER | H5: CANYON | I5: INFLOW | J5: INFLOW | K5: INFLOW | L5: INF/OTF | M5: TOT DIV | N5: WETLAND | O5: UTE F&R | P5: MVI,CTZ | Q5: PINE | R5: LAT | S5: MVI | T5: CALL | U5: CANAL | V5: MC PHEE | W5: RELEASE | X5: OUTFLOW | Y5: OUTFLOW | Z5: OUTFLOW | AB5: TMP | AC5: TMP | AD5: "NOV"
A7: SEASON BAL
A8: YTD | B8: 6887.21 | C8: 238865 | W8: 15179
A10: 1 | B10: 6887.25 | C10: 238997 | D10: =C10-C8 -> 132 | E10: =C10-152000 -> 86997 | F10: =D10/$D$2 -> 66.549029 | G10: 124 | H10: 0 | I10: =G10+H10 -> 124 | J10: =IF(L10>0,L10,0) -> 44.749029 | K10: =I10+J10 -> 168.74903 | L10: =F10-(I10-X10) -> 44.749029 | M10: 48.8 | N10: 0 | O10: 0 | P10: =M10-(N10+O10) -> 48.8 | Q10: 0 | R10: 19.2 | S10: =SUM(P10:R10) -> 68 | U10: 0 | V10: 34.2 | W10: =W8-V10 -> 15144.8 | X10: =N10+O10+S10+U10+V10 -> 102.2 | Y10: =IF(L10<0,L10*-1,0) -> 0 | Z10: =X10+Y10 -> 102.2 | AA10: 0 | AB10: 61 | AC10: 33 | AD10: 1
A11: =A10+1 -> 2 | B11: 6887.27 | C11: 239063 | D11: =C11-C10 -> 66 | E11: =C11-152000 -> 87063 | F11: =D11/$D$2 -> 33.274515 | G11: 129.8 | H11: 0 | I11: =G11+H11 -> 129.8 | J11: =IF(L11>0,L11,0) -> 5.6745147 | K11: =I11+J11 -> 135.47451 | L11: =F11-(I11-X11) -> 5.6745147 | M11: 48.8 | N11: 0 | O11: 0 | P11: =M11-(N11+O11) -> 48.8 | Q11: 0 | R11: 19.2 | S11: =SUM(P11:R11) -> 68 | U11: 0 | V11: 34.2 | W11: =W10-V11 -> 15110.6 | X11: =N11+O11+S11+U11+V11 -> 102.2 | Y11: =IF(L11<0,L11*-1,0) -> 0 | Z11: =X11+Y11 -> 102.2 | AA11: 0.22 | AB11: 45 | AC11: 37 | AD11: =AD10+1 -> 2
A12: =A11+1 -> 3 | B12: 6887.28 | C12: 239096 | D12: =C12-C11 -> 33 | E12: =C12-152000 -> 87096 | F12: =D12/$D$2 -> 16.637257 | G12: 127.5 | H12: 0 | I12: =G12+H12 -> 127.5 | J12: =IF(L12>0,L12,0) -> 0 | K12: =I12+J12 -> 127.5 | L12: =F12-(I12-X12) -> -8.7627426 | M12: 48.8 | N12: 0 | O12: 0 | P12: =M12-(N12+O12) -> 48.8 | Q12: 0 | R12: 19.2 | S12: =SUM(P12:R12) -> 68 | U12: 0 | V12: 34.1 | W12: =W11-V12 -> 15076.5 | X12: =N12+O12+S12+U12+V12 -> 102.1 | Y12: =IF(L12<0,L12*-1,0) -> 8.7627426 | Z12: =X12+Y12 -> 110.86274 | AA12: 0 | AB12: 47 | AC12: 36 | AD12: =AD11+1 -> 3
A13: =A12+1 -> 4 | B13: 6887.29 | C13: 239129 | D13: =C13-C12 -> 33 | E13: =C13-152000 -> 87129 | F13: =D13/$D$2 -> 16.637257 | G13: 108.5 | H13: 0 | I13: =G13+H13 -> 108.5 | J13: =IF(L13>0,L13,0) -> 10.137257 | K13: =I13+J13 -> 118.63726 | L13: =F13-(I13-X13) -> 10.137257 | M13: 48.8 | N13: 0 | O13: 0 | P13: =M13-(N13+O13) -> 48.8 | Q13: 0 | R13: 19.2 | S13: =SUM(P13:R13) -> 68 | U13: 0 | V13: 34 | W13: =W12-V13 -> 15042.5 | X13: =N13+O13+S13+U13+V13 -> 102 | Y13: =IF(L13<0,L13*-1,0) -> 0 | Z13: =X13+Y13 -> 102 | AA13: 0 | AB13: 49 | AC13: 31 | AD13: =AD12+1 -> 4
A14: =A13+1 -> 5 | B14: 6887.31 | C14: 239195 | D14: =C14-C13 -> 66 | E14: =C14-152000 -> 87195 | F14: =D14/$D$2 -> 33.274515 | G14: 103 | H14: 0 | I14: =G14+H14 -> 103 | J14: =IF(L14>0,L14,0) -> 18.074515 | K14: =I14+J14 -> 121.07451 | L14: =F14-(I14-X14) -> 18.074515 | M14: 36 | N14: 0 | O14: 0 | P14: =M14-(N14+O14) -> 36 | Q14: 0 | R14: 19 | S14: =SUM(P14:R14) -> 55 | U14: 0 | V14: 32.8 | W14: =W13-V14 -> 15009.7 | X14: =N14+O14+S14+U14+V14 -> 87.8 | Y14: =IF(L14<0,L14*-1,0) -> 0 | Z14: =X14+Y14 -> 87.8 | AA14: 0 | AB14: 49 | AC14: 29 | AD14: =AD13+1 -> 5
A15: =A14+1 -> 6 | B15: 6887.33 | C15: 239260 | D15: =C15-C14 -> 65 | E15: =C15-152000 -> 87260 | F15: =D15/$D$2 -> 32.770355 | G15: 110.1 | H15: 0 | I15: =G15+H15 -> 110.1 | J15: =IF(L15>0,L15,0) -> 0 | K15: =I15+J15 -> 110.1 | L15: =F15-(I15-X15) -> -0.52964457 | M15: 26.2 | N15: 0 | O15: 0 | P15: =M15-(N15+O15) -> 26.2 | Q15: 0 | R15: 18.8 | S15: =SUM(P15:R15) -> 45 | U15: 0 | V15: 31.8 | W15: =W14-V15 -> 14977.9 | X15: =N15+O15+S15+U15+V15 -> 76.8 | Y15: =IF(L15<0,L15*-1,0) -> 0.52964457 | Z15: =X15+Y15 -> 77.329645 | AA15: 0.13 | AB15: 39 | AC15: 21 | AD15: =AD14+1 -> 6
A16: =A15+1 -> 7 | B16: 6887.35 | C16: 239326 | D16: =C16-C15 -> 66 | E16: =C16-152000 -> 87326 | F16: =D16/$D$2 -> 33.274515 | G16: 106.5 | H16: 0 | I16: =G16+H16 -> 106.5 | J16: =IF(L16>0,L16,0) -> 0 | K16: =I16+J16 -> 106.5 | L16: =F16-(I16-X16) -> -0.42548525 | M16: 23.3 | N16: 0 | O16: 0 | P16: =M16-(N16+O16) -> 23.3 | Q16: 0 | R16: 18.7 | S16: =SUM(P16:R16) -> 42 | U16: 0 | V16: 30.8 | W16: =W15-V16 -> 14947.1 | X16: =N16+O16+S16+U16+V16 -> 72.8 | Y16: =IF(L16<0,L16*-1,0) -> 0.42548525 | Z16: =X16+Y16 -> 73.225485 | AA16: 0.49 | AB16: 41 | AC16: 24 | AD16: =AD15+1 -> 7
A17: =A16+1 -> 8 | B17: 6887.35 | C17: 239326 | D17: =C17-C16 -> 0 | E17: =C17-152000 -> 87326 | F17: =D17/$D$2 -> 0 | G17: 95.8 | H17: 0 | I17: =G17+H17 -> 95.8 | J17: =IF(L17>0,L17,0) -> 0 | K17: =I17+J17 -> 95.8 | L17: =F17-(I17-X17) -> -26.2 | M17: 20.9 | N17: 0 | O17: 0 | P17: =M17-(N17+O17) -> 20.9 | Q17: 0 | R17: 19.1 | S17: =SUM(P17:R17) -> 40 | U17: 0 | V17: 29.6 | W17: =W16-V17 -> 14917.5 | X17: =N17+O17+S17+U17+V17 -> 69.6 | Y17: =IF(L17<0,L17*-1,0) -> 26.2 | Z17: =X17+Y17 -> 95.8 | AA17: 0 | AB17: 39 | AC17: 22 | AD17: =AD16+1 -> 8
A18: =A17+1 -> 9 | B18: 6887.37 | C18: 239392 | D18: =C18-C17 -> 66 | E18: =C18-152000 -> 87392 | F18: =D18/$D$2 -> 33.274515 | G18: 92.4 | H18: 0 | I18: =G18+H18 -> 92.4 | J18: =IF(L18>0,L18,0) -> 10.574515 | K18: =I18+J18 -> 102.97451 | L18: =F18-(I18-X18) -> 10.574515 | M18: 20.9 | N18: 0 | O18: 0 | P18: =M18-(N18+O18) -> 20.9 | Q18: 0 | R18: 19.1 | S18: =SUM(P18:R18) -> 40 | U18: 0 | V18: 29.7 | W18: =W17-V18 -> 14887.8 | X18: =N18+O18+S18+U18+V18 -> 69.7 | Y18: =IF(L18<0,L18*-1,0) -> 0 | Z18: =X18+Y18 -> 69.7 | AA18: 0 | AB18: 42 | AC18: 20 | AD18: =AD17+1 -> 9
A19: =A18+1 -> 10 | B19: 6887.39 | C19: 239458 | D19: =C19-C18 -> 66 | E19: =C19-152000 -> 87458 | F19: =D19/$D$2 -> 33.274515 | G19: 94.1 | H19: 0 | I19: =G19+H19 -> 94.1 | J19: =IF(L19>0,L19,0) -> 8.8745147 | K19: =I19+J19 -> 102.97451 | L19: =F19-(I19-X19) -> 8.8745147 | M19: 20.9 | N19: 0 | O19: 0 | P19: =M19-(N19+O19) -> 20.9 | Q19: 0 | R19: 19.1 | S19: =SUM(P19:R19) -> 40 | U19: 0 | V19: 29.7 | W19: =W18-V19 -> 14858.1 | X19: =N19+O19+S19+U19+V19 -> 69.7 | Y19: =IF(L19<0,L19*-1,0) -> 0 | Z19: =X19+Y19 -> 69.7 | AA19: 0 | AB19: 53 | AC19: 24 | AD19: =AD18+1 -> 10
A20: =A19+1 -> 11 | B20: 6887.41 | C20: 239524 | D20: =C20-C19 -> 66 | E20: =C20-152000 -> 87524 | F20: =D20/$D$2 -> 33.274515 | G20: 95.7 | H20: 0 | I20: =G20+H20 -> 95.7 | J20: =IF(L20>0,L20,0) -> 7.2745147 | K20: =I20+J20 -> 102.97451 | L20: =F20-(I20-X20) -> 7.2745147 | M20: 20.9 | N20: 0 | O20: 0 | P20: =M20-(N20+O20) -> 20.9 | Q20: 0 | R20: 19.1 | S20: =SUM(P20:R20) -> 40 | U20: 0 | V20: 29.7 | W20: =W19-V20 -> 14828.4 | X20: =N20+O20+S20+U20+V20 -> 69.7 | Y20: =IF(L20<0,L20*-1,0) -> 0 | Z20: =X20+Y20 -> 69.7 | AA20: 0 | AB20: 55 | AC20: 23 | AD20: =AD19+1 -> 11
A21: =A20+1 -> 12 | B21: 6887.4 | C21: 239491 | D21: =C21-C20 -> -33 | E21: =C21-152000 -> 87491 | F21: =D21/$D$2 -> -16.637257 | G21: 95.3 | H21: 0 | I21: =G21+H21 -> 95.3 | J21: =IF(L21>0,L21,0) -> 0 | K21: =I21+J21 -> 95.3 | L21: =F21-(I21-X21) -> -36.237257 | M21: 27.5 | N21: 0 | O21: 0 | P21: =M21-(N21+O21) -> 27.5 | Q21: 0 | R21: 18.5 | S21: =SUM(P21:R21) -> 46 | U21: 0 | V21: 29.7 | W21: =W20-V21 -> 14798.7 | X21: =N21+O21+S21+U21+V21 -> 75.7 | Y21: =IF(L21<0,L21*-1,0) -> 36.237257 | Z21: =X21+Y21 -> 111.93726 | AA21: 0 | AB21: 62 | AC21: 23 | AD21: =AD20+1 -> 12
A22: =A21+1 -> 13 | B22: 6887.41 | C22: 239524 | D22: =C22-C21 -> 33 | E22: =C22-152000 -> 87524 | F22: =D22/$D$2 -> 16.637257 | G22: 97.2 | H22: 0 | I22: =G22+H22 -> 97.2 | J22: =IF(L22>0,L22,0) -> 0 | K22: =I22+J22 -> 97.2 | L22: =F22-(I22-X22) -> -2.0627426 | M22: 31.2 | N22: 0 | O22: 0 | P22: =M22-(N22+O22) -> 31.2 | Q22: 0 | R22: 17.8 | S22: =SUM(P22:R22) -> 49 | U22: 0 | V22: 29.5 | W22: =W21-V22 -> 14769.2 | X22: =N22+O22+S22+U22+V22 -> 78.5 | Y22: =IF(L22<0,L22*-1,0) -> 2.0627426 | Z22: =X22+Y22 -> 80.562743 | AA22: 0 | AB22: 61 | AC22: 22 | AD22: =AD21+1 -> 13
... A38: =A37+1 -> 29 | B38: 6887.62 | C38: 240216 | D38: =C38-C37 -> -66 | E38: =C38-152000 -> 88216 | F38: =D38/$D$2 -> -33.274515 | G38: 52.5 | H38: 0 | I38: =G38+H38 -> 52.5 | J38: =IF(L38>0,L38,0) -> 0 | K38: =I38+J38 -> 52.5 | L38: =F38-(I38-X38) -> -50.074515 | M38: 6.7 | N38: 0 | O38: 0 | P38: =M38-(N38+O38) -> 6.7 | Q38: 0 | R38: 0 | S38: =SUM(P38:R38) -> 6.7 | U38: 0 | V38: 29 | W38: =W37-V38 -> 14294.1 | X38: =N38+O38+S38+U38+V38 -> 35.7 | Y38: =IF(L38<0,L38*-1,0) -> 50.074515 | Z38: =X38+Y38 -> 85.774515 | AA38: 0 | AB38: 43 | AC38: 7 | AD38: =AD37+1 -> 29
A39: 30 | B39: 6887.63 | C39: 240249 | D39: =C39-C38 -> 33 | E39: =C39-152000 -> 88249 | F39: =D39/$D$2 -> 16.637257 | G39: 52.7 | H39: 0 | I39: =G39+H39 -> 52.7 | J39: =IF(L39>0,L39,0) -> 0 | K39: =I39+J39 -> 52.7 | L39: =F39-(I39-X39) -> -0.062742627 | M39: 6.7 | N39: 0 | O39: 0 | P39: =M39-(N39+O39) -> 6.7 | Q39: 0 | R39: 0 | S39: =SUM(P39:R39) -> 6.7 | U39: 0 | V39: 29.3 | W39: =W38-V39 -> 14264.8 | X39: =N39+O39+S39+U39+V39 -> 36 | Y39: =IF(L39<0,L39*-1,0) -> 0.062742627 | Z39: =X39+Y39 -> 36.062743 | AA39: 0 | AB39: 38 | AC39: 12 | AD39: 30
A41: MONTH / CFS | F41: =SUM(F10:F39) -> 697.75649 | G41: =SUM(G10:G39) -> 2871.7 | H41: =SUM(H10:H39) -> 0 | I41: =SUM(I10:I39) -> 2871.7 | J41: =SUM(J10:J39) -> 184.0763 | K41: =SUM(K10:K39) -> 3055.7763 | L41: =SUM(L10:L39) -> -170.44351 | M41: =SUM(M10:M40) -> 716.9 | N41: =SUM(N10:N39) -> 0 | O41: =SUM(O10:O39) -> 0 | P41: =SUM(P10:P39) -> 716.9 | Q41: =SUM(Q10:Q39) -> 0 | R41: =SUM(R10:R39) -> 372.4 | S41: =SUM(S10:S39) -> 1089.3 | U41: =SUM(U10:U39) -> 0 | V41: =SUM(V10:V39) -> 914.2 | X41: =SUM(X10:X39) -> 2003.5 | Y41: =SUM(Y10:Y39) -> 354.51981 | Z41: =SUM(Z10:Z39) -> 2358.0198 | AA41: =SUM(AA10:AA39) -> 1.48 | AB41: =AVERAGE(AB10:AB39) -> 50.6 | AC41: =AVERAGE(AC10:AC39) -> 23.133333 | AD41: Avg
A42: MONTH / AF | D42: =SUM(D10:D39) -> 1384 | F42: =F41*$D$2 -> 1384 | G42: =G41*$D$2 -> 5696.017 | H42: =H41*$D$2 -> 0 | I42: =I41*$D$2 -> 5696.017 | J42: =J41*$D$2 -> 365.11535 | K42: =K41*$D$2 -> 6061.1323 | L42: =L41*$D$2 -> -338.0747 | M42: =M41*$D$2 -> 1421.9712 | ... S42: =S41*$D$2 -> 2160.6265 | U42: =U41*$D$2 -> 0 | V42: =V41*$D$2 -> 1813.3157 | X42: =X41*$D$2 -> 3973.9423 | Y42: =Y41*$D$2 -> 703.19005 | Z42: =Z41*$D$2 -> 4677.1323 | AB42: =MAX(AB10:AB39) -> 62 | AC42: =MAX(AC10:AC39) -> 43 | AD42: HI
A44: SEASON / CFS | AB44: =MIN(AB10:AB39) -> 30 | AC44: =MIN(AC10:AC39) -> 5 | AD44: LO
A45: SEASON / AF
A47: YTD / CFS | F47: =F8+F41 -> 697.75649 | G47: =G8+G41 -> 2871.7 | H47: =H8+H41 -> 0 | I47: =I8+I41 -> 2871.7 | J47: =J8+J41 -> 184.0763 | K47: =K8+K41 -> 3055.7763 | L47: =L8+L41 -> -170.44351 | M47: =M8+M41 -> 716.9 | ... S47: =S8+S41 -> 1089.3 | U47: =U8+U41 -> 0 | V47: =V8+V41 -> 914.2 | W47: =W39 -> 14264.8 | X47: =X8+X41 -> 2003.5 | Y47: =Y8+Y41 -> 354.51981 | Z47: =Z8+Z41 -> 2358.0198 | AA47: =AA8+AA41 -> 1.48
A48: YTD / AF | D48: =D8+D42 -> 1384 | E48: =E39 -> 88249 | F48: =F47*$D$2 -> 1384 | G48: =G47*$D$2 -> 5696.017 | H48: =H47*$D$2 -> 0 | I48: =I47*$D$2 -> 5696.017 | J48: =J47*$D$2 -> 365.11535 | K48: =K47*$D$2 -> 6061.1323 | L48: =L47*$D$2 -> -338.0747 | M48: =M47*$D$2 -> 1421.9712 | ... Z48: =Z47*$D$2 -> 4677.1323

Sheet DEC
K1: MC PHEE RESERVOIR IN/OUT FLOW TABULATION
A2: AF/cfs CONVERT FACTOR | D2: 1.9835 | K2: DECEMBER "1990"
A4: DATE | B4: RESERV | C4: RESERV | D4: AC FT | E4: ACTIVE | F4: CONV TO | G4: DOLORES | H4: LOST | I4: RECORDED | J4: CALC | K4: TOTAL | L4: CALC | M4: TUNNEL | Q4: LONE | R4: U | S4: TOTAL | T4: MVI | U4: DV CR | V4: BELOW | W4: REMAIN | X4: RECORDED | Y4: CALC | Z4: TOTAL | AA4: RAIN | AB4: MAX | AC4: MIN | AD4: DATE
A5: "DEC" | B5: ELEV | C5: AC FT | D5: CHANGE | E5: CAP | F5: CFS | G5: RIVER | H5: CANYON | I5: INFLOW | J5: INFLOW | K5: INFLOW | L5: INF/OTF | M5: TOT DIV | N5: WETLAND | O5: UTE F&R | P5: MVI,CTZ | Q5: PINE | R5: LAT | S5: MVI | T5: CALL | U5: CANAL | V5: MC PHEE | W5: RELEASE | X5: OUTFLOW | Y5: OUTFLOW | Z5: OUTFLOW | AB5: TMP | AC5: TMP | AD5: "DEC"
A7: SEASON BAL
A8: YTD | B8: =NOV!B39 -> 6887.63 | C8: =NOV!C39 -> 240249 | D8: =NOV!$D$48 -> 1384 | E8: =NOV!$E$39 -> 88249 | F8: =NOV!F47 -> 697.75649 | G8: =NOV!G47 -> 2871.7 | H8: =NOV!H47 -> 0 | I8: =NOV!I47 -> 2871.7 | J8: =NOV!J47 -> 184.0763 | K8: =NOV!K47 -> 3055.7763 | L8: =NOV!L47 -> -170.44351 | M8: =NOV!M47 -> 716.9 | ... AA8: =NOV!AA47 -> 1.48
A10: 1 | B10: 6887.64 | C10: 240282 | D10: =C10-C8 -> 33 | E10: =C10-152000 -> 88282 | F10: =D10/$D$2 -> 16.637257 | G10: 52.8 | H10: 0 | I10: =G10+H10 -> 52.8 | J10: =IF(L10>0,L10,0) -> 0 | K10: =I10+J10 -> 52.8 | L10: =F10-(I10-X10) -> -0.062742627 | M10: 6.7 | N10: 0 | O10: 0 | P10: =M10-(N10+O10) -> 6.7 | Q10: 0 | R10: 0 | S10: =SUM(P10:R10) -> 6.7 | U10: 0 | V10: 29.4 | W10: =W8-V10 -> 14235.4 | X10: =N10+O10+S10+U10+V10 -> 36.1 | Y10: =IF(L10<0,L10*-1,0) -> 0.062742627 | Z10: =X10+Y10 -> 36.162743 | AA10: 0 | AB10: 35 | AC10: 11 | AD10: 1
A11: =A10+1 -> 2 | B11: 6887.64 | C11: 240282 | D11: =C11-C10 -> 0 | E11: =C11-152000 -> 88282 | F11: =D11/$D$2 -> 0 | G11: 33.4 | H11: 0 | I11: =G11+H11 -> 33.4 | J11: =IF(L11>0,L11,0) -> 0 | K11: =I11+J11 -> 33.4 | L11: =F11-(I11-X11) -> 0 | M11: 4.4 | N11: 0 | O11: 0 | P11: =M11-(N11+O11) -> 4.4 | Q11: 0 | R11: 0 | S11: =SUM(P11:R11) -> 4.4 | U11: 0 | V11: 29 | W11: =W10-V11 -> 14206.4 | X11: =N11+O11+S11+U11+V11 -> 33.4 | Y11: =IF(L11<0,L11*-1,0) -> 0 | Z11: =X11+Y11 -> 33.4 | AA11: 0 | AB11: 26 | AC11: 7 | AD11: =AD10+1 -> 2
A12: =A11+1 -> 3 | B12: 6887.65 | C12: 240315 | D12: =C12-C11 -> 33 | E12: =C12-152000 -> 88315 | F12: =D12/$D$2 -> 16.637257 | G12: 50 | H12: 0 | I12: =G12+H12 -> 50 | J12: =IF(L12>0,L12,0) -> 0.037257373 | K12: =I12+J12 -> 50.037257 | L12: =F12-(I12-X12) -> 0.037257373 | M12: 4.4 | N12: 0 | O12: 0 | P12: =M12-(N12+O12) -> 4.4 | Q12: 0 | R12: 0 | S12: =SUM(P12:R12) -> 4.4 | U12: 0 | V12: 29 | W12: =W11-V12 -> 14177.4 | X12: =N12+O12+S12+U12+V12 -> 33.4 | Y12: =IF(L12<0,L12*-1,0) -> 0 | Z12: =X12+Y12 -> 33.4 | AA12: 0 | AB12: 34 | AC12: 0 | AD12: =AD11+1 -> 3
A13: =A12+1 -> 4 | B13: 6887.66 | C13: 240348 | D13: =C13-C12 -> 33 | E13: =C13-152000 -> 88348 | F13: =D13/$D$2 -> 16.637257 | G13: 50.5 | H13: 0 | I13: =G13+H13 -> 50.5 | J13: =IF(L13>0,L13,0) -> 0.037257373 | K13: =I13+J13 -> 50.537257 | L13: =F13-(I13-X13) -> 0.037257373 | M13: 4.2 | N13: 0 | O13: 0 | P13: =M13-(N13+O13) -> 4.2 | Q13: 0 | R13: 0 | S13: =SUM(P13:R13) -> 4.2 | U13: 0 | V13: 29.7 | W13: =W12-V13 -> 14147.7 | X13: =N13+O13+S13+U13+V13 -> 33.9 | Y13: =IF(L13<0,L13*-1,0) -> 0 | Z13: =X13+Y13 -> 33.9 | AA13: 0 | AB13: 36 | AC13: 9 | AD13: =AD12+1 -> 4
A14: =A13+1 -> 5 | B14: 6887.673 | C14: 240381 | D14: =C14-C13 -> 33 | E14: =C14-152000 -> 88381 | F14: =D14/$D$2 -> 16.637257 | G14: 51.2 | H14: 0 | I14: =G14+H14 -> 51.2 | J14: =IF(L14>0,L14,0) -> 0.037257373 | K14: =I14+J14 -> 51.237257 | L14: =F14-(I14-X14) -> 0.037257373 | M14: 4.1 | N14: 0 | O14: 0 | P14: =M14-(N14+O14) -> 4.1 | Q14: 0 | R14: 0 | S14: =SUM(P14:R14) -> 4.1 | U14: 0 | V14: 30.5 | W14: =W13-V14 -> 14117.2 | X14: =N14+O14+S14+U14+V14 -> 34.6 | Y14: =IF(L14<0,L14*-1,0) -> 0 | Z14: =X14+Y14 -> 34.6 | AA14: 0 | AB14: 39 | AC14: 12 | AD14: =AD13+1 -> 5
A15: =A14+1 -> 6 | B15: 6887.68 | C15: 240414 | D15: =C15-C14 -> 33 | E15: =C15-152000 -> 88414 | F15: =D15/$D$2 -> 16.637257 | G15: 51.2 | H15: 0 | I15: =G15+H15 -> 51.2 | J15: =IF(L15>0,L15,0) -> 0 | K15: =I15+J15 -> 51.2 | L15: =F15-(I15-X15) -> -0.062742627 | M15: 4 | N15: 0 | O15: 0 | P15: =M15-(N15+O15) -> 4 | Q15: 0 | R15: 0 | S15: =SUM(P15:R15) -> 4 | U15: 0 | V15: 30.5 | W15: =W14-V15 -> 14086.7 | X15: =N15+O15+S15+U15+V15 -> 34.5 | Y15: =IF(L15<0,L15*-1,0) -> 0.062742627 | Z15: =X15+Y15 -> 34.562743 | AA15: 0 | AB15: 31 | AC15: 9 | AD15: =AD14+1 -> 6
A16: =A15+1 -> 7 | B16: 6887.69 | C16: 240447 | D16: =C16-C15 -> 33 | E16: =C16-152000 -> 88447 | F16: =D16/$D$2 -> 16.637257 | G16: 51.2 | H16: 0 | I16: =G16+H16 -> 51.2 | J16: =IF(L16>0,L16,0) -> 0.037257373 | K16: =I16+J16 -> 51.237257 | L16: =F16-(I16-X16) -> 0.037257373 | M16: 4.1 | N16: 0 | O16: 0 | P16: =M16-(N16+O16) -> 4.1 | Q16: 0 | R16: 0 | S16: =SUM(P16:R16) -> 4.1 | U16: 0 | V16: 30.5 | W16: =W15-V16 -> 14056.2 | X16: =N16+O16+S16+U16+V16 -> 34.6 | Y16: =IF(L16<0,L16*-1,0) -> 0 | Z16: =X16+Y16 -> 34.6 | AA16: 0 | AB16: 12 | AC16: 7 | AD16: =AD15+1 -> 7
A17: =A16+1 -> 8 | B17: 6887.7 | C17: 240480 | D17: =C17-C16 -> 33 | E17: =C17-152000 -> 88480 | F17: =D17/$D$2 -> 16.637257 | G17: 51 | H17: 0 | I17: =G17+H17 -> 51 | J17: =IF(L17>0,L17,0) -> 0.037257373 | K17: =I17+J17 -> 51.037257 | L17: =F17-(I17-X17) -> 0.037257373 | M17: 4.1 | N17: 0 | O17: 0 | P17: =M17-(N17+O17) -> 4.1 | Q17: 0 | R17: 0 | S17: =SUM(P17:R17) -> 4.1 | U17: 0 | V17: 30.3 | W17: =W16-V17 -> 14025.9 | X17: =N17+O17+S17+U17+V17 -> 34.4 | Y17: =IF(L17<0,L17*-1,0) -> 0 | Z17: =X17+Y17 -> 34.4 | AA17: 0 | AB17: 37 | AC17: 10 | AD17: =AD16+1 -> 8
A18: =A17+1 -> 9 | B18: 6887.71 | C18: 240513 | D18: =C18-C17 -> 33 | E18: =C18-152000 -> 88513 | F18: =D18/$D$2 -> 16.637257 | G18: 50.4 | H18: 0 | I18: =G18+H18 -> 50.4 | J18: =IF(L18>0,L18,0) -> 0.037257373 | K18: =I18+J18 -> 50.437257 | L18: =F18-(I18-X18) -> 0.037257373 | M18: 4.1 | N18: 0 | O18: 0 | P18: =M18-(N18+O18) -> 4.1 | Q18: 0 | R18: 0 | S18: =SUM(P18:R18) -> 4.1 | U18: 0 | V18: 29.7 | W18: =W17-V18 -> 13996.2 | X18: =N18+O18+S18+U18+V18 -> 33.8 | Y18: =IF(L18<0,L18*-1,0) -> 0 | Z18: =X18+Y18 -> 33.8 | AA18: 0 | AB18: 42 | AC18: 11 | AD18: =AD17+1 -> 9
A19: =A18+1 -> 10 | B19: 6887.73 | C19: 240579 | D19: =C19-C18 -> 66 | E19: =C19-152000 -> 88579 | F19: =D19/$D$2 -> 33.274515 | G19: 67.9 | H19: 0 | I19: =G19+H19 -> 67.9 | J19: =IF(L19>0,L19,0) -> 0.074514747 | K19: =I19+J19 -> 67.974515 | L19: =F19-(I19-X19) -> 0.074514747 | M19: 4.1 | N19: 0 | O19: 0 | P19: =M19-(N19+O19) -> 4.1 | Q19: 0 | R19: 0 | S19: =SUM(P19:R19) -> 4.1 | U19: 0 | V19: 30.6 | W19: =W18-V19 -> 13965.6 | X19: =N19+O19+S19+U19+V19 -> 34.7 | Y19: =IF(L19<0,L19*-1,0) -> 0 | Z19: =X19+Y19 -> 34.7 | AA19: 0 | AB19: 41 | AC19: 12 | AD19: =AD18+1 -> 10
A20: =A19+1 -> 11 | B20: 6887.76 | C20: 240678 | D20: =C20-C19 -> 99 | E20: =C20-152000 -> 88678 | F20: =D20/$D$2 -> 49.911772 | G20: 85.2 | H20: 0 | I20: =G20+H20 -> 85.2 | J20: =IF(L20>0,L20,0) -> 0.01177212 | K20: =I20+J20 -> 85.211772 | L20: =F20-(I20-X20) -> 0.01177212 | M20: 4.1 | N20: 0 | O20: 0 | P20: =M20-(N20+O20) -> 4.1 | Q20: 0 | R20: 0 | S20: =SUM(P20:R20) -> 4.1 | U20: 0 | V20: 31.2 | W20: =W19-V20 -> 13934.4 | X20: =N20+O20+S20+U20+V20 -> 35.3 | Y20: =IF(L20<0,L20*-1,0) -> 0 | Z20: =X20+Y20 -> 35.3 | AA20: 0 | AB20: 54 | AC20: 11 | AD20: =AD19+1 -> 11
A21: =A20+1 -> 12 | B21: 6887.78 | C21: 240744 | D21: =C21-C20 -> 66 | E21: =C21-152000 -> 88744 | F21: =D21/$D$2 -> 33.274515 | G21: 71 | H21: 0 | I21: =G21+H21 -> 71 | J21: =IF(L21>0,L21,0) -> 0.074514747 | K21: =I21+J21 -> 71.074515 | L21: =F21-(I21-X21) -> 0.074514747 | M21: 4.1 | N21: 0 | O21: 0 | P21: =M21-(N21+O21) -> 4.1 | Q21: 0 | R21: 0 | S21: =SUM(P21:R21) -> 4.1 | U21: 0 | V21: 33.7 | W21: =W20-V21 -> 13900.7 | X21: =N21+O21+S21+U21+V21 -> 37.8 | Y21: =IF(L21<0,L21*-1,0) -> 0 | Z21: =X21+Y21 -> 37.8 | AA21: 0.16 | AB21: 39 | AC21: 30 | AD21: =AD20+1 -> 12
A22: =A21+1 -> 13 | B22: 6887.81 | C22: 240843 | D22: =C22-C21 -> 99 | E22: =C22-152000 -> 88843 | F22: =D22/$D$2 -> 49.911772 | G22: 89.4 | H22: 0 | I22: =G22+H22 -> 89.4 | J22: =IF(L22>0,L22,0) -> 0.11177212 | K22: =I22+J22 -> 89.511772 | L22: =F22-(I22-X22) -> 0.11177212 | M22: 4.1 | N22: 0 | O22: 0 | P22: =M22-(N22+O22) -> 4.1 | Q22: 0 | R22: 0 | S22: =SUM(P22:R22) -> 4.1 | U22: 0 | V22: 35.5 | W22: =W21-V22 -> 13865.2 | X22: =N22+O22+S22+U22+V22 -> 39.6 | Y22: =IF(L22<0,L22*-1,0) -> 0 | Z22: =X22+Y22 -> 39.6 | AA22: 0.12 | AB22: 36 | AC22: 32 | AD22: =AD21+1 -> 13
... A38: =A37+1 -> 29 | B38: 6887.97 | C38: 241370 | D38: =C38-C37 -> 66 | E38: =C38-152000 -> 89370 | F38: =D38/$D$2 -> 33.274515 | G38: 69.2 | H38: 0 | I38: =G38+H38 -> 69.2 | J38: =IF(L38>0,L38,0) -> 0.074514747 | K38: =I38+J38 -> 69.274515 | L38: =F38-(I38-X38) -> 0.074514747 | M38: 4.1 | N38: 0 | O38: 0 | P38: =M38-(N38+O38) -> 4.1 | Q38: 0 | R38: 0 | S38: =SUM(P38:R38) -> 4.1 | U38: 0 | V38: 31.9 | W38: =W37-V38 -> 13328.7 | X38: =N38+O38+S38+U38+V38 -> 36 | Y38: =IF(L38<0,L38*-1,0) -> 0 | Z38: =X38+Y38 -> 36 | AA38: 0.19 | AB38: 37 | AC38: 8 | AD38: =AD37+1 -> 29
A39: 30 | B39: 6888 | C39: 241469 | D39: =C39-C38 -> 99 | E39: =C39-152000 -> 89469 | F39: =D39/$D$2 -> 49.911772 | G39: 85.9 | H39: 0 | I39: =G39+H39 -> 85.9 | J39: =IF(L39>0,L39,0) -> 0.01177212 | K39: =I39+J39 -> 85.911772 | L39: =F39-(I39-X39) -> 0.01177212 | M39: 4.1 | N39: 0 | O39: 0 | P39: =M39-(N39+O39) -> 4.1 | Q39: 0 | R39: 0 | S39: =SUM(P39:R39) -> 4.1 | U39: 0 | V39: 31.9 | W39: =W38-V39 -> 13296.8 | X39: =N39+O39+S39+U39+V39 -> 36 | Y39: =IF(L39<0,L39*-1,0) -> 0 | Z39: =X39+Y39 -> 36 | AA39: 0 | AB39: 33 | AC39: 10 | AD39: 30
A40: 31 | B40: 6888.02 | C40: 241536 | D40: =C40-C39 -> 67 | E40: =C40-152000 -> 89536 | F40: =D40/$D$2 -> 33.778674 | G40: 69.8 | H40: 0 | I40: =G40+H40 -> 69.8 | J40: =IF(L40>0,L40,0) -> 0 | K40: =I40+J40 -> 69.8 | L40: =F40-(I40-X40) -> -0.021325939 | M40: 4.1 | N40: 0 | O40: 0 | P40: =M40-(N40+O40) -> 4.1 | Q40: 0 | R40: 0 | S40: =SUM(P40:R40) -> 4.1 | U40: 0 | V40: 31.9 | W40: =W39-V40 -> 13264.9 | X40: =N40+O40+S40+U40+V40 -> 36 | Y40: =IF(L40<0,L40*-1,0) -> 0.021325939 | Z40: =X40+Y40 -> 36.021326 | AA40: 0 | AB40: 32 | AC40: -11 | AD40: 31
A42: MONTH / CFS | F42: =SUM(F10:F40) -> 648.85304 | G42: =SUM(G10:G40) -> 1778.2 | H42: =SUM(H10:H40) -> 0 | I42: =SUM(I10:I40) -> 1778.2 | J42: =SUM(J10:J40) -> 1.0041845 | K42: =SUM(K10:K40) -> 1779.2042 | L42: =SUM(L10:L40) -> 0.85303756 | M42: =SUM(M10:M40) -> 130.3 | ... S42: =SUM(S10:S40) -> 130.3 | U42: =SUM(U10:U40) -> 0 | V42: =SUM(V10:V40) -> 999.9 | X42: =SUM(X10:X40) -> 1130.2 | Y42: =SUM(Y10:Y40) -> 0.15114696 | Z42: =SUM(Z10:Z40) -> 1130.3511 | AA42: =SUM(AA10:AA40) -> 0.85 | AB42: =AVERAGE(AB10:AB40) -> 30 | AC42: =AVERAGE(AC10:AC40) -> 8.2580645 | AD42: Avg
A43: MONTH / AF | D43: =SUM(D10:D40) -> 1287 | F43: =F42*$D$2 -> 1287 | G43: =G42*$D$2 -> 3527.0597 | H43: =H42*$D$2 -> 0 | I43: =I42*$D$2 -> 3527.0597 | J43: =J42*$D$2 -> 1.9918 | K43: =K42*$D$2 -> 3529.0515 | L43: =L42*$D$2 -> 1.692 | M43: =M42*$D$2 -> 258.45005 | ... S43: =S42*$D$2 -> 258.45005 | U43: =U42*$D$2 -> 0 | V43: =V42*$D$2 -> 1983.3017 | X43: =X42*$D$2 -> 2241.7517 | Y43: =Y42*$D$2 -> 0.2998 | Z43: =Z42*$D$2 -> 2242.0515 | AB43: =MAX(AB10:AB40) -> 54 | AC43: =MAX(AC10:AC40) -> 32 | AD43: HI
A45: SEASON / CFS | AB45: =MIN(AB10:AB40) -> 8 | AC45: =MIN(AC10:AC40) -> -13 | AD45: LO
A46: SEASON / AF
A48: YTD / CFS | F48: =F8+F42 -> 1346.6095 | G48: =G8+G42 -> 4649.9 | H48: =H8+H42 -> 0 | I48: =I8+I42 -> 4649.9 | J48: =J8+J42 -> 185.08049 | K48: =K8+K42 -> 4834.9805 | L48: =L8+L42 -> -169.59047 | M48: =M8+M42 -> 847.2 | ... S48: =S8+S42 -> 1219.6 | U48: =U8+U42 -> 0 | V48: =V8+V42 -> 1914.1 | W48: =W40 -> 13264.9 | X48: =X8+X42 -> 3133.7 | Y48: =Y8+Y42 -> 354.67096 | Z48: =Z8+Z42 -> 3488.371 | AA48: =AA8+AA42 -> 2.33
A49: YTD / AF | D49: =D8+D43 -> 2671 | E49: =E40 -> 89536 | F49: =F48*$D$2 -> 2671 | G49: =G48*$D$2 -> 9223.0767 | H49: =H48*$D$2 -> 0 | I49: =I48*$D$2 -> 9223.0767 | J49: =J48*$D$2 -> 367.10715 | K49: =K48*$D$2 -> 9590.1838 | L49: =L48*$D$2 -> -336.3827 | M49: =M48*$D$2 -> 1680.4212 | ... Z49: =Z48*$D$2 -> 6919.1838

Sheet JAN
K1: MC PHEE RESERVOIR IN/OUT FLOW TABULATION
A2: AF/cfs CONVERT FACTOR | D2: 1.9835 | K2: JANUARY "1991"
A4: DATE | B4: RESERV | C4: RESERV | D4: AC FT | E4: ACTIVE | F4: CONV TO | G4: DOLORES | H4: LOST | I4: RECORDED | J4: CALC | K4: TOTAL | L4: CALC | M4: TUNNEL | Q4: LONE | R4: U | S4: TOTAL | T4: MVI | U4: DV CR | V4: BELOW | W4: REMAIN | X4: RECORDED | Y4: CALC | Z4: TOTAL | AA4: RAIN | AB4: MAX | AC4: MIN | AD4: DATE
A5: "JAN" | B5: ELEV | C5: AC FT | D5: CHANGE | E5: CAP | F5: CFS | G5: RIVER | H5: CANYON | I5: INFLOW | J5: INFLOW | K5: INFLOW | L5: INF/OTF | M5: TOT DIV | N5: WETLAND | O5: UTE F&R | P5: MVI,CTZ | Q5: PINE | R5: LAT | S5: MVI | T5: CALL | U5: CANAL | V5: MC PHEE | W5: RELEASE | X5: OUTFLOW | Y5: OUTFLOW | Z5: OUTFLOW | AB5: TMP | AC5: TMP | AD5: "JAN"
A7: SEASON BAL
A8: YTD | B8: =DEC!B40 -> 6888.02 | C8: =DEC!C40 -> 241536 | D8: =DEC!$D$49 -> 2671 | E8: =DEC!$E$40 -> 89536 | F8: =DEC!F48 -> 1346.6095 | G8: =DEC!G48 -> 4649.9 | H8: =DEC!H48 -> 0 | I8: =DEC!I48 -> 4649.9 | J8: =DEC!J48 -> 185.08049 | K8: =DEC!K48 -> 4834.9805 | L8: =DEC!L48 -> -169.59047 | M8: =DEC!M48 -> 847.2 | ... AA8: =DEC!AA48 -> 2.33
A10: 1 | B10: 6888.03 | C10: 241569 | D10: =C10-C8 -> 33 | E10: =C10-152000 -> 89569 | F10: =D10/$D$2 -> 16.637257 | G10: 52.6 | H10: 0 | I10: =G10+H10 -> 52.6 | J10: =IF(L10>0,L10,0) -> 0.037257373 | K10: =I10+J10 -> 52.637257 | L10: =F10-(I10-X10) -> 0.037257373 | M10: 4.1 | N10: 0 | O10: 0 | P10: =M10-(N10+O10) -> 4.1 | Q10: 0 | R10: 0 | S10: =SUM(P10:R10) -> 4.1 | U10: 0 | V10: 31.9 | W10: =W8-V10 -> 13233 | X10: =N10+O10+S10+U10+V10 -> 36 | Y10: =IF(L10<0,L10*-1,0) -> 0 | Z10: =X10+Y10 -> 36 | AA10: 0 | AB10: 32 | AC10: -2 | AD10: 1
A11: =A10+1 -> 2 | B11: 6888.05 | C11: 241636 | D11: =C11-C10 -> 67 | E11: =C11-152000 -> 89636 | F11: =D11/$D$2 -> 33.778674 | G11: 69.5 | H11: 0 | I11: =G11+H11 -> 69.5 | J11: =IF(L11>0,L11,0) -> 0 | K11: =I11+J11 -> 69.5 | L11: =F11-(I11-X11) -> -0.021325939 | M11: 4.1 | N11: 0 | O11: 0 | P11: =M11-(N11+O11) -> 4.1 | Q11: 0 | R11: 0 | S11: =SUM(P11:R11) -> 4.1 | U11: 0 | V11: 31.6 | W11: =W10-V11 -> 13201.4 | X11: =N11+O11+S11+U11+V11 -> 35.7 | Y11: =IF(L11<0,L11*-1,0) -> 0.021325939 | Z11: =X11+Y11 -> 35.721326 | AA11: 0 | AB11: 39 | AC11: 3 | AD11: =AD10+1 -> 2
A12: =A11+1 -> 3 | B12: 6888.08 | C12: 241736 | D12: =C12-C11 -> 100 | E12: =C12-152000 -> 89736 | F12: =D12/$D$2 -> 50.415931 | G12: 85.7 | H12: 0 | I12: =G12+H12 -> 85.7 | J12: =IF(L12>0,L12,0) -> 0.015931434 | K12: =I12+J12 -> 85.715931 | L12: =F12-(I12-X12) -> 0.015931434 | M12: 4.1 | N12: 0 | O12: 0 | P12: =M12-(N12+O12) -> 4.1 | Q12: 0 | R12: 0 | S12: =SUM(P12:R12) -> 4.1 | U12: 0 | V12: 31.2 | W12: =W11-V12 -> 13170.2 | X12: =N12+O12+S12+U12+V12 -> 35.3 | Y12: =IF(L12<0,L12*-1,0) -> 0 | Z12: =X12+Y12 -> 35.3 | AA12: 0.47 | AB12: 39 | AC12: 5 | AD12: =AD11+1 -> 3
A13: =A12+1 -> 4 | B13: 3888.12 | C13: 241869 | D13: =C13-C12 -> 133 | E13: =C13-152000 -> 89869 | F13: =D13/$D$2 -> 67.053189 | G13: 95.9 | H13: 0 | I13: =G13+H13 -> 95.9 | J13: =IF(L13>0,L13,0) -> 0.053188808 | K13: =I13+J13 -> 95.953189 | L13: =F13-(I13-X13) -> 0.053188808 | M13: 4.1 | N13: 0 | O13: 0 | P13: =M13-(N13+O13) -> 4.1 | Q13: 0 | R13: 0 | S13: =SUM(P13:R13) -> 4.1 | U13: 0 | V13: 24.8 | W13: =W12-V13 -> 13145.4 | X13: =N13+O13+S13+U13+V13 -> 28.9 | Y13: =IF(L13<0,L13*-1,0) -> 0 | Z13: =X13+Y13 -> 28.9 | AA13: 0 | AB13: 36 | AC13: 7 | AD13: =AD12+1 -> 4
A14: =A13+1 -> 5 | B14: 6888.16 | C14: 242002 | D14: =C14-C13 -> 133 | E14: =C14-152000 -> 90002 | F14: =D14/$D$2 -> 67.053189 | G14: 98.7 | H14: 0 | I14: =G14+H14 -> 98.7 | J14: =IF(L14>0,L14,0) -> 0.053188808 | K14: =I14+J14 -> 98.753189 | L14: =F14-(I14-X14) -> 0.053188808 | M14: 4.1 | N14: 0 | O14: 0 | P14: =M14-(N14+O14) -> 4.1 | Q14: 0 | R14: 0 | S14: =SUM(P14:R14) -> 4.1 | U14: 0 | V14: 27.6 | W14: =W13-V14 -> 13117.8 | X14: =N14+O14+S14+U14+V14 -> 31.7 | Y14: =IF(L14<0,L14*-1,0) -> 0 | Z14: =X14+Y14 -> 31.7 | AA14: 0 | AB14: 42 | AC14: 8 | AD14: =AD13+1 -> 5
A15: =A14+1 -> 6 | B15: 6888.21 | C15: 242169 | D15: =C15-C14 -> 167 | E15: =C15-152000 -> 90169 | F15: =D15/$D$2 -> 84.194605 | G15: 115.8 | H15: 0 | I15: =G15+H15 -> 115.8 | J15: =IF(L15>0,L15,0) -> 0 | K15: =I15+J15 -> 115.8 | L15: =F15-(I15-X15) -> -0.0053945047 | M15: 4.1 | N15: 0 | O15: 0 | P15: =M15-(N15+O15) -> 4.1 | Q15: 0 | R15: 0 | S15: =SUM(P15:R15) -> 4.1 | U15: 0 | V15: 27.5 | W15: =W14-V15 -> 13090.3 | X15: =N15+O15+S15+U15+V15 -> 31.6 | Y15: =IF(L15<0,L15*-1,0) -> 0.0053945047 | Z15: =X15+Y15 -> 31.605395 | AA15: 0.35 | AB15: 38 | AC15: 11 | AD15: =AD14+1 -> 6
A16: =A15+1 -> 7 | B16: 6888.24 | C16: 242269 | D16: =C16-C15 -> 100 | E16: =C16-152000 -> 90269 | F16: =D16/$D$2 -> 50.415931 | G16: 83.8 | H16: 0 | I16: =G16+H16 -> 83.8 | J16: =IF(L16>0,L16,0) -> 0.015931434 | K16: =I16+J16 -> 83.815931 | L16: =F16-(I16-X16) -> 0.015931434 | M16: 4.1 | N16: 0 | O16: 0 | P16: =M16-(N16+O16) -> 4.1 | Q16: 0 | R16: 0 | S16: =SUM(P16:R16) -> 4.1 | U16: 0 | V16: 29.3 | W16: =W15-V16 -> 13061 | X16: =N16+O16+S16+U16+V16 -> 33.4 | Y16: =IF(L16<0,L16*-1,0) -> 0 | Z16: =X16+Y16 -> 33.4 | AA16: 0 | AB16: 43 | AC16: 13 | AD16: =AD15+1 -> 7
A17: =A16+1 -> 8 | B17: 6888.25 | C17: 242302 | D17: =C17-C16 -> 33 | E17: =C17-152000 -> 90302 | F17: =D17/$D$2 -> 16.637257 | G17: 52.5 | H17: 0 | I17: 36 | J17: =IF(L17>0,L17,0) -> 16.537257 | K17: =I17+J17 -> 52.537257 | L17: =F17-(I17-X17) -> 16.537257 | M17: 4.1 | N17: 0 | O17: 0 | P17: =M17-(N17+O17) -> 4.1 | Q17: 0 | R17: 0 | S17: =SUM(P17:R17) -> 4.1 | U17: 0 | V17: 31.8 | W17: =W16-V17 -> 13029.2 | X17: =N17+O17+S17+U17+V17 -> 35.9 | Y17: =IF(L17<0,L17*-1,0) -> 0 | Z17: =X17+Y17 -> 35.9 | AA17: 0 | AB17: 35 | AC17: 19 | AD17: =AD16+1 -> 8
A18: =A17+1 -> 9 | B18: 6888.25 | C18: 242302 | D18: =C18-C17 -> 0 | E18: =C18-152000 -> 90302 | F18: =D18/$D$2 -> 0 | G18: 36 | H18: 0 | I18: 36 | J18: =IF(L18>0,L18,0) -> 0 | K18: =I18+J18 -> 36 | L18: =F18-(I18-X18) -> 0 | M18: 4.1 | N18: 0 | O18: 0 | P18: =M18-(N18+O18) -> 4.1 | Q18: 0 | R18: 0 | S18: =SUM(P18:R18) -> 4.1 | U18: 0 | V18: 31.9 | W18: =W17-V18 -> 12997.3 | X18: =N18+O18+S18+U18+V18 -> 36 | Y18: =IF(L18<0,L18*-1,0) -> 0 | Z18: =X18+Y18 -> 36 | AA18: 0 | AB18: 40 | AC18: 17 | AD18: =AD17+1 -> 9
A19: =A18+1 -> 10 | B19: 6888.26 | C19: 242335 | D19: =C19-C18 -> 33 | E19: =C19-152000 -> 90335 | F19: =D19/$D$2 -> 16.637257 | G19: 53.7 | H19: 0 | I19: 49.6 | J19: =IF(L19>0,L19,0) -> 4.1372574 | K19: =I19+J19 -> 53.737257 | L19: =F19-(I19-X19) -> 4.1372574 | M19: 5.8 | N19: 0 | O19: 0 | P19: =M19-(N19+O19) -> 5.8 | Q19: 0 | R19: 0 | S19: =SUM(P19:R19) -> 5.8 | U19: 0 | V19: 31.3 | W19: =W18-V19 -> 12966 | X19: =N19+O19+S19+U19+V19 -> 37.1 | Y19: =IF(L19<0,L19*-1,0) -> 0 | Z19: =X19+Y19 -> 37.1 | AA19: 0 | AB19: 30 | AC19: 14 | AD19: =AD18+1 -> 10
A20: =A19+1 -> 11 | B20: 6888.27 | C20: 242369 | D20: =C20-C19 -> 34 | E20: =C20-152000 -> 90369 | F20: =D20/$D$2 -> 17.141417 | G20: 54.6 | H20: 0 | I20: 31.1 | J20: =IF(L20>0,L20,0) -> 23.541417 | K20: =I20+J20 -> 54.641417 | L20: =F20-(I20-X20) -> 23.541417 | M20: 5.4 | N20: 0 | O20: 0 | P20: =M20-(N20+O20) -> 5.4 | Q20: 0 | R20: 0 | S20: =SUM(P20:R20) -> 5.4 | U20: 0 | V20: 32.1 | W20: =W19-V20 -> 12933.9 | X20: =N20+O20+S20+U20+V20 -> 37.5 | Y20: =IF(L20<0,L20*-1,0) -> 0 | Z20: =X20+Y20 -> 37.5 | AA20: 0 | AB20: 33 | AC20: 10 | AD20: =AD19+1 -> 11
A21: =A20+1 -> 12 | B21: 6888.28 | C21: 242402 | D21: =C21-C20 -> 33 | E21: =C21-152000 -> 90402 | F21: =D21/$D$2 -> 16.637257 | G21: 55.2 | H21: 0 | I21: 34.1 | J21: =IF(L21>0,L21,0) -> 21.137257 | K21: =I21+J21 -> 55.237257 | L21: =F21-(I21-X21) -> 21.137257 | M21: 5.3 | N21: 0 | O21: 0 | P21: =M21-(N21+O21) -> 5.3 | Q21: 0 | R21: 0 | S21: =SUM(P21:R21) -> 5.3 | U21: 0 | V21: 33.3 | W21: =W20-V21 -> 12900.6 | X21: =N21+O21+S21+U21+V21 -> 38.6 | Y21: =IF(L21<0,L21*-1,0) -> 0 | Z21: =X21+Y21 -> 38.6 | AA21: 0 | AB21: 34 | AC21: 7 | AD21: =AD20+1 -> 12
A22: 13 | B22: 6888.3 | C22: 242469 | D22: =C22-C21 -> 67 | E22: =C22-152000 -> 90469 | F22: =D22/$D$2 -> 33.778674 | G22: 72.1 | H22: 0 | I22: 34.1 | J22: =IF(L22>0,L22,0) -> 37.978674 | K22: =I22+J22 -> 72.078674 | L22: =F22-(I22-X22) -> 37.978674 | M22: 5.1 | N22: 0 | O22: 0 | P22: =M22-(N22+O22) -> 5.1 | Q22: 0 | R22: 0 | S22: =SUM(P22:R22) -> 5.1 | U22: 0 | V22: 33.2 | W22: =W21-V22 -> 12867.4 | X22: =N22+O22+S22+U22+V22 -> 38.3 | Y22: =IF(L22<0,L22*-1,0) -> 0 | Z22: =X22+Y22 -> 38.3 | AA22: 0.06 | AB22: 33 | AC22: 5 | AD22: =AD21+1 -> 13
A23: =A22+1 -> 14 | B23: 6888.32 | C23: 242535 | D23: =C23-C22 -> 66 | E23: =C23-152000 -> 90535 | F23: =D23/$D$2 -> 33.274515 | G23: 70.7 | H23: 0 | I23: =G23+H23 -> 70.7 | J23: =IF(L23>0,L23,0) -> 1.0745147 | K23: =I23+J23 -> 71.774515 | L23: =F23-(I23-X23) -> 1.0745147 | M23: 5.4 | N23: 0 | O23: 0 | P23: =M23-(N23+O23) -> 5.4 | Q23: 0 | R23: 0 | S23: =SUM(P23:R23) -> 5.4 | U23: 0 | V23: 33.1 | W23: =W22-V23 -> 12834.3 | X23: =N23+O23+S23+U23+V23 -> 38.5 | Y23: =IF(L23<0,L23*-1,0) -> 0 | Z23: =X23+Y23 -> 38.5 | AA23: 0 | AB23: 33 | AC23: 9 | AD23: =AD22+1 -> 14
A24: =A23+1 -> 15 | B24: 6888.33 | C24: 242569 | D24: =C24-C23 -> 34 | E24: =C24-152000 -> 90569 | F24: =D24/$D$2 -> 17.141417 | G24: 53.8 | H24: 0 | I24: =G24+H24 -> 53.8 | J24: =IF(L24>0,L24,0) -> 0 | K24: =I24+J24 -> 53.8 | L24: =F24-(I24-X24) -> -0.058583312 | M24: 5.1 | N24: 0 | O24: 0 | P24: =M24-(N24+O24) -> 5.1 | Q24: 0 | R24: 0 | S24: =SUM(P24:R24) -> 5.1 | U24: 0 | V24: 31.5 | W24: =W23-V24 -> 12802.8 | X24: =N24+O24+S24+U24+V24 -> 36.6 | Y24: =IF(L24<0,L24*-1,0) -> 0.058583312 | Z24: =X24+Y24 -> 36.658583 | AA24: 0.02 | AB24: 32 | AC24: 5 | AD24: =AD23+1 -> 15
A25: =A24+1 -> 16 | B25: 6888.34 | C25: 242602 | D25: =C25-C24 -> 33 | E25: =C25-152000 -> 90602 | F25: =D25/$D$2 -> 16.637257 | G25: 53 | H25: 0 | I25: =G25+H25 -> 53 | J25: =IF(L25>0,L25,0) -> 0.037257373 | K25: =I25+J25 -> 53.037257 | L25: =F25-(I25-X25) -> 0.037257373 | M25: 5.1 | N25: 0 | O25: 0 | P25: =M25-(N25+O25) -> 5.1 | Q25: 0 | R25: 0 | S25: =SUM(P25:R25) -> 5.1 | U25: 0 | V25: 31.3 | W25: =W24-V25 -> 12771.5 | X25: =N25+O25+S25+U25+V25 -> 36.4 | Y25: =IF(L25<0,L25*-1,0) -> 0 | Z25: =X25+Y25 -> 36.4 | AA25: 0 | AB25: 35 | AC25: 16 | AD25: =AD24+1 -> 16
A26: =A25+1 -> 17 | B26: 6888.35 | C26: 242635 | D26: =C26-C25 -> 33 | E26: =C26-152000 -> 90635 | F26: =D26/$D$2 -> 16.637257 | G26: 53 | H26: 0 | I26: =G26+H26 -> 53 | J26: =IF(L26>0,L26,0) -> 0 | K26: =I26+J26 -> 53 | L26: =F26-(I26-X26) -> -0.062742627 | M26: 5.1 | N26: 0 | O26: 0 | P26: =M26-(N26+O26) -> 5.1 | Q26: 0 | R26: 0 | S26: =SUM(P26:R26) -> 5.1 | U26: 0 | V26: 31.2 | W26: =W25-V26 -> 12740.3 | X26: =N26+O26+S26+U26+V26 -> 36.3 | Y26: =IF(L26<0,L26*-1,0) -> 0.062742627 | Z26: =X26+Y26 -> 36.362743 | AA26: 0 | AB26: 36 | AC26: 4 | AD26: =AD25+1 -> 17
A27: =A26+1 -> 18 | B27: 6888.37 | C27: 242702 | D27: =C27-C26 -> 67 | E27: =C27-152000 -> 90702 | F27: =D27/$D$2 -> 33.778674 | G27: 70.1 | H27: 0 | I27: =G27+H27 -> 70.1 | J27: =IF(L27>0,L27,0) -> 0 | K27: =I27+J27 -> 70.1 | L27: =F27-(I27-X27) -> -0.021325939 | M27: 5.1 | N27: 0 | O27: 0 | P27: =M27-(N27+O27) -> 5.1 | Q27: 0 | R27: 0 | S27: =SUM(P27:R27) -> 5.1 | U27: 0 | V27: 31.2 | W27: =W26-V27 -> 12709.1 | X27: =N27+O27+S27+U27+V27 -> 36.3 | Y27: =IF(L27<0,L27*-1,0) -> 0.021325939 | Z27: =X27+Y27 -> 36.321326 | AA27: 0 | AB27: 36 | AC27: 7 | AD27: =AD26+1 -> 18
A28: =A27+1 -> 19 | B28: 6888.39 | C28: 242769 | D28: =C28-C27 -> 67 | E28: =C28-152000 -> 90769 | F28: =D28/$D$2 -> 33.778674 | G28: 70.2 | H28: 0 | I28: =G28+H28 -> 70.2 | J28: =IF(L28>0,L28,0) -> 0 | K28: =I28+J28 -> 70.2 | L28: =F28-(I28-X28) -> -0.021325939 | M28: 5.1 | N28: 0 | O28: 0 | P28: =M28-(N28+O28) -> 5.1 | Q28: 0 | R28: 0 | S28: =SUM(P28:R28) -> 5.1 | U28: 0 | V28: 31.3 | W28: =W27-V28 -> 12677.8 | X28: =N28+O28+S28+U28+V28 -> 36.4 | Y28: =IF(L28<0,L28*-1,0) -> 0.021325939 | Z28: =X28+Y28 -> 36.421326 | AA28: 0 | AB28: 33 | AC28: 9 | AD28: =AD27+1 -> 19
A29: =A28+1 -> 20 | B29: 6888.41 | C29: 242835 | D29: =C29-C28 -> 66 | E29: =C29-152000 -> 90835 | F29: =D29/$D$2 -> 33.274515 | G29: 69.7 | H29: 0 | I29: =G29+H29 -> 69.7 | J29: =IF(L29>0,L29,0) -> 0.074514747 | K29: =I29+J29 -> 69.774515 | L29: =F29-(I29-X29) -> 0.074514747 | M29: 5.1 | N29: 0 | O29: 0 | P29: =M29-(N29+O29) -> 5.1 | Q29: 0 | R29: 0 | S29: =SUM(P29:R29) -> 5.1 | U29: 0 | V29: 31.4 | W29: =W28-V29 -> 12646.4 | X29: =N29+O29+S29+U29+V29 -> 36.5 | Y29: =IF(L29<0,L29*-1,0) -> 0 | Z29: =X29+Y29 -> 36.5 | AA29: 0.02 | AB29: 31 | AC29: 8 | AD29: =AD28+1 -> 20
A30: =A29+1 -> 21 | B30: 6888.41 | C30: 242835 | D30: =C30-C29 -> 0 | E30: =C30-152000 -> 90835 | F30: =D30/$D$2 -> 0 | G30: 36.4 | H30: 0 | I30: =G30+H30 -> 36.4 | J30: =IF(L30>0,L30,0) -> 0 | K30: =I30+J30 -> 36.4 | L30: =F30-(I30-X30) -> -0.1 | M30: 5.1 | N30: 0 | O30: 0 | P30: =M30-(N30+O30) -> 5.1 | Q30: 0 | R30: 0 | S30: =SUM(P30:R30) -> 5.1 | U30: 0 | V30: 31.2 | W30: =W29-V30 -> 12615.2 | X30: =N30+O30+S30+U30+V30 -> 36.3 | Y30: =IF(L30<0,L30*-1,0) -> 0.1 | Z30: =X30+Y30 -> 36.4 | AA30: 0 | AB30: 26 | AC30: 11 | AD30: =AD29+1 -> 21
A31: =A30+1 -> 22 | B31: 6888.41 | C31: 242835 | D31: =C31-C30 -> 0 | E31: =C31-152000 -> 90835 | F31: =D31/$D$2 -> 0 | G31: 36.3 | H31: 0 | I31: =G31+H31 -> 36.3 | J31: =IF(L31>0,L31,0) -> 0 | K31: =I31+J31 -> 36.3 | L31: =F31-(I31-X31) -> 0 | M31: 5.1 | N31: 0 | O31: 0 | P31: =M31-(N31+O31) -> 5.1 | Q31: 0 | R31: 0 | S31: =SUM(P31:R31) -> 5.1 | U31: 0 | V31: 31.2 | W31: =W30-V31 -> 12584 | X31: =N31+O31+S31+U31+V31 -> 36.3 | Y31: =IF(L31<0,L31*-1,0) -> 0 | Z31: =X31+Y31 -> 36.3 | AA31: 0 | AB31: 28 | AC31: -7 | AD31: =AD30+1 -> 22
A32: =A31+1 -> 23 | B32: 6888.42 | C32: 242869 | D32: =C32-C31 -> 34 | E32: =C32-152000 -> 90869 | F32: =D32/$D$2 -> 17.141417 | G32: 53.5 | H32: 0 | I32: =G32+H32 -> 53.5 | J32: =IF(L32>0,L32,0) -> 0 | K32: =I32+J32 -> 53.5 | L32: =F32-(I32-X32) -> -0.058583312 | M32: 5.1 | N32: 0 | O32: 0 | P32: =M32-(N32+O32) -> 5.1 | Q32: 0 | R32: 0 | S32: =SUM(P32:R32) -> 5.1 | U32: 0 | V32: 31.2 | W32: =W31-V32 -> 12552.8 | X32: =N32+O32+S32+U32+V32 -> 36.3 | Y32: =IF(L32<0,L32*-1,0) -> 0.058583312 | Z32: =X32+Y32 -> 36.358583 | AA32: 0 | AB32: 25 | AC32: -5 | AD32: =AD31+1 -> 23
A33: =A32+1 -> 24 | B33: 6888.43 | C33: 242902 | D33: =C33-C32 -> 33 | E33: =C33-152000 -> 90902 | F33: =D33/$D$2 -> 16.637257 | G33: 53 | H33: 0 | I33: =G33+H33 -> 53 | J33: =IF(L33>0,L33,0) -> 0 | K33: =I33+J33 -> 53 | L33: =F33-(I33-X33) -> -0.062742627 | M33: 5.1 | N33: 0 | O33: 0 | P33: =M33-(N33+O33) -> 5.1 | Q33: 0 | R33: 0 | S33: =SUM(P33:R33) -> 5.1 | U33: 0 | V33: 31.2 | W33: =W32-V33 -> 12521.6 | X33: =N33+O33+S33+U33+V33 -> 36.3 | Y33: =IF(L33<0,L33*-1,0) -> 0.062742627 | Z33: =X33+Y33 -> 36.362743 | AA33: 0 | AB33: 35 | AC33: -6 | AD33: =AD32+1 -> 24
A34: =A33+1 -> 25 | B34: 6888.44 | C34: 242935 | D34: =C34-C33 -> 33 | E34: =C34-152000 -> 90935 | F34: =D34/$D$2 -> 16.637257 | G34: 52.5 | H34: 0 | I34: =G34+H34 -> 52.5 | J34: =IF(L34>0,L34,0) -> 0 | K34: =I34+J34 -> 52.5 | L34: =F34-(I34-X34) -> -0.16274263 | M34: 4.5 | N34: 0 | O34: 0 | P34: =M34-(N34+O34) -> 4.5 | Q34: 0 | R34: 0 | S34: =SUM(P34:R34) -> 4.5 | U34: 0 | V34: 31.2 | W34: =W33-V34 -> 12490.4 | X34: =N34+O34+S34+U34+V34 -> 35.7 | Y34: =IF(L34<0,L34*-1,0) -> 0.16274263 | Z34: =X34+Y34 -> 35.862743 | AA34: 0 | AB34: 36 | AC34: 1 | AD34: =AD33+1 -> 25
... A38: =A37+1 -> 29 | B38: 6888.47 | C38: 243035 | D38: =C38-C37 -> 0 | E38: =C38-152000 -> 91035 | F38: =D38/$D$2 -> 0 | G38: 43 | H38: 0 | I38: =G38+H38 -> 43 | J38: =IF(L38>0,L38,0) -> 0 | K38: =I38+J38 -> 43 | L38: =F38-(I38-X38) -> 0 | M38: 4.2 | N38: 0 | O38: 0 | P38: =M38-(N38+O38) -> 4.2 | Q38: 0 | R38: 0 | S38: =SUM(P38:R38) -> 4.2 | U38: 0 | V38: 38.8 | W38: =W37-V38 -> 12354.4 | X38: =N38+O38+S38+U38+V38 -> 43 | Y38: =IF(L38<0,L38*-1,0) -> 0 | Z38: =X38+Y38 -> 43 | AA38: 0 | AB38: 26 | AC38: 11 | AD38: =AD37+1 -> 29
A39: 30 | B39: 6888.48 | C39: 243069 | D39: =C39-C38 -> 34 | E39: =C39-152000 -> 91069 | F39: =D39/$D$2 -> 17.141417 | G39: 60 | H39: 0 | I39: =G39+H39 -> 60 | J39: =IF(L39>0,L39,0) -> 0.041416688 | K39: =I39+J39 -> 60.041417 | L39: =F39-(I39-X39) -> 0.041416688 | M39: 4.1 | N39: 0 | O39: 0 | P39: =M39-(N39+O39) -> 4.1 | Q39: 0 | R39: 0 | S39: =SUM(P39:R39) -> 4.1 | U39: 0 | V39: 38.8 | W39: =W38-V39 -> 12315.6 | X39: =N39+O39+S39+U39+V39 -> 42.9 | Y39: =IF(L39<0,L39*-1,0) -> 0 | Z39: =X39+Y39 -> 42.9 | AA39: 0 | AB39: 29 | AC39: -3 | AD39: 30
A40: 31 | B40: 6888.48 | C40: 243069 | D40: =C40-C39 -> 0 | E40: =C40-152000 -> 91069 | F40: =D40/$D$2 -> 0 | G40: 42.9 | H40: 0 | I40: =G40+H40 -> 42.9 | J40: =IF(L40>0,L40,0) -> 0 | K40: =I40+J40 -> 42.9 | L40: =F40-(I40-X40) -> 0 | M40: 4.1 | N40: 0 | O40: 0 | P40: =M40-(N40+O40) -> 4.1 | Q40: 0 | R40: 0 | S40: =SUM(P40:R40) -> 4.1 | U40: 0 | V40: 38.8 | W40: =W39-V40 -> 12276.8 | X40: =N40+O40+S40+U40+V40 -> 42.9 | Y40: =IF(L40<0,L40*-1,0) -> 0 | Z40: =X40+Y40 -> 42.9 | AA40: 0 | AB40: 37 | AC40: -2 | AD40: 31
AB41: 39
A42: MONTH / CFS | F42: =SUM(F10:F40) -> 772.87623 | G42: =SUM(G10:G40) -> 1904.7 | H42: =SUM(H10:H40) -> 0 | I42: =SUM(I10:I40) -> 1801.5 | J42: =SUM(J10:J40) -> 104.81374 | K42: =SUM(K10:K40) -> 1906.3137 | L42: =SUM(L10:L40) -> 104.17623 | M42: =SUM(M10:M40) -> 144.7 | ... S42: =SUM(S10:S40) -> 144.7 | U42: =SUM(U10:U40) -> 0 | V42: =SUM(V10:V40) -> 988.1 | X42: =SUM(X10:X40) -> 1132.8 | Y42: =SUM(Y10:Y40) -> 0.63750945 | Z42: =SUM(Z10:Z40) -> 1133.4375 | AA42: =SUM(AA10:AA40) -> 0.92 | AB42: =AVERAGE(AB10:AB40) -> 34.354839 | AC42: =AVERAGE(AC10:AC40) -> 5.9677419 | AD42: AVE
A43: MONTH / AF | D43: =SUM(D10:D40) -> 1533 | F43: =F42*$D$2 -> 1533 | G43: =G42*$D$2 -> 3777.9725 | H43: =H42*$D$2 -> 0 | I43: =I42*$D$2 -> 3573.2753 | J43: =J42*$D$2 -> 207.89805 | K43: =K42*$D$2 -> 3781.1733 | L43: =L42*$D$2 -> 206.63355 | M43: =M42*$D$2 -> 287.01245 | ... S43: =S42*$D$2 -> 287.01245 | U43: =U42*$D$2 -> 0 | V43: =V42*$D$2 -> 1959.8963 | X43: =X42*$D$2 -> 2246.9088 | Y43: =Y42*$D$2 -> 1.2645 | Z43: =Z42*$D$2 -> 2248.1733 | AB43: =MAX(AB10:AB40) -> 43 | AC43: =MAX(AC10:AC40) -> 19 | AD43: HI
A45: SEASON / CFS | AB45: =MIN(AB10:AB40) -> 25 | AC45: =MIN(AC10:AC40) -> -7 | AD45: LO
A46: SEASON / AF
A48: YTD / CFS | F48: =F8+F42 -> 2119.4858 | G48: =G8+G42 -> 6554.6 | H48: =H8+H42 -> 0 | I48: =I8+I42 -> 6451.4 | J48: =J8+J42 -> 289.89423 | K48: =K8+K42 -> 6741.2942 | L48: =L8+L42 -> -65.414243 | M48: =M8+M42 -> 991.9 | ... S48: =S8+S42 -> 1364.3 | U48: =U8+U42 -> 0 | V48: =V8+V42 -> 2902.2 | W48: =W40 -> 12276.8 | X48: =X8+X42 -> 4266.5 | Y48: =Y8+Y42 -> 355.30847 | Z48: =Z8+Z42 -> 4621.8085 | AA48: =AA8+AA42 -> 3.25
...

Sheet FEB
K1: MC PHEE RESERVOIR IN/OUT FLOW TABULATION
A2: AF/cfs CONVERT FACTOR | D2: 1.9835 | K2: FEBRUARY "1991"
A4: DATE | B4: RESERV | C4: RESERV | D4: AC FT | E4: ACTIVE | F4: CONV TO | G4: DOLORES | H4: LOST | I4: RECORDED | J4: CALC | K4: TOTAL | L4: CALC | M4: TUNNEL | Q4: LONE | R4: U | S4: TOTAL | T4: MVI | U4: DV CR | V4: BELOW | W4: REMAIN | X4: RECORDED | Y4: CALC | Z4: TOTAL | AA4: RAIN | AB4: MAX | AC4: MIN | AD4: DATE
A5: FEB | B5: ELEV | C5: AC FT | D5: CHANGE | E5: CAP | F5: CFS | G5: RIVER | H5: CANYON | I5: INFLOW | J5: INFLOW | K5: INFLOW | L5: INF/OTF | M5: TOT DIV | N5: WETLAND | O5: UTE F&R | P5: MVI,CTZ | Q5: PINE | R5: LAT | S5: MVI | T5: CALL | U5: CANAL | V5: MC PHEE | W5: RELEASE | X5: OUTFLOW | Y5: OUTFLOW | Z5: OUTFLOW | AB5: TMP | AC5: TMP | AD5: FEB
A7: SEASON BAL
A8: YTD | B8: =JAN!B40 -> 6888.48 | C8: =JAN!C40 -> 243069 | D8: =JAN!$D$49 -> 4204 | E8: =JAN!$E$40 -> 91069 | F8: =JAN!F48 -> 2119.4858 | G8: =JAN!G48 -> 6554.6 | H8: =JAN!H48 -> 0 | I8: =JAN!I48 -> 6451.4 | J8: =JAN!J48 -> 289.89423 | K8: =JAN!K48 -> 6741.2942 | L8: =JAN!L48 -> -65.414243 | M8: =JAN!M48 -> 991.9 | ... AA8: =JAN!AA48 -> 3.25
A10: 1 | B10: 6888.48 | C10: 243069 | D10: =C10-C8 -> 0 | E10: =C10-152000 -> 91069 | F10: =D10/$D$2 -> 0 | G10: 42 | H10: 0 | I10: =G10+H10 -> 42 | J10: =IF(L10>0,L10,0) -> 0.02 | K10: =I10+J10 -> 42.02 | L10: =F10-(I10-X10) -> 0.02 | M10: 3.6 | N10: 0 | O10: 0 | P10: =M10-(N10+O10) -> 3.6 | Q10: 0 | R10: 0 | S10: =SUM(P10:R10) -> 3.6 | U10: 0 | V10: 38.42 | W10: =W8-V10 -> 12238.38 | X10: =N10+O10+S10+U10+V10 -> 42.02 | Y10: =IF(L10<0,L10*-1,0) -> 0 | Z10: =X10+Y10 -> 42.02 | AA10: 0 | AB10: 45 | AC10: 3 | AD10: 1
A11: =A10+1 -> 2 | B11: 6888.49 | C11: 243102 | D11: =C11-C10 -> 33 | E11: =C11-152000 -> 91102 | F11: =D11/$D$2 -> 16.637257 | G11: 57.8 | H11: 0 | I11: =G11+H11 -> 57.8 | J11: =IF(L11>0,L11,0) -> 0 | K11: =I11+J11 -> 57.8 | L11: =F11-(I11-X11) -> -0.012742627 | M11: 3.08 | N11: 0 | O11: 0 | P11: =M11-(N11+O11) -> 3.08 | Q11: 0 | R11: 0 | S11: =SUM(P11:R11) -> 3.08 | U11: 0 | V11: 38.07 | W11: =W10-V11 -> 12200.31 | X11: =N11+O11+S11+U11+V11 -> 41.15 | Y11: =IF(L11<0,L11*-1,0) -> 0.012742627 | Z11: =X11+Y11 -> 41.162743 | AA11: 0 | AB11: 46 | AC11: 5 | AD11: =AD10+1 -> 2
A12: =A11+1 -> 3 | B12: 6888.49 | C12: 243102 | D12: =C12-C11 -> 0 | E12: =C12-152000 -> 91102 | F12: =D12/$D$2 -> 0 | G12: 42.4 | H12: 0 | I12: =G12+H12 -> 42.4 | J12: =IF(L12>0,L12,0) -> 0 | K12: =I12+J12 -> 42.4 | L12: =F12-(I12-X12) -> -0.16 | M12: 3.08 | N12: 0 | O12: 0 | P12: =M12-(N12+O12) -> 3.08 | Q12: 0 | R12: 0 | S12: =SUM(P12:R12) -> 3.08 | U12: 0 | V12: 39.16 | W12: =W11-V12 -> 12161.15 | X12: =N12+O12+S12+U12+V12 -> 42.24 | Y12: =IF(L12<0,L12*-1,0) -> 0.16 | Z12: =X12+Y12 -> 42.4 | AA12: 0 | AB12: 48 | AC12: 7 | AD12: =AD11+1 -> 3
A13: =A12+1 -> 4 | B13: 6888.5 | C13: 243135 | D13: =C13-C12 -> 33 | E13: =C13-152000 -> 91135 | F13: =D13/$D$2 -> 16.637257 | G13: 60.5 | H13: 0 | I13: =G13+H13 -> 60.5 | J13: =IF(L13>0,L13,0) -> 0 | K13: =I13+J13 -> 60.5 | L13: =F13-(I13-X13) -> -0.022742627 | M13: 4.68 | N13: 0 | O13: 0 | P13: =M13-(N13+O13) -> 4.68 | Q13: 0 | R13: 0 | S13: =SUM(P13:R13) -> 4.68 | U13: 0 | V13: 39.16 | W13: =W12-V13 -> 12121.99 | X13: =N13+O13+S13+U13+V13 -> 43.84 | Y13: =IF(L13<0,L13*-1,0) -> 0.022742627 | Z13: =X13+Y13 -> 43.862743 | AA13: 0 | AB13: 46 | AC13: 10 | AD13: =AD12+1 -> 4
A14: =A13+1 -> 5 | B14: 6888.5 | C14: 243135 | D14: =C14-C13 -> 0 | E14: =C14-152000 -> 91135 | F14: =D14/$D$2 -> 0 | G14: 42.6 | H14: 0 | I14: =G14+H14 -> 42.6 | J14: =IF(L14>0,L14,0) -> 0 | K14: =I14+J14 -> 42.6 | L14: =F14-(I14-X14) -> -0.05 | M14: 3.39 | N14: 0 | O14: 0 | P14: =M14-(N14+O14) -> 3.39 | Q14: 0 | R14: 0 | S14: =SUM(P14:R14) -> 3.39 | U14: 0 | V14: 39.16 | W14: =W13-V14 -> 12082.83 | X14: =N14+O14+S14+U14+V14 -> 42.55 | Y14: =IF(L14<0,L14*-1,0) -> 0.05 | Z14: =X14+Y14 -> 42.6 | AA14: 0 | AB14: 45 | AC14: 10 | AD14: =AD13+1 -> 5
A15: =A14+1 -> 6 | B15: 6888.5 | C15: 243135 | D15: =C15-C14 -> 0 | E15: =C15-152000 -> 91135 | F15: =D15/$D$2 -> 0 | G15: 42.6 | H15: 0 | I15: =G15+H15 -> 42.6 | J15: =IF(L15>0,L15,0) -> 0 | K15: =I15+J15 -> 42.6 | L15: =F15-(I15-X15) -> -0.05 | M15: 3.39 | N15: 0 | O15: 0 | P15: =M15-(N15+O15) -> 3.39 | Q15: 0 | R15: 0 | S15: =SUM(P15:R15) -> 3.39 | U15: 0 | V15: 39.16 | W15: =W14-V15 -> 12043.67 | X15: =N15+O15+S15+U15+V15 -> 42.55 | Y15: =IF(L15<0,L15*-1,0) -> 0.05 | Z15: =X15+Y15 -> 42.6 | AA15: 0 | AB15: 50 | AC15: 9 | AD15: =AD14+1 -> 6
A16: =A15+1 -> 7 | B16: 6888.51 | C16: 243168 | D16: =C16-C15 -> 33 | E16: =C16-152000 -> 91168 | F16: =D16/$D$2 -> 16.637257 | G16: 59.2 | H16: 0 | I16: =G16+H16 -> 59.2 | J16: =IF(L16>0,L16,0) -> 0 | K16: =I16+J16 -> 59.2 | L16: =F16-(I16-X16) -> -0.012742627 | M16: 3.39 | N16: 0 | O16: 0 | P16: =M16-(N16+O16) -> 3.39 | Q16: 0 | R16: 0 | S16: =SUM(P16:R16) -> 3.39 | U16: 0 | V16: 39.16 | W16: =W15-V16 -> 12004.51 | X16: =N16+O16+S16+U16+V16 -> 42.55 | Y16: =IF(L16<0,L16*-1,0) -> 0.012742627 | Z16: =X16+Y16 -> 42.562743 | AA16: 0 | AB16: 53 | AC16: 20 | AD16: =AD15+1 -> 7
A17: =A16+1 -> 8 | B17: 6888.52 | C17: 243202 | D17: =C17-C16 -> 34 | E17: =C17-152000 -> 91202 | F17: =D17/$D$2 -> 17.141417 | G17: 55.5 | H17: 0 | I17: =G17+H17 -> 55.5 | J17: =IF(L17>0,L17,0) -> 0.031416688 | K17: =I17+J17 -> 55.531417 | L17: =F17-(I17-X17) -> 0.031416688 | M17: 3.39 | N17: 0 | O17: 0 | P17: =M17-(N17+O17) -> 3.39 | Q17: 0 | R17: 0 | S17: =SUM(P17:R17) -> 3.39 | U17: 0 | V17: 35 | W17: =W16-V17 -> 11969.51 | X17: =N17+O17+S17+U17+V17 -> 38.39 | Y17: =IF(L17<0,L17*-1,0) -> 0 | Z17: =X17+Y17 -> 38.39 | AA17: 0 | AB17: 51 | AC17: 20 | AD17: =AD16+1 -> 8
A18: =A17+1 -> 9 | B18: 6888.53 | C18: 243235 | D18: =C18-C17 -> 33 | E18: =C18-152000 -> 91235 | F18: =D18/$D$2 -> 16.637257 | G18: 49.7 | H18: 0 | I18: =G18+H18 -> 49.7 | J18: =IF(L18>0,L18,0) -> 0.027257373 | K18: =I18+J18 -> 49.727257 | L18: =F18-(I18-X18) -> 0.027257373 | M18: 3.39 | N18: 0 | O18: 0 | P18: =M18-(N18+O18) -> 3.39 | Q18: 0 | R18: 0 | S18: =SUM(P18:R18) -> 3.39 | U18: 0 | V18: 29.7 | W18: =W17-V18 -> 11939.81 | X18: =N18+O18+S18+U18+V18 -> 33.09 | Y18: =IF(L18<0,L18*-1,0) -> 0 | Z18: =X18+Y18 -> 33.09 | AA18: 0 | AB18: 49 | AC18: 16 | AD18: =AD17+1 -> 9
A19: =A18+1 -> 10 | B19: 6888.54 | C19: 243268 | D19: =C19-C18 -> 33 | E19: =C19-152000 -> 91268 | F19: =D19/$D$2 -> 16.637257 | G19: 49.7 | H19: 0 | I19: =G19+H19 -> 49.7 | J19: =IF(L19>0,L19,0) -> 0.027257373 | K19: =I19+J19 -> 49.727257 | L19: =F19-(I19-X19) -> 0.027257373 | M19: 3.39 | N19: 0 | O19: 0 | P19: =M19-(N19+O19) -> 3.39 | Q19: 0 | R19: 0 | S19: =SUM(P19:R19) -> 3.39 | U19: 0 | V19: 29.7 | W19: =W18-V19 -> 11910.11 | X19: =N19+O19+S19+U19+V19 -> 33.09 | Y19: =IF(L19<0,L19*-1,0) -> 0 | Z19: =X19+Y19 -> 33.09 | AA19: 0 | AB19: 48 | AC19: 14 | AD19: =AD18+1 -> 10
A20: =A19+1 -> 11 | B20: 6888.57 | C20: 243368 | D20: =C20-C19 -> 100 | E20: =C20-152000 -> 91368 | F20: =D20/$D$2 -> 50.415931 | G20: 82.7 | H20: 0 | I20: =G20+H20 -> 82.7 | J20: =IF(L20>0,L20,0) -> 0.015931434 | K20: =I20+J20 -> 82.715931 | L20: =F20-(I20-X20) -> 0.015931434 | M20: 3.39 | N20: 0 | O20: 0 | P20: =M20-(N20+O20) -> 3.39 | Q20: 0 | R20: 0 | S20: =SUM(P20:R20) -> 3.39 | U20: 0 | V20: 28.91 | W20: =W19-V20 -> 11881.2 | X20: =N20+O20+S20+U20+V20 -> 32.3 | Y20: =IF(L20<0,L20*-1,0) -> 0 | Z20: =X20+Y20 -> 32.3 | AA20: 0 | AB20: 51 | AC20: 12 | AD20: =AD19+1 -> 11
A21: =A20+1 -> 12 | B21: 6888.58 | C21: 243402 | D21: =C21-C20 -> 34 | E21: =C21-152000 -> 91402 | F21: =D21/$D$2 -> 17.141417 | G21: 50.6 | H21: 0 | I21: =G21+H21 -> 50.6 | J21: =IF(L21>0,L21,0) -> 0.011416688 | K21: =I21+J21 -> 50.611417 | L21: =F21-(I21-X21) -> 0.011416688 | M21: 3.39 | N21: 0 | O21: 0 | P21: =M21-(N21+O21) -> 3.39 | Q21: 0 | R21: 0 | S21: =SUM(P21:R21) -> 3.39 | U21: 0 | V21: 30.08 | W21: =W20-V21 -> 11851.12 | X21: =N21+O21+S21+U21+V21 -> 33.47 | Y21: =IF(L21<0,L21*-1,0) -> 0 | Z21: =X21+Y21 -> 33.47 | AA21: 0 | AB21: 48 | AC21: 17 | AD21: =AD20+1 -> 12
A22: =A21+1 -> 13 | B22: 6888.59 | C22: 243435 | D22: =C22-C21 -> 33 | E22: =C22-152000 -> 91435 | F22: =D22/$D$2 -> 16.637257 | G22: 50.6 | H22: 0 | I22: =G22+H22 -> 50.6 | J22: =IF(L22>0,L22,0) -> 0 | K22: =I22+J22 -> 50.6 | L22: =F22-(I22-X22) -> -0.042742627 | M22: 3.39 | N22: 0 | O22: 0 | P22: =M22-(N22+O22) -> 3.39 | Q22: 0 | R22: 0 | S22: =SUM(P22:R22) -> 3.39 | U22: 0 | V22: 30.53 | W22: =W21-V22 -> 11820.59 | X22: =N22+O22+S22+U22+V22 -> 33.92 | Y22: =IF(L22<0,L22*-1,0) -> 0.042742627 | Z22: =X22+Y22 -> 33.962743 | AA22: 0 | AB22: 48 | AC22: 20 | AD22: =AD21+1 -> 13
... A36: =A35+1 -> 27 | B36: 6888.89 | C36: 244435 | D36: =C36-C35 -> 134 | E36: =C36-152000 -> 92435 | F36: =D36/$D$2 -> 67.557348 | G36: 103.2 | H36: 0 | I36: =G36+H36 -> 103.2 | J36: =IF(L36>0,L36,0) -> 0 | K36: =I36+J36 -> 103.2 | L36: =F36-(I36-X36) -> -0.042651878 | M36: 4.4 | N36: 0 | O36: 0 | P36: =M36-(N36+O36) -> 4.4 | Q36: 0 | R36: 0 | S36: =SUM(P36:R36) -> 4.4 | U36: 0 | V36: 31.2 | W36: =W35-V36 -> 11379.98 | X36: =N36+O36+S36+U36+V36 -> 35.6 | Y36: =IF(L36<0,L36*-1,0) -> 0.042651878 | Z36: =X36+Y36 -> 35.642652 | AA36: 0.17 | AB36: 36 | AC36: 16 | AD36: =AD35+1 -> 27
A37: 28 | B37: 6888.94 | C37: 244601 | D37: =C37-C36 -> 166 | E37: =C37-152000 -> 92601 | F37: =D37/$D$2 -> 83.690446 | G37: 122 | H37: 0 | I37: =G37+H37 -> 122 | J37: =IF(L37>0,L37,0) -> 0 | K37: =I37+J37 -> 122 | L37: =F37-(I37-X37) -> -0.009553819 | M37: 6.64 | N37: 0 | O37: 0 | P37: =M37-(N37+O37) -> 6.64 | Q37: 0 | R37: 0 | S37: =SUM(P37:R37) -> 6.64 | U37: 0 | V37: 31.66 | W37: =W36-V37 -> 11348.32 | X37: =N37+O37+S37+U37+V37 -> 38.3 | Y37: =IF(L37<0,L37*-1,0) -> 0.009553819 | Z37: =X37+Y37 -> 38.309554 | AA37: 0.5 | AB37: 48 | AC37: 18 | AD37: 28
H38: 0
A39: MONTH / CFS | F39: =SUM(F10:F37) -> 772.37207 | G39: =SUM(G10:G37) -> 1920.72 | H39: =SUM(H10:H38) -> 0 | I39: =SUM(I10:I37) -> 1920.72 | J39: =SUM(J10:J37) -> 5.1038165 | K39: =SUM(K10:K37) -> 1925.8238 | L39: =SUM(L10:L37) -> -106.33793 | M39: =SUM(M10:M38) -> 113.53 | N39: =SUM(N10:N37) -> 0 | O39: =SUM(O10:O37) -> 0 | P39: =SUM(P10:P37) -> 113.53 | Q39: =SUM(Q10:Q37) -> 0 | R39: =SUM(R10:R37) -> 0 | S39: =SUM(S10:S37) -> 113.53 | U39: =SUM(U10:U37) -> 0 | V39: =SUM(V10:V37) -> 928.48 | X39: =SUM(X10:X37) -> 1042.01 | Y39: =SUM(Y10:Y37) -> 111.44175 | Z39: =SUM(Z10:Z37) -> 1153.4517 | AA39: =SUM(AA10:AA37) -> 0.77 | AB39: =AVERAGE(AB10:AB37) -> 45.464286 | AC39: =AVERAGE(AC10:AC37) -> 13.928571 | AD39: AVE
A40: MONTH / AF | D40: =SUM(D10:D37) -> 1532 | F40: =F39*$D$2 -> 1532 | G40: =G39*$D$2 -> 3809.7481 | H40: =H39*$D$2 -> 0 | I40: =I39*$D$2 -> 3809.7481 | J40: =J39*$D$2 -> 10.12342 | K40: =K39*$D$2 -> 3819.8715 | L40: =L39*$D$2 -> -210.92129 | M40: =M39*$D$2 -> 225.18676 | ... S40: =S39*$D$2 -> 225.18676 | U40: =U39*$D$2 -> 0 | V40: =V39*$D$2 -> 1841.6401 | X40: =X39*$D$2 -> 2066.8268 | Y40: =Y39*$D$2 -> 221.0447 | Z40: =Z39*$D$2 -> 2287.8715 | AB40: =MAX(AB10:AB37) -> 53 | AC40: =MAX(AC10:AC37) -> 20 | AD40: HI
A42: SEASON / CFS | AB42: =MIN(AB10:AB37) -> 31 | AC42: =MIN(AC10:AC37) -> 3 | AD42: LO
A43: SEASON / AF
A45: YTD / CFS | F45: =F8+F39 -> 2891.8578 | G45: =G8+G39 -> 8475.32 | H45: =H8+H39 -> 0 | I45: =I8+I39 -> 8372.12 | J45: =J8+J39 -> 294.99804 | K45: =K8+K39 -> 8667.118 | L45: =L8+L39 -> -171.75217 | M45: =M8+M39 -> 1105.43 | ... S45: =S8+S39 -> 1477.83 | U45: =U8+U39 -> 0 | V45: =V8+V39 -> 3830.68 | W45: =W37 -> 11348.32 | X45: =X8+X39 -> 5308.51 | Y45: =Y8+Y39 -> 466.75022 | Z45: =Z8+Z39 -> 5775.2602 | AA45: =AA8+AA39 -> 4.02
A46: YTD / AF | D46: =D8+D40 -> 5736 | E46: =E37 -> 92601 | F46: =F45*$D$2 -> 5736 | G46: =G45*$D$2 -> 16810.797 | H46: =H45*$D$2 -> 0 | I46: =I45*$D$2 -> 16606.1 | J46: =J45*$D$2 -> 585.12862 | K46: =K45*$D$2 -> 17191.229 | L46: =L45*$D$2 -> -340.67043 | M46: =M45*$D$2 -> 2192.6204 | ... Z46: =Z45*$D$2 -> 11455.229

Sheet MAR
K1: MC PHEE RESERVOIR IN/OUT FLOW TABULATION
A2: AF/cfs CONVERT FACTOR | D2: 1.9835 | K2: MARCH "1991"
A4: DATE | B4: RESERV | C4: RESERV | D4: AC FT | E4: ACTIVE | F4: CONV TO | G4: DOLORES | H4: LOST | I4: RECORDED | J4: CALC | K4: TOTAL | L4: CALC | M4: TUNNEL | Q4: LONE | R4: U | S4: TOTAL | T4: MVI | U4: DV CR | V4: BELOW | W4: REMAIN | X4: RECORDED | Y4: CALC | Z4: TOTAL | AA4: RAIN | AB4: MAX | AC4: MIN | AD4: DATE
A5: MAR | B5: ELEV | C5: AC FT | D5: CHANGE | E5: CAP | F5: CFS | G5: RIVER | H5: CANYON | I5: INFLOW | J5: INFLOW | K5: INFLOW | L5: INF/OTF | M5: TOT DIV | N5: WETLAND | O5: UTE F&R | P5: MVI,CTZ | Q5: PINE | R5: LAT | S5: MVI | T5: CALL | U5: CANAL | V5: MC PHEE | W5: RELEASE | X5: OUTFLOW | Y5: OUTFLOW | Z5: OUTFLOW | AB5: TMP | AC5: TMP | AD5: MAR
A7: SEASON BAL
A8: YTD | B8: =FEB!B37 -> 6888.94 | C8: =FEB!C37 -> 244601 | D8: =FEB!$D$46 -> 5736 | E8: =FEB!$E$37 -> 92601 | F8: =FEB!F45 -> 2891.8578 | G8: =FEB!G45 -> 8475.32 | H8: =FEB!H45 -> 0 | I8: =FEB!I45 -> 8372.12 | J8: =FEB!J45 -> 294.99804 | K8: =FEB!K45 -> 8667.118 | L8: =FEB!L45 -> -171.75217 | M8: =FEB!M45 -> 1105.43 | ... AA8: =FEB!AA45 -> 4.02
A10: 1 | B10: 6889 | C10: 244801 | D10: =C10-C8 -> 200 | E10: =C10-152000 -> 92801 | F10: =D10/$D$2 -> 100.83186 | G10: 136.75 | H10: 0 | I10: =G10+H10 -> 136.75 | J10: =IF(L10>0,L10,0) -> 0 | K10: =I10+J10 -> 136.75 | L10: =F10-(I10-X10) -> -0.048137131 | M10: 4.4 | N10: 0 | O10: 0 | P10: =M10-(N10+O10) -> 4.4 | Q10: 0 | R10: 0 | S10: =SUM(P10:R10) -> 4.4 | U10: 0 | V10: 31.47 | W10: =W8-V10 -> 11316.85 | X10: =N10+O10+S10+U10+V10 -> 35.87 | Y10: =IF(L10<0,L10*-1,0) -> 0.048137131 | Z10: =X10+Y10 -> 35.918137 | AA10: 0.21 | AB10: 34 | AC10: 28 | AD10: 1
A11: =A10+1 -> 2 | B11: 6889.06 | C11: 245003 | D11: =C11-C10 -> 202 | E11: =C11-152000 -> 93003 | F11: =D11/$D$2 -> 101.84018 | G11: 137.29 | H11: 0 | I11: =G11+H11 -> 137.29 | J11: =IF(L11>0,L11,0) -> 0 | K11: =I11+J11 -> 137.29 | L11: =F11-(I11-X11) -> -0.029818503 | M11: 4.4 | N11: 0 | O11: 0 | P11: =M11-(N11+O11) -> 4.4 | Q11: 0 | R11: 0 | S11: =SUM(P11:R11) -> 4.4 | U11: 0 | V11: 31.02 | W11: =W10-V11 -> 11285.83 | X11: =N11+O11+S11+U11+V11 -> 35.42 | Y11: =IF(L11<0,L11*-1,0) -> 0.029818503 | Z11: =X11+Y11 -> 35.449819 | AA11: 0.18 | AB11: 39 | AC11: 18 | AD11: =AD10+1 -> 2
A12: =A11+1 -> 3 | B12: 6889.12 | C12: 245205 | D12: =C12-C11 -> 202 | E12: =C12-152000 -> 93205 | F12: =D12/$D$2 -> 101.84018 | G12: 137.41 | H12: 0 | I12: =G12+H12 -> 137.41 | J12: =IF(L12>0,L12,0) -> 0 | K12: =I12+J12 -> 137.41 | L12: =F12-(I12-X12) -> -0.029818503 | M12: 4.4 | N12: 0 | O12: 0 | P12: =M12-(N12+O12) -> 4.4 | Q12: 0 | R12: 0 | S12: =SUM(P12:R12) -> 4.4 | U12: 0 | V12: 31.14 | W12: =W11-V12 -> 11254.69 | X12: =N12+O12+S12+U12+V12 -> 35.54 | Y12: =IF(L12<0,L12*-1,0) -> 0.029818503 | Z12: =X12+Y12 -> 35.569819 | AA12: 0 | AB12: 48 | AC12: 21 | AD12: =AD11+1 -> 3
A13: =A12+1 -> 4 | B13: 6889.17 | C13: 245374 | D13: =C13-C12 -> 169 | E13: =C13-152000 -> 93374 | F13: =D13/$D$2 -> 85.202924 | G13: 120.48 | H13: 0 | I13: =G13+H13 -> 120.48 | J13: =IF(L13>0,L13,0) -> 0 | K13: =I13+J13 -> 120.48 | L13: =F13-(I13-X13) -> -0.017075876 | M13: 4.42 | N13: 0 | O13: 0 | P13: =M13-(N13+O13) -> 4.42 | Q13: 0 | R13: 0 | S13: =SUM(P13:R13) -> 4.42 | U13: 0 | V13: 30.84 | W13: =W12-V13 -> 11223.85 | X13: =N13+O13+S13+U13+V13 -> 35.26 | Y13: =IF(L13<0,L13*-1,0) -> 0.017075876 | Z13: =X13+Y13 -> 35.277076 | AA13: 0.03 | AB13: 52 | AC13: 25 | AD13: =AD12+1 -> 4
A14: =A13+1 -> 5 | B14: 6889.51 | C14: 245508 | D14: =C14-C13 -> 134 | E14: =C14-152000 -> 93508 | F14: =D14/$D$2 -> 67.557348 | G14: 102.54 | H14: 0 | I14: =G14+H14 -> 102.54 | J14: =IF(L14>0,L14,0) -> 0.22734812 | K14: =I14+J14 -> 102.76735 | L14: =F14-(I14-X14) -> 0.22734812 | M14: 4.71 | N14: 0 | O14: 0 | P14: =M14-(N14+O14) -> 4.71 | Q14: 0 | R14: 0 | S14: =SUM(P14:R14) -> 4.71 | U14: 0 | V14: 30.5 | W14: =W13-V14 -> 11193.35 | X14: =N14+O14+S14+U14+V14 -> 35.21 | Y14: =IF(L14<0,L14*-1,0) -> 0 | Z14: =X14+Y14 -> 35.21 | AA14: 0.05 | AB14: 48 | AC14: 36 | AD14: =AD13+1 -> 5
A15: =A14+1 -> 6 | B15: 6889.25 | C15: 245643 | D15: =C15-C14 -> 135 | E15: =C15-152000 -> 93643 | F15: =D15/$D$2 -> 68.061507 | G15: 103.15 | H15: 0 | I15: =G15+H15 -> 103.15 | J15: =IF(L15>0,L15,0) -> 0 | K15: =I15+J15 -> 103.15 | L15: =F15-(I15-X15) -> -0.018492564 | M15: 4.57 | N15: 0 | O15: 0 | P15: =M15-(N15+O15) -> 4.57 | Q15: 0 | R15: 0 | S15: =SUM(P15:R15) -> 4.57 | U15: 0 | V15: 30.5 | W15: =W14-V15 -> 11162.85 | X15: =N15+O15+S15+U15+V15 -> 35.07 | Y15: =IF(L15<0,L15*-1,0) -> 0.018492564 | Z15: =X15+Y15 -> 35.088493 | AA15: 0 | AB15: 36 | AC15: 22 | AD15: =AD14+1 -> 6
A16: =A15+1 -> 7 | B16: 6889.27 | C16: 245710 | D16: =C16-C15 -> 67 | E16: =C16-152000 -> 93710 | F16: =D16/$D$2 -> 33.778674 | G16: 68.66 | H16: 0 | I16: =G16+H16 -> 68.66 | J16: =IF(L16>0,L16,0) -> 0 | K16: =I16+J16 -> 68.66 | L16: =F16-(I16-X16) -> -0.011325939 | M16: 4.4 | N16: 0 | O16: 0 | P16: =M16-(N16+O16) -> 4.4 | Q16: 0 | R16: 0 | S16: =SUM(P16:R16) -> 4.4 | U16: 0 | V16: 30.47 | W16: =W15-V16 -> 11132.38 | X16: =N16+O16+S16+U16+V16 -> 34.87 | Y16: =IF(L16<0,L16*-1,0) -> 0.011325939 | Z16: =X16+Y16 -> 34.881326 | AA16: 0 | AB16: 38 | AC16: 17 | AD16: =AD15+1 -> 7
A17: =A16+1 -> 8 | B17: 6889.28 | C17: 245744 | D17: =C17-C16 -> 34 | E17: =C17-152000 -> 93744 | F17: =D17/$D$2 -> 17.141417 | G17: 52.05 | H17: 0 | I17: =G17+H17 -> 52.05 | J17: =IF(L17>0,L17,0) -> 0 | K17: =I17+J17 -> 52.05 | L17: =F17-(I17-X17) -> -0.0085833123 | M17: 4.4 | N17: 0 | O17: 0 | P17: =M17-(N17+O17) -> 4.4 | Q17: 0 | R17: 0 | S17: =SUM(P17:R17) -> 4.4 | U17: 0 | V17: 30.5 | W17: =W16-V17 -> 11101.88 | X17: =N17+O17+S17+U17+V17 -> 34.9 | Y17: =IF(L17<0,L17*-1,0) -> 0.0085833123 | Z17: =X17+Y17 -> 34.908583 | AA17: 0 | AB17: 44 | AC17: 11 | AD17: =AD16+1 -> 8
