Workbook

Sheet NOV
K1: MCPHEE RESERVOIR INFLOW/OUTFLOW TABULATION
A2: AF/cfs CONVERT FACTOR | D2: 1.9835 | L2: NOVEMBER "2010"
D4: RESERVOIR | I4: INFLOW | X4: OUTFLOW | AP4: ADJUSTMENTS | AW4: WEATHER
A5: DATE | B5: RESERV | C5: RESERV | D5: AC FT | E5: ACTIVE | F5: CONV TO | G5: DOLORES | H5: LOST | I5: RECORD | J5: CALC | K5: TOTAL | L5: CALC | M5: DOLORES TUNNEL | V5: LONE | W5: U | X5: TOTAL | Y5: TOTAL | Z5: MVI | AA5: MVI | AB5: MVI | AC5: TO EX & | AD5: MVI | AE5: DV CR | AF5: D/S SENIOR | AH5: BELOW | AI5: FISH | AJ5: SPILL | AK5: RECORD | AL5: CALC | AM5: TOTAL | AN5: NAR | AO5: MVI | AP5: MVI | AQ5: MVI | AR5: DIST. | AS5: U/S | AT5: TOTTEN | AU5: UTES | AV5: RAIN | AW5: MAX | AX5: MIN | AZ5: TOTAL
A6: NOV | B6: ELEV | D6: CHANGE | E6: CAP | F6: CFS | G6: RIVER | H6: CAN | I6: INFLOW | J6: INFLOW | K6: INFLOW | L6: INF/OTF | M6: TOT DIV | N6: WET | O6: UTE | P6: QUEST | Q6: MWC | R6: CORTEZ | T6: UTE | U6: F-BAY | V6: PINE | W6: LAT | X6: MVI | Y6: MVI | Z6: CALL | AA6: CALL | AB6: APR- | AC6: U/S EX | AD6: PROJ | AE6: CANAL | AF6: MVIC | AG6: PROJ | AH6: MCP | AI6: LEFT | AK6: OTF | AL6: OTF | AM6: OTF | AN6: FILL | AO6: STOCK | AP6: STORED | AQ6: STORED | AR6: CLASS | AS6: USERS | AT6: (FRESH | AU6: FROM | AW6: TMP | AX6: TMP | AZ6: TUNNEL
N7: LAND | O7: F&R | Q7: NON - | R7: NON - | S7: PROJ | T7: PROJ | U7: BAL | X7: WATER | Y7: IRRIG. | Z7: STOR | AA7: SPILLED | AB7: JUNE | AF7: 1.7 | AG7: 1.3 | AI7: 31798 | AP7: Apr - Jun | AQ7: EVAP | AR7: "B" | AS7: EXCH | AT7: WATER) | AU7: DWCD | AZ7: Misc.
Q8: PROJ | R8: PROJ | X8: USED | Y8: WATER | AA8: OR | AB8: (DIV+
R9: 4.2 | Y9: USED | AA9: USED | AB9: CALL)
C10: AC. Ft. | E10: AC FT | G10: CFS | H10: CFS | I10: CFS | J10: CFS | K10: CFS | L10: CFS | M10: CFS | N10: CFS | O10: CFS | P10: CFS | Q10: CFS | R10: CFS | S10: CFS | T10: CFS | U10: CFS | V10: CFS | W10: CFS | X10: 153400 | Y10: 150400 | AB10: 72000 | AC10: CFS | AD10: CFS | AE10: CFS | AF10: CFS | AG10: CFS | AH10: CFS | AI10: CFS | AJ10: CFS | AK10: CFS | AL10: CFS | AM10: CFS | AN10: CFS | AO10: CFS | AP10: CFS | AQ10: AC.FT. | AR10: CFS | AS10: CFS | AT10: CFS | AU10: CFS | AZ10: Outflow
N11: 1.03 | O11: 1.05 | P11: 1.02 | Q11: 1.02 | R11: 1.04 | T11: 1.04 | X11: CFS | Y11: CFS | Z11: CFS | AA11: CFS | AB11: Ac. Ft. | AZ11: CFS
A12: SEASON BAL
A13: YTD | B13: 6898.31 | C13: 277391 | AI13: 5264 | AO13: 0
A15: 1 | B15: 6898.32 | C15: 277427 | D15: =C15-C13 -> 36 | E15: =C15-152000 -> 125427 | F15: =D15/$D$2 -> 18.149735 | G15: 85 | H15: 0.62 | I15: =G15+H15 -> 85.62 | J15: =IF(L15>0,L15,0) -> 0 | K15: =I15+J15 -> 85.62 | L15: =F15-(I15-AK15) -> -26.370265 | M15: 6.1 | N15: 0 | O15: 0 | P15: 0 | Q15: =1107300/325851/1.9835*1.02 -> 1.747488 | R15: =(1396020/325851/1.9835-T15)*1.04 -> 1.4878047 | S15: 0 | T15: =0.7013*1.04 -> 0.729352 | U15: =M15-(Q15+R15+S15+T15) -> 2.1353552 | V15: 0 | W15: 0 | X15: =M15-N15-P15-O15-Q15-R15-S15-T15-U15+V15+W15 -> 0 | Y15: =X15-AO15 -> 0 | AC15: 82.4 | AE15: 0 | AH15: 35 | AI15: =AI13-AH15 -> 5229 | AK15: =N15+O15+P15+Q15+R15+S15+T15+U15+X15+AE15+AH15 -> 41.1 | AL15: =IF(L15<0,L15*-1,0) -> 26.370265 | AM15: =AK15+AL15 -> 67.470265 | AV15: 0 | AW15: 56 | AX15: 32 | AZ15: =SUM(N15,P15:U15) -> 6.1
A16: =A15+1 -> 2 | B16: 6898.33 | C16: 277464 | D16: =C16-C15 -> 37 | E16: =C16-152000 -> 125464 | F16: =D16/$D$2 -> 18.653895 | G16: 79 | H16: 0.53 | I16: =G16+H16 -> 79.53 | J16: =IF(L16>0,L16,0) -> 0 | K16: =I16+J16 -> 79.53 | L16: =F16-(I16-AK16) -> -27.076105 | M16: 4.8 | N16: 0 | O16: 0 | P16: 0 | Q16: =1055000/325851/1.9835*1.02 -> 1.6649507 | R16: =(1442953/325851/1.9835-T16)*1.04 -> 1.5633245 | S16: 0 | T16: =0.7013*1.04 -> 0.729352 | U16: =M16-(Q16+R16+S16+T16) -> 0.84237287 | V16: 0 | W16: 0 | X16: =M16-N16-P16-O16-Q16-R16-S16-T16-U16+V16+W16 -> 0 | Y16: =X16-AO16 -> 0 | AC16: 76.3 | AE16: 0 | AH16: 29 | AI16: =AI15-AH16 -> 5200 | AK16: =N16+O16+P16+Q16+R16+S16+T16+U16+X16+AE16+AH16 -> 33.8 | AL16: =IF(L16<0,L16*-1,0) -> 27.076105 | AM16: =AK16+AL16 -> 60.876105 | AU16: =(4.2)*1.05 -> 4.41 | AV16: 0 | AW16: 66 | AX16: 33 | AZ16: =SUM(N16,P16:U16) -> 4.8
A17: =A16+1 -> 3 | B17: 6898.35 | C17: 277537 | D17: =C17-C16 -> 73 | E17: =C17-152000 -> 125537 | F17: =D17/$D$2 -> 36.80363 | G17: 76 | H17: 0.62 | I17: =G17+H17 -> 76.62 | J17: =IF(L17>0,L17,0) -> 0 | K17: =I17+J17 -> 76.62 | L17: =F17-(I17-AK17) -> -5.8163701 | M17: 5 | N17: 0 | O17: 0 | P17: 0 | Q17: =1042200/325851/1.9835*1.02 -> 1.6447503 | R17: =(1417984/325851/1.9835-T17)*1.04 -> 1.5231469 | S17: 0 | T17: =0.7013*1.04 -> 0.729352 | U17: =M17-(Q17+R17+S17+T17) -> 1.1027507 | V17: 0 | W17: 0 | X17: =M17-N17-P17-O17-Q17-R17-S17-T17-U17+V17+W17 -> 0 | Y17: =X17-AO17 -> 0 | AC17: 73.4 | AE17: 0 | AH17: 29 | AI17: =AI16-AH17 -> 5171 | AK17: =N17+O17+P17+Q17+R17+S17+T17+U17+X17+AE17+AH17 -> 34 | AL17: =IF(L17<0,L17*-1,0) -> 5.8163701 | AM17: =AK17+AL17 -> 39.81637 | AU17: =9.7*1.05 -> 10.185 | AV17: 0 | AW17: 67 | AX17: 40 | AZ17: =SUM(N17,P17:U17) -> 5
A18: =A17+1 -> 4 | B18: 6898.37 | C18: 277610 | D18: =C18-C17 -> 73 | E18: =C18-152000 -> 125610 | F18: =D18/$D$2 -> 36.80363 | G18: 82 | H18: 1 | I18: =G18+H18 -> 83 | J18: =IF(L18>0,L18,0) -> 0 | K18: =I18+J18 -> 83 | L18: =F18-(I18-AK18) -> -10.29637 | M18: 3.9 | N18: 0 | O18: 0 | P18: 0 | Q18: =1210500/325851/1.9835*1.02 -> 1.9103533 | R18: =(1401636/325851/1.9835-T18)*1.04 -> 1.4968414 | S18: 0 | T18: =0.7013*1.04 -> 0.729352 | U18: =M18-(Q18+R18+S18+T18) -> -0.23654677 | V18: 0 | W18: 0 | X18: =M18-N18-P18-O18-Q18-R18-S18-T18-U18+V18+W18 -> 0 | Y18: =X18-AO18 -> 0 | AC18: 79.6 | AE18: 0 | AH18: 32 | AI18: =AI17-AH18 -> 5139 | AK18: =N18+O18+P18+Q18+R18+S18+T18+U18+X18+AE18+AH18 -> 35.9 | AL18: =IF(L18<0,L18*-1,0) -> 10.29637 | AM18: =AK18+AL18 -> 46.19637 | AU18: =9.8*1.05 -> 10.29 | AV18: 0 | AW18: 63 | AX18: 36 | AZ18: =SUM(N18,P18:U18) -> 3.9
A19: =A18+1 -> 5 | B19: 6898.4 | C19: 277719 | D19: =C19-C18 -> 109 | E19: =C19-152000 -> 125719 | F19: =D19/$D$2 -> 54.953365 | G19: 83 | H19: 1.4 | I19: =G19+H19 -> 84.4 | J19: =IF(L19>0,L19,0) -> 8.5533653 | K19: =I19+J19 -> 92.953365 | L19: =F19-(I19-AK19) -> 8.5533653 | M19: 4 | N19: 0 | O19: 0 | P19: 0 | Q19: =995700/325851/1.9835*1.02 -> 1.5713662 | R19: =(1482628/325851/1.9835-T19)*1.04 -> 1.6232716 | S19: 0 | T19: =0.7049*1.04 -> 0.733096 | U19: =M19-(Q19+R19+S19+T19) -> 0.072266159 | V19: 0 | W19: 0 | X19: =M19-N19-P19-O19-Q19-R19-S19-T19-U19+V19+W19 -> -6.6613381e-16 | Y19: =X19-AO19 -> -6.6613381e-16 | AC19: 81.2 | AE19: 0 | AH19: 34 | AI19: =AI18-AH19 -> 5105 | AK19: =N19+O19+P19+Q19+R19+S19+T19+U19+X19+AE19+AH19 -> 38 | AL19: =IF(L19<0,L19*-1,0) -> 0 | AM19: =AK19+AL19 -> 38 | AU19: =4.2*1.05 -> 4.41 | AV19: 0 | AW19: 61 | AX19: 36 | AZ19: =SUM(N19,P19:U19) -> 4
A20: =A19+1 -> 6 | B20: 6898.42 | C20: 277792 | D20: =C20-C19 -> 73 | E20: =C20-152000 -> 125792 | F20: =D20/$D$2 -> 36.80363 | G20: 82 | H20: 1.6 | I20: =G20+H20 -> 83.6 | J20: =IF(L20>0,L20,0) -> 0 | K20: =I20+J20 -> 83.6 | L20: =F20-(I20-AK20) -> -8.6963701 | M20: 4.1 | N20: 0 | O20: 0 | P20: 0 | Q20: =1124800/325851/1.9835*1.02 -> 1.7751057 | R20: =(1595253/325851/1.9835-T20)*1.04 -> 1.8044961 | S20: 0 | T20: =0.7049*1.04 -> 0.733096 | U20: =M20-(Q20+R20+S20+T20) -> -0.21269779 | V20: 0 | W20: 0 | X20: =M20-N20-P20-O20-Q20-R20-S20-T20-U20+V20+W20 -> 0 | Y20: =X20-AO20 -> 0 | AC20: 80 | AE20: 0 | AH20: 34 | AI20: =AI19-AH20 -> 5071 | AK20: =N20+O20+P20+Q20+R20+S20+T20+U20+X20+AE20+AH20 -> 38.1 | AL20: =IF(L20<0,L20*-1,0) -> 8.6963701 | AM20: =AK20+AL20 -> 46.79637 | AU20: =2.2*1.05 -> 2.31 | AV20: 0 | AW20: 67 | AX20: 37 | AZ20: =SUM(N20,P20:U20) -> 4.1
A21: =A20+1 -> 7 | B21: 6898.44 | C21: 277865 | D21: =C21-C20 -> 73 | E21: =C21-152000 -> 125865 | F21: =D21/$D$2 -> 36.80363 | G21: 82 | H21: 1.8 | I21: =G21+H21 -> 83.8 | J21: =IF(L21>0,L21,0) -> 0 | K21: =I21+J21 -> 83.8 | L21: =F21-(I21-AK21) -> -9.5963701 | M21: 3.4 | N21: 0 | O21: 0 | P21: 0 | Q21: =1195100/325851/1.9835*1.02 -> 1.8860498 | R21: =(1473905/325851/1.9835-T21)*1.04 -> 1.6092355 | S21: 0 | T21: =0.7049*1.04 -> 0.733096 | U21: =M21-(Q21+R21+S21+T21) -> -0.82838126 | V21: 0 | W21: 0 | X21: =M21-N21-P21-O21-Q21-R21-S21-T21-U21+V21+W21 -> 0 | Y21: =X21-AO21 -> 0 | AC21: 80.3 | AE21: 0 | AH21: 34 | AI21: =AI20-AH21 -> 5037 | AK21: =N21+O21+P21+Q21+R21+S21+T21+U21+X21+AE21+AH21 -> 37.4 | AL21: =IF(L21<0,L21*-1,0) -> 9.5963701 | AM21: =AK21+AL21 -> 46.99637 | AV21: 0 | AW21: 58 | AX21: 38 | AZ21: =SUM(N21,P21:U21) -> 3.4
A22: =A21+1 -> 8 | B22: 6898.46 | C22: 277938 | D22: =C22-C21 -> 73 | E22: =C22-152000 -> 125938 | F22: =D22/$D$2 -> 36.80363 | G22: 81 | H22: 2.1 | I22: =G22+H22 -> 83.1 | J22: =IF(L22>0,L22,0) -> 25.40363 | K22: =I22+J22 -> 108.50363 | L22: =F22-(I22-AK22) -> 25.40363 | M22: 3.7 | N22: 0 | O22: 0 | P22: 0 | Q22: =1135100/325851/1.9835*1.02 -> 1.7913607 | R22: =(1517727/325851/1.9835-T22)*1.04 -> 1.6797493 | S22: 0 | T22: =0.7049*1.04 -> 0.733096 | U22: =M22-(Q22+R22+S22+T22) -> -0.50420595 | V22: 34 | W22: 0 | X22: =M22-N22-P22-O22-Q22-R22-S22-T22-U22+V22+W22 -> 34 | Y22: =X22-AO22 -> 34 | AC22: 45.2 | AE22: 0 | AH22: 34 | AI22: =AI21-AH22 -> 5003 | AK22: =N22+O22+P22+Q22+R22+S22+T22+U22+X22+AE22+AH22 -> 71.7 | AL22: =IF(L22<0,L22*-1,0) -> 0 | AM22: =AK22+AL22 -> 71.7 | AN22: =V22 -> 34 | AV22: 0 | AW22: 56 | AX22: 32 | AZ22: =SUM(N22,P22:U22) -> 3.7
A23: =A22+1 -> 9 | B23: 6898.45 | C23: 277901 | D23: =C23-C22 -> -37 | E23: =C23-152000 -> 125901 | F23: =D23/$D$2 -> -18.653895 | G23: 85 | H23: 2.3 | I23: =G23+H23 -> 87.3 | J23: =IF(L23>0,L23,0) -> 0 | K23: =I23+J23 -> 87.3 | L23: =F23-(I23-AK23) -> -17.153895 | M23: 3.8 | N23: 0 | O23: 0 | P23: 0 | Q23: =968000/325851/1.9835*1.02 -> 1.5276514 | R23: =(1437436/325851/1.9835-T23)*1.04 -> 1.5505533 | S23: 0 | T23: =0.7049*1.04 -> 0.733096 | U23: =M23-(Q23+R23+S23+T23) -> -0.011300736 | V23: 51 | W23: 0 | X23: =M23-N23-P23-O23-Q23-R23-S23-T23-U23+V23+W23 -> 51 | Y23: =X23-AO23 -> 51 | AC23: 33.2 | AE23: 0 | AH23: 34 | AI23: =AI22-AH23 -> 4969 | AK23: =N23+O23+P23+Q23+R23+S23+T23+U23+X23+AE23+AH23 -> 88.8 | AL23: =IF(L23<0,L23*-1,0) -> 17.153895 | AM23: =AK23+AL23 -> 105.95389 | AN23: =V23 -> 51 | AV23: 0.05 | AW23: 39 | AX23: 23 | AZ23: =SUM(N23,P23:U23) -> 3.8
A24: =A23+1 -> 10 | B24: 6898.41 | C24: 277792 | D24: =C24-C23 -> -109 | E24: =C24-152000 -> 125792 | F24: =D24/$D$2 -> -54.953365 | G24: 70 | H24: 1.8 | I24: =G24+H24 -> 71.8 | J24: =IF(L24>0,L24,0) -> 0 | K24: =I24+J24 -> 71.8 | L24: =F24-(I24-AK24) -> -17.343365 | M24: 17 | N24: 0 | O24: 0 | P24: 0 | Q24: =1019900/325851/1.9835*1.02 -> 1.6095575 | R24: =(1440521/325851/1.9835-T24)*1.04 -> 1.5555174 | S24: 0 | T24: =0.7049*1.04 -> 0.733096 | U24: 0 | V24: 51 | W24: 7.41 | X24: =M24-N24-P24-O24-Q24-R24-S24-T24-U24+V24+W24 -> 71.511829 | Y24: =X24-AO24 -> 51 | AE24: 0 | AH24: 34 | AI24: =AI23-AH24 -> 4935 | AK24: =N24+O24+P24+Q24+R24+S24+T24+U24+X24+AE24+AH24 -> 109.41 | AL24: =IF(L24<0,L24*-1,0) -> 17.343365 | AM24: =AK24+AL24 -> 126.75337 | AN24: =V24 -> 51 | AO24: =X24-V24 -> 20.511829 | AV24: 0.03 | AW24: 43 | AX24: 20 | AZ24: =SUM(N24,P24:U24) -> 3.8981709
A25: =A24+1 -> 11 | B25: 6898.39 | C25: 277683 | D25: =C25-C24 -> -109 | E25: =C25-152000 -> 125683 | F25: =D25/$D$2 -> -54.953365 | G25: 71 | H25: 0.81 | I25: =G25+H25 -> 71.81 | J25: =IF(L25>0,L25,0) -> 0 | K25: =I25+J25 -> 71.81 | L25: =F25-(I25-AK25) -> -1.7633653 | M25: 26 | N25: 0 | O25: 0 | P25: 0 | Q25: =869300/325851/1.9835*1.02 -> 1.3718878 | R25: =(1451364/325851/1.9835-T25)*1.04 -> 1.5729648 | S25: 0 | T25: =0.7049*1.04 -> 0.733096 | U25: 0 | V25: 54 | W25: 11 | X25: =M25-N25-P25-O25-Q25-R25-S25-T25-U25+V25+W25 -> 87.322051 | Y25: =X25-AO25 -> 48.8 | AE25: 0 | AH25: 34 | AI25: =AI24-AH25 -> 4901 | AK25: =N25+O25+P25+Q25+R25+S25+T25+U25+X25+AE25+AH25 -> 125 | AL25: =IF(L25<0,L25*-1,0) -> 1.7633653 | AM25: =AK25+AL25 -> 126.76337 | AN25: =V25-5.2 -> 48.8 | AO25: =X25-V25+5.2 -> 38.522051 | AV25: 0.02 | AW25: 39 | AX25: 25 | AZ25: =SUM(N25,P25:U25) -> 3.6779486
A26: =A25+1 -> 12 | B26: 6898.35 | C26: 277537 | D26: =C26-C25 -> -146 | E26: =C26-152000 -> 125537 | F26: =D26/$D$2 -> -73.60726 | G26: 57 | H26: 1.7 | I26: =G26+H26 -> 58.7 | J26: =IF(L26>0,L26,0) -> 3.6927401 | K26: =I26+J26 -> 62.39274 | L26: =F26-(I26-AK26) -> 3.6927401 | M26: 29 | N26: 0 | O26: 0 | P26: 0 | Q26: =1123600/325851/1.9835*1.02 -> 1.7732119 | R26: =(1364072/325851/1.9835-T26)*1.04 -> 1.499022 | S26: 0 | T26: =0.6434*1.04 -> 0.669136 | U26: 0 | V26: 61 | W26: 12 | X26: =M26-N26-P26-O26-Q26-R26-S26-T26-U26+V26+W26 -> 98.05863 | Y26: =X26-AO26 -> 53.3 | AE26: 0 | AH26: 34 | AI26: =AI25-AH26 -> 4867 | AK26: =N26+O26+P26+Q26+R26+S26+T26+U26+X26+AE26+AH26 -> 136 | AL26: =IF(L26<0,L26*-1,0) -> 0 | AM26: =AK26+AL26 -> 136 | AN26: =V26-7.7 -> 53.3 | AO26: =X26-V26+7.7 -> 44.75863 | AV26: 0 | AW26: 43 | AX26: 17 | AZ26: =SUM(N26,P26:U26) -> 3.9413699
A27: =A26+1 -> 13 | B27: 6898.29 | C27: 277318 | D27: =C27-C26 -> -219 | E27: =C27-152000 -> 125318 | F27: =D27/$D$2 -> -110.41089 | G27: 53 | H27: 1.2 | I27: =G27+H27 -> 54.2 | J27: =IF(L27>0,L27,0) -> 0 | K27: =I27+J27 -> 54.2 | L27: =F27-(I27-AK27) -> -28.61089 | M27: 29 | N27: 0 | O27: 0 | P27: 0 | Q27: =947600/325851/1.9835*1.02 -> 1.4954571 | R27: =(1355237/325851/1.9835-T27)*1.04 -> 1.4848056 | S27: 0 | T27: =0.6434*1.04 -> 0.669136 | U27: 0 | V27: 61 | W27: 12 | X27: =M27-N27-P27-O27-Q27-R27-S27-T27-U27+V27+W27 -> 98.350601 | Y27: =X27-AO27 -> 56 | AE27: 0 | AH27: 34 | AI27: =AI26-AH27 -> 4833 | AK27: =N27+O27+P27+Q27+R27+S27+T27+U27+X27+AE27+AH27 -> 136 | AL27: =IF(L27<0,L27*-1,0) -> 28.61089 | AM27: =AK27+AL27 -> 164.61089 | AN27: =V27-5 -> 56 | AO27: =X27-V27+5 -> 42.350601 | AV27: 0 | AW27: 42 | AX27: 21 | AZ27: =SUM(N27,P27:U27) -> 3.6493987
A28: =A27+1 -> 14 | B28: 6898.25 | C28: 277172 | D28: =C28-C27 -> -146 | E28: =C28-152000 -> 125172 | F28: =D28/$D$2 -> -73.60726 | G28: 61 | H28: 1.3 | I28: =G28+H28 -> 62.3 | J28: =IF(L28>0,L28,0) -> 0.092740106 | K28: =I28+J28 -> 62.39274 | L28: =F28-(I28-AK28) -> 0.092740106 | M28: 29 | N28: 0 | O28: 0 | P28: 0 | Q28: =1166200/325851/1.9835*1.02 -> 1.8404412 | R28: =(1313865/325851/1.9835-T28)*1.04 -> 1.4182341 | S28: 0 | T28: =0.6434*1.04 -> 0.669136 | U28: 0 | V28: 61 | W28: 12 | X28: =M28-N28-P28-O28-Q28-R28-S28-T28-U28+V28+W28 -> 98.072189 | Y28: =X28-AO28 -> 56 | AE28: 0 | AH28: 34 | AI28: =AI27-AH28 -> 4799 | AK28: =N28+O28+P28+Q28+R28+S28+T28+U28+X28+AE28+AH28 -> 136 | AL28: =IF(L28<0,L28*-1,0) -> 0 | AM28: =AK28+AL28 -> 136 | AN28: =V28-5 -> 56 | AO28: =X28-V28+5 -> 42.072189 | AV28: 0 | AW28: 44 | AX28: 21 | AZ28: =SUM(N28,P28:U28) -> 3.9278113
A29: =A28+1 -> 15 | B29: 6898.22 | C29: 277063 | D29: =C29-C28 -> -109 | E29: =C29-152000 -> 125063 | F29: =D29/$D$2 -> -54.953365 | G29: 73 | H29: 1.8 | I29: =G29+H29 -> 74.8 | J29: =IF(L29>0,L29,0) -> 0 | K29: =I29+J29 -> 74.8 | L29: =F29-(I29-AK29) -> -18.883365 | M29: 12 | N29: 0 | O29: 0 | P29: 0 | Q29: =1102100/325851/1.9835*1.02 -> 1.7392816 | R29: =(1350792/325851/1.9835-T29)*1.04 -> 1.4776532 | S29: 0 | T29: =0.6434*1.04 -> 0.669136 | U29: 0 | V29: 61 | W29: 3.87 | X29: =M29-N29-P29-O29-Q29-R29-S29-T29-U29+V29+W29 -> 72.983929 | Y29: =X29-AO29 -> 59.4 | AE29: 0 | AH29: 34 | AI29: =AI28-AH29 -> 4765 | AK29: =N29+O29+P29+Q29+R29+S29+T29+U29+X29+AE29+AH29 -> 110.87 | AL29: =IF(L29<0,L29*-1,0) -> 18.883365 | AM29: =AK29+AL29 -> 129.75337 | AN29: =V29-1.6 -> 59.4 | AO29: =X29-V29+1.6 -> 13.583929 | AV29: 0.09 | AW29: 41 | AX29: 23 | AZ29: =SUM(N29,P29:U29) -> 3.8860708
A30: =A29+1 -> 16 | B30: 6898.18 | C30: 276917 | D30: =C30-C29 -> -146 | E30: =C30-152000 -> 124917 | F30: =D30/$D$2 -> -73.60726 | G30: 68 | H30: 1.8 | I30: =G30+H30 -> 69.8 | J30: =IF(L30>0,L30,0) -> 0 | K30: =I30+J30 -> 69.8 | L30: =F30-(I30-AK30) -> -45.10726 | M30: 3.3 | N30: 0 | O30: 0 | P30: 0 | Q30: =1252800/325851/1.9835*1.02 -> 1.9771092 | R30: =(1312127/325851/1.9835-T30)*1.04 -> 1.4154375 | S30: 0 | T30: =0.6434*1.04 -> 0.669136 | U30: =M30-(Q30+R30+S30+T30) -> -0.76168264 | V30: 61 | W30: 0 | X30: =M30-N30-P30-O30-Q30-R30-S30-T30-U30+V30+W30 -> 61 | Y30: =X30-AO30 -> 61 | AC30: 5.3 | AE30: 0 | AH30: 34 | AI30: =AI29-AH30 -> 4731 | AK30: =N30+O30+P30+Q30+R30+S30+T30+U30+X30+AE30+AH30 -> 98.3 | AL30: =IF(L30<0,L30*-1,0) -> 45.10726 | AM30: =AK30+AL30 -> 143.40726 | AN30: =V30 -> 61 | AV30: 0 | AW30: 48 | AX30: 23 | AZ30: =SUM(N30,P30:U30) -> 3.3
A31: =A30+1 -> 17 | B31: 6898.14 | C31: 276771 | D31: =C31-C30 -> -146 | E31: =C31-152000 -> 124771 | F31: =D31/$D$2 -> -73.60726 | G31: 70 | H31: 1.9 | I31: =G31+H31 -> 71.9 | J31: =IF(L31>0,L31,0) -> 0 | K31: =I31+J31 -> 71.9 | L31: =F31-(I31-AK31) -> -46.60726 | M31: 3.9 | N31: 0 | O31: 0 | P31: 0 | Q31: =929600/325851/1.9835*1.02 -> 1.4670504 | R31: =(1497490/325851/1.9835-T31)*1.04 -> 1.7137044 | S31: 0 | T31: =0.6434*1.04 -> 0.669136 | U31: =M31-(Q31+R31+S31+T31) -> 0.050109234 | V31: 61 | W31: 0 | X31: =M31-N31-P31-O31-Q31-R31-S31-T31-U31+V31+W31 -> 61 | Y31: =X31-AO31 -> 61 | AC31: 7.5 | AE31: 0 | AH31: 34 | AI31: =AI30-AH31 -> 4697 | AK31: =N31+O31+P31+Q31+R31+S31+T31+U31+X31+AE31+AH31 -> 98.9 | AL31: =IF(L31<0,L31*-1,0) -> 46.60726 | AM31: =AK31+AL31 -> 145.50726 | AN31: =V31 -> 61 | AV31: 0 | AW31: 46 | AX31: 21 | AZ31: =SUM(N31,P31:U31) -> 3.9
A32: =A31+1 -> 18 | B32: 6898.11 | C32: 276662 | D32: =C32-C31 -> -109 | E32: =C32-152000 -> 124662 | F32: =D32/$D$2 -> -54.953365 | G32: 60 | H32: 1.1 | I32: =G32+H32 -> 61.1 | J32: =IF(L32>0,L32,0) -> 0 | K32: =I32+J32 -> 61.1 | L32: =F32-(I32-AK32) -> -18.553365 | M32: 3.5 | N32: 0 | O32: 0 | P32: 0 | Q32: =990400/325851/1.9835*1.02 -> 1.563002 | R32: =(1472293/325851/1.9835-T32)*1.04 -> 1.67316 | S32: 0 | T32: =0.6434*1.04 -> 0.669136 | U32: =M32-(Q32+R32+S32+T32) -> -0.40529802 | V32: 61 | W32: 0 | X32: =M32-N32-P32-O32-Q32-R32-S32-T32-U32+V32+W32 -> 61 | Y32: =X32-AO32 -> 61 | AE32: 0 | AH32: 33 | AI32: =AI31-AH32 -> 4664 | AK32: =N32+O32+P32+Q32+R32+S32+T32+U32+X32+AE32+AH32 -> 97.5 | AL32: =IF(L32<0,L32*-1,0) -> 18.553365 | AM32: =AK32+AL32 -> 116.05337 | AN32: =V32 -> 61 | AV32: 0 | AW32: 54 | AX32: 24 | AZ32: =SUM(N32,P32:U32) -> 3.5
A33: =A32+1 -> 19 | B33: 6898.09 | C33: 276589 | D33: =C33-C32 -> -73 | E33: =C33-152000 -> 124589 | F33: =D33/$D$2 -> -36.80363 | G33: 60 | H33: 1.2 | I33: =G33+H33 -> 61.2 | J33: =IF(L33>0,L33,0) -> 0 | K33: =I33+J33 -> 61.2 | L33: =F33-(I33-AK33) -> -1.1036299 | M33: 2.9 | N33: 0 | O33: 0 | P33: 0 | Q33: =1132000/325851/1.9835*1.02 -> 1.7864684 | R33: =(1477438/325851/1.9835-T33)*1.04 -> 1.6656474 | S33: 0 | T33: =0.658*1.04 -> 0.68432 | U33: =M33-(Q33+R33+S33+T33) -> -1.2364358 | V33: 61 | W33: 0 | X33: =M33-N33-P33-O33-Q33-R33-S33-T33-U33+V33+W33 -> 61 | Y33: =X33-AO33 -> 61 | AE33: 0 | AH33: 33 | AI33: =AI32-AH33 -> 4631 | AK33: =N33+O33+P33+Q33+R33+S33+T33+U33+X33+AE33+AH33 -> 96.9 | AL33: =IF(L33<0,L33*-1,0) -> 1.1036299 | AM33: =AK33+AL33 -> 98.00363 | AN33: =V33 -> 61 | AV33: 0 | AW33: 54 | AX33: 30 | AZ33: =SUM(N33,P33:U33) -> 2.9
A34: =A33+1 -> 20 | B34: 6898.07 | C34: 276516 | D34: =C34-C33 -> -73 | E34: =C34-152000 -> 124516 | F34: =D34/$D$2 -> -36.80363 | G34: 70 | H34: 1.6 | I34: =G34+H34 -> 71.6 | J34: =IF(L34>0,L34,0) -> 0 | K34: =I34+J34 -> 71.6 | L34: =F34-(I34-AK34) -> -10.30363 | M34: 4.1 | N34: 0 | O34: 0 | P34: 0 | Q34: =1019700/325851/1.9835*1.02 -> 1.6092419 | R34: =(1490704/325851/1.9835-T34)*1.04 -> 1.6869937 | S34: 0 | T34: =0.658*1.04 -> 0.68432 | U34: =M34-(Q34+R34+S34+T34) -> 0.1194444 | V34: 61 | W34: 0 | X34: =M34-N34-P34-O34-Q34-R34-S34-T34-U34+V34+W34 -> 61 | Y34: =X34-AO34 -> 61 | AC34: 7.2 | AE34: 0 | AH34: 33 | AI34: =AI33-AH34 -> 4598 | AK34: =N34+O34+P34+Q34+R34+S34+T34+U34+X34+AE34+AH34 -> 98.1 | AL34: =IF(L34<0,L34*-1,0) -> 10.30363 | AM34: =AK34+AL34 -> 108.40363 | AN34: =V34 -> 61 | AV34: 0 | AW34: 51 | AX34: 37 | AZ34: =SUM(N34,P34:U34) -> 4.1
A35: =A34+1 -> 21 | B35: 6898.05 | C35: 276443 | D35: =C35-C34 -> -73 | E35: =C35-152000 -> 124443 | F35: =D35/$D$2 -> -36.80363 | G35: 71 | H35: 1.7 | I35: =G35+H35 -> 72.7 | J35: =IF(L35>0,L35,0) -> 0 | K35: =I35+J35 -> 72.7 | L35: =F35-(I35-AK35) -> -10.30363 | M35: 4.2 | N35: 0 | O35: 0 | P35: 0 | Q35: =1223400/325851/1.9835*1.02 -> 1.9307115 | R35: =(1422192/325851/1.9835-T35)*1.04 -> 1.5767513 | S35: 0 | T35: =0.658*1.04 -> 0.68432 | U35: =M35-(Q35+R35+S35+T35) -> 0.0082171964 | V35: 61 | W35: 0 | X35: =M35-N35-P35-O35-Q35-R35-S35-T35-U35+V35+W35 -> 61 | Y35: =X35-AO35 -> 61 | AC35: 8 | AE35: 0 | AH35: 34 | AI35: =AI34-AH35 -> 4564 | AK35: =N35+O35+P35+Q35+R35+S35+T35+U35+X35+AE35+AH35 -> 99.2 | AL35: =IF(L35<0,L35*-1,0) -> 10.30363 | AM35: =AK35+AL35 -> 109.50363 | AN35: =V35 -> 61 | AV35: 0.06 | AW35: 44 | AX35: 24 | AZ35: =SUM(N35,P35:U35) -> 4.2
A36: =A35+1 -> 22 | B36: 6898.03 | C36: 276370 | D36: =C36-C35 -> -73 | E36: =C36-152000 -> 124370 | F36: =D36/$D$2 -> -36.80363 | G36: 66 | H36: 1.2 | I36: =G36+H36 -> 67.2 | J36: =IF(L36>0,L36,0) -> 0 | K36: =I36+J36 -> 67.2 | L36: =F36-(I36-AK36) -> -6.2036299 | M36: 2.8 | N36: 0 | O36: 0 | P36: 0 | Q36: =1069800/325851/1.9835*1.02 -> 1.6883073 | R36: =(1344035/325851/1.9835-T36)*1.04 -> 1.4509891 | S36: 0 | T36: =0.658*1.04 -> 0.68432 | U36: =M36-(Q36+R36+S36+T36) -> -1.0236165 | V36: 61 | W36: 0 | X36: =M36-N36-P36-O36-Q36-R36-S36-T36-U36+V36+W36 -> 61 | Y36: =X36-AO36 -> 61 | AC36: 3 | AE36: 0 | AH36: 34 | AI36: =AI35-AH36 -> 4530 | AK36: =N36+O36+P36+Q36+R36+S36+T36+U36+X36+AE36+AH36 -> 97.8 | AL36: =IF(L36<0,L36*-1,0) -> 6.2036299 | AM36: =AK36+AL36 -> 104.00363 | AN36: =V36 -> 61 | AV36: 0.01 | AW36: 35 | AX36: 19 | AZ36: =SUM(N36,P36:U36) -> 2.8
A37: =A36+1 -> 23 | B37: 6898.01 | C37: 276297 | D37: =C37-C36 -> -73 | E37: =C37-152000 -> 124297 | F37: =D37/$D$2 -> -36.80363 | G37: 56 | H37: 0.81 | I37: =G37+H37 -> 56.81 | J37: =IF(L37>0,L37,0) -> 5.5863701 | K37: =I37+J37 -> 62.39637 | L37: =F37-(I37-AK37) -> 5.5863701 | M37: 4.2 | N37: 0 | O37: 0 | P37: 0 | Q37: =821400/325851/1.9835*1.02 -> 1.2962943 | R37: =(1415179/325851/1.9835-T37)*1.04 -> 1.5654667 | S37: 0 | T37: =0.658*1.04 -> 0.68432 | U37: =M37-(Q37+R37+S37+T37) -> 0.65391901 | V37: 61 | W37: 0 | X37: =M37-N37-P37-O37-Q37-R37-S37-T37-U37+V37+W37 -> 61 | Y37: =X37-AO37 -> 61 | AE37: 0 | AH37: 34 | AI37: =AI36-AH37 -> 4496 | AK37: =N37+O37+P37+Q37+R37+S37+T37+U37+X37+AE37+AH37 -> 99.2 | AL37: =IF(L37<0,L37*-1,0) -> 0 | AM37: =AK37+AL37 -> 99.2 | AN37: =V37 -> 61 | AV37: 0 | AW37: 41 | AX37: 19 | AZ37: =SUM(N37,P37:U37) -> 4.2
A38: =A37+1 -> 24 | B38: 6897.98 | C38: 276188 | D38: =C38-C37 -> -109 | E38: =C38-152000 -> 124188 | F38: =D38/$D$2 -> -54.953365 | G38: 61 | H38: 1.4 | I38: =G38+H38 -> 62.4 | J38: =IF(L38>0,L38,0) -> 0 | K38: =I38+J38 -> 62.4 | L38: =F38-(I38-AK38) -> -19.553365 | M38: 2.8 | N38: 0 | O38: 0 | P38: 0 | Q38: =1266700/325851/1.9835*1.02 -> 1.9990455 | R38: =(1515090/325851/1.9835-T38)*1.04 -> 1.7262331 | S38: 0 | T38: =0.658*1.04 -> 0.68432 | U38: =M38-(Q38+R38+S38+T38) -> -1.6095986 | V38: 61 | W38: 0 | X38: =M38-N38-P38-O38-Q38-R38-S38-T38-U38+V38+W38 -> 61 | Y38: =X38-AO38 -> 61 | AE38: 0 | AH38: 34 | AI38: =AI37-AH38 -> 4462 | AK38: =N38+O38+P38+Q38+R38+S38+T38+U38+X38+AE38+AH38 -> 97.8 | AL38: =IF(L38<0,L38*-1,0) -> 19.553365 | AM38: =AK38+AL38 -> 117.35337 | AN38: =V38 -> 61 | AV38: 0 | AW38: 33 | AX38: 4 | AZ38: =SUM(N38,P38:U38) -> 2.8
A39: =A38+1 -> 25 | B39: 6897.95 | C39: 276080 | D39: =C39-C38 -> -108 | E39: =C39-152000 -> 124080 | F39: =D39/$D$2 -> -54.449206 | G39: 51 | H39: 0.58 | I39: =G39+H39 -> 51.58 | J39: =IF(L39>0,L39,0) -> 0 | K39: =I39+J39 -> 51.58 | L39: =F39-(I39-AK39) -> -7.7292059 | M39: 3.3 | N39: 0 | O39: 0 | P39: 0 | Q39: =968700/325851/1.9835*1.02 -> 1.5287561 | R39: =(1517339/325851/1.9835-T39)*1.04 -> 1.729852 | S39: 0 | T39: =0.658*1.04 -> 0.68432 | U39: =M39-(Q39+R39+S39+T39) -> -0.64292812 | V39: 61 | W39: 0 | X39: =M39-N39-P39-O39-Q39-R39-S39-T39-U39+V39+W39 -> 61 | Y39: =X39-AO39 -> 61 | AE39: 0 | AH39: 34 | AI39: =AI38-AH39 -> 4428 | AK39: =N39+O39+P39+Q39+R39+S39+T39+U39+X39+AE39+AH39 -> 98.3 | AL39: =IF(L39<0,L39*-1,0) -> 7.7292059 | AM39: =AK39+AL39 -> 106.02921 | AN39: =V39 -> 61 | AV39: 0 | AW39: 32 | AX39: 2 | AZ39: =SUM(N39,P39:U39) -> 3.3
A40: =A39+1 -> 26 | B40: 6897.92 | C40: 275971 | D40: =C40-C39 -> -109 | E40: =C40-152000 -> 123971 | F40: =D40/$D$2 -> -54.953365 | G40: 48 | H40: 0.73 | I40: =G40+H40 -> 48.73 | J40: =IF(L40>0,L40,0) -> 0 | K40: =I40+J40 -> 48.73 | L40: =F40-(I40-AK40) -> -5.0833653 | M40: 3.6 | N40: 0 | O40: 0 | P40: 0 | Q40: =1114900/325851/1.9835*1.04 -> 1.7939816 | R40: =(1457422/325851/1.9835-T40)*1.04 -> 1.5857412 | S40: 0 | T40: =0.7021*1.04 -> 0.730184 | U40: =M40-(Q40+R40+S40+T40) -> -0.50990684 | V40: 61 | W40: 0 | X40: =M40-N40-P40-O40-Q40-R40-S40-T40-U40+V40+W40 -> 61 | Y40: =X40-AO40 -> 61 | AE40: 0 | AH40: 34 | AI40: =AI39-AH40 -> 4394 | AK40: =N40+O40+P40+Q40+R40+S40+T40+U40+X40+AE40+AH40 -> 98.6 | AL40: =IF(L40<0,L40*-1,0) -> 5.0833653 | AM40: =AK40+AL40 -> 103.68337 | AN40: =V40 -> 61 | AV40: 0 | AW40: 38 | AX40: 10 | AZ40: =SUM(N40,P40:U40) -> 3.6
A41: =A40+1 -> 27 | B41: 6897.89 | C41: 275863 | D41: =C41-C40 -> -108 | E41: =C41-152000 -> 123863 | F41: =D41/$D$2 -> -54.449206 | G41: 51 | H41: 0.76 | I41: =G41+H41 -> 51.76 | J41: =IF(L41>0,L41,0) -> 0 | K41: =I41+J41 -> 51.76 | L41: =F41-(I41-AK41) -> -7.3092059 | M41: 3.9 | N41: 0 | O41: 0 | P41: 0 | Q41: =1158100/325851/1.9835*1.02 -> 1.8276582 | R41: =(1431028/325851/1.9835-T41)*1.04 -> 1.5432707 | S41: 0 | T41: =0.7021*1.04 -> 0.730184 | U41: =M41-(Q41+R41+S41+T41) -> -0.20111288 | V41: 61 | W41: 0 | X41: =M41-N41-P41-O41-Q41-R41-S41-T41-U41+V41+W41 -> 61 | Y41: =X41-AO41 -> 61 | AE41: 0 | AH41: 34 | AI41: =AI40-AH41 -> 4360 | AK41: =N41+O41+P41+Q41+R41+S41+T41+U41+X41+AE41+AH41 -> 98.9 | AL41: =IF(L41<0,L41*-1,0) -> 7.3092059 | AM41: =AK41+AL41 -> 106.20921 | AN41: =V41 -> 61 | AV41: 0 | AW41: 48 | AX41: 18 | AZ41: =SUM(N41,P41:U41) -> 3.9
A42: =A41+1 -> 28 | B42: 6897.86 | C42: 275754 | D42: =C42-C41 -> -109 | E42: =C42-152000 -> 123754 | F42: =D42/$D$2 -> -54.953365 | G42: 54 | H42: 0.88 | I42: =G42+H42 -> 54.88 | J42: =IF(L42>0,L42,0) -> 0 | K42: =I42+J42 -> 54.88 | L42: =F42-(I42-AK42) -> -10.333365 | M42: 4.5 | N42: 0 | O42: 0 | P42: 0 | Q42: =1460800/325851/1.9835*1.02 -> 2.3053649 | R42: =(1402011/325851/1.9835-T42)*1.04 -> 1.4965796 | S42: 0 | T42: =0.7021*1.04 -> 0.730184 | U42: =M42-(Q42+R42+S42+T42) -> -0.032128421 | V42: 61 | W42: 0 | X42: =M42-N42-P42-O42-Q42-R42-S42-T42-U42+V42+W42 -> 61 | Y42: =X42-AO42 -> 61 | AE42: 0 | AH42: 34 | AI42: =AI41-AH42 -> 4326 | AK42: =N42+O42+P42+Q42+R42+S42+T42+U42+X42+AE42+AH42 -> 99.5 | AL42: =IF(L42<0,L42*-1,0) -> 10.333365 | AM42: =AK42+AL42 -> 109.83337 | AN42: =V42 -> 61 | AV42: 0.3 | AW42: 36 | AX42: 20 | AZ42: =SUM(N42,P42:U42) -> 4.5
...

Sheet DEC
K1: MCPHEE RESERVOIR INFLOW/OUTFLOW TABULATION
A2: AF/cfs CONVERT FACTOR | D2: 1.9835 | K2: DECEMBER "2010"
D4: RESERVOIR | I4: INFLOW | X4: OUTFLOW | AP4: ADJUSTMENTS | AW4: WEATHER
A5: DATE | B5: RESERV | C5: RESERV | D5: AC FT | E5: ACTIVE | F5: CONV TO | G5: DOLORES | H5: LOST | I5: RECORD | J5: CALC | K5: TOTAL | L5: CALC | M5: DOLORES TUNNEL | V5: LONE | W5: U | X5: TOTAL | Y5: TOTAL | Z5: MVI | AA5: MVI | AB5: MVI | AC5: TO EX & | AD5: MVI | AE5: DV CR | AF5: D/S SENIOR | AH5: BELOW | AI5: FISH | AJ5: SPILL | AK5: RECORD | AL5: CALC | AM5: TOTAL | AN5: NAR | AO5: MVI | AP5: MVI | AQ5: MVI | AR5: DIST. | AS5: U/S | AT5: TOTTEN | AU5: UTES | AV5: RAIN | AW5: MAX | AX5: MIN | AZ5: TOTAL
A6: DEC | B6: ELEV | D6: CHANGE | E6: CAP | F6: CFS | G6: RIVER | H6: CAN | I6: INFLOW | J6: INFLOW | K6: INFLOW | L6: INF/OTF | M6: TOT DIV | N6: WET | O6: UTE | P6: QUEST | Q6: MWC | R6: CORTEZ | T6: UTE | U6: F-BAY | V6: PINE | W6: LAT | X6: MVI | Y6: MVI | Z6: CALL | AA6: CALL | AB6: APR- | AC6: U/S EX | AD6: PROJ | AE6: CANAL | AF6: MVIC | AG6: PROJ | AH6: MCP | AI6: LEFT | AK6: OTF | AL6: OTF | AM6: OTF | AN6: FILLL | AO6: STOCK | AP6: STORED | AQ6: STORED | AR6: CLASS | AS6: USERS | AT6: (FRESH | AU6: FROM | AW6: TMP | AX6: TMP | AZ6: TUNNEL
N7: LAND | O7: F&R | Q7: NON - | R7: NON - | S7: PROJ | T7: PROJ | U7: BAL | X7: WATER | Y7: IRRIG. | Z7: STOR | AA7: SPILLED | AB7: JUNE | AF7: 1.7 | AG7: 1.3 | AP7: Apr - Jun | AQ7: EVAP | AR7: "B" | AS7: EXCH | AT7: WATER) | AU7: DWCD | AZ7: Misc.
Q8: PROJ | R8: PROJ | X8: USED | Y8: WATER | AA8: OR | AB8: (DIV+
R9: 4.2 | Y9: USED | AA9: USED | AB9: CALL)
C10: AC. Ft. | E10: AC FT | G10: CFS | H10: CFS | I10: CFS | J10: CFS | K10: CFS | L10: CFS | M10: CFS | N10: CFS | O10: CFS | P10: CFS | Q10: CFS | R10: CFS | S10: CFS | T10: CFS | U10: CFS | V10: CFS | W10: CFS | X10: 153400 | Y10: 150400 | AB10: 72000 | AC10: CFS | AD10: CFS | AE10: CFS | AF10: CFS | AG10: CFS | AH10: CFS | AI10: CFS | AJ10: CFS | AK10: CFS | AL10: CFS | AM10: CFS | AN10: CFS | AO10: CFS | AP10: CFS | AQ10: AC.FT. | AR10: CFS | AS10: CFS | AT10: CFS | AU10: CFS | AZ10: Outflow
N11: 1.03 | O11: 1.05 | P11: 1.02 | Q11: 1.02 | R11: 1.04 | T11: 1.04 | X11: CFS | Y11: CFS | Z11: CFS | AA11: CFS | AB11: Ac. Ft. | AZ11: CFS
A12: SEASON BAL
A13: YTD | B13: =NOV!B44 -> 6897.81 | C13: =NOV!C44 -> 275576 | D13: =NOV!D53 -> -1815 | E13: =NOV!E53 -> 123576 | F13: =NOV!F52 -> -915.04916 | G13: =NOV!G52 -> 2023 | H13: =NOV!H52 -> 38.19 | I13: =NOV!I52 -> 2061.19 | J13: =NOV!J52 -> 51.637693 | K13: =NOV!K52 -> 2112.8277 | L13: =NOV!L52 -> -326.85916 | M13: =NOV!M52 -> 236.1 | ... O13: =NOV!O52 -> 0 | Q13: =NOV!Q52 -> 52.529684 | R13: =NOV!R52 -> 47.31885 | S13: =NOV!S52 -> 0 | T13: =NOV!T52 -> 21.174192 | U13: =NOV!U52 -> -3.9419556 | V13: =NOV!V52 -> 1349 | W13: =NOV!W52 -> 58.28 | X13: =NOV!X52 -> 1526.2992 | Y13: =NOV!Y52 -> 1324.5 | AC13: =NOV!AC52 -> 662.6 | AH13: =NOV!AH52 -> 1006 | AI13: =NOV!AI52 -> 4258 | AK13: =NOV!AK52 -> 2649.38 | AL13: =NOV!AL52 -> 378.49685 | AM13: =NOV!AM52 -> 3027.8768 | AN13: =NOV!AN52 -> 1324.5 | AO13: =NOV!AO52 -> 201.79923 | AV13: =NOV!AV52 -> 0.57 | AZ13: =NOV!AZ52 -> 117.08077
A15: 1 | B15: 6897.78 | C15: 275465 | D15: =C15-C13 -> -111 | E15: =C15-152000 -> 123465 | F15: =D15/$D$2 -> -55.961684 | G15: 52 | H15: 1.3 | I15: =G15+H15 -> 53.3 | J15: =IF(L15>0,L15,0) -> 0 | K15: =I15+J15 -> 53.3 | L15: =F15-(I15-AK15) -> -10.461684 | M15: 4.8 | N15: 0 | O15: 0 | P15: 0 | Q15: =1198100/325851/1.9835*1.02 -> 1.8907843 | R15: =(1501767/325851/1.9835-T15)*1.04 -> 1.5465571 | S15: 0 | T15: =0.8043*1.04 -> 0.836472 | U15: =M15-(Q15+R15+S15+T15) -> 0.52618668 | V15: 61 | W15: 0 | X15: =M15-N15-P15-O15-Q15-R15-S15-T15-U15+V15+W15 -> 61 | Y15: =X15-AO15 -> 61 | AE15: 0 | AH15: 33 | AI15: =AI13-AH15 -> 4225 | AK15: =N15+O15+P15+Q15+R15+S15+T15+U15+X15+AE15+AH15 -> 98.8 | AL15: =IF(L15<0,L15*-1,0) -> 10.461684 | AM15: =AK15+AL15 -> 109.26168 | AN15: =V15 -> 61 | AO15: 0 | AV15: 0 | AW15: 45 | AX15: 14 | AZ15: =SUM(N15,P15:U15) -> 4.8
A16: =A15+1 -> 2 | B16: 6897.75 | C16: 275356 | D16: =C16-C15 -> -109 | E16: =C16-152000 -> 123356 | F16: =D16/$D$2 -> -54.953365 | G16: 56 | H16: 1.3 | I16: =G16+H16 -> 57.3 | J16: =IF(L16>0,L16,0) -> 0 | K16: =I16+J16 -> 57.3 | L16: =F16-(I16-AK16) -> -15.553365 | M16: 3.7 | N16: 0 | O16: 0 | P16: 0 | Q16: =1368100/325851/1.9835*1.02 -> 2.1590701 | R16: =(1545284/325851/1.9835-T16)*1.04 -> 1.6165801 | S16: 0 | T16: =0.8043*1.04 -> 0.836472 | U16: =M16-(Q16+R16+S16+T16) -> -0.91212226 | V16: 61 | W16: 0 | X16: =M16-N16-P16-O16-Q16-R16-S16-T16-U16+V16+W16 -> 61 | Y16: =X16-AO16 -> 61 | AE16: 0 | AH16: 32 | AI16: =AI15-AH16 -> 4193 | AK16: =N16+O16+P16+Q16+R16+S16+T16+U16+X16+AE16+AH16 -> 96.7 | AL16: =IF(L16<0,L16*-1,0) -> 15.553365 | AM16: =AK16+AL16 -> 112.25337 | AN16: =V16 -> 61 | AO16: 0 | AV16: 0 | AW16: 51 | AX16: 24 | AZ16: =SUM(N16,P16:U16) -> 3.7
A17: =A16+1 -> 3 | B17: 6897.72 | C17: 275248 | D17: =C17-C16 -> -108 | E17: =C17-152000 -> 123248 | F17: =D17/$D$2 -> -54.449206 | G17: 64 | H17: 1.3 | I17: =G17+H17 -> 65.3 | J17: =IF(L17>0,L17,0) -> 0 | K17: =I17+J17 -> 65.3 | L17: =F17-(I17-AK17) -> -23.249206 | M17: 4.5 | N17: 0 | O17: 0 | P17: 0 | Q17: =1287000/325851/1.9835*1.02 -> 2.031082 | R17: =(1521031/325851/1.9835-T17)*1.04 -> 1.7182709 | S17: 0 | T17: =0.6742*1.04 -> 0.701168 | U17: =M17-(Q17+R17+S17+T17) -> 0.049479147 | V17: 61 | W17: 0 | X17: =M17-N17-P17-O17-Q17-R17-S17-T17-U17+V17+W17 -> 61 | Y17: =X17-AO17 -> 61 | AE17: 0 | AH17: 31 | AI17: =AI16-AH17 -> 4162 | AK17: =N17+O17+P17+Q17+R17+S17+T17+U17+X17+AE17+AH17 -> 96.5 | AL17: =IF(L17<0,L17*-1,0) -> 23.249206 | AM17: =AK17+AL17 -> 119.74921 | AN17: =V17 -> 61 | AO17: 0 | AV17: 0 | AW17: 55 | AX17: 33 | AZ17: =SUM(N17,P17:U17) -> 4.5
A18: =A17+1 -> 4 | B18: 6897.69 | C18: 275139 | D18: =C18-C17 -> -109 | E18: =C18-152000 -> 123139 | F18: =D18/$D$2 -> -54.953365 | G18: 68 | H18: 1.3 | I18: =G18+H18 -> 69.3 | J18: =IF(L18>0,L18,0) -> 0 | K18: =I18+J18 -> 69.3 | L18: =F18-(I18-AK18) -> -27.653365 | M18: 4.6 | N18: 0 | O18: 0 | P18: 0 | Q18: =1060700/325851/1.9835*1.02 -> 1.6739461 | R18: =(1549827/325851/1.9835-T18)*1.04 -> 1.7646064 | S18: 0 | T18: =0.6742*1.04 -> 0.701168 | U18: =M18-(Q18+R18+S18+T18) -> 0.46027947 | V18: 61 | W18: 0 | X18: =M18-N18-P18-O18-Q18-R18-S18-T18-U18+V18+W18 -> 61 | Y18: =X18-AO18 -> 61 | AE18: 0 | AH18: 31 | AI18: =AI17-AH18 -> 4131 | AK18: =N18+O18+P18+Q18+R18+S18+T18+U18+X18+AE18+AH18 -> 96.6 | AL18: =IF(L18<0,L18*-1,0) -> 27.653365 | AM18: =AK18+AL18 -> 124.25337 | AN18: =V18 -> 61 | AO18: 0 | AV18: 0 | AW18: 53 | AX18: 32 | AZ18: =SUM(N18,P18:U18) -> 4.6
A19: =A18+1 -> 5 | B19: 6897.66 | C19: 275031 | D19: =C19-C18 -> -108 | E19: =C19-152000 -> 123031 | F19: =D19/$D$2 -> -54.449206 | G19: 68 | H19: 1.2 | I19: =G19+H19 -> 69.2 | J19: =IF(L19>0,L19,0) -> 0 | K19: =I19+J19 -> 69.2 | L19: =F19-(I19-AK19) -> -28.449206 | M19: 3.2 | N19: 0 | O19: 0 | P19: 0 | Q19: =1383100/325851/1.9835*1.02 -> 2.1827424 | R19: =(1458890/325851/1.9835-T19)*1.04 -> 1.61828 | S19: 0 | T19: =0.6742*1.04 -> 0.701168 | U19: =M19-(Q19+R19+S19+T19) -> -1.3021904 | V19: 61 | W19: 0 | X19: =M19-N19-P19-O19-Q19-R19-S19-T19-U19+V19+W19 -> 61 | Y19: =X19-AO19 -> 61 | AE19: 0 | AH19: 31 | AI19: =AI18-AH19 -> 4100 | AK19: =N19+O19+P19+Q19+R19+S19+T19+U19+X19+AE19+AH19 -> 95.2 | AL19: =IF(L19<0,L19*-1,0) -> 28.449206 | AM19: =AK19+AL19 -> 123.64921 | AN19: =V19 -> 61 | AO19: 0 | AV19: 0 | AW19: 53 | AX19: 32 | AZ19: =SUM(N19,P19:U19) -> 3.2
A20: =A19+1 -> 6 | B20: 6897.65 | C20: 274995 | D20: =C20-C19 -> -36 | E20: =C20-152000 -> 122995 | F20: =D20/$D$2 -> -18.149735 | G20: 68 | H20: 1.2 | I20: =G20+H20 -> 69.2 | J20: =IF(L20>0,L20,0) -> 8.6502647 | K20: =I20+J20 -> 77.850265 | L20: =F20-(I20-AK20) -> 8.6502647 | M20: 4 | N20: 0 | O20: 0 | P20: 0 | Q20: =1240000/325851/1.9835*1.02 -> 1.9569088 | R20: =(1428632/325851/1.9835-T20)*1.04 -> 1.569592 | S20: 0 | T20: =0.6742*1.04 -> 0.701168 | U20: =M20-(Q20+R20+S20+T20) -> -0.22766879 | V20: 61 | W20: 0 | X20: =M20-N20-P20-O20-Q20-R20-S20-T20-U20+V20+W20 -> 61 | Y20: =X20-AO20 -> 61 | AC20: 14.5 | AE20: 0 | AH20: 31 | AI20: =AI19-AH20 -> 4069 | AK20: =N20+O20+P20+Q20+R20+S20+T20+U20+X20+AE20+AH20 -> 96 | AL20: =IF(L20<0,L20*-1,0) -> 0 | AM20: =AK20+AL20 -> 96 | AN20: =V20 -> 61 | AO20: 0 | AV20: 0.01 | AW20: 51 | AX20: 30 | AZ20: =SUM(N20,P20:U20) -> 4
A21: =A20+1 -> 7 | B21: 6897.64 | C21: 274958 | D21: =C21-C20 -> -37 | E21: =C21-152000 -> 122958 | F21: =D21/$D$2 -> -18.653895 | G21: 64 | H21: 1.1 | I21: =G21+H21 -> 65.1 | J21: =IF(L21>0,L21,0) -> 12.846105 | K21: =I21+J21 -> 77.946105 | L21: =F21-(I21-AK21) -> 12.846105 | M21: 4.6 | N21: 0 | O21: 0 | P21: 0 | Q21: =1169800/325851/1.9835*1.02 -> 1.8461225 | R21: =(1406695/325851/1.9835-T21)*1.04 -> 1.5342932 | S21: 0 | T21: =0.6742*1.04 -> 0.701168 | U21: =M21-(Q21+R21+S21+T21) -> 0.51841625 | V21: 61 | W21: 0 | X21: =M21-N21-P21-O21-Q21-R21-S21-T21-U21+V21+W21 -> 61 | Y21: =X21-AO21 -> 61 | AC21: 14.6 | AE21: 0 | AH21: 31 | AI21: =AI20-AH21 -> 4038 | AK21: =N21+O21+P21+Q21+R21+S21+T21+U21+X21+AE21+AH21 -> 96.6 | AL21: =IF(L21<0,L21*-1,0) -> 0 | AM21: =AK21+AL21 -> 96.6 | AN21: =V21 -> 61 | AO21: 0 | AV21: 0 | AW21: 45 | AX21: 25 | AZ21: =SUM(N21,P21:U21) -> 4.6
A22: =A21+1 -> 8 | B22: 6897.62 | C22: 274886 | D22: =C22-C21 -> -72 | E22: =C22-152000 -> 122886 | F22: =D22/$D$2 -> -36.299471 | G22: 61 | H22: 0.99 | I22: =G22+H22 -> 61.99 | J22: =IF(L22>0,L22,0) -> 0 | K22: =I22+J22 -> 61.99 | L22: =F22-(I22-AK22) -> -2.0894706 | M22: 4.2 | N22: 0 | O22: 0 | P22: 0 | Q22: =1214400/325851/1.9835*1.02 -> 1.9165081 | R22: =(1473941/325851/1.9835-T22)*1.04 -> 1.6424985 | S22: 0 | T22: =0.6742*1.04 -> 0.701168 | U22: =M22-(Q22+R22+S22+T22) -> -0.060174645 | V22: 61 | W22: 0 | X22: =M22-N22-P22-O22-Q22-R22-S22-T22-U22+V22+W22 -> 61 | Y22: =X22-AO22 -> 61 | AE22: 0 | AH22: 31 | AI22: =AI21-AH22 -> 4007 | AK22: =N22+O22+P22+Q22+R22+S22+T22+U22+X22+AE22+AH22 -> 96.2 | AL22: =IF(L22<0,L22*-1,0) -> 2.0894706 | AM22: =AK22+AL22 -> 98.289471 | AN22: =V22 -> 61 | AO22: 0 | AV22: 0 | AW22: 47 | AX22: 24 | AZ22: =SUM(N22,P22:U22) -> 4.2
A23: =A22+1 -> 9 | B23: 6897.6 | C23: 274814 | D23: =C23-C22 -> -72 | E23: =C23-152000 -> 122814 | F23: =D23/$D$2 -> -36.299471 | G23: 61 | H23: 0.93 | I23: =G23+H23 -> 61.93 | J23: =IF(L23>0,L23,0) -> 0 | K23: =I23+J23 -> 61.93 | L23: =F23-(I23-AK23) -> -2.3294706 | M23: 3.9 | N23: 0 | O23: 0 | P23: 0 | Q23: =1234600/325851/1.9835*1.02 -> 1.9483868 | R23: =(1443627/325851/1.9835-T23)*1.04 -> 1.5937204 | S23: 0 | T23: =0.6742*1.04 -> 0.701168 | U23: =M23-(Q23+R23+S23+T23) -> -0.34327517 | V23: 61 | W23: 0 | X23: =M23-N23-P23-O23-Q23-R23-S23-T23-U23+V23+W23 -> 61 | Y23: =X23-AO23 -> 61 | AE23: 0 | AH23: 31 | AI23: =AI22-AH23 -> 3976 | AK23: =N23+O23+P23+Q23+R23+S23+T23+U23+X23+AE23+AH23 -> 95.9 | AL23: =IF(L23<0,L23*-1,0) -> 2.3294706 | AM23: =AK23+AL23 -> 98.229471 | AN23: =V23 -> 61 | AO23: 0 | AV23: 0 | AW23: 49 | AX23: 28 | AZ23: =SUM(N23,P23:U23) -> 3.9
A24: =A23+1 -> 10 | B24: 6897.58 | C24: 274741 | D24: =C24-C23 -> -73 | E24: =C24-152000 -> 122741 | F24: =D24/$D$2 -> -36.80363 | G24: 61 | H24: 1 | I24: =G24+H24 -> 62 | J24: =IF(L24>0,L24,0) -> 0 | K24: =I24+J24 -> 62 | L24: =F24-(I24-AK24) -> -2.6036299 | M24: 4.2 | N24: 0 | O24: 0 | P24: 0 | Q24: =962800/325851/1.9835*1.02 -> 1.519445 | R24: =(1789077/325851/1.9835-T24)*1.04 -> 1.6735706 | S24: 0 | T24: =1.1143*1.04 -> 1.158872 | U24: =M24-(Q24+R24+S24+T24) -> -0.15188759 | V24: 61 | W24: 0 | X24: =M24-N24-P24-O24-Q24-R24-S24-T24-U24+V24+W24 -> 61 | Y24: =X24-AO24 -> 61 | AE24: 0 | AH24: 31 | AI24: =AI23-AH24 -> 3945 | AK24: =N24+O24+P24+Q24+R24+S24+T24+U24+X24+AE24+AH24 -> 96.2 | AL24: =IF(L24<0,L24*-1,0) -> 2.6036299 | AM24: =AK24+AL24 -> 98.80363 | AN24: =V24 -> 61 | AO24: 0 | AV24: 0 | AW24: 47 | AX24: 29 | AZ24: =SUM(N24,P24:U24) -> 4.2
A25: =A24+1 -> 11 | B25: 6897.56 | C25: 274669 | D25: =C25-C24 -> -72 | E25: =C25-152000 -> 122669 | F25: =D25/$D$2 -> -36.299471 | G25: 62 | H25: 0.93 | I25: =G25+H25 -> 62.93 | J25: =IF(L25>0,L25,0) -> 0 | K25: =I25+J25 -> 62.93 | L25: =F25-(I25-AK25) -> -2.9294706 | M25: 4.3 | N25: 0 | O25: 0 | P25: 0 | Q25: =1121000/325851/1.9835*1.02 -> 1.7691087 | R25: =(1453115/325851/1.9835-T25)*1.04 -> 1.1329753 | S25: 0 | T25: =1.1143*1.04 -> 1.158872 | U25: =M25-(Q25+R25+S25+T25) -> 0.23904398 | V25: 61 | W25: 0 | X25: =M25-N25-P25-O25-Q25-R25-S25-T25-U25+V25+W25 -> 61 | Y25: =X25-AO25 -> 61 | AE25: 0 | AH25: 31 | AI25: =AI24-AH25 -> 3914 | AK25: =N25+O25+P25+Q25+R25+S25+T25+U25+X25+AE25+AH25 -> 96.3 | AL25: =IF(L25<0,L25*-1,0) -> 2.9294706 | AM25: =AK25+AL25 -> 99.229471 | AN25: =V25 -> 61 | AO25: 0 | AV25: 0 | AW25: 47 | AX25: 27 | AZ25: =SUM(N25,P25:U25) -> 4.3
A26: =A25+1 -> 12 | B26: 6897.55 | C26: 274633 | D26: =C26-C25 -> -36 | E26: =C26-152000 -> 122633 | F26: =D26/$D$2 -> -18.149735 | G26: 61 | H26: 0.91 | I26: =G26+H26 -> 61.91 | J26: =IF(L26>0,L26,0) -> 16.040265 | K26: =I26+J26 -> 77.950265 | L26: =F26-(I26-AK26) -> 16.040265 | M26: 4.1 | N26: 0 | O26: 0 | P26: 0 | Q26: =1344300/325851/1.9835*1.02 -> 2.1215101 | R26: =(1745816/325851/1.9835-T26)*1.04 -> 1.6039594 | S26: 0 | T26: =1.1143*1.04 -> 1.158872 | U26: =M26-(Q26+R26+S26+T26) -> -0.78434156 | V26: 61 | W26: 0 | X26: =M26-N26-P26-O26-Q26-R26-S26-T26-U26+V26+W26 -> 61 | Y26: =X26-AO26 -> 61 | AC26: 14.2 | AE26: 0 | AH26: 31 | AI26: =AI25-AH26 -> 3883 | AK26: =N26+O26+P26+Q26+R26+S26+T26+U26+X26+AE26+AH26 -> 96.1 | AL26: =IF(L26<0,L26*-1,0) -> 0 | AM26: =AK26+AL26 -> 96.1 | AN26: =V26 -> 61 | AO26: 0 | AV26: 0 | AW26: 53 | AX26: 27 | AZ26: =SUM(N26,P26:U26) -> 4.1
A27: =A26+1 -> 13 | B27: 6897.53 | C27: 274560 | D27: =C27-C26 -> -73 | E27: =C27-152000 -> 122560 | F27: =D27/$D$2 -> -36.80363 | G27: 61 | H27: 0.93 | I27: =G27+H27 -> 61.93 | J27: =IF(L27>0,L27,0) -> 0 | K27: =I27+J27 -> 61.93 | L27: =F27-(I27-AK27) -> -3.4336299 | M27: 3.3 | N27: 0 | O27: 0 | P27: 0 | Q27: =1207300/325851/1.9835*1.02 -> 1.9053033 | R27: =(1771776/325851/1.9835-T27)*1.04 -> 1.6457316 | S27: 0 | T27: =1.1143*1.04 -> 1.158872 | U27: =M27-(Q27+R27+S27+T27) -> -1.4099068 | V27: 61 | W27: 0 | X27: =M27-N27-P27-O27-Q27-R27-S27-T27-U27+V27+W27 -> 61 | Y27: =X27-AO27 -> 61 | AE27: 0 | AH27: 31 | AI27: =AI26-AH27 -> 3852 | AK27: =N27+O27+P27+Q27+R27+S27+T27+U27+X27+AE27+AH27 -> 95.3 | AL27: =IF(L27<0,L27*-1,0) -> 3.4336299 | AM27: =AK27+AL27 -> 98.73363 | AN27: =V27 -> 61 | AO27: 0 | AV27: 0 | AW27: 54 | AX27: 17 | AZ27: =SUM(N27,P27:U27) -> 3.3
A28: =A27+1 -> 14 | B28: 6897.51 | C28: 274488 | D28: =C28-C27 -> -72 | E28: =C28-152000 -> 122488 | F28: =D28/$D$2 -> -36.299471 | G28: 63 | H28: 1.1 | I28: =G28+H28 -> 64.1 | J28: =IF(L28>0,L28,0) -> 0 | K28: =I28+J28 -> 64.1 | L28: =F28-(I28-AK28) -> -3.7394706 | M28: 4.66 | N28: 0 | O28: 0 | P28: 0 | Q28: =1136700/325851/1.9835*1.02 -> 1.7938857 | R28: =(1981166/325851/1.9835-T28)*1.04 -> 1.9826603 | S28: 0 | T28: =1.1143*1.04 -> 1.158872 | U28: =M28-(Q28+R28+S28+T28) -> -0.275418 | V28: 61 | W28: 0 | X28: =M28-N28-P28-O28-Q28-R28-S28-T28-U28+V28+W28 -> 61 | Y28: =X28-AO28 -> 61 | AE28: 0 | AH28: 31 | AI28: =AI27-AH28 -> 3821 | AK28: =N28+O28+P28+Q28+R28+S28+T28+U28+X28+AE28+AH28 -> 96.66 | AL28: =IF(L28<0,L28*-1,0) -> 3.7394706 | AM28: =AK28+AL28 -> 100.39947 | AN28: =V28 -> 61 | AO28: 0 | AV28: 0 | AW28: 55 | AX28: 19 | AZ28: =SUM(N28,P28:U28) -> 4.66
A29: =A28+1 -> 15 | B29: 6897.49 | C29: 274415 | D29: =C29-C28 -> -73 | E29: =C29-152000 -> 122415 | F29: =D29/$D$2 -> -36.80363 | G29: 64 | H29: 1.4 | I29: =G29+H29 -> 65.4 | J29: =IF(L29>0,L29,0) -> 0.99637005 | K29: =I29+J29 -> 66.39637 | L29: =F29-(I29-AK29) -> 0.99637005 | M29: 4.2 | N29: 0 | O29: 0 | P29: 0 | Q29: =1096300/325851/1.9835*1.02 -> 1.7301284 | R29: =(2424835/325851/1.9835-T29)*1.04 -> 2.7622196 | S29: 0 | T29: =1.0536*1.04 -> 1.095744 | U29: =M29-(Q29+R29+S29+T29) -> -1.388092 | V29: 68 | W29: 0 | X29: =M29-N29-P29-O29-Q29-R29-S29-T29-U29+V29+W29 -> 68 | Y29: =X29-AO29 -> 68 | AE29: 0 | AH29: 31 | AI29: =AI28-AH29 -> 3790 | AK29: =N29+O29+P29+Q29+R29+S29+T29+U29+X29+AE29+AH29 -> 103.2 | AL29: =IF(L29<0,L29*-1,0) -> 0 | AM29: =AK29+AL29 -> 103.2 | AN29: =V29 -> 68 | AO29: 0 | AV29: 0.04 | AW29: 45 | AX29: 25 | AZ29: =SUM(N29,P29:U29) -> 4.2
A30: =A29+1 -> 16 | B30: 6897.46 | C30: 274307 | D30: =C30-C29 -> -108 | E30: =C30-152000 -> 122307 | F30: =D30/$D$2 -> -54.449206 | G30: 75 | H30: 1.7 | I30: =G30+H30 -> 76.7 | J30: =IF(L30>0,L30,0) -> 0 | K30: =I30+J30 -> 76.7 | L30: =F30-(I30-AK30) -> -30.949206 | M30: 4.2 | N30: 0 | O30: 0 | P30: 0 | Q30: =1166200/325851/1.9835*1.02 -> 1.8404412 | R30: =(1625852/325851/1.9835-T30)*1.04 -> 1.4765789 | S30: 0 | T30: =1.0536*1.04 -> 1.095744 | U30: =M30-(Q30+R30+S30+T30) -> -0.21276412 | V30: 65 | W30: 0 | X30: =M30-N30-P30-O30-Q30-R30-S30-T30-U30+V30+W30 -> 65 | Y30: =X30-AO30 -> 65 | AE30: 0 | AH30: 31 | AI30: =AI29-AH30 -> 3759 | AK30: =N30+O30+P30+Q30+R30+S30+T30+U30+X30+AE30+AH30 -> 100.2 | AL30: =IF(L30<0,L30*-1,0) -> 30.949206 | AM30: =AK30+AL30 -> 131.14921 | AN30: =V30 -> 65 | AO30: 0 | AV30: 0.2 | AW30: 37 | AX30: 30 | AZ30: =SUM(N30,P30:U30) -> 4.2
A31: =A30+1 -> 17 | B31: 6897.48 | C31: 274380 | D31: =C31-C30 -> 73 | E31: =C31-152000 -> 122380 | F31: =D31/$D$2 -> 36.80363 | G31: 84 | H31: 1.9 | I31: =G31+H31 -> 85.9 | J31: =IF(L31>0,L31,0) -> 45.10363 | K31: =I31+J31 -> 131.00363 | L31: =F31-(I31-AK31) -> 45.10363 | M31: 4.2 | N31: 0 | O31: 0 | P31: 0 | Q31: =1016800/325851/1.9835*1.02 -> 1.6046652 | R31: =(1411987/325851/1.9835-T31)*1.04 -> 0.91699479 | S31: 0 | T31: =1.2528*1.04 -> 1.302912 | U31: =M31-(Q31+R31+S31+T31) -> 0.37542797 | V31: 59 | W31: 0 | X31: =M31-N31-P31-O31-Q31-R31-S31-T31-U31+V31+W31 -> 59 | Y31: =X31-AO31 -> 59 | AC31: 13.7 | AE31: 0 | AH31: 31 | AI31: =AI30-AH31 -> 3728 | AK31: =N31+O31+P31+Q31+R31+S31+T31+U31+X31+AE31+AH31 -> 94.2 | AL31: =IF(L31<0,L31*-1,0) -> 0 | AM31: =AK31+AL31 -> 94.2 | AN31: =V31 -> 59 | AO31: 0 | AV31: 0.06 | AW31: 39 | AX31: 22 | AZ31: =SUM(N31,P31:U31) -> 4.2
A32: =A31+1 -> 18 | B32: 6897.5 | C32: 274452 | D32: =C32-C31 -> 72 | E32: =C32-152000 -> 122452 | F32: =D32/$D$2 -> 36.299471 | G32: 91 | H32: 2.8 | I32: =G32+H32 -> 93.8 | J32: =IF(L32>0,L32,0) -> 36.699471 | K32: =I32+J32 -> 130.49947 | L32: =F32-(I32-AK32) -> 36.699471 | M32: 4.2 | N32: 0 | O32: 0 | P32: 0 | Q32: =967900/325851/1.9835*1.02 -> 1.5274936 | R32: =(1857879/325851/1.9835-T32)*1.04 -> 1.634478 | S32: 0 | T32: =1.2528*1.04 -> 1.302912 | U32: =M32-(Q32+R32+S32+T32) -> -0.26488362 | V32: 59 | W32: 0 | X32: =M32-N32-P32-O32-Q32-R32-S32-T32-U32+V32+W32 -> 59 | Y32: =X32-AO32 -> 59 | AC32: 10.7 | AE32: 0 | AH32: 31 | AI32: =AI31-AH32 -> 3697 | AK32: =N32+O32+P32+Q32+R32+S32+T32+U32+X32+AE32+AH32 -> 94.2 | AL32: =IF(L32<0,L32*-1,0) -> 0 | AM32: =AK32+AL32 -> 94.2 | AN32: =V32 -> 59 | AO32: 0 | AV32: 0.4 | AW32: 36 | AX32: 30 | AZ32: =SUM(N32,P32:U32) -> 4.2
A33: =A32+1 -> 19 | B33: 6897.52 | C33: 274524 | D33: =C33-C32 -> 72 | E33: =C33-152000 -> 122524 | F33: =D33/$D$2 -> 36.299471 | G33: 96 | H33: 3.8 | I33: =G33+H33 -> 99.8 | J33: =IF(L33>0,L33,0) -> 31.699471 | K33: =I33+J33 -> 131.49947 | L33: =F33-(I33-AK33) -> 31.699471 | M33: 4.2 | N33: 0 | O33: 0 | P33: 0 | Q33: =1145700/325851/1.9835*1.02 -> 1.8080891 | R33: =(1814288/325851/1.9835-T33)*1.04 -> 1.5643359 | S33: 0 | T33: =1.2528*1.04 -> 1.302912 | U33: =M33-(Q33+R33+S33+T33) -> -0.47533697 | V33: 59 | W33: 0 | X33: =M33-N33-P33-O33-Q33-R33-S33-T33-U33+V33+W33 -> 59 | Y33: =X33-AO33 -> 59 | AC33: 11.8 | AE33: 0 | AH33: 32 | AI33: =AI32-AH33 -> 3665 | AK33: =N33+O33+P33+Q33+R33+S33+T33+U33+X33+AE33+AH33 -> 95.2 | AL33: =IF(L33<0,L33*-1,0) -> 0 | AM33: =AK33+AL33 -> 95.2 | AN33: =V33 -> 59 | AO33: 0 | AV33: 0.14 | AW33: 39 | AX33: 34 | AZ33: =SUM(N33,P33:U33) -> 4.2
A34: =A33+1 -> 20 | B34: 6897.56 | C34: 274669 | D34: =C34-C33 -> 145 | E34: =C34-152000 -> 122669 | F34: =D34/$D$2 -> 73.103101 | G34: 108 | H34: 5.2 | I34: =G34+H34 -> 113.2 | J34: =IF(L34>0,L34,0) -> 55.103101 | K34: =I34+J34 -> 168.3031 | L34: =F34-(I34-AK34) -> 55.103101 | M34: 4.2 | N34: 0 | O34: 0 | P34: 0 | Q34: =862900/325851/1.9835*1.02 -> 1.3617876 | R34: =(1609452/325851/1.9835-T34)*1.04 -> 1.234735 | S34: 0 | T34: =1.2528*1.04 -> 1.302912 | U34: =M34-(Q34+R34+S34+T34) -> 0.30056537 | V34: 59 | W34: 0 | X34: =M34-N34-P34-O34-Q34-R34-S34-T34-U34+V34+W34 -> 59 | Y34: =X34-AO34 -> 59 | AC34: 26.2 | AE34: 0 | AH34: 32 | AI34: =AI33-AH34 -> 3633 | AK34: =N34+O34+P34+Q34+R34+S34+T34+U34+X34+AE34+AH34 -> 95.2 | AL34: =IF(L34<0,L34*-1,0) -> 0 | AM34: =AK34+AL34 -> 95.2 | AN34: =V34 -> 59 | AO34: 0 | AV34: 0 | AW34: 43 | AX34: 34 | AZ34: =SUM(N34,P34:U34) -> 4.2
A35: =A34+1 -> 21 | B35: 6897.6 | C35: 274814 | D35: =C35-C34 -> 145 | E35: =C35-152000 -> 122814 | F35: =D35/$D$2 -> 73.103101 | G35: 122 | H35: 5.7 | I35: =G35+H35 -> 127.7 | J35: =IF(L35>0,L35,0) -> 39.823101 | K35: =I35+J35 -> 167.5231 | L35: =F35-(I35-AK35) -> 39.823101 | M35: 3.42 | N35: 0 | O35: 0 | P35: 0 | Q35: =1037800/325851/1.9835*1.02 -> 1.6378064 | R35: =(1745415/325851/1.9835-T35)*1.04 -> 1.4535126 | S35: 0 | T35: =1.2528*1.04 -> 1.302912 | U35: =M35-(Q35+R35+S35+T35) -> -0.97423104 | V35: 59 | W35: 0 | X35: =M35-N35-P35-O35-Q35-R35-S35-T35-U35+V35+W35 -> 59 | Y35: =X35-AO35 -> 59 | AC35: 24.9 | AE35: 0 | AH35: 32 | AI35: =AI34-AH35 -> 3601 | AK35: =N35+O35+P35+Q35+R35+S35+T35+U35+X35+AE35+AH35 -> 94.42 | AL35: =IF(L35<0,L35*-1,0) -> 0 | AM35: =AK35+AL35 -> 94.42 | AN35: =V35 -> 59 | AO35: 0 | AV35: 0.3 | AW35: 43 | AX35: 32 | AZ35: =SUM(N35,P35:U35) -> 3.42
A36: =A35+1 -> 22 | B36: 6897.65 | C36: 274995 | D36: =C36-C35 -> 181 | E36: =C36-152000 -> 122995 | F36: =D36/$D$2 -> 91.252836 | G36: 108 | H36: 6 | I36: =G36+H36 -> 114 | J36: =IF(L36>0,L36,0) -> 73.032836 | K36: =I36+J36 -> 187.03284 | L36: =F36-(I36-AK36) -> 73.032836 | M36: 4.78 | N36: 0 | O36: 0 | P36: 0 | Q36: =1007900/325851/1.9835*1.02 -> 1.5906197 | R36: =(1812416/325851/1.9835-T36)*1.04 -> 1.5613237 | S36: 0 | T36: =1.2528*1.04 -> 1.302912 | U36: =M36-(Q36+R36+S36+T36) -> 0.32514464 | V36: 59 | W36: 0 | X36: =M36-N36-P36-O36-Q36-R36-S36-T36-U36+V36+W36 -> 59 | Y36: =X36-AO36 -> 59 | AC36: 33.2 | AE36: 0 | AH36: 32 | AI36: =AI35-AH36 -> 3569 | AK36: =N36+O36+P36+Q36+R36+S36+T36+U36+X36+AE36+AH36 -> 95.78 | AL36: =IF(L36<0,L36*-1,0) -> 0 | AM36: =AK36+AL36 -> 95.78 | AN36: =V36 -> 59 | AO36: 0 | AV36: 0.41 | AW36: 45 | AX36: 35 | AZ36: =SUM(N36,P36:U36) -> 4.78
A37: =A36+1 -> 23 | B37: 6897.7 | C37: 275175 | D37: =C37-C36 -> 180 | E37: =C37-152000 -> 123175 | F37: =D37/$D$2 -> 90.748677 | G37: 107 | H37: 6.4 | I37: =G37+H37 -> 113.4 | J37: =IF(L37>0,L37,0) -> 72.858677 | K37: =I37+J37 -> 186.25868 | L37: =F37-(I37-AK37) -> 72.858677 | M37: 4.51 | N37: 0 | O37: 0 | P37: 0 | Q37: =1058800/325851/1.9835*1.02 -> 1.6709476 | R37: =(1995328/325851/1.9835-T37)*1.04 -> 1.8556467 | S37: 0 | T37: =1.2528*1.04 -> 1.302912 | U37: =M37-(Q37+R37+S37+T37) -> -0.31950636 | V37: 59 | W37: 0 | X37: =M37-N37-P37-O37-Q37-R37-S37-T37-U37+V37+W37 -> 59 | Y37: =X37-AO37 -> 59 | AC37: 33.4 | AE37: 0 | AH37: 32 | AI37: =AI36-AH37 -> 3537 | AK37: =N37+O37+P37+Q37+R37+S37+T37+U37+X37+AE37+AH37 -> 95.51 | AL37: =IF(L37<0,L37*-1,0) -> 0 | AM37: =AK37+AL37 -> 95.51 | AN37: =V37 -> 59 | AO37: 0 | AV37: 0.3 | AW37: 42 | AX37: 33 | AZ37: =SUM(N37,P37:U37) -> 4.51
A38: =A37+1 -> 24 | B38: 6897.71 | C38: 275212 | D38: =C38-C37 -> 37 | E38: =C38-152000 -> 123212 | F38: =D38/$D$2 -> 18.653895 | G38: 96 | H38: 5.5 | I38: =G38+H38 -> 101.5 | J38: =IF(L38>0,L38,0) -> 11.873895 | K38: =I38+J38 -> 113.37389 | L38: =F38-(I38-AK38) -> 11.873895 | M38: 3.72 | N38: 0 | O38: 0 | P38: 0 | Q38: =998500/325851/1.9835*1.02 -> 1.5757851 | R38: =(1927020/325851/1.9835-T38)*1.04 -> 1.770393 | S38: 0 | T38: =1.23*1.04 -> 1.2792 | U38: =M38-(Q38+R38+S38+T38) -> -0.9053781 | V38: 59 | W38: 0 | X38: =M38-N38-P38-O38-Q38-R38-S38-T38-U38+V38+W38 -> 59 | Y38: =X38-AO38 -> 59 | AC38: 17.2 | AE38: 0 | AH38: 32 | AI38: =AI37-AH38 -> 3505 | AK38: =N38+O38+P38+Q38+R38+S38+T38+U38+X38+AE38+AH38 -> 94.72 | AL38: =IF(L38<0,L38*-1,0) -> 0 | AM38: =AK38+AL38 -> 94.72 | AN38: =V38 -> 59 | AO38: 0 | AV38: 0 | AW38: 43 | AX38: 29 | AZ38: =SUM(N38,P38:U38) -> 3.72
A39: =A38+1 -> 25 | B39: 6897.72 | C39: 275248 | D39: =C39-C38 -> 36 | E39: =C39-152000 -> 123248 | F39: =D39/$D$2 -> 18.149735 | G39: 73 | H39: 4.5 | I39: =G39+H39 -> 77.5 | J39: =IF(L39>0,L39,0) -> 36.839735 | K39: =I39+J39 -> 114.33974 | L39: =F39-(I39-AK39) -> 36.839735 | M39: 5.19 | N39: 0 | O39: 0 | P39: 0 | Q39: =1144500/325851/1.9835*1.02 -> 1.8061953 | R39: =(1747738/325851/1.9835-T39)*1.04 -> 1.4854803 | S39: 0 | T39: =1.2267*1.04 -> 1.275768 | U39: =M39-(Q39+R39+S39+T39) -> 0.62255642 | V39: 59 | W39: 0 | X39: =M39-N39-P39-O39-Q39-R39-S39-T39-U39+V39+W39 -> 59 | Y39: =X39-AO39 -> 59 | AC39: 18.9 | AE39: 0 | AH39: 32 | AI39: =AI38-AH39 -> 3473 | AK39: =N39+O39+P39+Q39+R39+S39+T39+U39+X39+AE39+AH39 -> 96.19 | AL39: =IF(L39<0,L39*-1,0) -> 0 | AM39: =AK39+AL39 -> 96.19 | AN39: =V39 -> 59 | AO39: 0 | AV39: 0 | AW39: 45 | AX39: 26 | AZ39: =SUM(N39,P39:U39) -> 5.19
A40: =A39+1 -> 26 | B40: 6897.69 | C40: 275139 | D40: =C40-C39 -> -109 | E40: =C40-152000 -> 123139 | F40: =D40/$D$2 -> -54.953365 | G40: 65 | H40: 3.4 | I40: =G40+H40 -> 68.4 | J40: =IF(L40>0,L40,0) -> 0 | K40: =I40+J40 -> 68.4 | L40: =F40-(I40-AK40) -> -27.363365 | M40: 4.99 | N40: 0 | O40: 0 | P40: 0 | Q40: =1036800/325851/1.9835*1.02 -> 1.6362283 | R40: =(1890834/325851/1.9835-T40)*1.04 -> 1.7157356 | S40: 0 | T40: =1.2267*1.04 -> 1.275768 | U40: =M40-(Q40+R40+S40+T40) -> 0.36226816 | V40: 59 | W40: 0 | X40: =M40-N40-P40-O40-Q40-R40-S40-T40-U40+V40+W40 -> 59 | Y40: =X40-AO40 -> 59 | AE40: 0 | AH40: 32 | AI40: =AI39-AH40 -> 3441 | AK40: =N40+O40+P40+Q40+R40+S40+T40+U40+X40+AE40+AH40 -> 95.99 | AL40: =IF(L40<0,L40*-1,0) -> 27.363365 | AM40: =AK40+AL40 -> 123.35337 | AN40: =V40 -> 59 | AO40: 0 | AV40: 0 | AW40: 46 | AX40: 26 | AZ40: =SUM(N40,P40:U40) -> 4.99
A41: =A40+1 -> 27 | B41: 6897.68 | C41: 275103 | D41: =C41-C40 -> -36 | E41: =C41-152000 -> 123103 | F41: =D41/$D$2 -> -18.149735 | G41: 63 | H41: 2.6 | I41: =G41+H41 -> 65.6 | J41: =IF(L41>0,L41,0) -> 10.760265 | K41: =I41+J41 -> 76.360265 | L41: =F41-(I41-AK41) -> 10.760265 | M41: 3.51 | N41: 0 | O41: 0 | P41: 0 | Q41: =1056200/325851/1.9835*1.02 -> 1.6668444 | R41: =(1712138/325851/1.9835-T41)*1.04 -> 1.4281965 | S41: 0 | T41: =1.2267*1.04 -> 1.275768 | U41: =M41-(Q41+R41+S41+T41) -> -0.8608089 | V41: 59 | W41: 0 | X41: =M41-N41-P41-O41-Q41-R41-S41-T41-U41+V41+W41 -> 59 | Y41: =X41-AO41 -> 59 | AC41: 1.6 | AE41: 0 | AH41: 32 | AI41: =AI40-AH41 -> 3409 | AK41: =N41+O41+P41+Q41+R41+S41+T41+U41+X41+AE41+AH41 -> 94.51 | AL41: =IF(L41<0,L41*-1,0) -> 0 | AM41: =AK41+AL41 -> 94.51 | AN41: =V41 -> 59 | AO41: 0 | AV41: 0 | AW41: 36 | AX41: 23 | AZ41: =SUM(N41,P41:U41) -> 3.51
A42: =A41+1 -> 28 | B42: 6897.66 | C42: 275031 | D42: =C42-C41 -> -72 | E42: =C42-152000 -> 123031 | F42: =D42/$D$2 -> -36.299471 | G42: 62 | H42: 2.1 | I42: =G42+H42 -> 64.1 | J42: =IF(L42>0,L42,0) -> 0 | K42: =I42+J42 -> 64.1 | L42: =F42-(I42-AK42) -> -5.4694706 | M42: 3.93 | N42: 0 | O42: 0 | P42: 0 | Q42: =956000/325851/1.9835*1.02 -> 1.5087136 | R42: =(1691029/325851/1.9835-T42)*1.04 -> 1.39423 | S42: 0 | T42: =1.2267*1.04 -> 1.275768 | U42: =M42-(Q42+R42+S42+T42) -> -0.24871162 | V42: 59 | W42: 0 | X42: =M42-N42-P42-O42-Q42-R42-S42-T42-U42+V42+W42 -> 59 | Y42: =X42-AO42 -> 59 | AE42: 0 | AH42: 32 | AI42: =AI41-AH42 -> 3377 | AK42: =N42+O42+P42+Q42+R42+S42+T42+U42+X42+AE42+AH42 -> 94.93 | AL42: =IF(L42<0,L42*-1,0) -> 5.4694706 | AM42: =AK42+AL42 -> 100.39947 | AN42: =V42 -> 59 | AO42: 0 | AV42: 0 | AW42: 39 | AX42: 19 | AZ42: =SUM(N42,P42:U42) -> 3.93
...

Sheet JAN
K1: MCPHEE RESERVOIR INFLOW/OUTFLOW TABULATION
A2: AF/cfs CONVERT FACTOR | D2: 1.9835 | K2: JANUARY "2011"
D4: RESERVOIR | I4: INFLOW | X4: OUTFLOW | AP4: ADJUSTMENTS | AW4: WEATHER
A5: DATE | B5: RESERV | C5: RESERV | D5: AC FT | E5: ACTIVE | F5: CONV TO | G5: DOLORES | H5: LOST | I5: RECORD | J5: CALC | K5: TOTAL | L5: CALC | M5: DOLORES TUNNEL | V5: LONE | W5: U | X5: TOTAL | Y5: TOTAL | Z5: MVI | AA5: MVI | AB5: MVI | AC5: TO EX & | AD5: MVI | AE5: DV CR | AF5: D/S SENIOR | AH5: BELOW | AI5: FISH | AJ5: SPILL | AK5: RECORD | AL5: CALC | AM5: TOTAL | AN5: NAR | AO5: MVI | AP5: MVI | AQ5: MVI | AR5: DIST. | AS5: U/S | AT5: TOTTEN | AU5: UTES | AV5: RAIN | AW5: MAX | AX5: MIN | AZ5: TOTAL
A6: DEC | B6: ELEV | D6: CHANGE | E6: CAP | F6: CFS | G6: RIVER | H6: CAN | I6: INFLOW | J6: INFLOW | K6: INFLOW | L6: INF/OTF | M6: TOT DIV | N6: WET | O6: UTE | P6: QUEST | Q6: MWC | R6: CORTEZ | T6: UTE | U6: F-BAY | V6: PINE | W6: LAT | X6: MVI | Y6: MVI | Z6: CALL | AA6: CALL | AB6: APR- | AC6: U/S EX | AD6: PROJ | AE6: CANAL | AF6: MVIC | AG6: PROJ | AH6: MCP | AI6: LEFT | AK6: OTF | AL6: OTF | AM6: OTF | AN6: FILL | AO6: STOCK | AP6: STORED | AQ6: STORED | AR6: CLASS | AS6: USERS | AT6: (FRESH | AU6: FROM | AW6: TMP | AX6: TMP | AZ6: TUNNEL
N7: LAND | O7: F&R | Q7: NON - | R7: NON - | S7: PROJ | T7: PROJ | U7: BAL | X7: WATER | Y7: IRRIG. | Z7: STOR | AA7: SPILLED | AB7: JUNE | AF7: 1.7 | AG7: 1.3 | AP7: Apr - Jun | AQ7: EVAP | AR7: "B" | AS7: EXCH | AT7: WATER) | AU7: DWCD | AZ7: Misc.
Q8: PROJ | R8: PROJ | X8: USED | Y8: WATER | AA8: OR | AB8: (DIV+
R9: 4.2 | Y9: USED | AA9: USED | AB9: CALL)
C10: AC. Ft. | E10: AC FT | G10: CFS | H10: CFS | I10: CFS | J10: CFS | K10: CFS | L10: CFS | M10: CFS | N10: CFS | O10: CFS | P10: CFS | Q10: CFS | R10: CFS | S10: CFS | T10: CFS | U10: CFS | V10: CFS | W10: CFS | X10: 153400 | Y10: 150400 | AB10: 72000 | AC10: CFS | AD10: CFS | AE10: CFS | AF10: CFS | AG10: CFS | AH10: CFS | AI10: CFS | AJ10: CFS | AK10: CFS | AL10: CFS | AM10: CFS | AN10: CFS | AO10: CFS | AP10: CFS | AQ10: AC.FT. | AR10: CFS | AS10: CFS | AT10: CFS | AU10: CFS | AZ10: Outflow
N11: 1.03 | O11: 1.05 | P11: 1.02 | Q11: 1.02 | R11: 1.04 | T11: 1.04 | X11: CFS | Y11: CFS | Z11: CFS | AA11: CFS | AB11: Ac. Ft. | AZ11: CFS
A12: SEASON BAL
A13: YTD | B13: =DEC!B45 -> 6897.77 | C13: =DEC!C45 -> 275429 | D13: =DEC!D54 -> -1962 | E13: =DEC!E54 -> 123429 | F13: =DEC!F53 -> -989.16057 | G13: =DEC!G53 -> 4291 | H13: =DEC!H53 -> 112.98 | I13: =DEC!I53 -> 4403.98 | J13: =DEC!J53 -> 821.74949 | K13: =DEC!K53 -> 5225.7295 | L13: =DEC!L53 -> 234.58943 | M13: =DEC!M53 -> 365.45 | ... Y13: =DEC!Y53 -> 3196.5 | AC13: =DEC!AC53 -> 999.6 | AH13: =DEC!AH53 -> 1983 | AI13: =DEC!AI53 -> 3281 | AK13: =DEC!AK53 -> 5627.73 | AL13: =DEC!AL53 -> 587.16007 | AM13: =DEC!AM53 -> 6214.8901 | AN13: =DEC!AN53 -> 3196.5 | AO13: =DEC!AO53 -> 201.79923 | AV13: =DEC!AV53 -> 3.2 | AZ13: =DEC!AZ53 -> 246.43077
A15: 1 | B15: 6897.73 | C15: 275284 | D15: =C15-C13 -> -145 | E15: =C15-152000 -> 123284 | F15: =D15/$D$2 -> -73.103101 | G15: 67 | H15: 2 | I15: =G15+H15 -> 69 | J15: =IF(L15>0,L15,0) -> 0 | K15: =I15+J15 -> 69 | L15: =F15-(I15-AK15) -> -46.483101 | M15: 4.62 | N15: 0 | O15: 0 | P15: 0 | Q15: =1086700/325851/1.9835*1.02 -> 1.7149781 | R15: =(1746347/325851/1.9835-T15)*1.04 -> 1.5259652 | S15: 0 | T15: =1.1872*1.04 -> 1.234688 | U15: =M15-(Q15+R15+S15+T15) -> 0.14436867 | V15: 59 | W15: 0 | X15: =M15-N15-P15-O15-Q15-R15-S15-T15-U15+V15+W15 -> 59 | Y15: =X15-AO15 -> 59 | AE15: 0 | AH15: 32 | AI15: =AI13-AH15 -> 3249 | AK15: =N15+O15+P15+Q15+R15+S15+T15+U15+X15+AE15+AH15 -> 95.62 | AL15: =IF(L15<0,L15*-1,0) -> 46.483101 | AM15: =AK15+AL15 -> 142.1031 | AN15: =V15 -> 59 | AO15: 0 | AV15: 0 | AW15: 18 | AX15: -15 | AZ15: =SUM(N15,P15:U15) -> 4.62
A16: =A15+1 -> 2 | B16: 6897.7 | C16: 275175 | D16: =C16-C15 -> -109 | E16: =C16-152000 -> 123175 | F16: =D16/$D$2 -> -54.953365 | G16: 69 | H16: 1.8 | I16: =G16+H16 -> 70.8 | J16: =IF(L16>0,L16,0) -> 0 | K16: =I16+J16 -> 70.8 | L16: =F16-(I16-AK16) -> -31.093365 | M16: 3.66 | N16: 0 | O16: 0 | P16: 0 | Q16: =1177300/325851/1.9835*1.02 -> 1.8579587 | R16: =(2922462/325851/1.9835-T16)*1.04 -> 3.4184477 | S16: 0 | T16: =1.1872*1.04 -> 1.234688 | U16: =M16-(Q16+R16+S16+T16) -> -2.8510944 | V16: 59 | W16: 0 | X16: =M16-N16-P16-O16-Q16-R16-S16-T16-U16+V16+W16 -> 59 | Y16: =X16-AO16 -> 59 | AE16: 0 | AH16: 32 | AI16: =AI15-AH16 -> 3217 | AK16: =N16+O16+P16+Q16+R16+S16+T16+U16+X16+AE16+AH16 -> 94.66 | AL16: =IF(L16<0,L16*-1,0) -> 31.093365 | AM16: =AK16+AL16 -> 125.75337 | AN16: =V16 -> 59 | AO16: 0 | AV16: 0 | AW16: 24 | AX16: -18 | AZ16: =SUM(N16,P16:U16) -> 3.66
A17: =A16+1 -> 3 | B17: 6897.68 | C17: 275103 | D17: =C17-C16 -> -72 | E17: =C17-152000 -> 123103 | F17: =D17/$D$2 -> -36.299471 | G17: 58 | H17: 1.8 | I17: =G17+H17 -> 59.8 | J17: =IF(L17>0,L17,0) -> 0 | K17: =I17+J17 -> 59.8 | L17: =F17-(I17-AK17) -> -0.28947063 | M17: 4.81 | N17: 0 | O17: 0 | P17: 0 | Q17: =1290800/325851/1.9835*1.02 -> 2.037079 | R17: =((2039372+2601)/325851/1.9835-T17)*1.04 -> 2.001656 | S17: 0 | T17: =1.1872*1.04 -> 1.234688 | U17: =M17-(Q17+R17+S17+T17) -> -0.46342295 | V17: 59 | W17: 0 | X17: =M17-N17-P17-O17-Q17-R17-S17-T17-U17+V17+W17 -> 59 | Y17: =X17-AO17 -> 59 | AE17: 0 | AH17: 32 | AI17: =AI16-AH17 -> 3185 | AK17: =N17+O17+P17+Q17+R17+S17+T17+U17+X17+AE17+AH17 -> 95.81 | AL17: =IF(L17<0,L17*-1,0) -> 0.28947063 | AM17: =AK17+AL17 -> 96.099471 | AN17: =V17 -> 59 | AO17: 0 | AV17: 0 | AW17: 31 | AX17: -3 | AZ17: =SUM(N17,P17:U17) -> 4.81
