Workbook

Sheet NOV
K1: MC PHEE RESERVOIR IN/OUT FLOW TABULATION
A2: AF/cfs CONVERT FACTOR | D2: 1.983 | L2: NOVEMBER "95"
A4: DATE | B4: RESERV | C4: RESERV | D4: AC FT | E4: ACTIVE | F4: CONV TO | G4: DOLORES | H4: LOST | I4: RECORDED | J4: CALC | K4: TOTAL | L4: CALC | M4: DOLORES TUNNEL | P4: LONE | Q4: U | R4: TOTAL | S4: MVI | T4: DV CR | U4: BELOW | V4: REMAIN | W4: RECORDED | X4: CALC | Y4: TOTAL | Z4: RAIN | AA4: MAX | AB4: MIN | AC4: DATE
A5: "NOV" | B5: ELEV | C5: AC FT | D5: CHANGE | E5: CAP | F5: CFS | G5: RIVER | H5: CANYON | I5: INFLOW | J5: INFLOW | K5: INFLOW | L5: INF/OTF | M5: TOT DIV | N5: UTE F&R | O5: MVI,CTZ,MWC | P5: PINE | Q5: LATERAL | R5: MVI | S5: CALL | T5: CANAL | U5: MC PHEE | V5: RELEASE | W5: OUTFLOW | X5: OUTFLOW | Y5: OUTFLOW | AA5: TMP | AB5: TMP | AC5: "NOV"
A7: SEASON BAL
A8: YTD | B8: 6907.88 | C8: 313585 | V8: =(25400+3900+285)/1.9835 -> 14915.553 | AD8: 13149 | AE8: 17902
A10: 1 | B10: 6907.89 | C10: 313626 | D10: =C10-C8 -> 41 | E10: =C10-152000 -> 161626 | F10: =D10/$D$2 -> 20.675744 | G10: 51.29 | H10: 0 | I10: =G10+H10 -> 51.29 | J10: =IF(L10>0,L10,0) -> 49.665744 | K10: =I10+J10 -> 100.95574 | L10: =F10-(I10-W10) -> 49.665744 | M10: 30.92 | N10: 11 | O10: =M10-N10 -> 19.92 | R10: =SUM(O10:Q10) -> 19.92 | U10: 49.36 | V10: =V8-U10 -> 14866.193 | W10: =N10+R10+T10+U10 -> 80.28 | X10: =IF(L10<0,L10*-1,0) -> 0 | Y10: =W10+X10 -> 80.28 | Z10: 0.03 | AA10: 51 | AB10: 41 | AC10: 1 | AD10: 13243 | AF10: 7883
A11: =A10+1 -> 2 | B11: 6907.87 | C11: 313547 | D11: =C11-C10 -> -79 | E11: =C11-152000 -> 161547 | F11: =D11/$D$2 -> -39.838628 | G11: 53.62 | H11: 0 | I11: =G11+H11 -> 53.62 | J11: =IF(L11>0,L11,0) -> 0 | K11: =I11+J11 -> 53.62 | L11: =F11-(I11-W11) -> -26.768628 | M11: 27.09 | N11: 11 | O11: =M11-N11 -> 16.09 | R11: =SUM(O11:Q11) -> 16.09 | U11: 39.6 | V11: =V10-U11 -> 14826.593 | W11: =N11+R11+T11+U11 -> 66.69 | X11: =IF(L11<0,L11*-1,0) -> 26.768628 | Y11: =W11+X11 -> 93.458628 | Z11: 0 | AA11: 44 | AB11: 29 | AC11: =AC10+1 -> 2 | AD11: 13333 | AE11: 62
A12: =A11+1 -> 3 | B12: 6907.84 | C12: 313429 | D12: =C12-C11 -> -118 | E12: =C12-152000 -> 161429 | F12: =D12/$D$2 -> -59.505799 | G12: 61.66 | H12: 0 | I12: =G12+H12 -> 61.66 | J12: =IF(L12>0,L12,0) -> 0 | K12: =I12+J12 -> 61.66 | L12: =F12-(I12-W12) -> -57.195799 | M12: 24.37 | N12: 10 | O12: =M12-N12 -> 14.37 | R12: =SUM(O12:Q12) -> 14.37 | U12: 39.6 | V12: =V11-U12 -> 14786.993 | W12: =N12+R12+T12+U12 -> 63.97 | X12: =IF(L12<0,L12*-1,0) -> 57.195799 | Y12: =W12+X12 -> 121.1658 | Z12: 0 | AA12: 48 | AB12: 22 | AC12: =AC11+1 -> 3 | AD12: 13456 | AE12: 159
A13: =A12+1 -> 4 | B13: 6907.8 | C13: 313272 | D13: =C13-C12 -> -157 | E13: =C13-152000 -> 161272 | F13: =D13/$D$2 -> -79.17297 | G13: 57.02 | H13: 0 | I13: =G13+H13 -> 57.02 | J13: =IF(L13>0,L13,0) -> 0 | K13: =I13+J13 -> 57.02 | L13: =F13-(I13-W13) -> -72.37297 | M13: 24.22 | N13: 10 | O13: =M13-N13 -> 14.22 | R13: =SUM(O13:Q13) -> 14.22 | U13: 39.6 | V13: =V12-U13 -> 14747.393 | W13: =N13+R13+T13+U13 -> 63.82 | X13: =IF(L13<0,L13*-1,0) -> 72.37297 | Y13: =W13+X13 -> 136.19297 | Z13: 0 | AA13: 51 | AB13: 26 | AC13: =AC12+1 -> 4 | AD13: 13563 | AE13: 263
A14: =A13+1 -> 5 | B14: 6907.78 | C14: 313193 | D14: =C14-C13 -> -79 | E14: =C14-152000 -> 161193 | F14: =D14/$D$2 -> -39.838628 | G14: 48.21 | H14: 0 | I14: =G14+H14 -> 48.21 | J14: =IF(L14>0,L14,0) -> 0 | K14: =I14+J14 -> 48.21 | L14: =F14-(I14-W14) -> -24.228628 | M14: 24.22 | N14: 10 | O14: =M14-N14 -> 14.22 | R14: =SUM(O14:Q14) -> 14.22 | U14: 39.6 | V14: =V13-U14 -> 14707.793 | W14: =N14+R14+T14+U14 -> 63.82 | X14: =IF(L14<0,L14*-1,0) -> 24.228628 | Y14: =W14+X14 -> 88.048628 | Z14: 0 | AA14: 55 | AB14: 29 | AC14: =AC13+1 -> 5 | AD14: 13678 | AE14: 367
A15: =A14+1 -> 6 | B15: 6907.8 | C15: 313272 | D15: =C15-C14 -> 79 | E15: =C15-152000 -> 161272 | F15: =D15/$D$2 -> 39.838628 | G15: 60.63 | H15: 0 | I15: =G15+H15 -> 60.63 | J15: =IF(L15>0,L15,0) -> 41.918628 | K15: =I15+J15 -> 102.54863 | L15: =F15-(I15-W15) -> 41.918628 | M15: 23.11 | N15: 10 | O15: =M15-N15 -> 13.11 | R15: =SUM(O15:Q15) -> 13.11 | U15: 39.6 | V15: =V14-U15 -> 14668.193 | W15: =N15+R15+T15+U15 -> 62.71 | X15: =IF(L15<0,L15*-1,0) -> 0 | Y15: =W15+X15 -> 62.71 | Z15: 0 | AA15: 49 | AB15: 35 | AC15: =AC14+1 -> 6 | AD15: 13812 | AE15: 469
A16: =A15+1 -> 7 | B16: 6907.8 | C16: 313272 | D16: =C16-C15 -> 0 | E16: =C16-152000 -> 161272 | F16: =D16/$D$2 -> 0 | G16: 60.25 | H16: 0 | I16: =G16+H16 -> 60.25 | J16: =IF(L16>0,L16,0) -> 1.71 | K16: =I16+J16 -> 61.96 | L16: =F16-(I16-W16) -> 1.71 | M16: 22.36 | N16: 19 | O16: =M16-N16 -> 3.36 | R16: =SUM(O16:Q16) -> 3.36 | U16: 39.6 | V16: =V15-U16 -> 14628.593 | W16: =N16+R16+T16+U16 -> 61.96 | X16: =IF(L16<0,L16*-1,0) -> 0 | Y16: =W16+X16 -> 61.96 | Z16: 0 | AA16: 55 | AB16: 25 | AC16: =AC15+1 -> 7 | AD16: 13968 | AE16: 587
A17: =A16+1 -> 8 | B17: 6907.77 | C17: 313155 | D17: =C17-C16 -> -117 | E17: =C17-152000 -> 161155 | F17: =D17/$D$2 -> -59.001513 | G17: 73 | H17: 0 | I17: =G17+H17 -> 73 | J17: =IF(L17>0,L17,0) -> 0 | K17: =I17+J17 -> 73 | L17: =F17-(I17-W17) -> -69.891513 | M17: 22.51 | N17: 11 | O17: =M17-N17 -> 11.51 | R17: =SUM(O17:Q17) -> 11.51 | U17: 39.6 | V17: =V16-U17 -> 14588.993 | W17: =N17+R17+T17+U17 -> 62.11 | X17: =IF(L17<0,L17*-1,0) -> 69.891513 | Y17: =W17+X17 -> 132.00151 | Z17: 0 | AA17: 63 | AB17: 30 | AC17: =AC16+1 -> 8 | AD17: 14117 | AE17: 707
A18: =A17+1 -> 9 | B18: 6907.77 | C18: 313155 | D18: =C18-C17 -> 0 | E18: =C18-152000 -> 161155 | F18: =D18/$D$2 -> 0 | G18: 70.58 | H18: 0 | I18: =G18+H18 -> 70.58 | J18: =IF(L18>0,L18,0) -> 0 | K18: =I18+J18 -> 70.58 | L18: =F18-(I18-W18) -> -9.38 | M18: 21.6 | N18: 6 | O18: =M18-N18 -> 15.6 | R18: =SUM(O18:Q18) -> 15.6 | U18: 39.6 | V18: =V17-U18 -> 14549.393 | W18: =N18+R18+T18+U18 -> 61.2 | X18: =IF(L18<0,L18*-1,0) -> 9.38 | Y18: =W18+X18 -> 70.58 | Z18: 0 | AA18: 40 | AB18: 31 | AC18: =AC17+1 -> 9 | AD18: 14264 | AE18: 826
A19: =A18+1 -> 10 | B19: 6907.79 | C19: 313233 | D19: =C19-C18 -> 78 | E19: =C19-152000 -> 161233 | F19: =D19/$D$2 -> 39.334342 | G19: 60.61 | H19: 0 | I19: =G19+H19 -> 60.61 | J19: =IF(L19>0,L19,0) -> 40.204342 | K19: =I19+J19 -> 100.81434 | L19: =F19-(I19-W19) -> 40.204342 | M19: 21.6 | N19: 6 | O19: =M19-N19 -> 15.6 | R19: =SUM(O19:Q19) -> 15.6 | U19: 39.88 | V19: =V18-U19 -> 14509.513 | W19: =N19+R19+T19+U19 -> 61.48 | X19: =IF(L19<0,L19*-1,0) -> 0 | Y19: =W19+X19 -> 61.48 | Z19: 0.14 | AA19: 43 | AB19: 33 | AC19: =AC18+1 -> 10 | AD19: 14413 | AE19: 964
A20: =A19+1 -> 11 | B20: 6907.75 | C20: 313077 | D20: =C20-C19 -> -156 | E20: =C20-152000 -> 161077 | F20: =D20/$D$2 -> -78.668684 | G20: 62.74 | H20: 0 | I20: =G20+H20 -> 62.74 | J20: =IF(L20>0,L20,0) -> 0 | K20: =I20+J20 -> 62.74 | L20: =F20-(I20-W20) -> -80.208684 | M20: 21.6 | N20: 14 | O20: =M20-N20 -> 7.6 | R20: =SUM(O20:Q20) -> 7.6 | U20: 39.6 | V20: =V19-U20 -> 14469.913 | W20: =N20+R20+T20+U20 -> 61.2 | X20: =IF(L20<0,L20*-1,0) -> 80.208684 | Y20: =W20+X20 -> 141.40868 | Z20: 0 | AA20: 58 | AB20: 21 | AC20: =AC19+1 -> 11 | AD20: 14571 | AE20: 1065
A21: =A20+1 -> 12 | B21: 6907.79 | C21: 313233 | D21: =C21-C20 -> 156 | E21: =C21-152000 -> 161233 | F21: =D21/$D$2 -> 78.668684 | G21: 89.9 | H21: 0 | I21: =G21+H21 -> 89.9 | J21: =IF(L21>0,L21,0) -> 50.048684 | K21: =I21+J21 -> 139.94868 | L21: =F21-(I21-W21) -> 50.048684 | M21: 21.6 | N21: 5.5 | O21: =M21-N21 -> 16.1 | R21: =SUM(O21:Q21) -> 16.1 | U21: 39.68 | V21: =V20-U21 -> 14430.233 | W21: =N21+R21+T21+U21 -> 61.28 | X21: =IF(L21<0,L21*-1,0) -> 0 | Y21: =W21+X21 -> 61.28 | Z21: 0 | AA21: 58 | AB21: 28 | AC21: =AC20+1 -> 12 | AD21: 14696 | AE21: 1185
A22: =A21+1 -> 13 | B22: 6907.79 | C22: 313233 | D22: =C22-C21 -> 0 | E22: =C22-152000 -> 161233 | F22: =D22/$D$2 -> 0 | G22: 95.72 | H22: 0 | I22: =G22+H22 -> 95.72 | J22: =IF(L22>0,L22,0) -> 0 | K22: =I22+J22 -> 95.72 | L22: =F22-(I22-W22) -> -34.25 | M22: 21.87 | N22: 0.5 | O22: =M22-N22 -> 21.37 | R22: =SUM(O22:Q22) -> 21.37 | U22: 39.6 | V22: =V21-U22 -> 14390.633 | W22: =N22+R22+T22+U22 -> 61.47 | X22: =IF(L22<0,L22*-1,0) -> 34.25 | Y22: =W22+X22 -> 95.72 | Z22: 0 | AA22: 60 | AB22: 34 | AC22: =AC21+1 -> 13 | AD22: 14771 | AE22: 1299
A23: =A22+1 -> 14 | B23: 6907.76 | C23: 313115 | D23: =C23-C22 -> -118 | E23: =C23-152000 -> 161115 | F23: =D23/$D$2 -> -59.505799 | G23: 76.14 | H23: 0 | I23: =G23+H23 -> 76.14 | J23: =IF(L23>0,L23,0) -> 0 | K23: =I23+J23 -> 76.14 | L23: =F23-(I23-W23) -> -75.095799 | M23: 20.9 | O23: =M23-N23 -> 20.9 | R23: =SUM(O23:Q23) -> 20.9 | U23: 39.65 | V23: =V22-U23 -> 14350.983 | W23: =N23+R23+T23+U23 -> 60.55 | X23: =IF(L23<0,L23*-1,0) -> 75.095799 | Y23: =W23+X23 -> 135.6458 | Z23: 0 | AA23: 68 | AB23: 37 | AC23: =AC22+1 -> 14 | AD23: 14842 | AE23: 1407
A24: =A23+1 -> 15 | B24: 6907.76 | C24: 313115 | D24: =C24-C23 -> 0 | E24: =C24-152000 -> 161115 | F24: =D24/$D$2 -> 0 | G24: 59.43 | H24: FROZE | I24: =G24 -> 59.43 | J24: =IF(L24>0,L24,0) -> 0 | K24: =I24+J24 -> 59.43 | L24: =F24-(I24-W24) -> -1.16 | M24: 18.67 | O24: =M24-N24 -> 18.67 | R24: =SUM(O24:Q24) -> 18.67 | U24: 39.6 | V24: =V23-U24 -> 14311.383 | W24: =N24+R24+T24+U24 -> 58.27 | X24: =IF(L24<0,L24*-1,0) -> 1.16 | Y24: =W24+X24 -> 59.43 | Z24: 0 | AA24: 64 | AB24: 35 | AC24: =AC23+1 -> 15 | AD24: 14927 | AE24: 1516
A25: =A24+1 -> 16 | B25: 6907.74 | C25: 313038 | D25: =C25-C24 -> -77 | E25: =C25-152000 -> 161038 | F25: =D25/$D$2 -> -38.830055 | G25: 81.2 | H25: 0 | I25: =G25+H25 -> 81.2 | J25: =IF(L25>0,L25,0) -> 0 | K25: =I25+J25 -> 81.2 | L25: =F25-(I25-W25) -> -61.580055 | M25: 18.85 | O25: =M25-N25 -> 18.85 | R25: =SUM(O25:Q25) -> 18.85 | U25: 39.6 | V25: =V24-U25 -> 14271.783 | W25: =N25+R25+T25+U25 -> 58.45 | X25: =IF(L25<0,L25*-1,0) -> 61.580055 | Y25: =W25+X25 -> 120.03006 | Z25: 0 | AA25: 60 | AB25: 34 | AC25: =AC24+1 -> 16 | AD25: 15009 | AE25: 1615
A26: =A25+1 -> 17 | B26: 6907.73 | C26: 312998 | D26: =C26-C25 -> -40 | E26: =C26-152000 -> 160998 | F26: =D26/$D$2 -> -20.171457 | G26: 45.6 | H26: 0 | I26: =G26+H26 -> 45.6 | J26: =IF(L26>0,L26,0) -> 0 | K26: =I26+J26 -> 45.6 | L26: =F26-(I26-W26) -> -7.0714574 | M26: 19.1 | O26: =M26-N26 -> 19.1 | R26: =SUM(O26:Q26) -> 19.1 | U26: 39.6 | V26: =V25-U26 -> 14232.183 | W26: =N26+R26+T26+U26 -> 58.7 | X26: =IF(L26<0,L26*-1,0) -> 7.0714574 | Y26: =W26+X26 -> 65.771457 | Z26: 0 | AA26: 62 | AB26: 32 | AC26: =AC25+1 -> 17 | AD26: 15112 | AE26: 1714
A27: =A26+1 -> 18 | B27: 6907.73 | C27: 312998 | D27: =C27-C26 -> 0 | E27: =C27-152000 -> 160998 | F27: =D27/$D$2 -> 0 | G27: 98.9 | H27: 0 | I27: =G27+H27 -> 98.9 | J27: =IF(L27>0,L27,0) -> 0 | K27: =I27+J27 -> 98.9 | L27: =F27-(I27-W27) -> -40.12 | M27: 19.1 | O27: =M27-N27 -> 19.1 | R27: =SUM(O27:Q27) -> 19.1 | U27: 39.68 | V27: =V26-U27 -> 14192.503 | W27: =N27+R27+T27+U27 -> 58.78 | X27: =IF(L27<0,L27*-1,0) -> 40.12 | Y27: =W27+X27 -> 98.9 | Z27: 0 | AA27: 61 | AB27: 33 | AC27: =AC26+1 -> 18 | AD27: 15213 | AE27: 1812
A28: =A27+1 -> 19 | B28: 6907.69 | C28: 312841 | D28: =C28-C27 -> -157 | E28: =C28-152000 -> 160841 | F28: =D28/$D$2 -> -79.17297 | G28: 63.6 | H28: 0 | I28: =G28+H28 -> 63.6 | J28: =IF(L28>0,L28,0) -> 0 | K28: =I28+J28 -> 63.6 | L28: =F28-(I28-W28) -> -84.03297 | M28: 19.1 | O28: =M28-N28 -> 19.1 | R28: =SUM(O28:Q28) -> 19.1 | U28: 39.64 | V28: =V27-U28 -> 14152.863 | W28: =N28+R28+T28+U28 -> 58.74 | X28: =IF(L28<0,L28*-1,0) -> 84.03297 | Y28: =W28+X28 -> 142.77297 | Z28: 0 | AA28: 62 | AB28: 33 | AC28: =AC27+1 -> 19 | AD28: 15295 | AE28: 1909
A29: =A28+1 -> 20 | B29: 6907.7 | C29: 312881 | D29: =C29-C28 -> 40 | E29: =C29-152000 -> 160881 | F29: =D29/$D$2 -> 20.171457 | G29: 117.6 | H29: 0 | I29: =G29+H29 -> 117.6 | J29: =IF(L29>0,L29,0) -> 0 | K29: =I29+J29 -> 117.6 | L29: =F29-(I29-W29) -> -38.728543 | M29: 19.1 | O29: =M29-N29 -> 19.1 | R29: =SUM(O29:Q29) -> 19.1 | U29: 39.6 | V29: =V28-U29 -> 14113.263 | W29: =N29+R29+T29+U29 -> 58.7 | X29: =IF(L29<0,L29*-1,0) -> 38.728543 | Y29: =W29+X29 -> 97.428543 | Z29: 0 | AA29: 61 | AB29: 31 | AC29: =AC28+1 -> 20 | AD29: 15367 | AE29: 2006
A30: =A29+1 -> 21 | B30: 6907.72 | C30: 312960 | D30: =C30-C29 -> 79 | E30: =C30-152000 -> 160960 | F30: =D30/$D$2 -> 39.838628 | G30: 62.2 | H30: 0 | I30: =G30+H30 -> 62.2 | J30: =IF(L30>0,L30,0) -> 31.568628 | K30: =I30+J30 -> 93.768628 | L30: =F30-(I30-W30) -> 31.568628 | M30: 14.25 | O30: =M30-N30 -> 14.25 | R30: =SUM(O30:Q30) -> 14.25 | U30: 39.68 | V30: =V29-U30 -> 14073.583 | W30: =N30+R30+T30+U30 -> 53.93 | X30: =IF(L30<0,L30*-1,0) -> 0 | Y30: =W30+X30 -> 53.93 | Z30: 0 | AA30: 61 | AB30: 29 | AC30: =AC29+1 -> 21 | AD30: 15445 | AE30: 2106 | AF30: 273.4
A31: =A30+1 -> 22 | B31: 6907.72 | C31: 312960 | D31: =C31-C30 -> 0 | E31: =C31-152000 -> 160960 | F31: =D31/$D$2 -> 0 | G31: 43.4 | H31: 0 | I31: =G31+H31 -> 43.4 | J31: =IF(L31>0,L31,0) -> 0.57 | K31: =I31+J31 -> 43.97 | L31: =F31-(I31-W31) -> 0.57 | M31: 4.37 | O31: =M31-N31 -> 4.37 | R31: =SUM(O31:Q31) -> 4.37 | U31: 39.6 | V31: =V30-U31 -> 14033.983 | W31: =N31+R31+T31+U31 -> 43.97 | X31: =IF(L31<0,L31*-1,0) -> 0 | Y31: =W31+X31 -> 43.97 | Z31: 0 | AA31: 62 | AB31: 31 | AC31: =AC30+1 -> 22 | AD31: 15524 | AE31: 2203 | AF31: 249.63
A32: =A31+1 -> 23 | B32: 6907.71 | C32: 312920 | D32: =C32-C31 -> -40 | E32: =C32-152000 -> 160920 | F32: =D32/$D$2 -> -20.171457 | G32: 45.2 | H32: 0 | I32: 45.1 | J32: =IF(L32>0,L32,0) -> 0 | K32: =I32+J32 -> 45.1 | L32: =F32-(I32-W32) -> -21.611457 | M32: 4.06 | O32: =M32-N32 -> 4.06 | R32: =SUM(O32:Q32) -> 4.06 | U32: 39.6 | V32: =V31-U32 -> 13994.383 | W32: =N32+R32+T32+U32 -> 43.66 | X32: =IF(L32<0,L32*-1,0) -> 21.611457 | Y32: =W32+X32 -> 65.271457 | Z32: 0 | AA32: 52 | AB32: 32 | AC32: =AC31+1 -> 23 | AD32: 15607 | AE32: 2299 | AF32: 243.94
A33: =A32+1 -> 24 | B33: 6907.71 | C33: 312920 | D33: =C33-C32 -> 0 | E33: =C33-152000 -> 160920 | F33: =D33/$D$2 -> 0 | G33: 44.3 | H33: 0 | I33: =G33+H33 -> 44.3 | J33: =IF(L33>0,L33,0) -> 0 | K33: =I33+J33 -> 44.3 | L33: =F33-(I33-W33) -> -0.6 | M33: 4.06 | O33: =M33-N33 -> 4.06 | R33: =SUM(O33:Q33) -> 4.06 | U33: 39.64 | V33: =V32-U33 -> 13954.743 | W33: =N33+R33+T33+U33 -> 43.7 | X33: =IF(L33<0,L33*-1,0) -> 0.6 | Y33: =W33+X33 -> 44.3 | Z33: 0 | AA33: 58 | AB33: 21 | AC33: =AC32+1 -> 24 | AD33: 15666 | AE33: 2395 | AF33: 243.15
A34: =A33+1 -> 25 | B34: 6907.72 | C34: 312960 | D34: =C34-C33 -> 40 | E34: =C34-152000 -> 160960 | F34: =D34/$D$2 -> 20.171457 | G34: 27.6 | H34: 0 | I34: =G34+H34 -> 27.6 | J34: =IF(L34>0,L34,0) -> 36.231457 | K34: =I34+J34 -> 63.831457 | L34: =F34-(I34-W34) -> 36.231457 | M34: 4.06 | O34: =M34-N34 -> 4.06 | R34: =SUM(O34:Q34) -> 4.06 | U34: 39.6 | V34: =V33-U34 -> 13915.143 | W34: =N34+R34+T34+U34 -> 43.66 | X34: =IF(L34<0,L34*-1,0) -> 0 | Y34: =W34+X34 -> 43.66 | Z34: 0 | AA34: 58 | AB34: 22 | AC34: =AC33+1 -> 25 | AD34: 15726 | AE34: 2491 | AF34: 242.11
A35: =A34+1 -> 26 | B35: 6907.72 | C35: 312960 | D35: =C35-C34 -> 0 | E35: =C35-152000 -> 160960 | F35: =D35/$D$2 -> 0 | G35: 44.5 | H35: 0 | I35: =G35+H35 -> 44.5 | J35: =IF(L35>0,L35,0) -> 0 | K35: =I35+J35 -> 44.5 | L35: =F35-(I35-W35) -> -0.84 | M35: 4.06 | O35: =M35-N35 -> 4.06 | R35: =SUM(O35:Q35) -> 4.06 | U35: 39.6 | V35: =V34-U35 -> 13875.543 | W35: =N35+R35+T35+U35 -> 43.66 | X35: =IF(L35<0,L35*-1,0) -> 0.84 | Y35: =W35+X35 -> 44.5 | Z35: 0 | AA35: 60 | AB35: 28 | AC35: =AC34+1 -> 26 | AD35: 15781 | AE35: 2589 | AF35: 244.72
A36: =A35+1 -> 27 | B36: 6907.71 | C36: 312920 | D36: =C36-C35 -> -40 | E36: =C36-152000 -> 160920 | F36: =D36/$D$2 -> -20.171457 | G36: 61.7 | H36: 0 | I36: =G36+H36 -> 61.7 | J36: =IF(L36>0,L36,0) -> 0 | K36: =I36+J36 -> 61.7 | L36: =F36-(I36-W36) -> -38.171457 | M36: 4.06 | O36: =M36-N36 -> 4.06 | R36: =SUM(O36:Q36) -> 4.06 | U36: 39.64 | V36: =V35-U36 -> 13835.903 | W36: =N36+R36+T36+U36 -> 43.7 | X36: =IF(L36<0,L36*-1,0) -> 38.171457 | Y36: =W36+X36 -> 81.871457 | Z36: 0 | AA36: 35 | AB36: 18 | AC36: =AC35+1 -> 27 | AD36: 15841 | AE36: 2686 | AF36: 252.4
A37: =A36+1 -> 28 | B37: 6907.69 | C37: 312841 | D37: =C37-C36 -> -79 | E37: =C37-152000 -> 160841 | F37: =D37/$D$2 -> -39.838628 | G37: 27 | H37: 0 | I37: =G37+H37 -> 27 | J37: =IF(L37>0,L37,0) -> 0 | K37: =I37+J37 -> 27 | L37: =F37-(I37-W37) -> -23.178628 | M37: 4.06 | O37: =M37-N37 -> 4.06 | R37: =SUM(O37:Q37) -> 4.06 | U37: 39.6 | V37: =V36-U37 -> 13796.303 | W37: =N37+R37+T37+U37 -> 43.66 | X37: =IF(L37<0,L37*-1,0) -> 23.178628 | Y37: =W37+X37 -> 66.838628 | Z37: 0 | AA37: 40 | AB37: 14 | AC37: =AC36+1 -> 28 | AD37: 804 | AE37: 2779 | AF37: 254.14
A38: =A37+1 -> 29 | B38: 6707.69 | C38: 312841 | D38: =C38-C37 -> 0 | E38: =C38-152000 -> 160841 | F38: =D38/$D$2 -> 0 | G38: 7.1 | H38: 0 | I38: =G38+H38 -> 7.1 | J38: =IF(L38>0,L38,0) -> 36.41 | K38: =I38+J38 -> 43.51 | L38: =F38-(I38-W38) -> 36.41 | M38: 3.91 | O38: =M38-N38 -> 3.91 | R38: =SUM(O38:Q38) -> 3.91 | U38: 39.6 | V38: =V37-U38 -> 13756.703 | W38: =N38+R38+T38+U38 -> 43.51 | X38: =IF(L38<0,L38*-1,0) -> 0 | Y38: =W38+X38 -> 43.51 | Z38: 0 | AA38: 52 | AB38: 23 | AC38: =AC37+1 -> 29 | AD38: 862 | AE38: 2872 | AF38: 256.51
A39: 30 | B39: 6907.7 | C39: 312881 | D39: =C39-C38 -> 40 | E39: =C39-152000 -> 160881 | F39: =D39/$D$2 -> 20.171457 | G39: 44 | H39: 0 | I39: =G39+H39 -> 44 | J39: =IF(L39>0,L39,0) -> 19.491457 | K39: =I39+J39 -> 63.491457 | L39: =F39-(I39-W39) -> 19.491457 | M39: 3.72 | O39: =M39-N39 -> 3.72 | R39: =SUM(O39:Q39) -> 3.72 | U39: 39.6 | V39: =V38-U39 -> 13717.103 | W39: =N39+R39+T39+U39 -> 43.32 | X39: =IF(L39<0,L39*-1,0) -> 0 | Y39: =W39+X39 -> 43.32 | Z39: 0 | AA39: 56 | AB39: 27 | AC39: 30 | AD39: 927 | AE39: 2965 | AF39: 248.45
AA40: 73
A41: MONTH / CFS | F41: =SUM(F10:F39) -> -355.01765 | G41: =SUM(G10:G39) -> 1794.7 | H41: =SUM(H10:H39) -> 0 | I41: =SUM(I10:I39) -> 1794.6 | J41: =SUM(J10:J39) -> 307.81894 | K41: =SUM(K10:K39) -> 2102.4189 | L41: =SUM(L10:L39) -> -458.66765 | M41: =SUM(M10:M39) -> 492.5 | ... R41: =SUM(R10:R39) -> 368.5 | T41: =SUM(T10:T39) -> 0 | U41: =SUM(U10:U39) -> 1198.45 | W41: =SUM(W10:W39) -> 1690.95 | X41: =SUM(X10:X39) -> 766.48659 | Y41: =SUM(Y10:Y39) -> 2457.4366 | Z41: =SUM(Z10:Z39) -> 0.17 | AA41: =AVERAGE(AA10:AA39) -> 54.9 | AB41: =AVERAGE(AB10:AB39) -> 28.8
A42: MONTH / AF | D42: =SUM(D10:D39) -> -704 | F42: =F41*$D$2 -> -704 | G42: =G41*$D$2 -> 3558.8901 | H42: =H41*$D$2 -> 0 | I42: =I41*$D$2 -> 3558.6918 | J42: =J41*$D$2 -> 610.40496 | K42: =K41*$D$2 -> 4169.0968 | L42: =L41*$D$2 -> -909.53795 | M42: =M41*$D$2 -> 976.6275 | ... R42: =R41*$D$2 -> 730.7355 | T42: =T41*$D$2 -> 0 | U42: =U41*$D$2 -> 2376.5264 | W42: =W41*$D$2 -> 3353.1539 | X42: =X41*$D$2 -> 1519.9429 | Y42: =Y41*$D$2 -> 4873.0968 | AA42: =MAX(AA10:AA39) -> 68 | AB42: =MAX(AB10:AB39) -> 41 | AC42: HI
A44: SEASON / CFS | AA44: =MIN(AA10:AA39) -> 35 | AB44: =MIN(AB10:AB39) -> 14 | AC44: LO
...

Sheet DEC
K1: MC PHEE RESERVOIR IN/OUT FLOW TABULATION
A2: AF/cfs CONVERT FACTOR | D2: 1.983 | K2: DECEMBER "95"
A4: DATE | B4: RESERV | C4: RESERV | D4: AC FT | E4: ACTIVE | F4: CONV TO | G4: DOLORES | H4: LOST | I4: RECORDED | J4: CALC | K4: TOTAL | L4: CALC | M4: DOLORES TUNNEL | P4: LONE | Q4: U | R4: TOTAL | S4: MVI | T4: DV CR | U4: BELOW | V4: REMAIN | W4: RECORDED | X4: CALC | Y4: TOTAL | Z4: RAIN | AA4: MAX | AB4: MIN | AC4: DATE
A5: "DEC" | B5: ELEV | C5: AC FT | D5: CHANGE | E5: CAP | F5: CFS | G5: RIVER | H5: CANYON | I5: INFLOW | J5: INFLOW | K5: INFLOW | L5: INF/OTF | M5: TOT DIV | N5: UTE F&R | O5: MVI,CTZ | P5: PINE | Q5: LATERAL | R5: MVI | S5: CALL | T5: CANAL | U5: MC PHEE | V5: RELEASE | W5: OUTFLOW | X5: OUTFLOW | Y5: OUTFLOW | AA5: TMP | AB5: TMP | AC5: "DEC"
AD6: 741 | AE6: 742
A7: SEASON BAL
A8: YTD | B8: {=NOV!$B$39:$C$39} -> 6907.7 | C8: 312881 | D8: {=NOV!$D$48:$E$48} -> -704 | E8: 160881 | F8: {=NOV!$F$47:$Z$47} -> -355.01765 | G8: 1794.7 | H8: 0 | I8: 1794.6 | J8: 307.81894 | K8: 2102.4189 | L8: -458.66765 | M8: 492.5 | N8: 0 | O8: 0 | P8: 0 | Q8: 0 | R8: 368.5 | S8: 0 | T8: 0 | U8: 1198.45 | V8: 13717.103 | W8: 1690.95 | X8: 766.48659 | Y8: 2457.4366 | Z8: 0.17 | AD8: 285 | AE8: 251 | AF8: 1207.63
A10: 1 | B10: 6907.7 | C10: 312881 | D10: =C10-C8 -> 0 | E10: =C10-152000 -> 160881 | F10: =D10/$D$2 -> 0 | G10: 130.44299 | H10: 0 | I10: =G10+H10 -> 130.44299 | J10: =IF(L10>0,L10,0) -> 0 | K10: =I10+J10 -> 130.44299 | L10: =F10-(I10-W10) -> -87.122985 | M10: 3.72 | N10: 0 | O10: =M10-N10 -> 3.72 | P10: 0 | Q10: 0 | R10: =SUM(O10:Q10) -> 3.72 | T10: 0 | U10: 39.6 | V10: =V8-U10 -> 13677.503 | W10: =R10+T10+N10+U10 -> 43.32 | X10: =IF(L10<0,L10*-1,0) -> 87.122985 | Y10: =W10+X10 -> 130.44299 | Z10: 0 | AA10: 61 | AB10: 29 | AC10: 1 | AD10: 303 | AE10: 273 | AF10: 1256.86
A11: =A10+1 -> 2 | B11: 6907.7 | C11: 312881 | D11: =C11-C10 -> 0 | E11: =C11-152000 -> 160881 | F11: =D11/$D$2 -> 0 | G11: 39.47 | H11: 0 | I11: =G11+H11 -> 39.47 | J11: =IF(L11>0,L11,0) -> 3.85 | K11: =I11+J11 -> 43.32 | L11: =F11-(I11-W11) -> 3.85 | M11: 3.72 | N11: 0 | O11: =M11-N11 -> 3.72 | P11: 0 | Q11: 0 | R11: =SUM(O11:Q11) -> 3.72 | T11: 0 | U11: 39.6 | V11: =V10-U11 -> 13637.903 | W11: =R11+T11+N11+U11 -> 43.32 | X11: =IF(L11<0,L11*-1,0) -> 0 | Y11: =W11+X11 -> 43.32 | Z11: 0 | AA11: 60 | AB11: 28 | AC11: =AC10+1 -> 2 | AD11: 306 | AE11: 300 | AF11: 1306.42
A12: =A11+1 -> 3 | B12: 6907.7 | C12: 312881 | D12: =C12-C11 -> 0 | E12: =C12-152000 -> 160881 | F12: =D12/$D$2 -> 0 | G12: 39.6 | H12: 0 | I12: =G12+H12 -> 39.6 | J12: =IF(L12>0,L12,0) -> 3.72 | K12: =I12+J12 -> 43.32 | L12: =F12-(I12-W12) -> 3.72 | M12: 3.72 | N12: 0 | O12: =M12-N12 -> 3.72 | P12: 0 | Q12: 0 | R12: =SUM(O12:Q12) -> 3.72 | T12: 0 | U12: 39.6 | V12: =V11-U12 -> 13598.303 | W12: =R12+T12+N12+U12 -> 43.32 | X12: =IF(L12<0,L12*-1,0) -> 0 | Y12: =W12+X12 -> 43.32 | Z12: 0 | AA12: 58 | AB12: 29 | AC12: =AC11+1 -> 3 | AD12: 316 | AE12: 341 | AF12: 1355.74
A13: =A12+1 -> 4 | B13: 6907.71 | C13: 312920 | D13: =C13-C12 -> 39 | E13: =C13-152000 -> 160920 | F13: =D13/$D$2 -> 19.667171 | G13: 75.434337 | H13: 0 | I13: =G13+H13 -> 75.434337 | J13: =IF(L13>0,L13,0) -> 0 | K13: =I13+J13 -> 75.434337 | L13: =F13-(I13-W13) -> -11.527166 | M13: 4.64 | N13: 0 | O13: =M13-N13 -> 4.64 | P13: 0 | Q13: 0 | R13: =SUM(O13:Q13) -> 4.64 | T13: 0 | U13: 39.6 | V13: =V12-U13 -> 13558.703 | W13: =R13+T13+N13+U13 -> 44.24 | X13: =IF(L13<0,L13*-1,0) -> 11.527166 | Y13: =W13+X13 -> 55.767166 | Z13: 0 | AA13: 54 | AB13: 32 | AC13: =AC12+1 -> 4 | AD13: 316 | AE13: 395 | AF13: 1405.31
A14: =A13+1 -> 5 | B14: 6907.7 | C14: 312881 | D14: =C14-C13 -> -39 | E14: =C14-152000 -> 160881 | F14: =D14/$D$2 -> -19.667171 | G14: 236.836 | H14: 0 | I14: =G14+H14 -> 236.836 | J14: =IF(L14>0,L14,0) -> 0 | K14: =I14+J14 -> 236.836 | L14: =F14-(I14-W14) -> -211.55317 | M14: 5.35 | N14: 0 | O14: =M14-N14 -> 5.35 | P14: 0 | Q14: 0 | R14: =SUM(O14:Q14) -> 5.35 | T14: 0 | U14: 39.6 | V14: =V13-U14 -> 13519.103 | W14: =R14+T14+N14+U14 -> 44.95 | X14: =IF(L14<0,L14*-1,0) -> 211.55317 | Y14: =W14+X14 -> 256.50317 | Z14: 0 | AA14: 58 | AB14: 31 | AC14: =AC13+1 -> 5 | AD14: 316 | AE14: 466 | AF14: 1437.16
A15: =A14+1 -> 6 | B15: 6907.69 | C15: 312841 | D15: =C15-C14 -> -40 | E15: =C15-152000 -> 160841 | F15: =D15/$D$2 -> -20.171457 | G15: 40.05 | H15: 0 | I15: =G15+H15 -> 40.05 | J15: =IF(L15>0,L15,0) -> 0 | K15: =I15+J15 -> 40.05 | L15: =F15-(I15-W15) -> -14.731457 | M15: 5.89 | N15: 0 | O15: =M15-N15 -> 5.89 | P15: 0 | Q15: 0 | R15: =SUM(O15:Q15) -> 5.89 | T15: 0 | U15: 39.6 | V15: =V14-U15 -> 13479.503 | W15: =R15+T15+N15+U15 -> 45.49 | X15: =IF(L15<0,L15*-1,0) -> 14.731457 | Y15: =W15+X15 -> 60.221457 | Z15: 0 | AA15: 54 | AB15: 32 | AC15: =AC14+1 -> 6 | AD15: 325 | AE15: 538 | AF15: 1467.01
A16: =A15+1 -> 7 | B16: 6907.69 | C16: 312841 | D16: =C16-C15 -> 0 | E16: =C16-152000 -> 160841 | F16: =D16/$D$2 -> 0 | G16: 129.95727 | H16: 0 | I16: =G16+H16 -> 129.95727 | J16: =IF(L16>0,L16,0) -> 0 | K16: =I16+J16 -> 129.95727 | L16: =F16-(I16-W16) -> -85.157272 | M16: 5.2 | N16: 0 | O16: =M16-N16 -> 5.2 | P16: 0 | Q16: 0 | R16: =SUM(O16:Q16) -> 5.2 | T16: 0 | U16: 39.6 | V16: =V15-U16 -> 13439.903 | W16: =R16+T16+N16+U16 -> 44.8 | X16: =IF(L16<0,L16*-1,0) -> 85.157272 | Y16: =W16+X16 -> 129.95727 | Z16: 0 | AA16: 53 | AB16: 31 | AC16: =AC15+1 -> 7 | AD16: 342 | AE16: 618 | AF16: 1496.64
A17: =A16+1 -> 8 | B17: 6907.69 | C17: 312841 | D17: =C17-C16 -> 0 | E17: =C17-152000 -> 160841 | F17: =D17/$D$2 -> 0 | G17: 3.8556631 | H17: 0 | I17: =G17+H17 -> 3.8556631 | J17: =IF(L17>0,L17,0) -> 40.504337 | K17: =I17+J17 -> 44.36 | L17: =F17-(I17-W17) -> 40.504337 | M17: 4.76 | N17: 0 | O17: =M17-N17 -> 4.76 | P17: 0 | Q17: 0 | R17: =SUM(O17:Q17) -> 4.76 | T17: 0 | U17: 39.6 | V17: =V16-U17 -> 13400.303 | W17: =R17+T17+N17+U17 -> 44.36 | X17: =IF(L17<0,L17*-1,0) -> 0 | Y17: =W17+X17 -> 44.36 | Z17: 0 | AA17: 51 | AB17: 28 | AC17: =AC16+1 -> 8 | AD17: 367 | AE17: 704 | AF17: 1526.51
A18: =A17+1 -> 9 | B18: 6907.69 | C18: 312841 | D18: =C18-C17 -> 0 | E18: =C18-152000 -> 160841 | F18: =D18/$D$2 -> 0 | G18: 21.001402 | H18: 0 | I18: =G18+H18 -> 21.001402 | J18: =IF(L18>0,L18,0) -> 23.358598 | K18: =I18+J18 -> 44.36 | L18: =F18-(I18-W18) -> 23.358598 | M18: 4.76 | N18: 0 | O18: =M18-N18 -> 4.76 | P18: 0 | Q18: 0 | R18: =SUM(O18:Q18) -> 4.76 | T18: 0 | U18: 39.6 | V18: =V17-U18 -> 13360.703 | W18: =R18+T18+N18+U18 -> 44.36 | X18: =IF(L18<0,L18*-1,0) -> 0 | Y18: =W18+X18 -> 44.36 | Z18: 0 | AA18: 53 | AB18: 23 | AC18: =AC17+1 -> 9 | AD18: 390 | AE18: 805 | AF18: 1561.24
A19: =A18+1 -> 10 | B19: 6907.69 | C19: 312841 | D19: =C19-C18 -> 0 | E19: =C19-152000 -> 160841 | F19: =D19/$D$2 -> 0 | G19: 58.318598 | H19: 0 | I19: =G19+H19 -> 58.318598 | J19: =IF(L19>0,L19,0) -> 0 | K19: =I19+J19 -> 58.318598 | L19: =F19-(I19-W19) -> -13.958598 | M19: 4.76 | N19: 0 | O19: =M19-N19 -> 4.76 | P19: 0 | Q19: 0 | R19: =SUM(O19:Q19) -> 4.76 | T19: 0 | U19: 39.6 | V19: =V18-U19 -> 13321.103 | W19: =R19+T19+N19+U19 -> 44.36 | X19: =IF(L19<0,L19*-1,0) -> 13.958598 | Y19: =W19+X19 -> 58.318598 | Z19: 0 | AA19: 55 | AB19: 24 | AC19: =AC18+1 -> 10 | AD19: 437 | AE19: 920 | AF19: 1600.39
A20: =A19+1 -> 11 | B20: 6907.7 | C20: 312881 | D20: =C20-C19 -> 40 | E20: =C20-152000 -> 160881 | F20: =D20/$D$2 -> 20.171457 | G20: 21.001402 | H20: 0 | I20: =G20+H20 -> 21.001402 | J20: =IF(L20>0,L20,0) -> 43.530055 | K20: =I20+J20 -> 64.531457 | L20: =F20-(I20-W20) -> 43.530055 | M20: 4.76 | N20: 0 | O20: =M20-N20 -> 4.76 | P20: 0 | Q20: 0 | R20: =SUM(O20:Q20) -> 4.76 | T20: 0 | U20: 39.6 | V20: =V19-U20 -> 13281.503 | W20: =R20+T20+N20+U20 -> 44.36 | X20: =IF(L20<0,L20*-1,0) -> 0 | Y20: =W20+X20 -> 44.36 | Z20: 0 | AA20: 56 | AB20: 21 | AC20: =AC19+1 -> 11 | AD20: 498 | AE20: 1048 | AF20: 1642
A21: =A20+1 -> 12 | B21: 6907.7 | C21: 312881 | D21: =C21-C20 -> 0 | E21: =C21-152000 -> 160881 | F21: =D21/$D$2 -> 0 | G21: 94.122935 | H21: 0 | I21: =G21+H21 -> 94.122935 | J21: =IF(L21>0,L21,0) -> 0 | K21: =I21+J21 -> 94.122935 | L21: =F21-(I21-W21) -> -49.972935 | M21: 4.55 | N21: 0 | O21: =M21-N21 -> 4.55 | P21: 0 | Q21: 0 | R21: =SUM(O21:Q21) -> 4.55 | T21: 0 | U21: 39.6 | V21: =V20-U21 -> 13241.903 | W21: =R21+T21+N21+U21 -> 44.15 | X21: =IF(L21<0,L21*-1,0) -> 49.972935 | Y21: =W21+X21 -> 94.122935 | Z21: 0 | AA21: 54 | AB21: 34 | AC21: =AC20+1 -> 12 | AD21: 572 | AE21: 1182 | AF21: 1683.42
A22: =A21+1 -> 13 | B22: 6907.74 | C22: 313038 | D22: =C22-C21 -> 157 | E22: =C22-152000 -> 161038 | F22: =D22/$D$2 -> 79.17297 | G22: 75.464337 | H22: 0 | I22: =G22+H22 -> 75.464337 | J22: =IF(L22>0,L22,0) -> 47.708633 | K22: =I22+J22 -> 123.17297 | L22: =F22-(I22-W22) -> 47.708633 | M22: 4.4 | N22: 0 | O22: =M22-N22 -> 4.4 | P22: 0 | Q22: 0 | R22: =SUM(O22:Q22) -> 4.4 | T22: 0 | U22: 39.6 | V22: =V21-U22 -> 13202.303 | W22: =R22+T22+N22+U22 -> 44 | X22: =IF(L22<0,L22*-1,0) -> 0 | Y22: =W22+X22 -> 44 | Z22: 0 | AA22: 50 | AB22: 38 | AC22: =AC21+1 -> 13 | AD22: 716 | AE22: 1339 | AF22: 1725.1
... A38: =A37+1 -> 29 | B38: 6907.62 | C38: 312658 | D38: =C38-C37 -> 50 | E38: =C38-152000 -> 160658 | F38: =D38/$D$2 -> 25.214322 | G38: 34.83 | H38: 0 | I38: =G38+H38 -> 34.83 | J38: =IF(L38>0,L38,0) -> 25.704322 | K38: =I38+J38 -> 60.534322 | L38: =F38-(I38-W38) -> 25.704322 | M38: 6.29 | N38: 0 | O38: =M38-N38 -> 6.29 | P38: 0 | Q38: 0 | R38: =SUM(O38:Q38) -> 6.29 | T38: 0 | U38: 29.03 | V38: =V37-U38 -> 12689.103 | W38: =R38+T38+N38+U38 -> 35.32 | X38: =IF(L38<0,L38*-1,0) -> 0 | Y38: =W38+X38 -> 35.32 | Z38: 0.02 | AA38: 44 | AB38: 9 | AC38: =AC37+1 -> 29 | AD38: 4963 | AE38: 4000 | AF38: 2362.83
A39: 30 | B39: 6907.61 | C39: 312527 | D39: =C39-C38 -> -131 | E39: =C39-152000 -> 160527 | F39: =D39/$D$2 -> -66.061523 | G39: 0 | H39: 0 | I39: =G39+H39 -> 0 | J39: =IF(L39>0,L39,0) -> 0 | K39: =I39+J39 -> 0 | L39: =F39-(I39-W39) -> -30.771523 | M39: 6.29 | N39: 0 | O39: =M39-N39 -> 6.29 | P39: 0 | Q39: 0 | R39: =SUM(O39:Q39) -> 6.29 | T39: 0 | U39: 29 | V39: =V38-U39 -> 12660.103 | W39: =R39+T39+N39+U39 -> 35.29 | X39: =IF(L39<0,L39*-1,0) -> 30.771523 | Y39: =W39+X39 -> 66.061523 | Z39: 0.01 | AA39: 41 | AB39: 22 | AC39: 30 | AD39: 5210 | AE39: 4166 | AF39: 2362.83
A40: 31 | B40: 6907.62 | C40: 312568 | D40: =C40-C39 -> 41 | E40: =C40-152000 -> 160568 | F40: =D40/$D$2 -> 20.675744 | G40: 88.664362 | H40: 0 | I40: =G40+H40 -> 88.664362 | J40: =IF(L40>0,L40,0) -> 0 | K40: =I40+J40 -> 88.664362 | L40: =F40-(I40-W40) -> -32.898618 | M40: 6.06 | N40: 0 | O40: =M40-N40 -> 6.06 | P40: 0 | Q40: 0 | R40: =SUM(O40:Q40) -> 6.06 | T40: 0 | U40: 29.03 | V40: =V39-U40 -> 12631.073 | W40: =R40+T40+N40+U40 -> 35.09 | X40: =IF(L40<0,L40*-1,0) -> 32.898618 | Y40: =W40+X40 -> 67.988618 | Z40: 0.01 | AA40: 44 | AB40: 17 | AC40: 31 | AD40: 5455 | AE40: 4334 | AF40: 2403.37
AA41: 73
A42: MONTH / CFS | F42: =SUM(F10:F40) -> -157.84165 | G42: =SUM(G10:G40) -> 1921.7169 | H42: =SUM(H10:H40) -> 0 | I42: =SUM(I10:I40) -> 1921.7169 | J42: =SUM(J10:J40) -> 242.92595 | K42: =SUM(K10:K40) -> 2164.6429 | L42: =SUM(L10:L40) -> -829.96857 | M42: =SUM(M10:M40) -> 163.56 | ... R42: =SUM(R10:R40) -> 163.56 | T42: =SUM(T10:T40) -> 0 | U42: =SUM(U10:U40) -> 1086.03 | V42: =V40 -> 12631.073 | W42: =SUM(W10:W40) -> 1249.59 | X42: =SUM(X10:X40) -> 1072.8945 | Y42: =SUM(Y10:Y40) -> 2322.4845 | Z42: =SUM(Z10:Z40) -> 0.04 | AA42: =AVERAGE(AA10:AA40) -> 47.354839 | AB42: =AVERAGE(AB10:AB40) -> 21.516129
A43: MONTH / AF | D43: =SUM(D10:D40) -> -313 | F43: =F42*$D$2 -> -313 | G43: =G42*$D$2 -> 3810.7647 | H43: =H42*$D$2 -> 0 | I43: =I42*$D$2 -> 3810.7647 | J43: =J42*$D$2 -> 481.72215 | K43: =K42*$D$2 -> 4292.4868 | L43: =L42*$D$2 -> -1645.8277 | M43: =M42*$D$2 -> 324.33948 | ... R43: =R42*$D$2 -> 324.33948 | T43: =T42*$D$2 -> 0 | U43: =U42*$D$2 -> 2153.5975 | V43: =V42*$D$2 -> 25047.418 | W43: =W42*$D$2 -> 2477.937 | X43: =X42*$D$2 -> 2127.5498 | Y43: =Y42*$D$2 -> 4605.4868 | AA43: =MAX(AA10:AA40) -> 61 | AB43: =MAX(AB10:AB40) -> 38 | AC43: HI
A45: SEASON / CFS | AA45: =MIN(AA10:AA40) -> 29 | AB45: =MIN(AB10:AB40) -> 4 | AC45: LO
A46: SEASON / AF
A48: YTD / CFS | F48: =F8+F42 -> -512.8593 | G48: =G8+G42 -> 3716.4169 | H48: =H8+H42 -> 0 | I48: =I8+I42 -> 3716.3169 | J48: =J8+J42 -> 550.74489 | K48: =K8+K42 -> 4267.0618 | L48: =L8+L42 -> -1288.6362 | M48: =M8+M42 -> 656.06 | ... R48: =R8+R42 -> 532.06 | T48: =T8+T42 -> 0 | U48: =U8+U42 -> 2284.48 | V48: =V40 -> 12631.073 | W48: =W8+W42 -> 2940.54 | X48: =X8+X42 -> 1839.3811 | Y48: =Y8+Y42 -> 4779.9211 | Z48: =Z8+Z42 -> 0.21
A49: YTD / AF | D49: =D8+D43 -> -1017 | E49: =E40 -> 160568 | F49: =F48*$D$2 -> -1017 | G49: =G48*$D$2 -> 7369.6547 | H49: =H48*$D$2 -> 0 | I49: =I48*$D$2 -> 7369.4564 | J49: =J48*$D$2 -> 1092.1271 | K49: =K48*$D$2 -> 8461.5836 | L49: =L48*$D$2 -> -2555.3656 | M49: =M48*$D$2 -> 1300.967 | ... U49: =U48*$D$2 -> 4530.1238 | V49: =V40*$D$2 -> 25047.418 | W49: =W48*$D$2 -> 5831.0908 | X49: =X48*$D$2 -> 3647.4927 | Y49: =Y48*$D$2 -> 9478.5836
A51: ="JUN /9" -> JUN /9
B52: 6924.15 | C52: 381833 | E52: =C52-152000 -> 229833
A53: ="5/12/94 thru 6/9/94" -> 5/12/94 thru 6/9/94
B54: =B52-B21 -> 16.45 | D54: =C52-C22 -> 68795

Sheet JAN
K1: MC PHEE RESERVOIR IN/OUT FLOW TABULATION
A2: AF/cfs CONVERT FACTOR | D2: 1.983 | K2: JANUARY "96"
A4: DATE | B4: RESERV | C4: RESERV | D4: AC FT | E4: ACTIVE | F4: CONV TO | G4: DOLORES | H4: LOST | I4: RECORDED | J4: CALC | K4: TOTAL | L4: CALC | M4: DOLORES TUNNEL | P4: LONE | Q4: U | R4: TOTAL | S4: MVI | T4: DV CR | U4: BELOW | V4: REMAIN | W4: RECORDED | X4: CALC | Y4: TOTAL | Z4: RAIN | AA4: MAX | AB4: MIN | AC4: DATE
A5: "JAN" | B5: ELEV | C5: AC FT | D5: CHANGE | E5: CAP | F5: CFS | G5: RIVER | H5: CANYON | I5: INFLOW | J5: INFLOW | K5: INFLOW | L5: INF/OTF | M5: TOT DIV | N5: UTE F&R | O5: MVI,CTZ | P5: PINE | Q5: LATERAL | R5: MVI | S5: CALL | T5: CANAL | U5: MC PHEE | V5: RELEASE | W5: OUTFLOW | X5: OUTFLOW | Y5: OUTFLOW | AA5: TMP | AB5: TMP | AC5: "JAN"
AD6: 741 | AE6: 742
A7: SEASON BAL
A8: YTD | B8: {=DEC!$B$40:$C$40} -> 6907.62 | C8: 312568 | D8: {=DEC!$D$49:$E$49} -> -1017 | E8: 160568 | F8: {=DEC!$F$48:$Z$48} -> -512.8593 | G8: 3716.4169 | H8: 0 | I8: 3716.3169 | J8: 550.74489 | K8: 4267.0618 | L8: -1288.6362 | M8: 656.06 | N8: 0 | O8: 163.56 | P8: 0 | Q8: 0 | R8: 532.06 | S8: 0 | T8: 0 | U8: 2284.48 | V8: 12631.073 | W8: 2940.54 | X8: 1839.3811 | Y8: 4779.9211 | Z8: 0.21 | AD8: 285 | AE8: 251 | AF8: 1207.63
A10: 1 | B10: 6907.62 | C10: 312568 | D10: =C10-C8 -> 0 | E10: =C10-152000 -> 160568 | F10: =D10/$D$2 -> 0 | G10: 17.559975 | H10: 0 | I10: =G10+H10 -> 17.559975 | J10: =IF(L10>0,L10,0) -> 17.520025 | K10: =I10+J10 -> 35.08 | L10: =F10-(I10-W10) -> 17.520025 | M10: 5.92 | N10: 0 | O10: =M10-N10 -> 5.92 | P10: 0 | Q10: 0 | R10: =SUM(O10:Q10) -> 5.92 | T10: 0 | U10: 29.16 | V10: =V8-U10 -> 12601.913 | W10: =R10+T10+N10+U10 -> 35.08 | X10: =IF(L10<0,L10*-1,0) -> 0 | Y10: =W10+X10 -> 35.08 | Z10: 0 | AA10: 54 | AB10: 36 | AC10: 1 | AD10: 303 | AE10: 273 | AF10: 1256.86
A11: =A10+1 -> 2 | B11: 6907.62 | C11: 312568 | D11: =C11-C10 -> 0 | E11: =C11-152000 -> 160568 | F11: =D11/$D$2 -> 0 | G11: 35.21 | H11: 0 | I11: =G11+H11 -> 35.21 | J11: =IF(L11>0,L11,0) -> 0.2 | K11: =I11+J11 -> 35.41 | L11: =F11-(I11-W11) -> 0.2 | M11: 6 | N11: 0 | O11: =M11-N11 -> 6 | P11: 0 | Q11: 0 | R11: =SUM(O11:Q11) -> 6 | T11: 0 | U11: 29.41 | V11: =V10-U11 -> 12572.503 | W11: =R11+T11+N11+U11 -> 35.41 | X11: =IF(L11<0,L11*-1,0) -> 0 | Y11: =W11+X11 -> 35.41 | Z11: 0.01 | AA11: 61 | AB11: 36 | AC11: =AC10+1 -> 2 | AD11: 306 | AE11: 300 | AF11: 1306.42
A12: =A11+1 -> 3 | B12: 6907.62 | C12: 312568 | D12: =C12-C11 -> 0 | E12: =C12-152000 -> 160568 | F12: =D12/$D$2 -> 0 | G12: 51.720025 | H12: 0 | I12: =G12+H12 -> 51.720025 | J12: =IF(L12>0,L12,0) -> 0 | K12: =I12+J12 -> 51.720025 | L12: =F12-(I12-W12) -> -17.060025 | M12: 4.96 | N12: 0 | O12: =M12-N12 -> 4.96 | P12: 0 | Q12: 0 | R12: =SUM(O12:Q12) -> 4.96 | T12: 0 | U12: 29.7 | V12: =V11-U12 -> 12542.803 | W12: =R12+T12+N12+U12 -> 34.66 | X12: =IF(L12<0,L12*-1,0) -> 17.060025 | Y12: =W12+X12 -> 51.720025 | Z12: 0 | AA12: 62 | AB12: 38 | AC12: =AC11+1 -> 3 | AD12: 316 | AE12: 341 | AF12: 1355.74
A13: =A12+1 -> 4 | B13: 6907.62 | C13: 312568 | D13: =C13-C12 -> 0 | E13: =C13-152000 -> 160568 | F13: =D13/$D$2 -> 0 | G13: 339.01758 | H13: 0 | I13: =G13+H13 -> 339.01758 | J13: =IF(L13>0,L13,0) -> 0 | K13: =I13+J13 -> 339.01758 | L13: =F13-(I13-W13) -> -305.43758 | M13: 3.88 | N13: 0 | O13: =M13-N13 -> 3.88 | P13: 0 | Q13: 0 | R13: =SUM(O13:Q13) -> 3.88 | T13: 0 | U13: 29.7 | V13: =V12-U13 -> 12513.103 | W13: =R13+T13+N13+U13 -> 33.58 | X13: =IF(L13<0,L13*-1,0) -> 305.43758 | Y13: =W13+X13 -> 339.01758 | Z13: 0 | AA13: 70 | AB13: 39 | AC13: =AC12+1 -> 4 | AD13: 316 | AE13: 395 | AF13: 1405.31
A14: =A13+1 -> 5 | B14: 6907.62 | C14: 312568 | D14: =C14-C13 -> 0 | E14: =C14-152000 -> 160568 | F14: =D14/$D$2 -> 0 | G14: 33.42 | H14: 0 | I14: =G14+H14 -> 33.42 | J14: =IF(L14>0,L14,0) -> 0 | K14: =I14+J14 -> 33.42 | L14: =F14-(I14-W14) -> -0.09 | M14: 3.72 | N14: 0 | O14: =M14-N14 -> 3.72 | P14: 0 | Q14: 0 | R14: =SUM(O14:Q14) -> 3.72 | T14: 0 | U14: 29.61 | V14: =V13-U14 -> 12483.493 | W14: =R14+T14+N14+U14 -> 33.33 | X14: =IF(L14<0,L14*-1,0) -> 0.09 | Y14: =W14+X14 -> 33.42 | Z14: 0 | AA14: 76 | AB14: 43 | AC14: =AC13+1 -> 5 | AD14: 316 | AE14: 466 | AF14: 1437.16
A15: =A14+1 -> 6 | B15: 6907.62 | C15: 312568 | D15: =C15-C14 -> 0 | E15: =C15-152000 -> 160568 | F15: =D15/$D$2 -> 0 | G15: 51.070025 | H15: 0 | I15: =G15+H15 -> 51.070025 | J15: =IF(L15>0,L15,0) -> 0 | K15: =I15+J15 -> 51.070025 | L15: =F15-(I15-W15) -> -17.740025 | M15: 3.72 | N15: 0 | O15: =M15-N15 -> 3.72 | P15: 0 | Q15: 0 | R15: =SUM(O15:Q15) -> 3.72 | T15: 0 | U15: 29.61 | V15: =V14-U15 -> 12453.883 | W15: =R15+T15+N15+U15 -> 33.33 | X15: =IF(L15<0,L15*-1,0) -> 17.740025 | Y15: =W15+X15 -> 51.070025 | Z15: 0 | AA15: 73 | AB15: 39 | AC15: =AC14+1 -> 6 | AD15: 325 | AE15: 538 | AF15: 1467.01
A16: =A15+1 -> 7 | B16: 6907.62 | C16: 312568 | D16: =C16-C15 -> 0 | E16: =C16-152000 -> 160568 | F16: =D16/$D$2 -> 0 | G16: 51.834312 | H16: 0 | I16: =G16+H16 -> 51.834312 | J16: =IF(L16>0,L16,0) -> 0 | K16: =I16+J16 -> 51.834312 | L16: =F16-(I16-W16) -> -18.414312 | M16: 3.72 | N16: 0 | O16: =M16-N16 -> 3.72 | P16: 0 | Q16: 0 | R16: =SUM(O16:Q16) -> 3.72 | T16: 0 | U16: 29.7 | V16: =V15-U16 -> 12424.183 | W16: =R16+T16+N16+U16 -> 33.42 | X16: =IF(L16<0,L16*-1,0) -> 18.414312 | Y16: =W16+X16 -> 51.834312 | Z16: 0 | AA16: 74 | AB16: 37 | AC16: =AC15+1 -> 7 | AD16: 342 | AE16: 618 | AF16: 1496.64
A17: =A16+1 -> 8 | B17: 6907.62 | C17: 312568 | D17: =C17-C16 -> 0 | E17: =C17-152000 -> 160568 | F17: =D17/$D$2 -> 0 | G17: 34.1 | H17: 0 | I17: =G17+H17 -> 34.1 | J17: =IF(L17>0,L17,0) -> 0 | K17: =I17+J17 -> 34.1 | L17: =F17-(I17-W17) -> -0.68 | M17: 3.72 | N17: 0 | O17: =M17-N17 -> 3.72 | P17: 0 | Q17: 0 | R17: =SUM(O17:Q17) -> 3.72 | T17: 0 | U17: 29.7 | V17: =V16-U17 -> 12394.483 | W17: =R17+T17+N17+U17 -> 33.42 | X17: =IF(L17<0,L17*-1,0) -> 0.68 | Y17: =W17+X17 -> 34.1 | Z17: 0 | AA17: 69 | AB17: 34 | AC17: =AC16+1 -> 8 | AD17: 367 | AE17: 704 | AF17: 1526.51
A18: =A17+1 -> 9 | B18: 6907.62 | C18: 312568 | D18: =C18-C17 -> 0 | E18: =C18-152000 -> 160568 | F18: =D18/$D$2 -> 0 | G18: 51.750025 | H18: 0 | I18: =G18+H18 -> 51.750025 | J18: =IF(L18>0,L18,0) -> 0 | K18: =I18+J18 -> 51.750025 | L18: =F18-(I18-W18) -> -18.330025 | M18: 3.72 | N18: 0 | O18: =M18-N18 -> 3.72 | P18: 0 | Q18: 0 | R18: =SUM(O18:Q18) -> 3.72 | T18: 0 | U18: 29.7 | V18: =V17-U18 -> 12364.783 | W18: =R18+T18+N18+U18 -> 33.42 | X18: =IF(L18<0,L18*-1,0) -> 18.330025 | Y18: =W18+X18 -> 51.750025 | Z18: 0 | AA18: 66 | AB18: 44 | AC18: =AC17+1 -> 9 | AD18: 390 | AE18: 805 | AF18: 1561.24
A19: =A18+1 -> 10 | B19: 6907.63 | C19: 312606 | D19: =C19-C18 -> 38 | E19: =C19-152000 -> 160606 | F19: =D19/$D$2 -> 19.162885 | G19: 70.408623 | H19: 0 | I19: =G19+H19 -> 70.408623 | J19: =IF(L19>0,L19,0) -> 0 | K19: =I19+J19 -> 70.408623 | L19: =F19-(I19-W19) -> -17.825739 | M19: 3.72 | N19: 0 | O19: =M19-N19 -> 3.72 | P19: 0 | Q19: 0 | R19: =SUM(O19:Q19) -> 3.72 | T19: 0 | U19: 29.7 | V19: =V18-U19 -> 12335.083 | W19: =R19+T19+N19+U19 -> 33.42 | X19: =IF(L19<0,L19*-1,0) -> 17.825739 | Y19: =W19+X19 -> 51.245739 | Z19: 0 | AA19: 66 | AB19: 36 | AC19: =AC18+1 -> 10 | AD19: 437 | AE19: 920 | AF19: 1600.39
A20: =A19+1 -> 11 | B20: 6907.63 | C20: 312606 | D20: =C20-C19 -> 0 | E20: =C20-152000 -> 160606 | F20: =D20/$D$2 -> 0 | G20: 159.90161 | H20: 0 | I20: =G20+H20 -> 159.90161 | J20: =IF(L20>0,L20,0) -> 0 | K20: =I20+J20 -> 159.90161 | L20: =F20-(I20-W20) -> -126.48161 | M20: 3.72 | N20: 0 | O20: =M20-N20 -> 3.72 | P20: 0 | Q20: 0 | R20: =SUM(O20:Q20) -> 3.72 | T20: 0 | U20: 29.7 | V20: =V19-U20 -> 12305.383 | W20: =R20+T20+N20+U20 -> 33.42 | X20: =IF(L20<0,L20*-1,0) -> 126.48161 | Y20: =W20+X20 -> 159.90161 | Z20: 0 | AA20: 68 | AB20: 40 | AC20: =AC19+1 -> 11 | AD20: 498 | AE20: 1048 | AF20: 1642
A21: =A20+1 -> 12 | B21: 6907.64 | C21: 312646 | D21: =C21-C20 -> 40 | E21: =C21-152000 -> 160646 | F21: =D21/$D$2 -> 20.171457 | G21: 33.09 | H21: 0 | I21: =G21+H21 -> 33.09 | J21: =IF(L21>0,L21,0) -> 20.471457 | K21: =I21+J21 -> 53.561457 | L21: =F21-(I21-W21) -> 20.471457 | M21: 3.72 | N21: 0 | O21: =M21-N21 -> 3.72 | P21: 0 | Q21: 0 | R21: =SUM(O21:Q21) -> 3.72 | T21: 0 | U21: 29.67 | V21: =V20-U21 -> 12275.713 | W21: =R21+T21+N21+U21 -> 33.39 | X21: =IF(L21<0,L21*-1,0) -> 0 | Y21: =W21+X21 -> 33.39 | Z21: 0 | AA21: 68 | AB21: 42 | AC21: =AC20+1 -> 12 | AD21: 572 | AE21: 1182 | AF21: 1683.42
A22: =A21+1 -> 13 | B22: 6907.64 | C22: 312646 | D22: =C22-C21 -> 0 | E22: =C22-152000 -> 160646 | F22: =D22/$D$2 -> 0 | G22: 33.35 | H22: 0 | I22: =G22+H22 -> 33.35 | J22: =IF(L22>0,L22,0) -> 0 | K22: =I22+J22 -> 33.35 | L22: =F22-(I22-W22) -> -0.08 | M22: 3.72 | N22: 0 | O22: =M22-N22 -> 3.72 | P22: 0 | Q22: 0 | R22: =SUM(O22:Q22) -> 3.72 | T22: 0 | U22: 29.55 | V22: =V21-U22 -> 12246.163 | W22: =R22+T22+N22+U22 -> 33.27 | X22: =IF(L22<0,L22*-1,0) -> 0.08 | Y22: =W22+X22 -> 33.35 | Z22: 0 | AA22: 63 | AB22: 38 | AC22: =AC21+1 -> 13 | AD22: 716 | AE22: 1339 | AF22: 1725.1
... A38: =A37+1 -> 29 | B38: 6907.84 | C38: 313429 | D38: =C38-C37 -> 79 | E38: =C38-152000 -> 161429 | F38: =D38/$D$2 -> 39.838628 | G38: 33.76 | H38: 0 | I38: =G38+H38 -> 33.76 | J38: =IF(L38>0,L38,0) -> 39.498628 | K38: =I38+J38 -> 73.258628 | L38: =F38-(I38-W38) -> 39.498628 | M38: 3.72 | N38: 0 | O38: =M38-N38 -> 3.72 | P38: 0 | Q38: 0 | R38: =SUM(O38:Q38) -> 3.72 | T38: 0 | U38: 29.7 | V38: =V37-U38 -> 11772.173 | W38: =R38+T38+N38+U38 -> 33.42 | X38: =IF(L38<0,L38*-1,0) -> 0 | Y38: =W38+X38 -> 33.42 | Z38: 0 | AA38: 78 | AB38: 44 | AC38: =AC37+1 -> 29 | AD38: 4963 | AE38: 4000 | AF38: 2362.83
A39: 30 | B39: 6907.85 | C39: 313469 | D39: =C39-C38 -> 40 | E39: =C39-152000 -> 161469 | F39: =D39/$D$2 -> 20.171457 | G39: 69.828623 | H39: 0 | I39: =G39+H39 -> 69.828623 | J39: =IF(L39>0,L39,0) -> 0 | K39: =I39+J39 -> 69.828623 | L39: =F39-(I39-W39) -> -16.237166 | M39: 3.72 | N39: 0 | O39: =M39-N39 -> 3.72 | P39: 0 | Q39: 0 | R39: =SUM(O39:Q39) -> 3.72 | T39: 0 | U39: 29.7 | V39: =V38-U39 -> 11742.473 | W39: =R39+T39+N39+U39 -> 33.42 | X39: =IF(L39<0,L39*-1,0) -> 16.237166 | Y39: =W39+X39 -> 49.657166 | Z39: 0.13 | AA39: 84 | AB39: 46 | AC39: 30 | AD39: 5210 | AE39: 4166 | AF39: 2362.83
A40: 31 | B40: 6907.87 | C40: 313547 | D40: =C40-C39 -> 78 | E40: =C40-152000 -> 161547 | F40: =D40/$D$2 -> 39.334342 | G40: 33.42 | H40: 0 | I40: =G40+H40 -> 33.42 | J40: =IF(L40>0,L40,0) -> 39.474342 | K40: =I40+J40 -> 72.894342 | L40: =F40-(I40-W40) -> 39.474342 | M40: 3.86 | N40: 0 | O40: =M40-N40 -> 3.86 | P40: 0 | Q40: 0 | R40: =SUM(O40:Q40) -> 3.86 | T40: 0 | U40: 29.7 | V40: =V39-U40 -> 11712.773 | W40: =R40+T40+N40+U40 -> 33.56 | X40: =IF(L40<0,L40*-1,0) -> 0 | Y40: =W40+X40 -> 33.56 | Z40: 0.19 | AA40: 82 | AB40: 46 | AC40: 31 | AD40: 5455 | AE40: 4334 | AF40: 2403.37
AA41: 73
A42: MONTH / CFS | F42: =SUM(F10:F40) -> 493.69642 | G42: =SUM(G10:G40) -> 1994.3328 | H42: =SUM(H10:H40) -> 0 | I42: =SUM(I10:I40) -> 1994.3328 | J42: =SUM(J10:J40) -> 387.64199 | K42: =SUM(K10:K40) -> 2381.9748 | L42: =SUM(L10:L40) -> -460.03635 | M42: =SUM(M10:M40) -> 122.3 | ... R42: =SUM(R10:R40) -> 122.3 | T42: =SUM(T10:T40) -> 0 | U42: =SUM(U10:U40) -> 918.3 | W42: =SUM(W10:W40) -> 1040.6 | X42: =SUM(X10:X40) -> 847.67834 | Y42: =SUM(Y10:Y40) -> 1888.2783 | Z42: =SUM(Z10:Z40) -> 1.46 | AA42: =AVERAGE(AA10:AA40) -> 71.451613 | AB42: =AVERAGE(AB10:AB40) -> 40.16129
A43: MONTH / AF | D43: =SUM(D10:D40) -> 979 | F43: =F42*$D$2 -> 979 | G43: =G42*$D$2 -> 3954.7619 | H43: =H42*$D$2 -> 0 | I43: =I42*$D$2 -> 3954.7619 | J43: =J42*$D$2 -> 768.69407 | K43: =K42*$D$2 -> 4723.4559 | L43: =L42*$D$2 -> -912.25208 | M43: =M42*$D$2 -> 242.5209 | ... R43: =R42*$D$2 -> 242.5209 | T43: =T42*$D$2 -> 0 | U43: =U42*$D$2 -> 1820.9889 | W43: =W42*$D$2 -> 2063.5098 | X43: =X42*$D$2 -> 1680.9461 | Y43: =Y42*$D$2 -> 3744.456 | AA43: =MAX(AA10:AA40) -> 84 | AB43: =MAX(AB10:AB40) -> 48 | AC43: HI
A45: SEASON / CFS | AA45: =MIN(AA10:AA40) -> 54 | AB45: =MIN(AB10:AB40) -> 30 | AC45: LO
A46: SEASON / AF
A48: YTD / CFS | F48: =F8+F42 -> -19.162885 | G48: =G8+G42 -> 5710.7497 | H48: =H8+H42 -> 0 | I48: =I8+I42 -> 5710.6497 | J48: =J8+J42 -> 938.38688 | K48: =K8+K42 -> 6649.0366 | L48: =L8+L42 -> -1748.6726 | M48: =M8+M42 -> 778.36 | ... R48: =R8+R42 -> 654.36 | T48: =T8+T42 -> 0 | U48: =U8+U42 -> 3202.78 | V48: =V40 -> 11712.773 | W48: =W8+W42 -> 3981.14 | X48: =X8+X42 -> 2687.0595 | Y48: =Y8+Y42 -> 6668.1995 | Z48: =Z8+Z42 -> 1.67
A49: YTD / AF | D49: =D8+D43 -> -38 | E49: =E40 -> 161547 | F49: =F48*$D$2 -> -38 | G49: =G48*$D$2 -> 11324.417 | H49: =H48*$D$2 -> 0 | I49: =I48*$D$2 -> 11324.218 | J49: =J48*$D$2 -> 1860.8212 | K49: =K48*$D$2 -> 13185.04 | L49: =L48*$D$2 -> -3467.6177 | M49: =M48*$D$2 -> 1543.4879 | ... U49: =U48*$D$2 -> 6351.1127 | V49: =V40*$D$2 -> 23226.429 | W49: =W48*$D$2 -> 7894.6006 | X49: =X48*$D$2 -> 5328.4389 | Y49: =Y48*$D$2 -> 13223.04
A51: ="JUN /9" -> JUN /9
B52: 6924.15 | C52: 381833 | E52: =C52-152000 -> 229833
A53: ="5/12/94 thru 6/9/94" -> 5/12/94 thru 6/9/94
B54: =B52-B21 -> 16.51 | D54: =C52-C23 -> 69149

Sheet FEB
K1: MC PHEE RESERVOIR IN/OUT FLOW TABULATION
A2: AF/cfs CONVERT FACTOR | D2: 1.983 | K2: FEBRUARY "96"
A4: DATE | B4: RESERV | C4: RESERV | D4: AC FT | E4: ACTIVE | F4: CONV TO | G4: DOLORES | H4: LOST | I4: RECORDED | J4: CALC | K4: TOTAL | L4: CALC | M4: DOLORES TUNNEL | P4: LONE | Q4: U | R4: TOTAL | S4: MVI | T4: DV CR | U4: BELOW | V4: REMAIN | W4: RECORDED | X4: CALC | Y4: TOTAL | Z4: RAIN | AA4: MAX | AB4: MIN | AC4: DATE
A5: FEB | B5: ELEV | C5: AC FT | D5: CHANGE | E5: CAP | F5: CFS | G5: RIVER | H5: CANYON | I5: INFLOW | J5: INFLOW | K5: INFLOW | L5: INF/OTF | M5: TOT DIV | N5: UTE F&R | O5: MVI,CTZ | P5: PINE | Q5: LATERAL | R5: MVI | S5: CALL | T5: CANAL | U5: MC PHEE | V5: RELEASE | W5: OUTFLOW | X5: OUTFLOW | Y5: OUTFLOW | AA5: TMP | AB5: TMP | AC5: FEB
AD6: 741 | AE6: 742
A7: SEASON BAL
A8: YTD | B8: {=JAN!$B$40:$C$40} -> 6907.87 | C8: 313547 | D8: {=JAN!$D$49:$E$49} -> -38 | E8: 161547 | F8: {=JAN!$F$48:$Z$48} -> -19.162885 | G8: 5710.7497 | H8: 0 | I8: 5710.6497 | J8: 938.38688 | K8: 6649.0366 | L8: -1748.6726 | M8: 778.36 | N8: 0 | O8: 285.86 | P8: 0 | Q8: 0 | R8: 654.36 | S8: 0 | T8: 0 | U8: 3202.78 | V8: 11712.773 | W8: 3981.14 | X8: 2687.0595 | Y8: 6668.1995 | Z8: 1.67 | AD8: 285 | AE8: 251 | AF8: 1207.63
A10: 1 | B10: 6907.89 | C10: 313626 | D10: =C10-C8 -> 79 | E10: =C10-152000 -> 161626 | F10: =D10/$D$2 -> 39.838628 | G10: 32.99 | H10: 0 | I10: =G10+H10 -> 32.99 | J10: =IF(L10>0,L10,0) -> 40.368628 | K10: =I10+J10 -> 73.358628 | L10: =F10-(I10-W10) -> 40.368628 | M10: 3.82 | N10: 0 | O10: =M10-N10 -> 3.82 | P10: 0 | Q10: 0 | R10: =SUM(O10:Q10) -> 3.82 | T10: 0 | U10: 29.7 | V10: =V8-U10 -> 11683.073 | W10: =R10+T10+N10+U10 -> 33.52 | X10: =IF(L10<0,L10*-1,0) -> 0 | Y10: =W10+X10 -> 33.52 | Z10: 0.06 | AA10: 54 | AB10: 36 | AC10: 1 | AD10: 303 | AE10: 273 | AF10: 1256.86
A11: =A10+1 -> 2 | B11: 6907.91 | C11: 313704 | D11: =C11-C10 -> 78 | E11: =C11-152000 -> 161704 | F11: =D11/$D$2 -> 39.334342 | G11: 50.934312 | H11: 0 | I11: =G11+H11 -> 50.934312 | J11: =IF(L11>0,L11,0) -> 21.84003 | K11: =I11+J11 -> 72.774342 | L11: =F11-(I11-W11) -> 21.84003 | M11: 3.74 | N11: 0 | O11: =M11-N11 -> 3.74 | P11: 0 | Q11: 0 | R11: =SUM(O11:Q11) -> 3.74 | T11: 0 | U11: 29.7 | V11: =V10-U11 -> 11653.373 | W11: =R11+T11+N11+U11 -> 33.44 | X11: =IF(L11<0,L11*-1,0) -> 0 | Y11: =W11+X11 -> 33.44 | Z11: 0.25 | AA11: 61 | AB11: 36 | AC11: =AC10+1 -> 2 | AD11: 306 | AE11: 300 | AF11: 1306.42
A12: =A11+1 -> 3 | B12: 6907.92 | C12: 313742 | D12: =C12-C11 -> 38 | E12: =C12-152000 -> 161742 | F12: =D12/$D$2 -> 19.162885 | G12: 69.088623 | H12: 0 | I12: =G12+H12 -> 69.088623 | J12: =IF(L12>0,L12,0) -> 0 | K12: =I12+J12 -> 69.088623 | L12: =F12-(I12-W12) -> -16.275739 | M12: 3.95 | N12: 0 | O12: =M12-N12 -> 3.95 | P12: 0 | Q12: 0 | R12: =SUM(O12:Q12) -> 3.95 | T12: 0 | U12: 29.7 | V12: =V11-U12 -> 11623.673 | W12: =R12+T12+N12+U12 -> 33.65 | X12: =IF(L12<0,L12*-1,0) -> 16.275739 | Y12: =W12+X12 -> 49.925739 | Z12: 0 | AA12: 62 | AB12: 38 | AC12: =AC11+1 -> 3 | AD12: 316 | AE12: 341 | AF12: 1355.74
A13: =A12+1 -> 4 | B13: 6907.95 | C13: 313861 | D13: =C13-C12 -> 119 | E13: =C13-152000 -> 161861 | F13: =D13/$D$2 -> 60.010086 | G13: 69.088623 | H13: 0 | I13: =G13+H13 -> 69.088623 | J13: =IF(L13>0,L13,0) -> 24.531462 | K13: =I13+J13 -> 93.620086 | L13: =F13-(I13-W13) -> 24.531462 | M13: 3.91 | N13: 0 | O13: =M13-N13 -> 3.91 | P13: 0 | Q13: 0 | R13: =SUM(O13:Q13) -> 3.91 | T13: 0 | U13: 29.7 | V13: =V12-U13 -> 11593.973 | W13: =R13+T13+N13+U13 -> 33.61 | X13: =IF(L13<0,L13*-1,0) -> 0 | Y13: =W13+X13 -> 33.61 | Z13: 0 | AA13: 70 | AB13: 39 | AC13: =AC12+1 -> 4 | AD13: 316 | AE13: 395 | AF13: 1405.31
A14: =A13+1 -> 5 | B14: 6907.97 | C14: 313939 | D14: =C14-C13 -> 78 | E14: =C14-152000 -> 161939 | F14: =D14/$D$2 -> 39.334342 | G14: 69.088623 | H14: 0 | I14: =G14+H14 -> 69.088623 | J14: =IF(L14>0,L14,0) -> 3.7757186 | K14: =I14+J14 -> 72.864342 | L14: =F14-(I14-W14) -> 3.7757186 | M14: 3.83 | N14: 0 | O14: =M14-N14 -> 3.83 | P14: 0 | Q14: 0 | R14: =SUM(O14:Q14) -> 3.83 | T14: 0 | U14: 29.7 | V14: =V13-U14 -> 11564.273 | W14: =R14+T14+N14+U14 -> 33.53 | X14: =IF(L14<0,L14*-1,0) -> 0 | Y14: =W14+X14 -> 33.53 | Z14: 0 | AA14: 76 | AB14: 43 | AC14: =AC13+1 -> 5 | AD14: 316 | AE14: 466 | AF14: 1437.16
A15: =A14+1 -> 6 | B15: 6907.97 | C15: 313939 | D15: =C15-C14 -> 0 | E15: =C15-152000 -> 161939 | F15: =D15/$D$2 -> 0 | G15: 86.878649 | H15: 0 | I15: =G15+H15 -> 86.878649 | J15: =IF(L15>0,L15,0) -> 0 | K15: =I15+J15 -> 86.878649 | L15: =F15-(I15-W15) -> -53.448649 | M15: 3.73 | N15: 0 | O15: =M15-N15 -> 3.73 | P15: 0 | Q15: 0 | R15: =SUM(O15:Q15) -> 3.73 | T15: 0 | U15: 29.7 | V15: =V14-U15 -> 11534.573 | W15: =R15+T15+N15+U15 -> 33.43 | X15: =IF(L15<0,L15*-1,0) -> 53.448649 | Y15: =W15+X15 -> 86.878649 | Z15: 0 | AA15: 73 | AB15: 39 | AC15: =AC14+1 -> 6 | AD15: 325 | AE15: 538 | AF15: 1467.01
A16: =A15+1 -> 7 | B16: 6907.99 | C16: 314018 | D16: =C16-C15 -> 79 | E16: =C16-152000 -> 162018 | F16: =D16/$D$2 -> 39.838628 | G16: 69.398623 | H16: 0 | I16: =G16+H16 -> 69.398623 | J16: =IF(L16>0,L16,0) -> 3.890005 | K16: =I16+J16 -> 73.288628 | L16: =F16-(I16-W16) -> 3.890005 | M16: 3.72 | N16: 0 | O16: =M16-N16 -> 3.72 | P16: 0 | Q16: 0 | R16: =SUM(O16:Q16) -> 3.72 | T16: 0 | U16: 29.73 | V16: =V15-U16 -> 11504.843 | W16: =R16+T16+N16+U16 -> 33.45 | X16: =IF(L16<0,L16*-1,0) -> 0 | Y16: =W16+X16 -> 33.45 | Z16: 0 | AA16: 74 | AB16: 37 | AC16: =AC15+1 -> 7 | AD16: 342 | AE16: 618 | AF16: 1496.64
A17: =A16+1 -> 8 | B17: 6907.99 | C17: 314018 | D17: =C17-C16 -> 0 | E17: =C17-152000 -> 162018 | F17: =D17/$D$2 -> 0 | G17: 87.642935 | H17: 0 | I17: =G17+H17 -> 87.642935 | J17: =IF(L17>0,L17,0) -> 0 | K17: =I17+J17 -> 87.642935 | L17: =F17-(I17-W17) -> -54.222935 | M17: 3.72 | N17: 0 | O17: =M17-N17 -> 3.72 | P17: 0 | Q17: 0 | R17: =SUM(O17:Q17) -> 3.72 | T17: 0 | U17: 29.7 | V17: =V16-U17 -> 11475.143 | W17: =R17+T17+N17+U17 -> 33.42 | X17: =IF(L17<0,L17*-1,0) -> 54.222935 | Y17: =W17+X17 -> 87.642935 | Z17: 0 | AA17: 69 | AB17: 34 | AC17: =AC16+1 -> 8 | AD17: 367 | AE17: 704 | AF17: 1526.51
A18: =A17+1 -> 9 | B18: 6908 | C18: 314056 | D18: =C18-C17 -> 38 | E18: =C18-152000 -> 162056 | F18: =D18/$D$2 -> 19.162885 | G18: 51.230025 | H18: 0 | I18: =G18+H18 -> 51.230025 | J18: =IF(L18>0,L18,0) -> 1.3828593 | K18: =I18+J18 -> 52.612885 | L18: =F18-(I18-W18) -> 1.3828593 | M18: 3.72 | N18: 0 | O18: =M18-N18 -> 3.72 | P18: 0 | Q18: 0 | R18: =SUM(O18:Q18) -> 3.72 | T18: 0 | U18: 29.73 | V18: =V17-U18 -> 11445.413 | W18: =R18+T18+N18+U18 -> 33.45 | X18: =IF(L18<0,L18*-1,0) -> 0 | Y18: =W18+X18 -> 33.45 | Z18: 0 | AA18: 66 | AB18: 44 | AC18: =AC17+1 -> 9 | AD18: 390 | AE18: 805 | AF18: 1561.24
A19: =A18+1 -> 10 | B19: 6908.01 | C19: 314095 | D19: =C19-C18 -> 39 | E19: =C19-152000 -> 162095 | F19: =D19/$D$2 -> 19.667171 | G19: 71.058623 | H19: 0 | I19: =G19+H19 -> 71.058623 | J19: =IF(L19>0,L19,0) -> 0 | K19: =I19+J19 -> 71.058623 | L19: =F19-(I19-W19) -> -17.941452 | M19: 3.72 | N19: 0 | O19: =M19-N19 -> 3.72 | P19: 0 | Q19: 0 | R19: =SUM(O19:Q19) -> 3.72 | T19: 0 | U19: 29.73 | V19: =V18-U19 -> 11415.683 | W19: =R19+T19+N19+U19 -> 33.45 | X19: =IF(L19<0,L19*-1,0) -> 17.941452 | Y19: =W19+X19 -> 51.391452 | Z19: 0 | AA19: 66 | AB19: 36 | AC19: =AC18+1 -> 10 | AD19: 437 | AE19: 920 | AF19: 1600.39
A20: =A19+1 -> 11 | B20: 6908.02 | C20: 314135 | D20: =C20-C19 -> 40 | E20: =C20-152000 -> 162135 | F20: =D20/$D$2 -> 20.171457 | G20: 107.44725 | H20: 0 | I20: =G20+H20 -> 107.44725 | J20: =IF(L20>0,L20,0) -> 0 | K20: =I20+J20 -> 107.44725 | L20: =F20-(I20-W20) -> -53.825789 | M20: 3.72 | N20: 0 | O20: =M20-N20 -> 3.72 | P20: 0 | Q20: 0 | R20: =SUM(O20:Q20) -> 3.72 | T20: 0 | U20: 29.73 | V20: =V19-U20 -> 11385.953 | W20: =R20+T20+N20+U20 -> 33.45 | X20: =IF(L20<0,L20*-1,0) -> 53.825789 | Y20: =W20+X20 -> 87.275789 | Z20: 0 | AA20: 68 | AB20: 40 | AC20: =AC19+1 -> 11 | AD20: 498 | AE20: 1048 | AF20: 1642
A21: =A20+1 -> 12 | B21: 6908.04 | C21: 314214 | D21: =C21-C20 -> 79 | E21: =C21-152000 -> 162214 | F21: =D21/$D$2 -> 39.838628 | G21: 52.130025 | H21: 0 | I21: =G21+H21 -> 52.130025 | J21: =IF(L21>0,L21,0) -> 23.378603 | K21: =I21+J21 -> 75.508628 | L21: =F21-(I21-W21) -> 23.378603 | M21: 5.97 | N21: 0 | O21: =M21-N21 -> 5.97 | P21: 0 | Q21: 0 | R21: =SUM(O21:Q21) -> 5.97 | T21: 0 | U21: 29.7 | V21: =V20-U21 -> 11356.253 | W21: =R21+T21+N21+U21 -> 35.67 | X21: =IF(L21<0,L21*-1,0) -> 0 | Y21: =W21+X21 -> 35.67 | Z21: 0 | AA21: 68 | AB21: 42 | AC21: =AC20+1 -> 12 | AD21: 572 | AE21: 1182 | AF21: 1683.42
A22: =A21+1 -> 13 | B22: 6908.05 | C22: 314253 | D22: =C22-C21 -> 39 | E22: =C22-152000 -> 162253 | F22: =D22/$D$2 -> 19.667171 | G22: 34.13 | H22: 0 | I22: =G22+H22 -> 34.13 | J22: =IF(L22>0,L22,0) -> 22.507171 | K22: =I22+J22 -> 56.637171 | L22: =F22-(I22-W22) -> 22.507171 | M22: 7.27 | N22: 0 | O22: =M22-N22 -> 7.27 | P22: 0 | Q22: 0 | R22: =SUM(O22:Q22) -> 7.27 | T22: 0 | U22: 29.7 | V22: =V21-U22 -> 11326.553 | W22: =R22+T22+N22+U22 -> 36.97 | X22: =IF(L22<0,L22*-1,0) -> 0 | Y22: =W22+X22 -> 36.97 | Z22: 0 | AA22: 63 | AB22: 38 | AC22: =AC21+1 -> 13 | AD22: 716 | AE22: 1339 | AF22: 1725.1
... A36: =A35+1 -> 27 | B36: 6908.49 | C36: 315992 | D36: =C36-C35 -> 0 | E36: =C36-152000 -> 163992 | F36: =D36/$D$2 -> 0 | G36: 198.83309 | H36: 0 | I36: =G36+H36 -> 198.83309 | J36: =IF(L36>0,L36,0) -> 0 | K36: =I36+J36 -> 198.83309 | L36: =F36-(I36-W36) -> -166.05309 | M36: 3.08 | N36: 0 | O36: =M36-N36 -> 3.08 | P36: 0 | Q36: 0 | R36: =SUM(O36:Q36) -> 3.08 | T36: 0 | U36: 29.7 | V36: =V35-U36 -> 10910.983 | W36: =R36+T36+N36+U36 -> 32.78 | X36: =IF(L36<0,L36*-1,0) -> 166.05309 | Y36: =W36+X36 -> 198.83309 | Z36: 0 | AA36: 67 | AB36: 40 | AC36: =AC35+1 -> 27 | AD36: 4501 | AE36: 3671 | AF36: 2362.83
A37: 28 | B37: 6908.5 | C37: 316031 | D37: =C37-C35 -> 39 | E37: =C37-152000 -> 164031 | F37: =D37/$D$2 -> 19.667171 | G37: 308.76753 | H37: 0 | I37: =G37+H37 -> 308.76753 | J37: =IF(L37>0,L37,0) -> 0 | K37: =I37+J37 -> 308.76753 | L37: =F37-(I37-W37) -> -255.55036 | M37: 3.94 | N37: 0 | O37: =M37-N37 -> 3.94 | P37: 0 | Q37: 0 | R37: =SUM(O37:Q37) -> 3.94 | T37: 0 | U37: 29.61 | V37: =V35-U37 -> 10911.073 | W37: =R37+T37+N37+U37 -> 33.55 | X37: =IF(L37<0,L37*-1,0) -> 255.55036 | Y37: =W37+X37 -> 289.10036 | Z37: 0 | AA37: 78 | AB37: 45 | AC37: =AC35+1 -> 27 | AD37: 4723
A38: 29 | B38: 6908.52 | C38: 316110 | D38: =C38-C36 -> 118 | E38: =C38-152000 -> 164110 | F38: =D38/$D$2 -> 59.505799 | G38: 308.76753 | H38: 0 | I38: =G38+H38 -> 308.76753 | J38: =IF(L38>0,L38,0) -> 0 | K38: =I38+J38 -> 308.76753 | L38: =F38-(I38-W38) -> -215.40173 | M38: 4.4 | N38: 0 | O38: =M38-N38 -> 4.4 | P38: 0 | Q38: 0 | R38: =SUM(O38:Q38) -> 4.4 | T38: 0 | U38: 29.46 | V38: =V36-U38 -> 10881.523 | W38: =R38+T38+N38+U38 -> 33.86 | X38: =IF(L38<0,L38*-1,0) -> 215.40173 | Y38: =W38+X38 -> 249.26173 | Z38: 0 | AA38: 78 | AB38: 45 | AC38: =AC36+1 -> 28 | AD38: 4723 | AE38: 3836 | AF38: 2362.83
AA39: 73
A40: MONTH / CFS | F40: =SUM(F10:F38) -> 1312.1533 | G40: =SUM(G10:G38) -> 3305.9904 | H40: =SUM(H10:H38) -> 0 | I40: =SUM(I10:I38) -> 3305.9904 | J40: =SUM(J10:J38) -> 299.94328 | K40: =SUM(K10:K38) -> 3605.9337 | L40: =SUM(L10:L38) -> -1003.2071 | M40: =SUM(M10:M38) -> 129.77 | ... R40: =SUM(R10:R38) -> 129.77 | T40: =SUM(T10:T38) -> 0 | U40: =SUM(U10:U38) -> 860.86 | W40: =SUM(W10:W38) -> 990.63 | X40: =SUM(X10:X38) -> 1303.1504 | Y40: =SUM(Y10:Y38) -> 2293.7804 | Z40: =SUM(Z10:Z38) -> 0.69 | AA40: =AVERAGE(AA10:AA38) -> 70.655172 | AB40: =AVERAGE(AB10:AB38) -> 39.793103
A41: MONTH / AF | D41: =SUM(D10:D38) -> 2602 | F41: =F40*$D$2 -> 2602 | G41: =G40*$D$2 -> 6555.779 | H41: =H40*$D$2 -> 0 | I41: =I40*$D$2 -> 6555.779 | J41: =J40*$D$2 -> 594.78753 | K41: =K40*$D$2 -> 7150.5666 | L41: =L40*$D$2 -> -1989.3598 | M41: =M40*$D$2 -> 257.33391 | ... R41: =R40*$D$2 -> 257.33391 | T41: =T40*$D$2 -> 0 | U41: =U40*$D$2 -> 1707.0854 | V41: =V40*$D$2 -> 0 | W41: =W40*$D$2 -> 1964.4193 | X41: =X40*$D$2 -> 2584.1473 | Y41: =Y40*$D$2 -> 4548.5666 | AA41: =MAX(AA10:AA38) -> 80 | AB41: =MAX(AB10:AB38) -> 48 | AC41: HI
A43: SEASON / CFS | AA43: =MIN(AA10:AA38) -> 54 | AB43: =MIN(AB10:AB38) -> 30 | AC43: LO
A44: SEASON / AF
A46: YTD / CFS | F46: =F8+F40 -> 1292.9904 | G46: =G8+G40 -> 9016.7401 | H46: =H8+H40 -> 0 | I46: =I8+I40 -> 9016.6401 | J46: =J8+J40 -> 1238.3302 | K46: =K8+K40 -> 10254.97 | L46: =L8+L40 -> -2751.8797 | M46: =M8+M40 -> 908.13 | ... R46: =R8+R40 -> 784.13 | T46: =T8+T40 -> 0 | U46: =U8+U40 -> 4063.64 | V46: =V38 -> 10881.523 | W46: =W8+W40 -> 4971.77 | X46: =X8+X40 -> 3990.2099 | Y46: =Y8+Y40 -> 8961.9799 | Z46: =Z8+Z40 -> 2.36
A47: YTD / AF | D47: =D8+D41 -> 2564 | E47: =E38 -> 164110 | F47: =F46*$D$2 -> 2564 | G47: =G46*$D$2 -> 17880.196 | H47: =H46*$D$2 -> 0 | I47: =I46*$D$2 -> 17879.997 | J47: =J46*$D$2 -> 2455.6087 | K47: =K46*$D$2 -> 20335.606 | L47: =L46*$D$2 -> -5456.9775 | M47: =M46*$D$2 -> 1800.8218 | ... Y47: =Y46*$D$2 -> 17771.606
A49: ="JUN /9" -> JUN /9
B50: 6924.15 | C50: 381833 | E50: =C50-152000 -> 229833
A51: ="5/12/94 thru 6/9/94" -> 5/12/94 thru 6/9/94
B52: =B50-B21 -> 16.11 | D52: =C50-C22 -> 67580

Sheet MAR
K1: MC PHEE RESERVOIR IN/OUT FLOW TABULATION
A2: AF/cfs CONVERT FACTOR | D2: 1.983 | K2: MARCH "96"
A4: DATE | B4: RESERV | C4: RESERV | D4: AC FT | E4: ACTIVE | F4: CONV TO | G4: DOLORES | H4: LOST | I4: RECORDED | J4: CALC | K4: TOTAL | L4: CALC | M4: DOLORES TUNNEL | P4: LONE | Q4: U | R4: TOTAL | S4: MVI | T4: DV CR | U4: BELOW | V4: REMAIN | W4: RECORDED | X4: CALC | Y4: TOTAL | Z4: RAIN | AA4: MAX | AB4: MIN | AC4: DATE
A5: MAR | B5: ELEV | C5: AC FT | D5: CHANGE | E5: CAP | F5: CFS | G5: RIVER | H5: CANYON | I5: INFLOW | J5: INFLOW | K5: INFLOW | L5: INF/OTF | M5: TOT DIV | N5: UTE F&R | O5: MVI,CTZ | P5: PINE | Q5: LATERAL | R5: MVI | S5: CALL | T5: CANAL | U5: MC PHEE | V5: RELEASE | W5: OUTFLOW | X5: OUTFLOW | Y5: OUTFLOW | AA5: TMP | AB5: TMP | AC5: MAR
AD6: 741 | AE6: 742
A7: SEASON BAL
A8: YTD | B8: {=FEB!$B$38:$C$38} -> 6908.52 | C8: 316110 | D8: {=FEB!$D$47:$E$47} -> 2564 | E8: 164110 | F8: {=FEB!$F$46:$Z$46} -> 1292.9904 | G8: 9016.7401 | H8: 0 | I8: 9016.6401 | J8: 1238.3302 | K8: 10254.97 | L8: -2751.8797 | M8: 908.13 | N8: 0 | O8: 415.63 | P8: 0 | Q8: 0 | R8: 784.13 | S8: 0 | T8: 0 | U8: 4063.64 | V8: 10881.523 | W8: 4971.77 | X8: 3990.2099 | Y8: 8961.9799 | Z8: 2.36 | AD8: 285 | AE8: 251 | AF8: 1207.63
A10: 1 | B10: 6908.54 | C10: 316189 | D10: =C10-C8 -> 79 | E10: =C10-152000 -> 164189 | F10: =D10/$D$2 -> 39.838628 | G10: 69.9 | H10: 3.78 | I10: =G10+H10 -> 73.68 | J10: =IF(L10>0,L10,0) -> 0.028628341 | K10: =I10+J10 -> 73.708628 | L10: =F10-(I10-W10) -> 0.028628341 | M10: 4.4 | N10: 0 | O10: =M10-N10 -> 4.4 | P10: 0 | Q10: 0 | R10: =SUM(O10:Q10) -> 4.4 | T10: 0 | U10: 29.47 | V10: =V8-U10 -> 10852.053 | W10: =R10+T10+N10+U10 -> 33.87 | X10: =IF(L10<0,L10*-1,0) -> 0 | Y10: =W10+X10 -> 33.87 | Z10: 0 | AA10: 39 | AB10: 36 | AC10: 1 | AD10: 303 | AE10: 273 | AF10: 1256.86
