Workbook

Sheet NOV
K1: MC PHEE RESERVOIR IN/OUT FLOW TABULATION
A2: AF/cfs CONVERT FACTOR | D2: 1.9835 | L2: NOVEMBER "1886"
A4: DATE | B4: RESERV | C4: RESERV | D4: AC FT | E4: ACTIVE | F4: CONV TO | G4: DOLORES | H4: LOST | I4: RECORDED | J4: CALC | K4: TOTAL | L4: CALC | M4: TUNNEL | Q4: LONE | R4: U | S4: TOTAL | T4: MVI | U4: DV CR | V4: BELOW | W4: RECORDED | X4: CALC | Y4: TOTAL | Z4: RAIN | AA4: MAX | AB4: MIN | AC4: DATE
A5: "NOV" | B5: ELEV | C5: AC FT | D5: CHANGE | E5: CAP | F5: CFS | G5: RIVER | H5: CANYON | I5: INFLOW | J5: INFLOW | K5: INFLOW | L5: INF/OTF | M5: TOT DIV | N5: WETLAND | O5: UTE F&R | P5: MVI,CTZ | Q5: PINE | R5: LAT | S5: MVI | T5: CALL | U5: CANAL | V5: MC PHEE | W5: OUTFLOW | X5: OUTFLOW | Y5: OUTFLOW | AA5: TMP | AB5: TMP | AC5: "NOV"
A7: SEASON BAL
A8: YTD | B8: 6901.78 | C8: 290193
A10: 1 | B10: 6902.05 | C10: 291203 | D10: =C10-C8 -> 1010 | E10: =C10-152000 -> 139203 | F10: =D10/$D$2 -> 509.20091 | G10: 320 | H10: 29 | I10: =G10+H10 -> 349 | J10: =IF(L10>0,L10,0) -> 365.20091 | K10: =I10+J10 -> 714.20091 | L10: =F10-(I10-W10) -> 365.20091 | M10: 34 | N10: 0 | O10: 0 | P10: =M10-(N10+O10) -> 34 | Q10: 0 | R10: 14 | S10: =SUM(P10:R10) -> 48 | U10: 0 | V10: 157 | W10: =N10+O10+S10+U10+V10 -> 205 | X10: =IF(L10<0,L10*-1,0) -> 0 | Y10: =W10+X10 -> 205 | Z10: 0.3 | AA10: 48 | AB10: 32 | AC10: 1
A11: =A10+1 -> 2 | B11: 6902.2 | C11: 291767 | D11: =C11-C10 -> 564 | E11: =C11-152000 -> 139767 | F11: =D11/$D$2 -> 284.34585 | G11: 302 | H11: 39 | I11: =G11+H11 -> 341 | J11: =IF(L11>0,L11,0) -> 147.34585 | K11: =I11+J11 -> 488.34585 | L11: =F11-(I11-W11) -> 147.34585 | M11: 34 | N11: 0 | O11: 0 | P11: =M11-(N11+O11) -> 34 | Q11: 0 | R11: 14 | S11: =SUM(P11:R11) -> 48 | U11: 0 | V11: 156 | W11: =N11+O11+S11+U11+V11 -> 204 | X11: =IF(L11<0,L11*-1,0) -> 0 | Y11: =W11+X11 -> 204 | Z11: 0.01 | AA11: 44 | AB11: 36 | AC11: =AC10+1 -> 2
A12: =A11+1 -> 3 | B12: 6902.25 | C12: 291955 | D12: =C12-C11 -> 188 | E12: =C12-152000 -> 139955 | F12: =D12/$D$2 -> 94.781951 | G12: 334 | H12: 34 | I12: =G12+H12 -> 368 | J12: =IF(L12>0,L12,0) -> 73.781951 | K12: =I12+J12 -> 441.78195 | L12: =F12-(I12-W12) -> 73.781951 | M12: 34 | N12: 0 | O12: 0 | P12: =M12-(N12+O12) -> 34 | Q12: 0 | R12: 14 | S12: =SUM(P12:R12) -> 48 | U12: 0 | V12: 299 | W12: =N12+O12+S12+U12+V12 -> 347 | X12: =IF(L12<0,L12*-1,0) -> 0 | Y12: =W12+X12 -> 347 | Z12: 0 | AA12: 45 | AB12: 30 | AC12: =AC11+1 -> 3
A13: =A12+1 -> 4 | B13: 6902.23 | C13: 291880 | D13: =C13-C12 -> -75 | E13: =C13-152000 -> 139880 | F13: =D13/$D$2 -> -37.811949 | G13: 345 | H13: 35 | I13: =G13+H13 -> 380 | J13: =IF(L13>0,L13,0) -> 72.188051 | K13: =I13+J13 -> 452.18805 | L13: =F13-(I13-W13) -> 72.188051 | M13: 35 | N13: 0 | O13: 0 | P13: =M13-(N13+O13) -> 35 | Q13: 0 | R13: 13 | S13: =SUM(P13:R13) -> 48 | U13: 0 | V13: 442 | W13: =N13+O13+S13+U13+V13 -> 490 | X13: =IF(L13<0,L13*-1,0) -> 0 | Y13: =W13+X13 -> 490 | Z13: 0 | AA13: 46 | AB13: 29 | AC13: =AC12+1 -> 4
A14: =A13+1 -> 5 | B14: 6902.17 | C14: 291654 | D14: =C14-C13 -> -226 | E14: =C14-152000 -> 139654 | F14: =D14/$D$2 -> -113.94001 | G14: 323 | H14: 33 | I14: =G14+H14 -> 356 | J14: =IF(L14>0,L14,0) -> 40.059995 | K14: =I14+J14 -> 396.05999 | L14: =F14-(I14-W14) -> 40.059995 | M14: 34 | N14: 0 | O14: 0 | P14: =M14-(N14+O14) -> 34 | Q14: 0 | R14: 14 | S14: =SUM(P14:R14) -> 48 | U14: 0 | V14: 462 | W14: =N14+O14+S14+U14+V14 -> 510 | X14: =IF(L14<0,L14*-1,0) -> 0 | Y14: =W14+X14 -> 510 | Z14: 0 | AA14: 50 | AB14: 23 | AC14: =AC13+1 -> 5
A15: =A14+1 -> 6 | B15: 6902.12 | C15: 291466 | D15: =C15-C14 -> -188 | E15: =C15-152000 -> 139466 | F15: =D15/$D$2 -> -94.781951 | G15: 330 | H15: 30 | I15: =G15+H15 -> 360 | J15: =IF(L15>0,L15,0) -> 56.218049 | K15: =I15+J15 -> 416.21805 | L15: =F15-(I15-W15) -> 56.218049 | M15: 34 | N15: 0 | O15: 0 | P15: =M15-(N15+O15) -> 34 | Q15: 0 | R15: 14 | S15: =SUM(P15:R15) -> 48 | U15: 1 | V15: 462 | W15: =N15+O15+S15+U15+V15 -> 511 | X15: =IF(L15<0,L15*-1,0) -> 0 | Y15: =W15+X15 -> 511 | Z15: 0.28 | AA15: 50 | AB15: 27 | AC15: =AC14+1 -> 6
A16: =A15+1 -> 7 | B16: 6902 | C16: 291014 | D16: =C16-C15 -> -452 | E16: =C16-152000 -> 139014 | F16: =D16/$D$2 -> -227.88001 | G16: 329 | H16: 28 | I16: =G16+H16 -> 357 | J16: =IF(L16>0,L16,0) -> 0 | K16: =I16+J16 -> 357 | L16: =F16-(I16-W16) -> -77.88001 | M16: 31 | N16: 0 | O16: 0 | P16: =M16-(N16+O16) -> 31 | Q16: 0 | R16: 14 | S16: =SUM(P16:R16) -> 45 | U16: 0 | V16: 462 | W16: =N16+O16+S16+U16+V16 -> 507 | X16: =IF(L16<0,L16*-1,0) -> 77.88001 | Y16: =W16+X16 -> 584.88001 | Z16: 0.01 | AA16: 30 | AB16: 14 | AC16: =AC15+1 -> 7
A17: =A16+1 -> 8 | B17: 6901.95 | C17: 290828 | D17: =C17-C16 -> -186 | E17: =C17-152000 -> 138828 | F17: =D17/$D$2 -> -93.773632 | G17: 293 | H17: 21 | I17: =G17+H17 -> 314 | J17: =IF(L17>0,L17,0) -> 97.226368 | K17: =I17+J17 -> 411.22637 | L17: =F17-(I17-W17) -> 97.226368 | M17: 30 | N17: 0 | O17: 0 | P17: =M17-(N17+O17) -> 30 | Q17: 0 | R17: 13 | S17: =SUM(P17:R17) -> 43 | U17: 0 | V17: 462 | W17: =N17+O17+S17+U17+V17 -> 505 | X17: =IF(L17<0,L17*-1,0) -> 0 | Y17: =W17+X17 -> 505 | Z17: 0 | AA17: 28 | AB17: 10 | AC17: =AC16+1 -> 8
A18: =A17+1 -> 9 | B18: 6901.87 | C18: 290529 | D18: =C18-C17 -> -299 | E18: =C18-152000 -> 138529 | F18: =D18/$D$2 -> -150.74363 | G18: 311 | H18: 26 | I18: =G18+H18 -> 337 | J18: =IF(L18>0,L18,0) -> 16.256365 | K18: =I18+J18 -> 353.25637 | L18: =F18-(I18-W18) -> 16.256365 | M18: 30 | N18: 0 | O18: 0 | P18: =M18-(N18+O18) -> 30 | Q18: 0 | R18: 13 | S18: =SUM(P18:R18) -> 43 | U18: 0 | V18: 461 | W18: =N18+O18+S18+U18+V18 -> 504 | X18: =IF(L18<0,L18*-1,0) -> 0 | Y18: =W18+X18 -> 504 | Z18: 0 | AA18: 34 | AB18: 16 | AC18: =AC17+1 -> 9
A19: =A18+1 -> 10 | B19: 6901.78 | C19: 290193 | D19: =C19-C18 -> -336 | E19: =C19-152000 -> 138193 | F19: =D19/$D$2 -> -169.39753 | G19: 250 | H19: 28 | I19: =G19+H19 -> 278 | J19: =IF(L19>0,L19,0) -> 0 | K19: =I19+J19 -> 278 | L19: =F19-(I19-W19) -> -157.39753 | M19: 30 | N19: 0 | O19: 0 | P19: =M19-(N19+O19) -> 30 | Q19: 0 | R19: 13 | S19: =SUM(P19:R19) -> 43 | U19: 0 | V19: 247 | W19: =N19+O19+S19+U19+V19 -> 290 | X19: =IF(L19<0,L19*-1,0) -> 157.39753 | Y19: =W19+X19 -> 447.39753 | Z19: 0 | AA19: 36 | AB19: 9 | AC19: =AC18+1 -> 10
A20: =A19+1 -> 11 | B20: 6901.89 | C20: 290604 | D20: =C20-C19 -> 411 | E20: =C20-152000 -> 138604 | F20: =D20/$D$2 -> 207.20948 | G20: 223 | H20: 29 | I20: =G20+H20 -> 252 | J20: =IF(L20>0,L20,0) -> 87.209478 | K20: =I20+J20 -> 339.20948 | L20: =F20-(I20-W20) -> 87.209478 | M20: 19 | N20: 0 | O20: 0 | P20: =M20-(N20+O20) -> 19 | Q20: 0 | R20: 13 | S20: =SUM(P20:R20) -> 32 | U20: 0 | V20: 100 | W20: =N20+O20+S20+U20+V20 -> 132 | X20: =IF(L20<0,L20*-1,0) -> 0 | Y20: =W20+X20 -> 132 | Z20: 0 | AA20: 44 | AB20: 12 | AC20: =AC19+1 -> 11
A21: =A20+1 -> 12 | B21: 6902 | C21: 291014 | D21: =C21-C20 -> 410 | E21: =C21-152000 -> 139014 | F21: =D21/$D$2 -> 206.70532 | G21: 268 | H21: 26 | I21: =G21+H21 -> 294 | J21: =IF(L21>0,L21,0) -> 42.705319 | K21: =I21+J21 -> 336.70532 | L21: =F21-(I21-W21) -> 42.705319 | M21: 16 | N21: 0 | O21: 0 | P21: =M21-(N21+O21) -> 16 | Q21: 0 | R21: 14 | S21: =SUM(P21:R21) -> 30 | U21: 0 | V21: 100 | W21: =N21+O21+S21+U21+V21 -> 130 | X21: =IF(L21<0,L21*-1,0) -> 0 | Y21: =W21+X21 -> 130 | Z21: 0 | AA21: 57 | AB21: 19 | AC21: =AC20+1 -> 12
A22: =A21+1 -> 13 | B22: 6902.08 | C22: 291315 | D22: =C22-C21 -> 301 | E22: =C22-152000 -> 139315 | F22: =D22/$D$2 -> 151.75195 | G22: 260 | H22: 22 | I22: =G22+H22 -> 282 | J22: =IF(L22>0,L22,0) -> 28.751954 | K22: =I22+J22 -> 310.75195 | L22: =F22-(I22-W22) -> 28.751954 | M22: 21 | N22: 0 | O22: 0 | P22: =M22-(N22+O22) -> 21 | Q22: 0 | R22: 13 | S22: =SUM(P22:R22) -> 34 | U22: 0 | V22: 125 | W22: =N22+O22+S22+U22+V22 -> 159 | X22: =IF(L22<0,L22*-1,0) -> 0 | Y22: =W22+X22 -> 159 | Z22: 0 | AA22: 59 | AB22: 20 | AC22: =AC21+1 -> 13
... A38: =A37+1 -> 29 | B38: 6902.87 | C38: 294288 | D38: =C38-C37 -> 0 | E38: =C38-152000 -> 142288 | F38: =D38/$D$2 -> 0 | G38: 313 | H38: 34 | I38: =G38+H38 -> 347 | J38: =IF(L38>0,L38,0) -> 1 | K38: =I38+J38 -> 348 | L38: =F38-(I38-W38) -> 1 | M38: 24 | N38: 0 | O38: 0 | P38: =M38-(N38+O38) -> 24 | Q38: 0 | R38: 11 | S38: =SUM(P38:R38) -> 35 | U38: 0 | V38: 313 | W38: =N38+O38+S38+U38+V38 -> 348 | X38: =IF(L38<0,L38*-1,0) -> 0 | Y38: =W38+X38 -> 348 | Z38: 0 | AA38: 44 | AB38: 28 | AC38: =AC37+1 -> 29
A39: 30 | B39: 6902.88 | C39: 294326 | D39: =C39-C38 -> 38 | E39: =C39-152000 -> 142326 | F39: =D39/$D$2 -> 19.158054 | G39: 323 | H39: 29 | I39: =G39+H39 -> 352 | J39: =IF(L39>0,L39,0) -> 15.158054 | K39: =I39+J39 -> 367.15805 | L39: =F39-(I39-W39) -> 15.158054 | M39: 24 | N39: 0 | O39: 0 | P39: =M39-(N39+O39) -> 24 | Q39: 0 | R39: 11 | S39: =SUM(P39:R39) -> 35 | U39: 0 | V39: 313 | W39: =N39+O39+S39+U39+V39 -> 348 | X39: =IF(L39<0,L39*-1,0) -> 0 | Y39: =W39+X39 -> 348 | Z39: 0 | AA39: 36 | AB39: 24 | AC39: 30
A41: MONTH / CFS | F41: =SUM(F10:F39) -> 2083.6904 | G41: =SUM(G10:G39) -> 9938 | H41: =SUM(H10:H39) -> 1326 | I41: =SUM(I10:I39) -> 11264 | J41: =SUM(J10:J39) -> 2833.4038 | K41: =SUM(K10:K39) -> 14097.404 | L41: =SUM(L10:L39) -> 2473.6904 | M41: =SUM(M10:M39) -> 789 | ... S41: =SUM(S10:S39) -> 1792 | U41: =SUM(U10:U39) -> 1 | V41: =SUM(V10:V39) -> 9861 | W41: =SUM(W10:W39) -> 11654 | X41: =SUM(X10:X39) -> 359.71339 | Y41: =SUM(Y10:Y39) -> 12013.713 | Z41: =SUM(Z10:Z39) -> 2.06 | AA41: =AVERAGE(AA10:AA39) -> 44.1 | AB41: =AVERAGE(AB10:AB39) -> 22.966667 | AC41: Avg
A42: MONTH / AF | D42: =SUM(D10:D39) -> 4133 | F42: =F41*$D$2 -> 4133 | G42: =G41*$D$2 -> 19712.023 | H42: =H41*$D$2 -> 2630.121 | I42: =I41*$D$2 -> 22342.144 | J42: =J41*$D$2 -> 5620.0565 | K42: =K41*$D$2 -> 27962.2 | L42: =L41*$D$2 -> 4906.565 | M42: =M41*$D$2 -> 1564.9815 | ... S42: =S41*$D$2 -> 3554.432 | U42: =U41*$D$2 -> 1.9835 | V42: =V41*$D$2 -> 19559.293 | W42: =W41*$D$2 -> 23115.709 | X42: =X41*$D$2 -> 713.4915 | Y42: =Y41*$D$2 -> 23829.2 | AA42: =MAX(AA10:AA39) -> 59 | AB42: =MAX(AB10:AB39) -> 36 | AC42: HI
A44: SEASON / CFS | AA44: =MIN(AA10:AA39) -> 28 | AB44: =MIN(AB10:AB39) -> 9 | AC44: LO
A45: SEASON / AF
A47: YTD / CFS | F47: =F8+F41 -> 2083.6904 | G47: =G8+G41 -> 9938 | H47: =H8+H41 -> 1326 | I47: =I8+I41 -> 11264 | J47: =J8+J41 -> 2833.4038 | K47: =K8+K41 -> 14097.404 | L47: =L8+L41 -> 2473.6904 | M47: =M8+M41 -> 789 | ... S47: =S8+S41 -> 1792 | U47: =U8+U41 -> 1 | V47: =V8+V41 -> 9861 | W47: =W8+W41 -> 11654 | X47: =X8+X41 -> 359.71339 | Y47: =Y8+Y41 -> 12013.713 | Z47: =Z8+Z41 -> 2.06
A48: YTD / AF | D48: =D8+D42 -> 4133 | E48: =E39 -> 142326 | F48: =F47*$D$2 -> 4133 | G48: =G47*$D$2 -> 19712.023 | H48: =H47*$D$2 -> 2630.121 | I48: =I47*$D$2 -> 22342.144 | J48: =J47*$D$2 -> 5620.0565 | K48: =K47*$D$2 -> 27962.2 | L48: =L47*$D$2 -> 4906.565 | M48: =M47*$D$2 -> 1564.9815 | ... Y48: =Y47*$D$2 -> 23829.2

Sheet DEC
K1: MC PHEE RESERVOIR IN/OUT FLOW TABULATION
A2: AF/cfs CONVERT FACTOR | D2: 1.9835 | K2: DECEMBER "1886"
A4: DATE | B4: RESERV | C4: RESERV | D4: AC FT | E4: ACTIVE | F4: CONV TO | G4: DOLORES | H4: LOST | I4: RECORDED | J4: CALC | K4: TOTAL | L4: CALC | M4: TUNNEL | Q4: LONE | R4: U | S4: TOTAL | T4: MVI | U4: DV CR | V4: BELOW | W4: RECORDED | X4: CALC | Y4: TOTAL | Z4: RAIN | AA4: MAX | AB4: MIN | AC4: DATE
A5: "DEC" | B5: ELEV | C5: AC FT | D5: CHANGE | E5: CAP | F5: CFS | G5: RIVER | H5: CANYON | I5: INFLOW | J5: INFLOW | K5: INFLOW | L5: INF/OTF | M5: TOT DIV | N5: WETLAND | O5: UTE F&R | P5: MVI,CTZ | Q5: PINE | R5: LAT | S5: MVI | T5: CALL | U5: CANAL | V5: MC PHEE | W5: OUTFLOW | X5: OUTFLOW | Y5: OUTFLOW | AA5: TMP | AB5: TMP | AC5: "DEC"
A7: SEASON BAL
A8: YTD | B8: =NOV!B39 -> 6902.88 | C8: =NOV!C39 -> 294326 | D8: =NOV!$D$48 -> 4133 | E8: =NOV!$E$39 -> 142326 | F8: =NOV!F47 -> 2083.6904 | G8: =NOV!G47 -> 9938 | H8: =NOV!H47 -> 1326 | I8: =NOV!I47 -> 11264 | J8: =NOV!J47 -> 2833.4038 | K8: =NOV!K47 -> 14097.404 | L8: =NOV!L47 -> 2473.6904 | M8: =NOV!M47 -> 789 | ... Z8: =NOV!Z47 -> 2.06
A10: 1 | B10: 6902.84 | C10: 294175 | D10: =C10-C8 -> -151 | E10: =C10-152000 -> 142175 | F10: =D10/$D$2 -> -76.128056 | G10: 247 | H10: 25 | I10: =G10+H10 -> 272 | J10: =IF(L10>0,L10,0) -> 0 | K10: =I10+J10 -> 272 | L10: =F10-(I10-W10) -> -2.1280565 | M10: 24 | N10: 0 | O10: 0 | P10: =M10-(N10+O10) -> 24 | Q10: 0 | R10: 10 | S10: =SUM(P10:R10) -> 34 | U10: 0 | V10: 312 | W10: =N10+O10+S10+U10+V10 -> 346 | X10: =IF(L10<0,L10*-1,0) -> 2.1280565 | Y10: =W10+X10 -> 348.12806 | Z10: 0 | AA10: 46 | AB10: 22 | AC10: 1
A11: =A10+1 -> 2 | B11: 6902.8 | C11: 294025 | D11: =C11-C10 -> -150 | E11: =C11-152000 -> 142025 | F11: =D11/$D$2 -> -75.623897 | G11: 250 | H11: 30 | I11: =G11+H11 -> 280 | J11: =IF(L11>0,L11,0) -> 0 | K11: =I11+J11 -> 280 | L11: =F11-(I11-W11) -> -7.6238972 | M11: 24 | N11: 0 | O11: 0 | P11: =M11-(N11+O11) -> 24 | Q11: 0 | R11: 11 | S11: =SUM(P11:R11) -> 35 | U11: 0 | V11: 313 | W11: =N11+O11+S11+U11+V11 -> 348 | X11: =IF(L11<0,L11*-1,0) -> 7.6238972 | Y11: =W11+X11 -> 355.6239 | Z11: 0 | AA11: 45 | AB11: 15 | AC11: =AC10+1 -> 2
A12: =A11+1 -> 3 | B12: 6902.82 | C12: 294100 | D12: =C12-C11 -> 75 | E12: =C12-152000 -> 142100 | F12: =D12/$D$2 -> 37.811949 | G12: 261 | H12: 30 | I12: =G12+H12 -> 291 | J12: =IF(L12>0,L12,0) -> 94.811949 | K12: =I12+J12 -> 385.81195 | L12: =F12-(I12-W12) -> 94.811949 | M12: 24 | N12: 0 | O12: 0 | P12: =M12-(N12+O12) -> 24 | Q12: 0 | R12: 11 | S12: =SUM(P12:R12) -> 35 | U12: 0 | V12: 313 | W12: =N12+O12+S12+U12+V12 -> 348 | X12: =IF(L12<0,L12*-1,0) -> 0 | Y12: =W12+X12 -> 348 | Z12: 0 | AA12: 46 | AB12: 21 | AC12: =AC11+1 -> 3
A13: =A12+1 -> 4 | B13: 6902.77 | C13: 293912 | D13: =C13-C12 -> -188 | E13: =C13-152000 -> 141912 | F13: =D13/$D$2 -> -94.781951 | G13: 269 | H13: 27 | I13: =G13+H13 -> 296 | J13: =IF(L13>0,L13,0) -> 0 | K13: =I13+J13 -> 296 | L13: =F13-(I13-W13) -> -42.781951 | M13: 24 | N13: 0 | O13: 0 | P13: =M13-(N13+O13) -> 24 | Q13: 0 | R13: 11 | S13: =SUM(P13:R13) -> 35 | U13: 0 | V13: 313 | W13: =N13+O13+S13+U13+V13 -> 348 | X13: =IF(L13<0,L13*-1,0) -> 42.781951 | Y13: =W13+X13 -> 390.78195 | Z13: 0 | AA13: 46 | AB13: 22 | AC13: =AC12+1 -> 4
A14: =A13+1 -> 5 | B14: 6902.77 | C14: 293912 | D14: =C14-C13 -> 0 | E14: =C14-152000 -> 141912 | F14: =D14/$D$2 -> 0 | G14: 271 | H14: 24 | I14: =G14+H14 -> 295 | J14: =IF(L14>0,L14,0) -> 53 | K14: =I14+J14 -> 348 | L14: =F14-(I14-W14) -> 53 | M14: 24 | N14: 0 | O14: 0 | P14: =M14-(N14+O14) -> 24 | Q14: 0 | R14: 11 | S14: =SUM(P14:R14) -> 35 | U14: 0 | V14: 313 | W14: =N14+O14+S14+U14+V14 -> 348 | X14: =IF(L14<0,L14*-1,0) -> 0 | Y14: =W14+X14 -> 348 | Z14: 0 | AA14: 48 | AB14: 29 | AC14: =AC13+1 -> 5
A15: =A14+1 -> 6 | B15: 6902.76 | C15: 293874 | D15: =C15-C14 -> -38 | E15: =C15-152000 -> 141874 | F15: =D15/$D$2 -> -19.158054 | G15: 266 | H15: 19 | I15: =G15+H15 -> 285 | J15: =IF(L15>0,L15,0) -> 31.841946 | K15: =I15+J15 -> 316.84195 | L15: =F15-(I15-W15) -> 31.841946 | M15: 15 | N15: 0 | O15: 0 | P15: =M15-(N15+O15) -> 15 | Q15: 0 | R15: 8 | S15: =SUM(P15:R15) -> 23 | U15: 0 | V15: 313 | W15: =N15+O15+S15+U15+V15 -> 336 | X15: =IF(L15<0,L15*-1,0) -> 0 | Y15: =W15+X15 -> 336 | Z15: 0.57 | AA15: 32 | AB15: 30 | AC15: =AC14+1 -> 6
A16: =A15+1 -> 7 | B16: 6902.76 | C16: 293874 | D16: =C16-C15 -> 0 | E16: =C16-152000 -> 141874 | F16: =D16/$D$2 -> 0 | G16: 252 | H16: 18 | I16: =G16+H16 -> 270 | J16: =IF(L16>0,L16,0) -> 52 | K16: =I16+J16 -> 322 | L16: =F16-(I16-W16) -> 52 | M16: 9 | N16: 0 | O16: 0 | P16: =M16-(N16+O16) -> 9 | Q16: 0 | R16: 0 | S16: =SUM(P16:R16) -> 9 | U16: 0 | V16: 313 | W16: =N16+O16+S16+U16+V16 -> 322 | X16: =IF(L16<0,L16*-1,0) -> 0 | Y16: =W16+X16 -> 322 | Z16: 0 | AA16: 40 | AB16: 27 | AC16: =AC15+1 -> 7
A17: =A16+1 -> 8 | B17: 6902.74 | C17: 293799 | D17: =C17-C16 -> -75 | E17: =C17-152000 -> 141799 | F17: =D17/$D$2 -> -37.811949 | G17: 225 | H17: 18 | I17: =G17+H17 -> 243 | J17: =IF(L17>0,L17,0) -> 39.188051 | K17: =I17+J17 -> 282.18805 | L17: =F17-(I17-W17) -> 39.188051 | M17: 7 | N17: 0 | O17: 0 | P17: =M17-(N17+O17) -> 7 | Q17: 0 | R17: 0 | S17: =SUM(P17:R17) -> 7 | U17: 0 | V17: 313 | W17: =N17+O17+S17+U17+V17 -> 320 | X17: =IF(L17<0,L17*-1,0) -> 0 | Y17: =W17+X17 -> 320 | Z17: 0 | AA17: 35 | AB17: 23 | AC17: =AC16+1 -> 8
A18: =A17+1 -> 9 | B18: 6902.72 | C18: 293724 | D18: =C18-C17 -> -75 | E18: =C18-152000 -> 141724 | F18: =D18/$D$2 -> -37.811949 | G18: 229 | H18: 17 | I18: =G18+H18 -> 246 | J18: =IF(L18>0,L18,0) -> 0 | K18: =I18+J18 -> 246 | L18: =F18-(I18-W18) -> -147.81195 | M18: 5 | N18: 0 | O18: 0 | P18: =M18-(N18+O18) -> 5 | Q18: 0 | R18: 0 | S18: =SUM(P18:R18) -> 5 | U18: 0 | V18: 131 | W18: =N18+O18+S18+U18+V18 -> 136 | X18: =IF(L18<0,L18*-1,0) -> 147.81195 | Y18: =W18+X18 -> 283.81195 | Z18: 0 | AA18: 26 | AB18: 20 | AC18: =AC17+1 -> 9
A19: =A18+1 -> 10 | B19: 6902.69 | C19: 293611 | D19: =C19-C18 -> -113 | E19: =C19-152000 -> 141611 | F19: =D19/$D$2 -> -56.970003 | G19: 149 | H19: 16 | I19: =G19+H19 -> 165 | J19: =IF(L19>0,L19,0) -> 8.0299975 | K19: =I19+J19 -> 173.03 | L19: =F19-(I19-W19) -> 8.0299975 | M19: 4 | N19: 0 | O19: 0 | P19: =M19-(N19+O19) -> 4 | Q19: 0 | R19: 0 | S19: =SUM(P19:R19) -> 4 | U19: 0 | V19: 226 | W19: =N19+O19+S19+U19+V19 -> 230 | X19: =IF(L19<0,L19*-1,0) -> 0 | Y19: =W19+X19 -> 230 | Z19: 0 | AA19: 26 | AB19: 4 | AC19: =AC18+1 -> 10
A20: =A19+1 -> 11 | B20: 6902.67 | C20: 293536 | D20: =C20-C19 -> -75 | E20: =C20-152000 -> 141536 | F20: =D20/$D$2 -> -37.811949 | G20: 130 | H20: 12 | I20: =G20+H20 -> 142 | J20: =IF(L20>0,L20,0) -> 3.1880514 | K20: =I20+J20 -> 145.18805 | L20: =F20-(I20-W20) -> 3.1880514 | M20: 4 | N20: 0 | O20: 0 | P20: =M20-(N20+O20) -> 4 | Q20: 0 | R20: 0 | S20: =SUM(P20:R20) -> 4 | U20: 0 | V20: 179 | W20: =N20+O20+S20+U20+V20 -> 183 | X20: =IF(L20<0,L20*-1,0) -> 0 | Y20: =W20+X20 -> 183 | Z20: 0 | AA20: 32 | AB20: 4 | AC20: =AC19+1 -> 11
A21: =A20+1 -> 12 | B21: 6902.67 | C21: 293536 | D21: =C21-C20 -> 0 | E21: =C21-152000 -> 141536 | F21: =D21/$D$2 -> 0 | G21: 180 | H21: 18 | I21: =G21+H21 -> 198 | J21: =IF(L21>0,L21,0) -> 0 | K21: =I21+J21 -> 198 | L21: =F21-(I21-W21) -> -15 | M21: 4 | N21: 0 | O21: 0 | P21: =M21-(N21+O21) -> 4 | Q21: 0 | R21: 0 | S21: =SUM(P21:R21) -> 4 | U21: 0 | V21: 179 | W21: =N21+O21+S21+U21+V21 -> 183 | X21: =IF(L21<0,L21*-1,0) -> 15 | Y21: =W21+X21 -> 198 | Z21: 0 | AA21: 45 | AB21: 8 | AC21: =AC20+1 -> 12
A22: =A21+1 -> 13 | B22: 6902.68 | C22: 293573 | D22: =C22-C21 -> 37 | E22: =C22-152000 -> 141573 | F22: =D22/$D$2 -> 18.653895 | G22: 209 | H22: 16 | I22: =G22+H22 -> 225 | J22: =IF(L22>0,L22,0) -> 0 | K22: =I22+J22 -> 225 | L22: =F22-(I22-W22) -> -23.346105 | M22: 4 | N22: 0 | O22: 0 | P22: =M22-(N22+O22) -> 4 | Q22: 0 | R22: 0 | S22: =SUM(P22:R22) -> 4 | U22: 0 | V22: 179 | W22: =N22+O22+S22+U22+V22 -> 183 | X22: =IF(L22<0,L22*-1,0) -> 23.346105 | Y22: =W22+X22 -> 206.34611 | Z22: 0 | AA22: 46 | AB22: 11 | AC22: =AC21+1 -> 13
... A38: =A37+1 -> 29 | B38: 6902.65 | C38: 293460 | D38: =C38-C37 -> 75 | E38: =C38-152000 -> 141460 | F38: =D38/$D$2 -> 37.811949 | G38: 177 | H38: 10 | I38: =G38+H38 -> 187 | J38: =IF(L38>0,L38,0) -> 0 | K38: =I38+J38 -> 187 | L38: =F38-(I38-W38) -> -0.18805142 | M38: 4 | N38: 0 | O38: 0 | P38: =M38-(N38+O38) -> 4 | Q38: 0 | R38: 0 | S38: =SUM(P38:R38) -> 4 | U38: 0 | V38: 145 | W38: =N38+O38+S38+U38+V38 -> 149 | X38: =IF(L38<0,L38*-1,0) -> 0.18805142 | Y38: =W38+X38 -> 149.18805 | Z38: 0 | AA38: 40 | AB38: 12 | AC38: =AC37+1 -> 29
A39: 30 | B39: 6902.64 | C39: 293423 | D39: =C39-C38 -> -37 | E39: =C39-152000 -> 141423 | F39: =D39/$D$2 -> -18.653895 | G39: 96 | H39: 11 | I39: =G39+H39 -> 107 | J39: =IF(L39>0,L39,0) -> 0.34610537 | K39: =I39+J39 -> 107.34611 | L39: =F39-(I39-W39) -> 0.34610537 | M39: 4 | N39: 0 | O39: 0 | P39: =M39-(N39+O39) -> 4 | Q39: 0 | R39: 0 | S39: =SUM(P39:R39) -> 4 | U39: 0 | V39: 122 | W39: =N39+O39+S39+U39+V39 -> 126 | X39: =IF(L39<0,L39*-1,0) -> 0 | Y39: =W39+X39 -> 126 | Z39: 0 | AA39: 40 | AB39: 14 | AC39: 30
A40: 31 | B40: 6902.63 | C40: 293385 | D40: =C40-C39 -> -38 | E40: =C40-152000 -> 141385 | F40: =D40/$D$2 -> -19.158054 | G40: 100 | H40: 7 | I40: =G40+H40 -> 107 | J40: =IF(L40>0,L40,0) -> 0 | K40: =I40+J40 -> 107 | L40: =F40-(I40-W40) -> -0.15805395 | M40: 4 | N40: 0 | O40: 0 | P40: =M40-(N40+O40) -> 4 | Q40: 0 | R40: 0 | S40: =SUM(P40:R40) -> 4 | U40: 0 | V40: 122 | W40: =N40+O40+S40+U40+V40 -> 126 | X40: =IF(L40<0,L40*-1,0) -> 0.15805395 | Y40: =W40+X40 -> 126.15805 | Z40: 0 | AA40: 38 | AB40: 11 | AC40: 31
A42: MONTH / CFS | F42: =SUM(F10:F40) -> -474.41391 | G42: =SUM(G10:G40) -> 6146 | H42: =SUM(H10:H40) -> 465 | I42: =SUM(I10:I40) -> 6611 | J42: =SUM(J10:J40) -> 352.3761 | K42: =SUM(K10:K40) -> 6963.3761 | L42: =SUM(L10:L40) -> -284.41391 | M42: =SUM(M10:M40) -> 245 | ... S42: =SUM(S10:S40) -> 307 | U42: =SUM(U10:U40) -> 0 | V42: =SUM(V10:V40) -> 6494 | W42: =SUM(W10:W40) -> 6801 | X42: =SUM(X10:X40) -> 636.79002 | Y42: =SUM(Y10:Y40) -> 7437.79 | Z42: =SUM(Z10:Z40) -> 0.57 | AA42: =AVERAGE(AA10:AA40) -> 39.354839 | AB42: =AVERAGE(AB10:AB40) -> 17.064516 | AC42: Avg
A43: MONTH / AF | D43: =SUM(D10:D40) -> -941 | F43: =F42*$D$2 -> -941 | G43: =G42*$D$2 -> 12190.591 | H43: =H42*$D$2 -> 922.3275 | I43: =I42*$D$2 -> 13112.918 | J43: =J42*$D$2 -> 698.938 | K43: =K42*$D$2 -> 13811.856 | L43: =L42*$D$2 -> -564.135 | M43: =M42*$D$2 -> 485.9575 | ... S43: =S42*$D$2 -> 608.9345 | U43: =U42*$D$2 -> 0 | V43: =V42*$D$2 -> 12880.849 | W43: =W42*$D$2 -> 13489.783 | X43: =X42*$D$2 -> 1263.073 | Y43: =Y42*$D$2 -> 14752.856 | AA43: =MAX(AA10:AA40) -> 48 | AB43: =MAX(AB10:AB40) -> 30 | AC43: HI
A45: SEASON / CFS | AA45: =MIN(AA10:AA40) -> 26 | AB45: =MIN(AB10:AB40) -> 4 | AC45: LO
A46: SEASON / AF
A48: YTD / CFS | F48: =F8+F42 -> 1609.2765 | G48: =G8+G42 -> 16084 | H48: =H8+H42 -> 1791 | I48: =I8+I42 -> 17875 | J48: =J8+J42 -> 3185.7799 | K48: =K8+K42 -> 21060.78 | L48: =L8+L42 -> 2189.2765 | M48: =M8+M42 -> 1034 | ... S48: =S8+S42 -> 2099 | U48: =U8+U42 -> 1 | V48: =V8+V42 -> 16355 | W48: =W8+W42 -> 18455 | X48: =X8+X42 -> 996.5034 | Y48: =Y8+Y42 -> 19451.503 | Z48: =Z8+Z42 -> 2.63
A49: YTD / AF | D49: =D8+D43 -> 3192 | E49: =E40 -> 141385 | F49: =F48*$D$2 -> 3192 | G49: =G48*$D$2 -> 31902.614 | H49: =H48*$D$2 -> 3552.4485 | I49: =I48*$D$2 -> 35455.062 | J49: =J48*$D$2 -> 6318.9945 | K49: =K48*$D$2 -> 41774.057 | L49: =L48*$D$2 -> 4342.43 | M49: =M48*$D$2 -> 2050.939 | ... Y49: =Y48*$D$2 -> 38582.057

Sheet JAN
K1: MC PHEE RESERVOIR IN/OUT FLOW TABULATION
A2: AF/cfs CONVERT FACTOR | D2: 1.9835 | K2: JANUARY "1887"
A4: DATE | B4: RESERV | C4: RESERV | D4: AC FT | E4: ACTIVE | F4: CONV TO | G4: DOLORES | H4: LOST | I4: RECORDED | J4: CALC | K4: TOTAL | L4: CALC | M4: TUNNEL | Q4: LONE | R4: U | S4: TOTAL | T4: MVI | U4: DV CR | V4: BELOW | W4: RECORDED | X4: CALC | Y4: TOTAL | Z4: RAIN | AA4: MAX | AB4: MIN | AC4: DATE
A5: "JAN" | B5: ELEV | C5: AC FT | D5: CHANGE | E5: CAP | F5: CFS | G5: RIVER | H5: CANYON | I5: INFLOW | J5: INFLOW | K5: INFLOW | L5: INF/OTF | M5: TOT DIV | N5: WETLAND | O5: UTE F&R | P5: MVI,CTZ | Q5: PINE | R5: LAT | S5: MVI | T5: CALL | U5: CANAL | V5: MC PHEE | W5: OUTFLOW | X5: OUTFLOW | Y5: OUTFLOW | AA5: TMP | AB5: TMP | AC5: "JAN"
A7: SEASON BAL
A8: YTD | B8: =DEC!B40 -> 6902.63 | C8: =DEC!C40 -> 293385 | D8: =DEC!$D$49 -> 3192 | E8: =DEC!$E$40 -> 141385 | F8: =DEC!F48 -> 1609.2765 | G8: =DEC!G48 -> 16084 | H8: =DEC!H48 -> 1791 | I8: =DEC!I48 -> 17875 | J8: =DEC!J48 -> 3185.7799 | K8: =DEC!K48 -> 21060.78 | L8: =DEC!L48 -> 2189.2765 | M8: =DEC!M48 -> 1034 | ... Z8: =DEC!Z48 -> 2.63
A10: 1 | B10: 6902.64 | C10: 293423 | D10: =C10-C8 -> 38 | E10: =C10-152000 -> 141423 | F10: =D10/$D$2 -> 19.158054 | G10: 140 | H10: 4 | I10: =G10+H10 -> 144 | J10: =IF(L10>0,L10,0) -> 5.1580539 | K10: =I10+J10 -> 149.15805 | L10: =F10-(I10-W10) -> 5.1580539 | M10: 4 | N10: 0 | O10: 0 | P10: =M10-(N10+O10) -> 4 | Q10: 0 | R10: 0 | S10: =SUM(P10:R10) -> 4 | U10: 0 | V10: 126 | W10: =N10+O10+S10+U10+V10 -> 130 | X10: =IF(L10<0,L10*-1,0) -> 0 | Y10: =W10+X10 -> 130 | Z10: 0 | AA10: 38 | AB10: 10 | AC10: 1
A11: =A10+1 -> 2 | B11: 6902.65 | C11: 293460 | D11: =C11-C10 -> 37 | E11: =C11-152000 -> 141460 | F11: =D11/$D$2 -> 18.653895 | G11: 144 | H11: 2 | I11: =G11+H11 -> 146 | J11: =IF(L11>0,L11,0) -> 3.6538946 | K11: =I11+J11 -> 149.65389 | L11: =F11-(I11-W11) -> 3.6538946 | M11: 4 | N11: 0 | O11: 0 | P11: =M11-(N11+O11) -> 4 | Q11: 0 | R11: 0 | S11: =SUM(P11:R11) -> 4 | U11: 0 | V11: 127 | W11: =N11+O11+S11+U11+V11 -> 131 | X11: =IF(L11<0,L11*-1,0) -> 0 | Y11: =W11+X11 -> 131 | Z11: 0 | AA11: 40 | AB11: 12 | AC11: =AC10+1 -> 2
A12: =A11+1 -> 3 | B12: 6902.67 | C12: 293536 | D12: =C12-C11 -> 76 | E12: =C12-152000 -> 141536 | F12: =D12/$D$2 -> 38.316108 | G12: 151 | H12: 14 | I12: =G12+H12 -> 165 | J12: =IF(L12>0,L12,0) -> 4.3161079 | K12: =I12+J12 -> 169.31611 | L12: =F12-(I12-W12) -> 4.3161079 | M12: 4 | N12: 0 | O12: 0 | P12: =M12-(N12+O12) -> 4 | Q12: 0 | R12: 0 | S12: =SUM(P12:R12) -> 4 | U12: 0 | V12: 127 | W12: =N12+O12+S12+U12+V12 -> 131 | X12: =IF(L12<0,L12*-1,0) -> 0 | Y12: =W12+X12 -> 131 | Z12: 0 | AA12: 44 | AB12: 13 | AC12: =AC11+1 -> 3
A13: =A12+1 -> 4 | B13: 6902.69 | C13: 293611 | D13: =C13-C12 -> 75 | E13: =C13-152000 -> 141611 | F13: =D13/$D$2 -> 37.811949 | G13: 162 | H13: 3 | I13: =G13+H13 -> 165 | J13: =IF(L13>0,L13,0) -> 3.8119486 | K13: =I13+J13 -> 168.81195 | L13: =F13-(I13-W13) -> 3.8119486 | M13: 4 | N13: 0 | O13: 0 | P13: =M13-(N13+O13) -> 4 | Q13: 0 | R13: 0 | S13: =SUM(P13:R13) -> 4 | U13: 0 | V13: 127 | W13: =N13+O13+S13+U13+V13 -> 131 | X13: =IF(L13<0,L13*-1,0) -> 0 | Y13: =W13+X13 -> 131 | Z13: 0 | AA13: 47 | AB13: 26 | AC13: =AC12+1 -> 4
A14: =A13+1 -> 5 | B14: 6902.68 | C14: 293573 | D14: =C14-C13 -> -38 | E14: =C14-152000 -> 141573 | F14: =D14/$D$2 -> -19.158054 | G14: 105 | H14: 3 | I14: =G14+H14 -> 108 | J14: =IF(L14>0,L14,0) -> 3.8419461 | K14: =I14+J14 -> 111.84195 | L14: =F14-(I14-W14) -> 3.8419461 | M14: 4 | N14: 0 | O14: 0 | P14: =M14-(N14+O14) -> 4 | Q14: 0 | R14: 0 | S14: =SUM(P14:R14) -> 4 | U14: 0 | V14: 127 | W14: =N14+O14+S14+U14+V14 -> 131 | X14: =IF(L14<0,L14*-1,0) -> 0 | Y14: =W14+X14 -> 131 | Z14: 0.07 | AA14: 40 | AB14: 34 | AC14: =AC13+1 -> 5
A15: =A14+1 -> 6 | B15: 6902.68 | C15: 293573 | D15: =C15-C14 -> 0 | E15: =C15-152000 -> 141573 | F15: =D15/$D$2 -> 0 | G15: 124 | H15: 3 | I15: =G15+H15 -> 127 | J15: =IF(L15>0,L15,0) -> 4 | K15: =I15+J15 -> 131 | L15: =F15-(I15-W15) -> 4 | M15: 4 | N15: 0 | O15: 0 | P15: =M15-(N15+O15) -> 4 | Q15: 0 | R15: 0 | S15: =SUM(P15:R15) -> 4 | U15: 0 | V15: 127 | W15: =N15+O15+S15+U15+V15 -> 131 | X15: =IF(L15<0,L15*-1,0) -> 0 | Y15: =W15+X15 -> 131 | Z15: 0 | AA15: 30 | AB15: 22 | AC15: =AC14+1 -> 6
A16: =A15+1 -> 7 | B16: 6902.69 | C16: 293611 | D16: =C16-C15 -> 38 | E16: =C16-152000 -> 141611 | F16: =D16/$D$2 -> 19.158054 | G16: 142 | H16: 4 | I16: =G16+H16 -> 146 | J16: =IF(L16>0,L16,0) -> 4.1580539 | K16: =I16+J16 -> 150.15805 | L16: =F16-(I16-W16) -> 4.1580539 | M16: 4 | N16: 0 | O16: 0 | P16: =M16-(N16+O16) -> 4 | Q16: 0 | R16: 0 | S16: =SUM(P16:R16) -> 4 | U16: 0 | V16: 127 | W16: =N16+O16+S16+U16+V16 -> 131 | X16: =IF(L16<0,L16*-1,0) -> 0 | Y16: =W16+X16 -> 131 | Z16: 0.42 | AA16: 32 | AB16: 18 | AC16: =AC15+1 -> 7
A17: =A16+1 -> 8 | B17: 6902.7 | C17: 293649 | D17: =C17-C16 -> 38 | E17: =C17-152000 -> 141649 | F17: =D17/$D$2 -> 19.158054 | G17: 142 | H17: 4 | I17: 36 | J17: =IF(L17>0,L17,0) -> 114.15805 | K17: =I17+J17 -> 150.15805 | L17: =F17-(I17-W17) -> 114.15805 | M17: 4 | N17: 0 | O17: 0 | P17: =M17-(N17+O17) -> 4 | Q17: 0 | R17: 0 | S17: =SUM(P17:R17) -> 4 | U17: 0 | V17: 127 | W17: =N17+O17+S17+U17+V17 -> 131 | X17: =IF(L17<0,L17*-1,0) -> 0 | Y17: =W17+X17 -> 131 | Z17: 0 | AA17: 29 | AB17: 19 | AC17: =AC16+1 -> 8
A18: =A17+1 -> 9 | B18: 6902.69 | C18: 293611 | D18: =C18-C17 -> -38 | E18: =C18-152000 -> 141611 | F18: =D18/$D$2 -> -19.158054 | G18: 97 | H18: 11 | I18: 36 | J18: =IF(L18>0,L18,0) -> 75.841946 | K18: =I18+J18 -> 111.84195 | L18: =F18-(I18-W18) -> 75.841946 | M18: 4 | N18: 0 | O18: 0 | P18: =M18-(N18+O18) -> 4 | Q18: 0 | R18: 0 | S18: =SUM(P18:R18) -> 4 | U18: 0 | V18: 127 | W18: =N18+O18+S18+U18+V18 -> 131 | X18: =IF(L18<0,L18*-1,0) -> 0 | Y18: =W18+X18 -> 131 | Z18: 0 | AA18: 32 | AB18: -2 | AC18: =AC17+1 -> 9
A19: =A18+1 -> 10 | B19: 6902.683 | C19: 293573 | D19: =C19-C18 -> -38 | E19: =C19-152000 -> 141573 | F19: =D19/$D$2 -> -19.158054 | G19: 96 | H19: 12 | I19: 49.6 | J19: =IF(L19>0,L19,0) -> 62.241946 | K19: =I19+J19 -> 111.84195 | L19: =F19-(I19-W19) -> 62.241946 | M19: 4 | N19: 0 | O19: 0 | P19: =M19-(N19+O19) -> 4 | Q19: 0 | R19: 0 | S19: =SUM(P19:R19) -> 4 | U19: 0 | V19: 127 | W19: =N19+O19+S19+U19+V19 -> 131 | X19: =IF(L19<0,L19*-1,0) -> 0 | Y19: =W19+X19 -> 131 | Z19: 0 | AA19: 36 | AB19: 0 | AC19: =AC18+1 -> 10
A20: =A19+1 -> 11 | B20: 6902.67 | C20: 293536 | D20: =C20-C19 -> -37 | E20: =C20-152000 -> 141536 | F20: =D20/$D$2 -> -18.653895 | G20: 101 | H20: 6 | I20: 31.1 | J20: =IF(L20>0,L20,0) -> 81.246105 | K20: =I20+J20 -> 112.34611 | L20: =F20-(I20-W20) -> 81.246105 | M20: 4 | N20: 0 | O20: 0 | P20: =M20-(N20+O20) -> 4 | Q20: 0 | R20: 0 | S20: =SUM(P20:R20) -> 4 | U20: 0 | V20: 127 | W20: =N20+O20+S20+U20+V20 -> 131 | X20: =IF(L20<0,L20*-1,0) -> 0 | Y20: =W20+X20 -> 131 | Z20: 0 | AA20: 40 | AB20: 10 | AC20: =AC19+1 -> 11
A21: =A20+1 -> 12 | B21: 6902.68 | C21: 293573 | D21: =C21-C20 -> 37 | E21: =C21-152000 -> 141573 | F21: =D21/$D$2 -> 18.653895 | G21: 141 | H21: 5 | I21: 34.1 | J21: =IF(L21>0,L21,0) -> 115.55389 | K21: =I21+J21 -> 149.65389 | L21: =F21-(I21-W21) -> 115.55389 | M21: 4 | N21: 0 | O21: 0 | P21: =M21-(N21+O21) -> 4 | Q21: 0 | R21: 0 | S21: =SUM(P21:R21) -> 4 | U21: 0 | V21: 127 | W21: =N21+O21+S21+U21+V21 -> 131 | X21: =IF(L21<0,L21*-1,0) -> 0 | Y21: =W21+X21 -> 131 | Z21: 0 | AA21: 48 | AB21: 10 | AC21: =AC20+1 -> 12
A22: 13 | B22: 6902.69 | C22: 293611 | D22: =C22-C21 -> 38 | E22: =C22-152000 -> 141611 | F22: =D22/$D$2 -> 19.158054 | G22: 143 | H22: 4 | I22: 34.1 | J22: =IF(L22>0,L22,0) -> 117.05805 | K22: =I22+J22 -> 151.15805 | L22: =F22-(I22-W22) -> 117.05805 | M22: 4 | N22: 0 | O22: 0 | P22: =M22-(N22+O22) -> 4 | Q22: 0 | R22: 0 | S22: =SUM(P22:R22) -> 4 | U22: 0 | V22: 128 | W22: =N22+O22+S22+U22+V22 -> 132 | X22: =IF(L22<0,L22*-1,0) -> 0 | Y22: =W22+X22 -> 132 | Z22: 0 | AA22: 46 | AB22: 12 | AC22: =AC21+1 -> 13
A23: =A22+1 -> 14 | B23: 6902.72 | C23: 293724 | D23: =C23-C22 -> 113 | E23: =C23-152000 -> 141724 | F23: =D23/$D$2 -> 56.970003 | G23: 181 | H23: 4 | I23: =G23+H23 -> 185 | J23: =IF(L23>0,L23,0) -> 3.9700025 | K23: =I23+J23 -> 188.97 | L23: =F23-(I23-W23) -> 3.9700025 | M23: 4 | N23: 0 | O23: 0 | P23: =M23-(N23+O23) -> 4 | Q23: 0 | R23: 0 | S23: =SUM(P23:R23) -> 4 | U23: 0 | V23: 128 | W23: =N23+O23+S23+U23+V23 -> 132 | X23: =IF(L23<0,L23*-1,0) -> 0 | Y23: =W23+X23 -> 132 | Z23: 0 | AA23: 32 | AB23: 10 | AC23: =AC22+1 -> 14
A24: =A23+1 -> 15 | B24: 6902.75 | C24: 293799 | D24: =C24-C23 -> 75 | E24: =C24-152000 -> 141799 | F24: =D24/$D$2 -> 37.811949 | G24: 182 | H24: 4 | I24: =G24+H24 -> 186 | J24: =IF(L24>0,L24,0) -> 0 | K24: =I24+J24 -> 186 | L24: =F24-(I24-W24) -> -15.188051 | M24: 4 | N24: 0 | O24: 0 | P24: =M24-(N24+O24) -> 4 | Q24: 0 | R24: 0 | S24: =SUM(P24:R24) -> 4 | U24: 0 | V24: 129 | W24: =N24+O24+S24+U24+V24 -> 133 | X24: =IF(L24<0,L24*-1,0) -> 15.188051 | Y24: =W24+X24 -> 148.18805 | Z24: 0.15 | AA24: 31 | AB24: 11 | AC24: =AC23+1 -> 15
A25: =A24+1 -> 16 | B25: 6902.73 | C25: 293761 | D25: =C25-C24 -> -38 | E25: =C25-152000 -> 141761 | F25: =D25/$D$2 -> -19.158054 | G25: 86 | H25: 5 | I25: =G25+H25 -> 91 | J25: =IF(L25>0,L25,0) -> 22.841946 | K25: =I25+J25 -> 113.84195 | L25: =F25-(I25-W25) -> 22.841946 | M25: 4 | N25: 0 | O25: 0 | P25: =M25-(N25+O25) -> 4 | Q25: 0 | R25: 0 | S25: =SUM(P25:R25) -> 4 | U25: 0 | V25: 129 | W25: =N25+O25+S25+U25+V25 -> 133 | X25: =IF(L25<0,L25*-1,0) -> 0 | Y25: =W25+X25 -> 133 | Z25: 0 | AA25: 22 | AB25: 14 | AC25: =AC24+1 -> 16
A26: =A25+1 -> 17 | B26: 6902.71 | C26: 293686 | D26: =C26-C25 -> -75 | E26: =C26-152000 -> 141686 | F26: =D26/$D$2 -> -37.811949 | G26: 85 | H26: 5 | I26: =G26+H26 -> 90 | J26: =IF(L26>0,L26,0) -> 5.1880514 | K26: =I26+J26 -> 95.188051 | L26: =F26-(I26-W26) -> 5.1880514 | M26: 4 | N26: 0 | O26: 0 | P26: =M26-(N26+O26) -> 4 | Q26: 0 | R26: 0 | S26: =SUM(P26:R26) -> 4 | U26: 0 | V26: 129 | W26: =N26+O26+S26+U26+V26 -> 133 | X26: =IF(L26<0,L26*-1,0) -> 0 | Y26: =W26+X26 -> 133 | Z26: 0 | AA26: 23 | AB26: -4 | AC26: =AC25+1 -> 17
A27: =A26+1 -> 18 | B27: 6902.7 | C27: 293649 | D27: =C27-C26 -> -37 | E27: =C27-152000 -> 141649 | F27: =D27/$D$2 -> -18.653895 | G27: 106 | H27: 5 | I27: =G27+H27 -> 111 | J27: =IF(L27>0,L27,0) -> 3.3461054 | K27: =I27+J27 -> 114.34611 | L27: =F27-(I27-W27) -> 3.3461054 | M27: 4 | N27: 0 | O27: 0 | P27: =M27-(N27+O27) -> 4 | Q27: 0 | R27: 0 | S27: =SUM(P27:R27) -> 4 | U27: 0 | V27: 129 | W27: =N27+O27+S27+U27+V27 -> 133 | X27: =IF(L27<0,L27*-1,0) -> 0 | Y27: =W27+X27 -> 133 | Z27: 0.27 | AA27: 30 | AB27: -6 | AC27: =AC26+1 -> 18
A28: =A27+1 -> 19 | B28: 6902.72 | C28: 293724 | D28: =C28-C27 -> 75 | E28: =C28-152000 -> 141724 | F28: =D28/$D$2 -> 37.811949 | G28: 163 | H28: 4 | I28: =G28+H28 -> 167 | J28: =IF(L28>0,L28,0) -> 3.8119486 | K28: =I28+J28 -> 170.81195 | L28: =F28-(I28-W28) -> 3.8119486 | M28: 4 | N28: 0 | O28: 0 | P28: =M28-(N28+O28) -> 4 | Q28: 0 | R28: 0 | S28: =SUM(P28:R28) -> 4 | U28: 0 | V28: 129 | W28: =N28+O28+S28+U28+V28 -> 133 | X28: =IF(L28<0,L28*-1,0) -> 0 | Y28: =W28+X28 -> 133 | Z28: 0.04 | AA28: 24 | AB28: 11 | AC28: =AC27+1 -> 19
A29: =A28+1 -> 20 | B29: 6902.71 | C29: 293686 | D29: =C29-C28 -> -38 | E29: =C29-152000 -> 141686 | F29: =D29/$D$2 -> -19.158054 | G29: 108 | H29: 3 | I29: =G29+H29 -> 111 | J29: =IF(L29>0,L29,0) -> 4.8419461 | K29: =I29+J29 -> 115.84195 | L29: =F29-(I29-W29) -> 4.8419461 | M29: 5 | N29: 0 | O29: 0 | P29: =M29-(N29+O29) -> 5 | Q29: 0 | R29: 0 | S29: =SUM(P29:R29) -> 5 | U29: 0 | V29: 130 | W29: =N29+O29+S29+U29+V29 -> 135 | X29: =IF(L29<0,L29*-1,0) -> 0 | Y29: =W29+X29 -> 135 | Z29: 0 | AA29: 28 | AB29: 6 | AC29: =AC28+1 -> 20
A30: =A29+1 -> 21 | B30: 6902.69 | C30: 293611 | D30: =C30-C29 -> -75 | E30: =C30-152000 -> 141611 | F30: =D30/$D$2 -> -37.811949 | G30: 90 | H30: 3 | I30: =G30+H30 -> 93 | J30: =IF(L30>0,L30,0) -> 4.1880514 | K30: =I30+J30 -> 97.188051 | L30: =F30-(I30-W30) -> 4.1880514 | M30: 5 | N30: 0 | O30: 0 | P30: =M30-(N30+O30) -> 5 | Q30: 0 | R30: 0 | S30: =SUM(P30:R30) -> 5 | U30: 0 | V30: 130 | W30: =N30+O30+S30+U30+V30 -> 135 | X30: =IF(L30<0,L30*-1,0) -> 0 | Y30: =W30+X30 -> 135 | Z30: 0 | AA30: 38 | AB30: -4 | AC30: =AC29+1 -> 21
A31: =A30+1 -> 22 | B31: 6902.67 | C31: 293536 | D31: =C31-C30 -> -75 | E31: =C31-152000 -> 141536 | F31: =D31/$D$2 -> -37.811949 | G31: 89 | H31: 3 | I31: =G31+H31 -> 92 | J31: =IF(L31>0,L31,0) -> 5.1880514 | K31: =I31+J31 -> 97.188051 | L31: =F31-(I31-W31) -> 5.1880514 | M31: 5 | N31: 0 | O31: 0 | P31: =M31-(N31+O31) -> 5 | Q31: 0 | R31: 0 | S31: =SUM(P31:R31) -> 5 | U31: 0 | V31: 130 | W31: =N31+O31+S31+U31+V31 -> 135 | X31: =IF(L31<0,L31*-1,0) -> 0 | Y31: =W31+X31 -> 135 | Z31: 0 | AA31: 37 | AB31: 0 | AC31: =AC30+1 -> 22
A32: =A31+1 -> 23 | B32: 6902.68 | C32: 293573 | D32: =C32-C31 -> 37 | E32: =C32-152000 -> 141573 | F32: =D32/$D$2 -> 18.653895 | G32: 147 | H32: 2 | I32: =G32+H32 -> 149 | J32: =IF(L32>0,L32,0) -> 4.6538946 | K32: =I32+J32 -> 153.65389 | L32: =F32-(I32-W32) -> 4.6538946 | M32: 5 | N32: 0 | O32: 0 | P32: =M32-(N32+O32) -> 5 | Q32: 0 | R32: 0 | S32: =SUM(P32:R32) -> 5 | U32: 0 | V32: 130 | W32: =N32+O32+S32+U32+V32 -> 135 | X32: =IF(L32<0,L32*-1,0) -> 0 | Y32: =W32+X32 -> 135 | Z32: 0 | AA32: 41 | AB32: 8 | AC32: =AC31+1 -> 23
A33: =A32+1 -> 24 | B33: 6902.69 | C33: 293611 | D33: =C33-C32 -> 38 | E33: =C33-152000 -> 141611 | F33: =D33/$D$2 -> 19.158054 | G33: 148 | H33: 2 | I33: =G33+H33 -> 150 | J33: =IF(L33>0,L33,0) -> 4.1580539 | K33: =I33+J33 -> 154.15805 | L33: =F33-(I33-W33) -> 4.1580539 | M33: 5 | N33: 0 | O33: 0 | P33: =M33-(N33+O33) -> 5 | Q33: 0 | R33: 0 | S33: =SUM(P33:R33) -> 5 | U33: 0 | V33: 130 | W33: =N33+O33+S33+U33+V33 -> 135 | X33: =IF(L33<0,L33*-1,0) -> 0 | Y33: =W33+X33 -> 135 | Z33: 0 | AA33: 47 | AB33: 11 | AC33: =AC32+1 -> 24
A34: =A33+1 -> 25 | B34: 6902.7 | C34: 293649 | D34: =C34-C33 -> 38 | E34: =C34-152000 -> 141649 | F34: =D34/$D$2 -> 19.158054 | G34: 148 | H34: 1 | I34: =G34+H34 -> 149 | J34: =IF(L34>0,L34,0) -> 5.1580539 | K34: =I34+J34 -> 154.15805 | L34: =F34-(I34-W34) -> 5.1580539 | M34: 5 | N34: 0 | O34: 0 | P34: =M34-(N34+O34) -> 5 | Q34: 0 | R34: 0 | S34: =SUM(P34:R34) -> 5 | U34: 0 | V34: 130 | W34: =N34+O34+S34+U34+V34 -> 135 | X34: =IF(L34<0,L34*-1,0) -> 0 | Y34: =W34+X34 -> 135 | Z34: 0 | AA34: 49 | AB34: 17 | AC34: =AC33+1 -> 25
... A38: =A37+1 -> 29 | B38: 6902.71 | C38: 293686 | D38: =C38-C37 -> 37 | E38: =C38-152000 -> 141686 | F38: =D38/$D$2 -> 18.653895 | G38: 147 | H38: 1 | I38: =G38+H38 -> 148 | J38: =IF(L38>0,L38,0) -> 5.6538946 | K38: =I38+J38 -> 153.65389 | L38: =F38-(I38-W38) -> 5.6538946 | M38: 5 | N38: 0 | O38: 0 | P38: =M38-(N38+O38) -> 5 | Q38: 0 | R38: 0 | S38: =SUM(P38:R38) -> 5 | U38: 0 | V38: 130 | W38: =N38+O38+S38+U38+V38 -> 135 | X38: =IF(L38<0,L38*-1,0) -> 0 | Y38: =W38+X38 -> 135 | Z38: 0 | AA38: 44 | AB38: 22 | AC38: =AC37+1 -> 29
A39: 30 | B39: 6902.7 | C39: 293649 | D39: =C39-C38 -> -37 | E39: =C39-152000 -> 141649 | F39: =D39/$D$2 -> -18.653895 | G39: 110 | H39: 1 | I39: =G39+H39 -> 111 | J39: =IF(L39>0,L39,0) -> 5.3461054 | K39: =I39+J39 -> 116.34611 | L39: =F39-(I39-W39) -> 5.3461054 | M39: 5 | N39: 0 | O39: 0 | P39: =M39-(N39+O39) -> 5 | Q39: 0 | R39: 0 | S39: =SUM(P39:R39) -> 5 | U39: 0 | V39: 130 | W39: =N39+O39+S39+U39+V39 -> 135 | X39: =IF(L39<0,L39*-1,0) -> 0 | Y39: =W39+X39 -> 135 | Z39: 0 | AA39: 47 | AB39: 22 | AC39: 30
A40: 31 | B40: 6902.68 | C40: 293573 | D40: =C40-C39 -> -76 | E40: =C40-152000 -> 141573 | F40: =D40/$D$2 -> -38.316108 | G40: 100 | H40: 1 | I40: =G40+H40 -> 101 | J40: =IF(L40>0,L40,0) -> 15.683892 | K40: =I40+J40 -> 116.68389 | L40: =F40-(I40-W40) -> 15.683892 | M40: 15 | N40: 0 | O40: 0 | P40: =M40-(N40+O40) -> 15 | Q40: 0 | R40: 0 | S40: =SUM(P40:R40) -> 15 | U40: 0 | V40: 140 | W40: =N40+O40+S40+U40+V40 -> 155 | X40: =IF(L40<0,L40*-1,0) -> 0 | Y40: =W40+X40 -> 155 | Z40: 0 | AA40: 42 | AB40: 30 | AC40: 31
AA41: 39
A42: MONTH / CFS | F42: =SUM(F10:F40) -> 94.781951 | G42: =SUM(G10:G40) -> 3964 | H42: =SUM(H10:H40) -> 122 | I42: =SUM(I10:I40) -> 3544.9 | J42: =SUM(J10:J40) -> 705.07 | K42: =SUM(K10:K40) -> 4249.97 | L42: =SUM(L10:L40) -> 689.88195 | M42: =SUM(M10:M40) -> 146 | ... S42: =SUM(S10:S40) -> 146 | U42: =SUM(U10:U40) -> 0 | V42: =SUM(V10:V40) -> 3994 | W42: =SUM(W10:W40) -> 4140 | X42: =SUM(X10:X40) -> 15.188051 | Y42: =SUM(Y10:Y40) -> 4155.1881 | Z42: =SUM(Z10:Z40) -> 1.08 | AA42: =AVERAGE(AA10:AA40) -> 38.258065 | AB42: =AVERAGE(AB10:AB40) -> 13.032258 | AC42: AVE
A43: MONTH / AF | D43: =SUM(D10:D40) -> 188 | F43: =F42*$D$2 -> 188 | G43: =G42*$D$2 -> 7862.594 | H43: =H42*$D$2 -> 241.987 | I43: =I42*$D$2 -> 7031.3092 | J43: =J42*$D$2 -> 1398.5064 | K43: =K42*$D$2 -> 8429.8155 | L43: =L42*$D$2 -> 1368.3809 | M43: =M42*$D$2 -> 289.591 | ... S43: =S42*$D$2 -> 289.591 | U43: =U42*$D$2 -> 0 | V43: =V42*$D$2 -> 7922.099 | W43: =W42*$D$2 -> 8211.69 | X43: =X42*$D$2 -> 30.1255 | Y43: =Y42*$D$2 -> 8241.8155 | AA43: =MAX(AA10:AA40) -> 55 | AB43: =MAX(AB10:AB40) -> 34 | AC43: HI
A45: SEASON / CFS | AA45: =MIN(AA10:AA40) -> 22 | AB45: =MIN(AB10:AB40) -> -6 | AC45: LO
A46: SEASON / AF
A48: YTD / CFS | F48: =F8+F42 -> 1704.0585 | G48: =G8+G42 -> 20048 | H48: =H8+H42 -> 1913 | I48: =I8+I42 -> 21419.9 | J48: =J8+J42 -> 3890.8499 | K48: =K8+K42 -> 25310.75 | L48: =L8+L42 -> 2879.1585 | M48: =M8+M42 -> 1180 | ... S48: =S8+S42 -> 2245 | U48: =U8+U42 -> 1 | V48: =V8+V42 -> 20349 | W48: =W8+W42 -> 22595 | X48: =X8+X42 -> 1011.6915 | Y48: =Y8+Y42 -> 23606.691 | Z48: =Z8+Z42 -> 3.71
...

Sheet FEB
K1: MC PHEE RESERVOIR IN/OUT FLOW TABULATION
A2: AF/cfs CONVERT FACTOR | D2: 1.9835 | K2: FEBRUARY "1887"
A4: DATE | B4: RESERV | C4: RESERV | D4: AC FT | E4: ACTIVE | F4: CONV TO | G4: DOLORES | H4: LOST | I4: RECORDED | J4: CALC | K4: TOTAL | L4: CALC | M4: TUNNEL | Q4: LONE | R4: U | S4: TOTAL | T4: MVI | U4: DV CR | V4: BELOW | W4: RECORDED | X4: CALC | Y4: TOTAL | Z4: RAIN | AA4: MAX | AB4: MIN | AC4: DATE
A5: FEB | B5: ELEV | C5: AC FT | D5: CHANGE | E5: CAP | F5: CFS | G5: RIVER | H5: CANYON | I5: INFLOW | J5: INFLOW | K5: INFLOW | L5: INF/OTF | M5: TOT DIV | N5: WETLAND | O5: UTE F&R | P5: MVI,CTZ | Q5: PINE | R5: LAT | S5: MVI | T5: CALL | U5: CANAL | V5: MC PHEE | W5: OUTFLOW | X5: OUTFLOW | Y5: OUTFLOW | AA5: TMP | AB5: TMP | AC5: FEB
A7: SEASON BAL
A8: YTD | B8: =JAN!B40 -> 6902.68 | C8: =JAN!C40 -> 293573 | D8: =JAN!$D$49 -> 3380 | E8: =JAN!$E$40 -> 141573 | F8: =JAN!F48 -> 1704.0585 | G8: =JAN!G48 -> 20048 | H8: =JAN!H48 -> 1913 | I8: =JAN!I48 -> 21419.9 | J8: =JAN!J48 -> 3890.8499 | K8: =JAN!K48 -> 25310.75 | L8: =JAN!L48 -> 2879.1585 | M8: =JAN!M48 -> 1180 | ... Z8: =JAN!Z48 -> 3.71
A10: 1 | B10: 6902.66 | C10: 293498 | D10: =C10-C8 -> -75 | E10: =C10-152000 -> 141498 | F10: =D10/$D$2 -> -37.811949 | G10: 107 | H10: 0 | I10: =G10+H10 -> 107 | J10: =IF(L10>0,L10,0) -> 0.18805142 | K10: =I10+J10 -> 107.18805 | L10: =F10-(I10-W10) -> 0.18805142 | M10: 20 | N10: 0 | O10: 0 | P10: =M10-(N10+O10) -> 20 | Q10: 0 | R10: 0 | S10: =SUM(P10:R10) -> 20 | U10: 0 | V10: 125 | W10: =N10+O10+S10+U10+V10 -> 145 | X10: =IF(L10<0,L10*-1,0) -> 0 | Y10: =W10+X10 -> 145 | Z10: 0 | AA10: 53 | AB10: 22 | AC10: 1
A11: =A10+1 -> 2 | B11: 6902.65 | C11: 293460 | D11: =C11-C10 -> -38 | E11: =C11-152000 -> 141460 | F11: =D11/$D$2 -> -19.158054 | G11: 126 | H11: 0 | I11: =G11+H11 -> 126 | J11: =IF(L11>0,L11,0) -> 0 | K11: =I11+J11 -> 126 | L11: =F11-(I11-W11) -> -0.15805395 | M11: 20 | N11: 0 | O11: 0 | P11: =M11-(N11+O11) -> 20 | Q11: 0 | R11: 0 | S11: =SUM(P11:R11) -> 20 | U11: 0 | V11: 125 | W11: =N11+O11+S11+U11+V11 -> 145 | X11: =IF(L11<0,L11*-1,0) -> 0.15805395 | Y11: =W11+X11 -> 145.15805 | Z11: 0 | AA11: 53 | AB11: 26 | AC11: =AC10+1 -> 2
A12: =A11+1 -> 3 | B12: 6902.64 | C12: 293423 | D12: =C12-C11 -> -37 | E12: =C12-152000 -> 141423 | F12: =D12/$D$2 -> -18.653895 | G12: 124 | H12: 0 | I12: =G12+H12 -> 124 | J12: =IF(L12>0,L12,0) -> 0.34610537 | K12: =I12+J12 -> 124.34611 | L12: =F12-(I12-W12) -> 0.34610537 | M12: 20 | N12: 0 | O12: 0 | P12: =M12-(N12+O12) -> 20 | Q12: 0 | R12: 0 | S12: =SUM(P12:R12) -> 20 | U12: 0 | V12: 123 | W12: =N12+O12+S12+U12+V12 -> 143 | X12: =IF(L12<0,L12*-1,0) -> 0 | Y12: =W12+X12 -> 143 | Z12: 0 | AA12: 52 | AB12: 25 | AC12: =AC11+1 -> 3
A13: =A12+1 -> 4 | B13: 6902.62 | C13: 293347 | D13: =C13-C12 -> -76 | E13: =C13-152000 -> 141347 | F13: =D13/$D$2 -> -38.316108 | G13: 117 | H13: 0 | I13: =G13+H13 -> 117 | J13: =IF(L13>0,L13,0) -> 0 | K13: =I13+J13 -> 117 | L13: =F13-(I13-W13) -> -0.31610789 | M13: 30 | N13: 0 | O13: 0 | P13: =M13-(N13+O13) -> 30 | Q13: 0 | R13: 0 | S13: =SUM(P13:R13) -> 30 | U13: 0 | V13: 125 | W13: =N13+O13+S13+U13+V13 -> 155 | X13: =IF(L13<0,L13*-1,0) -> 0.31610789 | Y13: =W13+X13 -> 155.31611 | Z13: 0 | AA13: 46 | AB13: 30 | AC13: =AC12+1 -> 4
A14: =A13+1 -> 5 | B14: 6902.61 | C14: 293310 | D14: =C14-C13 -> -37 | E14: =C14-152000 -> 141310 | F14: =D14/$D$2 -> -18.653895 | G14: 118 | H14: 0 | I14: =G14+H14 -> 118 | J14: =IF(L14>0,L14,0) -> 0.34610537 | K14: =I14+J14 -> 118.34611 | L14: =F14-(I14-W14) -> 0.34610537 | M14: 12 | N14: 0 | O14: 0 | P14: =M14-(N14+O14) -> 12 | Q14: 0 | R14: 0 | S14: =SUM(P14:R14) -> 12 | U14: 0 | V14: 125 | W14: =N14+O14+S14+U14+V14 -> 137 | X14: =IF(L14<0,L14*-1,0) -> 0 | Y14: =W14+X14 -> 137 | Z14: 0 | AA14: 57 | AB14: 22 | AC14: =AC13+1 -> 5
A15: =A14+1 -> 6 | B15: 6902.61 | C15: 293310 | D15: =C15-C14 -> 0 | E15: =C15-152000 -> 141310 | F15: =D15/$D$2 -> 0 | G15: 128 | H15: 0 | I15: =G15+H15 -> 128 | J15: =IF(L15>0,L15,0) -> 1 | K15: =I15+J15 -> 129 | L15: =F15-(I15-W15) -> 1 | M15: 4 | N15: 0 | O15: 0 | P15: =M15-(N15+O15) -> 4 | Q15: 0 | R15: 0 | S15: =SUM(P15:R15) -> 4 | U15: 0 | V15: 125 | W15: =N15+O15+S15+U15+V15 -> 129 | X15: =IF(L15<0,L15*-1,0) -> 0 | Y15: =W15+X15 -> 129 | Z15: 0 | AA15: 50 | AB15: 24 | AC15: =AC14+1 -> 6
A16: =A15+1 -> 7 | B16: 6902.61 | C16: 293310 | D16: =C16-C15 -> 0 | E16: =C16-152000 -> 141310 | F16: =D16/$D$2 -> 0 | G16: 128 | H16: 0 | I16: =G16+H16 -> 128 | J16: =IF(L16>0,L16,0) -> 0 | K16: =I16+J16 -> 128 | L16: =F16-(I16-W16) -> 0 | M16: 4 | N16: 0 | O16: 0 | P16: =M16-(N16+O16) -> 4 | Q16: 0 | R16: 0 | S16: =SUM(P16:R16) -> 4 | U16: 0 | V16: 124 | W16: =N16+O16+S16+U16+V16 -> 128 | X16: =IF(L16<0,L16*-1,0) -> 0 | Y16: =W16+X16 -> 128 | Z16: 0 | AA16: 52 | AB16: 20 | AC16: =AC15+1 -> 7
A17: =A16+1 -> 8 | B17: 6902.62 | C17: 293347 | D17: =C17-C16 -> 37 | E17: =C17-152000 -> 141347 | F17: =D17/$D$2 -> 18.653895 | G17: 147 | H17: 0 | I17: =G17+H17 -> 147 | J17: =IF(L17>0,L17,0) -> 0 | K17: =I17+J17 -> 147 | L17: =F17-(I17-W17) -> -0.34610537 | M17: 4 | N17: 0 | O17: 0 | P17: =M17-(N17+O17) -> 4 | Q17: 0 | R17: 0 | S17: =SUM(P17:R17) -> 4 | U17: 0 | V17: 124 | W17: =N17+O17+S17+U17+V17 -> 128 | X17: =IF(L17<0,L17*-1,0) -> 0.34610537 | Y17: =W17+X17 -> 128.34611 | Z17: 0 | AA17: 54 | AB17: 22 | AC17: =AC16+1 -> 8
A18: =A17+1 -> 9 | B18: 6902.64 | C18: 293423 | D18: =C18-C17 -> 76 | E18: =C18-152000 -> 141423 | F18: =D18/$D$2 -> 38.316108 | G18: 146 | H18: 0 | I18: =G18+H18 -> 146 | J18: =IF(L18>0,L18,0) -> 0.31610789 | K18: =I18+J18 -> 146.31611 | L18: =F18-(I18-W18) -> 0.31610789 | M18: 4 | N18: 0 | O18: 0 | P18: =M18-(N18+O18) -> 4 | Q18: 0 | R18: 0 | S18: =SUM(P18:R18) -> 4 | U18: 0 | V18: 104 | W18: =N18+O18+S18+U18+V18 -> 108 | X18: =IF(L18<0,L18*-1,0) -> 0 | Y18: =W18+X18 -> 108 | Z18: 0 | AA18: 51 | AB18: 24 | AC18: =AC17+1 -> 9
A19: =A18+1 -> 10 | B19: 6902.72 | C19: 293724 | D19: =C19-C18 -> 301 | E19: =C19-152000 -> 141724 | F19: =D19/$D$2 -> 151.75195 | G19: 229 | H19: 0 | I19: =G19+H19 -> 229 | J19: =IF(L19>0,L19,0) -> 0.75195362 | K19: =I19+J19 -> 229.75195 | L19: =F19-(I19-W19) -> 0.75195362 | M19: 4 | N19: 0 | O19: 0 | P19: =M19-(N19+O19) -> 4 | Q19: 0 | R19: 0 | S19: =SUM(P19:R19) -> 4 | U19: 0 | V19: 74 | W19: =N19+O19+S19+U19+V19 -> 78 | X19: =IF(L19<0,L19*-1,0) -> 0 | Y19: =W19+X19 -> 78 | Z19: 0 | AA19: 42 | AB19: 20 | AC19: =AC18+1 -> 10
A20: =A19+1 -> 11 | B20: 6902.74 | C20: 293799 | D20: =C20-C19 -> 75 | E20: =C20-152000 -> 141799 | F20: =D20/$D$2 -> 37.811949 | G20: 113 | H20: 0 | I20: =G20+H20 -> 113 | J20: =IF(L20>0,L20,0) -> 0 | K20: =I20+J20 -> 113 | L20: =F20-(I20-W20) -> -0.18805142 | M20: 4 | N20: 0 | O20: 0 | P20: =M20-(N20+O20) -> 4 | Q20: 0 | R20: 0 | S20: =SUM(P20:R20) -> 4 | U20: 0 | V20: 71 | W20: =N20+O20+S20+U20+V20 -> 75 | X20: =IF(L20<0,L20*-1,0) -> 0.18805142 | Y20: =W20+X20 -> 75.188051 | Z20: 0 | AA20: 48 | AB20: 26 | AC20: =AC19+1 -> 11
A21: =A20+1 -> 12 | B21: 6902.79 | C21: 293987 | D21: =C21-C20 -> 188 | E21: =C21-152000 -> 141987 | F21: =D21/$D$2 -> 94.781951 | G21: 174 | H21: 0 | I21: =G21+H21 -> 174 | J21: =IF(L21>0,L21,0) -> 0.7819511 | K21: =I21+J21 -> 174.78195 | L21: =F21-(I21-W21) -> 0.7819511 | M21: 4 | N21: 0 | O21: 0 | P21: =M21-(N21+O21) -> 4 | Q21: 0 | R21: 0 | S21: =SUM(P21:R21) -> 4 | U21: 0 | V21: 76 | W21: =N21+O21+S21+U21+V21 -> 80 | X21: =IF(L21<0,L21*-1,0) -> 0 | Y21: =W21+X21 -> 80 | Z21: 0 | AA21: 49 | AB21: 28 | AC21: =AC20+1 -> 12
A22: =A21+1 -> 13 | B22: 6902.84 | C22: 294175 | D22: =C22-C21 -> 188 | E22: =C22-152000 -> 142175 | F22: =D22/$D$2 -> 94.781951 | G22: 198 | H22: 0 | I22: =G22+H22 -> 198 | J22: =IF(L22>0,L22,0) -> 0 | K22: =I22+J22 -> 198 | L22: =F22-(I22-W22) -> -0.2180489 | M22: 4 | N22: 0 | O22: 0 | P22: =M22-(N22+O22) -> 4 | Q22: 0 | R22: 0 | S22: =SUM(P22:R22) -> 4 | U22: 0 | V22: 99 | W22: =N22+O22+S22+U22+V22 -> 103 | X22: =IF(L22<0,L22*-1,0) -> 0.2180489 | Y22: =W22+X22 -> 103.21805 | Z22: 0 | AA22: 48 | AB22: 30 | AC22: =AC21+1 -> 13
... A36: =A35+1 -> 27 | B36: 6902.74 | C36: 293799 | D36: =C36-C35 -> -151 | E36: =C36-152000 -> 141799 | F36: =D36/$D$2 -> -76.128056 | G36: 93 | H36: 0 | I36: =G36+H36 -> 93 | J36: =IF(L36>0,L36,0) -> 0 | K36: =I36+J36 -> 93 | L36: =F36-(I36-W36) -> -0.12805647 | M36: 5 | N36: 0 | O36: 0 | P36: =M36-(N36+O36) -> 5 | Q36: 0 | R36: 0 | S36: =SUM(P36:R36) -> 5 | U36: 0 | V36: 164 | W36: =N36+O36+S36+U36+V36 -> 169 | X36: =IF(L36<0,L36*-1,0) -> 0.12805647 | Y36: =W36+X36 -> 169.12806 | Z36: 0 | AA36: 29 | AB36: 7 | AC36: =AC35+1 -> 27
A37: 28 | B37: 6902.7 | C37: 293649 | D37: =C37-C36 -> -150 | E37: =C37-152000 -> 141649 | F37: =D37/$D$2 -> -75.623897 | G37: 92 | H37: 0 | I37: =G37+H37 -> 92 | J37: =IF(L37>0,L37,0) -> 0.37610285 | K37: =I37+J37 -> 92.376103 | L37: =F37-(I37-W37) -> 0.37610285 | M37: 5 | N37: 0 | O37: 0 | P37: =M37-(N37+O37) -> 5 | Q37: 0 | R37: 0 | S37: =SUM(P37:R37) -> 5 | U37: 0 | V37: 163 | W37: =N37+O37+S37+U37+V37 -> 168 | X37: =IF(L37<0,L37*-1,0) -> 0 | Y37: =W37+X37 -> 168 | Z37: 0 | AA37: 37 | AB37: 5 | AC37: 28
A39: MONTH / CFS | F39: =SUM(F10:F37) -> 38.316108 | G39: =SUM(G10:G37) -> 4079 | H39: =SUM(H10:H37) -> 0 | I39: =SUM(I10:I37) -> 4079 | J39: =SUM(J10:J37) -> 10.234686 | K39: =SUM(K10:K37) -> 4089.2347 | L39: =SUM(L10:L37) -> 8.3161079 | M39: =SUM(M10:M37) -> 199 | ... S39: =SUM(S10:S37) -> 199 | U39: =SUM(U10:U37) -> 0 | V39: =SUM(V10:V37) -> 3850 | W39: =SUM(W10:W37) -> 4049 | X39: =SUM(X10:X37) -> 1.9185783 | Y39: =SUM(Y10:Y37) -> 4050.9186 | Z39: =SUM(Z10:Z37) -> 1.82 | AA39: =AVERAGE(AA10:AA37) -> 42.714286 | AB39: =AVERAGE(AB10:AB37) -> 21.035714 | AC39: AVE
A40: MONTH / AF | D40: =SUM(D10:D37) -> 76 | F40: =F39*$D$2 -> 76 | G40: =G39*$D$2 -> 8090.6965 | H40: =H39*$D$2 -> 0 | I40: =I39*$D$2 -> 8090.6965 | J40: =J39*$D$2 -> 20.3005 | K40: =K39*$D$2 -> 8110.997 | L40: =L39*$D$2 -> 16.495 | M40: =M39*$D$2 -> 394.7165 | ... S40: =S39*$D$2 -> 394.7165 | U40: =U39*$D$2 -> 0 | V40: =V39*$D$2 -> 7636.475 | W40: =W39*$D$2 -> 8031.1915 | X40: =X39*$D$2 -> 3.8055 | Y40: =Y39*$D$2 -> 8034.997 | AA40: =MAX(AA10:AA37) -> 57 | AB40: =MAX(AB10:AB37) -> 30 | AC40: HI
A42: SEASON / CFS | AA42: =MIN(AA10:AA37) -> 29 | AB42: =MIN(AB10:AB37) -> 5 | AC42: LO
A43: SEASON / AF
A45: YTD / CFS | F45: =F8+F39 -> 1742.3746 | G45: =G8+G39 -> 24127 | H45: =H8+H39 -> 1913 | I45: =I8+I39 -> 25498.9 | J45: =J8+J39 -> 3901.0846 | K45: =K8+K39 -> 29399.985 | L45: =L8+L39 -> 2887.4746 | M45: =M8+M39 -> 1379 | ... S45: =S8+S39 -> 2444 | U45: =U8+U39 -> 1 | V45: =V8+V39 -> 24199 | W45: =W8+W39 -> 26644 | X45: =X8+X39 -> 1013.61 | Y45: =Y8+Y39 -> 27657.61 | Z45: =Z8+Z39 -> 5.53
A46: YTD / AF | D46: =D8+D40 -> 3456 | E46: =E37 -> 141649 | F46: =F45*$D$2 -> 3456 | G46: =G45*$D$2 -> 47855.904 | H46: =H45*$D$2 -> 3794.4355 | I46: =I45*$D$2 -> 50577.068 | J46: =J45*$D$2 -> 7737.8013 | K46: =K45*$D$2 -> 58314.87 | L46: =L45*$D$2 -> 5727.3058 | M46: =M45*$D$2 -> 2735.2465 | ... Y46: =Y45*$D$2 -> 54858.87

Sheet MAR
K1: MC PHEE RESERVOIR IN/OUT FLOW TABULATION
A2: AF/cfs CONVERT FACTOR | D2: 1.9835 | K2: MARCH "1887"
A4: DATE | B4: RESERV | C4: RESERV | D4: AC FT | E4: ACTIVE | F4: CONV TO | G4: DOLORES | H4: LOST | I4: RECORDED | J4: CALC | K4: TOTAL | L4: CALC | M4: TUNNEL | Q4: LONE | R4: U | S4: TOTAL | T4: MVI | U4: DV CR | V4: BELOW | W4: RECORDED | X4: CALC | Y4: TOTAL | Z4: RAIN | AA4: MAX | AB4: MIN | AC4: DATE
A5: MAR | B5: ELEV | C5: AC FT | D5: CHANGE | E5: CAP | F5: CFS | G5: RIVER | H5: CANYON | I5: INFLOW | J5: INFLOW | K5: INFLOW | L5: INF/OTF | M5: TOT DIV | N5: WETLAND | O5: UTE F&R | P5: MVI,CTZ | Q5: PINE | R5: LAT | S5: MVI | T5: CALL | U5: CANAL | V5: MC PHEE | W5: OUTFLOW | X5: OUTFLOW | Y5: OUTFLOW | AA5: TMP | AB5: TMP | AC5: MAR
A7: SEASON BAL
A8: YTD | B8: =FEB!B37 -> 6902.7 | C8: =FEB!C37 -> 293649 | D8: =FEB!$D$46 -> 3456 | E8: =FEB!$E$37 -> 141649 | F8: =FEB!F45 -> 1742.3746 | G8: =FEB!G45 -> 24127 | H8: =FEB!H45 -> 1913 | I8: =FEB!I45 -> 25498.9 | J8: =FEB!J45 -> 3901.0846 | K8: =FEB!K45 -> 29399.985 | L8: =FEB!L45 -> 2887.4746 | M8: =FEB!M45 -> 1379 | ... Z8: =FEB!Z45 -> 5.53
A10: 1 | B10: 6902.66 | C10: 293498 | D10: =C10-C8 -> -151 | E10: =C10-152000 -> 141498 | F10: =D10/$D$2 -> -76.128056 | G10: 88 | H10: 5 | I10: =G10+H10 -> 93 | J10: =IF(L10>0,L10,0) -> 0 | K10: =I10+J10 -> 93 | L10: =F10-(I10-W10) -> -0.12805647 | M10: 5 | N10: 0 | O10: 0 | P10: =M10-(N10+O10) -> 5 | Q10: 0 | R10: 0 | S10: =SUM(P10:R10) -> 5 | U10: 0 | V10: 164 | W10: =N10+O10+S10+U10+V10 -> 169 | X10: =IF(L10<0,L10*-1,0) -> 0.12805647 | Y10: =W10+X10 -> 169.12806 | Z10: 0 | AA10: 40 | AB10: 7 | AC10: 1
A11: =A10+1 -> 2 | B11: 6902.66 | C11: 293498 | D11: =C11-C10 -> 0 | E11: =C11-152000 -> 141498 | F11: =D11/$D$2 -> 0 | G11: 144 | H11: 6 | I11: =G11+H11 -> 150 | J11: =IF(L11>0,L11,0) -> 1 | K11: =I11+J11 -> 151 | L11: =F11-(I11-W11) -> 1 | M11: 5 | N11: 0 | O11: 0 | P11: =M11-(N11+O11) -> 5 | Q11: 0 | R11: 0 | S11: =SUM(P11:R11) -> 5 | U11: 0 | V11: 146 | W11: =N11+O11+S11+U11+V11 -> 151 | X11: =IF(L11<0,L11*-1,0) -> 0 | Y11: =W11+X11 -> 151 | Z11: 0 | AA11: 41 | AB11: 18 | AC11: =AC10+1 -> 2
A12: =A11+1 -> 3 | B12: 6902.69 | C12: 293611 | D12: =C12-C11 -> 113 | E12: =C12-152000 -> 141611 | F12: =D12/$D$2 -> 56.970003 | G12: 169 | H12: 18 | I12: =G12+H12 -> 187 | J12: =IF(L12>0,L12,0) -> 0 | K12: =I12+J12 -> 187 | L12: =F12-(I12-W12) -> -0.029997479 | M12: 5 | N12: 0 | O12: 0 | P12: =M12-(N12+O12) -> 5 | Q12: 0 | R12: 0 | S12: =SUM(P12:R12) -> 5 | U12: 0 | V12: 125 | W12: =N12+O12+S12+U12+V12 -> 130 | X12: =IF(L12<0,L12*-1,0) -> 0.029997479 | Y12: =W12+X12 -> 130.03 | Z12: 0 | AA12: 44 | AB12: 19 | AC12: =AC11+1 -> 3
A13: =A12+1 -> 4 | B13: 6902.71 | C13: 293686 | D13: =C13-C12 -> 75 | E13: =C13-152000 -> 141686 | F13: =D13/$D$2 -> 37.811949 | G13: 135 | H13: 34 | I13: =G13+H13 -> 169 | J13: =IF(L13>0,L13,0) -> 0 | K13: =I13+J13 -> 169 | L13: =F13-(I13-W13) -> -0.18805142 | M13: 5 | N13: 0 | O13: 0 | P13: =M13-(N13+O13) -> 5 | Q13: 0 | R13: 0 | S13: =SUM(P13:R13) -> 5 | U13: 0 | V13: 126 | W13: =N13+O13+S13+U13+V13 -> 131 | X13: =IF(L13<0,L13*-1,0) -> 0.18805142 | Y13: =W13+X13 -> 131.18805 | Z13: 0 | AA13: 56 | AB13: 22 | AC13: =AC12+1 -> 4
A14: =A13+1 -> 5 | B14: 6902.74 | C14: 293799 | D14: =C14-C13 -> 113 | E14: =C14-152000 -> 141799 | F14: =D14/$D$2 -> 56.970003 | G14: 140 | H14: 48 | I14: =G14+H14 -> 188 | J14: =IF(L14>0,L14,0) -> 0 | K14: =I14+J14 -> 188 | L14: =F14-(I14-W14) -> -0.029997479 | M14: 5 | N14: 0 | O14: 0 | P14: =M14-(N14+O14) -> 5 | Q14: 0 | R14: 0 | S14: =SUM(P14:R14) -> 5 | U14: 0 | V14: 126 | W14: =N14+O14+S14+U14+V14 -> 131 | X14: =IF(L14<0,L14*-1,0) -> 0.029997479 | Y14: =W14+X14 -> 131.03 | Z14: 0 | AA14: 60 | AB14: 26 | AC14: =AC13+1 -> 5
A15: =A14+1 -> 6 | B15: 6902.83 | C15: 294138 | D15: =C15-C14 -> 339 | E15: =C15-152000 -> 142138 | F15: =D15/$D$2 -> 170.91001 | G15: 273 | H15: 61 | I15: =G15+H15 -> 334 | J15: =IF(L15>0,L15,0) -> 0 | K15: =I15+J15 -> 334 | L15: =F15-(I15-W15) -> -0.089992438 | M15: 5 | N15: 0 | O15: 0 | P15: =M15-(N15+O15) -> 5 | Q15: 0 | R15: 0 | S15: =SUM(P15:R15) -> 5 | U15: 0 | V15: 158 | W15: =N15+O15+S15+U15+V15 -> 163 | X15: =IF(L15<0,L15*-1,0) -> 0.089992438 | Y15: =W15+X15 -> 163.08999 | Z15: 0 | AA15: 60 | AB15: 24 | AC15: =AC14+1 -> 6
A16: =A15+1 -> 7 | B16: 6902.95 | C16: 294589 | D16: =C16-C15 -> 451 | E16: =C16-152000 -> 142589 | F16: =D16/$D$2 -> 227.37585 | G16: 218 | H16: 80 | I16: =G16+H16 -> 298 | J16: =IF(L16>0,L16,0) -> 131.37585 | K16: =I16+J16 -> 429.37585 | L16: =F16-(I16-W16) -> 131.37585 | M16: 5 | N16: 0 | O16: 0 | P16: =M16-(N16+O16) -> 5 | Q16: 0 | R16: 0 | S16: =SUM(P16:R16) -> 5 | U16: 0 | V16: 197 | W16: =N16+O16+S16+U16+V16 -> 202 | X16: =IF(L16<0,L16*-1,0) -> 0 | Y16: =W16+X16 -> 202 | Z16: 0 | AA16: 58 | AB16: 27 | AC16: =AC15+1 -> 7
A17: =A16+1 -> 8 | B17: 6902.99 | C17: 294740 | D17: =C17-C16 -> 151 | E17: =C17-152000 -> 142740 | F17: =D17/$D$2 -> 76.128056 | G17: 239 | H17: 55 | I17: =G17+H17 -> 294 | J17: =IF(L17>0,L17,0) -> 98.128056 | K17: =I17+J17 -> 392.12806 | L17: =F17-(I17-W17) -> 98.128056 | M17: 5 | N17: 0 | O17: 0 | P17: =M17-(N17+O17) -> 5 | Q17: 0 | R17: 0 | S17: =SUM(P17:R17) -> 5 | U17: 0 | V17: 311 | W17: =N17+O17+S17+U17+V17 -> 316 | X17: =IF(L17<0,L17*-1,0) -> 0 | Y17: =W17+X17 -> 316 | Z17: 0.7 | AA17: 41 | AB17: 33 | AC17: =AC16+1 -> 8
A18: =A17+1 -> 9 | B18: 6902.94 | C18: 294552 | D18: =C18-C17 -> -188 | E18: =C18-152000 -> 142552 | F18: =D18/$D$2 -> -94.781951 | G18: 221 | H18: 50 | I18: =G18+H18 -> 271 | J18: =IF(L18>0,L18,0) -> 105.21805 | K18: =I18+J18 -> 376.21805 | L18: =F18-(I18-W18) -> 105.21805 | M18: 5 | N18: 0 | O18: 0 | P18: =M18-(N18+O18) -> 5 | Q18: 0 | R18: 0 | S18: =SUM(P18:R18) -> 5 | U18: 0 | V18: 466 | W18: =N18+O18+S18+U18+V18 -> 471 | X18: =IF(L18<0,L18*-1,0) -> 0 | Y18: =W18+X18 -> 471 | Z18: 0.15 | AA18: 40 | AB18: 30 | AC18: =AC17+1 -> 9
A19: =A18+1 -> 10 | B19: 6902.84 | C19: 294175 | D19: =C19-C18 -> -377 | E19: =C19-152000 -> 142175 | F19: =D19/$D$2 -> -190.06806 | G19: 218 | H19: 67 | I19: =G19+H19 -> 285 | J19: =IF(L19>0,L19,0) -> 129.93194 | K19: =I19+J19 -> 414.93194 | L19: =F19-(I19-W19) -> 129.93194 | M19: 5 | N19: 0 | O19: 0 | P19: =M19-(N19+O19) -> 5 | Q19: 0 | R19: 0 | S19: =SUM(P19:R19) -> 5 | U19: 0 | V19: 600 | W19: =N19+O19+S19+U19+V19 -> 605 | X19: =IF(L19<0,L19*-1,0) -> 0 | Y19: =W19+X19 -> 605 | Z19: 0 | AA19: 50 | AB19: 24 | AC19: =AC18+1 -> 10
A20: =A19+1 -> 11 | B20: 6902.83 | C20: 294138 | D20: =C20-C19 -> -37 | E20: =C20-152000 -> 142138 | F20: =D20/$D$2 -> -18.653895 | G20: 213 | H20: 74 | I20: =G20+H20 -> 287 | J20: =IF(L20>0,L20,0) -> 200.34611 | K20: =I20+J20 -> 487.34611 | L20: =F20-(I20-W20) -> 200.34611 | M20: 5 | N20: 0 | O20: 0 | P20: =M20-(N20+O20) -> 5 | Q20: 0 | R20: 0 | S20: =SUM(P20:R20) -> 5 | U20: 0 | V20: 501 | W20: =N20+O20+S20+U20+V20 -> 506 | X20: =IF(L20<0,L20*-1,0) -> 0 | Y20: =W20+X20 -> 506 | Z20: 0 | AA20: 50 | AB20: 24 | AC20: =AC19+1 -> 11
A21: =A20+1 -> 12 | B21: 6902.83 | C21: 294138 | D21: =C21-C20 -> 0 | E21: =C21-152000 -> 142138 | F21: =D21/$D$2 -> 0 | G21: 224 | H21: 58 | I21: =G21+H21 -> 282 | J21: =IF(L21>0,L21,0) -> 170 | K21: =I21+J21 -> 452 | L21: =F21-(I21-W21) -> 170 | M21: 5 | N21: 0 | O21: 0 | P21: =M21-(N21+O21) -> 5 | Q21: 0 | R21: 0 | S21: =SUM(P21:R21) -> 5 | U21: 0 | V21: 447 | W21: =N21+O21+S21+U21+V21 -> 452 | X21: =IF(L21<0,L21*-1,0) -> 0 | Y21: =W21+X21 -> 452 | Z21: 0 | AA21: 54 | AB21: 26 | AC21: =AC20+1 -> 12
A22: =A21+1 -> 13 | B22: 6902.9 | C22: 294401 | D22: =C22-C21 -> 263 | E22: =C22-152000 -> 142401 | F22: =D22/$D$2 -> 132.5939 | G22: 246 | H22: 80 | I22: =G22+H22 -> 326 | J22: =IF(L22>0,L22,0) -> 256.5939 | K22: =I22+J22 -> 582.5939 | L22: =F22-(I22-W22) -> 256.5939 | M22: 5 | N22: 0 | O22: 0 | P22: =M22-(N22+O22) -> 5 | Q22: 0 | R22: 0 | S22: =SUM(P22:R22) -> 5 | U22: 0 | V22: 445 | W22: =N22+O22+S22+U22+V22 -> 450 | X22: =IF(L22<0,L22*-1,0) -> 0 | Y22: =W22+X22 -> 450 | Z22: 0 | AA22: 59 | AB22: 31 | AC22: =AC21+1 -> 13
... A38: =A37+1 -> 29 | B38: 6902 | C38: 291014 | D38: =C38-C37 -> -377 | E38: =C38-152000 -> 139014 | F38: =D38/$D$2 -> -190.06806 | G38: 177 | H38: 28 | I38: =G38+H38 -> 205 | J38: =IF(L38>0,L38,0) -> 14.931938 | K38: =I38+J38 -> 219.93194 | L38: =F38-(I38-W38) -> 14.931938 | M38: 5 | N38: 0 | O38: 0 | P38: =M38-(N38+O38) -> 5 | Q38: 281 | R38: 0 | S38: =SUM(P38:R38) -> 286 | U38: 0 | V38: 124 | W38: =N38+O38+S38+U38+V38 -> 410 | X38: =IF(L38<0,L38*-1,0) -> 0 | Y38: =W38+X38 -> 410 | Z38: 0 | AA38: 35 | AB38: 19 | AC38: =AC37+1 -> 29
A39: 30 | B39: 6901.98 | C39: 290940 | D39: =C39-C38 -> -74 | E39: =C39-152000 -> 138940 | F39: =D39/$D$2 -> -37.307789 | G39: 159 | H39: 34 | I39: =G39+H39 -> 193 | J39: =IF(L39>0,L39,0) -> 139.69221 | K39: =I39+J39 -> 332.69221 | L39: =F39-(I39-W39) -> 139.69221 | M39: 5 | N39: 0 | O39: 0 | P39: =M39-(N39+O39) -> 5 | Q39: 241 | R39: 0 | S39: =SUM(P39:R39) -> 246 | U39: 0 | V39: 124 | W39: =N39+O39+S39+U39+V39 -> 370 | X39: =IF(L39<0,L39*-1,0) -> 0 | Y39: =W39+X39 -> 370 | Z39: 0 | AA39: 46 | AB39: 9 | AC39: 30
