Workbook

Sheet NOV
K1: MCPHEE RESERVOIR INFLOW/OUTFLOW TABULATION
A2: AF/cfs CONVERT FACTOR | D2: 1.9835 | L2: NOVEMBER "2006"
D4: RESERVOIR | U4: INFLOW/OUTFLOW (CFS) | AJ4: WEATHER | AN4: ADJUSTMENTS
A5: DATE | B5: RESERV | C5: RESERV | D5: AC FT | E5: ACTIVE | F5: CONV TO | G5: DOLORES | H5: LOST | I5: RECORD | J5: CALC | K5: TOTAL | L5: CALC | M5: DOLORES TUNNEL | U5: LONE | V5: U | W5: TOTAL | X5: MVI | Y5: TO EX & | Z5: MVI | AA5: DV CR | AB5: D/S SENIOR | AD5: BELOW | AE5: FISH | AF5: RECORD | AG5: CALC | AH5: TOTAL | AI5: RAIN | AJ5: MAX | AK5: MIN | AL5: NAR. | AM5: MVI | AN5: MVI | AO5: MVI | AP5: U/S | AQ5: TOTTEN
A6: NOV | B6: ELEV | C6: AC FT | D6: CHANGE | E6: CAP | F6: CFS | G6: RIVER | H6: CAN | I6: INFLOW | J6: INFLOW | K6: INFLOW | L6: INF/OTF | M6: TOT DIV | N6: WET | O6: UTE | P6: QUEST | Q6: MWC | R6: CTZ | S6: CTZ & | T6: F-BAY | U6: PINE | V6: LAT | W6: MVI | X6: CALL | Y6: U/S EX | Z6: PROJ | AA6: CANAL | AB6: MVIC | AC6: PROJ | AD6: MCP | AE6: LEFT | AF6: OTF | AG6: OTF | AH6: OTF | AJ6: TMP | AK6: TMP | AL6: CALL | AM6: STOCK | AN6: STORED | AO6: STORED | AP6: USERS | AQ6: (FRESH
E7: AC FT | N7: LAND | O7: F&R | S7: UTE | T7: SPILL | AL7: AC.FT. | AM7: CFS | AN7: Apr-Jun | AO7: EVAP | AP7: EXCH | AQ7: WATER)
N8: 1.03 | O8: 1.05 | P8: 1.02 | Q8: 1.02 | R8: 1.04 | S8: PROJ | AL8: TOTAL | AO8: AC.FT
A9: SEASON BAL
A10: YTD | B10: 6896.52 | C10: 270921 | AE10: 3819 | AM10: 321
A12: 1 | B12: 6896.54 | C12: 270992 | D12: =C12-C10 -> 71 | E12: =C12-152000 -> 118992 | F12: =D12/$D$2 -> 35.795311 | G12: 251 | H12: 5.2 | I12: =G12+H12 -> 256.2 | J12: =IF(L12>0,L12,0) -> 0 | K12: =I12+J12 -> 256.2 | L12: =F12-(I12-AF12) -> -7.1046887 | M12: 5.3 | N12: 0 | O12: 0 | P12: 0 | Q12: =1.57*1.02 -> 1.6014 | R12: 2.4 | S12: 0 | T12: =M12-(Q12+R12+S12) -> 1.2986 | U12: 175 | V12: 0 | W12: =M12-N12-P12-O12-Q12-R12-S12-T12+U12+V12 -> 175 | AA12: 0 | AD12: 33 | AE12: =AE10-AD12 -> 3786 | AF12: =N12+O12+P12+Q12+R12+S12+T12+W12+AA12+AD12 -> 213.3 | AG12: =IF(L12<0,L12*-1,0) -> 7.1046887 | AH12: =AF12+AG12 -> 220.40469 | AI12: 0 | AJ12: 54 | AK12: 30 | AL12: =(W12)*1.98353 -> 347.11775
A13: =A12+1 -> 2 | B13: 6896.5 | C13: 270849 | D13: =C13-C12 -> -143 | E13: =C13-152000 -> 118849 | F13: =D13/$D$2 -> -72.094782 | G13: 231 | H13: 4.6 | I13: =G13+H13 -> 235.6 | J13: =IF(L13>0,L13,0) -> 0 | K13: =I13+J13 -> 235.6 | L13: =F13-(I13-AF13) -> -21.494782 | M13: 5.2 | N13: 0 | O13: 0 | P13: 0 | Q13: =1.57*1.02 -> 1.6014 | R13: 4.3 | S13: 0 | T13: =M13-(Q13+R13+S13) -> -0.7014 | U13: 258 | V13: 0 | W13: =M13-N13-P13-O13-Q13-R13-S13-T13+U13+V13 -> 258 | AA13: 0 | AD13: 23 | AE13: =AE12-AD13 -> 3763 | AF13: =N13+O13+P13+Q13+R13+S13+T13+W13+AA13+AD13 -> 286.2 | AG13: =IF(L13<0,L13*-1,0) -> 21.494782 | AH13: =AF13+AG13 -> 307.69478 | AI13: 0 | AJ13: 58 | AK13: 30 | AL13: =(W13)*1.9835+AL12 -> 858.86075
A14: =A13+1 -> 3 | B14: 6896.46 | C14: 270705 | D14: =C14-C13 -> -144 | E14: =C14-152000 -> 118705 | F14: =D14/$D$2 -> -72.598941 | G14: 236 | H14: 5.4 | I14: =G14+H14 -> 241.4 | J14: =IF(L14>0,L14,0) -> 0 | K14: =I14+J14 -> 241.4 | L14: =F14-(I14-AF14) -> -27.798941 | M14: 5.2 | N14: 0 | O14: 0 | P14: 0 | Q14: =1.57*1.02 -> 1.6014 | R14: 2.95 | S14: 0 | T14: =M14-(Q14+R14+S14) -> 0.6486 | U14: 258 | V14: 0 | W14: =M14-N14-P14-O14-Q14-R14-S14-T14+U14+V14 -> 258 | AA14: 0 | AD14: 23 | AE14: =AE13-AD14 -> 3740 | AF14: =N14+O14+P14+Q14+R14+S14+T14+W14+AA14+AD14 -> 286.2 | AG14: =IF(L14<0,L14*-1,0) -> 27.798941 | AH14: =AF14+AG14 -> 313.99894 | AI14: 0 | AJ14: 57 | AK14: 33 | AL14: =(W14)*1.9835+AL13 -> 1370.6037
A15: =A14+1 -> 4 | B15: 6896.41 | C15: 270526 | D15: =C15-C14 -> -179 | E15: =C15-152000 -> 118526 | F15: =D15/$D$2 -> -90.244517 | G15: 223 | H15: 4.9 | I15: =G15+H15 -> 227.9 | J15: =IF(L15>0,L15,0) -> 0 | K15: =I15+J15 -> 227.9 | L15: =F15-(I15-AF15) -> -32.944517 | M15: 5.2 | N15: 0 | O15: 0 | P15: 0 | Q15: =1.57*1.02 -> 1.6014 | R15: 2.42 | S15: 0 | T15: =M15-(Q15+R15+S15) -> 1.1786 | U15: 257 | V15: 0 | W15: =M15-N15-P15-O15-Q15-R15-S15-T15+U15+V15 -> 257 | AA15: 0 | AD15: 23 | AE15: =AE14-AD15 -> 3717 | AF15: =N15+O15+P15+Q15+R15+S15+T15+W15+AA15+AD15 -> 285.2 | AG15: =IF(L15<0,L15*-1,0) -> 32.944517 | AH15: =AF15+AG15 -> 318.14452 | AI15: 0 | AJ15: 58 | AK15: 35 | AL15: =(W15)*1.9835+AL14 -> 1880.3633
A16: =A15+1 -> 5 | B16: 6896.36 | C16: 270347 | D16: =C16-C15 -> -179 | E16: =C16-152000 -> 118347 | F16: =D16/$D$2 -> -90.244517 | G16: 211 | H16: 4.3 | I16: =G16+H16 -> 215.3 | J16: =IF(L16>0,L16,0) -> 0 | K16: =I16+J16 -> 215.3 | L16: =F16-(I16-AF16) -> -20.344517 | M16: 5.2 | N16: 0 | O16: 0 | P16: 0 | Q16: =1.57*1.02 -> 1.6014 | R16: 2.19 | S16: 0 | T16: =M16-(Q16+R16+S16) -> 1.4086 | U16: 257 | V16: 0 | W16: =M16-N16-P16-O16-Q16-R16-S16-T16+U16+V16 -> 257 | AA16: 0 | AD16: 23 | AE16: =AE15-AD16 -> 3694 | AF16: =N16+O16+P16+Q16+R16+S16+T16+W16+AA16+AD16 -> 285.2 | AG16: =IF(L16<0,L16*-1,0) -> 20.344517 | AH16: =AF16+AG16 -> 305.54452 | AI16: 0 | AJ16: 56 | AK16: 32 | AL16: =(W16)*1.9835+AL15 -> 2390.1227
A17: =A16+1 -> 6 | B17: 6896.32 | C17: 270203 | D17: =C17-C16 -> -144 | E17: =C17-152000 -> 118203 | F17: =D17/$D$2 -> -72.598941 | G17: 203 | H17: 3.7 | I17: =G17+H17 -> 206.7 | J17: =IF(L17>0,L17,0) -> 0 | K17: =I17+J17 -> 206.7 | L17: =F17-(I17-AF17) -> -18.198941 | M17: 12 | N17: 0 | O17: 0 | P17: 0 | Q17: =1.57*1.02 -> 1.6014 | R17: 2.48 | S17: 0 | T17: 0 | U17: 220 | V17: 6.1 | W17: =M17-N17-P17-O17-Q17-R17-S17-T17+U17+V17 -> 234.0186 | AA17: 0 | AD17: 23 | AE17: =AE16-AD17 -> 3671 | AF17: =N17+O17+P17+Q17+R17+S17+T17+W17+AA17+AD17 -> 261.1 | AG17: =IF(L17<0,L17*-1,0) -> 18.198941 | AH17: =AF17+AG17 -> 279.29894 | AI17: 0 | AJ17: 61 | AK17: 30 | AL17: =(U17-9.92)*1.9835+AL16 -> 2806.8164 | AM17: =W17-(U17-9.92) -> 23.9386
A18: =A17+1 -> 7 | B18: 6896.28 | C18: 270059 | D18: =C18-C17 -> -144 | E18: =C18-152000 -> 118059 | F18: =D18/$D$2 -> -72.598941 | G18: 199 | H18: 3.4 | I18: =G18+H18 -> 202.4 | J18: =IF(L18>0,L18,0) -> 0 | K18: =I18+J18 -> 202.4 | L18: =F18-(I18-AF18) -> -28.998941 | M18: 27 | N18: 0 | O18: 0 | P18: 0 | Q18: =1.57*1.02 -> 1.6014 | R18: 2.36 | S18: 0 | T18: 0 | U18: 185 | V18: 11 | W18: =M18-N18-P18-O18-Q18-R18-S18-T18+U18+V18 -> 219.0386 | AA18: 0 | AD18: 23 | AE18: =AE17-AD18 -> 3648 | AF18: =N18+O18+P18+Q18+R18+S18+T18+W18+AA18+AD18 -> 246 | AG18: =IF(L18<0,L18*-1,0) -> 28.998941 | AH18: =AF18+AG18 -> 274.99894 | AI18: 0 | AJ18: 70 | AK18: 37 | AL18: =(U18-30.18)*1.9835+AL17 -> 3113.9019 | AM18: =W18-(U18-30.18) -> 64.2186
A19: =A18+1 -> 8 | B19: 6896.23 | C19: 269880 | D19: =C19-C18 -> -179 | E19: =C19-152000 -> 117880 | F19: =D19/$D$2 -> -90.244517 | G19: 195 | H19: 3 | I19: =G19+H19 -> 198 | J19: =IF(L19>0,L19,0) -> 0 | K19: =I19+J19 -> 198 | L19: =F19-(I19-AF19) -> -46.244517 | M19: 27 | N19: 0 | O19: 0 | P19: 0 | Q19: =1.57*1.02 -> 1.6014 | R19: 2.19 | S19: 0 | T19: 0 | U19: 181 | V19: 11 | W19: =M19-N19-P19-O19-Q19-R19-S19-T19+U19+V19 -> 215.2086 | AA19: 0 | AD19: 23 | AE19: =AE18-AD19 -> 3625 | AF19: =N19+O19+P19+Q19+R19+S19+T19+W19+AA19+AD19 -> 242 | AG19: =IF(L19<0,L19*-1,0) -> 46.244517 | AH19: =AF19+AG19 -> 288.24452 | AI19: 0 | AJ19: 67 | AK19: 36 | AL19: =(U19-30)*1.9835+AL18 -> 3413.4104 | AM19: =W19-(U19-30) -> 64.2086
A20: =A19+1 -> 9 | B20: 6896.2 | C20: 269772 | D20: =C20-C19 -> -108 | E20: =C20-152000 -> 117772 | F20: =D20/$D$2 -> -54.449206 | G20: 194 | H20: 3 | I20: =G20+H20 -> 197 | J20: =IF(L20>0,L20,0) -> 0 | K20: =I20+J20 -> 197 | L20: =F20-(I20-AF20) -> -11.449206 | M20: 26 | N20: 0 | O20: 0 | P20: 0 | Q20: =1.57*1.02 -> 1.6014 | R20: 2.29 | S20: 0 | T20: 0 | U20: 180 | V20: 11 | W20: =M20-N20-P20-O20-Q20-R20-S20-T20+U20+V20 -> 213.1086 | AA20: 0 | AD20: 23 | AE20: =AE19-AD20 -> 3602 | AF20: =N20+O20+P20+Q20+R20+S20+T20+W20+AA20+AD20 -> 240 | AG20: =IF(L20<0,L20*-1,0) -> 11.449206 | AH20: =AF20+AG20 -> 251.44921 | AI20: 0 | AJ20: 60 | AK20: 32 | AL20: =(U20-33.84)*1.9835+AL19 -> 3703.3188 | AM20: =W20-(U20-33.84) -> 66.9486
A21: =A20+1 -> 10 | B21: 6896.16 | C21: 269629 | D21: =C21-C20 -> -143 | E21: =C21-152000 -> 117629 | F21: =D21/$D$2 -> -72.094782 | G21: 182 | H21: 2.6 | I21: =G21+H21 -> 184.6 | J21: =IF(L21>0,L21,0) -> 0 | K21: =I21+J21 -> 184.6 | L21: =F21-(I21-AF21) -> -14.694782 | M21: 28 | N21: 0 | O21: 0 | P21: 0 | Q21: =1.57*1.02 -> 1.6014 | R21: 2.52 | S21: 0 | T21: 0 | U21: 180 | V21: 11 | W21: =M21-N21-P21-O21-Q21-R21-S21-T21+U21+V21 -> 214.8786 | AA21: 0 | AD21: 23 | AE21: =AE20-AD21 -> 3579 | AF21: =N21+O21+P21+Q21+R21+S21+T21+W21+AA21+AD21 -> 242 | AG21: =IF(L21<0,L21*-1,0) -> 14.694782 | AH21: =AF21+AG21 -> 256.69478 | AI21: 0 | AJ21: 48 | AK21: 25 | AL21: =(U21-41.5)*1.9835+AL20 -> 3978.0335 | AM21: =W21-(U21-41.5) -> 76.3786
A22: =A21+1 -> 11 | B22: 6896.11 | C22: 269449 | D22: =C22-C21 -> -180 | E22: =C22-152000 -> 117449 | F22: =D22/$D$2 -> -90.748677 | G22: 146 | H22: 1.5 | I22: =G22+H22 -> 147.5 | J22: =IF(L22>0,L22,0) -> 3.7513234 | K22: =I22+J22 -> 151.25132 | L22: =F22-(I22-AF22) -> 3.7513234 | M22: 28 | N22: 0 | O22: 0 | P22: 0 | Q22: =1.57*1.02 -> 1.6014 | R22: 2.19 | S22: 0 | T22: 0 | U22: 180 | V22: 11 | W22: =M22-N22-P22-O22-Q22-R22-S22-T22+U22+V22 -> 215.2086 | AA22: 0 | AD22: 23 | AE22: =AE21-AD22 -> 3556 | AF22: =N22+O22+P22+Q22+R22+S22+T22+W22+AA22+AD22 -> 242 | AG22: =IF(L22<0,L22*-1,0) -> 0 | AH22: =AF22+AG22 -> 242 | AI22: 0.06 | AJ22: 54 | AK22: 21 | AL22: =(U22-41.5)*1.9835+AL21 -> 4252.7483 | AM22: =W22-(U22-41.5) -> 76.7086
A23: =A22+1 -> 12 | B23: 6896.09 | C23: 269378 | D23: =C23-C22 -> -71 | E23: =C23-152000 -> 117378 | F23: =D23/$D$2 -> -35.795311 | G23: 173 | H23: 3.2 | I23: =G23+H23 -> 176.2 | J23: =IF(L23>0,L23,0) -> 30.004689 | K23: =I23+J23 -> 206.20469 | L23: =F23-(I23-AF23) -> 30.004689 | M23: 28 | N23: 0 | O23: 0 | P23: 0 | Q23: =1.57*1.02 -> 1.6014 | R23: 2.3 | S23: 0 | T23: 0 | U23: 180 | V23: 11 | W23: =M23-N23-P23-O23-Q23-R23-S23-T23+U23+V23 -> 215.0986 | AA23: 0 | AD23: 23 | AE23: =AE22-AD23 -> 3533 | AF23: =N23+O23+P23+Q23+R23+S23+T23+W23+AA23+AD23 -> 242 | AG23: =IF(L23<0,L23*-1,0) -> 0 | AH23: =AF23+AG23 -> 242 | AI23: 0.12 | AJ23: 41 | AK23: 23 | AL23: =(U23-44.5)*1.9835+AL22 -> 4521.5125 | AM23: =W23-(U23-44.5) -> 79.5986
A24: =A23+1 -> 13 | B24: 6896.06 | C24: 269270 | D24: =C24-C23 -> -108 | E24: =C24-152000 -> 117270 | F24: =D24/$D$2 -> -54.449206 | G24: 144 | H24: 2.4 | I24: =G24+H24 -> 146.4 | J24: =IF(L24>0,L24,0) -> 0 | K24: =I24+J24 -> 146.4 | L24: =F24-(I24-AF24) -> -4.7492059 | M24: 12 | N24: 0 | O24: 0 | P24: 0 | Q24: =1.57*1.02 -> 1.6014 | R24: 2.38 | S24: 0 | T24: 0 | U24: 158 | V24: 4.1 | W24: =M24-N24-P24-O24-Q24-R24-S24-T24+U24+V24 -> 170.1186 | AA24: 0 | AD24: 22 | AE24: =AE23-AD24 -> 3511 | AF24: =N24+O24+P24+Q24+R24+S24+T24+W24+AA24+AD24 -> 196.1 | AG24: =IF(L24<0,L24*-1,0) -> 4.7492059 | AH24: =AF24+AG24 -> 200.84921 | AI24: 0 | AJ24: 38 | AK24: 24 | AL24: =(U24-11.75)*1.9835+AL23 -> 4811.5994 | AM24: =W24-(U24-11.75) -> 23.8686
A25: =A24+1 -> 14 | B25: 6896.06 | C25: 269270 | D25: =C25-C24 -> 0 | E25: =C25-152000 -> 117270 | F25: =D25/$D$2 -> 0 | G25: 165 | H25: 2.3 | I25: =G25+H25 -> 167.3 | J25: =IF(L25>0,L25,0) -> 5.3 | K25: =I25+J25 -> 172.6 | L25: =F25-(I25-AF25) -> 5.3 | M25: 4.6 | N25: 0 | O25: 0 | P25: 0 | Q25: =1.57*1.02 -> 1.6014 | R25: 2.19 | S25: 0 | T25: =M25-(Q25+R25+S25) -> 0.8086 | U25: 146 | V25: 0 | W25: =M25-N25-P25-O25-Q25-R25-S25-T25+U25+V25 -> 146 | AA25: 0 | AD25: 22 | AE25: =AE24-AD25 -> 3489 | AF25: =N25+O25+P25+Q25+R25+S25+T25+W25+AA25+AD25 -> 172.6 | AG25: =IF(L25<0,L25*-1,0) -> 0 | AH25: =AF25+AG25 -> 172.6 | AI25: 0.04 | AJ25: 44 | AK25: 26 | AL25: =W25*1.9835+AL24 -> 5101.1904
A26: =A25+1 -> 15 | B26: 6896.04 | C26: 269198 | D26: =C26-C25 -> -72 | E26: =C26-152000 -> 117198 | F26: =D26/$D$2 -> -36.299471 | G26: 119 | H26: 2 | I26: =G26+H26 -> 121 | J26: =IF(L26>0,L26,0) -> 15.300529 | K26: =I26+J26 -> 136.30053 | L26: =F26-(I26-AF26) -> 15.300529 | M26: 4.6 | N26: 0 | O26: 0 | P26: 0 | Q26: =1.57*1.02 -> 1.6014 | R26: 2.32 | S26: 0 | T26: =M26-(Q26+R26+S26) -> 0.6786 | U26: 146 | V26: 0 | W26: =M26-N26-P26-O26-Q26-R26-S26-T26+U26+V26 -> 146 | AA26: 0 | AD26: 22 | AE26: =AE25-AD26 -> 3467 | AF26: =N26+O26+P26+Q26+R26+S26+T26+W26+AA26+AD26 -> 172.6 | AG26: =IF(L26<0,L26*-1,0) -> 0 | AH26: =AF26+AG26 -> 172.6 | AI26: 0 | AJ26: 48 | AK26: 22 | AL26: =W26*1.9835+AL25 -> 5390.7814
A27: =A26+1 -> 16 | B27: 6896.02 | C27: 269126 | D27: =C27-C26 -> -72 | E27: =C27-152000 -> 117126 | F27: =D27/$D$2 -> -36.299471 | G27: 129 | H27: 1.5 | I27: =G27+H27 -> 130.5 | J27: =IF(L27>0,L27,0) -> 6.8005294 | K27: =I27+J27 -> 137.30053 | L27: =F27-(I27-AF27) -> 6.8005294 | M27: 4.6 | N27: 0 | O27: 0 | P27: 0 | Q27: =1.57*1.02 -> 1.6014 | R27: 2.34 | S27: 0 | T27: =M27-(Q27+R27+S27) -> 0.6586 | U27: 146 | V27: 0 | W27: =M27-N27-P27-O27-Q27-R27-S27-T27+U27+V27 -> 146 | AA27: 0 | AD27: 23 | AE27: =AE26-AD27 -> 3444 | AF27: =N27+O27+P27+Q27+R27+S27+T27+W27+AA27+AD27 -> 173.6 | AG27: =IF(L27<0,L27*-1,0) -> 0 | AH27: =AF27+AG27 -> 173.6 | AI27: 0 | AJ27: 53 | AK27: 25 | AL27: =W27*1.9835+AL26 -> 5680.3724
A28: =A27+1 -> 17 | B28: 6896 | C28: 269055 | D28: =C28-C27 -> -71 | E28: =C28-152000 -> 117055 | F28: =D28/$D$2 -> -35.795311 | G28: 165 | H28: 2.4 | I28: =G28+H28 -> 167.4 | J28: =IF(L28>0,L28,0) -> 0 | K28: =I28+J28 -> 167.4 | L28: =F28-(I28-AF28) -> -29.595311 | M28: 4.6 | N28: 0 | O28: 0 | P28: 0 | Q28: =1.57*1.02 -> 1.6014 | R28: 2.23 | S28: 0 | T28: =M28-(Q28+R28+S28) -> 0.7686 | U28: 146 | V28: 0 | W28: =M28-N28-P28-O28-Q28-R28-S28-T28+U28+V28 -> 146 | AA28: 0 | AD28: 23 | AE28: =AE27-AD28 -> 3421 | AF28: =N28+O28+P28+Q28+R28+S28+T28+W28+AA28+AD28 -> 173.6 | AG28: =IF(L28<0,L28*-1,0) -> 29.595311 | AH28: =AF28+AG28 -> 203.19531 | AI28: 0 | AJ28: 58 | AK28: 27 | AL28: =W28*1.9835+AL27 -> 5969.9634
A29: =A28+1 -> 18 | B29: 6895.98 | C29: 268983 | D29: =C29-C28 -> -72 | E29: =C29-152000 -> 116983 | F29: =D29/$D$2 -> -36.299471 | G29: 152 | H29: 2.8 | I29: =G29+H29 -> 154.8 | J29: =IF(L29>0,L29,0) -> 0 | K29: =I29+J29 -> 154.8 | L29: =F29-(I29-AF29) -> -17.499471 | M29: 4.6 | N29: 0 | O29: 0 | P29: 0 | Q29: =1.57*1.02 -> 1.6014 | R29: 2.31 | S29: 0 | T29: =M29-(Q29+R29+S29) -> 0.6886 | U29: 146 | V29: 0 | W29: =M29-N29-P29-O29-Q29-R29-S29-T29+U29+V29 -> 146 | AA29: 0 | AD29: 23 | AE29: =AE28-AD29 -> 3398 | AF29: =N29+O29+P29+Q29+R29+S29+T29+W29+AA29+AD29 -> 173.6 | AG29: =IF(L29<0,L29*-1,0) -> 17.499471 | AH29: =AF29+AG29 -> 191.09947 | AI29: 0 | AJ29: 59 | AK29: 30 | AL29: =W29*1.9835+AL28 -> 6259.5544
A30: =A29+1 -> 19 | B30: 6895.95 | C30: 268877 | D30: =C30-C29 -> -106 | E30: =C30-152000 -> 116877 | F30: =D30/$D$2 -> -53.440887 | G30: 139 | H30: 2.1 | I30: =G30+H30 -> 141.1 | J30: =IF(L30>0,L30,0) -> 0 | K30: =I30+J30 -> 141.1 | L30: =F30-(I30-AF30) -> -20.940887 | M30: 4.6 | N30: 0 | O30: 0 | P30: 0 | Q30: =1.57*1.02 -> 1.6014 | R30: 2.3 | S30: 0 | T30: =M30-(Q30+R30+S30) -> 0.6986 | U30: 146 | V30: 0 | W30: =M30-N30-P30-O30-Q30-R30-S30-T30+U30+V30 -> 146 | AA30: 0 | AD30: 23 | AE30: =AE29-AD30 -> 3375 | AF30: =N30+O30+P30+Q30+R30+S30+T30+W30+AA30+AD30 -> 173.6 | AG30: =IF(L30<0,L30*-1,0) -> 20.940887 | AH30: =AF30+AG30 -> 194.54089 | AI30: 0 | AJ30: 58 | AK30: 31 | AL30: =W30*1.9835+AL29 -> 6549.1454
A31: =A30+1 -> 20 | B31: 6895.92 | C31: 268770 | D31: =C31-C30 -> -107 | E31: =C31-152000 -> 116770 | F31: =D31/$D$2 -> -53.945047 | G31: 138 | H31: 1.8 | I31: =G31+H31 -> 139.8 | J31: =IF(L31>0,L31,0) -> 0 | K31: =I31+J31 -> 139.8 | L31: =F31-(I31-AF31) -> -21.145047 | M31: 4.6 | N31: 0 | O31: 0 | P31: 0 | Q31: =1.57*1.02 -> 1.6014 | R31: 2.24 | S31: 0 | T31: =M31-(Q31+R31+S31) -> 0.7586 | U31: 145 | V31: 0 | W31: =M31-N31-P31-O31-Q31-R31-S31-T31+U31+V31 -> 145 | AA31: 0 | AD31: 23 | AE31: =AE30-AD31 -> 3352 | AF31: =N31+O31+P31+Q31+R31+S31+T31+W31+AA31+AD31 -> 172.6 | AG31: =IF(L31<0,L31*-1,0) -> 21.145047 | AH31: =AF31+AG31 -> 193.74505 | AI31: 0 | AJ31: 59 | AK31: 31 | AL31: =W31*1.9835+AL30 -> 6836.7529
A32: =A31+1 -> 21 | B32: 6895.89 | C32: 268663 | D32: =C32-C31 -> -107 | E32: =C32-152000 -> 116663 | F32: =D32/$D$2 -> -53.945047 | G32: 131 | H32: 1.7 | I32: =G32+H32 -> 132.7 | J32: =IF(L32>0,L32,0) -> 0 | K32: =I32+J32 -> 132.7 | L32: =F32-(I32-AF32) -> -16.045047 | M32: 4.6 | N32: 0 | O32: 0 | P32: 0 | Q32: =1.57*1.02 -> 1.6014 | R32: 2.31 | S32: 0 | T32: =M32-(Q32+R32+S32) -> 0.6886 | U32: 143 | V32: 0 | W32: =M32-N32-P32-O32-Q32-R32-S32-T32+U32+V32 -> 143 | AA32: 0 | AD32: 23 | AE32: =AE31-AD32 -> 3329 | AF32: =N32+O32+P32+Q32+R32+S32+T32+W32+AA32+AD32 -> 170.6 | AG32: =IF(L32<0,L32*-1,0) -> 16.045047 | AH32: =AF32+AG32 -> 186.64505 | AI32: 0 | AJ32: 60 | AK32: 32 | AL32: =W32*1.9835+AL31 -> 7120.3934
A33: =A32+1 -> 22 | B33: 6895.85 | C33: 268521 | D33: =C33-C32 -> -142 | E33: =C33-152000 -> 116521 | F33: =D33/$D$2 -> -71.590623 | G33: 132 | H33: 1.7 | I33: =G33+H33 -> 133.7 | J33: =IF(L33>0,L33,0) -> 0 | K33: =I33+J33 -> 133.7 | L33: =F33-(I33-AF33) -> -34.690623 | M33: 4.6 | N33: 0 | O33: 0 | P33: 0 | Q33: =1.57*1.02 -> 1.6014 | R33: 2.24 | S33: 0 | T33: =M33-(Q33+R33+S33) -> 0.7586 | U33: 143 | V33: 0 | W33: =M33-N33-P33-O33-Q33-R33-S33-T33+U33+V33 -> 143 | AA33: 0 | AD33: 23 | AE33: =AE32-AD33 -> 3306 | AF33: =N33+O33+P33+Q33+R33+S33+T33+W33+AA33+AD33 -> 170.6 | AG33: =IF(L33<0,L33*-1,0) -> 34.690623 | AH33: =AF33+AG33 -> 205.29062 | AI33: 0 | AJ33: 60 | AK33: 36 | AL33: =W33*1.9835+AL32 -> 7404.0339
A34: =A33+1 -> 23 | B34: 6895.82 | C34: 268414 | D34: =C34-C33 -> -107 | E34: =C34-152000 -> 116414 | F34: =D34/$D$2 -> -53.945047 | G34: 135 | H34: 1.9 | I34: =G34+H34 -> 136.9 | J34: =IF(L34>0,L34,0) -> 0 | K34: =I34+J34 -> 136.9 | L34: =F34-(I34-AF34) -> -20.245047 | M34: 4.6 | N34: 0 | O34: 0 | P34: 0 | Q34: =1.57*1.02 -> 1.6014 | R34: 2.22 | S34: 0 | T34: =M34-(Q34+R34+S34) -> 0.7786 | U34: 143 | V34: 0 | W34: =M34-N34-P34-O34-Q34-R34-S34-T34+U34+V34 -> 143 | AA34: 0 | AD34: 23 | AE34: =AE33-AD34 -> 3283 | AF34: =N34+O34+P34+Q34+R34+S34+T34+W34+AA34+AD34 -> 170.6 | AG34: =IF(L34<0,L34*-1,0) -> 20.245047 | AH34: =AF34+AG34 -> 190.84505 | AI34: 0 | AJ34: 56 | AK34: 32 | AL34: =W34*1.9835+AL33 -> 7687.6744
A35: =A34+1 -> 24 | B35: 6895.79 | C35: 268307 | D35: =C35-C34 -> -107 | E35: =C35-152000 -> 116307 | F35: =D35/$D$2 -> -53.945047 | G35: 130 | H35: 2 | I35: =G35+H35 -> 132 | J35: =IF(L35>0,L35,0) -> 0 | K35: =I35+J35 -> 132 | L35: =F35-(I35-AF35) -> -15.345047 | M35: 4.6 | N35: 0 | O35: 0 | P35: 0 | Q35: =1.57*1.02 -> 1.6014 | R35: 2.29 | S35: 0 | T35: =M35-(Q35+R35+S35) -> 0.7086 | U35: 143 | V35: 0 | W35: =M35-N35-P35-O35-Q35-R35-S35-T35+U35+V35 -> 143 | AA35: 0 | AD35: 23 | AE35: =AE34-AD35 -> 3260 | AF35: =N35+O35+P35+Q35+R35+S35+T35+W35+AA35+AD35 -> 170.6 | AG35: =IF(L35<0,L35*-1,0) -> 15.345047 | AH35: =AF35+AG35 -> 185.94505 | AI35: 0 | AJ35: 54 | AK35: 31 | AL35: =W35*1.9835+AL34 -> 7971.3149
A36: =A35+1 -> 25 | B36: 6895.77 | C36: 268236 | D36: =C36-C35 -> -71 | E36: =C36-152000 -> 116236 | F36: =D36/$D$2 -> -35.795311 | G36: 133 | H36: 2.6 | I36: =G36+H36 -> 135.6 | J36: =IF(L36>0,L36,0) -> 0 | K36: =I36+J36 -> 135.6 | L36: =F36-(I36-AF36) -> -0.79531132 | M36: 4.6 | N36: 0 | O36: 0 | P36: 0 | Q36: =1.57*1.02 -> 1.6014 | R36: 2.18 | S36: 0 | T36: =M36-(Q36+R36+S36) -> 0.8186 | U36: 143 | V36: 0 | W36: =M36-N36-P36-O36-Q36-R36-S36-T36+U36+V36 -> 143 | AA36: 0 | AD36: 23 | AE36: =AE35-AD36 -> 3237 | AF36: =N36+O36+P36+Q36+R36+S36+T36+W36+AA36+AD36 -> 170.6 | AG36: =IF(L36<0,L36*-1,0) -> 0.79531132 | AH36: =AF36+AG36 -> 171.39531 | AI36: 0.05 | AJ36: 52 | AK36: 30 | AL36: =W36*1.9835+AL35 -> 8254.9554
... A40: =A39+1 -> 29 | B40: 6895.82 | C40: 268414 | D40: =C40-C39 -> 178 | E40: =C40-152000 -> 116414 | F40: =D40/$D$2 -> 89.740358 | G40: 103 | H40: 1.2 | I40: =G40+H40 -> 104.2 | J40: =IF(L40>0,L40,0) -> 11.940358 | K40: =I40+J40 -> 116.14036 | L40: =F40-(I40-AF40) -> 11.940358 | M40: 3.4 | N40: 0 | O40: 0 | P40: 0 | Q40: =1.57*1.02 -> 1.6014 | R40: 0.05 | S40: 0 | T40: =M40-(Q40+R40+S40) -> 1.7486 | U40: 0 | V40: 0 | W40: =M40-N40-P40-O40-Q40-R40-S40-T40+U40+V40 -> 0 | AA40: 0 | AD40: 23 | AE40: =AE39-AD40 -> 3145 | AF40: =N40+O40+P40+Q40+R40+S40+T40+W40+AA40+AD40 -> 26.4 | AG40: =IF(L40<0,L40*-1,0) -> 0 | AH40: =AF40+AG40 -> 26.4 | AI40: 0 | AJ40: 23 | AK40: 7 | AL40: =W40*1.9835+AL39 -> 8822.2364
A41: 30 | B41: 6895.84 | C41: 268485 | D41: =C41-C40 -> 71 | E41: =C41-152000 -> 116485 | F41: =D41/$D$2 -> 35.795311 | G41: 97 | H41: 1.2 | I41: =G41+H41 -> 98.2 | J41: =IF(L41>0,L41,0) -> 0 | K41: =I41+J41 -> 98.2 | L41: =F41-(I41-AF41) -> -36.004689 | M41: 3.4 | N41: 0 | O41: 0 | P41: 0 | Q41: =1.57*1.02 -> 1.6014 | R41: 2.3 | S41: 0 | T41: =M41-(Q41+R41+S41) -> -0.5014 | U41: 0 | V41: 0 | W41: =M41-N41-P41-O41-Q41-R41-S41-T41+U41+V41 -> 0 | AA41: 0 | AD41: 23 | AE41: =AE40-AD41 -> 3122 | AF41: =N41+O41+P41+Q41+R41+S41+T41+W41+AA41+AD41 -> 26.4 | AG41: =IF(L41<0,L41*-1,0) -> 36.004689 | AH41: =AF41+AG41 -> 62.404689 | AI41: 0 | AJ41: 30 | AK41: 0 | AL41: =W41*1.9835+AL40 -> 8822.2364
A43: MONTH / CFS | F43: =SUM(F12:F41) -> -1228.1321 | G43: =SUM(G12:G41) -> 4795 | H43: =SUM(H12:H41) -> 78.1 | I43: =SUM(I12:I41) -> 4873.1 | J43: =SUM(J12:J41) -> 127.78336 | K43: =SUM(K12:K41) -> 5000.8834 | L43: =SUM(L12:L41) -> -349.03209 | M43: =SUM(M12:M41) -> 288 | ... O43: =SUM(O12:O41) -> 0 | Q43: =SUM(Q12:Q41) -> 48.042 | R43: =SUM(R12:R41) -> 72.48 | S43: =SUM(S13:S41) -> 0 | T43: =SUM(T13:T41) -> 9.7006 | U43: =SUM(U12:U41) -> 4691 | V43: =SUM(V12:V41) -> 76.2 | W43: =SUM(W12:W41)-AM43 -> 4447.81 | AD43: =SUM(AD12:AD41) -> 697 | AF43: =SUM(AF12:AF41) -> 5752.2 | AG43: =SUM(AG12:AG41) -> 476.81545 | AH43: =SUM(AH12:AH41) -> 6229.0155 | AI43: =SUM(AI12:AI41) -> 0.43 | AJ43: =AVERAGE(AJ12:AJ41) -> 52.133333 | AK43: =AVERAGE(AK12:AK42) -> 27.433333 | AL43: Avg | AM43: =SUM(AM12:AM41) -> 475.8688
A44: MONTH / AF | D44: =SUM(D12:D41) -> -2436 | F44: =F43*$D$2 -> -2436 | G44: =G43*$D$2 -> 9510.8825 | H44: =H43*$D$2 -> 154.91135 | I44: =I43*$D$2 -> 9665.7939 | J44: =J43*$D$2 -> 253.4583 | K44: =K43*$D$2 -> 9919.2522 | L44: =L43*$D$2 -> -692.30515 | M44: =M43*$D$2 -> 571.248 | ... O44: =O43*$D$2 -> 0 | Q44: =Q43*$D$2 -> 95.291307 | R44: =R43*$D$2 -> 143.76408 | S44: =S43*$D$2 -> 0 | T44: =T43*$D$2 -> 19.24114 | U44: =U43*$D$2 -> 9304.5985 | V44: =V43*$D$2 -> 151.1427 | W44: =W43*$D$2 -> 8822.2311 | AD44: =AD43*$D$2 -> 1382.4995 | AF44: =AF43*$D$2 -> 11409.489 | AG44: =AG43*$D$2 -> 945.76345 | AH44: =AH43*$D$2 -> 12355.252 | AJ44: =MAX(AJ12:AJ41) -> 70 | AK44: =MAX(AK12:AK42) -> 37 | AL44: HI | AM44: =AM43*$D$2 -> 943.88576
A46: SEASON / CFS | AJ46: =MIN(AJ12:AJ41) -> 23 | AK46: =MIN(AK12:AK42) -> 0 | AL46: LO
A47: SEASON / AF
...

Sheet DEC
K1: MCPHEE RESERVOIR INFLOW/OUTFLOW TABULATION
A2: AF/cfs CONVERT FACTOR | D2: 1.9835 | K2: DECEMBER "2006"
D4: RESERVOIR | U4: INFLOW/OUTFLOW (CFS) | AJ4: WEATHER | AN4: ADJUSTMENTS
A5: DATE | B5: RESERV | C5: RESERV | D5: AC FT | E5: ACTIVE | F5: CONV TO | G5: DOLORES | H5: LOST | I5: RECORD | J5: CALC | K5: TOTAL | L5: CALC | M5: DOLORES TUNNEL | U5: LONE | V5: U | W5: TOTAL | X5: MVI | Y5: TO EX & | Z5: MVI | AA5: DV CR | AB5: D/S SENIOR | AD5: BELOW | AE5: FISH | AF5: RECORD | AG5: CALC | AH5: TOTAL | AI5: RAIN | AJ5: MAX | AK5: MIN | AL5: NAR | AM5: MVI | AN5: MVI | AO5: MVI | AP5: U/S | AQ5: TOTTEN
A6: DEC | B6: ELEV | C6: AC FT | D6: CHANGE | E6: CAP | F6: CFS | G6: RIVER | H6: CAN | I6: INFLOW | J6: INFLOW | K6: INFLOW | L6: INF/OTF | M6: TOT DIV | N6: WET | O6: UTE | P6: QUEST | Q6: MWC | R6: CTZ | S6: CTZ & | T6: F-BAY | U6: PINE | V6: LAT | W6: MVI | X6: CALL | Y6: U/S EX | Z6: PROJ | AA6: CANAL | AD6: MCP | AE6: LEFT | AF6: OTF | AG6: OTF | AH6: OTF | AJ6: TMP | AK6: TMP | AL6: CALL | AM6: STOCK | AN6: STORED | AO6: STORED | AP6: USERS | AQ6: (FRESH
E7: AC FT | N7: LAND | O7: F&R | S7: UTE | T7: SPILL | AL7: AC.FT. | AM7: CFS | AN7: Apr-Jun | AO7: EVAP | AP7: EXCH | AQ7: WATER)
N8: 1.03 | O8: 1.05 | P8: 1.02 | Q8: 1.02 | R8: 1.04 | S8: PROJ | AO8: AC.FT.
A9: SEASON BAL
A10: YTD | B10: =NOV!B41 -> 6895.84 | C10: =NOV!C41 -> 268485 | D10: =NOV!D50 -> -2436 | E10: =NOV!E50 -> 116485 | F10: =NOV!F49 -> -1228.1321 | G10: =NOV!G49 -> 4795 | H10: =NOV!H49 -> 78.1 | I10: =NOV!I49 -> 4873.1 | J10: =NOV!J49 -> 127.78336 | K10: =NOV!K49 -> 5000.8834 | L10: =NOV!L49 -> -349.03209 | M10: =NOV!M49 -> 288 | ... O10: =NOV!O49 -> 0 | Q10: =NOV!Q49 -> 48.042 | R10: =NOV!R49 -> 72.48 | S10: =NOV!S49 -> 0 | T10: =NOV!T49 -> 9.7006 | U10: =NOV!U49 -> 4691 | V10: =NOV!V49 -> 76.2 | W10: =NOV!W49 -> 4447.81 | AD10: =NOV!AD49 -> 697 | AE10: =NOV!AE49 -> 3122 | AF10: =NOV!AF49 -> 5752.2 | AG10: =NOV!AG49 -> 476.81545 | AH10: =NOV!AH49 -> 6229.0155 | AI10: =NOV!AI49 -> 0.43 | AL10: =NOV!AL50 -> 8822.2364 | AM10: =NOV!AM49 -> 796.8688
A12: 1 | B12: 6895.86 | C12: 268556 | D12: =C12-C10 -> 71 | E12: =C12-152000 -> 116556 | F12: =D12/$D$2 -> 35.795311 | G12: 90 | H12: 1.5 | I12: =G12+H12 -> 91.5 | J12: =IF(L12>0,L12,0) -> 0 | K12: =I12+J12 -> 91.5 | L12: =F12-(I12-AF12) -> -28.304689 | M12: 3.4 | N12: 0 | O12: 0 | P12: 0 | Q12: =1.6*1.02 -> 1.632 | R12: 2.15 | S12: 0 | T12: =M12-(Q12+R12+S12) -> -0.382 | U12: 0 | V12: 0 | W12: =M12-N12-O12-P12-Q12-R12-S12-T12+U12+V12 -> 0 | AA12: 0 | AD12: 24 | AE12: =AE10-AD12 -> 3098 | AF12: =N12+O12+P12+Q12+R12+S12+T12+W12+AA12+AD12 -> 27.4 | AG12: =IF(L12<0,L12*-1,0) -> 28.304689 | AH12: =AF12+AG12 -> 55.704689 | AI12: 0 | AJ12: 31 | AK12: 8 | AL12: =AL10+(W12*1.9835) -> 8822.2364 | AM12: 0
A13: =A12+1 -> 2 | B13: 6895.89 | C13: 268663 | D13: =C13-C12 -> 107 | E13: =C13-152000 -> 116663 | F13: =D13/$D$2 -> 53.945047 | G13: 95 | H13: 1.4 | I13: =G13+H13 -> 96.4 | J13: =IF(L13>0,L13,0) -> 0 | K13: =I13+J13 -> 96.4 | L13: =F13-(I13-AF13) -> -15.054953 | M13: 3.4 | N13: 0 | O13: 0 | P13: 0 | Q13: =1.6*1.02 -> 1.632 | R13: 2.35 | S13: 0 | T13: =M13-(Q13+R13+S13) -> -0.582 | U13: 0 | V13: 0 | W13: =M13-N13-O13-P13-Q13-R13-S13-T13+U13+V13 -> 0 | AA13: 0 | AD13: 24 | AE13: =AE12-AD13 -> 3074 | AF13: =N13+O13+P13+Q13+R13+S13+T13+W13+AA13+AD13 -> 27.4 | AG13: =IF(L13<0,L13*-1,0) -> 15.054953 | AH13: =AF13+AG13 -> 42.454953 | AI13: 0 | AJ13: 32 | AK13: 11 | AL13: =AL12 -> 8822.2364 | AM13: 0
A14: =A13+1 -> 3 | B14: 6895.92 | C14: 268770 | D14: =C14-C13 -> 107 | E14: =C14-152000 -> 116770 | F14: =D14/$D$2 -> 53.945047 | G14: 87 | H14: 1.1 | I14: =G14+H14 -> 88.1 | J14: =IF(L14>0,L14,0) -> 0 | K14: =I14+J14 -> 88.1 | L14: =F14-(I14-AF14) -> -6.7549534 | M14: 3.4 | N14: 0 | O14: 0 | P14: 0 | Q14: =1.6*1.02 -> 1.632 | R14: 2.35 | S14: 0 | T14: =M14-(Q14+R14+S14) -> -0.582 | U14: 0 | V14: 0 | W14: =M14-N14-O14-P14-Q14-R14-S14-T14+U14+V14 -> 0 | AA14: 0 | AD14: 24 | AE14: =AE13-AD14 -> 3050 | AF14: =N14+O14+P14+Q14+R14+S14+T14+W14+AA14+AD14 -> 27.4 | AG14: =IF(L14<0,L14*-1,0) -> 6.7549534 | AH14: =AF14+AG14 -> 34.154953 | AI14: 0 | AJ14: 34 | AK14: 7 | AL14: =AL13 -> 8822.2364 | AM14: 0
A15: =A14+1 -> 4 | B15: 6895.95 | C15: 268877 | D15: =C15-C14 -> 107 | E15: =C15-152000 -> 116877 | F15: =D15/$D$2 -> 53.945047 | G15: 83 | H15: 0.9 | I15: =G15+H15 -> 83.9 | J15: =IF(L15>0,L15,0) -> 0 | K15: =I15+J15 -> 83.9 | L15: =F15-(I15-AF15) -> -2.5549534 | M15: 3.4 | N15: 0 | O15: 0 | P15: 0 | Q15: =1.6*1.02 -> 1.632 | R15: 2.38 | S15: 0 | T15: =M15-(Q15+R15+S15) -> -0.612 | U15: 0 | V15: 0 | W15: =M15-N15-O15-P15-Q15-R15-S15-T15+U15+V15 -> 0 | AA15: 0 | AD15: 24 | AE15: =AE14-AD15 -> 3026 | AF15: =N15+O15+P15+Q15+R15+S15+T15+W15+AA15+AD15 -> 27.4 | AG15: =IF(L15<0,L15*-1,0) -> 2.5549534 | AH15: =AF15+AG15 -> 29.954953 | AI15: 0 | AJ15: 43 | AK15: 12 | AL15: =AL14 -> 8822.2364 | AM15: 0
A16: =A15+1 -> 5 | B16: 6895.98 | C16: 268983 | D16: =C16-C15 -> 106 | E16: =C16-152000 -> 116983 | F16: =D16/$D$2 -> 53.440887 | G16: 109 | H16: 0.69 | I16: =G16+H16 -> 109.69 | J16: =IF(L16>0,L16,0) -> 0 | K16: =I16+J16 -> 109.69 | L16: =F16-(I16-AF16) -> -28.849113 | M16: 3.4 | N16: 0 | O16: 0 | P16: 0 | Q16: =1.6*1.02 -> 1.632 | R16: 3.37 | S16: 0 | T16: =M16-(Q16+R16+S16) -> -1.602 | U16: 0 | V16: 0 | W16: =M16-N16-O16-P16-Q16-R16-S16-T16+U16+V16 -> 0 | AA16: 0 | AD16: 24 | AE16: =AE15-AD16 -> 3002 | AF16: =N16+O16+P16+Q16+R16+S16+T16+W16+AA16+AD16 -> 27.4 | AG16: =IF(L16<0,L16*-1,0) -> 28.849113 | AH16: =AF16+AG16 -> 56.249113 | AI16: 0 | AJ16: 46 | AK16: 19 | AL16: =AL15 -> 8822.2364 | AM16: 0
A17: =A16+1 -> 6 | B17: 6896.01 | C17: 269091 | D17: =C17-C16 -> 108 | E17: =C17-152000 -> 117091 | F17: =D17/$D$2 -> 54.449206 | G17: 113 | H17: 0.76 | I17: =G17+H17 -> 113.76 | J17: =IF(L17>0,L17,0) -> 0 | K17: =I17+J17 -> 113.76 | L17: =F17-(I17-AF17) -> -31.910794 | M17: 3.4 | N17: 0 | O17: 0 | P17: 0 | Q17: =1.6*1.02 -> 1.632 | R17: 2.6 | S17: 0 | T17: =M17-(Q17+R17+S17) -> -0.832 | U17: 0 | V17: 0 | W17: =M17-N17-O17-P17-Q17-R17-S17-T17+U17+V17 -> 0 | AA17: 0 | AD17: 24 | AE17: =AE16-AD17 -> 2978 | AF17: =N17+O17+P17+Q17+R17+S17+T17+W17+AA17+AD17 -> 27.4 | AG17: =IF(L17<0,L17*-1,0) -> 31.910794 | AH17: =AF17+AG17 -> 59.310794 | AI17: 0 | AJ17: 50 | AK17: 23 | AL17: =AL16 -> 8822.2364 | AM17: 0
A18: =A17+1 -> 7 | B18: 6896.05 | C18: 269234 | D18: =C18-C17 -> 143 | E18: =C18-152000 -> 117234 | F18: =D18/$D$2 -> 72.094782 | G18: 112 | H18: 0.86 | I18: =G18+H18 -> 112.86 | J18: =IF(L18>0,L18,0) -> 0 | K18: =I18+J18 -> 112.86 | L18: =F18-(I18-AF18) -> -14.365218 | M18: 3.4 | N18: 0 | O18: 0 | P18: 0 | Q18: =1.6*1.02 -> 1.632 | R18: 2.5 | S18: 0 | T18: =M18-(Q18+R18+S18) -> -0.732 | U18: 0 | V18: 0 | W18: =M18-N18-O18-P18-Q18-R18-S18-T18+U18+V18 -> 0 | AA18: 0 | AD18: 23 | AE18: =AE17-AD18 -> 2955 | AF18: =N18+O18+P18+Q18+R18+S18+T18+W18+AA18+AD18 -> 26.4 | AG18: =IF(L18<0,L18*-1,0) -> 14.365218 | AH18: =AF18+AG18 -> 40.765218 | AI18: 0 | AJ18: 51 | AK18: 24 | AL18: =AL17 -> 8822.2364 | AM18: 0
A19: =A18+1 -> 8 | B19: 6896.09 | C19: 269378 | D19: =C19-C18 -> 144 | E19: =C19-152000 -> 117378 | F19: =D19/$D$2 -> 72.598941 | G19: 128 | H19: 0.99 | I19: =G19+H19 -> 128.99 | J19: =IF(L19>0,L19,0) -> 0 | K19: =I19+J19 -> 128.99 | L19: =F19-(I19-AF19) -> -29.791059 | M19: 3.6 | N19: 0 | O19: 0 | P19: 0 | Q19: =1.6*1.02 -> 1.632 | R19: 2.54 | S19: 0 | T19: =M19-(Q19+R19+S19) -> -0.572 | U19: 0 | V19: 0 | W19: =M19-N19-O19-P19-Q19-R19-S19-T19+U19+V19 -> 0 | AA19: 0 | AD19: 23 | AE19: =AE18-AD19 -> 2932 | AF19: =N19+O19+P19+Q19+R19+S19+T19+W19+AA19+AD19 -> 26.6 | AG19: =IF(L19<0,L19*-1,0) -> 29.791059 | AH19: =AF19+AG19 -> 56.391059 | AI19: 0 | AJ19: 50 | AK19: 24 | AL19: =AL18 -> 8822.2364 | AM19: 0
A20: =A19+1 -> 9 | B20: 6896.13 | C20: 269521 | D20: =C20-C19 -> 143 | E20: =C20-152000 -> 117521 | F20: =D20/$D$2 -> 72.094782 | G20: 130 | H20: 1 | I20: =G20+H20 -> 131 | J20: =IF(L20>0,L20,0) -> 0 | K20: =I20+J20 -> 131 | L20: =F20-(I20-AF20) -> -32.205218 | M20: 3.7 | N20: 0 | O20: 0 | P20: 0 | Q20: =1.6*1.02 -> 1.632 | R20: 2.43 | S20: 0 | T20: =M20-(Q20+R20+S20) -> -0.362 | U20: 0 | V20: 0 | W20: =M20-N20-O20-P20-Q20-R20-S20-T20+U20+V20 -> 0 | AA20: 0 | AD20: 23 | AE20: =AE19-AD20 -> 2909 | AF20: =N20+O20+P20+Q20+R20+S20+T20+W20+AA20+AD20 -> 26.7 | AG20: =IF(L20<0,L20*-1,0) -> 32.205218 | AH20: =AF20+AG20 -> 58.905218 | AI20: 0 | AJ20: 47 | AK20: 24 | AL20: =AL19 -> 8822.2364 | AM20: 0
A21: =A20+1 -> 10 | B21: 6896.17 | C21: 269665 | D21: =C21-C20 -> 144 | E21: =C21-152000 -> 117665 | F21: =D21/$D$2 -> 72.598941 | G21: 126 | H21: 0.99 | I21: =G21+H21 -> 126.99 | J21: =IF(L21>0,L21,0) -> 0 | K21: =I21+J21 -> 126.99 | L21: =F21-(I21-AF21) -> -27.691059 | M21: 3.7 | N21: 0 | O21: 0 | P21: 0 | Q21: =1.6*1.02 -> 1.632 | R21: 2.39 | S21: 0 | T21: =M21-(Q21+R21+S21) -> -0.322 | U21: 0 | V21: 0 | W21: =M21-N21-O21-P21-Q21-R21-S21-T21+U21+V21 -> 0 | AA21: 0 | AD21: 23 | AE21: =AE20-AD21 -> 2886 | AF21: =N21+O21+P21+Q21+R21+S21+T21+W21+AA21+AD21 -> 26.7 | AG21: =IF(L21<0,L21*-1,0) -> 27.691059 | AH21: =AF21+AG21 -> 54.391059 | AI21: 0.36 | AJ21: 46 | AK21: 25 | AL21: =AL20 -> 8822.2364 | AM21: 0
A22: =A21+1 -> 11 | B22: 6896.2 | C22: 269772 | D22: =C22-C21 -> 107 | E22: =C22-152000 -> 117772 | F22: =D22/$D$2 -> 53.945047 | G22: 130 | H22: 0.99 | I22: =G22+H22 -> 130.99 | J22: =IF(L22>0,L22,0) -> 0 | K22: =I22+J22 -> 130.99 | L22: =F22-(I22-AF22) -> -50.344953 | M22: 3.7 | N22: 0 | O22: 0 | P22: 0 | Q22: =1.6*1.02 -> 1.632 | R22: 3.713 | S22: 0 | T22: =M22-(Q22+R22+S22) -> -1.645 | U22: 0 | V22: 0 | W22: =M22-N22-O22-P22-Q22-R22-S22-T22+U22+V22 -> 0 | AA22: 0 | AD22: 23 | AE22: =AE21-AD22 -> 2863 | AF22: =N22+O22+P22+Q22+R22+S22+T22+W22+AA22+AD22 -> 26.7 | AG22: =IF(L22<0,L22*-1,0) -> 50.344953 | AH22: =AF22+AG22 -> 77.044953 | AI22: 0 | AJ22: 34 | AK22: 17 | AL22: =AL21 -> 8822.2364 | AM22: 0
A23: =A22+1 -> 12 | B23: 6896.24 | C23: 269916 | D23: =C23-C22 -> 144 | E23: =C23-152000 -> 117916 | F23: =D23/$D$2 -> 72.598941 | G23: 125 | H23: 0.99 | I23: =G23+H23 -> 125.99 | J23: =IF(L23>0,L23,0) -> 0 | K23: =I23+J23 -> 125.99 | L23: =F23-(I23-AF23) -> -26.691059 | M23: 3.7 | N23: 0 | O23: 0 | P23: 0 | Q23: =1.6*1.02 -> 1.632 | R23: 1.55 | S23: 0 | T23: =M23-(Q23+R23+S23) -> 0.518 | U23: 0 | V23: 0 | W23: =M23-N23-O23-P23-Q23-R23-S23-T23+U23+V23 -> 0 | AA23: 0 | AD23: 23 | AE23: =AE22-AD23 -> 2840 | AF23: =N23+O23+P23+Q23+R23+S23+T23+W23+AA23+AD23 -> 26.7 | AG23: =IF(L23<0,L23*-1,0) -> 26.691059 | AH23: =AF23+AG23 -> 53.391059 | AI23: 0 | AJ23: 38 | AK23: 14 | AL23: =AL22 -> 8822.2364 | AM23: 0
A24: =A23+1 -> 13 | B24: 6896.28 | C24: 270059 | D24: =C24-C23 -> 143 | E24: =C24-152000 -> 118059 | F24: =D24/$D$2 -> 72.094782 | G24: 115 | H24: 0.98 | I24: =G24+H24 -> 115.98 | J24: =IF(L24>0,L24,0) -> 0 | K24: =I24+J24 -> 115.98 | L24: =F24-(I24-AF24) -> -17.185218 | M24: 3.7 | N24: 0 | O24: 0 | P24: 0 | Q24: =1.6*1.02 -> 1.632 | R24: 3.39 | S24: 0 | T24: =M24-(Q24+R24+S24) -> -1.322 | U24: 0 | V24: 0 | W24: =M24-N24-O24-P24-Q24-R24-S24-T24+U24+V24 -> 0 | AA24: 0 | AD24: 23 | AE24: =AE23-AD24 -> 2817 | AF24: =N24+O24+P24+Q24+R24+S24+T24+W24+AA24+AD24 -> 26.7 | AG24: =IF(L24<0,L24*-1,0) -> 17.185218 | AH24: =AF24+AG24 -> 43.885218 | AI24: 0 | AJ24: 43 | AK24: 19 | AL24: =AL23 -> 8822.2364 | AM24: 0
... A28: =A27+1 -> 17 | B28: 6896.44 | C28: 270634 | D28: =C28-C27 -> 144 | E28: =C28-152000 -> 118634 | F28: =D28/$D$2 -> 72.598941 | G28: 76 | H28: 0.72 | I28: =G28+H28 -> 76.72 | J28: =IF(L28>0,L28,0) -> 22.578941 | K28: =I28+J28 -> 99.298941 | L28: =F28-(I28-AF28) -> 22.578941 | M28: 3.7 | N28: 0 | O28: 0 | P28: 0 | Q28: =1.6*1.02 -> 1.632 | R28: 2.29 | S28: 0 | T28: =M28-(Q28+R28+S28) -> -0.222 | U28: 0 | V28: 0 | W28: =M28-N28-O28-P28-Q28-R28-S28-T28+U28+V28 -> 0 | AA28: 0 | AD28: 23 | AE28: =AE27-AD28 -> 2724 | AF28: =N28+O28+P28+Q28+R28+S28+T28+W28+AA28+AD28 -> 26.7 | AG28: =IF(L28<0,L28*-1,0) -> 0 | AH28: =AF28+AG28 -> 26.7 | AI28: 0.08 | AJ28: 42 | AK28: 30 | AL28: =AL27 -> 8822.2364 | AM28: 0
A29: =A28+1 -> 18 | B29: 6896.54 | C29: 270992 | D29: =C29-C28 -> 358 | E29: =C29-152000 -> 118992 | F29: =D29/$D$2 -> 180.48903 | G29: 72 | H29: 0.72 | I29: =G29+H29 -> 72.72 | J29: =IF(L29>0,L29,0) -> 134.46903 | K29: =I29+J29 -> 207.18903 | L29: =F29-(I29-AF29) -> 134.46903 | M29: 3.7 | N29: 0 | O29: 0 | P29: 0 | Q29: =1.6*1.02 -> 1.632 | R29: 2.38 | S29: 0 | T29: =M29-(Q29+R29+S29) -> -0.312 | U29: 0 | V29: 0 | W29: =M29-N29-O29-P29-Q29-R29-S29-T29+U29+V29 -> 0 | AA29: 0 | AD29: 23 | AE29: =AE28-AD29 -> 2701 | AF29: =N29+O29+P29+Q29+R29+S29+T29+W29+AA29+AD29 -> 26.7 | AG29: =IF(L29<0,L29*-1,0) -> 0 | AH29: =AF29+AG29 -> 26.7 | AI29: 0.31 | AJ29: 44 | AK29: 25 | AL29: =AL28+(W29*1.9835) -> 8822.2364 | AM29: 0
A30: =A29+1 -> 19 | B30: 6896.64 | C30: 271351 | D30: =C30-C29 -> 359 | E30: =C30-152000 -> 119351 | F30: =D30/$D$2 -> 180.99319 | G30: 84 | H30: 0.68 | I30: =G30+H30 -> 84.68 | J30: =IF(L30>0,L30,0) -> 123.01319 | K30: =I30+J30 -> 207.69319 | L30: =F30-(I30-AF30) -> 123.01319 | M30: 3.7 | N30: 0 | O30: 0 | P30: 0 | Q30: =1.6*1.02 -> 1.632 | R30: 2.54 | S30: 0 | T30: =M30-(Q30+R30+S30) -> -0.472 | U30: 0 | V30: 0 | W30: =M30-N30-O30-P30-Q30-R30-S30-T30+U30+V30 -> 0 | AA30: 0 | AD30: 23 | AE30: =AE29-AD30 -> 2678 | AF30: =N30+O30+P30+Q30+R30+S30+T30+W30+AA30+AD30 -> 26.7 | AG30: =IF(L30<0,L30*-1,0) -> 0 | AH30: =AF30+AG30 -> 26.7 | AI30: 0.21 | AJ30: 36 | AK30: 21 | AL30: =AL29+(W30*1.9835) -> 8822.2364 | AM30: 0
A31: =A30+1 -> 20 | B31: 6896.66 | C31: 271423 | D31: =C31-C30 -> 72 | E31: =C31-152000 -> 119423 | F31: =D31/$D$2 -> 36.299471 | G31: 69 | H31: 0.57 | I31: =G31+H31 -> 69.57 | J31: =IF(L31>0,L31,0) -> 0 | K31: =I31+J31 -> 69.57 | L31: =F31-(I31-AF31) -> -6.5705294 | M31: 3.7 | N31: 0 | O31: 0 | P31: 0 | Q31: =1.6*1.02 -> 1.632 | R31: 2.34 | S31: 0 | T31: =M31-(Q31+R31+S31) -> -0.272 | U31: 0 | V31: 0 | W31: =M31-N31-O31-P31-Q31-R31-S31-T31+U31+V31 -> 0 | AA31: 0 | AD31: 23 | AE31: =AE30-AD31 -> 2655 | AF31: =N31+O31+P31+Q31+R31+S31+T31+W31+AA31+AD31 -> 26.7 | AG31: =IF(L31<0,L31*-1,0) -> 6.5705294 | AH31: =AF31+AG31 -> 33.270529 | AI31: 0 | AJ31: 28 | AK31: 21 | AL31: =AL30+(W31*1.9835) -> 8822.2364 | AM31: 0
A32: =A31+1 -> 21 | B32: 6896.68 | C32: 271495 | D32: =C32-C31 -> 72 | E32: =C32-152000 -> 119495 | F32: =D32/$D$2 -> 36.299471 | G32: 80 | H32: 0.58 | I32: =G32+H32 -> 80.58 | J32: =IF(L32>0,L32,0) -> 0 | K32: =I32+J32 -> 80.58 | L32: =F32-(I32-AF32) -> -17.580529 | M32: 3.7 | N32: 0 | O32: 0 | P32: 0 | Q32: =1.6*1.02 -> 1.632 | R32: 2.34 | S32: 0 | T32: =M32-(Q32+R32+S32) -> -0.272 | U32: 0 | V32: 0 | W32: =M32-N32-O32-P32-Q32-R32-S32-T32+U32+V32 -> 0 | AA32: 0 | AD32: 23 | AE32: =AE31-AD32 -> 2632 | AF32: =N32+O32+P32+Q32+R32+S32+T32+W32+AA32+AD32 -> 26.7 | AG32: =IF(L32<0,L32*-1,0) -> 17.580529 | AH32: =AF32+AG32 -> 44.280529 | AI32: 0 | AJ32: 37 | AK32: 13 | AL32: =AL31+(W32*1.9835) -> 8822.2364 | AM32: 0
A33: =A32+1 -> 22 | B33: 6896.7 | C33: 271567 | D33: =C33-C32 -> 72 | E33: =C33-152000 -> 119567 | F33: =D33/$D$2 -> 36.299471 | G33: 74 | H33: 0.63 | I33: =G33+H33 -> 74.63 | J33: =IF(L33>0,L33,0) -> 0 | K33: =I33+J33 -> 74.63 | L33: =F33-(I33-AF33) -> -11.630529 | M33: 3.7 | N33: 0 | O33: 0 | P33: 0 | Q33: =1.6*1.02 -> 1.632 | R33: 2.54 | S33: 0 | T33: =M33-(Q33+R33+S33) -> -0.472 | U33: 0 | V33: 0 | W33: =M33-N33-O33-P33-Q33-R33-S33-T33+U33+V33 -> 0 | AA33: 0 | AD33: 23 | AE33: =AE32-AD33 -> 2609 | AF33: =N33+O33+P33+Q33+R33+S33+T33+W33+AA33+AD33 -> 26.7 | AG33: =IF(L33<0,L33*-1,0) -> 11.630529 | AH33: =AF33+AG33 -> 38.330529 | AI33: 0 | AJ33: 38 | AK33: 11 | AL33: =AL32+(W33*1.9835) -> 8822.2364 | AM33: 0
A34: =A33+1 -> 23 | B34: 6896.72 | C34: 271638 | D34: =C34-C33 -> 71 | E34: =C34-152000 -> 119638 | F34: =D34/$D$2 -> 35.795311 | G34: 73 | H34: 0.63 | I34: =G34+H34 -> 73.63 | J34: =IF(L34>0,L34,0) -> 0 | K34: =I34+J34 -> 73.63 | L34: =F34-(I34-AF34) -> -11.134689 | M34: 3.7 | N34: 0 | O34: 0 | P34: 0 | Q34: =1.6*1.02 -> 1.632 | R34: 3.01 | S34: 0 | T34: =M34-(Q34+R34+S34) -> -0.942 | U34: 0 | V34: 0 | W34: =M34-N34-O34-P34-Q34-R34-S34-T34+U34+V34 -> 0 | AA34: 0 | AD34: 23 | AE34: =AE33-AD34 -> 2586 | AF34: =N34+O34+P34+Q34+R34+S34+T34+W34+AA34+AD34 -> 26.7 | AG34: =IF(L34<0,L34*-1,0) -> 11.134689 | AH34: =AF34+AG34 -> 37.834689 | AI34: 0 | AJ34: 40 | AK34: 14 | AL34: =AL33+(W34*1.9835) -> 8822.2364 | AM34: 0
A35: =A34+1 -> 24 | B35: 6896.74 | C35: 271710 | D35: =C35-C34 -> 72 | E35: =C35-152000 -> 119710 | F35: =D35/$D$2 -> 36.299471 | G35: 67 | H35: 0.63 | I35: =G35+H35 -> 67.63 | J35: =IF(L35>0,L35,0) -> 0 | K35: =I35+J35 -> 67.63 | L35: =F35-(I35-AF35) -> -4.6305294 | M35: 3.7 | N35: 0 | O35: 0 | P35: 0 | Q35: =1.6*1.02 -> 1.632 | R35: 3.56 | S35: 0 | T35: =M35-(Q35+R35+S35) -> -1.492 | U35: 0 | V35: 0 | W35: =M35-N35-O35-P35-Q35-R35-S35-T35+U35+V35 -> 0 | AA35: 0 | AD35: 23 | AE35: =AE34-AD35 -> 2563 | AF35: =N35+O35+P35+Q35+R35+S35+T35+W35+AA35+AD35 -> 26.7 | AG35: =IF(L35<0,L35*-1,0) -> 4.6305294 | AH35: =AF35+AG35 -> 31.330529 | AI35: 0 | AJ35: 37 | AK35: 14 | AL35: =AL34+(W35*1.9835) -> 8822.2364 | AM35: 0
A36: =A35+1 -> 25 | B36: 6896.76 | C36: 271782 | D36: =C36-C35 -> 72 | E36: =C36-152000 -> 119782 | F36: =D36/$D$2 -> 36.299471 | G36: 67 | H36: 0.63 | I36: =G36+H36 -> 67.63 | J36: =IF(L36>0,L36,0) -> 0 | K36: =I36+J36 -> 67.63 | L36: =F36-(I36-AF36) -> -4.6305294 | M36: 3.7 | N36: 0 | O36: 0 | P36: 0 | Q36: =1.6*1.02 -> 1.632 | R36: 2.57 | S36: 0 | T36: =M36-(Q36+R36+S36) -> -0.502 | U36: 0 | V36: 0 | W36: =M36-N36-O36-P36-Q36-R36-S36-T36+U36+V36 -> 0 | AA36: 0 | AD36: 23 | AE36: =AE35-AD36 -> 2540 | AF36: =N36+O36+P36+Q36+R36+S36+T36+W36+AA36+AD36 -> 26.7 | AG36: =IF(L36<0,L36*-1,0) -> 4.6305294 | AH36: =AF36+AG36 -> 31.330529 | AI36: 0 | AJ36: 40 | AK36: 11 | AL36: =AL35+(W36*1.9835) -> 8822.2364 | AM36: 0
A37: =A36+1 -> 26 | B37: 6896.78 | C37: 271854 | D37: =C37-C36 -> 72 | E37: =C37-152000 -> 119854 | F37: =D37/$D$2 -> 36.299471 | G37: 65 | H37: 0.89 | I37: =G37+H37 -> 65.89 | J37: =IF(L37>0,L37,0) -> 0 | K37: =I37+J37 -> 65.89 | L37: =F37-(I37-AF37) -> -2.8905294 | M37: 3.7 | N37: 0 | O37: 0 | P37: 0 | Q37: =1.6*1.02 -> 1.632 | R37: 2.4 | S37: 0 | T37: =M37-(Q37+R37+S37) -> -0.332 | U37: 0 | V37: 0 | W37: =M37-N37-O37-P37-Q37-R37-S37-T37+U37+V37 -> 0 | AA37: 0 | AD37: 23 | AE37: =AE36-AD37 -> 2517 | AF37: =N37+O37+P37+Q37+R37+S37+T37+W37+AA37+AD37 -> 26.7 | AG37: =IF(L37<0,L37*-1,0) -> 2.8905294 | AH37: =AF37+AG37 -> 29.590529 | AI37: 0 | AJ37: 48 | AK37: 19 | AL37: =AL36+(W37*1.9835) -> 8822.2364 | AM37: 0
A38: =A37+1 -> 27 | B38: 6896.8 | C38: 271926 | D38: =C38-C37 -> 72 | E38: =C38-152000 -> 119926 | F38: =D38/$D$2 -> 36.299471 | G38: 122 | H38: 1.2 | I38: =G38+H38 -> 123.2 | J38: =IF(L38>0,L38,0) -> 0 | K38: =I38+J38 -> 123.2 | L38: =F38-(I38-AF38) -> -60.200529 | M38: 3.7 | N38: 0 | O38: 0 | P38: 0 | Q38: =1.6*1.02 -> 1.632 | R38: 2.04 | S38: 0 | T38: =M38-(Q38+R38+S38) -> 0.028 | U38: 0 | V38: 0 | W38: =M38-N38-O38-P38-Q38-R38-S38-T38+U38+V38 -> 0 | AA38: 0 | AD38: 23 | AE38: =AE37-AD38 -> 2494 | AF38: =N38+O38+P38+Q38+R38+S38+T38+W38+AA38+AD38 -> 26.7 | AG38: =IF(L38<0,L38*-1,0) -> 60.200529 | AH38: =AF38+AG38 -> 86.900529 | AI38: 0 | AJ38: 46 | AK38: 31 | AL38: =AL37+(W38*1.9835) -> 8822.2364 | AM38: 0
A39: =A38+1 -> 28 | B39: 6896.84 | C39: 272069 | D39: =C39-C38 -> 143 | E39: =C39-152000 -> 120069 | F39: =D39/$D$2 -> 72.094782 | G39: 124 | H39: 1.2 | I39: =G39+H39 -> 125.2 | J39: =IF(L39>0,L39,0) -> 0 | K39: =I39+J39 -> 125.2 | L39: =F39-(I39-AF39) -> -26.405218 | M39: 3.7 | N39: 0 | O39: 0 | P39: 0 | Q39: =1.6*1.02 -> 1.632 | R39: 2.8 | S39: 0 | T39: =M39-(Q39+R39+S39) -> -0.732 | U39: 0 | V39: 0 | W39: =M39-N39-O39-P39-Q39-R39-S39-T39+U39+V39 -> 0 | AA39: 0 | AD39: 23 | AE39: =AE38-AD39 -> 2471 | AF39: =N39+O39+P39+Q39+R39+S39+T39+W39+AA39+AD39 -> 26.7 | AG39: =IF(L39<0,L39*-1,0) -> 26.405218 | AH39: =AF39+AG39 -> 53.105218 | AI39: 0.07 | AJ39: 48 | AK39: 29 | AL39: =AL38+(W39*1.9835) -> 8822.2364 | AM39: 0
A40: =A39+1 -> 29 | B40: 6896.86 | C40: 272141 | D40: =C40-C39 -> 72 | E40: =C40-152000 -> 120141 | F40: =D40/$D$2 -> 36.299471 | G40: 113 | H40: 1.2 | I40: =G40+H40 -> 114.2 | J40: =IF(L40>0,L40,0) -> 0 | K40: =I40+J40 -> 114.2 | L40: =F40-(I40-AF40) -> -51.200529 | M40: 3.7 | N40: 0 | O40: 0 | P40: 0 | Q40: =1.6*1.02 -> 1.632 | R40: 2.87 | S40: 0 | T40: =M40-(Q40+R40+S40) -> -0.802 | U40: 0 | V40: 0 | W40: =M40-N40-O40-P40-Q40-R40-S40-T40+U40+V40 -> 0 | AA40: 0 | AD40: 23 | AE40: =AE39-AD40 -> 2448 | AF40: =N40+O40+P40+Q40+R40+S40+T40+W40+AA40+AD40 -> 26.7 | AG40: =IF(L40<0,L40*-1,0) -> 51.200529 | AH40: =AF40+AG40 -> 77.900529 | AI40: 0 | AJ40: 37 | AK40: 25 | AL40: =AL39+(W40*1.9835) -> 8822.2364 | AM40: 0
A41: 30 | B41: 6896.88 | C41: 272213 | D41: =C41-C40 -> 72 | E41: =C41-152000 -> 120213 | F41: =D41/$D$2 -> 36.299471 | G41: 99 | H41: 1.1 | I41: =G41+H41 -> 100.1 | J41: =IF(L41>0,L41,0) -> 0 | K41: =I41+J41 -> 100.1 | L41: =F41-(I41-AF41) -> -37.100529 | M41: 3.7 | N41: 0 | O41: 0 | P41: 0 | Q41: =1.6*1.02 -> 1.632 | R41: 2.5 | S41: 0 | T41: =M41-(Q41+R41+S41) -> -0.432 | U41: 0 | V41: 0 | W41: =M41-N41-O41-P41-Q41-R41-S41-T41+U41+V41 -> 0 | AA41: 0 | AD41: 23 | AE41: =AE40-AD41 -> 2425 | AF41: =N41+O41+P41+Q41+R41+S41+T41+W41+AA41+AD41 -> 26.7 | AG41: =IF(L41<0,L41*-1,0) -> 37.100529 | AH41: =AF41+AG41 -> 63.800529 | AI41: 0 | AJ41: 43 | AK41: 18 | AL41: =AL40+(W41*1.9835) -> 8822.2364 | AM41: 0
A42: 31 | B42: 6896.9 | C42: 272284 | D42: =C42-C41 -> 71 | E42: =C42-152000 -> 120284 | F42: =D42/$D$2 -> 35.795311 | G42: 89 | H42: 1.1 | I42: =G42+H42 -> 90.1 | J42: =IF(L42>0,L42,0) -> 0 | K42: =I42+J42 -> 90.1 | L42: =F42-(I42-AF42) -> -27.604689 | M42: 3.7 | N42: 0 | O42: 0 | P42: 0 | Q42: =1.6*1.02 -> 1.632 | R42: 2.9 | S42: 0 | T42: =M42-(Q42+R42+S42) -> -0.832 | U42: 0 | V42: 0 | W42: =M42-N42-O42-P42-Q42-R42-S42-T42+U42+V42 -> 0 | AA42: 0 | AD42: 23 | AE42: =AE41-AD42 -> 2402 | AF42: =N42+O42+P42+Q42+R42+S42+T42+W42+AA42+AD42 -> 26.7 | AG42: =IF(L42<0,L42*-1,0) -> 27.604689 | AH42: =AF42+AG42 -> 54.304689 | AI42: 0 | AJ42: 40 | AK42: 15 | AL42: =AL41+(W42*1.9835) -> 8822.2364 | AM42: 0
W43: =M43-N43-O43-Q43-R43-S43+U43+V43 -> 0 | AF43: =N43+O43+Q43+R43+S43+W43+AA43+AD43 -> 0
A44: MONTH / CFS | F44: =SUM(F12:F42) -> 1915.3012 | G44: =SUM(G12:G42) -> 3061 | H44: =SUM(H12:H42) -> 28.36 | I44: =SUM(I12:I42) -> 3089.36 | J44: =SUM(J12:J42) -> 289.08595 | K44: =SUM(K12:K42) -> 3378.446 | L44: =SUM(L12:L42) -> -341.55876 | M44: =SUM(M12:M43) -> 112.5 | N44: =SUM(N12:N42) -> 0 | O44: =SUM(O12:O42) -> 0 | Q44: =SUM(Q12:Q42) -> 50.592 | R44: =SUM(R12:R42) -> 81.003 | S44: =SUM(S12:S42) -> 0 | T44: =SUM(T12:T42) -> -19.095 | U44: =SUM(U12:U42) -> 0 | V44: =SUM(V12:V42) -> 0 | W44: =SUM(W12:W43) -> 0 | AD44: =SUM(AD12:AD43) -> 720 | AF44: =SUM(AF12:AF43) -> 832.5 | AG44: =SUM(AG12:AG42) -> 630.64472 | AH44: =SUM(AH12:AH42) -> 1463.1447 | AI44: =SUM(AI12:AI42) -> 1.03 | AJ44: =AVERAGE(AJ12:AJ42) -> 41.612903 | AK44: =AVERAGE(AK12:AK42) -> 19.516129 | AL44: Avg | AM44: =SUM(AM12:AM42) -> 0
A45: MONTH / AF | D45: =SUM(D12:D42) -> 3799 | F45: =F44*$D$2 -> 3799 | G45: =G44*$D$2 -> 6071.4935 | H45: =H44*$D$2 -> 56.25206 | I45: =I44*$D$2 -> 6127.7456 | J45: =J44*$D$2 -> 573.40198 | K45: =K44*$D$2 -> 6701.1475 | L45: =L44*$D$2 -> -677.48181 | M45: =M44*$D$2 -> 223.14375 | ... O45: =O44*$D$2 -> 0 | Q45: =Q44*$D$2 -> 100.34923 | R45: =R44*$D$2 -> 160.66945 | S45: =S44*$D$2 -> 0 | T45: =T44*$D$2 -> -37.874932 | U45: =U44*$D$2 -> 0 | V45: =V44*$D$2 -> 0 | W45: =W44*$D$2 -> 0 | AD45: =AD44*$D$2 -> 1428.12 | AF45: =AF44*$D$2 -> 1651.2638 | AG45: =AG44*$D$2 -> 1250.8838 | AH45: =AH44*$D$2 -> 2902.1475 | AJ45: =MAX(AJ12:AJ42) -> 51 | AK45: =MAX(AK12:AK42) -> 31 | AL45: HI | AM45: =AM44*$D$2 -> 0
...

Sheet JAN
K1: MCPHEE RESERVOIR INFLOW/OUTFLOW TABULATION
A2: AF/cfs CONVERT FACTOR | D2: 1.9835 | K2: JANUARY "2007"
D4: RESERVOIR | U4: INFLOW/OUTFLOW (CFS) | AJ4: WEATHER | AN4: ADJUSTMENTS
A5: DATE | B5: RESERV | C5: RESERV | D5: AC FT | E5: ACTIVE | F5: CONV TO | G5: DOLORES | H5: LOST | I5: RECORD | J5: CALC | K5: TOTAL | L5: CALC | M5: DOLORES TUNNEL | U5: LONE | V5: U | W5: TOTAL | X5: MVI | Y5: TO EX & | Z5: MVI | AA5: DV CR | AB5: D/S SENIOR | AD5: BELOW | AE5: FISH | AF5: RECORD | AG5: CALC | AH5: TOTAL | AI5: RAIN | AJ5: MAX | AK5: MIN | AL5: NAR | AM5: MVI | AN5: MVI | AO5: MVI | AP5: U/S | AQ5: TOTTEN
A6: JAN | B6: ELEV | C6: AC FT | D6: CHANGE | E6: CAP | F6: CFS | G6: RIVER | H6: CAN | I6: INFLOW | J6: INFLOW | K6: INFLOW | L6: INF/OTF | M6: TOT DIV | N6: WET | O6: UTE | P6: QUEST | Q6: MWC | R6: CTZ | S6: CTZ & | T6: F-BAY | U6: PINE | V6: LAT | W6: MVI | X6: CALL | Y6: U/S EX | Z6: PROJ | AA6: CANAL | AD6: MCP | AE6: LEFT | AF6: OTF | AG6: OTF | AH6: OTF | AJ6: TMP | AK6: TMP | AL6: CALL | AM6: STOCK | AN6: STORED | AO6: STORED | AP6: USERS | AQ6: (FRESH
E7: AC FT | N7: LAND | O7: F&R | S7: UTE | T7: SPILL | AL7: AC.FT. | AM7: CFS | AN7: Apr-Jun | AO7: EVAP | AP7: EXCH | AQ7: WATER)
N8: 1.03 | O8: 1.05 | P8: 1.02 | Q8: 1.02 | R8: 1.04 | S8: PROJ | AO8: AC.FT.
A9: SEASON BAL
A10: YTD | B10: =DEC!B42 -> 6896.9 | C10: =DEC!C42 -> 272284 | D10: =DEC!D51 -> 1363 | E10: =DEC!E51 -> 120284 | F10: =DEC!F50 -> 687.16915 | G10: =DEC!G50 -> 7856 | H10: =DEC!H50 -> 106.46 | I10: =DEC!I50 -> 7962.46 | J10: =DEC!J50 -> 416.86931 | K10: =DEC!K50 -> 8379.3293 | L10: =DEC!L50 -> -690.59085 | M10: =DEC!M50 -> 400.5 | ... O10: =DEC!O50 -> 0 | Q10: =DEC!Q50 -> 98.634 | R10: =DEC!R50 -> 153.483 | S10: =DEC!S50 -> 0 | T10: =DEC!T50 -> -9.3944 | U10: =DEC!U50 -> 4691 | V10: =DEC!V50 -> 76.2 | W10: =DEC!W50 -> 4447.81 | AD10: =DEC!AD50 -> 1417 | AE10: =DEC!AE50 -> 2402 | AF10: =DEC!AF50 -> 6584.7 | AG10: =DEC!AG50 -> 1107.4602 | AH10: =DEC!AH50 -> 7692.1602 | AI10: =DEC!AI50 -> 1.46 | AL10: =DEC!AL51 -> 8822.2364
A12: 1 | B12: 6896.92 | C12: 272356 | D12: =C12-C10 -> 72 | E12: =C12-152000 -> 120356 | F12: =D12/$D$2 -> 36.299471 | G12: 78 | H12: 1 | I12: =G12+H12 -> 79 | J12: =IF(L12>0,L12,0) -> 0 | K12: =I12+J12 -> 79 | L12: =F12-(I12-AF12) -> -16.000529 | M12: 3.7 | N12: 0 | O12: 0 | P12: 0 | Q12: =1.52*1.02 -> 1.5504 | R12: 2.39 | S12: 0 | T12: =M12-(Q12+R12+S12) -> -0.2404 | U12: 0 | V12: 0 | W12: =M12-N12-O12-P12-Q12-R12-S12-T12+U12+V12 -> 0 | AA12: 0 | AD12: 23 | AE12: =AE10-AD12 -> 2379 | AF12: =N12+O12+P12+Q12+R12+S12+T12+W12+AA12+AD12 -> 26.7 | AG12: =IF(L12<0,L12*-1,0) -> 16.000529 | AH12: =AF12+AG12 -> 42.700529 | AI12: 0 | AJ12: 46 | AK12: 23 | AL12: =AL10+(W12*1.9835) -> 8822.2364 | AM12: 0
A13: =A12+1 -> 2 | B13: 6896.94 | C13: 272428 | D13: =C13-C12 -> 72 | E13: =C13-152000 -> 120428 | F13: =D13/$D$2 -> 36.299471 | G13: 81 | H13: 0.99 | I13: =G13+H13 -> 81.99 | J13: =IF(L13>0,L13,0) -> 0 | K13: =I13+J13 -> 81.99 | L13: =F13-(I13-AF13) -> -18.990529 | M13: 3.7 | N13: 0 | O13: 0 | P13: 0 | Q13: =1.52*1.02 -> 1.5504 | R13: 2.8 | S13: 0 | T13: =M13-(Q13+R13+S13) -> -0.6504 | U13: 0 | V13: 0 | W13: =M13-N13-O13-P13-Q13-R13-S13-T13+U13+V13 -> 0 | AA13: 0 | AD13: 23 | AE13: =AE12-AD13 -> 2356 | AF13: =N13+O13+P13+Q13+R13+S13+T13+W13+AA13+AD13 -> 26.7 | AG13: =IF(L13<0,L13*-1,0) -> 18.990529 | AH13: =AF13+AG13 -> 45.690529 | AI13: 0 | AJ13: 44 | AK13: 20 | AL13: =AL12+(W13*1.9835) -> 8822.2364 | AM13: 0
A14: =A13+1 -> 3 | B14: 6896.96 | C14: 272500 | D14: =C14-C13 -> 72 | E14: =C14-152000 -> 120500 | F14: =D14/$D$2 -> 36.299471 | G14: 71 | H14: 0.99 | I14: =G14+H14 -> 71.99 | J14: =IF(L14>0,L14,0) -> 0 | K14: =I14+J14 -> 71.99 | L14: =F14-(I14-AF14) -> -8.9905294 | M14: 3.7 | N14: 0 | O14: 0 | P14: 0 | Q14: =1.52*1.02 -> 1.5504 | R14: 2.49 | S14: 0 | T14: =M14-(Q14+R14+S14) -> -0.3404 | U14: 0 | V14: 0 | W14: =M14-N14-O14-P14-Q14-R14-S14-T14+U14+V14 -> 0 | AA14: 0 | AD14: 23 | AE14: =AE13-AD14 -> 2333 | AF14: =N14+O14+P14+Q14+R14+S14+T14+W14+AA14+AD14 -> 26.7 | AG14: =IF(L14<0,L14*-1,0) -> 8.9905294 | AH14: =AF14+AG14 -> 35.690529 | AI14: 0 | AJ14: 44 | AK14: 19 | AL14: =AL13+(W14*1.9835) -> 8822.2364 | AM14: 0
A15: =A14+1 -> 4 | B15: 6896.98 | C15: 272571 | D15: =C15-C14 -> 71 | E15: =C15-152000 -> 120571 | F15: =D15/$D$2 -> 35.795311 | G15: 79 | H15: 1 | I15: =G15+H15 -> 80 | J15: =IF(L15>0,L15,0) -> 0 | K15: =I15+J15 -> 80 | L15: =F15-(I15-AF15) -> -17.504689 | M15: 3.7 | N15: 0 | O15: 0 | P15: 0 | Q15: =1.52*1.02 -> 1.5504 | R15: 2.5 | S15: 0 | T15: =M15-(Q15+R15+S15) -> -0.3504 | U15: 0 | V15: 0 | W15: =M15-N15-O15-P15-Q15-R15-S15-T15+U15+V15 -> 0 | AA15: 0 | AD15: 23 | AE15: =AE14-AD15 -> 2310 | AF15: =N15+O15+P15+Q15+R15+S15+T15+W15+AA15+AD15 -> 26.7 | AG15: =IF(L15<0,L15*-1,0) -> 17.504689 | AH15: =AF15+AG15 -> 44.204689 | AI15: 0 | AJ15: 48 | AK15: 23 | AL15: =AL14+(W15*1.9835) -> 8822.2364 | AM15: 0
A16: =A15+1 -> 5 | B16: 9897 | C16: 272643 | D16: =C16-C15 -> 72 | E16: =C16-152000 -> 120643 | F16: =D16/$D$2 -> 36.299471 | G16: 93 | H16: 1.1 | I16: =G16+H16 -> 94.1 | J16: =IF(L16>0,L16,0) -> 0 | K16: =I16+J16 -> 94.1 | L16: =F16-(I16-AF16) -> -32.100529 | M16: 3.7 | N16: 0 | O16: 0 | P16: 0 | Q16: =1.52*1.02 -> 1.5504 | R16: 2.36 | S16: 0 | T16: =M16-(Q16+R16+S16) -> -0.2104 | U16: 0 | V16: 0 | W16: =M16-N16-O16-P16-Q16-R16-S16-T16+U16+V16 -> 0 | AA16: 0 | AD16: 22 | AE16: =AE15-AD16 -> 2288 | AF16: =N16+O16+P16+Q16+R16+S16+T16+W16+AA16+AD16 -> 25.7 | AG16: =IF(L16<0,L16*-1,0) -> 32.100529 | AH16: =AF16+AG16 -> 57.800529 | AI16: 0.03 | AJ16: 39 | AK16: 22 | AL16: =AL15+(W16*1.9835) -> 8822.2364 | AM16: 0
A17: =A16+1 -> 6 | B17: 6897.02 | C17: 272716 | D17: =C17-C16 -> 73 | E17: =C17-152000 -> 120716 | F17: =D17/$D$2 -> 36.80363 | G17: 70 | H17: 0.95 | I17: =G17+H17 -> 70.95 | J17: =IF(L17>0,L17,0) -> 0 | K17: =I17+J17 -> 70.95 | L17: =F17-(I17-AF17) -> -8.4463701 | M17: 3.7 | N17: 0 | O17: 0 | P17: 0 | Q17: =1.52*1.02 -> 1.5504 | R17: 2.99 | S17: 0 | T17: =M17-(Q17+R17+S17) -> -0.8404 | U17: 0 | V17: 0 | W17: =M17-N17-O17-P17-Q17-R17-S17-T17+U17+V17 -> 0 | AA17: 0 | AD17: 22 | AE17: =AE16-AD17 -> 2266 | AF17: =N17+O17+P17+Q17+R17+S17+T17+W17+AA17+AD17 -> 25.7 | AG17: =IF(L17<0,L17*-1,0) -> 8.4463701 | AH17: =AF17+AG17 -> 34.14637 | AI17: 0 | AJ17: 32 | AK17: 12 | AL17: =AL16+(W17*1.9835) -> 8822.2364 | AM17: 0
A18: =A17+1 -> 7 | B18: 6897.04 | C18: 272788 | D18: =C18-C17 -> 72 | E18: =C18-152000 -> 120788 | F18: =D18/$D$2 -> 36.299471 | G18: 49 | H18: 0.8 | I18: =G18+H18 -> 49.8 | J18: =IF(L18>0,L18,0) -> 12.199471 | K18: =I18+J18 -> 61.999471 | L18: =F18-(I18-AF18) -> 12.199471 | M18: 3.7 | N18: 0 | O18: 0 | P18: 0 | Q18: =1.52*1.02 -> 1.5504 | R18: 2.49 | S18: 0 | T18: =M18-(Q18+R18+S18) -> -0.3404 | U18: 0 | V18: 0 | W18: =M18-N18-O18-P18-Q18-R18-S18-T18+U18+V18 -> 0 | AA18: 0 | AD18: 22 | AE18: =AE17-AD18 -> 2244 | AF18: =N18+O18+P18+Q18+R18+S18+T18+W18+AA18+AD18 -> 25.7 | AG18: =IF(L18<0,L18*-1,0) -> 0 | AH18: =AF18+AG18 -> 25.7 | AI18: 0 | AJ18: 34 | AK18: 14 | AL18: =AL17+(W18*1.9835) -> 8822.2364 | AM18: 0
A19: =A18+1 -> 8 | B19: 6897.07 | C19: 272896 | D19: =C19-C18 -> 108 | E19: =C19-152000 -> 120896 | F19: =D19/$D$2 -> 54.449206 | G19: 47 | H19: 0.8 | I19: =G19+H19 -> 47.8 | J19: =IF(L19>0,L19,0) -> 32.349206 | K19: =I19+J19 -> 80.149206 | L19: =F19-(I19-AF19) -> 32.349206 | M19: 3.7 | N19: 0 | O19: 0 | P19: 0 | Q19: =1.52*1.02 -> 1.5504 | R19: 3.06 | S19: 0 | T19: =M19-(Q19+R19+S19) -> -0.9104 | U19: 0 | V19: 0 | W19: =M19-N19-O19-P19-Q19-R19-S19-T19+U19+V19 -> 0 | AA19: 0 | AD19: 22 | AE19: =AE18-AD19 -> 2222 | AF19: =N19+O19+P19+Q19+R19+S19+T19+W19+AA19+AD19 -> 25.7 | AG19: =IF(L19<0,L19*-1,0) -> 0 | AH19: =AF19+AG19 -> 25.7 | AI19: 0 | AJ19: 43 | AK19: 15 | AL19: =AL18+(W19*1.9835) -> 8822.2364 | AM19: 0
A20: =A19+1 -> 9 | B20: 6897.1 | C20: 273005 | D20: =C20-C19 -> 109 | E20: =C20-152000 -> 121005 | F20: =D20/$D$2 -> 54.953365 | G20: 59 | H20: 0.8 | I20: =G20+H20 -> 59.8 | J20: =IF(L20>0,L20,0) -> 20.853365 | K20: =I20+J20 -> 80.653365 | L20: =F20-(I20-AF20) -> 20.853365 | M20: 3.7 | N20: 0 | O20: 0 | P20: 0 | Q20: =1.52*1.02 -> 1.5504 | R20: 2.45 | S20: 0 | T20: =M20-(Q20+R20+S20) -> -0.3004 | U20: 0 | V20: 0 | W20: =M20-N20-O20-P20-Q20-R20-S20-T20+U20+V20 -> 0 | AA20: 0 | AD20: 22 | AE20: =AE19-AD20 -> 2200 | AF20: =N20+O20+P20+Q20+R20+S20+T20+W20+AA20+AD20 -> 25.7 | AG20: =IF(L20<0,L20*-1,0) -> 0 | AH20: =AF20+AG20 -> 25.7 | AI20: 0 | AJ20: 43 | AK20: 18 | AL20: =AL19+(W20*1.9835) -> 8822.2364 | AM20: 0
A21: =A20+1 -> 10 | B21: 6897.13 | C21: 273113 | D21: =C21-C20 -> 108 | E21: =C21-152000 -> 121113 | F21: =D21/$D$2 -> 54.449206 | G21: 63 | H21: 0.8 | I21: =G21+H21 -> 63.8 | J21: =IF(L21>0,L21,0) -> 16.349206 | K21: =I21+J21 -> 80.149206 | L21: =F21-(I21-AF21) -> 16.349206 | M21: 3.7 | N21: 0 | O21: 0 | P21: 0 | Q21: =1.52*1.02 -> 1.5504 | R21: 2.64 | S21: 0 | T21: =M21-(Q21+R21+S21) -> -0.4904 | U21: 0 | V21: 0 | W21: =M21-N21-O21-P21-Q21-R21-S21-T21+U21+V21 -> 0 | AA21: 0 | AD21: 22 | AE21: =AE20-AD21 -> 2178 | AF21: =N21+O21+P21+Q21+R21+S21+T21+W21+AA21+AD21 -> 25.7 | AG21: =IF(L21<0,L21*-1,0) -> 0 | AH21: =AF21+AG21 -> 25.7 | AI21: 0 | AJ21: 43 | AK21: 22 | AL21: =AL20+(W21*1.9835) -> 8822.2364 | AM21: 0
A22: =A21+1 -> 11 | B22: 6897.16 | C22: 273222 | D22: =C22-C21 -> 109 | E22: =C22-152000 -> 121222 | F22: =D22/$D$2 -> 54.953365 | G22: 69 | H22: 0.86 | I22: =G22+H22 -> 69.86 | J22: =IF(L22>0,L22,0) -> 10.793365 | K22: =I22+J22 -> 80.653365 | L22: =F22-(I22-AF22) -> 10.793365 | M22: 3.7 | N22: 0 | O22: 0 | P22: 0 | Q22: =1.52*1.02 -> 1.5504 | R22: 2.59 | S22: 0 | T22: =M22-(Q22+R22+S22) -> -0.4404 | U22: 0 | V22: 0 | W22: =M22-N22-O22-P22-Q22-R22-S22-T22+U22+V22 -> 0 | AA22: 0 | AD22: 22 | AE22: =AE21-AD22 -> 2156 | AF22: =N22+O22+P22+Q22+R22+S22+T22+W22+AA22+AD22 -> 25.7 | AG22: =IF(L22<0,L22*-1,0) -> 0 | AH22: =AF22+AG22 -> 25.7 | AI22: 0 | AJ22: 45 | AK22: 15 | AL22: =AL21+(W22*1.9835) -> 8822.2364 | AM22: 0
A23: =A22+1 -> 12 | B23: 6897.19 | C23: 273331 | D23: =C23-C22 -> 109 | E23: =C23-152000 -> 121331 | F23: =D23/$D$2 -> 54.953365 | G23: 80 | H23: 1 | I23: =G23+H23 -> 81 | J23: =IF(L23>0,L23,0) -> 0 | K23: =I23+J23 -> 81 | L23: =F23-(I23-AF23) -> -0.34663474 | M23: 3.7 | N23: 0 | O23: 0 | P23: 0 | Q23: =1.52*1.02 -> 1.5504 | R23: 2.73 | S23: 0 | T23: =M23-(Q23+R23+S23) -> -0.5804 | U23: 0 | V23: 0 | W23: =M23-N23-O23-P23-Q23-R23-S23-T23+U23+V23 -> 0 | AA23: 0 | AD23: 22 | AE23: =AE22-AD23 -> 2134 | AF23: =N23+O23+P23+Q23+R23+S23+T23+W23+AA23+AD23 -> 25.7 | AG23: =IF(L23<0,L23*-1,0) -> 0.34663474 | AH23: =AF23+AG23 -> 26.046635 | AI23: 0.2 | AJ23: 42 | AK23: 32 | AL23: =AL22+(W23*1.9835) -> 8822.2364 | AM23: 0
A24: 13 | B24: 6897.22 | C24: 273439 | D24: =C24-C23 -> 108 | E24: =C24-152000 -> 121439 | F24: =D24/$D$2 -> 54.449206 | G24: 79 | H24: 1 | I24: =G24+H24 -> 80 | J24: =IF(L24>0,L24,0) -> 0.14920595 | K24: =I24+J24 -> 80.149206 | L24: =F24-(I24-AF24) -> 0.14920595 | M24: 3.7 | N24: 0 | O24: 0 | P24: 0 | Q24: =1.52*1.02 -> 1.5504 | R24: 2.54 | S24: 0 | T24: =M24-(Q24+R24+S24) -> -0.3904 | U24: 0 | V24: 0 | W24: =M24-N24-O24-P24-Q24-R24-S24-T24+U24+V24 -> 0 | AA24: 0 | AD24: 22 | AE24: =AE23-AD24 -> 2112 | AF24: =N24+O24+P24+Q24+R24+S24+T24+W24+AA24+AD24 -> 25.7 | AG24: =IF(L24<0,L24*-1,0) -> 0 | AH24: =AF24+AG24 -> 25.7 | AI24: 0.15 | AJ24: 34 | AK24: 24 | AL24: =AL23+(W24*1.9835) -> 8822.2364 | AM24: 0
A25: =A24+1 -> 14 | B25: 6897.24 | C25: 273511 | D25: =C25-C24 -> 72 | E25: =C25-152000 -> 121511 | F25: =D25/$D$2 -> 36.299471 | G25: 62 | H25: 0.88 | I25: =G25+H25 -> 62.88 | J25: =IF(L25>0,L25,0) -> 0 | K25: =I25+J25 -> 62.88 | L25: =F25-(I25-AF25) -> -0.88052937 | M25: 3.7 | N25: 0 | O25: 0 | P25: 0 | Q25: =1.52*1.02 -> 1.5504 | R25: 3.06 | S25: 0 | T25: =M25-(Q25+R25+S25) -> -0.9104 | U25: 0 | V25: 0 | W25: =M25-N25-O25-P25-Q25-R25-S25-T25+U25+V25 -> 0 | AA25: 0 | AD25: 22 | AE25: =AE24-AD25 -> 2090 | AF25: =N25+O25+P25+Q25+R25+S25+T25+W25+AA25+AD25 -> 25.7 | AG25: =IF(L25<0,L25*-1,0) -> 0.88052937 | AH25: =AF25+AG25 -> 26.580529 | AI25: 0.06 | AJ25: 25 | AK25: 10 | AL25: =AL24+(W25*1.9835) -> 8822.2364 | AM25: 0
A26: =A25+1 -> 15 | B26: 6897.26 | C26: 273584 | D26: =C26-C25 -> 73 | E26: =C26-152000 -> 121584 | F26: =D26/$D$2 -> 36.80363 | G26: 46 | H26: 0.68 | I26: =G26+H26 -> 46.68 | J26: =IF(L26>0,L26,0) -> 15.82363 | K26: =I26+J26 -> 62.50363 | L26: =F26-(I26-AF26) -> 15.82363 | M26: 3.7 | N26: 0 | O26: 0 | P26: 0 | Q26: =1.52*1.02 -> 1.5504 | R26: 2.56 | S26: 0 | T26: =M26-(Q26+R26+S26) -> -0.4104 | U26: 0 | V26: 0 | W26: =M26-N26-O26-P26-Q26-R26-S26-T26+U26+V26 -> 0 | AA26: 0 | AD26: 22 | AE26: =AE25-AD26 -> 2068 | AF26: =N26+O26+P26+Q26+R26+S26+T26+W26+AA26+AD26 -> 25.7 | AG26: =IF(L26<0,L26*-1,0) -> 0 | AH26: =AF26+AG26 -> 25.7 | AI26: 0 | AJ26: 25 | AK26: -3 | AL26: =AL25+(W26*1.9835) -> 8822.2364 | AM26: 0
A27: =A26+1 -> 16 | B27: 6897.28 | C27: 273656 | D27: =C27-C26 -> 72 | E27: =C27-152000 -> 121656 | F27: =D27/$D$2 -> 36.299471 | G27: 34 | H27: 0.58 | I27: =G27+H27 -> 34.58 | J27: =IF(L27>0,L27,0) -> 27.419471 | K27: =I27+J27 -> 61.999471 | L27: =F27-(I27-AF27) -> 27.419471 | M27: 3.7 | N27: 0 | O27: 0 | P27: 0 | Q27: =1.52*1.02 -> 1.5504 | R27: 3.01 | S27: 0 | T27: =M27-(Q27+R27+S27) -> -0.8604 | U27: 0 | V27: 0 | W27: =M27-N27-O27-P27-Q27-R27-S27-T27+U27+V27 -> 0 | AA27: 0 | AD27: 22 | AE27: =AE26-AD27 -> 2046 | AF27: =N27+O27+P27+Q27+R27+S27+T27+W27+AA27+AD27 -> 25.7 | AG27: =IF(L27<0,L27*-1,0) -> 0 | AH27: =AF27+AG27 -> 25.7 | AI27: 0 | AJ27: 32 | AK27: 0 | AL27: =AL26+(W27*1.9835) -> 8822.2364 | AM27: 0
