Workbook

Sheet NOV
K1: MCPHEE RESERVOIR INFLOW/OUTFLOW TABULATION
A2: AF/cfs CONVERT FACTOR | D2: 1.9835 | L2: NOVEMBER "2015"
D4: RESERVOIR | I4: INFLOW | X4: OUTFLOW | AP4: ADJUSTMENTS | AW4: WEATHER
A5: DATE | B5: RESERV | C5: RESERV | D5: AC FT | E5: ACTIVE | F5: CONV TO | G5: DOLORES | H5: LOST | I5: RECORD | J5: CALC | K5: TOTAL | L5: CALC | M5: DOLORES TUNNEL | V5: LONE | W5: U | X5: TOTAL | Y5: TOTAL | Z5: MVI | AA5: MVI | AB5: MVI | AC5: TO EX & | AD5: MVI | AE5: DV CR | AF5: D/S SENIOR | AH5: BELOW | AI5: FISH | AJ5: SPILL | AK5: RECORD | AL5: CALC | AM5: TOTAL | AN5: NAR | AO5: MVI | AP5: MVI | AQ5: MVI | AR5: DIST. | AS5: U/S | AT5: TOTTEN | AU5: UF&R | AV5: RAIN | AW5: MAX | AX5: MIN | AZ5: TOTAL | BA5: GRNDHOG | BB5: GRNDHOG
A6: NOV | B6: ELEV | D6: CHANGE | E6: CAP | F6: CFS | G6: RIVER | H6: CAN | I6: INFLOW | J6: INFLOW | K6: INFLOW | L6: INF/OTF | M6: TOT DIV | N6: WET | O6: UTE | P6: QUEST | Q6: MWC | R6: CORTEZ | T6: UTE | U6: F-BAY | V6: PINE | W6: LAT | X6: MVI | Y6: MVI | Z6: CALL | AA6: CALL | AB6: APR- | AC6: U/S EX | AD6: PROJ | AE6: CANAL | AF6: MVIC | AG6: PROJ | AH6: MCP | AI6: LEFT | AK6: OTF | AL6: OTF | AM6: OTF | AN6: FILL | AO6: STOCK | AP6: STORED | AQ6: STORED | AR6: CLASS | AS6: USERS | AT6: (FRESH | AU6: LEASE | AW6: TMP | AX6: TMP | AZ6: TUNNEL | BA6: DISCHARGE | BB6: CAPACITY
N7: LAND | O7: F&R | Q7: NON - | R7: NON - | S7: PROJ | T7: PROJ | U7: BAL | X7: WATER | Y7: IRRIG. | Z7: STOR | AA7: SPILLED | AB7: JUNE | AF7: 1.7 | AG7: 1.3 | AP7: Apr - Jun | AQ7: EVAP | AR7: "B" | AS7: EXCH | AT7: WATER) | AU7: WATER | AZ7: Misc.
Q8: PROJ | R8: PROJ | X8: USED | Y8: WATER | AA8: OR | AB8: (DIV+
R9: 4.2 | Y9: USED | AA9: USED | AB9: CALL) | BB9: FP = 3960
C10: AC. Ft. | E10: AC FT | G10: CFS | H10: CFS | I10: CFS | J10: CFS | K10: CFS | L10: CFS | M10: CFS | N10: CFS | O10: CFS | P10: CFS | Q10: CFS | R10: CFS | S10: CFS | T10: CFS | U10: CFS | V10: CFS | W10: CFS | X10: 153400 | Y10: 150400 | AB10: 72000 | AC10: CFS | AD10: CFS | AE10: CFS | AF10: CFS | AG10: CFS | AH10: CFS | AI10: CFS | AJ10: CFS | AK10: CFS | AL10: CFS | AM10: CFS | AN10: CFS | AO10: CFS | AP10: CFS | AQ10: AC.FT. | AR10: CFS | AS10: CFS | AT10: CFS | AU10: CFS | AZ10: Outflow | BA10: CFS | BB10: AC FT
N11: 1.03 | O11: 1.05 | P11: 1.02 | Q11: 1.02 | R11: 1.04 | T11: 1.04 | X11: CFS | Y11: CFS | Z11: CFS | AA11: CFS | AB11: Ac. Ft. | AZ11: CFS
A12: SEASON BAL
A13: YTD | B13: 6888.51 | C13: 243168 | AI13: 5218.2579
A15: 1 | B15: 6888.49 | C15: 243069 | D15: =C15-C13 -> -99 | E15: =C15-152000 -> 91069 | F15: =D15/$D$2 -> -49.911772 | G15: 91 | H15: 0 | I15: =G15+H15 -> 91 | J15: =IF(L15>0,L15,0) -> 0 | K15: =I15+J15 -> 91 | L15: =F15-(I15-AK15) -> -32.641772 | M15: 7.57 | N15: 0 | O15: =0*1.05 -> 0 | P15: 0 | Q15: =1220300/325851/1.9835*1.02 -> 1.9258192 | R15: =IF(((2.5*1.04)-T15)>=4.2,4.2,(2.5*1.04)-T15) -> 1.9650176 | S15: =IF(((2.5*1.04)-T15)>=4.2,((2.5*1.04)-T15)-4.2,0) -> 0 | T15: =(0.576*1.06)*1.04 -> 0.6349824 | U15: =M15-(Q15+R15+S15+T15) -> 3.0441808 | V15: 70.5 | W15: 0 | X15: =M15-N15-O15-P15-Q15-R15-S15-T15-U15+V15+W15-AU15+AR15 -> 70.5 | Y15: =X15-AO15 -> 70.5 | AE15: 0 | AH15: 30.2 | AI15: =AI13-AH15 -> 5188.0579 | AK15: =N15+O15+P15+Q15+R15+S15+T15+U15+X15+AE15+AH15 -> 108.27 | AL15: =IF(L15<0,L15*-1,0) -> 32.641772 | AM15: =AK15+AL15 -> 140.91177 | AN15: =V15 -> 70.5 | AV15: 0 | AW15: 67 | AX15: 34 | AZ15: =SUM(N15,P15:U15) -> 7.57 | BA15: 0.081 | BB15: 18583
A16: =A15+1 -> 2 | B16: 6888.47 | C16: 243035 | D16: =C16-C15 -> -34 | E16: =C16-152000 -> 91035 | F16: =D16/$D$2 -> -17.141417 | G16: 87 | H16: 0 | I16: =G16+H16 -> 87 | J16: =IF(L16>0,L16,0) -> 1.9685833 | K16: =I16+J16 -> 88.968583 | L16: =F16-(I16-AK16) -> 1.9685833 | M16: 5.51 | N16: 0 | O16: =0*1.05 -> 0 | P16: 0 | Q16: =968000/325851/1.9835*1.02 -> 1.5276514 | R16: =IF(((2.6*1.04)-T16)>=4.2,4.2,(2.6*1.04)-T16) -> 2.0690176 | S16: =IF(((2.6*1.04)-T16)>=4.2,((2.6*1.04)-T16)-4.2,0) -> 0 | T16: =(0.576*1.06)*1.04 -> 0.6349824 | U16: =M16-(Q16+R16+S16+T16) -> 1.2783486 | V16: 70.5 | W16: 0 | X16: =M16-N16-O16-P16-Q16-R16-S16-T16-U16+V16+W16-AU16+AR16 -> 70.5 | Y16: =X16-AO16 -> 70.5 | AE16: 0 | AH16: 30.1 | AI16: =AI15-AH16 -> 5157.9579 | AK16: =N16+O16+P16+Q16+R16+S16+T16+U16+X16+AE16+AH16 -> 106.11 | AL16: =IF(L16<0,L16*-1,0) -> 0 | AM16: =AK16+AL16 -> 106.11 | AN16: =V16 -> 70.5 | AV16: 0 | AW16: 68 | AX16: 38 | AZ16: =SUM(N16,P16:U16) -> 5.51 | BA16: 0.159 | BB16: 18573
A17: =A16+1 -> 3 | B17: 6888.44 | C17: 242935 | D17: =C17-C16 -> -100 | E17: =C17-152000 -> 90935 | F17: =D17/$D$2 -> -50.415931 | G17: 85 | H17: 0 | I17: =G17+H17 -> 85 | J17: =IF(L17>0,L17,0) -> 0 | K17: =I17+J17 -> 85 | L17: =F17-(I17-AK17) -> -31.648931 | M17: 3.12 | N17: 0 | O17: =0*1.05 -> 0 | P17: 0 | Q17: =948200/325851/1.9835*1.02 -> 1.496404 | R17: =IF(((2.5*1.04)-T17)>=4.2,4.2,(2.5*1.04)-T17) -> 1.9650176 | S17: =IF(((2.5*1.04)-T17)>=4.2,((2.5*1.04)-T17)-4.2,0) -> 0 | T17: =(0.576*1.06)*1.04 -> 0.6349824 | U17: =M17-(Q17+R17+S17+T17) -> -0.976404 | V17: 70.5 | W17: 0.047 | X17: =M17-N17-O17-P17-Q17-R17-S17-T17-U17+V17+W17-AU17+AR17 -> 70.547 | Y17: =X17-AO17 -> 70.547 | AE17: 0 | AH17: 30.1 | AI17: =AI16-AH17 -> 5127.8579 | AK17: =N17+O17+P17+Q17+R17+S17+T17+U17+X17+AE17+AH17 -> 103.767 | AL17: =IF(L17<0,L17*-1,0) -> 31.648931 | AM17: =AK17+AL17 -> 135.41593 | AN17: =V17 -> 70.5 | AV17: 0.01 | AW17: 67 | AX17: 41 | AZ17: =SUM(N17,P17:U17) -> 3.12 | BA17: 0.189 | BB17: 18583
A18: =A17+1 -> 4 | B18: 6888.46 | C18: 243002 | D18: =C18-C17 -> 67 | E18: =C18-152000 -> 91002 | F18: =D18/$D$2 -> 33.778674 | G18: 104 | H18: 0 | I18: =G18+H18 -> 104 | J18: =IF(L18>0,L18,0) -> 35.248674 | K18: =I18+J18 -> 139.24867 | L18: =F18-(I18-AK18) -> 35.248674 | M18: 4.17 | N18: 0 | O18: =0*1.05 -> 0 | P18: 0 | Q18: =838000/325851/1.9835*1.02 -> 1.3224916 | R18: =IF(((2.4*1.04)-T18)>=4.2,4.2,(2.4*1.04)-T18) -> 1.8610176 | S18: =IF(((2.4*1.04)-T18)>=4.2,((2.4*1.04)-T18)-4.2,0) -> 0 | T18: =(0.576*1.06)*1.04 -> 0.6349824 | U18: =M18-(Q18+R18+S18+T18) -> 0.35150838 | V18: 70.9 | W18: 0 | X18: =M18-N18-O18-P18-Q18-R18-S18-T18-U18+V18+W18-AU18+AR18 -> 70.9 | Y18: =X18-AO18 -> 70.9 | AE18: 0 | AH18: 30.4 | AI18: =AI17-AH18 -> 5097.4579 | AK18: =N18+O18+P18+Q18+R18+S18+T18+U18+X18+AE18+AH18 -> 105.47 | AL18: =IF(L18<0,L18*-1,0) -> 0 | AM18: =AK18+AL18 -> 105.47 | AN18: =V18 -> 70.9 | AV18: 0.41 | AW18: 49 | AX18: 30 | AZ18: =SUM(N18,P18:U18) -> 4.17 | BA18: 0.191 | BB18: 18571
A19: =A18+1 -> 5 | B19: 6888.46 | C19: 243002 | D19: =C19-C18 -> 0 | E19: =C19-152000 -> 91002 | F19: =D19/$D$2 -> 0 | G19: 99 | H19: 0 | I19: =G19+H19 -> 99 | J19: =IF(L19>0,L19,0) -> 23.22 | K19: =I19+J19 -> 122.22 | L19: =F19-(I19-AK19) -> 23.22 | M19: 2.72 | N19: 0 | O19: =0*1.05 -> 0 | P19: 0 | Q19: =843700/325851/1.9835*1.02 -> 1.3314871 | R19: =IF(((1.9*1.04)-T19)>=4.2,4.2,(1.9*1.04)-T19) -> 1.3410176 | S19: =IF(((1.9*1.04)-T19)>=4.2,((1.9*1.04)-T19)-4.2,0) -> 0 | T19: =(0.576*1.06)*1.04 -> 0.6349824 | U19: =M19-(Q19+R19+S19+T19) -> -0.58748708 | V19: 89.4 | W19: 0 | X19: =M19-N19-O19-P19-Q19-R19-S19-T19-U19+V19+W19-AU19+AR19 -> 89.4 | Y19: =X19-AO19 -> 89.4 | AE19: 0 | AH19: 30.1 | AI19: =AI18-AH19 -> 5067.3579 | AK19: =N19+O19+P19+Q19+R19+S19+T19+U19+X19+AE19+AH19 -> 122.22 | AL19: =IF(L19<0,L19*-1,0) -> 0 | AM19: =AK19+AL19 -> 122.22 | AN19: =V19 -> 89.4 | AV19: 0.05 | AW19: 43 | AX19: 30 | AZ19: =SUM(N19,P19:U19) -> 2.72 | BA19: 0.267 | BB19: 18677
A20: =A19+1 -> 6 | B20: 6888.42 | C20: 242869 | D20: =C20-C19 -> -133 | E20: =C20-152000 -> 90869 | F20: =D20/$D$2 -> -67.053189 | G20: 92 | H20: 0 | I20: =G20+H20 -> 92 | J20: =IF(L20>0,L20,0) -> 0 | K20: =I20+J20 -> 92 | L20: =F20-(I20-AK20) -> -26.353189 | M20: 2.9 | N20: 0 | O20: =0*1.05 -> 0 | P20: 0 | Q20: =880900/325851/1.9835*1.02 -> 1.3901943 | R20: =IF(((2*1.04)-T20)>=4.2,4.2,(2*1.04)-T20) -> 1.5010195 | S20: =IF(((2*1.04)-T20)>=4.2,((2*1.04)-T20)-4.2,0) -> 0 | T20: =(0.5252*1.06)*1.04 -> 0.57898048 | U20: =M20-(Q20+R20+S20+T20) -> -0.57019435 | V20: 99.7 | W20: 0 | X20: =M20-N20-O20-P20-Q20-R20-S20-T20-U20+V20+W20-AU20+AR20 -> 99.7 | Y20: =X20-AO20 -> 99.7 | AE20: 0 | AH20: 30.1 | AI20: =AI19-AH20 -> 5037.2579 | AK20: =N20+O20+P20+Q20+R20+S20+T20+U20+X20+AE20+AH20 -> 132.7 | AL20: =IF(L20<0,L20*-1,0) -> 26.353189 | AM20: =AK20+AL20 -> 159.05319 | AN20: =V20 -> 99.7 | AV20: 0 | AW20: 46 | AX20: 30 | AZ20: =SUM(N20,P20:U20) -> 2.9 | BA20: 0.186 | BB20: 18645
A21: =A20+1 -> 7 | B21: 6888.37 | C21: 242702 | D21: =C21-C20 -> -167 | E21: =C21-152000 -> 90702 | F21: =D21/$D$2 -> -84.194605 | G21: 79 | H21: 0 | I21: =G21+H21 -> 79 | J21: =IF(L21>0,L21,0) -> 0 | K21: =I21+J21 -> 79 | L21: =F21-(I21-AK21) -> -29.784605 | M21: 3.61 | N21: 0 | O21: =0*1.05 -> 0 | P21: 0 | Q21: =967500/325851/1.9835*1.02 -> 1.5268623 | R21: =IF(((1.7*1.04)-T21)>=4.2,4.2,(1.7*1.04)-T21) -> 1.1890195 | S21: =IF(((1.7*1.04)-T21)>=4.2,((1.7*1.04)-T21)-4.2,0) -> 0 | T21: =(0.5252*1.06)*1.04 -> 0.57898048 | U21: =M21-(Q21+R21+S21+T21) -> 0.31513766 | V21: 99.7 | W21: 0 | X21: =M21-N21-O21-P21-Q21-R21-S21-T21-U21+V21+W21-AU21+AR21 -> 99.7 | Y21: =X21-AO21 -> 99.7 | AE21: 0 | AH21: 30.1 | AI21: =AI20-AH21 -> 5007.1579 | AK21: =N21+O21+P21+Q21+R21+S21+T21+U21+X21+AE21+AH21 -> 133.41 | AL21: =IF(L21<0,L21*-1,0) -> 29.784605 | AM21: =AK21+AL21 -> 163.19461 | AN21: =V21 -> 99.7 | AV21: 0 | AW21: 48 | AX21: 29 | AZ21: =SUM(N21,P21:U21) -> 3.61 | BA21: 0.291 | BB21: 18639
A22: =A21+1 -> 8 | B22: 6888.32 | C22: 242535 | D22: =C22-C21 -> -167 | E22: =C22-152000 -> 90535 | F22: =D22/$D$2 -> -84.194605 | G22: 73 | H22: 0 | I22: =G22+H22 -> 73 | J22: =IF(L22>0,L22,0) -> 0 | K22: =I22+J22 -> 73 | L22: =F22-(I22-AK22) -> -25.084605 | M22: 2.31 | N22: 0 | O22: =0*1.05 -> 0 | P22: 0 | Q22: =977300/325851/1.9835*1.02 -> 1.5423282 | R22: =IF(((1.7*1.04)-T22)>=4.2,4.2,(1.7*1.04)-T22) -> 1.1890195 | S22: =IF(((1.7*1.04)-T22)>=4.2,((1.7*1.04)-T22)-4.2,0) -> 0 | T22: =(0.5252*1.06)*1.04 -> 0.57898048 | U22: =M22-(Q22+R22+S22+T22) -> -1.0003282 | V22: 99.7 | W22: 0 | X22: =M22-N22-O22-P22-Q22-R22-S22-T22-U22+V22+W22-AU22+AR22 -> 99.7 | Y22: =X22-AO22 -> 99.7 | AE22: 0 | AH22: 30.1 | AI22: =AI21-AH22 -> 4977.0579 | AK22: =N22+O22+P22+Q22+R22+S22+T22+U22+X22+AE22+AH22 -> 132.11 | AL22: =IF(L22<0,L22*-1,0) -> 25.084605 | AM22: =AK22+AL22 -> 157.19461 | AN22: =V22 -> 99.7 | AV22: 0 | AW22: 53 | AX22: 25 | AZ22: =SUM(N22,P22:U22) -> 2.31 | BA22: 0.11 | BB22: 18649
A23: =A22+1 -> 9 | B23: 6888.29 | C23: 242435 | D23: =C23-C22 -> -100 | E23: =C23-152000 -> 90435 | F23: =D23/$D$2 -> -50.415931 | G23: 80 | H23: 0 | I23: =G23+H23 -> 80 | J23: =IF(L23>0,L23,0) -> 2.6640686 | K23: =I23+J23 -> 82.664069 | L23: =F23-(I23-AK23) -> 2.6640686 | M23: 3.28 | N23: 0 | O23: =0*1.05 -> 0 | P23: 0 | Q23: =1069700/325851/1.9835*1.02 -> 1.6881495 | R23: =IF(((1.6*1.04)-T23)>=4.2,4.2,(1.6*1.04)-T23) -> 1.0850195 | S23: =IF(((1.6*1.04)-T23)>=4.2,((1.6*1.04)-T23)-4.2,0) -> 0 | T23: =(0.5252*1.06)*1.04 -> 0.57898048 | U23: =M23-(Q23+R23+S23+T23) -> -0.072149501 | V23: 99.7 | W23: 0 | X23: =M23-N23-O23-P23-Q23-R23-S23-T23-U23+V23+W23-AU23+AR23 -> 99.7 | Y23: =X23-AO23 -> 99.7 | AE23: 0 | AH23: 30.1 | AI23: =AI22-AH23 -> 4946.9579 | AK23: =N23+O23+P23+Q23+R23+S23+T23+U23+X23+AE23+AH23 -> 133.08 | AL23: =IF(L23<0,L23*-1,0) -> 0 | AM23: =AK23+AL23 -> 133.08 | AN23: =V23 -> 99.7 | AV23: 0 | AW23: 59 | AX23: 25 | AZ23: =SUM(N23,P23:U23) -> 3.28 | BA23: 0.005 | BB23: 18637
A24: =A23+1 -> 10 | B24: 6888.26 | C24: 242335 | D24: =C24-C23 -> -100 | E24: =C24-152000 -> 90335 | F24: =D24/$D$2 -> -50.415931 | G24: 86 | H24: 0 | I24: =G24+H24 -> 86 | J24: =IF(L24>0,L24,0) -> 0 | K24: =I24+J24 -> 86 | L24: =F24-(I24-AK24) -> -3.7359314 | M24: 2.68 | N24: 0 | O24: =0*1.05 -> 0 | P24: 0 | Q24: =838100/325851/1.9835*1.02 -> 1.3226494 | R24: =IF(((1.9*1.04)-T24)>=4.2,4.2,(1.9*1.04)-T24) -> 1.3970195 | S24: =IF(((1.9*1.04)-T24)>=4.2,((1.9*1.04)-T24)-4.2,0) -> 0 | T24: =(0.5252*1.06)*1.04 -> 0.57898048 | U24: =M24-(Q24+R24+S24+T24) -> -0.61864943 | V24: 99.7 | W24: 0 | X24: =M24-N24-O24-P24-Q24-R24-S24-T24-U24+V24+W24-AU24+AR24 -> 99.7 | Y24: =X24-AO24 -> 99.7 | AE24: 0 | AH24: 30.3 | AI24: =AI23-AH24 -> 4916.6579 | AK24: =N24+O24+P24+Q24+R24+S24+T24+U24+X24+AE24+AH24 -> 132.68 | AL24: =IF(L24<0,L24*-1,0) -> 3.7359314 | AM24: =AK24+AL24 -> 136.41593 | AN24: =V24 -> 99.7 | AV24: 0.087 | AW24: 57 | AX24: 27 | AZ24: =SUM(N24,P24:U24) -> 2.68 | BA24: 0.111 | BB24: 18618
A25: =A24+1 -> 11 | B25: 6888.26 | C25: 242335 | D25: =C25-C24 -> 0 | E25: =C25-152000 -> 90335 | F25: =D25/$D$2 -> 0 | G25: 88 | H25: 0 | I25: =G25+H25 -> 88 | J25: =IF(L25>0,L25,0) -> 45.46 | K25: =I25+J25 -> 133.46 | L25: =F25-(I25-AK25) -> 45.46 | M25: 3.46 | N25: 0 | O25: =2.35*1.05 -> 2.4675 | P25: 0 | Q25: =1020500/325851/1.9835*1.02 -> 1.6105044 | R25: =IF(((2*1.04)-T25)>=4.2,4.2,(2*1.04)-T25) -> 1.5010195 | S25: =IF(((2*1.04)-T25)>=4.2,((2*1.04)-T25)-4.2,0) -> 0 | T25: =(0.5252*1.06)*1.04 -> 0.57898048 | U25: =M25-(Q25+R25+S25+T25) -> -0.23050441 | V25: 99.7 | W25: 0 | X25: =M25-N25-O25-P25-Q25-R25-S25-T25-U25+V25+W25-AU25+AR25 -> 97.2325 | Y25: =X25-AO25 -> 97.2325 | AE25: 0 | AH25: 30.3 | AI25: =AI24-AH25 -> 4886.3579 | AK25: =N25+O25+P25+Q25+R25+S25+T25+U25+X25+AE25+AH25 -> 133.46 | AL25: =IF(L25<0,L25*-1,0) -> 0 | AM25: =AK25+AL25 -> 133.46 | AN25: =V25 -> 99.7 | AV25: 0.203 | AW25: 42 | AX25: 21 | AZ25: =SUM(N25,P25:U25) -> 3.46 | BA25: 0.157 | BB25: 18663
A26: =A25+1 -> 12 | B26: 6888.18 | C26: 242069 | D26: =C26-C25 -> -266 | E26: =C26-152000 -> 90069 | F26: =D26/$D$2 -> -134.10638 | G26: 66 | H26: 0 | I26: =G26+H26 -> 66 | J26: =IF(L26>0,L26,0) -> 0 | K26: =I26+J26 -> 66 | L26: =F26-(I26-AK26) -> -67.206378 | M26: 3 | N26: 0 | O26: =0*1.05 -> 0 | P26: 0 | Q26: =860100/325851/1.9835*1.02 -> 1.3573688 | R26: =IF(((2.2*1.04)-T26)>=4.2,4.2,(2.2*1.04)-T26) -> 1.7090195 | S26: =IF(((2.2*1.04)-T26)>=4.2,((2.2*1.04)-T26)-4.2,0) -> 0 | T26: =(0.5252*1.06)*1.04 -> 0.57898048 | U26: =M26-(Q26+R26+S26+T26) -> -0.64536878 | V26: 99.7 | W26: 0 | X26: =M26-N26-O26-P26-Q26-R26-S26-T26-U26+V26+W26-AU26+AR26 -> 99.7 | Y26: =X26-AO26 -> 99.7 | AE26: 0 | AH26: 30.2 | AI26: =AI25-AH26 -> 4856.1579 | AK26: =N26+O26+P26+Q26+R26+S26+T26+U26+X26+AE26+AH26 -> 132.9 | AL26: =IF(L26<0,L26*-1,0) -> 67.206378 | AM26: =AK26+AL26 -> 200.10638 | AN26: =V26 -> 99.7 | AV26: 0.02 | AW26: 51 | AX26: 19 | AZ26: =SUM(N26,P26:U26) -> 3 | BA26: 0.162 | BB26: 18665
A27: =A26+1 -> 13 | B27: 6888.14 | C27: 241936 | D27: =C27-C26 -> -133 | E27: =C27-152000 -> 89936 | F27: =D27/$D$2 -> -67.053189 | G27: 67 | H27: 0 | I27: =G27+H27 -> 67 | J27: =IF(L27>0,L27,0) -> 0 | K27: =I27+J27 -> 67 | L27: =F27-(I27-AK27) -> -0.42318881 | M27: 3.73 | N27: 0 | O27: =0*1.05 -> 0 | P27: 0 | Q27: =1111800/325851/1.9835*1.02 -> 1.7545897 | R27: =IF(((2.1*1.04)-T27)>=4.2,4.2,(2.1*1.04)-T27) -> 1.6783291 | S27: =IF(((2.1*1.04)-T27)>=4.2,((2.1*1.04)-T27)-4.2,0) -> 0 | T27: =(0.4587*1.06)*1.04 -> 0.50567088 | U27: =M27-(Q27+R27+S27+T27) -> -0.20858971 | V27: 99.7 | W27: 0 | X27: =M27-N27-O27-P27-Q27-R27-S27-T27-U27+V27+W27-AU27+AR27 -> 99.7 | Y27: =X27-AO27 -> 99.7 | AE27: 0 | AH27: 30.2 | AI27: =AI26-AH27 -> 4825.9579 | AK27: =N27+O27+P27+Q27+R27+S27+T27+U27+X27+AE27+AH27 -> 133.63 | AL27: =IF(L27<0,L27*-1,0) -> 0.42318881 | AM27: =AK27+AL27 -> 134.05319 | AN27: =V27 -> 99.7 | AV27: 0 | AW27: 58 | AX27: 26 | AZ27: =SUM(N27,P27:U27) -> 3.73 | BA27: 0.187 | BB27: 18640
A28: =A27+1 -> 14 | B28: 6888.08 | C28: 241736 | D28: =C28-C27 -> -200 | E28: =C28-152000 -> 89736 | F28: =D28/$D$2 -> -100.83186 | G28: 64 | H28: 0 | I28: =G28+H28 -> 64 | J28: =IF(L28>0,L28,0) -> 0 | K28: =I28+J28 -> 64 | L28: =F28-(I28-AK28) -> -32.231863 | M28: 2.8 | N28: 0 | O28: =0*1.05 -> 0 | P28: 0 | Q28: =811400/325851/1.9835*1.02 -> 1.2805128 | R28: =IF(((2.2*1.04)-T28)>=4.2,4.2,(2.2*1.04)-T28) -> 1.7823291 | S28: =IF(((2.2*1.04)-T28)>=4.2,((2.2*1.04)-T28)-4.2,0) -> 0 | T28: =(0.4587*1.06)*1.04 -> 0.50567088 | U28: =M28-(Q28+R28+S28+T28) -> -0.76851277 | V28: 99.7 | W28: 0 | X28: =M28-N28-O28-P28-Q28-R28-S28-T28-U28+V28+W28-AU28+AR28 -> 99.7 | Y28: =X28-AO28 -> 99.7 | AE28: 0 | AH28: 30.1 | AI28: =AI27-AH28 -> 4795.8579 | AK28: =N28+O28+P28+Q28+R28+S28+T28+U28+X28+AE28+AH28 -> 132.6 | AL28: =IF(L28<0,L28*-1,0) -> 32.231863 | AM28: =AK28+AL28 -> 164.83186 | AN28: =V28 -> 99.7 | AV28: 0 | AW28: 60 | AX28: 28 | AZ28: =SUM(N28,P28:U28) -> 2.8 | BA28: 0.274 | BB28: 18638
A29: =A28+1 -> 15 | B29: 6888.05 | C29: 241636 | D29: =C29-C28 -> -100 | E29: =C29-152000 -> 89636 | F29: =D29/$D$2 -> -50.415931 | G29: 67 | H29: 0 | I29: =G29+H29 -> 67 | J29: =IF(L29>0,L29,0) -> 16.174069 | K29: =I29+J29 -> 83.174069 | L29: =F29-(I29-AK29) -> 16.174069 | M29: 3.79 | N29: 0 | O29: =0*1.05 -> 0 | P29: 0 | Q29: =1092100/325851/1.9835*1.02 -> 1.7235001 | R29: =IF(((2.1*1.04)-T29)>=4.2,4.2,(2.1*1.04)-T29) -> 1.6783291 | S29: =IF(((2.1*1.04)-T29)>=4.2,((2.1*1.04)-T29)-4.2,0) -> 0 | T29: =(0.4587*1.06)*1.04 -> 0.50567088 | U29: =M29-(Q29+R29+S29+T29) -> -0.11750011 | V29: 99.7 | W29: 0 | X29: =M29-N29-O29-P29-Q29-R29-S29-T29-U29+V29+W29-AU29+AR29 -> 99.7 | Y29: =X29-AO29 -> 99.7 | AE29: 0 | AH29: 30.1 | AI29: =AI28-AH29 -> 4765.7579 | AK29: =N29+O29+P29+Q29+R29+S29+T29+U29+X29+AE29+AH29 -> 133.59 | AL29: =IF(L29<0,L29*-1,0) -> 0 | AM29: =AK29+AL29 -> 133.59 | AN29: =V29 -> 99.7 | AV29: 0.27 | AW29: 56 | AX29: 29 | AZ29: =SUM(N29,P29:U29) -> 3.79 | BA29: 0.296 | BB29: 18639
A30: =A29+1 -> 16 | B30: 6888.08 | C30: 241736 | D30: =C30-C29 -> 100 | E30: =C30-152000 -> 89736 | F30: =D30/$D$2 -> 50.415931 | G30: 66 | H30: 0 | I30: =G30+H30 -> 66 | J30: =IF(L30>0,L30,0) -> 117.56593 | K30: =I30+J30 -> 183.56593 | L30: =F30-(I30-AK30) -> 117.56593 | M30: 3.05 | N30: 0 | O30: =0*1.05 -> 0 | P30: 0 | Q30: =906600/325851/1.9835*1.02 -> 1.4307529 | R30: =IF(((1.6*1.04)-T30)>=4.2,4.2,(1.6*1.04)-T30) -> 1.1583291 | S30: =IF(((1.6*1.04)-T30)>=4.2,((1.6*1.04)-T30)-4.2,0) -> 0 | T30: =(0.4587*1.06)*1.04 -> 0.50567088 | U30: =M30-(Q30+R30+S30+T30) -> -0.044752863 | V30: 99.7 | W30: 0 | X30: =M30-N30-O30-P30-Q30-R30-S30-T30-U30+V30+W30-AU30+AR30 -> 99.7 | Y30: =X30-AO30 -> 99.7 | AE30: 0 | AH30: 30.4 | AI30: =AI29-AH30 -> 4735.3579 | AK30: =N30+O30+P30+Q30+R30+S30+T30+U30+X30+AE30+AH30 -> 133.15 | AL30: =IF(L30<0,L30*-1,0) -> 0 | AM30: =AK30+AL30 -> 133.15 | AN30: =V30 -> 99.7 | AV30: 0.945 | AW30: 41 | AX30: 26 | AZ30: =SUM(N30,P30:U30) -> 3.05 | BA30: 0.237 | BB30: 18681
A31: =A30+1 -> 17 | B31: 6888.02 | C31: 241536 | D31: =C31-C30 -> -200 | E31: =C31-152000 -> 89536 | F31: =D31/$D$2 -> -100.83186 | G31: 70 | H31: 0 | I31: =G31+H31 -> 70 | J31: =IF(L31>0,L31,0) -> 0 | K31: =I31+J31 -> 70 | L31: =F31-(I31-AK31) -> -38.451863 | M31: 2.58 | N31: 0 | O31: =0*1.05 -> 0 | P31: 0 | Q31: =1046600/325851/1.9835*1.02 -> 1.6516942 | R31: =IF(((2.2*1.04)-T31)>=4.2,4.2,(2.2*1.04)-T31) -> 1.7823291 | S31: =IF(((2.2*1.04)-T31)>=4.2,((2.2*1.04)-T31)-4.2,0) -> 0 | T31: =(0.4587*1.06)*1.04 -> 0.50567088 | U31: =M31-(Q31+R31+S31+T31) -> -1.3596942 | V31: 99.7 | W31: 0 | X31: =M31-N31-O31-P31-Q31-R31-S31-T31-U31+V31+W31-AU31+AR31 -> 99.7 | Y31: =X31-AO31 -> 99.7 | AE31: 0 | AH31: 30.1 | AI31: =AI30-AH31 -> 4705.2579 | AK31: =N31+O31+P31+Q31+R31+S31+T31+U31+X31+AE31+AH31 -> 132.38 | AL31: =IF(L31<0,L31*-1,0) -> 38.451863 | AM31: =AK31+AL31 -> 170.83186 | AN31: =V31 -> 99.7 | AV31: 0 | AW31: 34 | AX31: 21 | AZ31: =SUM(N31,P31:U31) -> 2.58 | BA31: 0.172 | BB31: 18713
A32: =A31+1 -> 18 | B32: 6888.02 | C32: 241536 | D32: =C32-C31 -> 0 | E32: =C32-152000 -> 89536 | F32: =D32/$D$2 -> 0 | G32: 77.3 | H32: 0 | I32: =G32+H32 -> 77.3 | J32: =IF(L32>0,L32,0) -> 0.01 | K32: =I32+J32 -> 77.31 | L32: =F32-(I32-AK32) -> 0.01 | M32: 4.01 | N32: 0 | O32: =0*1.05 -> 0 | P32: 0 | Q32: =1088400/325851/1.9835*1.02 -> 1.7176609 | R32: =IF(((2.2*1.04)-T32)>=4.2,4.2,(2.2*1.04)-T32) -> 1.7823291 | S32: =IF(((2.2*1.04)-T32)>=4.2,((2.2*1.04)-T32)-4.2,0) -> 0 | T32: =(0.4587*1.06)*1.04 -> 0.50567088 | U32: =M32-(Q32+R32+S32+T32) -> 0.0043390516 | V32: 43.2 | W32: 0 | X32: =M32-N32-O32-P32-Q32-R32-S32-T32-U32+V32+W32-AU32+AR32 -> 43.2 | Y32: =X32-AO32 -> 43.2 | AE32: 0 | AH32: 30.1 | AI32: =AI31-AH32 -> 4675.1579 | AK32: =N32+O32+P32+Q32+R32+S32+T32+U32+X32+AE32+AH32 -> 77.31 | AL32: =IF(L32<0,L32*-1,0) -> 0 | AM32: =AK32+AL32 -> 77.31 | AN32: =V32 -> 43.2 | AV32: 0 | AW32: 48 | AX32: 19 | AZ32: =SUM(N32,P32:U32) -> 4.01 | BA32: 0.164 | BB32: 18715
A33: =A32+1 -> 19 | B33: 6888.02 | C33: 241536 | D33: =C33-C32 -> 0 | E33: =C33-152000 -> 89536 | F33: =D33/$D$2 -> 0 | G33: 33.68 | H33: 0 | I33: =G33+H33 -> 33.68 | J33: =IF(L33>0,L33,0) -> 0 | K33: =I33+J33 -> 33.68 | L33: =F33-(I33-AK33) -> 0 | M33: 3.58 | N33: 0 | O33: =0*1.05 -> 0 | P33: 0 | Q33: =989300/325851/1.9835*1.02 -> 1.5612661 | R33: =IF(((1.9*1.04)-T33)>=4.2,4.2,(1.9*1.04)-T33) -> 1.4703291 | S33: =IF(((1.9*1.04)-T33)>=4.2,((1.9*1.04)-T33)-4.2,0) -> 0 | T33: =(0.4587*1.06)*1.04 -> 0.50567088 | U33: =M33-(Q33+R33+S33+T33) -> 0.042733943 | V33: 0 | W33: 0 | X33: =M33-N33-O33-P33-Q33-R33-S33-T33-U33+V33+W33-AU33+AR33 -> 4.4408921e-16 | Y33: =X33-AO33 -> 4.4408921e-16 | AE33: 0 | AH33: 30.1 | AI33: =AI32-AH33 -> 4645.0579 | AK33: =N33+O33+P33+Q33+R33+S33+T33+U33+X33+AE33+AH33 -> 33.68 | AL33: =IF(L33<0,L33*-1,0) -> 0 | AM33: =AK33+AL33 -> 33.68 | AN33: =V33 -> 0 | AV33: 0 | AW33: 55 | AX33: 27 | AZ33: =SUM(N33,P33:U33) -> 3.58 | BA33: 0.162 | BB33: 18725
A34: =A33+1 -> 20 | B34: 6888.07 | C34: 241702 | D34: =C34-C33 -> 166 | E34: =C34-152000 -> 89702 | F34: =D34/$D$2 -> 83.690446 | G34: 116.34045 | H34: 0 | I34: =G34+H34 -> 116.34045 | J34: =IF(L34>0,L34,0) -> 0 | K34: =I34+J34 -> 116.34045 | L34: =F34-(I34-AK34) -> 0 | M34: 2.55 | N34: 0 | O34: =0*1.05 -> 0 | P34: 0 | Q34: =856700/325851/1.9835*1.02 -> 1.3520031 | R34: =IF(((2*1.04)-T34)>=4.2,4.2,(2*1.04)-T34) -> 1.5854634 | S34: =IF(((2*1.04)-T34)>=4.2,((2*1.04)-T34)-4.2,0) -> 0 | T34: =(0.4486*1.06)*1.04 -> 0.49453664 | U34: =M34-(Q34+R34+S34+T34) -> -0.88200306 | V34: 0 | W34: 0 | X34: =M34-N34-O34-P34-Q34-R34-S34-T34-U34+V34+W34-AU34+AR34 -> 0 | Y34: =X34-AO34 -> 0 | AE34: 0 | AH34: 30.1 | AI34: =AI33-AH34 -> 4614.9579 | AK34: =N34+O34+P34+Q34+R34+S34+T34+U34+X34+AE34+AH34 -> 32.65 | AL34: =IF(L34<0,L34*-1,0) -> 0 | AM34: =AK34+AL34 -> 32.65 | AN34: =V34 -> 0 | AV34: 0 | AW34: 55 | AX34: 27 | AZ34: =SUM(N34,P34:U34) -> 2.55 | BA34: 0.165 | BB34: 18718
A35: =A34+1 -> 21 | B35: 6888.11 | C35: 241836 | D35: =C35-C34 -> 134 | E35: =C35-152000 -> 89836 | F35: =D35/$D$2 -> 67.557348 | G35: 101.08735 | H35: 0 | I35: =G35+H35 -> 101.08735 | J35: =IF(L35>0,L35,0) -> 0 | K35: =I35+J35 -> 101.08735 | L35: =F35-(I35-AK35) -> 0 | M35: 3.43 | N35: 0 | O35: =0*1.05 -> 0 | P35: 0 | Q35: =1018090/325851/1.9835*1.02 -> 1.6067011 | R35: =IF(((2*1.04)-T35)>=4.2,4.2,(2*1.04)-T35) -> 1.5854634 | S35: =IF(((2*1.04)-T35)>=4.2,((2*1.04)-T35)-4.2,0) -> 0 | T35: =(0.4486*1.06)*1.04 -> 0.49453664 | U35: =M35-(Q35+R35+S35+T35) -> -0.25670106 | V35: 0 | W35: 0 | X35: =M35-N35-O35-P35-Q35-R35-S35-T35-U35+V35+W35-AU35+AR35 -> 0 | Y35: =X35-AO35 -> 0 | AE35: 0 | AH35: 30.1 | AI35: =AI34-AH35 -> 4584.8579 | AK35: =N35+O35+P35+Q35+R35+S35+T35+U35+X35+AE35+AH35 -> 33.53 | AL35: =IF(L35<0,L35*-1,0) -> 0 | AM35: =AK35+AL35 -> 33.53 | AN35: =V35 -> 0 | AV35: 0 | AW35: 52 | AX35: 21 | AZ35: =SUM(N35,P35:U35) -> 3.43 | BA35: 0.162 | BB35: 18697
A36: =A35+1 -> 22 | B36: 6888.09 | C36: 241769 | D36: =C36-C35 -> -67 | E36: =C36-152000 -> 89769 | F36: =D36/$D$2 -> -33.778674 | G36: 0 | H36: 0 | I36: =G36+H36 -> 0 | J36: =IF(L36>0,L36,0) -> 0 | K36: =I36+J36 -> 0 | L36: =F36-(I36-AK36) -> -0.42867406 | M36: 3.25 | N36: 0 | O36: =0*1.05 -> 0 | P36: 0 | Q36: =1036310/325851/1.9835*1.02 -> 1.635455 | R36: =IF(((1.9*1.04)-T36)>=4.2,4.2,(1.9*1.04)-T36) -> 1.4814634 | S36: =IF(((1.9*1.04)-T36)>=4.2,((1.9*1.04)-T36)-4.2,0) -> 0 | T36: =(0.4486*1.06)*1.04 -> 0.49453664 | U36: =M36-(Q36+R36+S36+T36) -> -0.361455 | V36: 0 | W36: 0 | X36: =M36-N36-O36-P36-Q36-R36-S36-T36-U36+V36+W36-AU36+AR36 -> 0 | Y36: =X36-AO36 -> 0 | AC36: 0 | AE36: 0 | AH36: 30.1 | AI36: =AI35-AH36 -> 4554.7579 | AK36: =N36+O36+P36+Q36+R36+S36+T36+U36+X36+AE36+AH36 -> 33.35 | AL36: =IF(L36<0,L36*-1,0) -> 0.42867406 | AM36: =AK36+AL36 -> 33.778674 | AN36: =V36 -> 0 | AV36: 0 | AW36: 52 | AX36: 21 | AZ36: =SUM(N36,P36:U36) -> 3.25 | BA36: 0.162 | BB36: 18694
A37: =A36+1 -> 23 | B37: 6888.11 | C37: 241836 | D37: =C37-C36 -> 67 | E37: =C37-152000 -> 89836 | F37: =D37/$D$2 -> 33.778674 | G37: 67.1 | H37: 0 | I37: =G37+H37 -> 67.1 | J37: =IF(L37>0,L37,0) -> 0 | K37: =I37+J37 -> 67.1 | L37: =F37-(I37-AK37) -> -0.001325939 | M37: 3.22 | N37: 0 | O37: =0*1.05 -> 0 | P37: 0 | Q37: =957800/325851/1.9835*1.02 -> 1.5115543 | R37: =IF(((1.9*1.04)-T37)>=4.2,4.2,(1.9*1.04)-T37) -> 1.4814634 | S37: =IF(((1.9*1.04)-T37)>=4.2,((1.9*1.04)-T37)-4.2,0) -> 0 | T37: =(0.4486*1.06)*1.04 -> 0.49453664 | U37: =M37-(Q37+R37+S37+T37) -> -0.26755426 | V37: 0 | W37: 0 | X37: =M37-N37-O37-P37-Q37-R37-S37-T37-U37+V37+W37-AU37+AR37 -> 0 | Y37: =X37-AO37 -> 0 | AC37: 61.106982 | AE37: 0 | AH37: 30.1 | AI37: =AI36-AH37 -> 4524.6579 | AK37: =N37+O37+P37+Q37+R37+S37+T37+U37+X37+AE37+AH37 -> 33.32 | AL37: =IF(L37<0,L37*-1,0) -> 0.001325939 | AM37: =AK37+AL37 -> 33.321326 | AN37: =V37 -> 0 | AV37: 0 | AW37: 58 | AX37: 21 | AZ37: =SUM(N37,P37:U37) -> 3.22 | BA37: 0.162 | BB37: 18711
A38: =A37+1 -> 24 | B38: 6888.13 | C38: 241902 | D38: =C38-C37 -> 66 | E38: =C38-152000 -> 89902 | F38: =D38/$D$2 -> 33.274515 | G38: 66.834515 | H38: 0 | I38: =G38+H38 -> 66.834515 | J38: =IF(L38>0,L38,0) -> 0 | K38: =I38+J38 -> 66.834515 | L38: =F38-(I38-AK38) -> 0 | M38: 3.46 | N38: 0 | O38: =0*1.05 -> 0 | P38: 0 | Q38: =1001100/325851/1.9835*1.02 -> 1.5798883 | R38: =IF(((1.9*1.04)-T38)>=4.2,4.2,(1.9*1.04)-T38) -> 1.4814634 | S38: =IF(((1.9*1.04)-T38)>=4.2,((1.9*1.04)-T38)-4.2,0) -> 0 | T38: =(0.4486*1.06)*1.04 -> 0.49453664 | U38: =M38-(Q38+R38+S38+T38) -> -0.095888254 | V38: 0 | W38: 0 | X38: =M38-N38-O38-P38-Q38-R38-S38-T38-U38+V38+W38-AU38+AR38 -> 0 | Y38: =X38-AO38 -> 0 | AC38: 0 | AE38: 0 | AH38: 30.1 | AI38: =AI37-AH38 -> 4494.5579 | AK38: =N38+O38+P38+Q38+R38+S38+T38+U38+X38+AE38+AH38 -> 33.56 | AL38: =IF(L38<0,L38*-1,0) -> 0 | AM38: =AK38+AL38 -> 33.56 | AN38: =V38 -> 0 | AV38: 0 | AW38: 56 | AX38: 29 | AZ38: =SUM(N38,P38:U38) -> 3.46 | BA38: 0.162 | BB38: 18718
A39: =A38+1 -> 25 | B39: 6888.16 | C39: 242002 | D39: =C39-C38 -> 100 | E39: =C39-152000 -> 90002 | F39: =D39/$D$2 -> 50.415931 | G39: 83.305931 | H39: 0 | I39: =G39+H39 -> 83.305931 | J39: =IF(L39>0,L39,0) -> 0 | K39: =I39+J39 -> 83.305931 | L39: =F39-(I39-AK39) -> 0 | M39: 2.79 | N39: 0 | O39: =0*1.05 -> 0 | P39: 0 | Q39: =988600/325851/1.9835*1.02 -> 1.5601614 | R39: =IF(((1.9*1.04)-T39)>=4.2,4.2,(1.9*1.04)-T39) -> 1.4814634 | S39: =IF(((1.9*1.04)-T39)>=4.2,((1.9*1.04)-T39)-4.2,0) -> 0 | T39: =(0.4486*1.06)*1.04 -> 0.49453664 | U39: =M39-(Q39+R39+S39+T39) -> -0.74616135 | V39: 0 | W39: 0 | X39: =M39-N39-O39-P39-Q39-R39-S39-T39-U39+V39+W39-AU39+AR39 -> 0 | Y39: =X39-AO39 -> 0 | AC39: 77.264307 | AE39: 0 | AH39: 30.1 | AI39: =AI38-AH39 -> 4464.4579 | AK39: =N39+O39+P39+Q39+R39+S39+T39+U39+X39+AE39+AH39 -> 32.89 | AL39: =IF(L39<0,L39*-1,0) -> 0 | AM39: =AK39+AL39 -> 32.89 | AN39: =V39 -> 0 | AV39: 0 | AW39: 53 | AX39: 34 | AZ39: =SUM(N39,P39:U39) -> 2.79 | BA39: 0.164 | BB39: 18760
A40: =A39+1 -> 26 | B40: 6888.17 | C40: 242036 | D40: =C40-C39 -> 34 | E40: =C40-152000 -> 90036 | F40: =D40/$D$2 -> 17.141417 | G40: 51.121417 | H40: 0 | I40: =G40+H40 -> 51.121417 | J40: =IF(L40>0,L40,0) -> 0 | K40: =I40+J40 -> 51.121417 | L40: =F40-(I40-AK40) -> 0 | M40: 3.88 | N40: 0 | O40: =0*1.05 -> 0 | P40: 0 | Q40: =903900/325851/1.9835*1.02 -> 1.4264919 | R40: =IF(((2*1.04)-T40)>=4.2,4.2,(2*1.04)-T40) -> 1.5854634 | S40: =IF(((2*1.04)-T40)>=4.2,((2*1.04)-T40)-4.2,0) -> 0 | T40: =(0.4486*1.06)*1.04 -> 0.49453664 | U40: =M40-(Q40+R40+S40+T40) -> 0.37350815 | V40: 0 | W40: 0 | X40: =M40-N40-O40-P40-Q40-R40-S40-T40-U40+V40+W40-AU40+AR40 -> 0 | Y40: =X40-AO40 -> 0 | AC40: 45.109461 | AE40: 0 | AH40: 30.1 | AI40: =AI39-AH40 -> 4434.3579 | AK40: =N40+O40+P40+Q40+R40+S40+T40+U40+X40+AE40+AH40 -> 33.98 | AL40: =IF(L40<0,L40*-1,0) -> 0 | AM40: =AK40+AL40 -> 33.98 | AN40: =V40 -> 0 | AV40: 0 | AW40: 49 | AX40: 29 | AZ40: =SUM(N40,P40:U40) -> 3.88 | BA40: 0.162 | BB40: 18729
A41: =A40+1 -> 27 | B41: 6888.22 | C41: 242202 | D41: =C41-C40 -> 166 | E41: =C41-152000 -> 90202 | F41: =D41/$D$2 -> 83.690446 | G41: 117.69045 | H41: 0 | I41: =G41+H41 -> 117.69045 | J41: =IF(L41>0,L41,0) -> 0 | K41: =I41+J41 -> 117.69045 | L41: =F41-(I41-AK41) -> 0 | M41: 3.9 | N41: 0 | O41: =0*1.05 -> 0 | P41: 0 | Q41: =967700/325851/1.9835*1.02 -> 1.527178 | R41: =IF(((1.9*1.04)-T41)>=4.2,4.2,(1.9*1.04)-T41) -> 1.4843296 | S41: =IF(((1.9*1.04)-T41)>=4.2,((1.9*1.04)-T41)-4.2,0) -> 0 | T41: =(0.446*1.06)*1.04 -> 0.4916704 | U41: =M41-(Q41+R41+S41+T41) -> 0.39682203 | V41: 0 | W41: 0 | X41: =M41-N41-O41-P41-Q41-R41-S41-T41-U41+V41+W41-AU41+AR41 -> 0 | Y41: =X41-AO41 -> 0 | AC41: 111.67894 | AE41: 0 | AH41: 30.1 | AI41: =AI40-AH41 -> 4404.2579 | AK41: =N41+O41+P41+Q41+R41+S41+T41+U41+X41+AE41+AH41 -> 34 | AL41: =IF(L41<0,L41*-1,0) -> 0 | AM41: =AK41+AL41 -> 34 | AN41: =V41 -> 0 | AV41: 0.04 | AW41: 52 | AX41: 23 | AZ41: =SUM(N41,P41:U41) -> 3.9 | BA41: 0.162 | BB41: 18716
A42: =A41+1 -> 28 | B42: 6888.23 | C42: 242236 | D42: =C42-C41 -> 34 | E42: =C42-152000 -> 90236 | F42: =D42/$D$2 -> 17.141417 | G42: 50.121417 | H42: 0 | I42: =G42+H42 -> 50.121417 | J42: =IF(L42>0,L42,0) -> 0 | K42: =I42+J42 -> 50.121417 | L42: =F42-(I42-AK42) -> 0 | M42: 2.78 | N42: 0 | O42: =0*1.05 -> 0 | P42: 0 | Q42: =1010300/325851/1.9835*1.02 -> 1.5944073 | R42: =IF(((1.9*1.04)-T42)>=4.2,4.2,(1.9*1.04)-T42) -> 1.4843296 | S42: =IF(((1.9*1.04)-T42)>=4.2,((1.9*1.04)-T42)-4.2,0) -> 0 | T42: =(0.446*1.06)*1.04 -> 0.4916704 | U42: =M42-(Q42+R42+S42+T42) -> -0.79040725 | V42: 0 | W42: 0 | X42: =M42-N42-O42-P42-Q42-R42-S42-T42-U42+V42+W42-AU42+AR42 -> 0 | Y42: =X42-AO42 -> 0 | AC42: 44.04268 | AE42: 0 | AH42: 30.2 | AI42: =AI41-AH42 -> 4374.0579 | AK42: =N42+O42+P42+Q42+R42+S42+T42+U42+X42+AE42+AH42 -> 32.98 | AL42: =IF(L42<0,L42*-1,0) -> 0 | AM42: =AK42+AL42 -> 32.98 | AN42: =V42 -> 0 | AV42: 0 | AW42: 44 | AX42: 20 | AZ42: =SUM(N42,P42:U42) -> 2.78 | BA42: 0.162 | BB42: 18736
...

Sheet DEC
K1: MCPHEE RESERVOIR INFLOW/OUTFLOW TABULATION
A2: AF/cfs CONVERT FACTOR | D2: 1.9835 | K2: DECEMBER "2015"
D4: RESERVOIR | I4: INFLOW | X4: OUTFLOW | AP4: ADJUSTMENTS | AW4: WEATHER
A5: DATE | B5: RESERV | C5: RESERV | D5: AC FT | E5: ACTIVE | F5: CONV TO | G5: DOLORES | H5: LOST | I5: RECORD | J5: CALC | K5: TOTAL | L5: CALC | M5: DOLORES TUNNEL | V5: LONE | W5: U | X5: TOTAL | Y5: TOTAL | Z5: MVI | AA5: MVI | AB5: MVI | AC5: TO EX & | AD5: MVI | AE5: DV CR | AF5: D/S SENIOR | AH5: BELOW | AI5: FISH | AJ5: SPILL | AK5: RECORD | AL5: CALC | AM5: TOTAL | AN5: NAR | AO5: MVI | AP5: MVI | AQ5: MVI | AR5: DIST. | AS5: U/S | AT5: TOTTEN | AU5: UF&R | AV5: RAIN | AW5: MAX | AX5: MIN | AZ5: TOTAL | BA5: GRNDHOG | BB5: GRNDHOG
A6: DEC | B6: ELEV | D6: CHANGE | E6: CAP | F6: CFS | G6: RIVER | H6: CAN | I6: INFLOW | J6: INFLOW | K6: INFLOW | L6: INF/OTF | M6: TOT DIV | N6: WET | O6: UTE | P6: QUEST | Q6: MWC | R6: CORTEZ | T6: UTE | U6: F-BAY | V6: PINE | W6: LAT | X6: MVI | Y6: MVI | Z6: CALL | AA6: CALL | AB6: APR- | AC6: U/S EX | AD6: PROJ | AE6: CANAL | AF6: MVIC | AG6: PROJ | AH6: MCP | AI6: LEFT | AK6: OTF | AL6: OTF | AM6: OTF | AN6: FILLL | AO6: STOCK | AP6: STORED | AQ6: STORED | AR6: CLASS | AS6: USERS | AT6: (FRESH | AU6: LEASE | AW6: TMP | AX6: TMP | AZ6: TUNNEL | BA6: DISCHARGE | BB6: CAPACITY
N7: LAND | O7: F&R | Q7: NON - | R7: NON - | S7: PROJ | T7: PROJ | U7: BAL | X7: WATER | Y7: IRRIG. | Z7: STOR | AA7: SPILLED | AB7: JUNE | AF7: 1.7 | AG7: 1.3 | AP7: Apr - Jun | AQ7: EVAP | AR7: "B" | AS7: EXCH | AT7: WATER) | AU7: WATER | AZ7: Misc.
Q8: PROJ | R8: PROJ | X8: USED | Y8: WATER | AA8: OR | AB8: (DIV+
R9: 4.2 | Y9: USED | AA9: USED | AB9: CALL) | BB9: FP = 3960
C10: AC. Ft. | E10: AC FT | G10: CFS | H10: CFS | I10: CFS | J10: CFS | K10: CFS | L10: CFS | M10: CFS | N10: CFS | O10: CFS | P10: CFS | Q10: CFS | R10: CFS | S10: CFS | T10: CFS | U10: CFS | V10: CFS | W10: CFS | X10: 153400 | Y10: 150400 | AB10: 72000 | AC10: CFS | AD10: CFS | AE10: CFS | AF10: CFS | AG10: CFS | AH10: CFS | AI10: CFS | AJ10: CFS | AK10: CFS | AL10: CFS | AM10: CFS | AN10: CFS | AO10: CFS | AP10: CFS | AQ10: AC.FT. | AR10: CFS | AS10: CFS | AT10: CFS | AU10: CFS | AZ10: Outflow | BA10: CFS | BB10: AC FT
N11: 1.03 | O11: 1.05 | P11: 1.02 | Q11: 1.02 | R11: 1.04 | T11: 1.04 | X11: CFS | Y11: CFS | Z11: CFS | AA11: CFS | AB11: Ac. Ft. | AZ11: CFS
A12: SEASON BAL
A13: YTD | B13: =NOV!B44 -> 6888.27 | C13: =NOV!C44 -> 242369 | D13: =NOV!D53 -> -799 | E13: =NOV!E53 -> 90369 | F13: =NOV!F52 -> -402.82329 | G13: =NOV!G52 -> 2263.7547 | H13: =NOV!H52 -> 0 | I13: =NOV!I52 -> 2263.7547 | J13: =NOV!J52 -> 242.31133 | K13: =NOV!K52 -> 2506.066 | L13: =NOV!L52 -> -45.681001 | M13: =NOV!M52 -> 104.55 | ... Y13: =NOV!Y52 -> 1608.9795 | AC13: =NOV!AC52 -> 462.45039 | AH13: =NOV!AH52 -> 904.9 | AI13: =NOV!AI52 -> 4313.3579 | AK13: =NOV!AK52 -> 2620.897 | AL13: =NOV!AL52 -> 287.99233 | AM13: =NOV!AM52 -> 2908.8893 | AN13: =NOV!AN52 -> 1611.4 | AO13: =NOV!AO52 -> 0 | AV13: =NOV!AV52 -> 2.035 | AZ13: =NOV!AZ52 -> 104.55 | BA13: =NOV!BA52 -> 5.188
A15: 1 | B15: 6888.27 | C15: 242369 | D15: =C15-C13 -> 0 | E15: =C15-152000 -> 90369 | F15: =D15/$D$2 -> 0 | G15: 33.85 | H15: 0 | I15: =G15+H15 -> 33.85 | J15: =IF(L15>0,L15,0) -> 0 | K15: =I15+J15 -> 33.85 | L15: =F15-(I15-AK15) -> 0 | M15: 3.45 | N15: 0 | O15: =0*1.05 -> 0 | P15: 0 | Q15: =1105500/325851/1.9835*1.02 -> 1.7446474 | R15: =IF(((1.9*1.04)-T15)>=4.2,4.2,(1.9*1.04)-T15) -> 1.1899888 | S15: =IF(((1.9*1.04)-T15)>=4.2,((1.9*1.04)-T15)-4.2,0) -> 0 | T15: =(0.713*1.06)*1.04 -> 0.7860112 | U15: =M15-(Q15+R15+S15+T15) -> -0.27064735 | V15: 0 | W15: 0 | X15: =M15-N15-P15-O15-Q15-R15-S15-T15-U15+V15+W15 -> 0 | Y15: =X15-AO15 -> 0 | AC15: 27.915364 | AE15: 0 | AH15: 30.4 | AI15: =AI13-AH15 -> 4282.9579 | AK15: =N15+O15+P15+Q15+R15+S15+T15+U15+X15+AE15+AH15 -> 33.85 | AL15: =IF(L15<0,L15*-1,0) -> 0 | AM15: =AK15+AL15 -> 33.85 | AV15: 0.04 | AW15: 44 | AX15: 12 | AZ15: =SUM(N15,P15:U15) -> 3.45 | BA15: 0.162 | BB15: 18732
A16: =A15+1 -> 2 | B16: 6888.25 | C16: 242302 | D16: =C16-C15 -> -67 | E16: =C16-152000 -> 90302 | F16: =D16/$D$2 -> -33.778674 | G16: 0.68132594 | H16: 0 | I16: =G16+H16 -> 0.68132594 | J16: =IF(L16>0,L16,0) -> 0 | K16: =I16+J16 -> 0.68132594 | L16: =F16-(I16-AK16) -> 0 | M16: 4.06 | N16: 0 | O16: =0*1.05 -> 0 | P16: 0 | Q16: =1004700/325851/1.9835*1.02 -> 1.5855696 | R16: =IF(((2*1.04)-T16)>=4.2,4.2,(2*1.04)-T16) -> 1.2939888 | S16: =IF(((2*1.04)-T16)>=4.2,((2*1.04)-T16)-4.2,0) -> 0 | T16: =(0.713*1.06)*1.04 -> 0.7860112 | U16: =M16-(Q16+R16+S16+T16) -> 0.3944304 | V16: 0 | W16: 0 | X16: =M16-N16-P16-O16-Q16-R16-S16-T16-U16+V16+W16 -> 0 | Y16: =X16-AO16 -> 0 | AC16: 0 | AE16: 0 | AH16: 30.4 | AI16: =AI15-AH16 -> 4252.5579 | AK16: =N16+O16+P16+Q16+R16+S16+T16+U16+X16+AE16+AH16 -> 34.46 | AL16: =IF(L16<0,L16*-1,0) -> 0 | AM16: =AK16+AL16 -> 34.46 | AV16: 0 | AW16: 48 | AX16: 14 | AZ16: =SUM(N16,P16:U16) -> 4.06 | BA16: 0.162 | BB16: 18758
A17: =A16+1 -> 3 | B17: 6888.25 | C17: 242302 | D17: =C17-C16 -> 0 | E17: =C17-152000 -> 90302 | F17: =D17/$D$2 -> 0 | G17: 34.26 | H17: 0 | I17: =G17+H17 -> 34.26 | J17: =IF(L17>0,L17,0) -> 0 | K17: =I17+J17 -> 34.26 | L17: =F17-(I17-AK17) -> 0 | M17: 4.06 | N17: 0 | O17: =0*1.05 -> 0 | P17: 0 | Q17: =1008100/325851/1.9835*1.02 -> 1.5909353 | R17: =IF(((1.9*1.04)-T17)>=4.2,4.2,(1.9*1.04)-T17) -> 1.1899888 | S17: =IF(((1.9*1.04)-T17)>=4.2,((1.9*1.04)-T17)-4.2,0) -> 0 | T17: =(0.713*1.06)*1.04 -> 0.7860112 | U17: =M17-(Q17+R17+S17+T17) -> 0.49306468 | V17: 0 | W17: 0 | X17: =M17-N17-P17-O17-Q17-R17-S17-T17-U17+V17+W17 -> 0 | Y17: =X17-AO17 -> 0 | AC17: 28.479076 | AE17: 0 | AH17: 30.2 | AI17: =AI16-AH17 -> 4222.3579 | AK17: =N17+O17+P17+Q17+R17+S17+T17+U17+X17+AE17+AH17 -> 34.26 | AL17: =IF(L17<0,L17*-1,0) -> 0 | AM17: =AK17+AL17 -> 34.26 | AV17: 0 | AW17: 52 | AX17: 21 | AZ17: =SUM(N17,P17:U17) -> 4.06 | BA17: 0.162 | BB17: 18808
A18: =A17+1 -> 4 | B18: 6888.26 | C18: 242335 | D18: =C18-C17 -> 33 | E18: =C18-152000 -> 90335 | F18: =D18/$D$2 -> 16.637257 | G18: 50.997257 | H18: 0 | I18: =G18+H18 -> 50.997257 | J18: =IF(L18>0,L18,0) -> 0 | K18: =I18+J18 -> 50.997257 | L18: =F18-(I18-AK18) -> 0 | M18: 4.06 | N18: 0 | O18: =0*1.05 -> 0 | P18: 0 | Q18: =1042800/325851/1.9835*1.02 -> 1.6456972 | R18: =IF(((2*1.04)-T18)>=4.2,4.2,(2*1.04)-T18) -> 1.5367373 | S18: =IF(((2*1.04)-T18)>=4.2,((2*1.04)-T18)-4.2,0) -> 0 | T18: =(0.4928*1.06)*1.04 -> 0.54326272 | U18: =M18-(Q18+R18+S18+T18) -> 0.3343028 | V18: 0 | W18: 0 | X18: =M18-N18-P18-O18-Q18-R18-S18-T18-U18+V18+W18 -> 0 | Y18: =X18-AO18 -> 0 | AC18: 44.814823 | AE18: 0 | AH18: 30.3 | AI18: =AI17-AH18 -> 4192.0579 | AK18: =N18+O18+P18+Q18+R18+S18+T18+U18+X18+AE18+AH18 -> 34.36 | AL18: =IF(L18<0,L18*-1,0) -> 0 | AM18: =AK18+AL18 -> 34.36 | AV18: 0 | AW18: 56 | AX18: 27 | AZ18: =SUM(N18,P18:U18) -> 4.06 | BA18: 0.221 | BB18: 18772
A19: =A18+1 -> 5 | B19: 6888.31 | C19: 242502 | D19: =C19-C18 -> 167 | E19: =C19-152000 -> 90502 | F19: =D19/$D$2 -> 84.194605 | G19: 118.16461 | H19: 0 | I19: =G19+H19 -> 118.16461 | J19: =IF(L19>0,L19,0) -> 0 | K19: =I19+J19 -> 118.16461 | L19: =F19-(I19-AK19) -> 0 | M19: 3.37 | N19: 0 | O19: =0*1.05 -> 0 | P19: 0 | Q19: =975300/325851/1.9835*1.02 -> 1.5391719 | R19: =IF(((2*1.04)-T19)>=4.2,4.2,(2*1.04)-T19) -> 1.5367373 | S19: =IF(((2*1.04)-T19)>=4.2,((2*1.04)-T19)-4.2,0) -> 0 | T19: =(0.4928*1.06)*1.04 -> 0.54326272 | U19: =M19-(Q19+R19+S19+T19) -> -0.24917192 | V19: 0 | W19: 0 | X19: =M19-N19-P19-O19-Q19-R19-S19-T19-U19+V19+W19 -> 0 | Y19: =X19-AO19 -> 0 | AC19: 112.0887 | AE19: 0 | AH19: 30.6 | AI19: =AI18-AH19 -> 4161.4579 | AK19: =N19+O19+P19+Q19+R19+S19+T19+U19+X19+AE19+AH19 -> 33.97 | AL19: =IF(L19<0,L19*-1,0) -> 0 | AM19: =AK19+AL19 -> 33.97 | AV19: 0.01 | AW19: 48 | AX19: 21 | AZ19: =SUM(N19,P19:U19) -> 3.37 | BA19: 0.487 | BB19: 18775
A20: =A19+1 -> 6 | B20: 6888.32 | C20: 242535 | D20: =C20-C19 -> 33 | E20: =C20-152000 -> 90535 | F20: =D20/$D$2 -> 16.637257 | G20: 51.387257 | H20: 0 | I20: =G20+H20 -> 51.387257 | J20: =IF(L20>0,L20,0) -> 0 | K20: =I20+J20 -> 51.387257 | L20: =F20-(I20-AK20) -> 0 | M20: 4.15 | N20: 0 | O20: =0*1.05 -> 0 | P20: 0 | Q20: =1092700/325851/1.9835*1.02 -> 1.724447 | R20: =IF(((2.2*1.04)-T20)>=4.2,4.2,(2.2*1.04)-T20) -> 1.7447373 | S20: =IF(((2.2*1.04)-T20)>=4.2,((2.2*1.04)-T20)-4.2,0) -> 0 | T20: =(0.4928*1.06)*1.04 -> 0.54326272 | U20: =M20-(Q20+R20+S20+T20) -> 0.137553 | V20: 0 | W20: 0 | X20: =M20-N20-P20-O20-Q20-R20-S20-T20-U20+V20+W20 -> 0 | Y20: =X20-AO20 -> 0 | AC20: 0 | AE20: 0 | AH20: 30.6 | AI20: =AI19-AH20 -> 4130.8579 | AK20: =N20+O20+P20+Q20+R20+S20+T20+U20+X20+AE20+AH20 -> 34.75 | AL20: =IF(L20<0,L20*-1,0) -> 0 | AM20: =AK20+AL20 -> 34.75 | AV20: 0 | AW20: 51 | AX20: 21 | AZ20: =SUM(N20,P20:U20) -> 4.15 | BA20: 0.487 | BB20: 18746
A21: =A20+1 -> 7 | B21: 6888.32 | C21: 242535 | D21: =C21-C20 -> 0 | E21: =C21-152000 -> 90535 | F21: =D21/$D$2 -> 0 | G21: 34.99 | H21: 0 | I21: =G21+H21 -> 34.99 | J21: =IF(L21>0,L21,0) -> 0 | K21: =I21+J21 -> 34.99 | L21: =F21-(I21-AK21) -> 0 | M21: 4.29 | N21: 0 | O21: =0*1.05 -> 0 | P21: 0 | Q21: =1020600/325851/1.9835*1.02 -> 1.6106622 | R21: =IF(((2.3*1.04)-T21)>=4.2,4.2,(2.3*1.04)-T21) -> 1.8487373 | S21: =IF(((2.3*1.04)-T21)>=4.2,((2.3*1.04)-T21)-4.2,0) -> 0 | T21: =(0.4928*1.06)*1.04 -> 0.54326272 | U21: =M21-(Q21+R21+S21+T21) -> 0.28733778 | V21: 0 | W21: 0 | X21: =M21-N21-P21-O21-Q21-R21-S21-T21-U21+V21+W21 -> 0 | Y21: =X21-AO21 -> 0 | AC21: 28.5306 | AE21: 0 | AH21: 30.7 | AI21: =AI20-AH21 -> 4100.1579 | AK21: =N21+O21+P21+Q21+R21+S21+T21+U21+X21+AE21+AH21 -> 34.99 | AL21: =IF(L21<0,L21*-1,0) -> 0 | AM21: =AK21+AL21 -> 34.99 | AV21: 0 | AW21: 58 | AX21: 23 | AZ21: =SUM(N21,P21:U21) -> 4.29 | BA21: 0.487 | BB21: 18665
A22: =A21+1 -> 8 | B22: 6888.32 | C22: 242535 | D22: =C22-C21 -> 0 | E22: =C22-152000 -> 90535 | F22: =D22/$D$2 -> 0 | G22: 33.911 | H22: 0.049 | I22: =G22+H22 -> 33.96 | J22: =IF(L22>0,L22,0) -> 0 | K22: =I22+J22 -> 33.96 | L22: =F22-(I22-AK22) -> 0 | M22: 3.46 | N22: 0 | O22: =0*1.05 -> 0 | P22: 0 | Q22: =832000/325851/1.9835*1.02 -> 1.3130227 | R22: =IF(((2.3*1.04)-T22)>=4.2,4.2,(2.3*1.04)-T22) -> 1.8487373 | S22: =IF(((2.3*1.04)-T22)>=4.2,((2.3*1.04)-T22)-4.2,0) -> 0 | T22: =(0.4928*1.06)*1.04 -> 0.54326272 | U22: =M22-(Q22+R22+S22+T22) -> -0.2450227 | V22: 0 | W22: 0 | X22: =M22-N22-P22-O22-Q22-R22-S22-T22-U22+V22+W22 -> 0 | Y22: =X22-AO22 -> 0 | AC22: 27.74924 | AE22: 0 | AH22: 30.5 | AI22: =AI21-AH22 -> 4069.6579 | AK22: =N22+O22+P22+Q22+R22+S22+T22+U22+X22+AE22+AH22 -> 33.96 | AL22: =IF(L22<0,L22*-1,0) -> 0 | AM22: =AK22+AL22 -> 33.96 | AV22: 0 | AW22: 60 | AX22: 27 | AZ22: =SUM(N22,P22:U22) -> 3.46 | BA22: 0.499 | BB22: 18657
A23: =A22+1 -> 9 | B23: 6888.34 | C23: 242602 | D23: =C23-C22 -> 67 | E23: =C23-152000 -> 90602 | F23: =D23/$D$2 -> 33.778674 | G23: 67.908674 | H23: 1.31 | I23: =G23+H23 -> 69.218674 | J23: =IF(L23>0,L23,0) -> 0 | K23: =I23+J23 -> 69.218674 | L23: =F23-(I23-AK23) -> 0 | M23: 3.72 | N23: 0 | O23: =0*1.05 -> 0 | P23: 0 | Q23: =912700/325851/1.9835*1.02 -> 1.4403796 | R23: =IF(((2.2*1.04)-T23)>=4.2,4.2,(2.2*1.04)-T23) -> 1.7447373 | S23: =IF(((2.2*1.04)-T23)>=4.2,((2.2*1.04)-T23)-4.2,0) -> 0 | T23: =(0.4928*1.06)*1.04 -> 0.54326272 | U23: =M23-(Q23+R23+S23+T23) -> -0.0083795917 | V23: 1.12 | W23: 0 | X23: =M23-N23-P23-O23-Q23-R23-S23-T23-U23+V23+W23 -> 1.12 | Y23: =X23-AO23 -> 1.12 | AC23: 61.723557 | AE23: 0 | AH23: 30.6 | AI23: =AI22-AH23 -> 4039.0579 | AK23: =N23+O23+P23+Q23+R23+S23+T23+U23+X23+AE23+AH23 -> 35.44 | AL23: =IF(L23<0,L23*-1,0) -> 0 | AM23: =AK23+AL23 -> 35.44 | AV23: 0 | AW23: 57 | AX23: 27 | AZ23: =SUM(N23,P23:U23) -> 3.72 | BA23: 0.65 | BB23: 18686
A24: =A23+1 -> 10 | B24: 6888.36 | C24: 242669 | D24: =C24-C23 -> 67 | E24: =C24-152000 -> 90669 | F24: =D24/$D$2 -> 33.778674 | G24: 67.598674 | H24: 0 | I24: =G24+H24 -> 67.598674 | J24: =IF(L24>0,L24,0) -> 0 | K24: =I24+J24 -> 67.598674 | L24: =F24-(I24-AK24) -> 0 | M24: 3.72 | N24: 0 | O24: =0*1.05 -> 0 | P24: 0 | Q24: =1083000/325851/1.9835*1.02 -> 1.7091389 | R24: =IF(((2.2*1.04)-T24)>=4.2,4.2,(2.2*1.04)-T24) -> 1.7447373 | S24: =IF(((2.2*1.04)-T24)>=4.2,((2.2*1.04)-T24)-4.2,0) -> 0 | T24: =(0.4928*1.06)*1.04 -> 0.54326272 | U24: =M24-(Q24+R24+S24+T24) -> -0.27713893 | V24: 0 | W24: 0 | X24: =M24-N24-P24-O24-Q24-R24-S24-T24-U24+V24+W24 -> 0 | Y24: =X24-AO24 -> 0 | AC24: 61.144798 | AE24: 0 | AH24: 30.1 | AI24: =AI23-AH24 -> 4008.9579 | AK24: =N24+O24+P24+Q24+R24+S24+T24+U24+X24+AE24+AH24 -> 33.82 | AL24: =IF(L24<0,L24*-1,0) -> 0 | AM24: =AK24+AL24 -> 33.82 | AV24: 0 | AW24: 55 | AX24: 29 | AZ24: =SUM(N24,P24:U24) -> 3.72 | BA24: 0.65 | BB24: 18702
A25: =A24+1 -> 11 | B25: 6888.38 | C25: 242735 | D25: =C25-C24 -> 66 | E25: =C25-152000 -> 90735 | F25: =D25/$D$2 -> 33.274515 | G25: 68.034515 | H25: 0 | I25: =G25+H25 -> 68.034515 | J25: =IF(L25>0,L25,0) -> 0 | K25: =I25+J25 -> 68.034515 | L25: =F25-(I25-AK25) -> 0 | M25: 4.66 | N25: 0 | O25: =0*1.05 -> 0 | P25: 0 | Q25: =863500/325851/1.9835*1.02 -> 1.3627345 | R25: =IF(((2.3*1.04)-T25)>=4.2,4.2,(2.3*1.04)-T25) -> 1.8459813 | S25: =IF(((2.3*1.04)-T25)>=4.2,((2.3*1.04)-T25)-4.2,0) -> 0 | T25: =(0.4953*1.06)*1.04 -> 0.54601872 | U25: =M25-(Q25+R25+S25+T25) -> 0.9052655 | V25: 0 | W25: 0 | X25: =M25-N25-P25-O25-Q25-R25-S25-T25-U25+V25+W25 -> 0 | Y25: =X25-AO25 -> 0 | AC25: 61.825799 | AE25: 0 | AH25: 30.1 | AI25: =AI24-AH25 -> 3978.8579 | AK25: =N25+O25+P25+Q25+R25+S25+T25+U25+X25+AE25+AH25 -> 34.76 | AL25: =IF(L25<0,L25*-1,0) -> 0 | AM25: =AK25+AL25 -> 34.76 | AV25: 0 | AW25: 53 | AX25: 31 | AZ25: =SUM(N25,P25:U25) -> 4.66 | BA25: 0.645 | BB25: 18743
A26: =A25+1 -> 12 | B26: 6888.43 | C26: 242902 | D26: =C26-C25 -> 167 | E26: =C26-152000 -> 90902 | F26: =D26/$D$2 -> 84.194605 | G26: 118.26461 | H26: 0 | I26: =G26+H26 -> 118.26461 | J26: =IF(L26>0,L26,0) -> 0 | K26: =I26+J26 -> 118.26461 | L26: =F26-(I26-AK26) -> 0 | M26: 3.87 | N26: 0 | O26: =0*1.05 -> 0 | P26: 0 | Q26: =911300/325851/1.9835*1.02 -> 1.4381702 | R26: =IF(((2.3*1.04)-T26)>=4.2,4.2,(2.3*1.04)-T26) -> 1.8459813 | S26: =IF(((2.3*1.04)-T26)>=4.2,((2.3*1.04)-T26)-4.2,0) -> 0 | T26: =(0.4953*1.06)*1.04 -> 0.54601872 | U26: =M26-(Q26+R26+S26+T26) -> 0.039829822 | V26: 0 | W26: 0 | X26: =M26-N26-P26-O26-Q26-R26-S26-T26-U26+V26+W26 -> 5.5511151e-16 | Y26: =X26-AO26 -> 5.5511151e-16 | AC26: 111.98045 | AE26: 0 | AH26: 30.2 | AI26: =AI25-AH26 -> 3948.6579 | AK26: =N26+O26+P26+Q26+R26+S26+T26+U26+X26+AE26+AH26 -> 34.07 | AL26: =IF(L26<0,L26*-1,0) -> 0 | AM26: =AK26+AL26 -> 34.07 | AV26: 0.11 | AW26: 38 | AX26: 26 | AZ26: =SUM(N26,P26:U26) -> 3.87 | BA26: 0.577 | BB26: 18762
A27: =A26+1 -> 13 | B27: 6888.45 | C27: 242969 | D27: =C27-C26 -> 67 | E27: =C27-152000 -> 90969 | F27: =D27/$D$2 -> 33.778674 | G27: 67.658674 | H27: 0 | I27: =G27+H27 -> 67.658674 | J27: =IF(L27>0,L27,0) -> 0 | K27: =I27+J27 -> 67.658674 | L27: =F27-(I27-AK27) -> 0 | M27: 3.68 | N27: 0 | O27: =0*1.05 -> 0 | P27: 0 | Q27: =1052800/325851/1.9835*1.02 -> 1.6614787 | R27: =IF(((2.3*1.04)-T27)>=4.2,4.2,(2.3*1.04)-T27) -> 1.8459813 | S27: =IF(((2.3*1.04)-T27)>=4.2,((2.3*1.04)-T27)-4.2,0) -> 0 | T27: =(0.4953*1.06)*1.04 -> 0.54601872 | U27: =M27-(Q27+R27+S27+T27) -> -0.37347873 | V27: 0 | W27: 0 | X27: =M27-N27-P27-O27-Q27-R27-S27-T27-U27+V27+W27 -> 0 | Y27: =X27-AO27 -> 0 | AC27: 0 | AE27: 0 | AH27: 30.2 | AI27: =AI26-AH27 -> 3918.4579 | AK27: =N27+O27+P27+Q27+R27+S27+T27+U27+X27+AE27+AH27 -> 33.88 | AL27: =IF(L27<0,L27*-1,0) -> 0 | AM27: =AK27+AL27 -> 33.88 | AV27: 0 | AW27: 42 | AX27: 17 | AZ27: =SUM(N27,P27:U27) -> 3.68 | BA27: 0.487 | BB27: 18821
A28: =A27+1 -> 14 | B28: 6888.49 | C28: 243102 | D28: =C28-C27 -> 133 | E28: =C28-152000 -> 91102 | F28: =D28/$D$2 -> 67.053189 | G28: 102.17319 | H28: 0 | I28: =G28+H28 -> 102.17319 | J28: =IF(L28>0,L28,0) -> 0 | K28: =I28+J28 -> 102.17319 | L28: =F28-(I28-AK28) -> 0 | M28: 4.62 | N28: 0 | O28: =9.36*1.05 -> 9.828 | P28: 0 | Q28: =867200/325851/1.9835*1.02 -> 1.3685737 | R28: =IF(((2.3*1.04)-T28)>=4.2,4.2,(2.3*1.04)-T28) -> 1.8459813 | S28: =IF(((2.3*1.04)-T28)>=4.2,((2.3*1.04)-T28)-4.2,0) -> 0 | T28: =(0.4953*1.06)*1.04 -> 0.54601872 | U28: =M28-(Q28+R28+S28+T28) -> 0.85942634 | V28: 0 | W28: 0 | X28: =M28-N28-P28-O28-Q28-R28-S28-T28-U28+V28+W28 -> -9.828 | Y28: =X28-AO28 -> -9.828 | AC28: 95.958634 | AE28: 0 | AH28: 30.5 | AI28: =AI27-AH28 -> 3887.9579 | AK28: =N28+O28+P28+Q28+R28+S28+T28+U28+X28+AE28+AH28 -> 35.12 | AL28: =IF(L28<0,L28*-1,0) -> 0 | AM28: =AK28+AL28 -> 35.12 | AV28: 0.695 | AW28: 37 | AX28: 20 | AZ28: =SUM(N28,P28:U28) -> 4.62 | BA28: 0.487 | BB28: 18819
A29: =A28+1 -> 15 | B29: 6888.49 | C29: 243102 | D29: =C29-C28 -> 0 | E29: =C29-152000 -> 91102 | F29: =D29/$D$2 -> 0 | G29: 34.06 | H29: 0 | I29: =G29+H29 -> 34.06 | J29: =IF(L29>0,L29,0) -> 0 | K29: =I29+J29 -> 34.06 | L29: =F29-(I29-AK29) -> 0 | M29: 3.76 | N29: 0 | O29: =10.4*1.05 -> 10.92 | P29: 0 | Q29: =1001300/325851/1.9835*1.02 -> 1.5802039 | R29: =IF(((2.2*1.04)-T29)>=4.2,4.2,(2.2*1.04)-T29) -> 1.7419813 | S29: =IF(((2.2*1.04)-T29)>=4.2,((2.2*1.04)-T29)-4.2,0) -> 0 | T29: =(0.4953*1.06)*1.04 -> 0.54601872 | U29: =M29-(Q29+R29+S29+T29) -> -0.10820388 | V29: 0 | W29: 0 | X29: =M29-N29-P29-O29-Q29-R29-S29-T29-U29+V29+W29 -> -10.92 | Y29: =X29-AO29 -> -10.92 | AC29: 27.737815 | AE29: 0 | AH29: 30.3 | AI29: =AI28-AH29 -> 3857.6579 | AK29: =N29+O29+P29+Q29+R29+S29+T29+U29+X29+AE29+AH29 -> 34.06 | AL29: =IF(L29<0,L29*-1,0) -> 0 | AM29: =AK29+AL29 -> 34.06 | AV29: 0 | AW29: 29 | AX29: 8 | AZ29: =SUM(N29,P29:U29) -> 3.76 | BA29: 0.487 | BB29: 18790
A30: =A29+1 -> 16 | B30: 6888.498 | C30: 243135 | D30: =C30-C29 -> 33 | E30: =C30-152000 -> 91135 | F30: =D30/$D$2 -> 16.637257 | G30: 50.987257 | H30: 0 | I30: =G30+H30 -> 50.987257 | J30: =IF(L30>0,L30,0) -> 0 | K30: =I30+J30 -> 50.987257 | L30: =F30-(I30-AK30) -> 0 | M30: 4.15 | N30: 0 | O30: =0.019*1.05 -> 0.01995 | P30: 0 | Q30: =1043700/325851/1.9835*1.02 -> 1.6471175 | R30: =IF(((2.3*1.04)-T30)>=4.2,4.2,(2.3*1.04)-T30) -> 1.8459813 | S30: =IF(((2.3*1.04)-T30)>=4.2,((2.3*1.04)-T30)-4.2,0) -> 0 | T30: =(0.4953*1.06)*1.04 -> 0.54601872 | U30: =M30-(Q30+R30+S30+T30) -> 0.11088246 | V30: 0 | W30: 0 | X30: =M30-N30-P30-O30-Q30-R30-S30-T30-U30+V30+W30 -> -0.01995 | Y30: =X30-AO30 -> -0.01995 | AC30: 44.494159 | AE30: 0 | AH30: 30.2 | AI30: =AI29-AH30 -> 3827.4579 | AK30: =N30+O30+P30+Q30+R30+S30+T30+U30+X30+AE30+AH30 -> 34.35 | AL30: =IF(L30<0,L30*-1,0) -> 0 | AM30: =AK30+AL30 -> 34.35 | AV30: 0 | AW30: 22 | AX30: 7 | AZ30: =SUM(N30,P30:U30) -> 4.15 | BA30: 0.487 | BB30: 18798
A31: =A30+1 -> 17 | B31: 6888.506 | C31: 243168 | D31: =C31-C30 -> 33 | E31: =C31-152000 -> 91168 | F31: =D31/$D$2 -> 16.637257 | G31: 51.177257 | H31: 0 | I31: =G31+H31 -> 51.177257 | J31: =IF(L31>0,L31,0) -> 0 | K31: =I31+J31 -> 51.177257 | L31: =F31-(I31-AK31) -> 0 | M31: 4.14 | N31: 0 | O31: =0.039*1.05 -> 0.04095 | P31: 0 | Q31: =941800/325851/1.9835*1.02 -> 1.4863038 | R31: =IF(((2.2*1.04)-T31)>=4.2,4.2,(2.2*1.04)-T31) -> 1.7419813 | S31: =IF(((2.2*1.04)-T31)>=4.2,((2.2*1.04)-T31)-4.2,0) -> 0 | T31: =(0.4953*1.06)*1.04 -> 0.54601872 | U31: =M31-(Q31+R31+S31+T31) -> 0.36569618 | V31: 0 | W31: 0 | X31: =M31-N31-P31-O31-Q31-R31-S31-T31-U31+V31+W31 -> -0.04095 | Y31: =X31-AO31 -> -0.04095 | AC31: 44.948972 | AE31: 0 | AH31: 30.4 | AI31: =AI30-AH31 -> 3797.0579 | AK31: =N31+O31+P31+Q31+R31+S31+T31+U31+X31+AE31+AH31 -> 34.54 | AL31: =IF(L31<0,L31*-1,0) -> 0 | AM31: =AK31+AL31 -> 34.54 | AV31: 0 | AW31: 24 | AX31: 9 | AZ31: =SUM(N31,P31:U31) -> 4.14 | BA31: 0.487 | BB31: 18814
A32: =A31+1 -> 18 | B32: 6888.514 | C32: 243168 | D32: =C32-C31 -> 0 | E32: =C32-152000 -> 91168 | F32: =D32/$D$2 -> 0 | G32: 34.61 | H32: 0 | I32: =G32+H32 -> 34.61 | J32: =IF(L32>0,L32,0) -> 0 | K32: =I32+J32 -> 34.61 | L32: =F32-(I32-AK32) -> 0 | M32: 4.01 | N32: 0 | O32: =0.016*1.05 -> 0.0168 | P32: 0 | Q32: =953000/325851/1.9835*1.02 -> 1.5039791 | R32: =IF(((2.2*1.04)-T32)>=4.2,4.2,(2.2*1.04)-T32) -> 1.64034 | S32: =IF(((2.2*1.04)-T32)>=4.2,((2.2*1.04)-T32)-4.2,0) -> 0 | T32: =(0.5875*1.06)*1.04 -> 0.64766 | U32: =M32-(Q32+R32+S32+T32) -> 0.21802087 | V32: 0 | W32: 0 | X32: =M32-N32-P32-O32-Q32-R32-S32-T32-U32+V32+W32 -> -0.0168 | Y32: =X32-AO32 -> -0.0168 | AC32: 28.465681 | AE32: 0 | AH32: 30.6 | AI32: =AI31-AH32 -> 3766.4579 | AK32: =N32+O32+P32+Q32+R32+S32+T32+U32+X32+AE32+AH32 -> 34.61 | AL32: =IF(L32<0,L32*-1,0) -> 0 | AM32: =AK32+AL32 -> 34.61 | AV32: 0.12 | AW32: 43 | AX32: 11 | AZ32: =SUM(N32,P32:U32) -> 4.01 | BA32: 0.487 | BB32: 18812
A33: =A32+1 -> 19 | B33: 6888.522 | C33: 243202 | D33: =C33-C32 -> 34 | E33: =C33-152000 -> 91202 | F33: =D33/$D$2 -> 17.141417 | G33: 51.741417 | H33: 0 | I33: =G33+H33 -> 51.741417 | J33: =IF(L33>0,L33,0) -> 0 | K33: =I33+J33 -> 51.741417 | L33: =F33-(I33-AK33) -> 0 | M33: 4.1 | N33: 0 | O33: =0.458*1.05 -> 0.4809 | P33: 0 | Q33: =1019200/325851/1.9835*1.02 -> 1.6084528 | R33: =IF(((2.3*1.04)-T33)>=4.2,4.2,(2.3*1.04)-T33) -> 1.74434 | S33: =IF(((2.3*1.04)-T33)>=4.2,((2.3*1.04)-T33)-4.2,0) -> 0 | T33: =(0.5875*1.06)*1.04 -> 0.64766 | U33: =M33-(Q33+R33+S33+T33) -> 0.09954719 | V33: 0 | W33: 0 | X33: =M33-N33-P33-O33-Q33-R33-S33-T33-U33+V33+W33 -> -0.4809 | Y33: =X33-AO33 -> -0.4809 | AC33: 45.388624 | AE33: 0 | AH33: 30.5 | AI33: =AI32-AH33 -> 3735.9579 | AK33: =N33+O33+P33+Q33+R33+S33+T33+U33+X33+AE33+AH33 -> 34.6 | AL33: =IF(L33<0,L33*-1,0) -> 0 | AM33: =AK33+AL33 -> 34.6 | AV33: 0.04 | AW33: 53 | AX33: 21 | AZ33: =SUM(N33,P33:U33) -> 4.1 | BA33: 0.487 | BB33: 18846
A34: =A33+1 -> 20 | B34: 6888.53 | C34: 243235 | D34: =C34-C33 -> 33 | E34: =C34-152000 -> 91235 | F34: =D34/$D$2 -> 16.637257 | G34: 51.767257 | H34: 0 | I34: =G34+H34 -> 51.767257 | J34: =IF(L34>0,L34,0) -> 0 | K34: =I34+J34 -> 51.767257 | L34: =F34-(I34-AK34) -> 0 | M34: 4.43 | N34: 0 | O34: =0*1.05 -> 0 | P34: 0 | Q34: =1079400/325851/1.9835*1.02 -> 1.7034576 | R34: =IF(((2.2*1.04)-T34)>=4.2,4.2,(2.2*1.04)-T34) -> 1.64034 | S34: =IF(((2.2*1.04)-T34)>=4.2,((2.2*1.04)-T34)-4.2,0) -> 0 | T34: =(0.5875*1.06)*1.04 -> 0.64766 | U34: =M34-(Q34+R34+S34+T34) -> 0.43854242 | V34: 0 | W34: 0 | X34: =M34-N34-P34-O34-Q34-R34-S34-T34-U34+V34+W34 -> 0 | Y34: =X34-AO34 -> 0 | AC34: 45.42346 | AE34: 0 | AH34: 30.7 | AI34: =AI33-AH34 -> 3705.2579 | AK34: =N34+O34+P34+Q34+R34+S34+T34+U34+X34+AE34+AH34 -> 35.13 | AL34: =IF(L34<0,L34*-1,0) -> 0 | AM34: =AK34+AL34 -> 35.13 | AV34: 0.1 | AW34: 48 | AX34: 28 | AZ34: =SUM(N34,P34:U34) -> 4.43 | BA34: 0.487 | BB34: 18858
A35: =A34+1 -> 21 | B35: 6888.56 | C35: 243335 | D35: =C35-C34 -> 100 | E35: =C35-152000 -> 91335 | F35: =D35/$D$2 -> 50.415931 | G35: 85.405931 | H35: 0 | I35: =G35+H35 -> 85.405931 | J35: =IF(L35>0,L35,0) -> 0 | K35: =I35+J35 -> 85.405931 | L35: =F35-(I35-AK35) -> 0 | M35: 4.19 | N35: 0 | O35: =0*1.05 -> 0 | P35: 0 | Q35: =963900/325851/1.9835*1.02 -> 1.521181 | R35: =IF(((2.2*1.04)-T35)>=4.2,4.2,(2.2*1.04)-T35) -> 1.64034 | S35: =IF(((2.2*1.04)-T35)>=4.2,((2.2*1.04)-T35)-4.2,0) -> 0 | T35: =(0.5875*1.06)*1.04 -> 0.64766 | U35: =M35-(Q35+R35+S35+T35) -> 0.38081901 | V35: 0 | W35: 0 | X35: =M35-N35-P35-O35-Q35-R35-S35-T35-U35+V35+W35 -> 0 | Y35: =X35-AO35 -> 0 | AC35: 79.24441 | AE35: 0 | AH35: 30.8 | AI35: =AI34-AH35 -> 3674.4579 | AK35: =N35+O35+P35+Q35+R35+S35+T35+U35+X35+AE35+AH35 -> 34.99 | AL35: =IF(L35<0,L35*-1,0) -> 0 | AM35: =AK35+AL35 -> 34.99 | AV35: 0.1 | AW35: 39 | AX35: 26 | AZ35: =SUM(N35,P35:U35) -> 4.19 | BA35: 0.487 | BB35: 18861
A36: =A35+1 -> 22 | B36: 6888.64 | C36: 243602 | D36: =C36-C35 -> 267 | E36: =C36-152000 -> 91602 | F36: =D36/$D$2 -> 134.61054 | G36: 168.74054 | H36: 0 | I36: =G36+H36 -> 168.74054 | J36: =IF(L36>0,L36,0) -> 0 | K36: =I36+J36 -> 168.74054 | L36: =F36-(I36-AK36) -> 0 | M36: 3.33 | N36: 0 | O36: =0*1.05 -> 0 | P36: 0 | Q36: =951000/325851/1.9835*1.02 -> 1.5008228 | R36: =IF(((1.9*1.04)-T36)>=4.2,4.2,(1.9*1.04)-T36) -> 1.32834 | S36: =IF(((1.9*1.04)-T36)>=4.2,((1.9*1.04)-T36)-4.2,0) -> 0 | T36: =(0.5875*1.06)*1.04 -> 0.64766 | U36: =M36-(Q36+R36+S36+T36) -> -0.14682282 | V36: 0 | W36: 0 | X36: =M36-N36-P36-O36-Q36-R36-S36-T36-U36+V36+W36 -> 0 | Y36: =X36-AO36 -> 0 | AC36: 162.91137 | AE36: 0 | AH36: 30.8 | AI36: =AI35-AH36 -> 3643.6579 | AK36: =N36+O36+P36+Q36+R36+S36+T36+U36+X36+AE36+AH36 -> 34.13 | AL36: =IF(L36<0,L36*-1,0) -> 0 | AM36: =AK36+AL36 -> 34.13 | AV36: 0.68 | AW36: 38 | AX36: 29 | AZ36: =SUM(N36,P36:U36) -> 3.33 | BA36: 0.487 | BB36: 18872
A37: =A36+1 -> 23 | B37: 6888.64 | C37: 243602 | D37: =C37-C36 -> 0 | E37: =C37-152000 -> 91602 | F37: =D37/$D$2 -> 0 | G37: 34.19 | H37: 0 | I37: =G37+H37 -> 34.19 | J37: =IF(L37>0,L37,0) -> 0 | K37: =I37+J37 -> 34.19 | L37: =F37-(I37-AK37) -> 0 | M37: 3.39 | N37: 0 | O37: =0*1.05 -> 0 | P37: 0 | Q37: =865500/325851/1.9835*1.02 -> 1.3658908 | R37: =IF(((1.9*1.04)-T37)>=4.2,4.2,(1.9*1.04)-T37) -> 1.32834 | S37: =IF(((1.9*1.04)-T37)>=4.2,((1.9*1.04)-T37)-4.2,0) -> 0 | T37: =(0.5875*1.06)*1.04 -> 0.64766 | U37: =M37-(Q37+R37+S37+T37) -> 0.048109196 | V37: 0 | W37: 0 | X37: =M37-N37-P37-O37-Q37-R37-S37-T37-U37+V37+W37 -> 0 | Y37: =X37-AO37 -> 0 | AC37: 28.495769 | AE37: 0 | AH37: 30.8 | AI37: =AI36-AH37 -> 3612.8579 | AK37: =N37+O37+P37+Q37+R37+S37+T37+U37+X37+AE37+AH37 -> 34.19 | AL37: =IF(L37<0,L37*-1,0) -> 0 | AM37: =AK37+AL37 -> 34.19 | AV37: 0.16964286 | AW37: 34 | AX37: 8 | AZ37: =SUM(N37,P37:U37) -> 3.39 | BA37: 0.487 | BB37: 18868
A38: =A37+1 -> 24 | B38: 6888.64 | C38: 243602 | D38: =C38-C37 -> 0 | E38: =C38-152000 -> 91602 | F38: =D38/$D$2 -> 0 | G38: 34.65 | H38: 0 | I38: =G38+H38 -> 34.65 | J38: =IF(L38>0,L38,0) -> 0 | K38: =I38+J38 -> 34.65 | L38: =F38-(I38-AK38) -> 0 | M38: 3.85 | N38: 0 | O38: =0*1.05 -> 0 | P38: 0 | Q38: =857200/325851/1.9835*1.02 -> 1.3527921 | R38: =IF(((2*1.04)-T38)>=4.2,4.2,(2*1.04)-T38) -> 1.43234 | S38: =IF(((2*1.04)-T38)>=4.2,((2*1.04)-T38)-4.2,0) -> 0 | T38: =(0.5875*1.06)*1.04 -> 0.64766 | U38: =M38-(Q38+R38+S38+T38) -> 0.41720786 | V38: 0 | W38: 0 | X38: =M38-N38-P38-O38-Q38-R38-S38-T38-U38+V38+W38 -> 0 | Y38: =X38-AO38 -> 0 | AC38: 28.864868 | AE38: 0 | AH38: 30.8 | AI38: =AI37-AH38 -> 3582.0579 | AK38: =N38+O38+P38+Q38+R38+S38+T38+U38+X38+AE38+AH38 -> 34.65 | AL38: =IF(L38<0,L38*-1,0) -> 0 | AM38: =AK38+AL38 -> 34.65 | AV38: 0.20357143 | AW38: 33 | AX38: 3 | AZ38: =SUM(N38,P38:U38) -> 3.85 | BA38: 0.487 | BB38: 18958
A39: =A38+1 -> 25 | B39: 6888.67 | C39: 243702 | D39: =C39-C38 -> 100 | E39: =C39-152000 -> 91702 | F39: =D39/$D$2 -> 50.415931 | G39: 85.075931 | H39: 0 | I39: =G39+H39 -> 85.075931 | J39: =IF(L39>0,L39,0) -> 0 | K39: =I39+J39 -> 85.075931 | L39: =F39-(I39-AK39) -> 0 | M39: 3.86 | N39: 0 | O39: =0*1.05 -> 0 | P39: 0 | Q39: =1029400/325851/1.9835*1.02 -> 1.62455 | R39: =IF(((1.8*1.04)-T39)>=4.2,4.2,(1.8*1.04)-T39) -> 1.2370176 | S39: =IF(((1.8*1.04)-T39)>=4.2,((1.8*1.04)-T39)-4.2,0) -> 0 | T39: =(0.576*1.06)*1.04 -> 0.6349824 | U39: =M39-(Q39+R39+S39+T39) -> 0.36345004 | V39: 0 | W39: 0 | X39: =M39-N39-P39-O39-Q39-R39-S39-T39-U39+V39+W39 -> 0 | Y39: =X39-AO39 -> 0 | AC39: 53.44 | AE39: 0 | AH39: 30.8 | AI39: =AI38-AH39 -> 3551.2579 | AK39: =N39+O39+P39+Q39+R39+S39+T39+U39+X39+AE39+AH39 -> 34.66 | AL39: =IF(L39<0,L39*-1,0) -> 0 | AM39: =AK39+AL39 -> 34.66 | AV39: 0.10178571 | AW39: 34 | AX39: 13 | AZ39: =SUM(N39,P39:U39) -> 3.86 | BA39: 0.487 | BB39: 18906
A40: =A39+1 -> 26 | B40: 6888.69 | C40: 243768 | D40: =C40-C39 -> 66 | E40: =C40-152000 -> 91768 | F40: =D40/$D$2 -> 33.274515 | G40: 67.284515 | H40: 0 | I40: =G40+H40 -> 67.284515 | J40: =IF(L40>0,L40,0) -> 0 | K40: =I40+J40 -> 67.284515 | L40: =F40-(I40-AK40) -> 0 | M40: 3.21 | N40: 0 | O40: =0*1.05 -> 0 | P40: 0 | Q40: =915600/325851/1.9835*1.02 -> 1.4449562 | R40: =IF(((1.8*1.04)-T40)>=4.2,4.2,(1.8*1.04)-T40) -> 1.2370176 | S40: =IF(((1.8*1.04)-T40)>=4.2,((1.8*1.04)-T40)-4.2,0) -> 0 | T40: =(0.576*1.06)*1.04 -> 0.6349824 | U40: =M40-(Q40+R40+S40+T40) -> -0.10695623 | V40: 0 | W40: 0 | X40: =M40-N40-P40-O40-Q40-R40-S40-T40-U40+V40+W40 -> 0 | Y40: =X40-AO40 -> 0 | AE40: 0 | AH40: 30.8 | AI40: =AI39-AH40 -> 3520.4579 | AK40: =N40+O40+P40+Q40+R40+S40+T40+U40+X40+AE40+AH40 -> 34.01 | AL40: =IF(L40<0,L40*-1,0) -> 0 | AM40: =AK40+AL40 -> 34.01 | AV40: 0 | AW40: 24 | AX40: 7 | AZ40: =SUM(N40,P40:U40) -> 3.21 | BA40: 0.487 | BB40: 18925
A41: =A40+1 -> 27 | B41: 6888.69 | C41: 243768 | D41: =C41-C40 -> 0 | E41: =C41-152000 -> 91768 | F41: =D41/$D$2 -> 0 | G41: 35.24 | H41: 0 | I41: =G41+H41 -> 35.24 | J41: =IF(L41>0,L41,0) -> 0 | K41: =I41+J41 -> 35.24 | L41: =F41-(I41-AK41) -> 0 | M41: 4.44 | N41: 0 | O41: =0*1.05 -> 0 | P41: 0 | Q41: =1128000/325851/1.9835*1.02 -> 1.7801558 | R41: =IF(((1.9*1.04)-T41)>=4.2,4.2,(1.9*1.04)-T41) -> 1.3410176 | S41: =IF(((1.9*1.04)-T41)>=4.2,((1.9*1.04)-T41)-4.2,0) -> 0 | T41: =(0.576*1.06)*1.04 -> 0.6349824 | U41: =M41-(Q41+R41+S41+T41) -> 0.68384422 | V41: 0 | W41: 0 | X41: =M41-N41-P41-O41-Q41-R41-S41-T41-U41+V41+W41 -> 0 | Y41: =X41-AO41 -> 0 | AE41: 0 | AH41: 30.8 | AI41: =AI40-AH41 -> 3489.6579 | AK41: =N41+O41+P41+Q41+R41+S41+T41+U41+X41+AE41+AH41 -> 35.24 | AL41: =IF(L41<0,L41*-1,0) -> 0 | AM41: =AK41+AL41 -> 35.24 | AV41: 0 | AW41: 27 | AX41: 2 | AZ41: =SUM(N41,P41:U41) -> 4.44 | BA41: 0.487 | BB41: 18904
